Workbook

Sheet 표지
A6: 2026년 5월 마감 손익
A24: 레미콘사업본부

Sheet 손익총괄
C3: □ 건재사업본부 손익실적(2026-05)
X4: [단위 : 천㎥, 톤, 원/㎥, 원/톤, 백만원]
C5: 구분 | E5: 5월 | J5: 5월누계 | P5: 5월 주요지표
E6: 계획 | F6: 실적 | G6: 계획대비 | H6: 전년 | I6: 전년대비 | J6: 계획 | K6: 실적 | L6: 계획대비 | M6: 전년 | N6: 전년대비
C7: 물량 | D7: 레미콘 | E7: =+'[1]5월'!$Z$7/1000 -> 270 | F7: =+'[2]5월'!$Z$7/1000 -> 218.1895 | G7: =+F7-E7 -> -51.8105 | H7: =+'[3]5월'!$Z$7/1000 -> 242.9955 | I7: =+F7-H7 -> -24.806 | J7: =+'[1]5월누계'!$Z$7/1000 -> 1166.4998 | K7: =+'[2]5월누계'!$Z$7/1000 -> 1075.544 | L7: =+K7-J7 -> -90.9558 | M7: =+'[3]5월누계'!$Z$7/1000 -> 1174.434 | N7: =+K7-M7 -> -98.89 | Q7: □ 레미콘
D8: 골재 | E8: =+'[1]5월'!$AE$7/1000 -> 73.588167 | F8: =+'[2]5월'!$AN$7/1000 -> 67.368 | G8: =+F8-E8 -> -6.2201672 | H8: =+'[3]5월'!$AN$7/1000 -> 69.689 | I8: =+F8-H8 -> -2.321 | J8: =+'[1]5월누계'!$AE$7/1000 -> 346.96908 | K8: =+'[2]5월누계'!$AN$7/1000 -> 316.091 | L8: =+K8-J8 -> -30.878083 | M8: =+'[3]5월누계'!$AN$7/1000 -> 305.114 | N8: =+K8-M8 -> 10.977 | Q8: 구분 | S8: 계획 | T8: 실적 | U8: 계획대비 | V8: 전년 | W8: 전년대비
C9: 매출 | D9: 레미콘 | E9: =+'[1]5월'!$Z$8/1000 -> 27386.723 | F9: =+'[2]5월'!$Z$8/1000 -> 22382.409 | G9: =+F9-E9 -> -5004.314 | H9: =+'[3]5월'!$Z$8/1000 -> 23799.928 | I9: =+F9-H9 -> -1417.519 | J9: =+'[1]5월누계'!$Z$8/1000 -> 118311.05 | K9: =+'[2]5월누계'!$Z$8/1000 -> 110917.84 | L9: =+K9-J9 -> -7393.2085 | M9: =+'[3]5월누계'!$Z$8/1000 -> 115938.49 | N9: =+K9-M9 -> -5020.646 | Q9: 물량 | R9: 수도권 | S9: =+[4]수도권!$T$5/1000 -> 105 | T9: =+[4]수도권!$U$5/1000 -> 92.18 | U9: =+T9-S9 -> -12.82 | V9: =+[5]수도권!$T$5/1000 -> 85.7685 | W9: =+T9-V9 -> 6.4115
D10: 골재 | E10: =+'[1]5월'!$AE$8/1000 -> 1333.4312 | F10: =+'[2]5월'!$AN$8/1000 -> 1213.8512 | G10: =+F10-E10 -> -119.57996 | H10: =+'[3]5월'!$AN$8/1000 -> 1467.6265 | I10: =+F10-H10 -> -253.7753 | J10: =+'[1]5월누계'!$AE$8/1000 -> 6265.4408 | K10: =+'[2]5월누계'!$AN$8/1000 -> 6154.7293 | L10: =+K10-J10 -> -110.71153 | M10: =+'[3]5월누계'!$AN$8/1000 -> 6494.441 | N10: =+K10-M10 -> -339.7117 | R10: 영남권 | S10: =+[4]영남권!$T$5/1000 -> 117 | T10: =+[4]영남권!$U$5/1000 -> 83.368 | U10: =+T10-S10 -> -33.632 | V10: =+[5]영남권!$T$5/1000 -> 106.883 | W10: =+T10-V10 -> -23.515
D11: 기타 | E11: =+'[1]5월'!$E$8/1000-E9-E33-E10 -> 119.36667 | F11: =+('[2]5월'!$BJ$8+'[2]5월'!$BA$8+'[2]5월'!$AP$8+'[2]5월'!$AH$8)/1000 -> 56.28337 | G11: =+F11-E11 -> -63.083297 | H11: =+'[3]5월'!$F$8/1000-H9-H33-H10 -> 118.78848 | I11: =+F11-H11 -> -62.505111 | J11: =+'[1]5월누계'!$E$8/1000-J9-J33-J10 -> 604.63333 | K11: =+('[2]5월누계'!$BJ$8+'[2]5월누계'!$BA$8+'[2]5월누계'!$AP$8+'[2]5월누계'!$AH$8)/1000 -> 463.26409 | L11: =+K11-J11 -> -141.36924 | M11: =+'[3]5월누계'!$F$8/1000-M9-M33-M10 -> 710.11164 | N11: =+K11-M11 -> -246.84755 | R11: 중부권 | S11: =+[4]중부권!$T$5/1000 -> 48 | T11: =+[4]중부권!$U$5/1000 -> 42.6415 | U11: =+T11-S11 -> -5.3585 | V11: =+[5]중부권!$T$5/1000 -> 50.344 | W11: =+T11-V11 -> -7.7025
C12: 계 | E12: =SUM(E9:E11) -> 28839.521 | F12: =SUM(F9:F11) -> 23652.544 | G12: =+F12-E12 -> -5186.9772 | H12: =SUM(H9:H11) -> 25386.343 | I12: =+F12-H12 -> -1733.7994 | J12: =SUM(J9:J11) -> 125181.13 | K12: =SUM(K9:K11) -> 117535.84 | L12: =+K12-J12 -> -7645.2893 | M12: =SUM(M9:M11) -> 123143.04 | N12: =+K12-M12 -> -5607.2053 | Q12: 계 | S12: =SUM(S9:S11) -> 270 | T12: =SUM(T9:T11) -> 218.1895 | U12: =+T12-S12 -> -51.8105 | V12: =SUM(V9:V11) -> 242.9955 | W12: =+T12-V12 -> -24.806
C13: 매출원가 | D13: 레미콘 | E13: =+('[1]5월'!$Z$10+'[1]5월'!$Z$19)/1000 -> 23862.626 | F13: =+('[2]5월'!$Z$10+'[2]5월'!$Z$19)/1000 -> 20336.808 | G13: =+F13-E13 -> -3525.8174 | H13: =+('[3]5월'!$Z$10+'[3]5월'!$Z$19)/1000 -> 21588.831 | I13: =+F13-H13 -> -1252.0224 | J13: =+('[1]5월누계'!$Z$10+'[1]5월누계'!$Z$19)/1000 -> 107056.15 | K13: =+('[2]5월누계'!$Z$10+'[2]5월누계'!$Z$19)/1000 -> 102910.29 | L13: =+K13-J13 -> -4145.8554 | M13: =+('[3]5월누계'!$Z$10+'[3]5월누계'!$Z$19)/1000 -> 106232.04 | N13: =+K13-M13 -> -3321.7499 | Q13: 판매단가 | R13: 수도권 | S13: =+[4]수도권!$T$61 -> 98482.527 | T13: =+[4]수도권!$U$61 -> 100715.68 | U13: =+T13-S13 -> 2233.1483 | V13: =+[5]수도권!$Q$85 -> 96609.726 | W13: =+T13-V13 -> 4105.9488
D14: 골재 | E14: =+('[1]5월'!$AE$10+'[1]5월'!$AE$19)/1000 -> 1332.0381 | F14: =+('[2]5월'!$AN$10+'[2]5월'!$AN$19)/1000 -> 1270.1057 | G14: =+F14-E14 -> -61.932372 | H14: =+('[3]5월'!$AN$10+'[3]5월'!$AN$19)/1000 -> 1406.9589 | I14: =+F14-H14 -> -136.85316 | J14: =+('[1]5월누계'!$AE$10+'[1]5월누계'!$AE$19)/1000 -> 6343.9285 | K14: =+('[2]5월누계'!$AN$10+'[2]5월누계'!$AN$19)/1000 -> 6548.1851 | L14: =+K14-J14 -> 204.25661 | M14: =+('[3]5월누계'!$AN$10+'[3]5월누계'!$AN$19)/1000 -> 6694.1268 | N14: =+K14-M14 -> -145.94171 | R14: 영남권 | S14: =+[4]영남권!$T$61 -> 102761.14 | T14: =+[4]영남권!$U$61 -> 102825.49 | U14: =+T14-S14 -> 64.35209 | V14: =+[5]영남권!$Q$85 -> 97803.84 | W14: =+T14-V14 -> 5021.6533
D15: 기타 | E15: =+('[1]5월'!$AL$10+'[1]5월'!$AL$19+'[1]5월'!$AV$10+'[1]5월'!$AV$19)/1000 -> 54.346293 | F15: =+('[2]5월'!$AH$10+'[2]5월'!$AH$19+'[2]5월'!$AP$10+'[2]5월'!$AP$19+'[2]5월'!$BA$10+'[2]5월'!$BA$19+'[2]5월'!$BJ$10+'[2]5월'!$BJ$19)/1000 -> 20.826595 | G15: =+F15-E15 -> -33.519698 | H15: =+('[3]5월'!$F$10+'[3]5월'!$F$19)/1000-H13-H14-('[3]5월'!$AO$10+'[3]5월'!$AO$19)/1000 -> 18.465355 | I15: =+F15-H15 -> 2.36124 | J15: =+('[1]5월누계'!$AL$10+'[1]5월누계'!$AL$19+'[1]5월누계'!$AV$10+'[1]5월누계'!$AV$19)/1000 -> -164.90285 | K15: =+('[2]5월누계'!$AH$10+'[2]5월누계'!$AH$19+'[2]5월누계'!$AP$10+'[2]5월누계'!$AP$19+'[2]5월누계'!$BA$10+'[2]5월누계'!$BA$19+'[2]5월누계'!$BJ$10+'[2]5월누계'!$BJ$19)/1000 -> -409.71527 | L15: =+K15-J15 -> -244.81242 | M15: =+('[3]5월누계'!$F$10+'[3]5월누계'!$F$19)/1000-M13-M14-('[3]5월누계'!$AO$10+'[3]5월누계'!$AO$19)/1000 -> 422.6893 | N15: =+K15-M15 -> -832.40456 | R15: 중부권 | S15: =+[4]중부권!$T$61 -> 104645.92 | T15: =+[4]중부권!$U$61 -> 106299.7 | U15: =+T15-S15 -> 1653.7784 | V15: =+[5]중부권!$Q$85 -> 100717.64 | W15: =+T15-V15 -> 5582.0544
C16: 계 | E16: =SUM(E13:E15) -> 25249.01 | F16: =SUM(F13:F15) -> 21627.741 | G16: =+F16-E16 -> -3621.2695 | H16: =SUM(H13:H15) -> 23014.255 | I16: =+F16-H16 -> -1386.5143 | J16: =SUM(J13:J15) -> 113235.18 | K16: =SUM(K13:K15) -> 109048.76 | L16: =+K16-J16 -> -4186.4112 | M16: =SUM(M13:M15) -> 113348.86 | N16: =+K16-M16 -> -4300.0961 | Q16: 계 | S16: =+[4]합계!$T$61 -> 101432.31 | T16: =+[4]합계!$U$61 -> 102620.92 | U16: =+T16-S16 -> 1188.6098 | V16: =+[5]합계!$Q$85 -> 97989.576 | W16: =+T16-V16 -> 4631.3411
C17: 매출이익 | D17: 레미콘 | E17: =+E9-E13 -> 3524.0972 | F17: =+F9-F13 -> 2045.6007 | G17: =+F17-E17 -> -1478.4966 | H17: =+H9-H13 -> 2211.0972 | I17: =+F17-H17 -> -165.49657 | J17: =+J9-J13 -> 11254.902 | K17: =+K9-K13 -> 8007.5492 | L17: =+K17-J17 -> -3247.3532 | M17: =+M9-M13 -> 9706.4454 | N17: =+K17-M17 -> -1698.8962 | Q17: 공헌이익 | R17: 수도권 | S17: =+[4]수도권!$Q$90 -> 18721.061 | T17: =+[4]수도권!$R$90 -> 17293.722 | U17: =+T17-S17 -> -1427.3391 | V17: =+[5]수도권!$Q$90 -> 16471.138 | W17: =+T17-V17 -> 822.58438
D18: 골재 | E18: =+E10-E14 -> 1.3930446 | F18: =+F10-F14 -> -56.254548 | G18: =+F18-E18 -> -57.647593 | H18: =+H10-H14 -> 60.667594 | I18: =+F18-H18 -> -116.92214 | J18: =+J10-J14 -> -78.487669 | K18: =+K10-K14 -> -393.45582 | L18: =+K18-J18 -> -314.96815 | M18: =+M10-M14 -> -199.68582 | N18: =+K18-M18 -> -193.76999 | R18: 영남권 | S18: =+[4]영남권!$Q$90 -> 23752.07 | T18: =+[4]영남권!$R$90 -> 21307.012 | U18: =+T18-S18 -> -2445.0583 | V18: =+[5]영남권!$Q$90 -> 19421.045 | W18: =+T18-V18 -> 1885.9665
D19: 기타 | E19: =+E11-E15 -> 65.020374 | F19: =+F11-F15 -> 35.456775 | G19: =+F19-E19 -> -29.563599 | H19: =+H11-H15 -> 100.32313 | I19: =+F19-H19 -> -64.866351 | J19: =+J11-J15 -> 769.53618 | K19: =+K11-K15 -> 872.97936 | L19: =+K19-J19 -> 103.44318 | M19: =+M11-M15 -> 287.42234 | N19: =+K19-M19 -> 585.55702 | R19: 중부권 | S19: =+[4]중부권!$Q$90 -> 26509.57 | T19: =+[4]중부권!$R$90 -> 24275.881 | U19: =+T19-S19 -> -2233.6892 | V19: =+[5]중부권!$Q$90 -> 22337.894 | W19: =+T19-V19 -> 1937.987
C20: 계 | E20: =SUM(E17:E19) -> 3590.5106 | F20: =SUM(F17:F19) -> 2024.8029 | G20: =+F20-E20 -> -1565.7077 | H20: =SUM(H17:H19) -> 2372.088 | I20: =+F20-H20 -> -347.28506 | J20: =SUM(J17:J19) -> 11945.951 | K20: =SUM(K17:K19) -> 8487.0727 | L20: =+K20-J20 -> -3458.8781 | M20: =SUM(M17:M19) -> 9794.1819 | N20: =+K20-M20 -> -1307.1092 | Q20: 계 | S20: =+[4]합계!$Q$90 -> 22285.789 | T20: =+[4]합계!$R$90 -> 20204.136 | U20: =+T20-S20 -> -2081.6534 | V20: =+[5]합계!$Q$90 -> 18989.722 | W20: =+T20-V20 -> 1214.4136
C21: 판관비 | D21: 레미콘 | E21: =+('[1]5월'!$Z$13+'[1]5월'!$Z$20+'[1]5월'!$Z$22)/1000 -> 2013.7341 | F21: =+('[2]5월'!$Z$13+'[2]5월'!$Z$20+'[2]5월'!$Z$22)/1000 -> 2009.5698 | G21: =+F21-E21 -> -4.1642686 | H21: =+('[3]5월'!$Z$13+'[3]5월'!$Z$20+'[3]5월'!$Z$22)/1000 -> 2062.5888 | I21: =+F21-H21 -> -53.018992 | J21: =+('[1]5월누계'!$Z$13+'[1]5월누계'!$Z$20+'[1]5월누계'!$Z$22)/1000 -> 10788.35 | K21: =+('[2]5월누계'!$Z$13+'[2]5월누계'!$Z$20+'[2]5월누계'!$Z$22)/1000 -> 11054.254 | L21: =+K21-J21 -> 265.90362 | M21: =+('[3]5월누계'!$Z$13+'[3]5월누계'!$Z$20+'[3]5월누계'!$Z$22)/1000 -> 10642.001 | N21: =+K21-M21 -> 412.25208 | Q21: □ 골재
D22: 골재 | E22: =+('[1]5월'!$AE$13+'[1]5월'!$AE$20+'[1]5월'!$AE$22)/1000 -> 49.762296 | F22: =+('[2]5월'!$AN$13+'[2]5월'!$AN$20+'[2]5월'!$AN$22)/1000 -> 48.745048 | G22: =+F22-E22 -> -1.0172477 | H22: =+('[3]5월'!$AN$13+'[3]5월'!$AN$20+'[3]5월'!$AN$22)/1000 -> 47.21642 | I22: =+F22-H22 -> 1.5286279 | J22: =+('[1]5월누계'!$AE$13+'[1]5월누계'!$AE$20+'[1]5월누계'!$AE$22)/1000 -> 252.15726 | K22: =+('[2]5월누계'!$AN$13+'[2]5월누계'!$AN$20+'[2]5월누계'!$AN$22)/1000 -> 253.7371 | L22: =+K22-J22 -> 1.5798353 | M22: =+('[3]5월누계'!$AN$13+'[3]5월누계'!$AN$20+'[3]5월누계'!$AN$22)/1000 -> 234.60151 | N22: =+K22-M22 -> 19.135592 | Q22: 구분 | S22: 계획 | T22: 실적 | U22: 계획대비 | V22: 전년 | W22: 전년대비
D23: 기타 | E23: =+('[1]5월'!$AL$13+'[1]5월'!$AV$13+'[1]5월'!$AL$20+'[1]5월'!$AV$20+'[1]5월'!$AL$22+'[1]5월'!$AV$22)/1000 -> 81.055169 | F23: =+('[2]5월'!$F$13+'[2]5월'!$F$20+'[2]5월'!$F$22)/1000-F21-F22-('[2]5월'!$AO$13+'[2]5월'!$AO$20+'[2]5월'!$AO$22)/1000 -> 63.591677 | G23: =+F23-E23 -> -17.463492 | H23: =+('[3]5월'!$F$13+'[3]5월'!$F$20+'[3]5월'!$F$22)/1000-H21-H22-('[3]5월'!$AO$13+'[3]5월'!$AO$20+'[3]5월'!$AO$22)/1000 -> 63.464139 | I23: =+F23-H23 -> 0.127538 | J23: =+('[1]5월누계'!$AL$13+'[1]5월누계'!$AV$13+'[1]5월누계'!$AL$20+'[1]5월누계'!$AV$20+'[1]5월누계'!$AL$22+'[1]5월누계'!$AV$22)/1000 -> 319.25734 | K23: =+('[2]5월누계'!$F$13+'[2]5월누계'!$F$20+'[2]5월누계'!$F$22)/1000-K21-K22-('[2]5월누계'!$AO$13+'[2]5월누계'!$AO$20+'[2]5월누계'!$AO$22)/1000 -> 73.683921 | L23: =+K23-J23 -> -245.57342 | M23: =+('[3]5월누계'!$F$13+'[3]5월누계'!$F$20+'[3]5월누계'!$F$22)/1000-M21-M22-('[3]5월누계'!$AO$13+'[3]5월누계'!$AO$20+'[3]5월누계'!$AO$22)/1000 -> 1213.9717 | N23: =+K23-M23 -> -1140.2877 | Q23: 판매량 | R23: 자가 | S23: =+[6]원가손익!$W$10+[7]원가손익!$U$27+[8]손익!$F$10 -> 45427.167 | T23: =+[6]원가손익!$X$10+[7]원가손익!$V$27+[8]손익!$G$10 -> 31626 | U23: =+T23-S23 -> -13801.167 | V23: =+[9]원가손익!$X$10+[10]원가손익!$V$27+[11]손익!$Y$25 -> 43506 | W23: =+T23-V23 -> -11880
C24: 계 | E24: =SUM(E21:E23) -> 2144.5516 | F24: =SUM(F21:F23) -> 2121.9066 | G24: =+F24-E24 -> -22.645008 | H24: =SUM(H21:H23) -> 2173.2694 | I24: =+F24-H24 -> -51.362826 | J24: =SUM(J21:J23) -> 11359.765 | K24: =SUM(K21:K23) -> 11381.675 | L24: =+K24-J24 -> 21.910036 | M24: =SUM(M21:M23) -> 12090.575 | N24: =+K24-M24 -> -708.90006 | R24: 외판 | S24: =+[6]원가손익!$W$14+[7]원가손익!$U$29+[8]손익!$F$12 -> 28160 | T24: =+[6]원가손익!$X$14+[7]원가손익!$V$29+[8]손익!$G$12 -> 20952 | U24: =+T24-S24 -> -7208 | V24: =+[9]원가손익!$X$14+[10]원가손익!$V$29+[11]손익!$Y$27 -> 26183 | W24: =+T24-V24 -> -5231
C25: 영업이익 | D25: 레미콘 | E25: =+E17-E21 -> 1510.3631 | F25: =+F17-F21 -> 36.030836 | G25: =+F25-E25 -> -1474.3323 | H25: =+H17-H21 -> 148.50841 | I25: =+F25-H25 -> -112.47758 | J25: =+J17-J21 -> 466.5524 | K25: =+K17-K21 -> -3046.7044 | L25: =+K25-J25 -> -3513.2568 | M25: =+M17-M21 -> -935.55613 | N25: =+K25-M25 -> -2111.1483 | Q25: 합 계 | S25: =SUM(S23:S24) -> 73587.167 | T25: =SUM(T23:T24) -> 52578 | U25: =+T25-S25 -> -21009.167 | V25: =SUM(V23:V24) -> 69689 | W25: =+T25-V25 -> -17111
D26: % | E26: =+E25/E9 -> 0.055149465 | F26: =+F25/F9 -> 0.0016097836 | G26: =+F26-E26 -> -0.053539681 | H26: =+H25/H9 -> 0.0062398682 | I26: =+F26-H26 -> -0.0046300846 | J26: =+J25/J9 -> 0.0039434388 | K26: =+K25/K9 -> -0.027468118 | L26: =+K26-J26 -> -0.031411557 | M26: =+M25/M9 -> -0.008069418 | N26: =+K26-M26 -> -0.0193987 | Q26: □ 기타내역(영업이익)
D27: 골재 | E27: =+E18-E22 -> -48.369251 | F27: =+F18-F22 -> -104.9996 | G27: =+F27-E27 -> -56.630345 | H27: =+H18-H22 -> 13.451174 | I27: =+F27-H27 -> -118.45077 | J27: =+J18-J22 -> -330.64493 | K27: =+K18-K22 -> -647.19291 | L27: =+K27-J27 -> -316.54798 | M27: =+M18-M22 -> -434.28733 | N27: =+K27-M27 -> -212.90558 | Q27: 구분 | S27: 계획 | T27: 실적 | U27: 계획대비 | V27: 전년 | W27: 전년대비
D28: 기타 | E28: =+E19-E23 -> -16.034795 | F28: =+F19-F23 -> -28.134902 | G28: =+F28-E28 -> -12.100107 | H28: =+H19-H23 -> 36.858987 | I28: =+F28-H28 -> -64.993889 | J28: =+J19-J23 -> 450.27884 | K28: =+K19-K23 -> 799.29544 | L28: =+K28-J28 -> 349.0166 | M28: =+M19-M23 -> -926.54931 | N28: =+K28-M28 -> 1725.8447 | Q28: 레미콘임대 | S28: =+'사업장별(당월)'!T32 -> 25.462031 | T28: =+'사업장별(당월)'!U32 -> 16.302811 | U28: =+T28-S28 -> -9.15922 | V28: =+'사업장별(당월)'!W32 -> 23.178219 | W28: =+T28-V28 -> -6.875408
C29: 계 | E29: =+E25+E27+E28 -> 1445.9591 | F29: =+F25+F27+F28 -> -97.103662 | G29: =+F29-E29 -> -1543.0627 | H29: =+H25+H27+H28 -> 198.81858 | I29: =+F29-H29 -> -295.92224 | J29: =+J25+J27+J28 -> 586.1863 | K29: =+K25+K27+K28 -> -2894.6019 | L29: =+K29-J29 -> -3480.7882 | M29: =+M25+M27+M28 -> -2296.3928 | N29: =+K29-M29 -> -598.2091 | Q29: 임대 | S29: =+'사업장별(당월)'!T33 -> 72.847673 | T29: =+'사업장별(당월)'!U33 -> 4.091001 | U29: =+T29-S29 -> -68.756672 | V29: =+'사업장별(당월)'!W33 -> 66.602381 | W29: =+T29-V29 -> -62.51138
D30: % | E30: =+E29/E12 -> 0.05013811 | F30: =+F29/F12 -> -0.0041054215 | G30: =+F30-E30 -> -0.054243532 | H30: =+H29/H12 -> 0.0078317139 | I30: =+F30-H30 -> -0.011937135 | J30: =+J29/J12 -> 0.0046827052 | K30: =+K29/K12 -> -0.024627398 | L30: =+K30-J30 -> -0.029310103 | M30: =+M29/M12 -> -0.018648173 | N30: =+K30-M30 -> -0.0059792252 | Q30: 공통비 | S30: =+'사업장별(당월)'!T34 -> -1350.3536 | T30: =+'사업장별(당월)'!U34 -> -1314.2615 | U30: =+T30-S30 -> 36.092108 | V30: =+'사업장별(당월)'!W34 -> -1405.8047 | W30: =+T30-V30 -> 91.543206
C31: * 건자재 | Q31: 기타 | S31: =+S32-S28-S29-S30 -> -114.3445 | T31: =+T32-T28-T29-T30 -> -48.528714 | U31: =+T31-S31 -> 65.815785 | V31: =+V32-V28-V29-V30 -> -52.921613 | W31: =+T31-V31 -> 4.392899
C32: 물량 | E32: =+IFERROR(HLOOKUP($E$5,[12]손익!$G$5:$AI$54,2,),) -> 8100 | F32: =+'[2]5월'!$AO$7 -> 3740.231 | G32: =+F32-E32 -> -4359.769 | H32: =+'[3]5월'!$AO$7 -> 10256.286 | I32: =+F32-H32 -> -6516.055 | J32: =+'[1]5월누계'!$AA$7 -> 41000 | K32: =+'[2]5월누계'!$AO$7 -> 21045.185 | L32: =+K32-J32 -> -19954.815 | M32: =+'[3]5월누계'!$AO$7 -> 55602.746 | N32: =+K32-M32 -> -34557.561 | Q32: 합계 | S32: =+'사업장별(당월)'!T40 -> -1366.3884 | T32: =+'사업장별(당월)'!U40 -> -1342.3964 | U32: =+T32-S32 -> 23.992001 | V32: =+'사업장별(당월)'!W40 -> -1368.9457 | W32: =+T32-V32 -> 26.549317
C33: 매출 | E33: =+IFERROR(HLOOKUP($E$5,[12]손익!$G$5:$AI$54,3,),)/1000 -> 8182.096 | F33: =+'[2]5월'!$AO$8/1000 -> 4514.2479 | G33: =+F33-E33 -> -3667.8481 | H33: =+'[3]5월'!$AO$8/1000 -> 10025.106 | I33: =+F33-H33 -> -5510.8577 | J33: =+'[1]5월누계'!$AA$8/1000 -> 40039.457 | K33: =+'[2]5월누계'!$AO$8/1000 -> 22521.33 | L33: =+K33-J33 -> -17518.128 | M33: =+'[3]5월누계'!$AO$8/1000 -> 48464.953 | N33: =+K33-M33 -> -25943.624
C34: 매출이익 | E34: =+IFERROR(HLOOKUP($E$5,[12]손익!$G$5:$AI$54,7,),)/1000 -> 221.87149 | F34: =+'[2]5월'!$AO$12/1000 -> -8.702381 | G34: =+F34-E34 -> -230.57387 | H34: =+'[3]5월'!$AO$12/1000 -> 183.69473 | I34: =+F34-H34 -> -192.39711 | J34: =+'[1]5월누계'!$AA$12/1000 -> 927.55483 | K34: =+'[2]5월누계'!$AO$12/1000 -> 436.48128 | L34: =+K34-J34 -> -491.07354 | M34: =+'[3]5월누계'!$AO$12/1000 -> 683.85469 | N34: =+K34-M34 -> -247.3734 | Q34: □ 건자재
C35: (%) | E35: =+E34/E33 -> 0.027116706 | F35: =+F34/F33 -> -0.0019277588 | G35: =+F35-E35 -> -0.029044465 | H35: =+H34/H33 -> 0.018323471 | I35: =+I34/I33 -> 0.034912371 | J35: =+J34/J33 -> 0.023166019 | K35: =+K34/K33 -> 0.019380795 | L35: =+K35-J35 -> -0.0037852235 | M35: =+M34/M33 -> 0.014110293 | N35: =+K35-M35 -> 0.0052705024 | Q35: 구분 | S35: 계획 | T35: 실적 | U35: 계획대비 | V35: 전년 | W35: 전년대비
C36: 영업이익 | E36: =+IFERROR(HLOOKUP($E$5,[12]손익!$G$5:$AI$54,20,),)/1000 -> 43.605066 | F36: =+'[2]5월'!$AO$26/1000 -> -207.8716 | G36: =+F36-E36 -> -251.47666 | H36: =+'[3]5월'!$AO$26/1000 -> 46.262732 | I36: =+F36-H36 -> -254.13433 | J36: =+'[1]5월누계'!$AA$26/1000 -> -39.796673 | K36: =+'[2]5월누계'!$AO$26/1000 -> -381.18587 | L36: =+K36-J36 -> -341.3892 | M36: =+'[3]5월누계'!$AO$26/1000 -> -60.3202 | N36: =+K36-M36 -> -320.86567 | Q36: 철강재 판매단가 | S36: =+'[13]5월'!$F$10 -> 784722.22 | T36: =+'[13]5월'!$G$10 -> 873685.86 | U36: =+T36-S36 -> 88963.643 | V36: =+'[14]5월'!$G$10 -> 798001.53 | W36: =+T36-V36 -> 75684.339
C37: (%) | E37: =+E36/E33 -> 0.0053293271 | F37: =+F36/F33 -> -0.046047891 | G37: =+F37-E37 -> -0.051377218 | H37: =+H36/H33 -> 0.0046146877 | I37: =+F37-H37 -> -0.050662579 | J37: =+J36/J33 -> -0.00099393636 | K37: =+K36/K33 -> -0.016925549 | L37: =+K37-J37 -> -0.015931613 | M37: =+M36/M33 -> -0.0012446148 | N37: =+K37-M37 -> -0.015680934 | Q37: 철강재 마진률 | S37: =+'[13]5월'!$F$15 -> 0.023362832 | T37: =+'[13]5월'!$G$15 -> -0.010994486 | U37: =+T37-S37 -> -0.034357318 | V37: =+'[14]5월'!$G$15 -> 0.016605664 | W37: =+T37-V37 -> -0.02760015
E39: =+'[1]5월'!$E$26/1000 -> 1489.5641 | F39: =+'[2]5월'!$F$26/1000 -> -304.97526 | H39: =+'[3]5월'!$F$26/1000 -> 245.08131 | J39: =+'[1]5월누계'!$E$26/1000 -> 546.38963 | K39: =+'[2]5월누계'!$F$26/1000 -> -3275.7877 | M39: =+'[3]5월누계'!$F$26/1000 -> -2356.713
E40: =+(E29+E36)-E39 -> -4.7748472e-12 | F40: =+(F29+F36)-F39 -> 2.6716407e-12 | H40: =+(H29+H36)-H39 -> 1.5347723e-12 | J40: =+(J29+J36)-J39 -> 5.1159077e-12 | K40: =+(K29+K36)-K39 -> -2.4556357e-11 | M40: =+(M29+M36)-M39 -> 5.0022209e-12

Sheet 레미콘 영업이익
H3: □ 레미콘 영업이익(5월)
H5: 구분 | J5: 5월 | T5: 5월누계
J6: 영업이익(공통비 배부전) | O6: 영업이익(공통비 배부후) | T6: 영업이익(공통비 배부전) | Y6: 영업이익(공통비 배부전)
A7: 2024년 1월 마감 손익 | J7: 계획 | K7: 실적 | L7: 차이 | M7: 전년 | N7: 차이 | O7: 계획 | P7: 실적 | Q7: 차이 | R7: 전년 | S7: 차이 | T7: 계획 | U7: 실적 | V7: 차이 | W7: 전년 | X7: 차이 | Y7: 계획 | Z7: 실적 | AA7: 차이 | AB7: 전년 | AC7: 차이
B8: 안양 | H8: 레미콘 | I8: 안양 | J8: =+[4]안양!$H$86/1000 -> 434.05383 | K8: =+[4]안양!$I$86/1000 -> 439.64523 | L8: =+K8-J8 -> 5.591403 | M8: =+[5]안양!$H$86/1000 -> 242.51179 | N8: =+K8-M8 -> 197.13344 | O8: =+[4]안양!$H$92/1000 -> 259.8237 | P8: =+[4]안양!$I$92/1000 -> 239.02927 | Q8: =+P8-O8 -> -20.794434 | R8: =+[5]안양!$H$92/1000 -> 70.007907 | S8: =+P8-R8 -> 169.02136 | T8: =+[15]안양!$H$86/1000 -> 1612.0411 | U8: =+[15]안양!$I$86/1000 -> 1569.8666 | V8: =+U8-T8 -> -42.174538 | W8: =+[16]안양!$H$86/1000 -> 1107.7854 | X8: =+U8-W8 -> 462.08115 | Y8: =+[15]안양!$H$92/1000 -> 574.57742 | Z8: =+[15]안양!$I$92/1000 -> 368.56865 | AA8: =+Z8-Y8 -> -206.00878 | AB8: =+[16]안양!$H$92/1000 -> 88.083271 | AC8: =+Z8-AB8 -> 280.48538
B9: 인천 | H9: 직영 | I9: 인천 | J9: =+[4]인천!$H$86/1000 -> 296.46875 | K9: =+[4]인천!$I$86/1000 -> 49.957465 | L9: =+K9-J9 -> -246.51129 | M9: =+[5]인천!$H$86/1000 -> 160.60507 | N9: =+K9-M9 -> -110.6476 | O9: =+[4]인천!$H$92/1000 -> 128.89484 | P9: =+[4]인천!$I$92/1000 -> -115.82282 | Q9: =+P9-O9 -> -244.71766 | R9: =+[5]인천!$H$92/1000 -> -22.039388 | S9: =+P9-R9 -> -93.783431 | T9: =+[15]인천!$H$86/1000 -> 755.04966 | U9: =+[15]인천!$I$86/1000 -> 97.222469 | V9: =+U9-T9 -> -657.82719 | W9: =+[16]인천!$H$86/1000 -> 304.48832 | X9: =+U9-W9 -> -207.26585 | Y9: =+[15]인천!$H$92/1000 -> -169.54075 | Z9: =+[15]인천!$I$92/1000 -> -821.43444 | AA9: =+Z9-Y9 -> -651.89369 | AB9: =+[16]인천!$H$92/1000 -> -499.50165 | AC9: =+Z9-AB9 -> -321.93279
B10: 파주 | I10: 파주 | J10: =+[4]파주!$H$86/1000 -> 101.7489 | K10: =+[4]파주!$I$86/1000 -> 48.322042 | L10: =+K10-J10 -> -53.426855 | M10: =+[5]파주!$H$86/1000 -> -28.835518 | N10: =+K10-M10 -> 77.15756 | O10: =+[4]파주!$H$92/1000 -> 16.664439 | P10: =+[4]파주!$I$92/1000 -> -30.096654 | Q10: =+P10-O10 -> -46.761092 | R10: =+[5]파주!$H$92/1000 -> -89.797556 | S10: =+P10-R10 -> 59.700902 | T10: =+[15]파주!$H$86/1000 -> -12.101275 | U10: =+[15]파주!$I$86/1000 -> -166.68608 | V10: =+U10-T10 -> -154.58481 | W10: =+[16]파주!$H$86/1000 -> -341.58587 | X10: =+U10-W10 -> 174.89979 | Y10: =+[15]파주!$H$92/1000 -> -410.16055 | Z10: =+[15]파주!$I$92/1000 -> -553.9487 | AA10: =+Z10-Y10 -> -143.78815 | AB10: =+[16]파주!$H$92/1000 -> -655.06454 | AC10: =+Z10-AB10 -> 101.11585
B11: 김포 | I11: 김포 | J11: =+[4]김포!$H$86/1000 -> 101.76019 | K11: =+[4]김포!$I$86/1000 -> 64.671647 | L11: =+K11-J11 -> -37.088538 | M11: =+[5]김포!$H$86/1000 -> 30.961596 | N11: =+K11-M11 -> 33.710051 | O11: =+[4]김포!$H$92/1000 -> 32.792297 | P11: =+[4]김포!$I$92/1000 -> -20.227199 | Q11: =+P11-O11 -> -53.019496 | R11: =+[5]김포!$H$92/1000 -> -29.130571 | S11: =+P11-R11 -> 8.9033719 | T11: =+[15]김포!$H$86/1000 -> 136.8347 | U11: =+[15]김포!$I$86/1000 -> -28.49261 | V11: =+U11-T11 -> -165.32731 | W11: =+[16]김포!$H$86/1000 -> -19.549578 | X11: =+U11-W11 -> -8.943032 | Y11: =+[15]김포!$H$92/1000 -> -207.86931 | Z11: =+[15]김포!$I$92/1000 -> -407.98936 | AA11: =+Z11-Y11 -> -200.12005 | AB11: =+[16]김포!$H$92/1000 -> -293.9011 | AC11: =+Z11-AB11 -> -114.08826
B12: 부산 | I12: 부산 | J12: =+[4]부산!$H$86/1000 -> 211.20211 | K12: =+[4]부산!$I$86/1000 -> 92.754418 | L12: =+K12-J12 -> -118.44769 | M12: =+[5]부산!$H$86/1000 -> 308.13145 | N12: =+K12-M12 -> -215.37703 | O12: =+[4]부산!$H$92/1000 -> 101.70947 | P12: =+[4]부산!$I$92/1000 -> -0.62538272 | Q12: =+P12-O12 -> -102.33486 | R12: =+[5]부산!$H$92/1000 -> 168.40765 | S12: =+P12-R12 -> -169.03303 | T12: =+[15]부산!$H$86/1000 -> 853.5649 | U12: =+[15]부산!$I$86/1000 -> 1096.3584 | V12: =+U12-T12 -> 242.79351 | W12: =+[16]부산!$H$86/1000 -> 984.20983 | X12: =+U12-W12 -> 112.14858 | Y12: =+[15]부산!$H$92/1000 -> 184.00328 | Z12: =+[15]부산!$I$92/1000 -> 276.09195 | AA12: =+Z12-Y12 -> 92.088672 | AB12: =+[16]부산!$H$92/1000 -> 326.88042 | AC12: =+Z12-AB12 -> -50.788469
B13: 서부산 | I13: 서부산 | J13: =+[4]서부산!$H$86/1000 -> 317.8487 | K13: =+[4]서부산!$I$86/1000 -> 220.01484 | L13: =+K13-J13 -> -97.833859 | M13: =+[5]서부산!$H$86/1000 -> 89.008721 | N13: =+K13-M13 -> 131.00612 | O13: =+[4]서부산!$H$92/1000 -> 211.66803 | P13: =+[4]서부산!$I$92/1000 -> 94.690921 | Q13: =+P13-O13 -> -116.97711 | R13: =+[5]서부산!$H$92/1000 -> -11.917371 | S13: =+P13-R13 -> 106.60829 | T13: =+[15]서부산!$H$86/1000 -> 1228.277 | U13: =+[15]서부산!$I$86/1000 -> 774.01666 | V13: =+U13-T13 -> -454.26032 | W13: =+[16]서부산!$H$86/1000 -> 503.89407 | X13: =+U13-W13 -> 270.12259 | Y13: =+[15]서부산!$H$92/1000 -> 590.79351 | Z13: =+[15]서부산!$I$92/1000 -> 138.28183 | AA13: =+Z13-Y13 -> -452.51168 | AB13: =+[16]서부산!$H$92/1000 -> -26.581075 | AC13: =+Z13-AB13 -> 164.86291
B14: 김해 | I14: 김해 | J14: =+[4]김해!$H$86/1000 -> 84.549448 | K14: =+[4]김해!$I$86/1000 -> -21.796408 | L14: =+K14-J14 -> -106.34586 | M14: =+[5]김해!$H$86/1000 -> -70.922998 | N14: =+K14-M14 -> 49.12659 | O14: =+[4]김해!$H$92/1000 -> 32.85124 | P14: =+[4]김해!$I$92/1000 -> -54.403769 | Q14: =+P14-O14 -> -87.255009 | R14: =+[5]김해!$H$92/1000 -> -113.42006 | S14: =+P14-R14 -> 59.016292 | T14: =+[15]김해!$H$86/1000 -> 158.77152 | U14: =+[15]김해!$I$86/1000 -> -147.49573 | V14: =+U14-T14 -> -306.26725 | W14: =+[16]김해!$H$86/1000 -> -176.44743 | X14: =+U14-W14 -> 28.951698 | Y14: =+[15]김해!$H$92/1000 -> -115.60323 | Z14: =+[15]김해!$I$92/1000 -> -348.16615 | AA14: =+Z14-Y14 -> -232.56291 | AB14: =+[16]김해!$H$92/1000 -> -418.87468 | AC14: =+Z14-AB14 -> 70.708534
B15: 정관 | I15: 정관 | J15: =+[4]정관!$H$86/1000 -> 323.96239 | K15: =+[4]정관!$I$86/1000 -> 92.285135 | L15: =+K15-J15 -> -231.67725 | M15: =+[5]정관!$H$86/1000 -> 201.7835 | N15: =+K15-M15 -> -109.49837 | O15: =+[4]정관!$H$92/1000 -> 204.82019 | P15: =+[4]정관!$I$92/1000 -> -3.1200101 | Q15: =+P15-O15 -> -207.9402 | R15: =+[5]정관!$H$92/1000 -> 64.179564 | S15: =+P15-R15 -> -67.299574 | T15: =+[15]정관!$H$86/1000 -> 1023.5417 | U15: =+[15]정관!$I$86/1000 -> 208.45939 | V15: =+U15-T15 -> -815.08232 | W15: =+[16]정관!$H$86/1000 -> 848.94541 | X15: =+U15-W15 -> -640.48602 | Y15: =+[15]정관!$H$92/1000 -> 332.5507 | Z15: =+[15]정관!$I$92/1000 -> -279.846 | AA15: =+Z15-Y15 -> -612.3967 | AB15: =+[16]정관!$H$92/1000 -> 179.11156 | AC15: =+Z15-AB15 -> -458.95756
B16: 양산 | I16: 양산 | J16: =+[4]양산!$H$86/1000 -> 114.96988 | K16: =+[4]양산!$I$86/1000 -> -39.795293 | L16: =+K16-J16 -> -154.76518 | M16: =+[5]양산!$H$86/1000 -> 38.252911 | N16: =+K16-M16 -> -78.048204 | O16: =+[4]양산!$H$92/1000 -> 63.242665 | P16: =+[4]양산!$I$92/1000 -> -63.319553 | Q16: =+P16-O16 -> -126.56222 | R16: =+[5]양산!$H$92/1000 -> -9.5836434 | S16: =+P16-R16 -> -53.735909 | T16: =+[15]양산!$H$86/1000 -> 218.36063 | U16: =+[15]양산!$I$86/1000 -> -105.25103 | V16: =+U16-T16 -> -323.61167 | W16: =+[16]양산!$H$86/1000 -> 59.189078 | X16: =+U16-W16 -> -164.44011 | Y16: =+[15]양산!$H$92/1000 -> -39.221665 | Z16: =+[15]양산!$I$92/1000 -> -276.34353 | AA16: =+Z16-Y16 -> -237.12186 | AB16: =+[16]양산!$H$92/1000 -> -173.77892 | AC16: =+Z16-AB16 -> -102.5646
B17: 창원 | I17: 창원 | J17: =+[4]창원!$H$86/1000 -> 126.87661 | K17: =+[4]창원!$I$86/1000 -> 65.208746 | L17: =+K17-J17 -> -61.667864 | M17: =+[5]창원!$H$86/1000 -> 24.863254 | N17: =+K17-M17 -> 40.345492 | O17: =+[4]창원!$H$92/1000 -> 56.83218 | P17: =+[4]창원!$I$92/1000 -> -2.0351861 | Q17: =+P17-O17 -> -58.867366 | R17: =+[5]창원!$H$92/1000 -> -27.544133 | S17: =+P17-R17 -> 25.508946 | T17: =+[15]창원!$H$86/1000 -> 237.39573 | U17: =+[15]창원!$I$86/1000 -> 147.23081 | V17: =+U17-T17 -> -90.164921 | W17: =+[16]창원!$H$86/1000 -> 356.99214 | X17: =+U17-W17 -> -209.76133 | Y17: =+[15]창원!$H$92/1000 -> -111.67636 | Z17: =+[15]창원!$I$92/1000 -> -187.22118 | AA17: =+Z17-Y17 -> -75.544828 | AB17: =+[16]창원!$H$92/1000 -> 18.886943 | AC17: =+Z17-AB17 -> -206.10813
B18: 대구 | I18: 대구 | J18: =+[4]대구!$H$86/1000 -> 50.762107 | K18: =+[4]대구!$I$86/1000 -> -72.116301 | L18: =+K18-J18 -> -122.87841 | M18: =+[5]대구!$H$86/1000 -> -22.058378 | N18: =+K18-M18 -> -50.057923 | O18: =+[4]대구!$H$92/1000 -> 8.6725371 | P18: =+[4]대구!$I$92/1000 -> -95.045913 | Q18: =+P18-O18 -> -103.71845 | R18: =+[5]대구!$H$92/1000 -> -65.675422 | S18: =+P18-R18 -> -29.370491 | T18: =+[15]대구!$H$86/1000 -> -34.80434 | U18: =+[15]대구!$I$86/1000 -> -440.33887 | V18: =+U18-T18 -> -405.53453 | W18: =+[16]대구!$H$86/1000 -> 39.110662 | X18: =+U18-W18 -> -479.44954 | Y18: =+[15]대구!$H$92/1000 -> -259.00865 | Z18: =+[15]대구!$I$92/1000 -> -565.81824 | AA18: =+Z18-Y18 -> -306.80959 | AB18: =+[16]대구!$H$92/1000 -> -265.49719 | AC18: =+Z18-AB18 -> -300.32105
B19: 울산 | I19: 울산 | J19: =+[4]울산!$H$86/1000 -> 103.28835 | K19: =+[4]울산!$I$86/1000 -> 29.061433 | L19: =+K19-J19 -> -74.226915 | M19: =+[5]울산!$H$86/1000 -> 111.42436 | N19: =+K19-M19 -> -82.362923 | O19: =+[4]울산!$H$92/1000 -> 40.029557 | P19: =+[4]울산!$I$92/1000 -> -36.259659 | Q19: =+P19-O19 -> -76.289216 | R19: =+[5]울산!$H$92/1000 -> 38.720381 | S19: =+P19-R19 -> -74.98004 | T19: =+[15]울산!$H$86/1000 -> 152.50539 | U19: =+[15]울산!$I$86/1000 -> 334.07673 | V19: =+U19-T19 -> 181.57134 | W19: =+[16]울산!$H$86/1000 -> 530.68058 | X19: =+U19-W19 -> -196.60385 | Y19: =+[15]울산!$H$92/1000 -> -163.16553 | Z19: =+[15]울산!$I$92/1000 -> -90.662664 | AA19: =+Z19-Y19 -> 72.502864 | AB19: =+[16]울산!$H$92/1000 -> 143.54074 | AC19: =+Z19-AB19 -> -234.2034
B20: 아산 | I20: 아산 | J20: =+[4]아산!$H$86/1000 -> 213.00416 | K20: =+[4]아산!$I$86/1000 -> 122.41643 | L20: =+K20-J20 -> -90.587731 | M20: =+[5]아산!$H$86/1000 -> 136.46828 | N20: =+K20-M20 -> -14.051854 | O20: =+[4]아산!$H$92/1000 -> 108.75409 | P20: =+[4]아산!$I$92/1000 -> 14.795907 | Q20: =+P20-O20 -> -93.958187 | R20: =+[5]아산!$H$92/1000 -> 10.536863 | S20: =+P20-R20 -> 4.259044 | T20: =+[15]아산!$H$86/1000 -> 402.96918 | U20: =+[15]아산!$I$86/1000 -> 320.02433 | V20: =+U20-T20 -> -82.944851 | W20: =+[16]아산!$H$86/1000 -> 494.22789 | X20: =+U20-W20 -> -174.20356 | Y20: =+[15]아산!$H$92/1000 -> -93.776837 | Z20: =+[15]아산!$I$92/1000 -> -313.2002 | AA20: =+Z20-Y20 -> -219.42337 | AB20: =+[16]아산!$H$92/1000 -> -139.71348 | AC20: =+Z20-AB20 -> -173.48672
B21: 전주 | I21: 전주 | J21: =+[4]전주!$H$86/1000 -> 162.0915 | K21: =+[4]전주!$I$86/1000 -> 21.521379 | L21: =+K21-J21 -> -140.57012 | M21: =+[5]전주!$H$86/1000 -> 165.00719 | N21: =+K21-M21 -> -143.48581 | O21: =+[4]전주!$H$92/1000 -> 103.00044 | P21: =+[4]전주!$I$92/1000 -> -36.406364 | Q21: =+P21-O21 -> -139.4068 | R21: =+[5]전주!$H$92/1000 -> 87.442872 | S21: =+P21-R21 -> -123.84924 | T21: =+[15]전주!$H$86/1000 -> 283.94778 | U21: =+[15]전주!$I$86/1000 -> 130.07042 | V21: =+U21-T21 -> -153.87736 | W21: =+[16]전주!$H$86/1000 -> 851.34751 | X21: =+U21-W21 -> -721.27709 | Y21: =+[15]전주!$H$92/1000 -> 22.05097 | Z21: =+[15]전주!$I$92/1000 -> -198.06382 | AA21: =+Z21-Y21 -> -220.11479 | AB21: =+[16]전주!$H$92/1000 -> 409.08008 | AC21: =+Z21-AB21 -> -607.1439
B22: 군산 | I22: 군산 | J22: =+[4]군산!$H$86/1000 -> 106.87183 | K22: =+[4]군산!$I$86/1000 -> 44.935986 | L22: =+K22-J22 -> -61.935848 | M22: =+[5]군산!$H$86/1000 -> 130.46313 | N22: =+K22-M22 -> -85.527149 | O22: =+[4]군산!$H$92/1000 -> 79.998348 | P22: =+[4]군산!$I$92/1000 -> 20.455754 | Q22: =+P22-O22 -> -59.542594 | R22: =+[5]군산!$H$92/1000 -> 92.983562 | S22: =+P22-R22 -> -72.527808 | T22: =+[15]군산!$H$86/1000 -> 305.61097 | U22: =+[15]군산!$I$86/1000 -> 213.43138 | V22: =+U22-T22 -> -92.179592 | W22: =+[16]군산!$H$86/1000 -> 504.23734 | X22: =+U22-W22 -> -290.80596 | Y22: =+[15]군산!$H$92/1000 -> 176.20237 | Z22: =+[15]군산!$I$92/1000 -> 88.436705 | AA22: =+Z22-Y22 -> -87.76566 | AB22: =+[16]군산!$H$92/1000 -> 340.26988 | AC22: =+Z22-AB22 -> -251.83317
B23: 원주 | I23: 원주 | J23: =+[4]원주!$H$86/1000 -> 74.50264 | K23: =+[4]원주!$I$86/1000 -> 133.32987 | L23: =+K23-J23 -> 58.827227 | M23: =+[5]원주!$H$86/1000 -> -23.378171 | N23: =+K23-M23 -> 156.70804 | O23: =+[4]원주!$H$92/1000 -> 53.090145 | P23: =+[4]원주!$I$92/1000 -> 102.11788 | Q23: =+P23-O23 -> 49.02773 | R23: =+[5]원주!$H$92/1000 -> -33.976938 | S23: =+P23-R23 -> 136.09481 | T23: =+[15]원주!$H$86/1000 -> 251.57153 | U23: =+[15]원주!$I$86/1000 -> 312.66812 | V23: =+U23-T23 -> 61.096588 | W23: =+[16]원주!$H$86/1000 -> -85.33792 | X23: =+U23-W23 -> 398.00604 | Y23: =+[15]원주!$H$92/1000 -> 127.5835 | Z23: =+[15]원주!$I$92/1000 -> 188.77089 | AA23: =+Z23-Y23 -> 61.18739 | AB23: =+[16]원주!$H$92/1000 -> -155.00884 | AC23: =+Z23-AB23 -> 343.77973
B24: 제주 | I24: 제주 | J24: =+[4]제주!$H$86/1000 -> 36.75533 | K24: =+[4]제주!$I$86/1000 -> 59.875705 | L24: =+K24-J24 -> 23.120375 | M24: =+[5]제주!$H$86/1000 -> 60.026911 | N24: =+K24-M24 -> -0.151206 | O24: =+[4]제주!$H$92/1000 -> 7.5189482 | P24: =+[4]제주!$I$92/1000 -> 22.303622 | Q24: =+P24-O24 -> 14.784674 | R24: =+[5]제주!$H$92/1000 -> 19.314696 | S24: =+P24-R24 -> 2.9889259 | T24: =+[15]제주!$H$86/1000 -> 244.33061 | U24: =+[15]제주!$I$86/1000 -> 106.67891 | V24: =+U24-T24 -> -137.6517 | W24: =+[16]제주!$H$86/1000 -> 415.79217 | X24: =+U24-W24 -> -309.11326 | Y24: =+[15]제주!$H$92/1000 -> 28.813521 | Z24: =+[15]제주!$I$92/1000 -> -64.160133 | AA24: =+Z24-Y24 -> -92.973654 | AB24: =+[16]제주!$H$92/1000 -> 186.51247 | AC24: =+Z24-AB24 -> -250.6726
I25: 수도권 | J25: =SUM(J8:J11) -> 934.03166 | K25: =SUM(K8:K11) -> 602.59639 | L25: =+K25-J25 -> -331.43528 | M25: =SUM(M8:M11) -> 405.24294 | N25: =+K25-M25 -> 197.35345 | O25: =SUM(O8:O11) -> 438.17527 | P25: =SUM(P8:P11) -> 72.882594 | Q25: =+P25-O25 -> -365.29268 | R25: =SUM(R8:R11) -> -70.959608 | S25: =+P25-R25 -> 143.8422 | T25: =SUM(T8:T11) -> 2491.8242 | U25: =SUM(U8:U11) -> 1471.9103 | V25: =+U25-T25 -> -1019.9138 | W25: =SUM(W8:W11) -> 1051.1383 | X25: =+U25-W25 -> 420.77206 | Y25: =SUM(Y8:Y11) -> -212.99319 | Z25: =SUM(Z8:Z11) -> -1414.8038 | AA25: =+Z25-Y25 -> -1201.8107 | AB25: =SUM(AB8:AB11) -> -1360.384 | AC25: =+Z25-AB25 -> -54.419824
I26: 영남권 | J26: =SUM(J12:J19) -> 1333.4596 | K26: =SUM(K12:K19) -> 365.61657 | L26: =+K26-J26 -> -967.84302 | M26: =SUM(M12:M19) -> 680.48282 | N26: =+K26-M26 -> -314.86625 | O26: =SUM(O12:O19) -> 719.82588 | P26: =SUM(P12:P19) -> -160.11855 | Q26: =+P26-O26 -> -879.94443 | R26: =SUM(R12:R19) -> 43.166966 | S26: =+P26-R26 -> -203.28552 | T26: =SUM(T12:T19) -> 3837.6125 | U26: =SUM(U12:U19) -> 1867.0564 | V26: =+U26-T26 -> -1970.5562 | W26: =SUM(W12:W19) -> 3146.5743 | X26: =+U26-W26 -> -1279.518 | Y26: =SUM(Y12:Y19) -> 418.67207 | Z26: =SUM(Z12:Z19) -> -1333.684 | AA26: =+Z26-Y26 -> -1752.356 | AB26: =SUM(AB12:AB19) -> -216.31221 | AC26: =+Z26-AB26 -> -1117.3718
I27: 중부권 | J27: =SUM(J20:J24) -> 593.22546 | K27: =SUM(K20:K24) -> 382.07936 | L27: =+K27-J27 -> -211.1461 | M27: =SUM(M20:M24) -> 468.58735 | N27: =+K27-M27 -> -86.507984 | O27: =SUM(O20:O24) -> 352.36197 | P27: =SUM(P20:P24) -> 123.26679 | Q27: =+P27-O27 -> -229.09518 | R27: =SUM(R20:R24) -> 176.30106 | S27: =+P27-R27 -> -53.034261 | T27: =SUM(T20:T24) -> 1488.4301 | U27: =SUM(U20:U24) -> 1082.8732 | V27: =+U27-T27 -> -405.55692 | W27: =SUM(W20:W24) -> 2180.267 | X27: =+U27-W27 -> -1097.3938 | Y27: =SUM(Y20:Y24) -> 260.87352 | Z27: =SUM(Z20:Z24) -> -298.21656 | AA27: =+Z27-Y27 -> -559.09008 | AB27: =SUM(AB20:AB24) -> 641.14011 | AC27: =+Z27-AB27 -> -939.35667
H28: 레미콘 계 | J28: =SUM(J25:J27) -> 2860.7167 | K28: =SUM(K25:K27) -> 1350.2923 | L28: =+K28-J28 -> -1510.4244 | M28: =SUM(M25:M27) -> 1554.3131 | N28: =+K28-M28 -> -204.02078 | O28: =SUM(O25:O27) -> 1510.3631 | P28: =SUM(P25:P27) -> 36.030836 | Q28: =+P28-O28 -> -1474.3323 | R28: =SUM(R25:R27) -> 148.50841 | S28: =+P28-R28 -> -112.47758 | T28: =SUM(T25:T27) -> 7817.8668 | U28: =SUM(U25:U27) -> 4421.8399 | V28: =+U28-T28 -> -3396.0269 | W28: =SUM(W25:W27) -> 6377.9796 | X28: =+U28-W28 -> -1956.1397 | Y28: =SUM(Y25:Y27) -> 466.5524 | Z28: =SUM(Z25:Z27) -> -3046.7044 | AA28: =+Z28-Y28 -> -3513.2568 | AB28: =SUM(AB25:AB27) -> -935.55613 | AC28: =+Z28-AB28 -> -2111.1483

Sheet 사업장별(당월)
H3: □ 사업장별 손익실적(2026-05)
AG4: [단위 : 천㎥, 톤, 백만원]
H5: 구분 | J5: 물량 | O5: 매출 | T5: 영업이익(공통비 배부전) | Y5: 판매단가 | AB5: 변동비 | AE5: 공헌이익 | AI5: 판매비중
A6: 2024년 5월 마감 손익 | J6: 계획 | K6: 실적 | L6: 차이 | M6: 전년 | N6: 차이 | O6: 계획 | P6: 실적 | Q6: 차이 | R6: 전년 | S6: 차이 | T6: 계획 | U6: 실적 | V6: 차이 | W6: 전년 | X6: 차이 | Y6: 계획 | Z6: 실적 | AA6: 전년 | AB6: 계획 | AC6: 실적 | AD6: 전년 | AE6: 계획 | AF6: 실적 | AG6: 전년 | AI6: 공장명 | AJ6: 계획 | AK6: 추정 | AL6: 차이 | AO6: 전월 | AP6: 차이
B7: 안양 | G7: =+I7 -> 안양 | H7: 레미콘 | I7: 안양 | J7: =+IFERROR(HLOOKUP($B7,'[1]5월'!$D$6:$BN$259,2,),)/1000 -> 37 | K7: =+IFERROR(HLOOKUP($B7,'[2]5월'!$F$6:$CP$99,2,),)/1000 -> 34.368 | L7: =+K7-J7 -> -2.632 | M7: =+IFERROR(HLOOKUP($B7,'[3]5월'!$F$6:$CC$57,2,),)/1000 -> 31.314 | N7: =+K7-M7 -> 3.054 | O7: =+IFERROR(HLOOKUP($B7,'[1]5월'!$D$6:$BN$259,3,),)/1000 -> 3633.4219 | P7: =+IFERROR(HLOOKUP($B7,'[2]5월'!$F$6:$CP$99,3,),)/1000 -> 3513.5378 | Q7: =+P7-O7 -> -119.88407 | R7: =+IFERROR(HLOOKUP($B7,'[3]5월'!$F$6:$CC$57,3,),)/1000 -> 2998.4996 | S7: =+P7-R7 -> 515.03821 | T7: =+IFERROR(HLOOKUP($B7,'[1]5월'!$D$6:$BN$259,16,),)/1000 -> 434.05383 | U7: =+IFERROR(HLOOKUP($B7,'[2]5월'!$F$6:$CP$99,16,),)/1000 -> 439.64523 | V7: =+U7-T7 -> 5.591403 | W7: =+IFERROR(HLOOKUP($B7,'[3]5월'!$F$6:$CC$57,16,),)/1000 -> 242.51179 | X7: =+U7-W7 -> 197.13344 | Y7: =+[4]안양!$Q$85 -> 98200.591 | Z7: =+[4]안양!$R$85 -> 102248.21 | AA7: =+[5]안양!$Q$85 -> 95747.281 | AB7: =+[4]안양!$Q$89 -> 77977.697 | AC7: =+[4]안양!$R$89 -> 80684.876 | AD7: =+[5]안양!$Q$89 -> 78706.317 | AE7: =+Y7-AB7 -> 20222.895 | AF7: =+Z7-AC7 -> 21563.338 | AG7: =+AA7-AD7 -> 17040.964 | AI7: =+I7 -> 안양 | AJ7: =+J7/$J$27 -> 0.13703704 | AK7: =+K7/$K$27 -> 0.15751445 | AL7: =+AK7-AJ7 -> 0.020477417 | AM7: =+Y7*AL7 -> 2010.8945 | AO7: =+[17]안양!$T$5/[17]합계!$T$5 -> 0.15425649 | AP7: =+AK7-AO7 -> 0.0032579658 | AQ7: =+[17]안양!$Q$85*AP7 -> 316.61869
B8: 인천 | G8: =+I8 -> 인천 | H8: 직영 | I8: 인천 | J8: =+IFERROR(HLOOKUP($B8,'[1]5월'!$D$6:$BN$259,2,),)/1000 -> 35 | K8: =+IFERROR(HLOOKUP($B8,'[2]5월'!$F$6:$CP$99,2,),)/1000 -> 29.096 | L8: =+K8-J8 -> -5.904 | M8: =+IFERROR(HLOOKUP($B8,'[3]5월'!$F$6:$CC$57,2,),)/1000 -> 32.104 | N8: =+K8-M8 -> -3.008 | O8: =+IFERROR(HLOOKUP($B8,'[1]5월'!$D$6:$BN$259,3,),)/1000 -> 3494.6121 | P8: =+IFERROR(HLOOKUP($B8,'[2]5월'!$F$6:$CP$99,3,),)/1000 -> 2903.4344 | Q8: =+P8-O8 -> -591.17775 | R8: =+IFERROR(HLOOKUP($B8,'[3]5월'!$F$6:$CC$57,3,),)/1000 -> 3174.7652 | S8: =+P8-R8 -> -271.33086 | T8: =+IFERROR(HLOOKUP($B8,'[1]5월'!$D$6:$BN$259,16,),)/1000 -> 296.46875 | U8: =+IFERROR(HLOOKUP($B8,'[2]5월'!$F$6:$CP$99,16,),)/1000 -> 49.957465 | V8: =+U8-T8 -> -246.51129 | W8: =+IFERROR(HLOOKUP($B8,'[3]5월'!$F$6:$CC$57,16,),)/1000 -> 160.60507 | X8: =+U8-W8 -> -110.6476 | Y8: =+[4]인천!$Q$85 -> 99846.061 | Z8: =+[4]인천!$R$85 -> 99946.751 | AA8: =+[5]인천!$Q$85 -> 99229.134 | AB8: =+[4]인천!$Q$89 -> 82171.29 | AC8: =+[4]인천!$R$89 -> 87463.13 | AD8: =+[5]인천!$Q$89 -> 83784.72 | AE8: =+Y8-AB8 -> 17674.771 | AF8: =+Z8-AC8 -> 12483.62 | AG8: =+AA8-AD8 -> 15444.414 | AI8: =+I8 -> 인천 | AJ8: =+J8/$J$27 -> 0.12962963 | AK8: =+K8/$K$27 -> 0.13335197 | AL8: =+AK8-AJ8 -> 0.0037223419 | AM8: =+Y8*AL8 -> 371.66118 | AO8: =+[17]인천!$T$5/[17]합계!$T$5 -> 0.12976281 | AP8: =+AK8-AO8 -> 0.0035891596 | AQ8: =+[17]인천!$Q$85*AP8 -> 357.73669
B9: 파주 | G9: =+I9 -> 파주 | I9: 파주 | J9: =+IFERROR(HLOOKUP($B9,'[1]5월'!$D$6:$BN$259,2,),)/1000 -> 18 | K9: =+IFERROR(HLOOKUP($B9,'[2]5월'!$F$6:$CP$99,2,),)/1000 -> 13.3945 | L9: =+K9-J9 -> -4.6055 | M9: =+IFERROR(HLOOKUP($B9,'[3]5월'!$F$6:$CC$57,2,),)/1000 -> 11.412 | N9: =+K9-M9 -> 1.9825 | O9: =+IFERROR(HLOOKUP($B9,'[1]5월'!$D$6:$BN$259,3,),)/1000 -> 1774.3644 | P9: =+IFERROR(HLOOKUP($B9,'[2]5월'!$F$6:$CP$99,3,),)/1000 -> 1373.4054 | Q9: =+P9-O9 -> -400.95896 | R9: =+IFERROR(HLOOKUP($B9,'[3]5월'!$F$6:$CC$57,3,),)/1000 -> 1059.6553 | S9: =+P9-R9 -> 313.75014 | T9: =+IFERROR(HLOOKUP($B9,'[1]5월'!$D$6:$BN$259,16,),)/1000 -> 101.7489 | U9: =+IFERROR(HLOOKUP($B9,'[2]5월'!$F$6:$CP$99,16,),)/1000 -> 48.322042 | V9: =+U9-T9 -> -53.426855 | W9: =+IFERROR(HLOOKUP($B9,'[3]5월'!$F$6:$CC$57,16,),)/1000 -> -28.835518 | X9: =+U9-W9 -> 77.15756 | Y9: =+[4]파주!$Q$85 -> 98575.798 | Z9: =+[4]파주!$R$85 -> 102535.03 | AA9: =+[5]파주!$Q$85 -> 92818.058 | AB9: =+[4]파주!$Q$89 -> 81140.288 | AC9: =+[4]파주!$R$89 -> 84292.013 | AD9: =+[5]파주!$Q$89 -> 76791.949 | AE9: =+Y9-AB9 -> 17435.51 | AF9: =+Z9-AC9 -> 18243.013 | AG9: =+AA9-AD9 -> 16026.109 | AI9: =+I9 -> 파주 | AJ9: =+J9/$J$27 -> 0.066666667 | AK9: =+K9/$K$27 -> 0.061389297 | AL9: =+AK9-AJ9 -> -0.0052773697 | AM9: =+Y9*AL9 -> -520.22093 | AO9: =+[17]파주!$T$5/[17]합계!$T$5 -> 0.071464162 | AP9: =+AK9-AO9 -> -0.010074865 | AQ9: =+[17]파주!$Q$85*AP9 -> -1016.6705
B10: 김포 | G10: =+I10 -> 김포 | I10: 김포 | J10: =+IFERROR(HLOOKUP($B10,'[1]5월'!$D$6:$BN$259,2,),)/1000 -> 15 | K10: =+IFERROR(HLOOKUP($B10,'[2]5월'!$F$6:$CP$99,2,),)/1000 -> 15.3215 | L10: =+K10-J10 -> 0.3215 | M10: =+IFERROR(HLOOKUP($B10,'[3]5월'!$F$6:$CC$57,2,),)/1000 -> 10.9385 | N10: =+K10-M10 -> 4.383 | O10: =+IFERROR(HLOOKUP($B10,'[1]5월'!$D$6:$BN$259,3,),)/1000 -> 1438.2669 | P10: =+IFERROR(HLOOKUP($B10,'[2]5월'!$F$6:$CP$99,3,),)/1000 -> 1486.8971 | Q10: =+P10-O10 -> 48.630195 | R10: =+IFERROR(HLOOKUP($B10,'[3]5월'!$F$6:$CC$57,3,),)/1000 -> 1044.535 | S10: =+P10-R10 -> 442.36216 | T10: =+IFERROR(HLOOKUP($B10,'[1]5월'!$D$6:$BN$259,16,),)/1000 -> 101.76019 | U10: =+IFERROR(HLOOKUP($B10,'[2]5월'!$F$6:$CP$99,16,),)/1000 -> 64.671647 | V10: =+U10-T10 -> -37.088538 | W10: =+IFERROR(HLOOKUP($B10,'[3]5월'!$F$6:$CC$57,16,),)/1000 -> 30.961596 | X10: =+U10-W10 -> 33.710051 | Y10: =+[4]김포!$Q$85 -> 95884.463 | Z10: =+[4]김포!$R$85 -> 97081.727 | AA10: =+[5]김포!$Q$85 -> 95512.758 | AB10: =+[4]김포!$Q$89 -> 76883.918 | AC10: =+[4]김포!$R$89 -> 81141.001 | AD10: =+[5]김포!$Q$89 -> 77274.195 | AE10: =+Y10-AB10 -> 19000.545 | AF10: =+Z10-AC10 -> 15940.726 | AG10: =+AA10-AD10 -> 18238.563 | AI10: =+I10 -> 김포 | AJ10: =+J10/$J$27 -> 0.055555556 | AK10: =+K10/$K$27 -> 0.070221069 | AL10: =+AK10-AJ10 -> 0.014665514 | AM10: =+Y10*AL10 -> 1406.1949 | AO10: =+[17]김포!$T$5/[17]합계!$T$5 -> 0.064726615 | AP10: =+AK10-AO10 -> 0.0054944547 | AQ10: =+[17]김포!$Q$85*AP10 -> 543.03113
B11: 부산 | G11: =+I11 -> 부산 | I11: 부산 | J11: =+IFERROR(HLOOKUP($B11,'[1]5월'!$D$6:$BN$259,2,),)/1000 -> 20 | K11: =+IFERROR(HLOOKUP($B11,'[2]5월'!$F$6:$CP$99,2,),)/1000 -> 13.162 | L11: =+K11-J11 -> -6.838 | M11: =+IFERROR(HLOOKUP($B11,'[3]5월'!$F$6:$CC$57,2,),)/1000 -> 20.779 | N11: =+K11-M11 -> -7.617 | O11: =+IFERROR(HLOOKUP($B11,'[1]5월'!$D$6:$BN$259,3,),)/1000 -> 2145.3121 | P11: =+IFERROR(HLOOKUP($B11,'[2]5월'!$F$6:$CP$99,3,),)/1000 -> 1522.6011 | Q11: =+P11-O11 -> -622.71102 | R11: =+IFERROR(HLOOKUP($B11,'[3]5월'!$F$6:$CC$57,3,),)/1000 -> 2289.2581 | S11: =+P11-R11 -> -766.657 | T11: =+IFERROR(HLOOKUP($B11,'[1]5월'!$D$6:$BN$259,16,),)/1000 -> 211.20211 | U11: =+IFERROR(HLOOKUP($B11,'[2]5월'!$F$6:$CP$99,16,),)/1000 -> 92.754418 | V11: =+U11-T11 -> -118.44769 | W11: =+IFERROR(HLOOKUP($B11,'[3]5월'!$F$6:$CC$57,16,),)/1000 -> 308.13145 | X11: =+U11-W11 -> -215.37703 | Y11: =+[4]부산!$Q$85 -> 107265.61 | Z11: =+[4]부산!$R$85 -> 115681.59 | AA11: =+[5]부산!$Q$85 -> 110171.72 | AB11: =+[4]부산!$Q$89 -> 83341.75 | AC11: =+[4]부산!$R$89 -> 88327.848 | AD11: =+[5]부산!$Q$89 -> 83925.996 | AE11: =+Y11-AB11 -> 23923.856 | AF11: =+Z11-AC11 -> 27353.743 | AG11: =+AA11-AD11 -> 26245.72 | AI11: =+I11 -> 부산 | AJ11: =+J11/$J$27 -> 0.074074074 | AK11: =+K11/$K$27 -> 0.060323709 | AL11: =+AK11-AJ11 -> -0.013750365 | AM11: =+Y11*AL11 -> -1474.9412 | AO11: =+[17]부산!$T$5/[17]합계!$T$5 -> 0.076087753 | AP11: =+AK11-AO11 -> -0.015764044 | AQ11: =+[17]부산!$Q$85*AP11 -> -1817.7032
B12: 서부산 | G12: =+I12 -> 서부산 | I12: 서부산 | J12: =+IFERROR(HLOOKUP($B12,'[1]5월'!$D$6:$BN$259,2,),)/1000 -> 20 | K12: =+IFERROR(HLOOKUP($B12,'[2]5월'!$F$6:$CP$99,2,),)/1000 -> 19.707 | L12: =+K12-J12 -> -0.293 | M12: =+IFERROR(HLOOKUP($B12,'[3]5월'!$F$6:$CC$57,2,),)/1000 -> 17.147 | N12: =+K12-M12 -> 2.56 | O12: =+IFERROR(HLOOKUP($B12,'[1]5월'!$D$6:$BN$259,3,),)/1000 -> 2080.42 | P12: =+IFERROR(HLOOKUP($B12,'[2]5월'!$F$6:$CP$99,3,),)/1000 -> 2043.4648 | Q12: =+P12-O12 -> -36.955195 | R12: =+IFERROR(HLOOKUP($B12,'[3]5월'!$F$6:$CC$57,3,),)/1000 -> 1653.59 | S12: =+P12-R12 -> 389.87478 | T12: =+IFERROR(HLOOKUP($B12,'[1]5월'!$D$6:$BN$259,16,),)/1000 -> 317.8487 | U12: =+IFERROR(HLOOKUP($B12,'[2]5월'!$F$6:$CP$99,16,),)/1000 -> 220.01484 | V12: =+U12-T12 -> -97.833859 | W12: =+IFERROR(HLOOKUP($B12,'[3]5월'!$F$6:$CC$57,16,),)/1000 -> 89.008721 | X12: =+U12-W12 -> 131.00612 | Y12: =+[4]서부산!$Q$85 -> 104021 | Z12: =+[4]서부산!$R$85 -> 103692.33 | AA12: =+[5]서부산!$Q$85 -> 96775.187 | AB12: =+[4]서부산!$Q$89 -> 77250.208 | AC12: =+[4]서부산!$R$89 -> 80900.37 | AD12: =+[5]서부산!$Q$89 -> 78037.415 | AE12: =+Y12-AB12 -> 26770.791 | AF12: =+Z12-AC12 -> 22791.962 | AG12: =+AA12-AD12 -> 18737.772 | AI12: =+I12 -> 서부산 | AJ12: =+J12/$J$27 -> 0.074074074 | AK12: =+K12/$K$27 -> 0.09032057 | AL12: =+AK12-AJ12 -> 0.016246496 | AM12: =+Y12*AL12 -> 1689.9767 | AO12: =+[17]서부산!$T$5/[17]합계!$T$5 -> 0.080953149 | AP12: =+AK12-AO12 -> 0.0093674214 | AQ12: =+[17]서부산!$Q$85*AP12 -> 945.60189
B13: 김해 | G13: =+I13 -> 김해 | I13: 김해 | J13: =+IFERROR(HLOOKUP($B13,'[1]5월'!$D$6:$BN$259,2,),)/1000 -> 10 | K13: =+IFERROR(HLOOKUP($B13,'[2]5월'!$F$6:$CP$99,2,),)/1000 -> 5.473 | L13: =+K13-J13 -> -4.527 | M13: =+IFERROR(HLOOKUP($B13,'[3]5월'!$F$6:$CC$57,2,),)/1000 -> 8.128 | N13: =+K13-M13 -> -2.655 | O13: =+IFERROR(HLOOKUP($B13,'[1]5월'!$D$6:$BN$259,3,),)/1000 -> 1012.9338 | P13: =+IFERROR(HLOOKUP($B13,'[2]5월'!$F$6:$CP$99,3,),)/1000 -> 531.6782 | Q13: =+P13-O13 -> -481.25561 | R13: =+IFERROR(HLOOKUP($B13,'[3]5월'!$F$6:$CC$57,3,),)/1000 -> 696.279 | S13: =+P13-R13 -> -164.6008 | T13: =+IFERROR(HLOOKUP($B13,'[1]5월'!$D$6:$BN$259,16,),)/1000 -> 84.549448 | U13: =+IFERROR(HLOOKUP($B13,'[2]5월'!$F$6:$CP$99,16,),)/1000 -> -21.796408 | V13: =+U13-T13 -> -106.34586 | W13: =+IFERROR(HLOOKUP($B13,'[3]5월'!$F$6:$CC$57,16,),)/1000 -> -70.922998 | X13: =+U13-W13 -> 49.12659 | Y13: =+[4]김해!$Q$85 -> 101293.38 | Z13: =+[4]김해!$R$85 -> 97145.661 | AA13: =+[5]김해!$Q$85 -> 85822.552 | AB13: =+[4]김해!$Q$89 -> 78862.413 | AC13: =+[4]김해!$R$89 -> 77419.852 | AD13: =+[5]김해!$Q$89 -> 78014.983 | AE13: =+Y13-AB13 -> 22430.968 | AF13: =+Z13-AC13 -> 19725.808 | AG13: =+AA13-AD13 -> 7807.5691 | AI13: =+I13 -> 김해 | AJ13: =+J13/$J$27 -> 0.037037037 | AK13: =+K13/$K$27 -> 0.0250837 | AL13: =+AK13-AJ13 -> -0.011953337 | AM13: =+Y13*AL13 -> -1210.7939 | AO13: =+[17]김해!$T$5/[17]합계!$T$5 -> 0.023268168 | AP13: =+AK13-AO13 -> 0.0018155319 | AQ13: =+[17]김해!$Q$85*AP13 -> 178.67487
B14: 정관 | G14: =+I14 -> 정관 | I14: 정관 | J14: =+IFERROR(HLOOKUP($B14,'[1]5월'!$D$6:$BN$259,2,),)/1000 -> 22 | K14: =+IFERROR(HLOOKUP($B14,'[2]5월'!$F$6:$CP$99,2,),)/1000 -> 14.883 | L14: =+K14-J14 -> -7.117 | M14: =+IFERROR(HLOOKUP($B14,'[3]5월'!$F$6:$CC$57,2,),)/1000 -> 23.4385 | N14: =+K14-M14 -> -8.5555 | O14: =+IFERROR(HLOOKUP($B14,'[1]5월'!$D$6:$BN$259,3,),)/1000 -> 2334.3779 | P14: =+IFERROR(HLOOKUP($B14,'[2]5월'!$F$6:$CP$99,3,),)/1000 -> 1555.6253 | Q14: =+P14-O14 -> -778.75257 | R14: =+IFERROR(HLOOKUP($B14,'[3]5월'!$F$6:$CC$57,3,),)/1000 -> 2254.526 | S14: =+P14-R14 -> -698.90072 | T14: =+IFERROR(HLOOKUP($B14,'[1]5월'!$D$6:$BN$259,16,),)/1000 -> 323.96239 | U14: =+IFERROR(HLOOKUP($B14,'[2]5월'!$F$6:$CP$99,16,),)/1000 -> 92.285135 | V14: =+U14-T14 -> -231.67725 | W14: =+IFERROR(HLOOKUP($B14,'[3]5월'!$F$6:$CC$57,16,),)/1000 -> 201.7835 | X14: =+U14-W14 -> -109.49837 | Y14: =+[4]정관!$Q$85 -> 106108.08 | Z14: =+[4]정관!$R$85 -> 104523.64 | AA14: =+[5]정관!$Q$85 -> 96261.012 | AB14: =+[4]정관!$Q$89 -> 81375.819 | AC14: =+[4]정관!$R$89 -> 84602.536 | AD14: =+[5]정관!$Q$89 -> 78911.617 | AE14: =+Y14-AB14 -> 24732.265 | AF14: =+Z14-AC14 -> 19921.101 | AG14: =+AA14-AD14 -> 17349.395 | AI14: =+I14 -> 정관 | AJ14: =+J14/$J$27 -> 0.081481481 | AK14: =+K14/$K$27 -> 0.068211348 | AL14: =+AK14-AJ14 -> -0.013270133 | AM14: =+Y14*AL14 -> -1408.0684 | AO14: =+[17]정관!$T$5/[17]합계!$T$5 -> 0.066990782 | AP14: =+AK14-AO14 -> 0.0012205663 | AQ14: =+[17]정관!$Q$85*AP14 -> 125.42877
B15: 양산 | G15: =+I15 -> 양산 | I15: 양산 | J15: =+IFERROR(HLOOKUP($B15,'[1]5월'!$D$6:$BN$259,2,),)/1000 -> 10 | K15: =+IFERROR(HLOOKUP($B15,'[2]5월'!$F$6:$CP$99,2,),)/1000 -> 3.836 | L15: =+K15-J15 -> -6.164 | M15: =+IFERROR(HLOOKUP($B15,'[3]5월'!$F$6:$CC$57,2,),)/1000 -> 8.737 | N15: =+K15-M15 -> -4.901 | O15: =+IFERROR(HLOOKUP($B15,'[1]5월'!$D$6:$BN$259,3,),)/1000 -> 1013.5022 | P15: =+IFERROR(HLOOKUP($B15,'[2]5월'!$F$6:$CP$99,3,),)/1000 -> 383.574 | Q15: =+P15-O15 -> -629.9282 | R15: =+IFERROR(HLOOKUP($B15,'[3]5월'!$F$6:$CC$57,3,),)/1000 -> 783.76212 | S15: =+P15-R15 -> -400.18812 | T15: =+IFERROR(HLOOKUP($B15,'[1]5월'!$D$6:$BN$259,16,),)/1000 -> 114.96988 | U15: =+IFERROR(HLOOKUP($B15,'[2]5월'!$F$6:$CP$99,16,),)/1000 -> -39.795293 | V15: =+U15-T15 -> -154.76518 | W15: =+IFERROR(HLOOKUP($B15,'[3]5월'!$F$6:$CC$57,16,),)/1000 -> 38.252911 | X15: =+U15-W15 -> -78.048204 | Y15: =+[4]양산!$Q$85 -> 101350.22 | Z15: =+[4]양산!$R$85 -> 99993.222 | AA15: =+[5]양산!$Q$85 -> 89706.091 | AB15: =+[4]양산!$Q$89 -> 75892.305 | AC15: =+[4]양산!$R$89 -> 76277.523 | AD15: =+[5]양산!$Q$89 -> 71251.382 | AE15: =+Y15-AB15 -> 25457.915 | AF15: =+Z15-AC15 -> 23715.699 | AG15: =+AA15-AD15 -> 18454.709 | AI15: =+I15 -> 양산 | AJ15: =+J15/$J$27 -> 0.037037037 | AK15: =+K15/$K$27 -> 0.017581048 | AL15: =+AK15-AJ15 -> -0.019455989 | AM15: =+Y15*AL15 -> -1971.8688 | AO15: =+[17]양산!$T$5/[17]합계!$T$5 -> 0.026411624 | AP15: =+AK15-AO15 -> -0.0088305765 | AQ15: =+[17]양산!$Q$85*AP15 -> -869.50849
B16: 창원 | G16: =+I16 -> 창원 | I16: 창원 | J16: =+IFERROR(HLOOKUP($B16,'[1]5월'!$D$6:$BN$259,2,),)/1000 -> 14 | K16: =+IFERROR(HLOOKUP($B16,'[2]5월'!$F$6:$CP$99,2,),)/1000 -> 11.287 | L16: =+K16-J16 -> -2.713 | M16: =+IFERROR(HLOOKUP($B16,'[3]5월'!$F$6:$CC$57,2,),)/1000 -> 8.83 | N16: =+K16-M16 -> 2.457 | O16: =+IFERROR(HLOOKUP($B16,'[1]5월'!$D$6:$BN$259,3,),)/1000 -> 1372.3952 | P16: =+IFERROR(HLOOKUP($B16,'[2]5월'!$F$6:$CP$99,3,),)/1000 -> 1096.4436 | Q16: =+P16-O16 -> -275.95155 | R16: =+IFERROR(HLOOKUP($B16,'[3]5월'!$F$6:$CC$57,3,),)/1000 -> 858.6514 | S16: =+P16-R16 -> 237.7922 | T16: =+IFERROR(HLOOKUP($B16,'[1]5월'!$D$6:$BN$259,16,),)/1000 -> 126.87661 | U16: =+IFERROR(HLOOKUP($B16,'[2]5월'!$F$6:$CP$99,16,),)/1000 -> 65.208746 | V16: =+U16-T16 -> -61.667864 | W16: =+IFERROR(HLOOKUP($B16,'[3]5월'!$F$6:$CC$57,16,),)/1000 -> 24.863254 | X16: =+U16-W16 -> 40.345492 | Y16: =+[4]창원!$Q$85 -> 98028.225 | Z16: =+[4]창원!$R$85 -> 97142.164 | AA16: =+[5]창원!$Q$85 -> 97242.514 | AB16: =+[4]창원!$Q$89 -> 76554.334 | AC16: =+[4]창원!$R$89 -> 74983.097 | AD16: =+[5]창원!$Q$89 -> 75675.416 | AE16: =+Y16-AB16 -> 21473.891 | AF16: =+Z16-AC16 -> 22159.067 | AG16: =+AA16-AD16 -> 21567.098 | AI16: =+I16 -> 창원 | AJ16: =+J16/$J$27 -> 0.051851852 | AK16: =+K16/$K$27 -> 0.051730262 | AL16: =+AK16-AJ16 -> -0.00012158985 | AM16: =+Y16*AL16 -> -11.919238 | AO16: =+[17]창원!$T$5/[17]합계!$T$5 -> 0.04239269 | AP16: =+AK16-AO16 -> 0.0093375718 | AQ16: =+[17]창원!$Q$85*AP16 -> 874.52368
B17: 대구 | G17: =+I17 -> 대구 | I17: 대구 | J17: =+IFERROR(HLOOKUP($B17,'[1]5월'!$D$6:$BN$259,2,),)/1000 -> 9 | K17: =+IFERROR(HLOOKUP($B17,'[2]5월'!$F$6:$CP$99,2,),)/1000 -> 4.797 | L17: =+K17-J17 -> -4.203 | M17: =+IFERROR(HLOOKUP($B17,'[3]5월'!$F$6:$CC$57,2,),)/1000 -> 8.3985 | N17: =+K17-M17 -> -3.6015 | O17: =+IFERROR(HLOOKUP($B17,'[1]5월'!$D$6:$BN$259,3,),)/1000 -> 824.66973 | P17: =+IFERROR(HLOOKUP($B17,'[2]5월'!$F$6:$CP$99,3,),)/1000 -> 373.878 | Q17: =+P17-O17 -> -450.79173 | R17: =+IFERROR(HLOOKUP($B17,'[3]5월'!$F$6:$CC$57,3,),)/1000 -> 714.62896 | S17: =+P17-R17 -> -340.75096 | T17: =+IFERROR(HLOOKUP($B17,'[1]5월'!$D$6:$BN$259,16,),)/1000 -> 50.762107 | U17: =+IFERROR(HLOOKUP($B17,'[2]5월'!$F$6:$CP$99,16,),)/1000 -> -72.116301 | V17: =+U17-T17 -> -122.87841 | W17: =+IFERROR(HLOOKUP($B17,'[3]5월'!$F$6:$CC$57,16,),)/1000 -> -22.058378 | X17: =+U17-W17 -> -50.057923 | Y17: =+[4]대구!$Q$85 -> 91629.97 | Z17: =+[4]대구!$R$85 -> 77939.962 | AA17: =+[5]대구!$Q$85 -> 85090.071 | AB17: =+[4]대구!$Q$89 -> 70177.906 | AC17: =+[4]대구!$R$89 -> 66396.851 | AD17: =+[5]대구!$Q$89 -> 70269.761 | AE17: =+Y17-AB17 -> 21452.064 | AF17: =+Z17-AC17 -> 11543.111 | AG17: =+AA17-AD17 -> 14820.31 | AI17: =+I17 -> 대구 | AJ17: =+J17/$J$27 -> 0.033333333 | AK17: =+K17/$K$27 -> 0.021985476 | AL17: =+AK17-AJ17 -> -0.011347857 | AM17: =+Y17*AL17 -> -1039.8038 | AO17: =+[17]대구!$T$5/[17]합계!$T$5 -> 0.020932559 | AP17: =+AK17-AO17 -> 0.0010529173 | AQ17: =+[17]대구!$Q$85*AP17 -> 81.69637
B18: 울산 | G18: =+I18 -> 울산 | I18: 울산 | J18: =+IFERROR(HLOOKUP($B18,'[1]5월'!$D$6:$BN$259,2,),)/1000 -> 12 | K18: =+IFERROR(HLOOKUP($B18,'[2]5월'!$F$6:$CP$99,2,),)/1000 -> 10.223 | L18: =+K18-J18 -> -1.777 | M18: =+IFERROR(HLOOKUP($B18,'[3]5월'!$F$6:$CC$57,2,),)/1000 -> 11.425 | N18: =+K18-M18 -> -1.202 | O18: =+IFERROR(HLOOKUP($B18,'[1]5월'!$D$6:$BN$259,3,),)/1000 -> 1239.4427 | P18: =+IFERROR(HLOOKUP($B18,'[2]5월'!$F$6:$CP$99,3,),)/1000 -> 1065.0908 | Q18: =+P18-O18 -> -174.35192 | R18: =+IFERROR(HLOOKUP($B18,'[3]5월'!$F$6:$CC$57,3,),)/1000 -> 1191.1941 | S18: =+P18-R18 -> -126.1033 | T18: =+IFERROR(HLOOKUP($B18,'[1]5월'!$D$6:$BN$259,16,),)/1000 -> 103.28835 | U18: =+IFERROR(HLOOKUP($B18,'[2]5월'!$F$6:$CP$99,16,),)/1000 -> 29.061433 | V18: =+U18-T18 -> -74.226915 | W18: =+IFERROR(HLOOKUP($B18,'[3]5월'!$F$6:$CC$57,16,),)/1000 -> 111.42436 | X18: =+U18-W18 -> -82.362923 | Y18: =+[4]울산!$Q$85 -> 103286.89 | Z18: =+[4]울산!$R$85 -> 104185.74 | AA18: =+[5]울산!$Q$85 -> 104262.07 | AB18: =+[4]울산!$Q$89 -> 82587.096 | AC18: =+[4]울산!$R$89 -> 87862.053 | AD18: =+[5]울산!$Q$89 -> 81655.985 | AE18: =+Y18-AB18 -> 20699.797 | AF18: =+Z18-AC18 -> 16323.685 | AG18: =+AA18-AD18 -> 22606.081 | AI18: =+I18 -> 울산 | AJ18: =+J18/$J$27 -> 0.044444444 | AK18: =+K18/$K$27 -> 0.046853767 | AL18: =+AK18-AJ18 -> 0.0024093226 | AM18: =+Y18*AL18 -> 248.85144 | AO18: =+[17]울산!$T$5/[17]합계!$T$5 -> 0.052966133 | AP18: =+AK18-AO18 -> -0.0061123657 | AQ18: =+[17]울산!$Q$85*AP18 -> -620.78564
B19: 아산 | G19: =+I19 -> 아산 | I19: 아산 | J19: =+IFERROR(HLOOKUP($B19,'[1]5월'!$D$6:$BN$259,2,),)/1000 -> 22 | K19: =+IFERROR(HLOOKUP($B19,'[2]5월'!$F$6:$CP$99,2,),)/1000 -> 18.291 | L19: =+K19-J19 -> -3.709 | M19: =+IFERROR(HLOOKUP($B19,'[3]5월'!$F$6:$CC$57,2,),)/1000 -> 22.644 | N19: =+K19-M19 -> -4.353 | O19: =+IFERROR(HLOOKUP($B19,'[1]5월'!$D$6:$BN$259,3,),)/1000 -> 2174.0468 | P19: =+IFERROR(HLOOKUP($B19,'[2]5월'!$F$6:$CP$99,3,),)/1000 -> 1884.8388 | Q19: =+P19-O19 -> -289.208 | R19: =+IFERROR(HLOOKUP($B19,'[3]5월'!$F$6:$CC$57,3,),)/1000 -> 2188.967 | S19: =+P19-R19 -> -304.12816 | T19: =+IFERROR(HLOOKUP($B19,'[1]5월'!$D$6:$BN$259,16,),)/1000 -> 213.00416 | U19: =+IFERROR(HLOOKUP($B19,'[2]5월'!$F$6:$CP$99,16,),)/1000 -> 122.41643 | V19: =+U19-T19 -> -90.587731 | W19: =+IFERROR(HLOOKUP($B19,'[3]5월'!$F$6:$CC$57,16,),)/1000 -> 136.46828 | X19: =+U19-W19 -> -14.051854 | Y19: =+[4]아산!$Q$85 -> 98820.311 | Z19: =+[4]아산!$R$85 -> 103047.34 | AA19: =+[5]아산!$Q$85 -> 96668.742 | AB19: =+[4]아산!$Q$89 -> 77983.882 | AC19: =+[4]아산!$R$89 -> 82865.275 | AD19: =+[5]아산!$Q$89 -> 79974.966 | AE19: =+Y19-AB19 -> 20836.429 | AF19: =+Z19-AC19 -> 20182.062 | AG19: =+AA19-AD19 -> 16693.777 | AI19: =+I19 -> 아산 | AJ19: =+J19/$J$27 -> 0.081481481 | AK19: =+K19/$K$27 -> 0.083830798 | AL19: =+AK19-AJ19 -> 0.002349317 | AM19: =+Y19*AL19 -> 232.16023 | AO19: =+[17]아산!$T$5/[17]합계!$T$5 -> 0.088874071 | AP19: =+AK19-AO19 -> -0.0050432728 | AQ19: =+[17]아산!$Q$85*AP19 -> -503.86927
B20: 전주 | G20: =+I20 -> 전주 | I20: 전주 | J20: =+IFERROR(HLOOKUP($B20,'[1]5월'!$D$6:$BN$259,2,),)/1000 -> 12 | K20: =+IFERROR(HLOOKUP($B20,'[2]5월'!$F$6:$CP$99,2,),)/1000 -> 10.494 | L20: =+K20-J20 -> -1.506 | M20: =+IFERROR(HLOOKUP($B20,'[3]5월'!$F$6:$CC$57,2,),)/1000 -> 13.9375 | N20: =+K20-M20 -> -3.4435 | O20: =+IFERROR(HLOOKUP($B20,'[1]5월'!$D$6:$BN$259,3,),)/1000 -> 1232.294 | P20: =+IFERROR(HLOOKUP($B20,'[2]5월'!$F$6:$CP$99,3,),)/1000 -> 1014.532 | Q20: =+P20-O20 -> -217.762 | R20: =+IFERROR(HLOOKUP($B20,'[3]5월'!$F$6:$CC$57,3,),)/1000 -> 1348.2397 | S20: =+P20-R20 -> -333.7077 | T20: =+IFERROR(HLOOKUP($B20,'[1]5월'!$D$6:$BN$259,16,),)/1000 -> 162.0915 | U20: =+IFERROR(HLOOKUP($B20,'[2]5월'!$F$6:$CP$99,16,),)/1000 -> 21.521379 | V20: =+U20-T20 -> -140.57012 | W20: =+IFERROR(HLOOKUP($B20,'[3]5월'!$F$6:$CC$57,16,),)/1000 -> 165.00719 | X20: =+U20-W20 -> -143.48581 | Y20: =+[4]전주!$Q$85 -> 102691.17 | Z20: =+[4]전주!$R$85 -> 96677.339 | AA20: =+[5]전주!$Q$85 -> 96734.687 | AB20: =+[4]전주!$Q$89 -> 76384.788 | AC20: =+[4]전주!$R$89 -> 80526.778 | AD20: =+[5]전주!$Q$89 -> 74428.278 | AE20: =+Y20-AB20 -> 26306.379 | AF20: =+Z20-AC20 -> 16150.561 | AG20: =+AA20-AD20 -> 22306.409 | AI20: =+I20 -> 전주 | AJ20: =+J20/$J$27 -> 0.044444444 | AK20: =+K20/$K$27 -> 0.048095807 | AL20: =+AK20-AJ20 -> 0.0036513622 | AM20: =+Y20*AL20 -> 374.96264 | AO20: =+[17]전주!$T$5/[17]합계!$T$5 -> 0.049496607 | AP20: =+AK20-AO20 -> -0.0014008008 | AQ20: =+[17]전주!$Q$85*AP20 -> -136.21329
B21: 군산 | G21: =+I21 -> 군산 | I21: 군산 | J21: =+IFERROR(HLOOKUP($B21,'[1]5월'!$D$6:$BN$259,2,),)/1000 -> 5 | K21: =+IFERROR(HLOOKUP($B21,'[2]5월'!$F$6:$CP$99,2,),)/1000 -> 4.0275 | L21: =+K21-J21 -> -0.9725 | M21: =+IFERROR(HLOOKUP($B21,'[3]5월'!$F$6:$CC$57,2,),)/1000 -> 6.231 | N21: =+K21-M21 -> -2.2035 | O21: =+IFERROR(HLOOKUP($B21,'[1]5월'!$D$6:$BN$259,3,),)/1000 -> 560.4238 | P21: =+IFERROR(HLOOKUP($B21,'[2]5월'!$F$6:$CP$99,3,),)/1000 -> 428.74065 | Q21: =+P21-O21 -> -131.68315 | R21: =+IFERROR(HLOOKUP($B21,'[3]5월'!$F$6:$CC$57,3,),)/1000 -> 651.478 | S21: =+P21-R21 -> -222.73735 | T21: =+IFERROR(HLOOKUP($B21,'[1]5월'!$D$6:$BN$259,16,),)/1000 -> 106.87183 | U21: =+IFERROR(HLOOKUP($B21,'[2]5월'!$F$6:$CP$99,16,),)/1000 -> 44.935986 | V21: =+U21-T21 -> -61.935848 | W21: =+IFERROR(HLOOKUP($B21,'[3]5월'!$F$6:$CC$57,16,),)/1000 -> 130.46313 | X21: =+U21-W21 -> -85.527149 | Y21: =+[4]군산!$Q$85 -> 112084.76 | Z21: =+[4]군산!$R$85 -> 106453.3 | AA21: =+[5]군산!$Q$85 -> 104554.33 | AB21: =+[4]군산!$Q$89 -> 72924.397 | AC21: =+[4]군산!$R$89 -> 74907.398 | AD21: =+[5]군산!$Q$89 -> 70840.843 | AE21: =+Y21-AB21 -> 39160.363 | AF21: =+Z21-AC21 -> 31545.899 | AG21: =+AA21-AD21 -> 33713.482 | AI21: =+I21 -> 군산 | AJ21: =+J21/$J$27 -> 0.018518519 | AK21: =+K21/$K$27 -> 0.018458725 | AL21: =+AK21-AJ21 -> -5.9793419e-05 | AM21: =+Y21*AL21 -> -6.7019311 | AO21: =+[17]군산!$T$5/[17]합계!$T$5 -> 0.018688541 | AP21: =+AK21-AO21 -> -0.00022981631 | AQ21: =+[17]군산!$Q$85*AP21 -> -25.586897
B22: 원주 | G22: =+I22 -> 원주 | I22: 원주 | J22: =+IFERROR(HLOOKUP($B22,'[1]5월'!$D$6:$BN$259,2,),)/1000 -> 4 | K22: =+IFERROR(HLOOKUP($B22,'[2]5월'!$F$6:$CP$99,2,),)/1000 -> 4.766 | L22: =+K22-J22 -> 0.766 | M22: =+IFERROR(HLOOKUP($B22,'[3]5월'!$F$6:$CC$57,2,),)/1000 -> 1.6815 | N22: =+K22-M22 -> 3.0845 | O22: =+IFERROR(HLOOKUP($B22,'[1]5월'!$D$6:$BN$259,3,),)/1000 -> 446.53946 | P22: =+IFERROR(HLOOKUP($B22,'[2]5월'!$F$6:$CP$99,3,),)/1000 -> 546.639 | Q22: =+P22-O22 -> 100.09954 | R22: =+IFERROR(HLOOKUP($B22,'[3]5월'!$F$6:$CC$57,3,),)/1000 -> 184.23005 | S22: =+P22-R22 -> 362.40895 | T22: =+IFERROR(HLOOKUP($B22,'[1]5월'!$D$6:$BN$259,16,),)/1000 -> 74.50264 | U22: =+IFERROR(HLOOKUP($B22,'[2]5월'!$F$6:$CP$99,16,),)/1000 -> 133.32987 | V22: =+U22-T22 -> 58.827227 | W22: =+IFERROR(HLOOKUP($B22,'[3]5월'!$F$6:$CC$57,16,),)/1000 -> -23.378171 | X22: =+U22-W22 -> 156.70804 | Y22: =+[4]원주!$Q$85 -> 111634.86 | Z22: =+[4]원주!$R$85 -> 114695.55 | AA22: =+[5]원주!$Q$85 -> 109562.92 | AB22: =+[4]원주!$Q$89 -> 70677.633 | AC22: =+[4]원주!$R$89 -> 70522.994 | AD22: =+[5]원주!$Q$89 -> 72019.425 | AE22: =+Y22-AB22 -> 40957.232 | AF22: =+Z22-AC22 -> 44172.557 | AG22: =+AA22-AD22 -> 37543.495 | AI22: =+I22 -> 원주 | AJ22: =+J22/$J$27 -> 0.014814815 | AK22: =+K22/$K$27 -> 0.021843398 | AL22: =+AK22-AJ22 -> 0.0070285828 | AM22: =+Y22*AL22 -> 784.63489 | AO22: =+[17]원주!$T$5/[17]합계!$T$5 -> 0.01774697 | AP22: =+AK22-AO22 -> 0.0040964275 | AQ22: =+[17]원주!$Q$85*AP22 -> 446.32333
B23: 제주 | F23: =+K27-J27 -> -51.8105 | G23: =+I23 -> 제주 | I23: 제주 | J23: =+IFERROR(HLOOKUP($B23,'[1]5월'!$D$6:$BN$259,2,),)/1000 -> 5 | K23: =+IFERROR(HLOOKUP($B23,'[2]5월'!$F$6:$CP$99,2,),)/1000 -> 5.063 | L23: =+K23-J23 -> 0.063 | M23: =+IFERROR(HLOOKUP($B23,'[3]5월'!$F$6:$CC$57,2,),)/1000 -> 5.85 | N23: =+K23-M23 -> -0.787 | O23: =+IFERROR(HLOOKUP($B23,'[1]5월'!$D$6:$BN$259,3,),)/1000 -> 609.7 | P23: =+IFERROR(HLOOKUP($B23,'[2]5월'!$F$6:$CP$99,3,),)/1000 -> 658.02805 | Q23: =+P23-O23 -> 48.32805 | R23: =+IFERROR(HLOOKUP($B23,'[3]5월'!$F$6:$CC$57,3,),)/1000 -> 707.66847 | S23: =+P23-R23 -> -49.640425 | T23: =+IFERROR(HLOOKUP($B23,'[1]5월'!$D$6:$BN$259,16,),)/1000 -> 36.75533 | U23: =+IFERROR(HLOOKUP($B23,'[2]5월'!$F$6:$CP$99,16,),)/1000 -> 59.875705 | V23: =+U23-T23 -> 23.120375 | W23: =+IFERROR(HLOOKUP($B23,'[3]5월'!$F$6:$CC$57,16,),)/1000 -> 60.026911 | X23: =+U23-W23 -> -0.151206 | Y23: =+[4]제주!$Q$85 -> 121940 | Z23: =+[4]제주!$R$85 -> 129968.01 | AA23: =+[5]제주!$Q$85 -> 120514.24 | AB23: =+[4]제주!$Q$89 -> 94189.871 | AC23: =+[4]제주!$R$89 -> 98573.571 | AD23: =+[5]제주!$Q$89 -> 92365.438 | AE23: =+Y23-AB23 -> 27750.129 | AF23: =+Z23-AC23 -> 31394.442 | AG23: =+AA23-AD23 -> 28148.799 | AI23: =+I23 -> 제주 | AJ23: =+J23/$J$27 -> 0.018518519 | AK23: =+K23/$K$27 -> 0.0232046 | AL23: =+AK23-AJ23 -> 0.0046860812 | AM23: =+Y23*AL23 -> 571.42074 | AO23: =+[17]제주!$T$5/[17]합계!$T$5 -> 0.014980875 | AP23: =+AK23-AO23 -> 0.0082237242 | AQ23: =+[17]제주!$Q$85*AP23 -> 1079.0144
F24: =+K24/J24 -> 0.87790476 | G24: =+I24 -> 수도권 | I24: 수도권 | J24: =SUM(J7:J10) -> 105 | K24: =SUM(K7:K10) -> 92.18 | L24: =+K24-J24 -> -12.82 | M24: =SUM(M7:M10) -> 85.7685 | N24: =+K24-M24 -> 6.4115 | O24: =SUM(O7:O10) -> 10340.665 | P24: =SUM(P7:P10) -> 9277.2747 | Q24: =+P24-O24 -> -1063.3906 | R24: =SUM(R7:R10) -> 8277.4551 | S24: =+P24-R24 -> 999.81965 | T24: =SUM(T7:T10) -> 934.03166 | U24: =SUM(U7:U10) -> 602.59639 | V24: =+U24-T24 -> -331.43528 | W24: =SUM(W7:W10) -> 405.24294 | X24: =+U24-W24 -> 197.35345 | Y24: =+[4]수도권!$Q$85 -> 98482.527 | Z24: =+[4]수도권!$R$85 -> 100715.68 | AA24: =+[5]수도권!$Q$85 -> 96609.726 | AB24: =+[4]수도권!$Q$89 -> 79761.465 | AC24: =+[4]수도권!$R$89 -> 83421.953 | AD24: =+[5]수도권!$Q$89 -> 80138.588 | AE24: =+Y24-AB24 -> 18721.061 | AF24: =+Z24-AC24 -> 17293.722 | AG24: =+AA24-AD24 -> 16471.138 | AI24: =+I24 -> 수도권 | AJ24: =+J24/$J$27 -> 0.38888889 | AK24: =+K24/$K$27 -> 0.42247679 | AL24: =+AK24-AJ24 -> 0.033587903 | AM24: =+Y24*AL24 -> 3307.8216 | AO24: =+[17]수도권!$T$5/[17]합계!$T$5 -> 0.42021008 | AP24: =+AK24-AO24 -> 0.0022667153 | AQ24: =+[17]수도권!$Q$85*AP24 -> 223.98711
