Workbook

Sheet 표지
A6: 2026년 2월 마감 손익
A24: 레미콘사업본부

Sheet 손익총괄
C3: □ 건재사업본부 손익실적(2026-02)
X4: [단위 : 천㎥, 톤, 원/㎥, 원/톤, 백만원]
C5: 구분 | E5: 2월 | J5: 2월누계 | P5: 2월 주요지표
E6: 계획 | F6: 실적 | G6: 계획대비 | H6: 전년 | I6: 전년대비 | J6: 계획 | K6: 실적 | L6: 계획대비 | M6: 전년 | N6: 전년대비
C7: 물량 | D7: 레미콘 | E7: =+'[1]2월'!$Z$7/1000 -> 176.9998 | F7: =+'[2]2월'!$Z$7/1000 -> 170.009 | G7: =+F7-E7 -> -6.9908 | H7: =+'[3]2월'!$Z$7/1000 -> 210.779 | I7: =+F7-H7 -> -40.77 | J7: =+'[1]2월누계'!$Z$7/1000 -> 365.9998 | K7: =+'[2]2월누계'!$Z$7/1000 -> 346.1295 | L7: =+K7-J7 -> -19.8703 | M7: =+'[3]2월누계'!$Z$7/1000 -> 388.6585 | N7: =+K7-M7 -> -42.529 | Q7: □ 레미콘
D8: 골재 | E8: =+'[1]2월'!$AE$7/1000 -> 60.2957 | F8: =+'[2]2월'!$AN$7/1000 -> 50.674 | G8: =+F8-E8 -> -9.6217003 | H8: =+'[3]2월'!$AN$7/1000 -> 57.937 | I8: =+F8-H8 -> -7.263 | J8: =+'[1]2월누계'!$AE$7/1000 -> 135.05383 | K8: =+'[2]2월누계'!$AN$7/1000 -> 106.167 | L8: =+K8-J8 -> -28.886827 | M8: =+'[3]2월누계'!$AN$7/1000 -> 106.189 | N8: =+K8-M8 -> -0.022 | Q8: 구분 | S8: 계획 | T8: 실적 | U8: 계획대비 | V8: 전년 | W8: 전년대비
C9: 매출 | D9: 레미콘 | E9: =+'[1]2월'!$Z$8/1000 -> 17798.567 | F9: =+'[2]2월'!$Z$8/1000 -> 17781.846 | G9: =+F9-E9 -> -16.720929 | H9: =+'[3]2월'!$Z$8/1000 -> 21022.768 | I9: =+F9-H9 -> -3240.9215 | J9: =+'[1]2월누계'!$Z$8/1000 -> 36871.179 | K9: =+'[2]2월누계'!$Z$8/1000 -> 36527.701 | L9: =+K9-J9 -> -343.47802 | M9: =+'[3]2월누계'!$Z$8/1000 -> 38997.16 | N9: =+K9-M9 -> -2469.4586 | Q9: 물량 | R9: 수도권 | S9: =+[4]수도권!$T$5/1000 -> 67 | T9: =+[4]수도권!$U$5/1000 -> 66.767 | U9: =+T9-S9 -> -0.233 | V9: =+[5]수도권!$T$5/1000 -> 74.2395 | W9: =+T9-V9 -> -7.4725
D10: 골재 | E10: =+'[1]2월'!$AE$8/1000 -> 1053.0676 | F10: =+'[2]2월'!$AN$8/1000 -> 1044.5384 | G10: =+F10-E10 -> -8.5292454 | H10: =+'[3]2월'!$AN$8/1000 -> 1242.5835 | I10: =+F10-H10 -> -198.0451 | J10: =+'[1]2월누계'!$AE$8/1000 -> 2460.7562 | K10: =+'[2]2월누계'!$AN$8/1000 -> 2174.2788 | L10: =+K10-J10 -> -286.47745 | M10: =+'[3]2월누계'!$AN$8/1000 -> 2294.3315 | N10: =+K10-M10 -> -120.0527 | R10: 영남권 | S10: =+[4]영남권!$T$5/1000 -> 83.5 | T10: =+[4]영남권!$U$5/1000 -> 73.925 | U10: =+T10-S10 -> -9.575 | V10: =+[5]영남권!$T$5/1000 -> 95.894 | W10: =+T10-V10 -> -21.969
D11: 기타 | E11: =+'[1]2월'!$E$8/1000-E9-E33-E10 -> 123.53333 | F11: =+('[2]2월'!$BJ$8+'[2]2월'!$BA$8+'[2]2월'!$AP$8+'[2]2월'!$AH$8)/1000 -> 56.991226 | G11: =+F11-E11 -> -66.542107 | H11: =+'[3]2월'!$F$8/1000-H9-H33-H10 -> 164.51937 | I11: =+F11-H11 -> -107.52814 | J11: =+'[1]2월누계'!$E$8/1000-J9-J33-J10 -> 242.36667 | K11: =+('[2]2월누계'!$BJ$8+'[2]2월누계'!$BA$8+'[2]2월누계'!$AP$8+'[2]2월누계'!$AH$8)/1000 -> 109.3261 | L11: =+K11-J11 -> -133.04056 | M11: =+'[3]2월누계'!$F$8/1000-M9-M33-M10 -> 331.77197 | N11: =+K11-M11 -> -222.44586 | R11: 중부권 | S11: =+[4]중부권!$T$5/1000 -> 26.4998 | T11: =+[4]중부권!$U$5/1000 -> 29.317 | U11: =+T11-S11 -> 2.8172 | V11: =+[5]중부권!$T$5/1000 -> 40.6455 | W11: =+T11-V11 -> -11.3285
C12: 계 | E12: =SUM(E9:E11) -> 18975.168 | F12: =SUM(F9:F11) -> 18883.376 | G12: =+F12-E12 -> -91.792282 | H12: =SUM(H9:H11) -> 22429.871 | I12: =+F12-H12 -> -3546.4947 | J12: =SUM(J9:J11) -> 39574.302 | K12: =SUM(K9:K11) -> 38811.306 | L12: =+K12-J12 -> -762.99603 | M12: =SUM(M9:M11) -> 41623.263 | N12: =+K12-M12 -> -2811.9572 | Q12: 계 | S12: =SUM(S9:S11) -> 176.9998 | T12: =SUM(T9:T11) -> 170.009 | U12: =+T12-S12 -> -6.9908 | V12: =SUM(V9:V11) -> 210.779 | W12: =+T12-V12 -> -40.77
C13: 매출원가 | D13: 레미콘 | E13: =+('[1]2월'!$Z$10+'[1]2월'!$Z$19)/1000 -> 17104.216 | F13: =+('[2]2월'!$Z$10+'[2]2월'!$Z$19)/1000 -> 17308.862 | G13: =+F13-E13 -> 204.64547 | H13: =+('[3]2월'!$Z$10+'[3]2월'!$Z$19)/1000 -> 19459.467 | I13: =+F13-H13 -> -2150.6054 | J13: =+('[1]2월누계'!$Z$10+'[1]2월누계'!$Z$19)/1000 -> 35461.376 | K13: =+('[2]2월누계'!$Z$10+'[2]2월누계'!$Z$19)/1000 -> 35156.214 | L13: =+K13-J13 -> -305.16234 | M13: =+('[3]2월누계'!$Z$10+'[3]2월누계'!$Z$19)/1000 -> 36700.193 | N13: =+K13-M13 -> -1543.979 | Q13: 판매단가 | R13: 수도권 | S13: =+[4]수도권!$T$61 -> 98247.173 | T13: =+[4]수도권!$U$61 -> 102553.11 | U13: =+T13-S13 -> 4305.9384 | V13: =+[5]수도권!$Q$85 -> 96965.552 | W13: =+T13-V13 -> 5587.559
D14: 골재 | E14: =+('[1]2월'!$AE$10+'[1]2월'!$AE$19)/1000 -> 1117.0253 | F14: =+('[2]2월'!$AN$10+'[2]2월'!$AN$19)/1000 -> 1151.3959 | G14: =+F14-E14 -> 34.370579 | H14: =+('[3]2월'!$AN$10+'[3]2월'!$AN$19)/1000 -> 1294.0505 | I14: =+F14-H14 -> -142.65463 | J14: =+('[1]2월누계'!$AE$10+'[1]2월누계'!$AE$19)/1000 -> 2563.0946 | K14: =+('[2]2월누계'!$AN$10+'[2]2월누계'!$AN$19)/1000 -> 2404.6474 | L14: =+K14-J14 -> -158.44725 | M14: =+('[3]2월누계'!$AN$10+'[3]2월누계'!$AN$19)/1000 -> 2576.316 | N14: =+K14-M14 -> -171.66867 | R14: 영남권 | S14: =+[4]영남권!$T$61 -> 100395.73 | T14: =+[4]영남권!$U$61 -> 106159.44 | U14: =+T14-S14 -> 5763.7107 | V14: =+[5]영남권!$Q$85 -> 100787.78 | W14: =+T14-V14 -> 5371.6561
D15: 기타 | E15: =+('[1]2월'!$AL$10+'[1]2월'!$AL$19+'[1]2월'!$AV$10+'[1]2월'!$AV$19)/1000 -> 19.286963 | F15: =+('[2]2월'!$AH$10+'[2]2월'!$AH$19+'[2]2월'!$AP$10+'[2]2월'!$AP$19+'[2]2월'!$BA$10+'[2]2월'!$BA$19+'[2]2월'!$BJ$10+'[2]2월'!$BJ$19)/1000 -> -341.8475 | G15: =+F15-E15 -> -361.13446 | H15: =+('[3]2월'!$F$10+'[3]2월'!$F$19)/1000-H13-H14-('[3]2월'!$AO$10+'[3]2월'!$AO$19)/1000 -> 28.233255 | I15: =+F15-H15 -> -370.08075 | J15: =+('[1]2월누계'!$AL$10+'[1]2월누계'!$AL$19+'[1]2월누계'!$AV$10+'[1]2월누계'!$AV$19)/1000 -> 38.573926 | K15: =+('[2]2월누계'!$AH$10+'[2]2월누계'!$AH$19+'[2]2월누계'!$AP$10+'[2]2월누계'!$AP$19+'[2]2월누계'!$BA$10+'[2]2월누계'!$BA$19+'[2]2월누계'!$BJ$10+'[2]2월누계'!$BJ$19)/1000 -> -322.58392 | L15: =+K15-J15 -> -361.15784 | M15: =+('[3]2월누계'!$F$10+'[3]2월누계'!$F$19)/1000-M13-M14-('[3]2월누계'!$AO$10+'[3]2월누계'!$AO$19)/1000 -> 359.42361 | N15: =+K15-M15 -> -682.00753 | R15: 중부권 | S15: =+[4]중부권!$T$61 -> 106905.08 | T15: =+[4]중부권!$U$61 -> 105358.92 | U15: =+T15-S15 -> -1546.1532 | V15: =+[5]중부권!$Q$85 -> 102295.48 | W15: =+T15-V15 -> 3063.4438
C16: 계 | E16: =SUM(E13:E15) -> 18240.529 | F16: =SUM(F13:F15) -> 18118.41 | G16: =+F16-E16 -> -122.11841 | H16: =SUM(H13:H15) -> 20781.751 | I16: =+F16-H16 -> -2663.3408 | J16: =SUM(J13:J15) -> 38063.045 | K16: =SUM(K13:K15) -> 37238.277 | L16: =+K16-J16 -> -824.76744 | M16: =SUM(M13:M15) -> 39635.932 | N16: =+K16-M16 -> -2397.6552 | Q16: 계 | S16: =+[4]합계!$T$61 -> 100556.99 | T16: =+[4]합계!$U$61 -> 104606.76 | U16: =+T16-S16 -> 4049.7727 | V16: =+[5]합계!$Q$85 -> 99735.994 | W16: =+T16-V16 -> 4870.7689
C17: 매출이익 | D17: 레미콘 | E17: =+E9-E13 -> 694.35088 | F17: =+F9-F13 -> 472.98448 | G17: =+F17-E17 -> -221.3664 | H17: =+H9-H13 -> 1563.3005 | I17: =+F17-H17 -> -1090.316 | J17: =+J9-J13 -> 1409.8032 | K17: =+K9-K13 -> 1371.4876 | L17: =+K17-J17 -> -38.31568 | M17: =+M9-M13 -> 2296.9672 | N17: =+K17-M17 -> -925.47965 | Q17: 공헌이익 | R17: 수도권 | S17: =+[4]수도권!$Q$90 -> 14380.672 | T17: =+[4]수도권!$R$90 -> 14559.601 | U17: =+T17-S17 -> 178.92875 | V17: =+[5]수도권!$Q$90 -> 14691.292 | W17: =+T17-V17 -> -131.69112
D18: 골재 | E18: =+E10-E14 -> -63.957648 | F18: =+F10-F14 -> -106.85747 | G18: =+F18-E18 -> -42.899825 | H18: =+H10-H14 -> -51.467005 | I18: =+F18-H18 -> -55.390468 | J18: =+J10-J14 -> -102.33838 | K18: =+K10-K14 -> -230.36857 | L18: =+K18-J18 -> -128.03019 | M18: =+M10-M14 -> -281.98455 | N18: =+K18-M18 -> 51.615974 | R18: 영남권 | S18: =+[4]영남권!$Q$90 -> 18144.224 | T18: =+[4]영남권!$R$90 -> 21619.922 | U18: =+T18-S18 -> 3475.6982 | V18: =+[5]영남권!$Q$90 -> 20101.873 | W18: =+T18-V18 -> 1518.0493
D19: 기타 | E19: =+E11-E15 -> 104.24637 | F19: =+F11-F15 -> 398.83873 | G19: =+F19-E19 -> 294.59235 | H19: =+H11-H15 -> 136.28611 | I19: =+F19-H19 -> 262.55261 | J19: =+J11-J15 -> 203.79274 | K19: =+K11-K15 -> 431.91002 | L19: =+K19-J19 -> 228.11728 | M19: =+M11-M15 -> -27.651645 | N19: =+K19-M19 -> 459.56167 | R19: 중부권 | S19: =+[4]중부권!$Q$90 -> 24884.489 | T19: =+[4]중부권!$R$90 -> 20677.353 | U19: =+T19-S19 -> -4207.136 | V19: =+[5]중부권!$Q$90 -> 22532.494 | W19: =+T19-V19 -> -1855.1406
C20: 계 | E20: =SUM(E17:E19) -> 734.6396 | F20: =SUM(F17:F19) -> 764.96573 | G20: =+F20-E20 -> 30.326132 | H20: =SUM(H17:H19) -> 1648.1196 | I20: =+F20-H20 -> -883.1539 | J20: =SUM(J17:J19) -> 1511.2576 | K20: =SUM(K17:K19) -> 1573.029 | L20: =+K20-J20 -> 61.771409 | M20: =SUM(M17:M19) -> 1987.331 | N20: =+K20-M20 -> -414.302 | Q20: 계 | S20: =+[4]합계!$Q$90 -> 17728.73 | T20: =+[4]합계!$R$90 -> 18688.207 | U20: =+T20-S20 -> 959.47673 | V20: =+[5]합계!$Q$90 -> 18672.912 | W20: =+T20-V20 -> 15.295021
C21: 판관비 | D21: 레미콘 | E21: =+('[1]2월'!$Z$13+'[1]2월'!$Z$20+'[1]2월'!$Z$22)/1000 -> 1975.1272 | F21: =+('[2]2월'!$Z$13+'[2]2월'!$Z$20+'[2]2월'!$Z$22)/1000 -> 2817.4627 | G21: =+F21-E21 -> 842.33547 | H21: =+('[3]2월'!$Z$13+'[3]2월'!$Z$20+'[3]2월'!$Z$22)/1000 -> 1898.225 | I21: =+F21-H21 -> 919.2377 | J21: =+('[1]2월누계'!$Z$13+'[1]2월누계'!$Z$20+'[1]2월누계'!$Z$22)/1000 -> 4448.0507 | K21: =+('[2]2월누계'!$Z$13+'[2]2월누계'!$Z$20+'[2]2월누계'!$Z$22)/1000 -> 4718.4124 | L21: =+K21-J21 -> 270.3617 | M21: =+('[3]2월누계'!$Z$13+'[3]2월누계'!$Z$20+'[3]2월누계'!$Z$22)/1000 -> 4245.9444 | N21: =+K21-M21 -> 472.46799 | Q21: □ 골재
D22: 골재 | E22: =+('[1]2월'!$AE$13+'[1]2월'!$AE$20+'[1]2월'!$AE$22)/1000 -> 53.362179 | F22: =+('[2]2월'!$AN$13+'[2]2월'!$AN$20+'[2]2월'!$AN$22)/1000 -> 60.143505 | G22: =+F22-E22 -> 6.7813259 | H22: =+('[3]2월'!$AN$13+'[3]2월'!$AN$20+'[3]2월'!$AN$22)/1000 -> 46.67513 | I22: =+F22-H22 -> 13.468375 | J22: =+('[1]2월누계'!$AE$13+'[1]2월누계'!$AE$20+'[1]2월누계'!$AE$22)/1000 -> 103.47756 | K22: =+('[2]2월누계'!$AN$13+'[2]2월누계'!$AN$20+'[2]2월누계'!$AN$22)/1000 -> 106.90912 | L22: =+K22-J22 -> 3.4315649 | M22: =+('[3]2월누계'!$AN$13+'[3]2월누계'!$AN$20+'[3]2월누계'!$AN$22)/1000 -> 96.245044 | N22: =+K22-M22 -> 10.664079 | Q22: 구분 | S22: 계획 | T22: 실적 | U22: 계획대비 | V22: 전년 | W22: 전년대비
D23: 기타 | E23: =+('[1]2월'!$AL$13+'[1]2월'!$AV$13+'[1]2월'!$AL$20+'[1]2월'!$AV$20+'[1]2월'!$AL$22+'[1]2월'!$AV$22)/1000 -> 56.885059 | F23: =+('[2]2월'!$F$13+'[2]2월'!$F$20+'[2]2월'!$F$22)/1000-F21-F22-('[2]2월'!$AO$13+'[2]2월'!$AO$20+'[2]2월'!$AO$22)/1000 -> 57.01841 | G23: =+F23-E23 -> 0.133351 | H23: =+('[3]2월'!$F$13+'[3]2월'!$F$20+'[3]2월'!$F$22)/1000-H21-H22-('[3]2월'!$AO$13+'[3]2월'!$AO$20+'[3]2월'!$AO$22)/1000 -> 49.451233 | I23: =+F23-H23 -> 7.567177 | J23: =+('[1]2월누계'!$AL$13+'[1]2월누계'!$AV$13+'[1]2월누계'!$AL$20+'[1]2월누계'!$AV$20+'[1]2월누계'!$AL$22+'[1]2월누계'!$AV$22)/1000 -> 118.77012 | K23: =+('[2]2월누계'!$F$13+'[2]2월누계'!$F$20+'[2]2월누계'!$F$22)/1000-K21-K22-('[2]2월누계'!$AO$13+'[2]2월누계'!$AO$20+'[2]2월누계'!$AO$22)/1000 -> 120.19266 | L23: =+K23-J23 -> 1.422541 | M23: =+('[3]2월누계'!$F$13+'[3]2월누계'!$F$20+'[3]2월누계'!$F$22)/1000-M21-M22-('[3]2월누계'!$AO$13+'[3]2월누계'!$AO$20+'[3]2월누계'!$AO$22)/1000 -> 557.0322 | N23: =+K23-M23 -> -436.83954 | Q23: 판매량 | R23: 자가 | S23: =+[6]원가손익!$W$10+[7]원가손익!$U$27+[8]손익!$F$10 -> 35135.7 | T23: =+[6]원가손익!$X$10+[7]원가손익!$V$27+[8]손익!$G$10 -> 37530 | U23: =+T23-S23 -> 2394.2997 | V23: =+[9]원가손익!$X$10+[10]원가손익!$V$27+[11]손익!$Y$25 -> 31410 | W23: =+T23-V23 -> 6120
C24: 계 | E24: =SUM(E21:E23) -> 2085.3744 | F24: =SUM(F21:F23) -> 2934.6246 | G24: =+F24-E24 -> 849.25015 | H24: =SUM(H21:H23) -> 1994.3513 | I24: =+F24-H24 -> 940.27325 | J24: =SUM(J21:J23) -> 4670.2984 | K24: =SUM(K21:K23) -> 4945.5142 | L24: =+K24-J24 -> 275.2158 | M24: =SUM(M21:M23) -> 4899.2216 | N24: =+K24-M24 -> 46.292528 | R24: 외판 | S24: =+[6]원가손익!$W$14+[7]원가손익!$U$29+[8]손익!$F$12 -> 25160 | T24: =+[6]원가손익!$X$14+[7]원가손익!$V$29+[8]손익!$G$12 -> 13144 | U24: =+T24-S24 -> -12016 | V24: =+[9]원가손익!$X$14+[10]원가손익!$V$29+[11]손익!$Y$27 -> 26527 | W24: =+T24-V24 -> -13383
C25: 영업이익 | D25: 레미콘 | E25: =+E17-E21 -> -1280.7763 | F25: =+F17-F21 -> -2344.4782 | G25: =+F25-E25 -> -1063.7019 | H25: =+H17-H21 -> -334.92445 | I25: =+F25-H25 -> -2009.5537 | J25: =+J17-J21 -> -3038.2475 | K25: =+K17-K21 -> -3346.9248 | L25: =+K25-J25 -> -308.67738 | M25: =+M17-M21 -> -1948.9772 | N25: =+K25-M25 -> -1397.9476 | Q25: 합 계 | S25: =SUM(S23:S24) -> 60295.7 | T25: =SUM(T23:T24) -> 50674 | U25: =+T25-S25 -> -9621.7003 | V25: =SUM(V23:V24) -> 57937 | W25: =+T25-V25 -> -7263
D26: % | E26: =+E25/E9 -> -0.071959519 | F26: =+F25/F9 -> -0.13184673 | G26: =+F26-E26 -> -0.059887206 | H26: =+H25/H9 -> -0.015931511 | I26: =+F26-H26 -> -0.11591521 | J26: =+J25/J9 -> -0.082401689 | K26: =+K25/K9 -> -0.091627032 | L26: =+K26-J26 -> -0.0092253423 | M26: =+M25/M9 -> -0.049977414 | N26: =+K26-M26 -> -0.041649618 | Q26: □ 기타내역(영업이익)
D27: 골재 | E27: =+E18-E22 -> -117.31983 | F27: =+F18-F22 -> -167.00098 | G27: =+F27-E27 -> -49.68115 | H27: =+H18-H22 -> -98.142135 | I27: =+F27-H27 -> -68.858843 | J27: =+J18-J22 -> -205.81594 | K27: =+K18-K22 -> -337.2777 | L27: =+K27-J27 -> -131.46176 | M27: =+M18-M22 -> -378.22959 | N27: =+K27-M27 -> 40.951895 | Q27: 구분 | S27: 계획 | T27: 실적 | U27: 계획대비 | V27: 전년 | W27: 전년대비
D28: 기타 | E28: =+E19-E23 -> 47.361311 | F28: =+F19-F23 -> 341.82032 | G28: =+F28-E28 -> 294.459 | H28: =+H19-H23 -> 86.83488 | I28: =+F28-H28 -> 254.98544 | J28: =+J19-J23 -> 85.022623 | K28: =+K19-K23 -> 311.71736 | L28: =+K28-J28 -> 226.69474 | M28: =+M19-M23 -> -584.68384 | N28: =+K28-M28 -> 896.40121 | Q28: 레미콘임대 | S28: =+'사업장별(당월)'!T32 -> 29.628698 | T28: =+'사업장별(당월)'!U32 -> 23.702033 | U28: =+T28-S28 -> -5.9266647 | V28: =+'사업장별(당월)'!W32 -> 72.530954 | W28: =+T28-V28 -> -48.828921
C29: 계 | E29: =+E25+E27+E28 -> -1350.7348 | F29: =+F25+F27+F28 -> -2169.6589 | G29: =+F29-E29 -> -818.92401 | H29: =+H25+H27+H28 -> -346.23171 | I29: =+F29-H29 -> -1823.4272 | J29: =+J25+J27+J28 -> -3159.0408 | K29: =+K25+K27+K28 -> -3372.4852 | L29: =+K29-J29 -> -213.4444 | M29: =+M25+M27+M28 -> -2911.8906 | N29: =+K29-M29 -> -460.59453 | Q29: 임대 | S29: =+'사업장별(당월)'!T33 -> 72.847673 | T29: =+'사업장별(당월)'!U33 -> 4.800373 | U29: =+T29-S29 -> -68.0473 | V29: =+'사업장별(당월)'!W33 -> 61.899625 | W29: =+T29-V29 -> -57.099252
D30: % | E30: =+E29/E12 -> -0.071184341 | F30: =+F29/F12 -> -0.11489783 | G30: =+F30-E30 -> -0.043713486 | H30: =+H29/H12 -> -0.015436188 | I30: =+F30-H30 -> -0.099461639 | J30: =+J29/J12 -> -0.079825559 | K30: =+K29/K12 -> -0.0868944 | L30: =+K30-J30 -> -0.0070688417 | M30: =+M29/M12 -> -0.069958249 | N30: =+K30-M30 -> -0.016936151 | Q30: 공통비 | S30: =+'사업장별(당월)'!T34 -> -1285.2974 | T30: =+'사업장별(당월)'!U34 -> -1962.6589 | U30: =+T30-S30 -> -677.36148 | V30: =+'사업장별(당월)'!W34 -> -1276.8971 | W30: =+T30-V30 -> -685.76176
C31: * 건자재 | Q31: 기타 | S31: =+S32-S28-S29-S30 -> -55.115059 | T31: =+T32-T28-T29-T30 -> 313.31791 | U31: =+T31-S31 -> 368.43297 | V31: =+V32-V28-V29-V30 -> -47.595699 | W31: =+T31-V31 -> 360.91361
C32: 물량 | E32: =+IFERROR(HLOOKUP($E$5,[12]손익!$G$5:$AI$54,2,),) -> 7000 | F32: =+'[2]2월'!$AO$7 -> 4982.936 | G32: =+F32-E32 -> -2017.064 | H32: =+'[3]2월'!$AO$7 -> 9724.523 | I32: =+F32-H32 -> -4741.587 | J32: =+'[1]2월누계'!$AA$7 -> 15000 | K32: =+'[2]2월누계'!$AO$7 -> 9952.774 | L32: =+K32-J32 -> -5047.226 | M32: =+'[3]2월누계'!$AO$7 -> 18460.025 | N32: =+K32-M32 -> -8507.251 | Q32: 합계 | S32: =+'사업장별(당월)'!T40 -> -1237.9361 | T32: =+'사업장별(당월)'!U40 -> -1620.8385 | U32: =+T32-S32 -> -382.90248 | V32: =+'사업장별(당월)'!W40 -> -1190.0622 | W32: =+T32-V32 -> -430.77632
C33: 매출 | E33: =+IFERROR(HLOOKUP($E$5,[12]손익!$G$5:$AI$54,3,),)/1000 -> 6724.6123 | F33: =+'[2]2월'!$AO$8/1000 -> 4876.7031 | G33: =+F33-E33 -> -1847.9092 | H33: =+'[3]2월'!$AO$8/1000 -> 8276.9951 | I33: =+F33-H33 -> -3400.292 | J33: =+'[1]2월누계'!$AA$8/1000 -> 14389.456 | K33: =+'[2]2월누계'!$AO$8/1000 -> 9976.5899 | L33: =+K33-J33 -> -4412.8659 | M33: =+'[3]2월누계'!$AO$8/1000 -> 15757.115 | N33: =+K33-M33 -> -5780.525
C34: 매출이익 | E34: =+IFERROR(HLOOKUP($E$5,[12]손익!$G$5:$AI$54,7,),)/1000 -> 137.59374 | F34: =+'[2]2월'!$AO$12/1000 -> 140.69123 | G34: =+F34-E34 -> 3.097497 | H34: =+'[3]2월'!$AO$12/1000 -> 149.66104 | I34: =+F34-H34 -> -8.969808 | J34: =+'[1]2월누계'!$AA$12/1000 -> 305.39212 | K34: =+'[2]2월누계'!$AO$12/1000 -> 268.62131 | L34: =+K34-J34 -> -36.770807 | M34: =+'[3]2월누계'!$AO$12/1000 -> 295.57154 | N34: =+K34-M34 -> -26.950222 | Q34: □ 건자재
C35: (%) | E35: =+E34/E33 -> 0.020461215 | F35: =+F34/F33 -> 0.028849662 | G35: =+F35-E35 -> 0.0083884469 | H35: =+H34/H33 -> 0.018081567 | I35: =+I34/I33 -> 0.0026379523 | J35: =+J34/J33 -> 0.021223327 | K35: =+K34/K33 -> 0.026925164 | L35: =+K35-J35 -> 0.0057018369 | M35: =+M34/M33 -> 0.018757973 | N35: =+K35-M35 -> 0.0081671904 | Q35: 구분 | S35: 계획 | T35: 실적 | U35: 계획대비 | V35: 전년 | W35: 전년대비
C36: 영업이익 | E36: =+IFERROR(HLOOKUP($E$5,[12]손익!$G$5:$AI$54,20,),)/1000 -> -36.496143 | F36: =+'[2]2월'!$AO$26/1000 -> -81.299122 | G36: =+F36-E36 -> -44.802979 | H36: =+'[3]2월'!$AO$26/1000 -> 10.861713 | I36: =+F36-H36 -> -92.160835 | J36: =+'[1]2월누계'!$AA$26/1000 -> -82.713736 | K36: =+'[2]2월누계'!$AO$26/1000 -> -120.11452 | L36: =+K36-J36 -> -37.400787 | M36: =+'[3]2월누계'!$AO$26/1000 -> 12.558962 | N36: =+K36-M36 -> -132.67349 | Q36: 철강재 판매단가 | S36: =+'[13]2월'!$F$10 -> 742142.86 | T36: =+'[13]2월'!$G$10 -> 790996.73 | U36: =+T36-S36 -> 48853.873 | V36: =+'[14]2월'!$G$10 -> 744684.73 | W36: =+T36-V36 -> 46312.001
C37: (%) | E37: =+E36/E33 -> -0.0054272486 | F37: =+F36/F33 -> -0.016670919 | G37: =+F37-E37 -> -0.01124367 | H37: =+H36/H33 -> 0.0013122773 | I37: =+F37-H37 -> -0.017983196 | J37: =+J36/J33 -> -0.0057482185 | K37: =+K36/K33 -> -0.012039637 | L37: =+K37-J37 -> -0.0062914188 | M37: =+M36/M33 -> 0.00079703437 | N37: =+K37-M37 -> -0.012836672 | Q37: 철강재 마진률 | S37: =+'[13]2월'!$F$15 -> 0.014148219 | T37: =+'[13]2월'!$G$15 -> 0.025730287 | U37: =+T37-S37 -> 0.011582067 | V37: =+'[14]2월'!$G$15 -> 0.015585145 | W37: =+T37-V37 -> 0.010145141
E39: =+'[1]2월'!$E$26/1000 -> -1387.231 | F39: =+'[2]2월'!$F$26/1000 -> -2250.958 | H39: =+'[3]2월'!$F$26/1000 -> -335.37 | J39: =+'[1]2월누계'!$E$26/1000 -> -3241.7545 | K39: =+'[2]2월누계'!$F$26/1000 -> -3492.5997 | M39: =+'[3]2월누계'!$F$26/1000 -> -2899.3317
E40: =+(E29+E36)-E39 -> 0 | F40: =+(F29+F36)-F39 -> 0 | H40: =+(H29+H36)-H39 -> -1.1937118e-12 | J40: =+(J29+J36)-J39 -> 0 | K40: =+(K29+K36)-K39 -> 0 | M40: =+(M29+M36)-M39 -> 0

Sheet 레미콘 영업이익
H3: □ 레미콘 영업이익(2월)
H5: 구분 | J5: 2월 | T5: 2월누계
J6: 영업이익(공통비 배부전) | O6: 영업이익(공통비 배부후) | T6: 영업이익(공통비 배부전) | Y6: 영업이익(공통비 배부전)
A7: 2024년 1월 마감 손익 | J7: 계획 | K7: 실적 | L7: 차이 | M7: 전년 | N7: 차이 | O7: 계획 | P7: 실적 | Q7: 차이 | R7: 전년 | S7: 차이 | T7: 계획 | U7: 실적 | V7: 차이 | W7: 전년 | X7: 차이 | Y7: 계획 | Z7: 실적 | AA7: 차이 | AB7: 전년 | AC7: 차이
B8: 안양 | H8: 레미콘 | I8: 안양 | J8: =+[4]안양!$H$86/1000 -> 111.30886 | K8: =+[4]안양!$I$86/1000 -> 153.40702 | L8: =+K8-J8 -> 42.098164 | M8: =+[5]안양!$H$86/1000 -> 265.58446 | N8: =+K8-M8 -> -112.17744 | O8: =+[4]안양!$H$92/1000 -> -80.428067 | P8: =+[4]안양!$I$92/1000 -> -175.96858 | Q8: =+P8-O8 -> -95.540511 | R8: =+[5]안양!$H$92/1000 -> 65.846897 | S8: =+P8-R8 -> -241.81548 | T8: =+[15]안양!$H$86/1000 -> 285.75343 | U8: =+[15]안양!$I$86/1000 -> 384.63904 | V8: =+U8-T8 -> 98.885606 | W8: =+[16]안양!$H$86/1000 -> 353.64214 | X8: =+U8-W8 -> 30.996892 | Y8: =+[15]안양!$H$92/1000 -> -168.69472 | Z8: =+[15]안양!$I$92/1000 -> -160.89499 | AA8: =+Z8-Y8 -> 7.7997284 | AB8: =+[16]안양!$H$92/1000 -> -87.162062 | AC8: =+Z8-AB8 -> -73.732932
B9: 인천 | H9: 직영 | I9: 인천 | J9: =+[4]인천!$H$86/1000 -> -35.878112 | K9: =+[4]인천!$I$86/1000 -> -78.239109 | L9: =+K9-J9 -> -42.360997 | M9: =+[5]인천!$H$86/1000 -> -49.38036 | N9: =+K9-M9 -> -28.858749 | O9: =+[4]인천!$H$92/1000 -> -190.07915 | P9: =+[4]인천!$I$92/1000 -> -318.23393 | Q9: =+P9-O9 -> -128.15478 | R9: =+[5]인천!$H$92/1000 -> -173.11322 | S9: =+P9-R9 -> -145.12071 | T9: =+[15]인천!$H$86/1000 -> -65.318117 | U9: =+[15]인천!$I$86/1000 -> -108.80581 | V9: =+U9-T9 -> -43.487692 | W9: =+[16]인천!$H$86/1000 -> -176.5301 | X9: =+U9-W9 -> 67.724293 | Y9: =+[15]인천!$H$92/1000 -> -448.4643 | Z9: =+[15]인천!$I$92/1000 -> -492.77106 | AA9: =+Z9-Y9 -> -44.306763 | AB9: =+[16]인천!$H$92/1000 -> -442.98955 | AC9: =+Z9-AB9 -> -49.781512
B10: 파주 | I10: 파주 | J10: =+[4]파주!$H$86/1000 -> -120.66919 | K10: =+[4]파주!$I$86/1000 -> -146.03662 | L10: =+K10-J10 -> -25.367431 | M10: =+[5]파주!$H$86/1000 -> -42.738868 | N10: =+K10-M10 -> -103.29775 | O10: =+[4]파주!$H$92/1000 -> -179.92701 | P10: =+[4]파주!$I$92/1000 -> -235.61139 | Q10: =+P10-O10 -> -55.684372 | R10: =+[5]파주!$H$92/1000 -> -102.82798 | S10: =+P10-R10 -> -132.7834 | T10: =+[15]파주!$H$86/1000 -> -208.53352 | U10: =+[15]파주!$I$86/1000 -> -263.56188 | V10: =+U10-T10 -> -55.028358 | W10: =+[16]파주!$H$86/1000 -> -149.28401 | X10: =+U10-W10 -> -114.27787 | Y10: =+[15]파주!$H$92/1000 -> -354.29529 | Z10: =+[15]파주!$I$92/1000 -> -401.71545 | AA10: =+Z10-Y10 -> -47.42016 | AB10: =+[16]파주!$H$92/1000 -> -280.73918 | AC10: =+Z10-AB10 -> -120.97628
B11: 김포 | I11: 김포 | J11: =+[4]김포!$H$86/1000 -> -38.987187 | K11: =+[4]김포!$I$86/1000 -> -121.40124 | L11: =+K11-J11 -> -82.414057 | M11: =+[5]김포!$H$86/1000 -> -46.86888 | N11: =+K11-M11 -> -74.532364 | O11: =+[4]김포!$H$92/1000 -> -95.48628 | P11: =+[4]김포!$I$92/1000 -> -202.86892 | Q11: =+P11-O11 -> -107.38265 | R11: =+[5]김포!$H$92/1000 -> -88.504562 | S11: =+P11-R11 -> -114.36436 | T11: =+[15]김포!$H$86/1000 -> -96.434709 | U11: =+[15]김포!$I$86/1000 -> -220.93077 | V11: =+U11-T11 -> -124.49606 | W11: =+[16]김포!$H$86/1000 -> -154.20578 | X11: =+U11-W11 -> -66.724997 | Y11: =+[15]김포!$H$92/1000 -> -226.47483 | Z11: =+[15]김포!$I$92/1000 -> -344.61704 | AA11: =+Z11-Y11 -> -118.14221 | AB11: =+[16]김포!$H$92/1000 -> -242.71433 | AC11: =+Z11-AB11 -> -101.90271
B12: 부산 | I12: 부산 | J12: =+[4]부산!$H$86/1000 -> 74.964892 | K12: =+[4]부산!$I$86/1000 -> 207.73551 | L12: =+K12-J12 -> 132.77062 | M12: =+[5]부산!$H$86/1000 -> 133.31258 | N12: =+K12-M12 -> 74.42293 | O12: =+[4]부산!$H$92/1000 -> -53.505452 | P12: =+[4]부산!$I$92/1000 -> -50.493193 | Q12: =+P12-O12 -> 3.0122584 | R12: =+[5]부산!$H$92/1000 -> 20.797695 | S12: =+P12-R12 -> -71.290889 | T12: =+[15]부산!$H$86/1000 -> 161.17328 | U12: =+[15]부산!$I$86/1000 -> 480.14891 | V12: =+U12-T12 -> 318.97563 | W12: =+[16]부산!$H$86/1000 -> 160.24382 | X12: =+U12-W12 -> 319.90509 | Y12: =+[15]부산!$H$92/1000 -> -152.97171 | Z12: =+[15]부산!$I$92/1000 -> 44.207976 | AA12: =+Z12-Y12 -> 197.17969 | AB12: =+[16]부산!$H$92/1000 -> -87.469863 | AC12: =+Z12-AB12 -> 131.67784
B13: 서부산 | I13: 서부산 | J13: =+[4]서부산!$H$86/1000 -> 118.33251 | K13: =+[4]서부산!$I$86/1000 -> -5.990017 | L13: =+K13-J13 -> -124.32253 | M13: =+[5]서부산!$H$86/1000 -> 77.502494 | N13: =+K13-M13 -> -83.492511 | O13: =+[4]서부산!$H$92/1000 -> -0.98819839 | P13: =+[4]서부산!$I$92/1000 -> -142.64957 | Q13: =+P13-O13 -> -141.66137 | R13: =+[5]서부산!$H$92/1000 -> -29.159798 | S13: =+P13-R13 -> -113.48978 | T13: =+[15]서부산!$H$86/1000 -> 257.03376 | U13: =+[15]서부산!$I$86/1000 -> 178.5332 | V13: =+U13-T13 -> -78.500552 | W13: =+[16]서부산!$H$86/1000 -> 112.66153 | X13: =+U13-W13 -> 65.871677 | Y13: =+[15]서부산!$H$92/1000 -> -34.567418 | Z13: =+[15]서부산!$I$92/1000 -> -80.634449 | AA13: =+Z13-Y13 -> -46.06703 | AB13: =+[16]서부산!$H$92/1000 -> -108.03428 | AC13: =+Z13-AB13 -> 27.39983
B14: 김해 | I14: 김해 | J14: =+[4]김해!$H$86/1000 -> -14.53489 | K14: =+[4]김해!$I$86/1000 -> -36.280646 | L14: =+K14-J14 -> -21.745756 | M14: =+[5]김해!$H$86/1000 -> -73.487828 | N14: =+K14-M14 -> 37.207182 | O14: =+[4]김해!$H$92/1000 -> -65.592605 | P14: =+[4]김해!$I$92/1000 -> -97.526505 | Q14: =+P14-O14 -> -31.9339 | R14: =+[5]김해!$H$92/1000 -> -101.92556 | S14: =+P14-R14 -> 4.3990581 | T14: =+[15]김해!$H$86/1000 -> -71.551453 | U14: =+[15]김해!$I$86/1000 -> -131.5109 | V14: =+U14-T14 -> -59.959447 | W14: =+[16]김해!$H$86/1000 -> -137.97555 | X14: =+U14-W14 -> 6.464649 | Y14: =+[15]김해!$H$92/1000 -> -185.79399 | Z14: =+[15]김해!$I$92/1000 -> -220.94789 | AA14: =+Z14-Y14 -> -35.1539 | AB14: =+[16]김해!$H$92/1000 -> -212.46842 | AC14: =+Z14-AB14 -> -8.4794737
B15: 정관 | I15: 정관 | J15: =+[4]정관!$H$86/1000 -> 71.756078 | K15: =+[4]정관!$I$86/1000 -> -47.580852 | L15: =+K15-J15 -> -119.33693 | M15: =+[5]정관!$H$86/1000 -> 150.8114 | N15: =+K15-M15 -> -198.39225 | O15: =+[4]정관!$H$92/1000 -> -62.258638 | P15: =+[4]정관!$I$92/1000 -> -176.96721 | Q15: =+P15-O15 -> -114.70857 | R15: =+[5]정관!$H$92/1000 -> 31.124671 | S15: =+P15-R15 -> -208.09188 | T15: =+[15]정관!$H$86/1000 -> 136.07842 | U15: =+[15]정관!$I$86/1000 -> -113.65395 | V15: =+U15-T15 -> -249.73237 | W15: =+[16]정관!$H$86/1000 -> 245.21989 | X15: =+U15-W15 -> -358.87384 | Y15: =+[15]정관!$H$92/1000 -> -179.52093 | Z15: =+[15]정관!$I$92/1000 -> -313.58174 | AA15: =+Z15-Y15 -> -134.06081 | AB15: =+[16]정관!$H$92/1000 -> -30.14338 | AC15: =+Z15-AB15 -> -283.43836
B16: 양산 | I16: 양산 | J16: =+[4]양산!$H$86/1000 -> -26.949417 | K16: =+[4]양산!$I$86/1000 -> -66.233686 | L16: =+K16-J16 -> -39.284269 | M16: =+[5]양산!$H$86/1000 -> 32.887764 | N16: =+K16-M16 -> -99.12145 | O16: =+[4]양산!$H$92/1000 -> -69.933627 | P16: =+[4]양산!$I$92/1000 -> -107.03815 | Q16: =+P16-O16 -> -37.104523 | R16: =+[5]양산!$H$92/1000 -> -16.754585 | S16: =+P16-R16 -> -90.283565 | T16: =+[15]양산!$H$86/1000 -> -71.146107 | U16: =+[15]양산!$I$86/1000 -> -95.344321 | V16: =+U16-T16 -> -24.198214 | W16: =+[16]양산!$H$86/1000 -> -17.321488 | X16: =+U16-W16 -> -78.022833 | Y16: =+[15]양산!$H$92/1000 -> -169.07611 | Z16: =+[15]양산!$I$92/1000 -> -171.2097 | AA16: =+Z16-Y16 -> -2.1335865 | AB16: =+[16]양산!$H$92/1000 -> -117.38996 | AC16: =+Z16-AB16 -> -53.819733
B17: 창원 | I17: 창원 | J17: =+[4]창원!$H$86/1000 -> -6.3142939 | K17: =+[4]창원!$I$86/1000 -> -25.872475 | L17: =+K17-J17 -> -19.558181 | M17: =+[5]창원!$H$86/1000 -> 108.75022 | N17: =+K17-M17 -> -134.6227 | O17: =+[4]창원!$H$92/1000 -> -68.490085 | P17: =+[4]창원!$I$92/1000 -> -126.50703 | Q17: =+P17-O17 -> -58.016948 | R17: =+[5]창원!$H$92/1000 -> 40.647485 | S17: =+P17-R17 -> -167.15452 | T17: =+[15]창원!$H$86/1000 -> -41.279721 | U17: =+[15]창원!$I$86/1000 -> -18.894895 | V17: =+U17-T17 -> 22.384826 | W17: =+[16]창원!$H$86/1000 -> 115.95934 | X17: =+U17-W17 -> -134.85424 | Y17: =+[15]창원!$H$92/1000 -> -183.5827 | Z17: =+[15]창원!$I$92/1000 -> -172.14568 | AA17: =+Z17-Y17 -> 11.437019 | AB17: =+[16]창원!$H$92/1000 -> -37.717401 | AC17: =+Z17-AB17 -> -134.42828
B18: 대구 | I18: 대구 | J18: =+[4]대구!$H$86/1000 -> -25.107902 | K18: =+[4]대구!$I$86/1000 -> -89.101347 | L18: =+K18-J18 -> -63.993445 | M18: =+[5]대구!$H$86/1000 -> 11.519029 | N18: =+K18-M18 -> -100.62038 | O18: =+[4]대구!$H$92/1000 -> -68.829246 | P18: =+[4]대구!$I$92/1000 -> -132.07503 | Q18: =+P18-O18 -> -63.245788 | R18: =+[5]대구!$H$92/1000 -> -43.826267 | S18: =+P18-R18 -> -88.248767 | T18: =+[15]대구!$H$86/1000 -> -74.589893 | U18: =+[15]대구!$I$86/1000 -> -182.91056 | V18: =+U18-T18 -> -108.32067 | W18: =+[16]대구!$H$86/1000 -> 33.549731 | X18: =+U18-W18 -> -216.46029 | Y18: =+[15]대구!$H$92/1000 -> -174.97831 | Z18: =+[15]대구!$I$92/1000 -> -243.20318 | AA18: =+Z18-Y18 -> -68.224863 | AB18: =+[16]대구!$H$92/1000 -> -108.92876 | AC18: =+Z18-AB18 -> -134.27441
B19: 울산 | I19: 울산 | J19: =+[4]울산!$H$86/1000 -> -81.807409 | K19: =+[4]울산!$I$86/1000 -> 11.388659 | L19: =+K19-J19 -> 93.196068 | M19: =+[5]울산!$H$86/1000 -> 78.01652 | N19: =+K19-M19 -> -66.627861 | O19: =+[4]울산!$H$92/1000 -> -124.96358 | P19: =+[4]울산!$I$92/1000 -> -106.82256 | Q19: =+P19-O19 -> 18.141023 | R19: =+[5]울산!$H$92/1000 -> 12.336041 | S19: =+P19-R19 -> -119.1586 | T19: =+[15]울산!$H$86/1000 -> -127.70622 | U19: =+[15]울산!$I$86/1000 -> 95.465084 | V19: =+U19-T19 -> 223.1713 | W19: =+[16]울산!$H$86/1000 -> 135.74101 | X19: =+U19-W19 -> -40.275924 | Y19: =+[15]울산!$H$92/1000 -> -245.83913 | Z19: =+[15]울산!$I$92/1000 -> -104.12617 | AA19: =+Z19-Y19 -> 141.71296 | AB19: =+[16]울산!$H$92/1000 -> -21.440051 | AC19: =+Z19-AB19 -> -82.686123
B20: 아산 | I20: 아산 | J20: =+[4]아산!$H$86/1000 -> -64.53117 | K20: =+[4]아산!$I$86/1000 -> -9.287506 | L20: =+K20-J20 -> 55.243664 | M20: =+[5]아산!$H$86/1000 -> 71.697309 | N20: =+K20-M20 -> -80.984815 | O20: =+[4]아산!$H$92/1000 -> -133.77131 | P20: =+[4]아산!$I$92/1000 -> -185.06286 | Q20: =+P20-O20 -> -51.291546 | R20: =+[5]아산!$H$92/1000 -> -33.606403 | S20: =+P20-R20 -> -151.45645 | T20: =+[15]아산!$H$86/1000 -> -128.78124 | U20: =+[15]아산!$I$86/1000 -> -5.431116 | V20: =+U20-T20 -> 123.35012 | W20: =+[16]아산!$H$86/1000 -> 40.915752 | X20: =+U20-W20 -> -46.346868 | Y20: =+[15]아산!$H$92/1000 -> -288.32273 | Z20: =+[15]아산!$I$92/1000 -> -278.7498 | AA20: =+Z20-Y20 -> 9.5729386 | AB20: =+[16]아산!$H$92/1000 -> -217.53514 | AC20: =+Z20-AB20 -> -61.214656
B21: 전주 | I21: 전주 | J21: =+[4]전주!$H$86/1000 -> -28.142013 | K21: =+[4]전주!$I$86/1000 -> -75.588009 | L21: =+K21-J21 -> -47.445996 | M21: =+[5]전주!$H$86/1000 -> 149.1804 | N21: =+K21-M21 -> -224.76841 | O21: =+[4]전주!$H$92/1000 -> -70.968907 | P21: =+[4]전주!$I$92/1000 -> -144.89662 | Q21: =+P21-O21 -> -73.92771 | R21: =+[5]전주!$H$92/1000 -> 74.945889 | S21: =+P21-R21 -> -219.84251 | T21: =+[15]전주!$H$86/1000 -> -71.759243 | U21: =+[15]전주!$I$86/1000 -> -91.461026 | V21: =+U21-T21 -> -19.701783 | W21: =+[16]전주!$H$86/1000 -> 252.88457 | X21: =+U21-W21 -> -344.34559 | Y21: =+[15]전주!$H$92/1000 -> -161.25189 | Z21: =+[15]전주!$I$92/1000 -> -214.64861 | AA21: =+Z21-Y21 -> -53.396727 | AB21: =+[16]전주!$H$92/1000 -> 75.110594 | AC21: =+Z21-AB21 -> -289.75921
B22: 군산 | I22: 군산 | J22: =+[4]군산!$H$86/1000 -> 11.36952 | K22: =+[4]군산!$I$86/1000 -> -20.390283 | L22: =+K22-J22 -> -31.759803 | M22: =+[5]군산!$H$86/1000 -> 57.866905 | N22: =+K22-M22 -> -78.257188 | O22: =+[4]군산!$H$92/1000 -> -8.9328669 | P22: =+[4]군산!$I$92/1000 -> -43.852418 | Q22: =+P22-O22 -> -34.919551 | R22: =+[5]군산!$H$92/1000 -> 33.365198 | S22: =+P22-R22 -> -77.217616 | T22: =+[15]군산!$H$86/1000 -> 17.596197 | U22: =+[15]군산!$I$86/1000 -> -16.544515 | V22: =+U22-T22 -> -34.140712 | W22: =+[16]군산!$H$86/1000 -> 67.924105 | X22: =+U22-W22 -> -84.46862 | Y22: =+[15]군산!$H$92/1000 -> -29.184083 | Z22: =+[15]군산!$I$92/1000 -> -55.956934 | AA22: =+Z22-Y22 -> -26.77285 | AB22: =+[16]군산!$H$92/1000 -> 17.272949 | AC22: =+Z22-AB22 -> -73.229882
B23: 원주 | I23: 원주 | J23: =+[4]원주!$H$86/1000 -> 33.348804 | K23: =+[4]원주!$I$86/1000 -> -24.850722 | L23: =+K23-J23 -> -58.199526 | M23: =+[5]원주!$H$86/1000 -> -36.517007 | N23: =+K23-M23 -> 11.666285 | O23: =+[4]원주!$H$92/1000 -> 9.1941198 | P23: =+[4]원주!$I$92/1000 -> -45.341208 | Q23: =+P23-O23 -> -54.535328 | R23: =+[5]원주!$H$92/1000 -> -44.695248 | S23: =+P23-R23 -> -0.64596001 | T23: =+[15]원주!$H$86/1000 -> 51.635532 | U23: =+[15]원주!$I$86/1000 -> -17.716925 | V23: =+U23-T23 -> -69.352457 | W23: =+[16]원주!$H$86/1000 -> -40.546711 | X23: =+U23-W23 -> 22.829786 | Y23: =+[15]원주!$H$92/1000 -> -4.0151757 | Z23: =+[15]원주!$I$92/1000 -> -55.51779 | AA23: =+Z23-Y23 -> -51.502614 | AB23: =+[16]원주!$H$92/1000 -> -70.849277 | AC23: =+Z23-AB23 -> 15.331487
B24: 제주 | I24: 제주 | J24: =+[4]제주!$H$86/1000 -> 26.361966 | K24: =+[4]제주!$I$86/1000 -> -7.498015 | L24: =+K24-J24 -> -33.859981 | M24: =+[5]제주!$H$86/1000 -> 53.836508 | N24: =+K24-M24 -> -61.334523 | O24: =+[4]제주!$H$92/1000 -> -15.815418 | P24: =+[4]제주!$I$92/1000 -> -52.563021 | Q24: =+P24-O24 -> -36.747603 | R24: =+[5]제주!$H$92/1000 -> 20.425297 | S24: =+P24-R24 -> -72.988317 | T24: =+[15]제주!$H$86/1000 -> 77.498136 | U24: =+[15]제주!$I$86/1000 -> -4.859883 | V24: =+U24-T24 -> -82.358019 | W24: =+[16]제주!$H$86/1000 -> 122.23265 | X24: =+U24-W24 -> -127.09254 | Y24: =+[15]제주!$H$92/1000 -> -31.214125 | Z24: =+[15]제주!$I$92/1000 -> -80.412318 | AA24: =+Z24-Y24 -> -49.198193 | AB24: =+[16]제주!$H$92/1000 -> 24.220917 | AC24: =+Z24-AB24 -> -104.63323
I25: 수도권 | J25: =SUM(J8:J11) -> -84.22563 | K25: =SUM(K8:K11) -> -192.26995 | L25: =+K25-J25 -> -108.04432 | M25: =SUM(M8:M11) -> 126.59635 | N25: =+K25-M25 -> -318.8663 | O25: =SUM(O8:O11) -> -545.92052 | P25: =SUM(P8:P11) -> -932.68282 | Q25: =+P25-O25 -> -386.76231 | R25: =SUM(R8:R11) -> -298.59887 | S25: =+P25-R25 -> -634.08396 | T25: =SUM(T8:T11) -> -84.532918 | U25: =SUM(U8:U11) -> -208.65943 | V25: =+U25-T25 -> -124.12651 | W25: =SUM(W8:W11) -> -126.37775 | X25: =+U25-W25 -> -82.281677 | Y25: =SUM(Y8:Y11) -> -1197.9291 | Z25: =SUM(Z8:Z11) -> -1399.9986 | AA25: =+Z25-Y25 -> -202.0694 | AB25: =SUM(AB8:AB11) -> -1053.6051 | AC25: =+Z25-AB25 -> -346.39343
I26: 영남권 | J26: =SUM(J12:J19) -> 110.33957 | K26: =SUM(K12:K19) -> -51.934856 | L26: =+K26-J26 -> -162.27442 | M26: =SUM(M12:M19) -> 519.31218 | N26: =+K26-M26 -> -571.24703 | O26: =SUM(O12:O19) -> -514.56144 | P26: =SUM(P12:P19) -> -940.07926 | Q26: =+P26-O26 -> -425.51782 | R26: =SUM(R12:R19) -> -86.76032 | S26: =+P26-R26 -> -853.31894 | T26: =SUM(T12:T19) -> 168.01206 | U26: =SUM(U12:U19) -> 211.83257 | V26: =+U26-T26 -> 43.820508 | W26: =SUM(W12:W19) -> 648.07827 | X26: =+U26-W26 -> -436.2457 | Y26: =SUM(Y12:Y19) -> -1326.3303 | Z26: =SUM(Z12:Z19) -> -1261.6408 | AA26: =+Z26-Y26 -> 64.689471 | AB26: =SUM(AB12:AB19) -> -723.59212 | AC26: =+Z26-AB26 -> -538.04872
I27: 중부권 | J27: =SUM(J20:J24) -> -21.592893 | K27: =SUM(K20:K24) -> -137.61454 | L27: =+K27-J27 -> -116.02164 | M27: =SUM(M20:M24) -> 296.06412 | N27: =+K27-M27 -> -433.67865 | O27: =SUM(O20:O24) -> -220.29438 | P27: =SUM(P20:P24) -> -471.71612 | Q27: =+P27-O27 -> -251.42174 | R27: =SUM(R20:R24) -> 50.434732 | S27: =+P27-R27 -> -522.15085 | T27: =SUM(T20:T24) -> -53.810619 | U27: =SUM(U20:U24) -> -136.01346 | V27: =+U27-T27 -> -82.202846 | W27: =SUM(W20:W24) -> 443.41036 | X27: =+U27-W27 -> -579.42383 | Y27: =SUM(Y20:Y24) -> -513.988 | Z27: =SUM(Z20:Z24) -> -685.28545 | AA27: =+Z27-Y27 -> -171.29745 | AB27: =SUM(AB20:AB24) -> -171.77996 | AC27: =+Z27-AB27 -> -513.50549
H28: 레미콘 계 | J28: =SUM(J25:J27) -> 4.5210444 | K28: =SUM(K25:K27) -> -381.81934 | L28: =+K28-J28 -> -386.34039 | M28: =SUM(M25:M27) -> 941.97265 | N28: =+K28-M28 -> -1323.792 | O28: =SUM(O25:O27) -> -1280.7763 | P28: =SUM(P25:P27) -> -2344.4782 | Q28: =+P28-O28 -> -1063.7019 | R28: =SUM(R25:R27) -> -334.92445 | S28: =+P28-R28 -> -2009.5537 | T28: =SUM(T25:T27) -> 29.668525 | U28: =SUM(U25:U27) -> -132.84032 | V28: =+U28-T28 -> -162.50884 | W28: =SUM(W25:W27) -> 965.11089 | X28: =+U28-W28 -> -1097.9512 | Y28: =SUM(Y25:Y27) -> -3038.2475 | Z28: =SUM(Z25:Z27) -> -3346.9248 | AA28: =+Z28-Y28 -> -308.67738 | AB28: =SUM(AB25:AB27) -> -1948.9772 | AC28: =+Z28-AB28 -> -1397.9476

Sheet 사업장별(당월)
H3: □ 사업장별 손익실적(2026-02)
AG4: [단위 : 천㎥, 톤, 백만원]
H5: 구분 | J5: 물량 | O5: 매출 | T5: 영업이익(공통비 배부전) | Y5: 판매단가 | AB5: 변동비 | AE5: 공헌이익 | AI5: 판매비중
A6: 2024년 2월 마감 손익 | J6: 계획 | K6: 실적 | L6: 차이 | M6: 전년 | N6: 차이 | O6: 계획 | P6: 실적 | Q6: 차이 | R6: 전년 | S6: 차이 | T6: 계획 | U6: 실적 | V6: 차이 | W6: 전년 | X6: 차이 | Y6: 계획 | Z6: 실적 | AA6: 전년 | AB6: 계획 | AC6: 실적 | AD6: 전년 | AE6: 계획 | AF6: 실적 | AG6: 전년 | AI6: 공장명 | AJ6: 계획 | AK6: 추정 | AL6: 차이 | AO6: 전월 | AP6: 차이
B7: 안양 | G7: =+I7 -> 안양 | H7: 레미콘 | I7: 안양 | J7: =+IFERROR(HLOOKUP($B7,'[1]2월'!$D$6:$BN$259,2,),)/1000 -> 28 | K7: =+IFERROR(HLOOKUP($B7,'[2]2월'!$F$6:$CP$99,2,),)/1000 -> 29.129 | L7: =+K7-J7 -> 1.129 | M7: =+IFERROR(HLOOKUP($B7,'[3]2월'!$F$6:$CC$57,2,),)/1000 -> 34.905 | N7: =+K7-M7 -> -5.776 | O7: =+IFERROR(HLOOKUP($B7,'[1]2월'!$D$6:$BN$259,3,),)/1000 -> 2733.6667 | P7: =+IFERROR(HLOOKUP($B7,'[2]2월'!$F$6:$CP$99,3,),)/1000 -> 3045.1153 | Q7: =+P7-O7 -> 311.44858 | R7: =+IFERROR(HLOOKUP($B7,'[3]2월'!$F$6:$CC$57,3,),)/1000 -> 3382.0325 | S7: =+P7-R7 -> -336.91727 | T7: =+IFERROR(HLOOKUP($B7,'[1]2월'!$D$6:$BN$259,16,),)/1000 -> 111.30886 | U7: =+IFERROR(HLOOKUP($B7,'[2]2월'!$F$6:$CP$99,16,),)/1000 -> 153.40702 | V7: =+U7-T7 -> 42.098164 | W7: =+IFERROR(HLOOKUP($B7,'[3]2월'!$F$6:$CC$57,16,),)/1000 -> 265.58446 | X7: =+U7-W7 -> -112.17744 | Y7: =+[4]안양!$Q$85 -> 97630.953 | Z7: =+[4]안양!$R$85 -> 104538.96 | AA7: =+[5]안양!$Q$85 -> 96859.207 | AB7: =+[4]안양!$Q$89 -> 81756.36 | AC7: =+[4]안양!$R$89 -> 86705.369 | AD7: =+[5]안양!$Q$89 -> 80767.793 | AE7: =+Y7-AB7 -> 15874.593 | AF7: =+Z7-AC7 -> 17833.588 | AG7: =+AA7-AD7 -> 16091.414 | AI7: =+I7 -> 안양 | AJ7: =+J7/$J$27 -> 0.15819227 | AK7: =+K7/$K$27 -> 0.17133799 | AL7: =+AK7-AJ7 -> 0.013145719 | AM7: =+Y7*AL7 -> 1283.4291 | AO7: =+[17]안양!$T$5/[17]합계!$T$5 -> 0.1752323 | AP7: =+AK7-AO7 -> -0.0038943104 | AQ7: =+[17]안양!$Q$85*AP7 -> -421.10097
B8: 인천 | G8: =+I8 -> 인천 | H8: 직영 | I8: 인천 | J8: =+IFERROR(HLOOKUP($B8,'[1]2월'!$D$6:$BN$259,2,),)/1000 -> 22 | K8: =+IFERROR(HLOOKUP($B8,'[2]2월'!$F$6:$CP$99,2,),)/1000 -> 21.471 | L8: =+K8-J8 -> -0.529 | M8: =+IFERROR(HLOOKUP($B8,'[3]2월'!$F$6:$CC$57,2,),)/1000 -> 21.485 | N8: =+K8-M8 -> -0.014 | O8: =+IFERROR(HLOOKUP($B8,'[1]2월'!$D$6:$BN$259,3,),)/1000 -> 2198.5032 | P8: =+IFERROR(HLOOKUP($B8,'[2]2월'!$F$6:$CP$99,3,),)/1000 -> 2218.7797 | Q8: =+P8-O8 -> 20.276473 | R8: =+IFERROR(HLOOKUP($B8,'[3]2월'!$F$6:$CC$57,3,),)/1000 -> 2095.0919 | S8: =+P8-R8 -> 123.6878 | T8: =+IFERROR(HLOOKUP($B8,'[1]2월'!$D$6:$BN$259,16,),)/1000 -> -35.878112 | U8: =+IFERROR(HLOOKUP($B8,'[2]2월'!$F$6:$CP$99,16,),)/1000 -> -78.239109 | V8: =+U8-T8 -> -42.360997 | W8: =+IFERROR(HLOOKUP($B8,'[3]2월'!$F$6:$CC$57,16,),)/1000 -> -49.38036 | X8: =+U8-W8 -> -28.858749 | Y8: =+[4]인천!$Q$85 -> 99931.965 | Z8: =+[4]인천!$R$85 -> 103435.47 | AA8: =+[5]인천!$Q$85 -> 97514.168 | AB8: =+[4]인천!$Q$89 -> 87676.92 | AC8: =+[4]인천!$R$89 -> 89863.361 | AD8: =+[5]인천!$Q$89 -> 86203.914 | AE8: =+Y8-AB8 -> 12255.045 | AF8: =+Z8-AC8 -> 13572.111 | AG8: =+AA8-AD8 -> 11310.254 | AI8: =+I8 -> 인천 | AJ8: =+J8/$J$27 -> 0.12429393 | AK8: =+K8/$K$27 -> 0.12629331 | AL8: =+AK8-AJ8 -> 0.0019993881 | AM8: =+Y8*AL8 -> 199.80278 | AO8: =+[17]인천!$T$5/[17]합계!$T$5 -> 0.12417067 | AP8: =+AK8-AO8 -> 0.0021226466 | AQ8: =+[17]인천!$Q$85*AP8 -> 215.7395
B9: 파주 | G9: =+I9 -> 파주 | I9: 파주 | J9: =+IFERROR(HLOOKUP($B9,'[1]2월'!$D$6:$BN$259,2,),)/1000 -> 9 | K9: =+IFERROR(HLOOKUP($B9,'[2]2월'!$F$6:$CP$99,2,),)/1000 -> 8.475 | L9: =+K9-J9 -> -0.525 | M9: =+IFERROR(HLOOKUP($B9,'[3]2월'!$F$6:$CC$57,2,),)/1000 -> 10.445 | N9: =+K9-M9 -> -1.97 | O9: =+IFERROR(HLOOKUP($B9,'[1]2월'!$D$6:$BN$259,3,),)/1000 -> 844.86148 | P9: =+IFERROR(HLOOKUP($B9,'[2]2월'!$F$6:$CP$99,3,),)/1000 -> 828.129 | Q9: =+P9-O9 -> -16.732476 | R9: =+IFERROR(HLOOKUP($B9,'[3]2월'!$F$6:$CC$57,3,),)/1000 -> 1017.4518 | S9: =+P9-R9 -> -189.3228 | T9: =+IFERROR(HLOOKUP($B9,'[1]2월'!$D$6:$BN$259,16,),)/1000 -> -120.66919 | U9: =+IFERROR(HLOOKUP($B9,'[2]2월'!$F$6:$CP$99,16,),)/1000 -> -146.03662 | V9: =+U9-T9 -> -25.367431 | W9: =+IFERROR(HLOOKUP($B9,'[3]2월'!$F$6:$CC$57,16,),)/1000 -> -42.738868 | X9: =+U9-W9 -> -103.29775 | Y9: =+[4]파주!$Q$85 -> 93873.497 | Z9: =+[4]파주!$R$85 -> 97714.336 | AA9: =+[5]파주!$Q$85 -> 97410.416 | AB9: =+[4]파주!$Q$89 -> 81194.057 | AC9: =+[4]파주!$R$89 -> 88151.277 | AD9: =+[5]파주!$Q$89 -> 80870.416 | AE9: =+Y9-AB9 -> 12679.441 | AF9: =+Z9-AC9 -> 9563.0591 | AG9: =+AA9-AD9 -> 16540.001 | AI9: =+I9 -> 파주 | AJ9: =+J9/$J$27 -> 0.050847515 | AK9: =+K9/$K$27 -> 0.049850302 | AL9: =+AK9-AJ9 -> -0.00099721304 | AM9: =+Y9*AL9 -> -93.611876 | AO9: =+[17]파주!$T$5/[17]합계!$T$5 -> 0.042300584 | AP9: =+AK9-AO9 -> 0.0075497181 | AQ9: =+[17]파주!$Q$85*AP9 -> 759.7584
B10: 김포 | G10: =+I10 -> 김포 | I10: 김포 | J10: =+IFERROR(HLOOKUP($B10,'[1]2월'!$D$6:$BN$259,2,),)/1000 -> 8 | K10: =+IFERROR(HLOOKUP($B10,'[2]2월'!$F$6:$CP$99,2,),)/1000 -> 7.692 | L10: =+K10-J10 -> -0.308 | M10: =+IFERROR(HLOOKUP($B10,'[3]2월'!$F$6:$CC$57,2,),)/1000 -> 7.4045 | N10: =+K10-M10 -> 0.2875 | O10: =+IFERROR(HLOOKUP($B10,'[1]2월'!$D$6:$BN$259,3,),)/1000 -> 805.52917 | P10: =+IFERROR(HLOOKUP($B10,'[2]2월'!$F$6:$CP$99,3,),)/1000 -> 753.17807 | Q10: =+P10-O10 -> -52.351106 | R10: =+IFERROR(HLOOKUP($B10,'[3]2월'!$F$6:$CC$57,3,),)/1000 -> 704.99124 | S10: =+P10-R10 -> 48.186831 | T10: =+IFERROR(HLOOKUP($B10,'[1]2월'!$D$6:$BN$259,16,),)/1000 -> -38.987187 | U10: =+IFERROR(HLOOKUP($B10,'[2]2월'!$F$6:$CP$99,16,),)/1000 -> -121.40124 | V10: =+U10-T10 -> -82.414057 | W10: =+IFERROR(HLOOKUP($B10,'[3]2월'!$F$6:$CC$57,16,),)/1000 -> -46.86888 | X10: =+U10-W10 -> -74.532364 | Y10: =+[4]김포!$Q$85 -> 100691.15 | Z10: =+[4]김포!$R$85 -> 97917.065 | AA10: =+[5]김포!$Q$85 -> 95239.126 | AB10: =+[4]김포!$Q$89 -> 83779.837 | AC10: =+[4]김포!$R$89 -> 87512.934 | AD10: =+[5]김포!$Q$89 -> 79871.523 | AE10: =+Y10-AB10 -> 16911.309 | AF10: =+Z10-AC10 -> 10404.131 | AG10: =+AA10-AD10 -> 15367.602 | AI10: =+I10 -> 김포 | AJ10: =+J10/$J$27 -> 0.045197791 | AK10: =+K10/$K$27 -> 0.045244664 | AL10: =+AK10-AJ10 -> 4.6872334e-05 | AM10: =+Y10*AL10 -> 4.719629 | AO10: =+[17]김포!$T$5/[17]합계!$T$5 -> 0.037678748 | AP10: =+AK10-AO10 -> 0.0075659152 | AQ10: =+[17]김포!$Q$85*AP10 -> 743.08416
B11: 부산 | G11: =+I11 -> 부산 | I11: 부산 | J11: =+IFERROR(HLOOKUP($B11,'[1]2월'!$D$6:$BN$259,2,),)/1000 -> 16 | K11: =+IFERROR(HLOOKUP($B11,'[2]2월'!$F$6:$CP$99,2,),)/1000 -> 19.626 | L11: =+K11-J11 -> 3.626 | M11: =+IFERROR(HLOOKUP($B11,'[3]2월'!$F$6:$CC$57,2,),)/1000 -> 16.897 | N11: =+K11-M11 -> 2.729 | O11: =+IFERROR(HLOOKUP($B11,'[1]2월'!$D$6:$BN$259,3,),)/1000 -> 1723.429 | P11: =+IFERROR(HLOOKUP($B11,'[2]2월'!$F$6:$CP$99,3,),)/1000 -> 2281.7649 | Q11: =+P11-O11 -> 558.33589 | R11: =+IFERROR(HLOOKUP($B11,'[3]2월'!$F$6:$CC$57,3,),)/1000 -> 1794.1025 | S11: =+P11-R11 -> 487.66235 | T11: =+IFERROR(HLOOKUP($B11,'[1]2월'!$D$6:$BN$259,16,),)/1000 -> 74.964892 | U11: =+IFERROR(HLOOKUP($B11,'[2]2월'!$F$6:$CP$99,16,),)/1000 -> 207.73551 | V11: =+U11-T11 -> 132.77062 | W11: =+IFERROR(HLOOKUP($B11,'[3]2월'!$F$6:$CC$57,16,),)/1000 -> 133.31258 | X11: =+U11-W11 -> 74.42293 | Y11: =+[4]부산!$Q$85 -> 107714.31 | Z11: =+[4]부산!$R$85 -> 116262.35 | AA11: =+[5]부산!$Q$85 -> 106178.76 | AB11: =+[4]부산!$Q$89 -> 87368.82 | AC11: =+[4]부산!$R$89 -> 91250.127 | AD11: =+[5]부산!$Q$89 -> 84408.739 | AE11: =+Y11-AB11 -> 20345.49 | AF11: =+Z11-AC11 -> 25012.222 | AG11: =+AA11-AD11 -> 21770.02 | AI11: =+I11 -> 부산 | AJ11: =+J11/$J$27 -> 0.090395582 | AK11: =+K11/$K$27 -> 0.11544095 | AL11: =+AK11-AJ11 -> 0.025045365 | AM11: =+Y11*AL11 -> 2697.7442 | AO11: =+[17]부산!$T$5/[17]합계!$T$5 -> 0.1224389 | AP11: =+AK11-AO11 -> -0.0069979511 | AQ11: =+[17]부산!$Q$85*AP11 -> -833.76833
B12: 서부산 | G12: =+I12 -> 서부산 | I12: 서부산 | J12: =+IFERROR(HLOOKUP($B12,'[1]2월'!$D$6:$BN$259,2,),)/1000 -> 16 | K12: =+IFERROR(HLOOKUP($B12,'[2]2월'!$F$6:$CP$99,2,),)/1000 -> 11.794 | L12: =+K12-J12 -> -4.206 | M12: =+IFERROR(HLOOKUP($B12,'[3]2월'!$F$6:$CC$57,2,),)/1000 -> 17.85 | N12: =+K12-M12 -> -6.056 | O12: =+IFERROR(HLOOKUP($B12,'[1]2월'!$D$6:$BN$259,3,),)/1000 -> 1600.6866 | P12: =+IFERROR(HLOOKUP($B12,'[2]2월'!$F$6:$CP$99,3,),)/1000 -> 1207.5535 | Q12: =+P12-O12 -> -393.13312 | R12: =+IFERROR(HLOOKUP($B12,'[3]2월'!$F$6:$CC$57,3,),)/1000 -> 1700.7802 | S12: =+P12-R12 -> -493.2267 | T12: =+IFERROR(HLOOKUP($B12,'[1]2월'!$D$6:$BN$259,16,),)/1000 -> 118.33251 | U12: =+IFERROR(HLOOKUP($B12,'[2]2월'!$F$6:$CP$99,16,),)/1000 -> -5.990017 | V12: =+U12-T12 -> -124.32253 | W12: =+IFERROR(HLOOKUP($B12,'[3]2월'!$F$6:$CC$57,16,),)/1000 -> 77.502494 | X12: =+U12-W12 -> -83.492511 | Y12: =+[4]서부산!$Q$85 -> 100042.91 | Z12: =+[4]서부산!$R$85 -> 102387.1 | AA12: =+[5]서부산!$Q$85 -> 95281.804 | AB12: =+[4]서부산!$Q$89 -> 79142.507 | AC12: =+[4]서부산!$R$89 -> 81278.708 | AD12: =+[5]서부산!$Q$89 -> 78548.451 | AE12: =+Y12-AB12 -> 20900.406 | AF12: =+Z12-AC12 -> 21108.396 | AG12: =+AA12-AD12 -> 16733.353 | AI12: =+I12 -> 서부산 | AJ12: =+J12/$J$27 -> 0.090395582 | AK12: =+K12/$K$27 -> 0.069372798 | AL12: =+AK12-AJ12 -> -0.021022784 | AM12: =+Y12*AL12 -> -2103.1806 | AO12: =+[17]서부산!$T$5/[17]합계!$T$5 -> 0.093572299 | AP12: =+AK12-AO12 -> -0.024199501 | AQ12: =+[17]서부산!$Q$85*AP12 -> -2600.4742
B13: 김해 | G13: =+I13 -> 김해 | I13: 김해 | J13: =+IFERROR(HLOOKUP($B13,'[1]2월'!$D$6:$BN$259,2,),)/1000 -> 7 | K13: =+IFERROR(HLOOKUP($B13,'[2]2월'!$F$6:$CP$99,2,),)/1000 -> 5.282 | L13: =+K13-J13 -> -1.718 | M13: =+IFERROR(HLOOKUP($B13,'[3]2월'!$F$6:$CC$57,2,),)/1000 -> 4.58 | N13: =+K13-M13 -> 0.702 | O13: =+IFERROR(HLOOKUP($B13,'[1]2월'!$D$6:$BN$259,3,),)/1000 -> 684.93897 | P13: =+IFERROR(HLOOKUP($B13,'[2]2월'!$F$6:$CP$99,3,),)/1000 -> 541.1817 | Q13: =+P13-O13 -> -143.75727 | R13: =+IFERROR(HLOOKUP($B13,'[3]2월'!$F$6:$CC$57,3,),)/1000 -> 453.453 | S13: =+P13-R13 -> 87.7287 | T13: =+IFERROR(HLOOKUP($B13,'[1]2월'!$D$6:$BN$259,16,),)/1000 -> -14.53489 | U13: =+IFERROR(HLOOKUP($B13,'[2]2월'!$F$6:$CP$99,16,),)/1000 -> -36.280646 | V13: =+U13-T13 -> -21.745756 | W13: =+IFERROR(HLOOKUP($B13,'[3]2월'!$F$6:$CC$57,16,),)/1000 -> -73.487828 | X13: =+U13-W13 -> 37.207182 | Y13: =+[4]김해!$Q$85 -> 97848.424 | Z13: =+[4]김해!$R$85 -> 102457.72 | AA13: =+[5]김해!$Q$85 -> 99140.018 | AB13: =+[4]김해!$Q$89 -> 80075.457 | AC13: =+[4]김해!$R$89 -> 79308.164 | AD13: =+[5]김해!$Q$89 -> 83284.996 | AE13: =+Y13-AB13 -> 17772.967 | AF13: =+Z13-AC13 -> 23149.56 | AG13: =+AA13-AD13 -> 15855.022 | AI13: =+I13 -> 김해 | AJ13: =+J13/$J$27 -> 0.039548067 | AK13: =+K13/$K$27 -> 0.031068943 | AL13: =+AK13-AJ13 -> -0.0084791239 | AM13: =+Y13*AL13 -> -829.66891 | AO13: =+[17]김해!$T$5/[17]합계!$T$5 -> 0.025823229 | AP13: =+AK13-AO13 -> 0.0052457144 | AQ13: =+[17]김해!$Q$85*AP13 -> 470.09237
B14: 정관 | G14: =+I14 -> 정관 | I14: 정관 | J14: =+IFERROR(HLOOKUP($B14,'[1]2월'!$D$6:$BN$259,2,),)/1000 -> 18 | K14: =+IFERROR(HLOOKUP($B14,'[2]2월'!$F$6:$CP$99,2,),)/1000 -> 10.532 | L14: =+K14-J14 -> -7.468 | M14: =+IFERROR(HLOOKUP($B14,'[3]2월'!$F$6:$CC$57,2,),)/1000 -> 18.366 | N14: =+K14-M14 -> -7.834 | O14: =+IFERROR(HLOOKUP($B14,'[1]2월'!$D$6:$BN$259,3,),)/1000 -> 1797.8067 | P14: =+IFERROR(HLOOKUP($B14,'[2]2월'!$F$6:$CP$99,3,),)/1000 -> 1143.2859 | Q14: =+P14-O14 -> -654.52077 | R14: =+IFERROR(HLOOKUP($B14,'[3]2월'!$F$6:$CC$57,3,),)/1000 -> 1908.4609 | S14: =+P14-R14 -> -765.175 | T14: =+IFERROR(HLOOKUP($B14,'[1]2월'!$D$6:$BN$259,16,),)/1000 -> 71.756078 | U14: =+IFERROR(HLOOKUP($B14,'[2]2월'!$F$6:$CP$99,16,),)/1000 -> -47.580852 | V14: =+U14-T14 -> -119.33693 | W14: =+IFERROR(HLOOKUP($B14,'[3]2월'!$F$6:$CC$57,16,),)/1000 -> 150.8114 | X14: =+U14-W14 -> -198.39225 | Y14: =+[4]정관!$Q$85 -> 99878.149 | Z14: =+[4]정관!$R$85 -> 108553.54 | AA14: =+[5]정관!$Q$85 -> 103912.71 | AB14: =+[4]정관!$Q$89 -> 84282.857 | AC14: =+[4]정관!$R$89 -> 87864.808 | AD14: =+[5]정관!$Q$89 -> 85082.054 | AE14: =+Y14-AB14 -> 15595.291 | AF14: =+Z14-AC14 -> 20688.733 | AG14: =+AA14-AD14 -> 18830.66 | AI14: =+I14 -> 정관 | AJ14: =+J14/$J$27 -> 0.10169503 | AK14: =+K14/$K$27 -> 0.061949661 | AL14: =+AK14-AJ14 -> -0.039745369 | AM14: =+Y14*AL14 -> -3969.6938 | AO14: =+[17]정관!$T$5/[17]합계!$T$5 -> 0.057284643 | AP14: =+AK14-AO14 -> 0.0046650183 | AQ14: =+[17]정관!$Q$85*AP14 -> 471.559
B15: 양산 | G15: =+I15 -> 양산 | I15: 양산 | J15: =+IFERROR(HLOOKUP($B15,'[1]2월'!$D$6:$BN$259,2,),)/1000 -> 6 | K15: =+IFERROR(HLOOKUP($B15,'[2]2월'!$F$6:$CP$99,2,),)/1000 -> 3.393 | L15: =+K15-J15 -> -2.607 | M15: =+IFERROR(HLOOKUP($B15,'[3]2월'!$F$6:$CC$57,2,),)/1000 -> 8.188 | N15: =+K15-M15 -> -4.795 | O15: =+IFERROR(HLOOKUP($B15,'[1]2월'!$D$6:$BN$259,3,),)/1000 -> 576.63294 | P15: =+IFERROR(HLOOKUP($B15,'[2]2월'!$F$6:$CP$99,3,),)/1000 -> 360.5571 | Q15: =+P15-O15 -> -216.07584 | R15: =+IFERROR(HLOOKUP($B15,'[3]2월'!$F$6:$CC$57,3,),)/1000 -> 791.5705 | S15: =+P15-R15 -> -431.0134 | T15: =+IFERROR(HLOOKUP($B15,'[1]2월'!$D$6:$BN$259,16,),)/1000 -> -26.949417 | U15: =+IFERROR(HLOOKUP($B15,'[2]2월'!$F$6:$CP$99,16,),)/1000 -> -66.233686 | V15: =+U15-T15 -> -39.284269 | W15: =+IFERROR(HLOOKUP($B15,'[3]2월'!$F$6:$CC$57,16,),)/1000 -> 32.887764 | X15: =+U15-W15 -> -99.12145 | Y15: =+[4]양산!$Q$85 -> 96105.49 | Z15: =+[4]양산!$R$85 -> 106264.99 | AA15: =+[5]양산!$Q$85 -> 96674.463 | AB15: =+[4]양산!$Q$89 -> 77253.829 | AC15: =+[4]양산!$R$89 -> 82411.796 | AD15: =+[5]양산!$Q$89 -> 74256.725 | AE15: =+Y15-AB15 -> 18851.66 | AF15: =+Z15-AC15 -> 23853.19 | AG15: =+AA15-AD15 -> 22417.738 | AI15: =+I15 -> 양산 | AJ15: =+J15/$J$27 -> 0.033898343 | AK15: =+K15/$K$27 -> 0.019957767 | AL15: =+AK15-AJ15 -> -0.013940576 | AM15: =+Y15*AL15 -> -1339.7659 | AO15: =+[17]양산!$T$5/[17]합계!$T$5 -> 0.029417359 | AP15: =+AK15-AO15 -> -0.0094595922 | AQ15: =+[17]양산!$Q$85*AP15 -> -925.48316
B16: 창원 | G16: =+I16 -> 창원 | I16: 창원 | J16: =+IFERROR(HLOOKUP($B16,'[1]2월'!$D$6:$BN$259,2,),)/1000 -> 8.5 | K16: =+IFERROR(HLOOKUP($B16,'[2]2월'!$F$6:$CP$99,2,),)/1000 -> 9.434 | L16: =+K16-J16 -> 0.934 | M16: =+IFERROR(HLOOKUP($B16,'[3]2월'!$F$6:$CC$57,2,),)/1000 -> 10.864 | N16: =+K16-M16 -> -1.43 | O16: =+IFERROR(HLOOKUP($B16,'[1]2월'!$D$6:$BN$259,3,),)/1000 -> 834.0879 | P16: =+IFERROR(HLOOKUP($B16,'[2]2월'!$F$6:$CP$99,3,),)/1000 -> 889.2288 | Q16: =+P16-O16 -> 55.140904 | R16: =+IFERROR(HLOOKUP($B16,'[3]2월'!$F$6:$CC$57,3,),)/1000 -> 1085.93 | S16: =+P16-R16 -> -196.70125 | T16: =+IFERROR(HLOOKUP($B16,'[1]2월'!$D$6:$BN$259,16,),)/1000 -> -6.3142939 | U16: =+IFERROR(HLOOKUP($B16,'[2]2월'!$F$6:$CP$99,16,),)/1000 -> -25.872475 | V16: =+U16-T16 -> -19.558181 | W16: =+IFERROR(HLOOKUP($B16,'[3]2월'!$F$6:$CC$57,16,),)/1000 -> 108.75022 | X16: =+U16-W16 -> -134.6227 | Y16: =+[4]창원!$Q$85 -> 98127.988 | Z16: =+[4]창원!$R$85 -> 94257.876 | AA16: =+[5]창원!$Q$85 -> 99956.742 | AB16: =+[4]창원!$Q$89 -> 79244.477 | AC16: =+[4]창원!$R$89 -> 75692.193 | AD16: =+[5]창원!$Q$89 -> 74426.787 | AE16: =+Y16-AB16 -> 18883.511 | AF16: =+Z16-AC16 -> 18565.683 | AG16: =+AA16-AD16 -> 25529.956 | AI16: =+I16 -> 창원 | AJ16: =+J16/$J$27 -> 0.048022653 | AK16: =+K16/$K$27 -> 0.05549118 | AL16: =+AK16-AJ16 -> 0.0074685267 | AM16: =+Y16*AL16 -> 732.8715 | AO16: =+[17]창원!$T$5/[17]합계!$T$5 -> 0.042584481 | AP16: =+AK16-AO16 -> 0.012906699 | AQ16: =+[17]창원!$Q$85*AP16 -> 1309.0616
B17: 대구 | G17: =+I17 -> 대구 | I17: 대구 | J17: =+IFERROR(HLOOKUP($B17,'[1]2월'!$D$6:$BN$259,2,),)/1000 -> 6.5 | K17: =+IFERROR(HLOOKUP($B17,'[2]2월'!$F$6:$CP$99,2,),)/1000 -> 4.393 | L17: =+K17-J17 -> -2.107 | M17: =+IFERROR(HLOOKUP($B17,'[3]2월'!$F$6:$CC$57,2,),)/1000 -> 9.434 | N17: =+K17-M17 -> -5.041 | O17: =+IFERROR(HLOOKUP($B17,'[1]2월'!$D$6:$BN$259,3,),)/1000 -> 586.52159 | P17: =+IFERROR(HLOOKUP($B17,'[2]2월'!$F$6:$CP$99,3,),)/1000 -> 379.72483 | Q17: =+P17-O17 -> -206.79676 | R17: =+IFERROR(HLOOKUP($B17,'[3]2월'!$F$6:$CC$57,3,),)/1000 -> 882.50667 | S17: =+P17-R17 -> -502.78184 | T17: =+IFERROR(HLOOKUP($B17,'[1]2월'!$D$6:$BN$259,16,),)/1000 -> -25.107902 | U17: =+IFERROR(HLOOKUP($B17,'[2]2월'!$F$6:$CP$99,16,),)/1000 -> -89.101347 | V17: =+U17-T17 -> -63.993445 | W17: =+IFERROR(HLOOKUP($B17,'[3]2월'!$F$6:$CC$57,16,),)/1000 -> 11.519029 | X17: =+U17-W17 -> -100.62038 | Y17: =+[4]대구!$Q$85 -> 90234.09 | Z17: =+[4]대구!$R$85 -> 86438.613 | AA17: =+[5]대구!$Q$85 -> 93545.333 | AB17: =+[4]대구!$Q$89 -> 73047.936 | AC17: =+[4]대구!$R$89 -> 71234.762 | AD17: =+[5]대구!$Q$89 -> 76356.339 | AE17: =+Y17-AB17 -> 17186.155 | AF17: =+Z17-AC17 -> 15203.851 | AG17: =+AA17-AD17 -> 17188.994 | AI17: =+I17 -> 대구 | AJ17: =+J17/$J$27 -> 0.036723205 | AK17: =+K17/$K$27 -> 0.025839808 | AL17: =+AK17-AJ17 -> -0.010883397 | AM17: =+Y17*AL17 -> -982.05342 | AO17: =+[17]대구!$T$5/[17]합계!$T$5 -> 0.015321896 | AP17: =+AK17-AO17 -> 0.010517912 | AQ17: =+[17]대구!$Q$85*AP17 -> 975.92065
B18: 울산 | G18: =+I18 -> 울산 | I18: 울산 | J18: =+IFERROR(HLOOKUP($B18,'[1]2월'!$D$6:$BN$259,2,),)/1000 -> 5.5 | K18: =+IFERROR(HLOOKUP($B18,'[2]2월'!$F$6:$CP$99,2,),)/1000 -> 9.471 | L18: =+K18-J18 -> 3.971 | M18: =+IFERROR(HLOOKUP($B18,'[3]2월'!$F$6:$CC$57,2,),)/1000 -> 9.715 | N18: =+K18-M18 -> -0.244 | O18: =+IFERROR(HLOOKUP($B18,'[1]2월'!$D$6:$BN$259,3,),)/1000 -> 578.93985 | P18: =+IFERROR(HLOOKUP($B18,'[2]2월'!$F$6:$CP$99,3,),)/1000 -> 1044.54 | Q18: =+P18-O18 -> 465.60015 | R18: =+IFERROR(HLOOKUP($B18,'[3]2월'!$F$6:$CC$57,3,),)/1000 -> 1047.306 | S18: =+P18-R18 -> -2.766 | T18: =+IFERROR(HLOOKUP($B18,'[1]2월'!$D$6:$BN$259,16,),)/1000 -> -81.807409 | U18: =+IFERROR(HLOOKUP($B18,'[2]2월'!$F$6:$CP$99,16,),)/1000 -> 11.388659 | V18: =+U18-T18 -> 93.196068 | W18: =+IFERROR(HLOOKUP($B18,'[3]2월'!$F$6:$CC$57,16,),)/1000 -> 78.01652 | X18: =+U18-W18 -> -66.627861 | Y18: =+[4]울산!$Q$85 -> 105261.79 | Z18: =+[4]울산!$R$85 -> 110288.25 | AA18: =+[5]울산!$Q$85 -> 107802.99 | AB18: =+[4]울산!$Q$89 -> 93506.781 | AC18: =+[4]울산!$R$89 -> 89654.83 | AD18: =+[5]울산!$Q$89 -> 85472.134 | AE18: =+Y18-AB18 -> 11755.009 | AF18: =+Z18-AC18 -> 20633.419 | AG18: =+AA18-AD18 -> 22330.851 | AI18: =+I18 -> 울산 | AJ18: =+J18/$J$27 -> 0.031073481 | AK18: =+K18/$K$27 -> 0.055708815 | AL18: =+AK18-AJ18 -> 0.024635334 | AM18: =+Y18*AL18 -> 2593.1594 | AO18: =+[17]울산!$T$5/[17]합계!$T$5 -> 0.059902169 | AP18: =+AK18-AO18 -> -0.0041933538 | AQ18: =+[17]울산!$Q$85*AP18 -> -467.64191
B19: 아산 | G19: =+I19 -> 아산 | I19: 아산 | J19: =+IFERROR(HLOOKUP($B19,'[1]2월'!$D$6:$BN$259,2,),)/1000 -> 10 | K19: =+IFERROR(HLOOKUP($B19,'[2]2월'!$F$6:$CP$99,2,),)/1000 -> 15.899 | L19: =+K19-J19 -> 5.899 | M19: =+IFERROR(HLOOKUP($B19,'[3]2월'!$F$6:$CC$57,2,),)/1000 -> 17.767 | N19: =+K19-M19 -> -1.868 | O19: =+IFERROR(HLOOKUP($B19,'[1]2월'!$D$6:$BN$259,3,),)/1000 -> 987.18316 | P19: =+IFERROR(HLOOKUP($B19,'[2]2월'!$F$6:$CP$99,3,),)/1000 -> 1625.0633 | Q19: =+P19-O19 -> 637.88015 | R19: =+IFERROR(HLOOKUP($B19,'[3]2월'!$F$6:$CC$57,3,),)/1000 -> 1783.0426 | S19: =+P19-R19 -> -157.97929 | T19: =+IFERROR(HLOOKUP($B19,'[1]2월'!$D$6:$BN$259,16,),)/1000 -> -64.53117 | U19: =+IFERROR(HLOOKUP($B19,'[2]2월'!$F$6:$CP$99,16,),)/1000 -> -9.287506 | V19: =+U19-T19 -> 55.243664 | W19: =+IFERROR(HLOOKUP($B19,'[3]2월'!$F$6:$CC$57,16,),)/1000 -> 71.697309 | X19: =+U19-W19 -> -80.984815 | Y19: =+[4]아산!$Q$85 -> 98718.316 | Z19: =+[4]아산!$R$85 -> 102211.67 | AA19: =+[5]아산!$Q$85 -> 100356.99 | AB19: =+[4]아산!$Q$89 -> 80564.17 | AC19: =+[4]아산!$R$89 -> 85417.311 | AD19: =+[5]아산!$Q$89 -> 83852.328 | AE19: =+Y19-AB19 -> 18154.146 | AF19: =+Z19-AC19 -> 16794.357 | AG19: =+AA19-AD19 -> 16504.66 | AI19: =+I19 -> 아산 | AJ19: =+J19/$J$27 -> 0.056497239 | AK19: =+K19/$K$27 -> 0.093518578 | AL19: =+AK19-AJ19 -> 0.037021339 | AM19: =+Y19*AL19 -> 3654.6843 | AO19: =+[17]아산!$T$5/[17]합계!$T$5 -> 0.082347029 | AP19: =+AK19-AO19 -> 0.011171549 | AQ19: =+[17]아산!$Q$85*AP19 -> 1160.0072
B20: 전주 | G20: =+I20 -> 전주 | I20: 전주 | J20: =+IFERROR(HLOOKUP($B20,'[1]2월'!$D$6:$BN$259,2,),)/1000 -> 6 | K20: =+IFERROR(HLOOKUP($B20,'[2]2월'!$F$6:$CP$99,2,),)/1000 -> 6.723 | L20: =+K20-J20 -> 0.723 | M20: =+IFERROR(HLOOKUP($B20,'[3]2월'!$F$6:$CC$57,2,),)/1000 -> 13.0765 | N20: =+K20-M20 -> -6.3535 | O20: =+IFERROR(HLOOKUP($B20,'[1]2월'!$D$6:$BN$259,3,),)/1000 -> 610.59942 | P20: =+IFERROR(HLOOKUP($B20,'[2]2월'!$F$6:$CP$99,3,),)/1000 -> 640.76605 | Q20: =+P20-O20 -> 30.166628 | R20: =+IFERROR(HLOOKUP($B20,'[3]2월'!$F$6:$CC$57,3,),)/1000 -> 1256.9671 | S20: =+P20-R20 -> -616.20107 | T20: =+IFERROR(HLOOKUP($B20,'[1]2월'!$D$6:$BN$259,16,),)/1000 -> -28.142013 | U20: =+IFERROR(HLOOKUP($B20,'[2]2월'!$F$6:$CP$99,16,),)/1000 -> -75.588009 | V20: =+U20-T20 -> -47.445996 | W20: =+IFERROR(HLOOKUP($B20,'[3]2월'!$F$6:$CC$57,16,),)/1000 -> 149.1804 | X20: =+U20-W20 -> -224.76841 | Y20: =+[4]전주!$Q$85 -> 101766.57 | Z20: =+[4]전주!$R$85 -> 95309.542 | AA20: =+[5]전주!$Q$85 -> 96124.125 | AB20: =+[4]전주!$Q$89 -> 79902.404 | AC20: =+[4]전주!$R$89 -> 80533.023 | AD20: =+[5]전주!$Q$89 -> 73533.899 | AE20: =+Y20-AB20 -> 21864.166 | AF20: =+Z20-AC20 -> 14776.519 | AG20: =+AA20-AD20 -> 22590.226 | AI20: =+I20 -> 전주 | AJ20: =+J20/$J$27 -> 0.033898343 | AK20: =+K20/$K$27 -> 0.039544965 | AL20: =+AK20-AJ20 -> 0.0056466219 | AM20: =+Y20*AL20 -> 574.63734 | AO20: =+[17]전주!$T$5/[17]합계!$T$5 -> 0.046334754 | AP20: =+AK20-AO20 -> -0.0067897885 | AQ20: =+[17]전주!$Q$85*AP20 -> -692.5303
B21: 군산 | G21: =+I21 -> 군산 | I21: 군산 | J21: =+IFERROR(HLOOKUP($B21,'[1]2월'!$D$6:$BN$259,2,),)/1000 -> 2.5 | K21: =+IFERROR(HLOOKUP($B21,'[2]2월'!$F$6:$CP$99,2,),)/1000 -> 1.991 | L21: =+K21-J21 -> -0.509 | M21: =+IFERROR(HLOOKUP($B21,'[3]2월'!$F$6:$CC$57,2,),)/1000 -> 3.896 | N21: =+K21-M21 -> -1.905 | O21: =+IFERROR(HLOOKUP($B21,'[1]2월'!$D$6:$BN$259,3,),)/1000 -> 289.45889 | P21: =+IFERROR(HLOOKUP($B21,'[2]2월'!$F$6:$CP$99,3,),)/1000 -> 216.91014 | Q21: =+P21-O21 -> -72.548758 | R21: =+IFERROR(HLOOKUP($B21,'[3]2월'!$F$6:$CC$57,3,),)/1000 -> 414.87225 | S21: =+P21-R21 -> -197.96211 | T21: =+IFERROR(HLOOKUP($B21,'[1]2월'!$D$6:$BN$259,16,),)/1000 -> 11.36952 | U21: =+IFERROR(HLOOKUP($B21,'[2]2월'!$F$6:$CP$99,16,),)/1000 -> -20.390283 | V21: =+U21-T21 -> -31.759803 | W21: =+IFERROR(HLOOKUP($B21,'[3]2월'!$F$6:$CC$57,16,),)/1000 -> 57.866905 | X21: =+U21-W21 -> -78.257188 | Y21: =+[4]군산!$Q$85 -> 115783.56 | Z21: =+[4]군산!$R$85 -> 108945.32 | AA21: =+[5]군산!$Q$85 -> 106486.72 | AB21: =+[4]군산!$Q$89 -> 76837.808 | AC21: =+[4]군산!$R$89 -> 72951.092 | AD21: =+[5]군산!$Q$89 -> 71564.787 | AE21: =+Y21-AB21 -> 38945.75 | AF21: =+Z21-AC21 -> 35994.23 | AG21: =+AA21-AD21 -> 34921.93 | AI21: =+I21 -> 군산 | AJ21: =+J21/$J$27 -> 0.01412431 | AK21: =+K21/$K$27 -> 0.011711145 | AL21: =+AK21-AJ21 -> -0.002413165 | AM21: =+Y21*AL21 -> -279.40483 | AO21: =+[17]군산!$T$5/[17]합계!$T$5 -> 0.011739122 | AP21: =+AK21-AO21 -> -2.797709e-05 | AQ21: =+[17]군산!$Q$85*AP21 -> -3.3330957
B22: 원주 | G22: =+I22 -> 원주 | I22: 원주 | J22: =+IFERROR(HLOOKUP($B22,'[1]2월'!$D$6:$BN$259,2,),)/1000 -> 2.9998 | K22: =+IFERROR(HLOOKUP($B22,'[2]2월'!$F$6:$CP$99,2,),)/1000 -> 1.475 | L22: =+K22-J22 -> -1.5248 | M22: =+IFERROR(HLOOKUP($B22,'[3]2월'!$F$6:$CC$57,2,),)/1000 -> 1.228 | N22: =+K22-M22 -> 0.247 | O22: =+IFERROR(HLOOKUP($B22,'[1]2월'!$D$6:$BN$259,3,),)/1000 -> 344.38257 | P22: =+IFERROR(HLOOKUP($B22,'[2]2월'!$F$6:$CP$99,3,),)/1000 -> 189.4369 | Q22: =+P22-O22 -> -154.94567 | R22: =+IFERROR(HLOOKUP($B22,'[3]2월'!$F$6:$CC$57,3,),)/1000 -> 138.4771 | S22: =+P22-R22 -> 50.9598 | T22: =+IFERROR(HLOOKUP($B22,'[1]2월'!$D$6:$BN$259,16,),)/1000 -> 33.348804 | U22: =+IFERROR(HLOOKUP($B22,'[2]2월'!$F$6:$CP$99,16,),)/1000 -> -24.850722 | V22: =+U22-T22 -> -58.199526 | W22: =+IFERROR(HLOOKUP($B22,'[3]2월'!$F$6:$CC$57,16,),)/1000 -> -36.517007 | X22: =+U22-W22 -> 11.666285 | Y22: =+[4]원주!$Q$85 -> 114801.84 | Z22: =+[4]원주!$R$85 -> 128431.8 | AA22: =+[5]원주!$Q$85 -> 112766.37 | AB22: =+[4]원주!$Q$89 -> 74199.59 | AC22: =+[4]원주!$R$89 -> 81521.713 | AD22: =+[5]원주!$Q$89 -> 75882.36 | AE22: =+Y22-AB22 -> 40602.252 | AF22: =+Z22-AC22 -> 46910.083 | AG22: =+AA22-AD22 -> 36884.008 | AI22: =+I22 -> 원주 | AJ22: =+J22/$J$27 -> 0.016948042 | AK22: =+K22/$K$27 -> 0.0086760113 | AL22: =+AK22-AJ22 -> -0.0082720305 | AM22: =+Y22*AL22 -> -949.64434 | AO22: =+[17]원주!$T$5/[17]합계!$T$5 -> 0.012182 | AP22: =+AK22-AO22 -> -0.0035059891 | AQ22: =+[17]원주!$Q$85*AP22 -> -436.71306
B23: 제주 | F23: =+K27-J27 -> -6.9908 | G23: =+I23 -> 제주 | I23: 제주 | J23: =+IFERROR(HLOOKUP($B23,'[1]2월'!$D$6:$BN$259,2,),)/1000 -> 5 | K23: =+IFERROR(HLOOKUP($B23,'[2]2월'!$F$6:$CP$99,2,),)/1000 -> 3.229 | L23: =+K23-J23 -> -1.771 | M23: =+IFERROR(HLOOKUP($B23,'[3]2월'!$F$6:$CC$57,2,),)/1000 -> 4.678 | N23: =+K23-M23 -> -1.449 | O23: =+IFERROR(HLOOKUP($B23,'[1]2월'!$D$6:$BN$259,3,),)/1000 -> 601.3391 | P23: =+IFERROR(HLOOKUP($B23,'[2]2월'!$F$6:$CP$99,3,),)/1000 -> 416.63115 | Q23: =+P23-O23 -> -184.70795 | R23: =+IFERROR(HLOOKUP($B23,'[3]2월'!$F$6:$CC$57,3,),)/1000 -> 565.73136 | S23: =+P23-R23 -> -149.10021 | T23: =+IFERROR(HLOOKUP($B23,'[1]2월'!$D$6:$BN$259,16,),)/1000 -> 26.361966 | U23: =+IFERROR(HLOOKUP($B23,'[2]2월'!$F$6:$CP$99,16,),)/1000 -> -7.498015 | V23: =+U23-T23 -> -33.859981 | W23: =+IFERROR(HLOOKUP($B23,'[3]2월'!$F$6:$CC$57,16,),)/1000 -> 53.836508 | X23: =+U23-W23 -> -61.334523 | Y23: =+[4]제주!$Q$85 -> 120267.82 | Z23: =+[4]제주!$R$85 -> 129027.92 | AA23: =+[5]제주!$Q$85 -> 120936.46 | AB23: =+[4]제주!$Q$89 -> 94758.915 | AC23: =+[4]제주!$R$89 -> 98460.087 | AD23: =+[5]제주!$Q$89 -> 89525.331 | AE23: =+Y23-AB23 -> 25508.905 | AF23: =+Z23-AC23 -> 30567.833 | AG23: =+AA23-AD23 -> 31411.133 | AI23: =+I23 -> 제주 | AJ23: =+J23/$J$27 -> 0.028248619 | AK23: =+K23/$K$27 -> 0.018993112 | AL23: =+AK23-AJ23 -> -0.0092555074 | AM23: =+Y23*AL23 -> -1113.1397 | AO23: =+[17]제주!$T$5/[17]합계!$T$5 -> 0.021669823 | AP23: =+AK23-AO23 -> -0.0026767105 | AQ23: =+[17]제주!$Q$85*AP23 -> -329.21777
F24: =+K24/J24 -> 0.99652239 | G24: =+I24 -> 수도권 | I24: 수도권 | J24: =SUM(J7:J10) -> 67 | K24: =SUM(K7:K10) -> 66.767 | L24: =+K24-J24 -> -0.233 | M24: =SUM(M7:M10) -> 74.2395 | N24: =+K24-M24 -> -7.4725 | O24: =SUM(O7:O10) -> 6582.5606 | P24: =SUM(P7:P10) -> 6845.202 | Q24: =+P24-O24 -> 262.64147 | R24: =SUM(R7:R10) -> 7199.5675 | S24: =+P24-R24 -> -354.36544 | T24: =SUM(T7:T10) -> -84.22563 | U24: =SUM(U7:U10) -> -192.26995 | V24: =+U24-T24 -> -108.04432 | W24: =SUM(W7:W10) -> 126.59635 | X24: =+U24-W24 -> -318.8663 | Y24: =+[4]수도권!$Q$85 -> 98247.173 | Z24: =+[4]수도권!$R$85 -> 102553.11 | AA24: =+[5]수도권!$Q$85 -> 96965.552 | AB24: =+[4]수도권!$Q$89 -> 83866.501 | AC24: =+[4]수도권!$R$89 -> 87993.51 | AD24: =+[5]수도권!$Q$89 -> 82274.26 | AE24: =+Y24-AB24 -> 14380.672 | AF24: =+Z24-AC24 -> 14559.601 | AG24: =+AA24-AD24 -> 14691.292 | AI24: =+I24 -> 수도권 | AJ24: =+J24/$J$27 -> 0.3785315 | AK24: =+K24/$K$27 -> 0.39272627 | AL24: =+AK24-AJ24 -> 0.014194766 | AM24: =+Y24*AL24 -> 1394.5957 | AO24: =+[17]수도권!$T$5/[17]합계!$T$5 -> 0.3793823 | AP24: =+AK24-AO24 -> 0.01334397 | AQ24: =+[17]수도권!$Q$85*AP24 -> 1390.2918
