Workbook

Sheet 표지
A6: 2026년 3월 마감 손익
A24: 레미콘사업본부

Sheet 손익총괄
C3: □ 건재사업본부 손익실적(2026-03)
X4: [단위 : 천㎥, 톤, 원/㎥, 원/톤, 백만원]
C5: 구분 | E5: 3월 | J5: 3월누계 | P5: 3월 주요지표
E6: 계획 | F6: 실적 | G6: 계획대비 | H6: 전년 | I6: 전년대비 | J6: 계획 | K6: 실적 | L6: 계획대비 | M6: 전년 | N6: 전년대비
C7: 물량 | D7: 레미콘 | E7: =+'[1]3월'!$Z$7/1000 -> 258.5 | F7: =+'[2]3월'!$Z$7/1000 -> 238.277 | G7: =+F7-E7 -> -20.223 | H7: =+'[3]3월'!$Z$7/1000 -> 265.927 | I7: =+F7-H7 -> -27.65 | J7: =+'[1]3월누계'!$Z$7/1000 -> 624.4998 | K7: =+'[2]3월누계'!$Z$7/1000 -> 584.4065 | L7: =+K7-J7 -> -40.0933 | M7: =+'[3]3월누계'!$Z$7/1000 -> 654.5855 | N7: =+K7-M7 -> -70.179 | Q7: □ 레미콘
D8: 골재 | E8: =+'[1]3월'!$AE$7/1000 -> 67.358804 | F8: =+'[2]3월'!$AN$7/1000 -> 71.063 | G8: =+F8-E8 -> 3.7041961 | H8: =+'[3]3월'!$AN$7/1000 -> 61.211 | I8: =+F8-H8 -> 9.852 | J8: =+'[1]3월누계'!$AE$7/1000 -> 202.41263 | K8: =+'[2]3월누계'!$AN$7/1000 -> 177.23 | L8: =+K8-J8 -> -25.182631 | M8: =+'[3]3월누계'!$AN$7/1000 -> 167.4 | N8: =+K8-M8 -> 9.83 | Q8: 구분 | S8: 계획 | T8: 실적 | U8: 계획대비 | V8: 전년 | W8: 전년대비
C9: 매출 | D9: 레미콘 | E9: =+'[1]3월'!$Z$8/1000 -> 26431.599 | F9: =+'[2]3월'!$Z$8/1000 -> 24485.299 | G9: =+F9-E9 -> -1946.3006 | H9: =+'[3]3월'!$Z$8/1000 -> 25879.148 | I9: =+F9-H9 -> -1393.849 | J9: =+'[1]3월누계'!$Z$8/1000 -> 63302.778 | K9: =+'[2]3월누계'!$Z$8/1000 -> 61013 | L9: =+K9-J9 -> -2289.7786 | M9: =+'[3]3월누계'!$Z$8/1000 -> 64876.307 | N9: =+K9-M9 -> -3863.3076 | Q9: 물량 | R9: 수도권 | S9: =+[4]수도권!$T$5/1000 -> 102 | T9: =+[4]수도권!$U$5/1000 -> 99.251 | U9: =+T9-S9 -> -2.749 | V9: =+[5]수도권!$T$5/1000 -> 93.47 | W9: =+T9-V9 -> 5.781
D10: 골재 | E10: =+'[1]3월'!$AE$8/1000 -> 1207.5321 | F10: =+'[2]3월'!$AN$8/1000 -> 1365.4242 | G10: =+F10-E10 -> 157.89213 | H10: =+'[3]3월'!$AN$8/1000 -> 1283.417 | I10: =+F10-H10 -> 82.0072 | J10: =+'[1]3월누계'!$AE$8/1000 -> 3668.2883 | K10: =+'[2]3월누계'!$AN$8/1000 -> 3539.703 | L10: =+K10-J10 -> -128.58531 | M10: =+'[3]3월누계'!$AN$8/1000 -> 3577.7485 | N10: =+K10-M10 -> -38.0455 | R10: 영남권 | S10: =+[4]영남권!$T$5/1000 -> 110 | T10: =+[4]영남권!$U$5/1000 -> 90.495 | U10: =+T10-S10 -> -19.505 | V10: =+[5]영남권!$T$5/1000 -> 117.338 | W10: =+T10-V10 -> -26.843
D11: 기타 | E11: =+'[1]3월'!$E$8/1000-E9-E33-E10 -> 123.53333 | F11: =+('[2]3월'!$BJ$8+'[2]3월'!$BA$8+'[2]3월'!$AP$8+'[2]3월'!$AH$8)/1000 -> 241.14624 | G11: =+F11-E11 -> 117.61291 | H11: =+'[3]3월'!$F$8/1000-H9-H33-H10 -> 141.06233 | I11: =+F11-H11 -> 100.08391 | J11: =+'[1]3월누계'!$E$8/1000-J9-J33-J10 -> 365.9 | K11: =+('[2]3월누계'!$BJ$8+'[2]3월누계'!$BA$8+'[2]3월누계'!$AP$8+'[2]3월누계'!$AH$8)/1000 -> 350.47234 | L11: =+K11-J11 -> -15.427657 | M11: =+'[3]3월누계'!$F$8/1000-M9-M33-M10 -> 472.83429 | N11: =+K11-M11 -> -122.36195 | R11: 중부권 | S11: =+[4]중부권!$T$5/1000 -> 46.5 | T11: =+[4]중부권!$U$5/1000 -> 48.531 | U11: =+T11-S11 -> 2.031 | V11: =+[5]중부권!$T$5/1000 -> 55.119 | W11: =+T11-V11 -> -6.588
C12: 계 | E12: =SUM(E9:E11) -> 27762.665 | F12: =SUM(F9:F11) -> 26091.869 | G12: =+F12-E12 -> -1670.7955 | H12: =SUM(H9:H11) -> 27303.627 | I12: =+F12-H12 -> -1211.7579 | J12: =SUM(J9:J11) -> 67336.967 | K12: =SUM(K9:K11) -> 64903.175 | L12: =+K12-J12 -> -2433.7916 | M12: =SUM(M9:M11) -> 68926.89 | N12: =+K12-M12 -> -4023.7151 | Q12: 계 | S12: =SUM(S9:S11) -> 258.5 | T12: =SUM(T9:T11) -> 238.277 | U12: =+T12-S12 -> -20.223 | V12: =SUM(V9:V11) -> 265.927 | W12: =+T12-V12 -> -27.65
C13: 매출원가 | D13: 레미콘 | E13: =+('[1]3월'!$Z$10+'[1]3월'!$Z$19)/1000 -> 23656.081 | F13: =+('[2]3월'!$Z$10+'[2]3월'!$Z$19)/1000 -> 22378.737 | G13: =+F13-E13 -> -1277.3442 | H13: =+('[3]3월'!$Z$10+'[3]3월'!$Z$19)/1000 -> 23517.883 | I13: =+F13-H13 -> -1139.1462 | J13: =+('[1]3월누계'!$Z$10+'[1]3월누계'!$Z$19)/1000 -> 59117.457 | K13: =+('[2]3월누계'!$Z$10+'[2]3월누계'!$Z$19)/1000 -> 57534.951 | L13: =+K13-J13 -> -1582.5065 | M13: =+('[3]3월누계'!$Z$10+'[3]3월누계'!$Z$19)/1000 -> 60218.076 | N13: =+K13-M13 -> -2683.1251 | Q13: 판매단가 | R13: 수도권 | S13: =+[4]수도권!$T$61 -> 100185.22 | T13: =+[4]수도권!$U$61 -> 98854.894 | U13: =+T13-S13 -> -1330.3213 | V13: =+[5]수도권!$Q$85 -> 93007.036 | W13: =+T13-V13 -> 5847.8584
D14: 골재 | E14: =+('[1]3월'!$AE$10+'[1]3월'!$AE$19)/1000 -> 1207.5407 | F14: =+('[2]3월'!$AN$10+'[2]3월'!$AN$19)/1000 -> 1411.2819 | G14: =+F14-E14 -> 203.74126 | H14: =+('[3]3월'!$AN$10+'[3]3월'!$AN$19)/1000 -> 1364.7504 | I14: =+F14-H14 -> 46.531485 | J14: =+('[1]3월누계'!$AE$10+'[1]3월누계'!$AE$19)/1000 -> 3770.6353 | K14: =+('[2]3월누계'!$AN$10+'[2]3월누계'!$AN$19)/1000 -> 3815.9293 | L14: =+K14-J14 -> 45.294007 | M14: =+('[3]3월누계'!$AN$10+'[3]3월누계'!$AN$19)/1000 -> 3941.0665 | N14: =+K14-M14 -> -125.13719 | R14: 영남권 | S14: =+[4]영남권!$T$61 -> 103621.41 | T14: =+[4]영남권!$U$61 -> 106535.28 | U14: =+T14-S14 -> 2913.8689 | V14: =+[5]영남권!$Q$85 -> 98256.721 | W14: =+T14-V14 -> 8278.5574
D15: 기타 | E15: =+('[1]3월'!$AL$10+'[1]3월'!$AL$19+'[1]3월'!$AV$10+'[1]3월'!$AV$19)/1000 -> -312.16936 | F15: =+('[2]3월'!$AH$10+'[2]3월'!$AH$19+'[2]3월'!$AP$10+'[2]3월'!$AP$19+'[2]3월'!$BA$10+'[2]3월'!$BA$19+'[2]3월'!$BJ$10+'[2]3월'!$BJ$19)/1000 -> -127.2281 | G15: =+F15-E15 -> 184.94126 | H15: =+('[3]3월'!$F$10+'[3]3월'!$F$19)/1000-H13-H14-('[3]3월'!$AO$10+'[3]3월'!$AO$19)/1000 -> 22.176476 | I15: =+F15-H15 -> -149.40457 | J15: =+('[1]3월누계'!$AL$10+'[1]3월누계'!$AL$19+'[1]3월누계'!$AV$10+'[1]3월누계'!$AV$19)/1000 -> -273.59543 | K15: =+('[2]3월누계'!$AH$10+'[2]3월누계'!$AH$19+'[2]3월누계'!$AP$10+'[2]3월누계'!$AP$19+'[2]3월누계'!$BA$10+'[2]3월누계'!$BA$19+'[2]3월누계'!$BJ$10+'[2]3월누계'!$BJ$19)/1000 -> -449.81201 | L15: =+K15-J15 -> -176.21658 | M15: =+('[3]3월누계'!$F$10+'[3]3월누계'!$F$19)/1000-M13-M14-('[3]3월누계'!$AO$10+'[3]3월누계'!$AO$19)/1000 -> 381.60009 | N15: =+K15-M15 -> -831.4121 | R15: 중부권 | S15: =+[4]중부권!$T$61 -> 103534.46 | T15: =+[4]중부권!$U$61 -> 103857.2 | U15: =+T15-S15 -> 322.74865 | V15: =+[5]중부권!$Q$85 -> 102574.02 | W15: =+T15-V15 -> 1283.188
C16: 계 | E16: =SUM(E13:E15) -> 24551.453 | F16: =SUM(F13:F15) -> 23662.791 | G16: =+F16-E16 -> -888.66167 | H16: =SUM(H13:H15) -> 24904.81 | I16: =+F16-H16 -> -1242.0193 | J16: =SUM(J13:J15) -> 62614.497 | K16: =SUM(K13:K15) -> 60901.068 | L16: =+K16-J16 -> -1713.4291 | M16: =SUM(M13:M15) -> 64540.742 | N16: =+K16-M16 -> -3639.6744 | Q16: 계 | S16: =+[4]합계!$T$61 -> 102249.9 | T16: =+[4]합계!$U$61 -> 102799.58 | U16: =+T16-S16 -> 549.68371 | V16: =+[5]합계!$Q$85 -> 97314.829 | W16: =+T16-V16 -> 5484.755
C17: 매출이익 | D17: 레미콘 | E17: =+E9-E13 -> 2775.5179 | F17: =+F9-F13 -> 2106.5616 | G17: =+F17-E17 -> -668.95638 | H17: =+H9-H13 -> 2361.2644 | I17: =+F17-H17 -> -254.70283 | J17: =+J9-J13 -> 4185.3212 | K17: =+K9-K13 -> 3478.0491 | L17: =+K17-J17 -> -707.27206 | M17: =+M9-M13 -> 4658.2316 | N17: =+K17-M17 -> -1180.1825 | Q17: 공헌이익 | R17: 수도권 | S17: =+[4]수도권!$Q$90 -> 17861.214 | T17: =+[4]수도권!$R$90 -> 14219.627 | U17: =+T17-S17 -> -3641.5868 | V17: =+[5]수도권!$Q$90 -> 12300.18 | W17: =+T17-V17 -> 1919.4467
D18: 골재 | E18: =+E10-E14 -> -0.0085986706 | F18: =+F10-F14 -> -45.857726 | G18: =+F18-E18 -> -45.849127 | H18: =+H10-H14 -> -81.333441 | I18: =+F18-H18 -> 35.475715 | J18: =+J10-J14 -> -102.34698 | K18: =+K10-K14 -> -276.2263 | L18: =+K18-J18 -> -173.87932 | M18: =+M10-M14 -> -363.31799 | N18: =+K18-M18 -> 87.091689 | R18: 영남권 | S18: =+[4]영남권!$Q$90 -> 23276.341 | T18: =+[4]영남권!$R$90 -> 22651.543 | U18: =+T18-S18 -> -624.79827 | V18: =+[5]영남권!$Q$90 -> 20424.307 | W18: =+T18-V18 -> 2227.2359
D19: 기타 | E19: =+E11-E15 -> 435.70269 | F19: =+F11-F15 -> 368.37433 | G19: =+F19-E19 -> -67.328358 | H19: =+H11-H15 -> 118.88585 | I19: =+F19-H19 -> 249.48848 | J19: =+J11-J15 -> 639.49543 | K19: =+K11-K15 -> 800.28436 | L19: =+K19-J19 -> 160.78892 | M19: =+M11-M15 -> 91.234206 | N19: =+K19-M19 -> 709.05015 | R19: 중부권 | S19: =+[4]중부권!$Q$90 -> 23262.909 | T19: =+[4]중부권!$R$90 -> 22157.104 | U19: =+T19-S19 -> -1105.8048 | V19: =+[5]중부권!$Q$90 -> 21953.416 | W19: =+T19-V19 -> 203.68836
C20: 계 | E20: =SUM(E17:E19) -> 3211.212 | F20: =SUM(F17:F19) -> 2429.0782 | G20: =+F20-E20 -> -782.13386 | H20: =SUM(H17:H19) -> 2398.8168 | I20: =+F20-H20 -> 30.261368 | J20: =SUM(J17:J19) -> 4722.4696 | K20: =SUM(K17:K19) -> 4002.1072 | L20: =+K20-J20 -> -720.36245 | M20: =SUM(M17:M19) -> 4386.1478 | N20: =+K20-M20 -> -384.04064 | Q20: 계 | S20: =+[4]합계!$Q$90 -> 21137.202 | T20: =+[4]합계!$R$90 -> 19049.613 | U20: =+T20-S20 -> -2087.5886 | V20: =+[5]합계!$Q$90 -> 17907.066 | W20: =+T20-V20 -> 1142.5467
C21: 판관비 | D21: 레미콘 | E21: =+('[1]3월'!$Z$13+'[1]3월'!$Z$20+'[1]3월'!$Z$22)/1000 -> 1997.8487 | F21: =+('[2]3월'!$Z$13+'[2]3월'!$Z$20+'[2]3월'!$Z$22)/1000 -> 1986.669 | G21: =+F21-E21 -> -11.179674 | H21: =+('[3]3월'!$Z$13+'[3]3월'!$Z$20+'[3]3월'!$Z$22)/1000 -> 2007.1221 | I21: =+F21-H21 -> -20.453143 | J21: =+('[1]3월누계'!$Z$13+'[1]3월누계'!$Z$20+'[1]3월누계'!$Z$22)/1000 -> 6445.8994 | K21: =+('[2]3월누계'!$Z$13+'[2]3월누계'!$Z$20+'[2]3월누계'!$Z$22)/1000 -> 6705.0814 | L21: =+K21-J21 -> 259.18202 | M21: =+('[3]3월누계'!$Z$13+'[3]3월누계'!$Z$20+'[3]3월누계'!$Z$22)/1000 -> 6253.0665 | N21: =+K21-M21 -> 452.01485 | Q21: □ 골재
D22: 골재 | E22: =+('[1]3월'!$AE$13+'[1]3월'!$AE$20+'[1]3월'!$AE$22)/1000 -> 49.430094 | F22: =+('[2]3월'!$AN$13+'[2]3월'!$AN$20+'[2]3월'!$AN$22)/1000 -> 48.928915 | G22: =+F22-E22 -> -0.50117863 | H22: =+('[3]3월'!$AN$13+'[3]3월'!$AN$20+'[3]3월'!$AN$22)/1000 -> 45.48203 | I22: =+F22-H22 -> 3.4468856 | J22: =+('[1]3월누계'!$AE$13+'[1]3월누계'!$AE$20+'[1]3월누계'!$AE$22)/1000 -> 152.90765 | K22: =+('[2]3월누계'!$AN$13+'[2]3월누계'!$AN$20+'[2]3월누계'!$AN$22)/1000 -> 155.83804 | L22: =+K22-J22 -> 2.9303862 | M22: =+('[3]3월누계'!$AN$13+'[3]3월누계'!$AN$20+'[3]3월누계'!$AN$22)/1000 -> 141.72707 | N22: =+K22-M22 -> 14.110965 | Q22: 구분 | S22: 계획 | T22: 실적 | U22: 계획대비 | V22: 전년 | W22: 전년대비
D23: 기타 | E23: =+('[1]3월'!$AL$13+'[1]3월'!$AV$13+'[1]3월'!$AL$20+'[1]3월'!$AV$20+'[1]3월'!$AL$22+'[1]3월'!$AV$22)/1000 -> 38.376884 | F23: =+('[2]3월'!$F$13+'[2]3월'!$F$20+'[2]3월'!$F$22)/1000-F21-F22-('[2]3월'!$AO$13+'[2]3월'!$AO$20+'[2]3월'!$AO$22)/1000 -> -168.39279 | G23: =+F23-E23 -> -206.76968 | H23: =+('[3]3월'!$F$13+'[3]3월'!$F$20+'[3]3월'!$F$22)/1000-H21-H22-('[3]3월'!$AO$13+'[3]3월'!$AO$20+'[3]3월'!$AO$22)/1000 -> 537.35408 | I23: =+F23-H23 -> -705.74687 | J23: =+('[1]3월누계'!$AL$13+'[1]3월누계'!$AV$13+'[1]3월누계'!$AL$20+'[1]3월누계'!$AV$20+'[1]3월누계'!$AL$22+'[1]3월누계'!$AV$22)/1000 -> 157.147 | K23: =+('[2]3월누계'!$F$13+'[2]3월누계'!$F$20+'[2]3월누계'!$F$22)/1000-K21-K22-('[2]3월누계'!$AO$13+'[2]3월누계'!$AO$20+'[2]3월누계'!$AO$22)/1000 -> -48.200134 | L23: =+K23-J23 -> -205.34714 | M23: =+('[3]3월누계'!$F$13+'[3]3월누계'!$F$20+'[3]3월누계'!$F$22)/1000-M21-M22-('[3]3월누계'!$AO$13+'[3]3월누계'!$AO$20+'[3]3월누계'!$AO$22)/1000 -> 1094.3863 | N23: =+K23-M23 -> -1142.5864 | Q23: 판매량 | R23: 자가 | S23: =+[6]원가손익!$W$10+[7]원가손익!$U$27+[8]손익!$F$10 -> 42198.804 | T23: =+[6]원가손익!$X$10+[7]원가손익!$V$27+[8]손익!$G$10 -> 51616 | U23: =+T23-S23 -> 9417.1961 | V23: =+[9]원가손익!$X$10+[10]원가손익!$V$27+[11]손익!$Y$25 -> 31410 | W23: =+T23-V23 -> 20206
C24: 계 | E24: =SUM(E21:E23) -> 2085.6556 | F24: =SUM(F21:F23) -> 1867.2051 | G24: =+F24-E24 -> -218.45053 | H24: =SUM(H21:H23) -> 2589.9582 | I24: =+F24-H24 -> -722.75313 | J24: =SUM(J21:J23) -> 6755.954 | K24: =SUM(K21:K23) -> 6812.7193 | L24: =+K24-J24 -> 56.765274 | M24: =SUM(M21:M23) -> 7489.1799 | N24: =+K24-M24 -> -676.4606 | R24: 외판 | S24: =+[6]원가손익!$W$14+[7]원가손익!$U$29+[8]손익!$F$12 -> 25160 | T24: =+[6]원가손익!$X$14+[7]원가손익!$V$29+[8]손익!$G$12 -> 19447 | U24: =+T24-S24 -> -5713 | V24: =+[9]원가손익!$X$14+[10]원가손익!$V$29+[11]손익!$Y$27 -> 26527 | W24: =+T24-V24 -> -7080
C25: 영업이익 | D25: 레미콘 | E25: =+E17-E21 -> 777.66927 | F25: =+F17-F21 -> 119.89257 | G25: =+F25-E25 -> -657.7767 | H25: =+H17-H21 -> 354.14225 | I25: =+F25-H25 -> -234.24969 | J25: =+J17-J21 -> -2260.5782 | K25: =+K17-K21 -> -3227.0323 | L25: =+K25-J25 -> -966.45408 | M25: =+M17-M21 -> -1594.8349 | N25: =+K25-M25 -> -1632.1973 | Q25: 합 계 | S25: =SUM(S23:S24) -> 67358.804 | T25: =SUM(T23:T24) -> 71063 | U25: =+T25-S25 -> 3704.1961 | V25: =SUM(V23:V24) -> 57937 | W25: =+T25-V25 -> 13126
D26: % | E26: =+E25/E9 -> 0.029421953 | F26: =+F25/F9 -> 0.0048965124 | G26: =+F26-E26 -> -0.024525441 | H26: =+H25/H9 -> 0.013684464 | I26: =+F26-H26 -> -0.0087879513 | J26: =+J25/J9 -> -0.035710568 | K26: =+K25/K9 -> -0.052890897 | L26: =+K26-J26 -> -0.017180328 | M26: =+M25/M9 -> -0.024582702 | N26: =+K26-M26 -> -0.028308194 | Q26: □ 기타내역(영업이익)
D27: 골재 | E27: =+E18-E22 -> -49.438693 | F27: =+F18-F22 -> -94.786641 | G27: =+F27-E27 -> -45.347949 | H27: =+H18-H22 -> -126.81547 | I27: =+F27-H27 -> 32.028829 | J27: =+J18-J22 -> -255.25463 | K27: =+K18-K22 -> -432.06434 | L27: =+K27-J27 -> -176.80971 | M27: =+M18-M22 -> -505.04506 | N27: =+K27-M27 -> 72.980724 | Q27: 구분 | S27: 계획 | T27: 실적 | U27: 계획대비 | V27: 전년 | W27: 전년대비
D28: 기타 | E28: =+E19-E23 -> 397.32581 | F28: =+F19-F23 -> 536.76713 | G28: =+F28-E28 -> 139.44132 | H28: =+H19-H23 -> -418.46822 | I28: =+F28-H28 -> 955.23535 | J28: =+J19-J23 -> 482.34843 | K28: =+K19-K23 -> 848.48449 | L28: =+K28-J28 -> 366.13606 | M28: =+M19-M23 -> -1003.1521 | N28: =+K28-M28 -> 1851.6366 | Q28: 레미콘임대 | S28: =+'사업장별(당월)'!T32 -> 32.447924 | T28: =+'사업장별(당월)'!U32 -> 26.803493 | U28: =+T28-S28 -> -5.6444307 | V28: =+'사업장별(당월)'!W32 -> 46.568992 | W28: =+T28-V28 -> -19.765499
C29: 계 | E29: =+E25+E27+E28 -> 1125.5564 | F29: =+F25+F27+F28 -> 561.87305 | G29: =+F29-E29 -> -563.68333 | H29: =+H25+H27+H28 -> -191.14144 | I29: =+F29-H29 -> 753.01449 | J29: =+J25+J27+J28 -> -2033.4844 | K29: =+K25+K27+K28 -> -2810.6121 | L29: =+K29-J29 -> -777.12773 | M29: =+M25+M27+M28 -> -3103.0321 | N29: =+K29-M29 -> 292.41996 | Q29: 임대 | S29: =+'사업장별(당월)'!T33 -> 76.544099 | T29: =+'사업장별(당월)'!U33 -> 192.6119 | U29: =+T29-S29 -> 116.0678 | V29: =+'사업장별(당월)'!W33 -> 76.003665 | W29: =+T29-V29 -> 116.60823
D30: % | E30: =+E29/E12 -> 0.040542088 | F30: =+F29/F12 -> 0.021534412 | G30: =+F30-E30 -> -0.019007676 | H30: =+H29/H12 -> -0.0070005879 | I30: =+F30-H30 -> 0.028535 | J30: =+J29/J12 -> -0.030198634 | K30: =+K29/K12 -> -0.043304694 | L30: =+K30-J30 -> -0.01310606 | M30: =+M29/M12 -> -0.04501918 | N30: =+K30-M30 -> 0.0017144864 | Q30: 공통비 | S30: =+'사업장별(당월)'!T34 -> -1289.5109 | T30: =+'사업장별(당월)'!U34 -> -1294.5632 | U30: =+T30-S30 -> -5.0523647 | V30: =+'사업장별(당월)'!W34 -> -1338.7445 | W30: =+T30-V30 -> 44.181259
C31: * 건자재 | Q31: 기타 | S31: =+S32-S28-S29-S30 -> 288.33379 | T31: =+T32-T28-T29-T30 -> 317.35174 | U31: =+T31-S31 -> 29.017952 | V31: =+V32-V28-V29-V30 -> -541.04088 | W31: =+T31-V31 -> 858.39262
C32: 물량 | E32: =+IFERROR(HLOOKUP($E$5,[12]손익!$G$5:$AI$54,2,),) -> 8500 | F32: =+'[2]3월'!$AO$7 -> 3925.464 | G32: =+F32-E32 -> -4574.536 | H32: =+'[3]3월'!$AO$7 -> 15762.77 | I32: =+F32-H32 -> -11837.306 | J32: =+'[1]3월누계'!$AA$7 -> 23500 | K32: =+'[2]3월누계'!$AO$7 -> 13878.238 | L32: =+K32-J32 -> -9621.762 | M32: =+'[3]3월누계'!$AO$7 -> 34222.795 | N32: =+K32-M32 -> -20344.557 | Q32: 합계 | S32: =+'사업장별(당월)'!T40 -> -892.18505 | T32: =+'사업장별(당월)'!U40 -> -757.7961 | U32: =+T32-S32 -> 134.38895 | V32: =+'사업장별(당월)'!W40 -> -1757.2127 | W32: =+T32-V32 -> 999.41661
C33: 매출 | E33: =+IFERROR(HLOOKUP($E$5,[12]손익!$G$5:$AI$54,3,),)/1000 -> 8197.6135 | F33: =+'[2]3월'!$AO$8/1000 -> 4017.7919 | G33: =+F33-E33 -> -4179.8216 | H33: =+'[3]3월'!$AO$8/1000 -> 12535.229 | I33: =+F33-H33 -> -8517.4368 | J33: =+'[1]3월누계'!$AA$8/1000 -> 22587.069 | K33: =+'[2]3월누계'!$AO$8/1000 -> 13994.382 | L33: =+K33-J33 -> -8592.6876 | M33: =+'[3]3월누계'!$AO$8/1000 -> 28292.343 | N33: =+K33-M33 -> -14297.962
C34: 매출이익 | E34: =+IFERROR(HLOOKUP($E$5,[12]손익!$G$5:$AI$54,7,),)/1000 -> 177.35419 | F34: =+'[2]3월'!$AO$12/1000 -> 63.273636 | G34: =+F34-E34 -> -114.08055 | H34: =+'[3]3월'!$AO$12/1000 -> 36.844564 | I34: =+F34-H34 -> 26.429072 | J34: =+'[1]3월누계'!$AA$12/1000 -> 482.74631 | K34: =+'[2]3월누계'!$AO$12/1000 -> 331.89495 | L34: =+K34-J34 -> -150.85136 | M34: =+'[3]3월누계'!$AO$12/1000 -> 332.4161 | N34: =+K34-M34 -> -0.52115 | Q34: □ 건자재
C35: (%) | E35: =+E34/E33 -> 0.021634856 | F35: =+F34/F33 -> 0.015748361 | G35: =+F35-E35 -> -0.005886495 | H35: =+H34/H33 -> 0.0029392814 | I35: =+I34/I33 -> -0.0031029373 | J35: =+J34/J33 -> 0.021372685 | K35: =+K34/K33 -> 0.0237163 | L35: =+K35-J35 -> 0.002343615 | M35: =+M34/M33 -> 0.011749331 | N35: =+K35-M35 -> 0.011966969 | Q35: 구분 | S35: 계획 | T35: 실적 | U35: 계획대비 | V35: 전년 | W35: 전년대비
C36: 영업이익 | E36: =+IFERROR(HLOOKUP($E$5,[12]손익!$G$5:$AI$54,20,),)/1000 -> -2.7137755 | F36: =+'[2]3월'!$AO$26/1000 -> 1.360901 | G36: =+F36-E36 -> 4.0746765 | H36: =+'[3]3월'!$AO$26/1000 -> -118.87035 | I36: =+F36-H36 -> 120.23125 | J36: =+'[1]3월누계'!$AA$26/1000 -> -85.427511 | K36: =+'[2]3월누계'!$AO$26/1000 -> -118.75362 | L36: =+K36-J36 -> -33.326111 | M36: =+'[3]3월누계'!$AO$26/1000 -> -106.31139 | N36: =+K36-M36 -> -12.442236 | Q36: 철강재 판매단가 | S36: =+'[13]3월'!$F$10 -> 745617.65 | T36: =+'[13]3월'!$G$10 -> 807163.01 | U36: =+T36-S36 -> 61545.363 | V36: =+'[14]3월'!$G$10 -> 736140.84 | W36: =+T36-V36 -> 71022.171
C37: (%) | E37: =+E36/E33 -> -0.00033104458 | F37: =+F36/F33 -> 0.00033871864 | G37: =+F37-E37 -> 0.00066976322 | H37: =+H36/H33 -> -0.0094829022 | I37: =+F37-H37 -> 0.0098216209 | J37: =+J36/J33 -> -0.0037821423 | K37: =+K36/K33 -> -0.008485807 | L37: =+K37-J37 -> -0.0047036646 | M37: =+M36/M33 -> -0.0037576027 | N37: =+K37-M37 -> -0.0047282043 | Q37: 철강재 마진률 | S37: =+'[13]3월'!$F$15 -> 0.017269536 | T37: =+'[13]3월'!$G$15 -> 0.01261442 | U37: =+T37-S37 -> -0.0046551155 | V37: =+'[14]3월'!$G$15 -> 0.0014844908 | W37: =+T37-V37 -> 0.011129929
E39: =+'[1]3월'!$E$26/1000 -> 1122.8426 | F39: =+'[2]3월'!$F$26/1000 -> 563.23395 | H39: =+'[3]3월'!$F$26/1000 -> -310.01179 | J39: =+'[1]3월누계'!$E$26/1000 -> -2118.9119 | K39: =+'[2]3월누계'!$F$26/1000 -> -2929.3657 | M39: =+'[3]3월누계'!$F$26/1000 -> -3209.3435
E40: =+(E29+E36)-E39 -> -4.0927262e-12 | F40: =+(F29+F36)-F39 -> 6.9348971e-12 | H40: =+(H29+H36)-H39 -> 6.0822458e-12 | J40: =+(J29+J36)-J39 -> 0 | K40: =+(K29+K36)-K39 -> 0 | M40: =+(M29+M36)-M39 -> 0

Sheet 레미콘 영업이익
H3: □ 레미콘 영업이익(3월)
H5: 구분 | J5: 3월 | T5: 3월누계
J6: 영업이익(공통비 배부전) | O6: 영업이익(공통비 배부후) | T6: 영업이익(공통비 배부전) | Y6: 영업이익(공통비 배부전)
A7: 2024년 1월 마감 손익 | J7: 계획 | K7: 실적 | L7: 차이 | M7: 전년 | N7: 차이 | O7: 계획 | P7: 실적 | Q7: 차이 | R7: 전년 | S7: 차이 | T7: 계획 | U7: 실적 | V7: 차이 | W7: 전년 | X7: 차이 | Y7: 계획 | Z7: 실적 | AA7: 차이 | AB7: 전년 | AC7: 차이
B8: 안양 | H8: 레미콘 | I8: 안양 | J8: =+[4]안양!$H$86/1000 -> 399.94344 | K8: =+[4]안양!$I$86/1000 -> 386.86276 | L8: =+K8-J8 -> -13.080678 | M8: =+[5]안양!$H$86/1000 -> 190.6149 | N8: =+K8-M8 -> 196.24786 | O8: =+[4]안양!$H$92/1000 -> 218.84603 | P8: =+[4]안양!$I$92/1000 -> 170.98331 | Q8: =+P8-O8 -> -47.862728 | R8: =+[5]안양!$H$92/1000 -> 12.112096 | S8: =+P8-R8 -> 158.87121 | T8: =+[15]안양!$H$86/1000 -> 685.69687 | U8: =+[15]안양!$I$86/1000 -> 771.50179 | V8: =+U8-T8 -> 85.804927 | W8: =+[16]안양!$H$86/1000 -> 544.25705 | X8: =+U8-W8 -> 227.24475 | Y8: =+[15]안양!$H$92/1000 -> 50.151311 | Z8: =+[15]안양!$I$92/1000 -> 10.088312 | AA8: =+Z8-Y8 -> -40.063 | AB8: =+[16]안양!$H$92/1000 -> -75.049966 | AC8: =+Z8-AB8 -> 85.138278
B9: 인천 | H9: 직영 | I9: 인천 | J9: =+[4]인천!$H$86/1000 -> 233.65111 | K9: =+[4]인천!$I$86/1000 -> 34.480905 | L9: =+K9-J9 -> -199.17021 | M9: =+[5]인천!$H$86/1000 -> 97.876781 | N9: =+K9-M9 -> -63.395876 | O9: =+[4]인천!$H$92/1000 -> 62.817834 | P9: =+[4]인천!$I$92/1000 -> -128.18976 | Q9: =+P9-O9 -> -191.00759 | R9: =+[5]인천!$H$92/1000 -> -59.939543 | S9: =+P9-R9 -> -68.250214 | T9: =+[15]인천!$H$86/1000 -> 168.33299 | U9: =+[15]인천!$I$86/1000 -> -74.324904 | V9: =+U9-T9 -> -242.6579 | W9: =+[16]인천!$H$86/1000 -> -78.653321 | X9: =+U9-W9 -> 4.328417 | Y9: =+[15]인천!$H$92/1000 -> -385.64647 | Z9: =+[15]인천!$I$92/1000 -> -620.96082 | AA9: =+Z9-Y9 -> -235.31436 | AB9: =+[16]인천!$H$92/1000 -> -502.92909 | AC9: =+Z9-AB9 -> -118.03173
B10: 파주 | I10: 파주 | J10: =+[4]파주!$H$86/1000 -> 20.418977 | K10: =+[4]파주!$I$86/1000 -> -80.522035 | L10: =+K10-J10 -> -100.94101 | M10: =+[5]파주!$H$86/1000 -> -148.3122 | N10: =+K10-M10 -> 67.790166 | O10: =+[4]파주!$H$92/1000 -> -49.282803 | P10: =+[4]파주!$I$92/1000 -> -136.91396 | Q10: =+P10-O10 -> -87.631159 | R10: =+[5]파주!$H$92/1000 -> -194.04474 | S10: =+P10-R10 -> 57.130775 | T10: =+[15]파주!$H$86/1000 -> -188.11454 | U10: =+[15]파주!$I$86/1000 -> -344.08391 | V10: =+U10-T10 -> -155.96937 | W10: =+[16]파주!$H$86/1000 -> -297.59622 | X10: =+U10-W10 -> -46.487699 | Y10: =+[15]파주!$H$92/1000 -> -403.5781 | Z10: =+[15]파주!$I$92/1000 -> -538.62942 | AA10: =+Z10-Y10 -> -135.05132 | AB10: =+[16]파주!$H$92/1000 -> -474.78391 | AC10: =+Z10-AB10 -> -63.845501
B11: 김포 | I11: 김포 | J11: =+[4]김포!$H$86/1000 -> 39.479855 | K11: =+[4]김포!$I$86/1000 -> 17.589357 | L11: =+K11-J11 -> -21.890498 | M11: =+[5]김포!$H$86/1000 -> 38.862012 | N11: =+K11-M11 -> -21.272655 | O11: =+[4]김포!$H$92/1000 -> -21.860145 | P11: =+[4]김포!$I$92/1000 -> -51.451573 | Q11: =+P11-O11 -> -29.591428 | R11: =+[5]김포!$H$92/1000 -> -16.745469 | S11: =+P11-R11 -> -34.706104 | T11: =+[15]김포!$H$86/1000 -> -56.954855 | U11: =+[15]김포!$I$86/1000 -> -203.34142 | V11: =+U11-T11 -> -146.38656 | W11: =+[16]김포!$H$86/1000 -> -115.34376 | X11: =+U11-W11 -> -87.997652 | Y11: =+[15]김포!$H$92/1000 -> -248.33498 | Z11: =+[15]김포!$I$92/1000 -> -396.06861 | AA11: =+Z11-Y11 -> -147.73364 | AB11: =+[16]김포!$H$92/1000 -> -259.4598 | AC11: =+Z11-AB11 -> -136.60881
B12: 부산 | I12: 부산 | J12: =+[4]부산!$H$86/1000 -> 252.0269 | K12: =+[4]부산!$I$86/1000 -> 323.34982 | L12: =+K12-J12 -> 71.322921 | M12: =+[5]부산!$H$86/1000 -> 403.32277 | N12: =+K12-M12 -> -79.972956 | O12: =+[4]부산!$H$92/1000 -> 138.95242 | P12: =+[4]부산!$I$92/1000 -> 180.50519 | Q12: =+P12-O12 -> 41.552768 | R12: =+[5]부산!$H$92/1000 -> 267.03058 | S12: =+P12-R12 -> -86.525391 | T12: =+[15]부산!$H$86/1000 -> 413.20018 | U12: =+[15]부산!$I$86/1000 -> 803.49873 | V12: =+U12-T12 -> 390.29855 | W12: =+[16]부산!$H$86/1000 -> 563.56659 | X12: =+U12-W12 -> 239.93214 | Y12: =+[15]부산!$H$92/1000 -> -14.019292 | Z12: =+[15]부산!$I$92/1000 -> 224.71316 | AA12: =+Z12-Y12 -> 238.73245 | AB12: =+[16]부산!$H$92/1000 -> 179.56071 | AC12: =+Z12-AB12 -> 45.152448
B13: 서부산 | I13: 서부산 | J13: =+[4]서부산!$H$86/1000 -> 303.00485 | K13: =+[4]서부산!$I$86/1000 -> 209.67643 | L13: =+K13-J13 -> -93.328419 | M13: =+[5]서부산!$H$86/1000 -> 146.35766 | N13: =+K13-M13 -> 63.318773 | O13: =+[4]서부산!$H$92/1000 -> 197.26031 | P13: =+[4]서부산!$I$92/1000 -> 96.379505 | Q13: =+P13-O13 -> -100.88081 | R13: =+[5]서부산!$H$92/1000 -> 55.998329 | S13: =+P13-R13 -> 40.381176 | T13: =+[15]서부산!$H$86/1000 -> 560.0386 | U13: =+[15]서부산!$I$86/1000 -> 388.20963 | V13: =+U13-T13 -> -171.82897 | W13: =+[16]서부산!$H$86/1000 -> 259.01918 | X13: =+U13-W13 -> 129.19045 | Y13: =+[15]서부산!$H$92/1000 -> 162.69289 | Z13: =+[15]서부산!$I$92/1000 -> 15.745056 | AA13: =+Z13-Y13 -> -146.94784 | AB13: =+[16]서부산!$H$92/1000 -> -52.03595 | AC13: =+Z13-AB13 -> 67.781006
B14: 김해 | I14: 김해 | J14: =+[4]김해!$H$86/1000 -> 66.063919 | K14: =+[4]김해!$I$86/1000 -> 13.214121 | L14: =+K14-J14 -> -52.849798 | M14: =+[5]김해!$H$86/1000 -> 55.355958 | N14: =+K14-M14 -> -42.141837 | O14: =+[4]김해!$H$92/1000 -> 19.755571 | P14: =+[4]김해!$I$92/1000 -> -26.756562 | Q14: =+P14-O14 -> -46.512132 | R14: =+[5]김해!$H$92/1000 -> -5.6537431 | S14: =+P14-R14 -> -21.102819 | T14: =+[15]김해!$H$86/1000 -> -5.4875343 | U14: =+[15]김해!$I$86/1000 -> -118.29678 | V14: =+U14-T14 -> -112.80924 | W14: =+[16]김해!$H$86/1000 -> -82.619591 | X14: =+U14-W14 -> -35.677188 | Y14: =+[15]김해!$H$92/1000 -> -166.03842 | Z14: =+[15]김해!$I$92/1000 -> -247.70445 | AA14: =+Z14-Y14 -> -81.666032 | AB14: =+[16]김해!$H$92/1000 -> -218.12216 | AC14: =+Z14-AB14 -> -29.582292
B15: 정관 | I15: 정관 | J15: =+[4]정관!$H$86/1000 -> 240.64452 | K15: =+[4]정관!$I$86/1000 -> 69.741612 | L15: =+K15-J15 -> -170.90291 | M15: =+[5]정관!$H$86/1000 -> 121.8508 | N15: =+K15-M15 -> -52.109191 | O15: =+[4]정관!$H$92/1000 -> 127.56805 | P15: =+[4]정관!$I$92/1000 -> -7.0220417 | Q15: =+P15-O15 -> -134.59009 | R15: =+[5]정관!$H$92/1000 -> 18.216996 | S15: =+P15-R15 -> -25.239037 | T15: =+[15]정관!$H$86/1000 -> 376.72294 | U15: =+[15]정관!$I$86/1000 -> -43.912337 | V15: =+U15-T15 -> -420.63527 | W15: =+[16]정관!$H$86/1000 -> 367.07069 | X15: =+U15-W15 -> -410.98303 | Y15: =+[15]정관!$H$92/1000 -> -51.952886 | Z15: =+[15]정관!$I$92/1000 -> -320.60378 | AA15: =+Z15-Y15 -> -268.6509 | AB15: =+[16]정관!$H$92/1000 -> -11.926384 | AC15: =+Z15-AB15 -> -308.6774
B16: 양산 | I16: 양산 | J16: =+[4]양산!$H$86/1000 -> 57.547751 | K16: =+[4]양산!$I$86/1000 -> 10.974981 | L16: =+K16-J16 -> -46.57277 | M16: =+[5]양산!$H$86/1000 -> 64.674861 | N16: =+K16-M16 -> -53.69988 | O16: =+[4]양산!$H$92/1000 -> 11.451931 | P16: =+[4]양산!$I$92/1000 -> -16.827523 | Q16: =+P16-O16 -> -28.279454 | R16: =+[5]양산!$H$92/1000 -> 15.847567 | S16: =+P16-R16 -> -32.67509 | T16: =+[15]양산!$H$86/1000 -> -13.598356 | U16: =+[15]양산!$I$86/1000 -> -84.36934 | V16: =+U16-T16 -> -70.770984 | W16: =+[16]양산!$H$86/1000 -> 47.353373 | X16: =+U16-W16 -> -131.72271 | Y16: =+[15]양산!$H$92/1000 -> -157.62418 | Z16: =+[15]양산!$I$92/1000 -> -188.03722 | AA16: =+Z16-Y16 -> -30.413041 | AB16: =+[16]양산!$H$92/1000 -> -101.5424 | AC16: =+Z16-AB16 -> -86.494823
B17: 창원 | I17: 창원 | J17: =+[4]창원!$H$86/1000 -> 52.912265 | K17: =+[4]창원!$I$86/1000 -> 26.96316 | L17: =+K17-J17 -> -25.949105 | M17: =+[5]창원!$H$86/1000 -> 89.749104 | N17: =+K17-M17 -> -62.785944 | O17: =+[4]창원!$H$92/1000 -> -6.1678759 | P17: =+[4]창원!$I$92/1000 -> -19.972217 | Q17: =+P17-O17 -> -13.804341 | R17: =+[5]창원!$H$92/1000 -> 32.900835 | S17: =+P17-R17 -> -52.873052 | T17: =+[15]창원!$H$86/1000 -> 11.632544 | U17: =+[15]창원!$I$86/1000 -> 8.068265 | V17: =+U17-T17 -> -3.5642793 | W17: =+[16]창원!$H$86/1000 -> 205.70844 | X17: =+U17-W17 -> -197.64018 | Y17: =+[15]창원!$H$92/1000 -> -189.75057 | Z17: =+[15]창원!$I$92/1000 -> -192.11789 | AA17: =+Z17-Y17 -> -2.3673218 | AB17: =+[16]창원!$H$92/1000 -> -4.8165667 | AC17: =+Z17-AB17 -> -187.30133
B18: 대구 | I18: 대구 | J18: =+[4]대구!$H$86/1000 -> -30.554162 | K18: =+[4]대구!$I$86/1000 -> -105.44824 | L18: =+K18-J18 -> -74.894079 | M18: =+[5]대구!$H$86/1000 -> -23.079407 | N18: =+K18-M18 -> -82.368834 | O18: =+[4]대구!$H$92/1000 -> -65.21434 | P18: =+[4]대구!$I$92/1000 -> -120.28845 | Q18: =+P18-O18 -> -55.074107 | R18: =+[5]대구!$H$92/1000 -> -75.428819 | S18: =+P18-R18 -> -44.859628 | T18: =+[15]대구!$H$86/1000 -> -105.14406 | U18: =+[15]대구!$I$86/1000 -> -288.35881 | V18: =+U18-T18 -> -183.21475 | W18: =+[16]대구!$H$86/1000 -> 10.470324 | X18: =+U18-W18 -> -298.82913 | Y18: =+[15]대구!$H$92/1000 -> -240.19265 | Z18: =+[15]대구!$I$92/1000 -> -363.49162 | AA18: =+Z18-Y18 -> -123.29897 | AB18: =+[16]대구!$H$92/1000 -> -184.35758 | AC18: =+Z18-AB18 -> -179.13404
B19: 울산 | I19: 울산 | J19: =+[4]울산!$H$86/1000 -> 82.087013 | K19: =+[4]울산!$I$86/1000 -> 95.170722 | L19: =+K19-J19 -> 13.083709 | M19: =+[5]울산!$H$86/1000 -> 108.61426 | N19: =+K19-M19 -> -13.443537 | O19: =+[4]울산!$H$92/1000 -> 21.127885 | P19: =+[4]울산!$I$92/1000 -> 26.150555 | Q19: =+P19-O19 -> 5.0226698 | R19: =+[5]울산!$H$92/1000 -> 41.383615 | S19: =+P19-R19 -> -15.233059 | T19: =+[15]울산!$H$86/1000 -> -45.619206 | U19: =+[15]울산!$I$86/1000 -> 190.63581 | V19: =+U19-T19 -> 236.25501 | W19: =+[16]울산!$H$86/1000 -> 244.35527 | X19: =+U19-W19 -> -53.719461 | Y19: =+[15]울산!$H$92/1000 -> -224.71124 | Z19: =+[15]울산!$I$92/1000 -> -77.975619 | AA19: =+Z19-Y19 -> 146.73563 | AB19: =+[16]울산!$H$92/1000 -> 19.943563 | AC19: =+Z19-AB19 -> -97.919183
B20: 아산 | I20: 아산 | J20: =+[4]아산!$H$86/1000 -> 88.591762 | K20: =+[4]아산!$I$86/1000 -> 69.207642 | L20: =+K20-J20 -> -19.38412 | M20: =+[5]아산!$H$86/1000 -> 139.57025 | N20: =+K20-M20 -> -70.362605 | O20: =+[4]아산!$H$92/1000 -> -11.78182 | P20: =+[4]아산!$I$92/1000 -> -41.395151 | Q20: =+P20-O20 -> -29.613331 | R20: =+[5]아산!$H$92/1000 -> 21.119953 | S20: =+P20-R20 -> -62.515104 | T20: =+[15]아산!$H$86/1000 -> -40.189479 | U20: =+[15]아산!$I$86/1000 -> 63.776526 | V20: =+U20-T20 -> 103.96601 | W20: =+[16]아산!$H$86/1000 -> 180.486 | X20: =+U20-W20 -> -116.70947 | Y20: =+[15]아산!$H$92/1000 -> -300.10455 | Z20: =+[15]아산!$I$92/1000 -> -320.14495 | AA20: =+Z20-Y20 -> -20.040393 | AB20: =+[16]아산!$H$92/1000 -> -196.41519 | AC20: =+Z20-AB20 -> -123.72976
B21: 전주 | I21: 전주 | J21: =+[4]전주!$H$86/1000 -> 64.392708 | K21: =+[4]전주!$I$86/1000 -> 138.57817 | L21: =+K21-J21 -> 74.185467 | M21: =+[5]전주!$H$86/1000 -> 206.10743 | N21: =+K21-M21 -> -67.529258 | O21: =+[4]전주!$H$92/1000 -> 16.189328 | P21: =+[4]전주!$I$92/1000 -> 68.357512 | Q21: =+P21-O21 -> 52.168184 | R21: =+[5]전주!$H$92/1000 -> 119.46098 | S21: =+P21-R21 -> -51.103471 | T21: =+[15]전주!$H$86/1000 -> -7.3665347 | U21: =+[15]전주!$I$86/1000 -> 47.117149 | V21: =+U21-T21 -> 54.483684 | W21: =+[16]전주!$H$86/1000 -> 458.992 | X21: =+U21-W21 -> -411.87485 | Y21: =+[15]전주!$H$92/1000 -> -145.06256 | Z21: =+[15]전주!$I$92/1000 -> -146.2911 | AA21: =+Z21-Y21 -> -1.2285436 | AB21: =+[16]전주!$H$92/1000 -> 194.57158 | AC21: =+Z21-AB21 -> -340.86268
B22: 군산 | I22: 군산 | J22: =+[4]군산!$H$86/1000 -> 75.349109 | K22: =+[4]군산!$I$86/1000 -> 88.678597 | L22: =+K22-J22 -> 13.329488 | M22: =+[5]군산!$H$86/1000 -> 131.89843 | N22: =+K22-M22 -> -43.21983 | O22: =+[4]군산!$H$92/1000 -> 52.160075 | P22: =+[4]군산!$I$92/1000 -> 60.777332 | Q22: =+P22-O22 -> 8.6172561 | R22: =+[5]군산!$H$92/1000 -> 100.59709 | S22: =+P22-R22 -> -39.819763 | T22: =+[15]군산!$H$86/1000 -> 92.945305 | U22: =+[15]군산!$I$86/1000 -> 72.134082 | V22: =+U22-T22 -> -20.811223 | W22: =+[16]군산!$H$86/1000 -> 199.82253 | X22: =+U22-W22 -> -127.68845 | Y22: =+[15]군산!$H$92/1000 -> 22.975992 | Z22: =+[15]군산!$I$92/1000 -> 4.8203981 | AA22: =+Z22-Y22 -> -18.155594 | AB22: =+[16]군산!$H$92/1000 -> 117.87004 | AC22: =+Z22-AB22 -> -113.04965
B23: 원주 | I23: 원주 | J23: =+[4]원주!$H$86/1000 -> 57.095763 | K23: =+[4]원주!$I$86/1000 -> 93.604436 | L23: =+K23-J23 -> 36.508673 | M23: =+[5]원주!$H$86/1000 -> -35.664611 | N23: =+K23-M23 -> 129.26905 | O23: =+[4]원주!$H$92/1000 -> 36.120174 | P23: =+[4]원주!$I$92/1000 -> 69.573558 | Q23: =+P23-O23 -> 33.453384 | R23: =+[5]원주!$H$92/1000 -> -47.222317 | S23: =+P23-R23 -> 116.79588 | T23: =+[15]원주!$H$86/1000 -> 108.73129 | U23: =+[15]원주!$I$86/1000 -> 75.887511 | V23: =+U23-T23 -> -32.843783 | W23: =+[16]원주!$H$86/1000 -> -76.211322 | X23: =+U23-W23 -> 152.09883 | Y23: =+[15]원주!$H$92/1000 -> 32.104998 | Z23: =+[15]원주!$I$92/1000 -> 14.055768 | AA23: =+Z23-Y23 -> -18.04923 | AB23: =+[16]원주!$H$92/1000 -> -118.07159 | AC23: =+Z23-AB23 -> 132.12736
B24: 제주 | I24: 제주 | J24: =+[4]제주!$H$86/1000 -> 64.524357 | K24: =+[4]제주!$I$86/1000 -> 22.333354 | L24: =+K24-J24 -> -42.191003 | M24: =+[5]제주!$H$86/1000 -> 105.08774 | N24: =+K24-M24 -> -82.754384 | O24: =+[4]제주!$H$92/1000 -> 29.726642 | P24: =+[4]제주!$I$92/1000 -> -4.0171506 | Q24: =+P24-O24 -> -33.743793 | R24: =+[5]제주!$H$92/1000 -> 68.508839 | S24: =+P24-R24 -> -72.52599 | T24: =+[15]제주!$H$86/1000 -> 142.02249 | U24: =+[15]제주!$I$86/1000 -> 17.473471 | V24: =+U24-T24 -> -124.54902 | W24: =+[16]제주!$H$86/1000 -> 227.32039 | X24: =+U24-W24 -> -209.84692 | Y24: =+[15]제주!$H$92/1000 -> -1.4874823 | Z24: =+[15]제주!$I$92/1000 -> -84.429469 | AA24: =+Z24-Y24 -> -82.941986 | AB24: =+[16]제주!$H$92/1000 -> 92.729756 | AC24: =+Z24-AB24 -> -177.15922
I25: 수도권 | J25: =SUM(J8:J11) -> 693.49338 | K25: =SUM(K8:K11) -> 358.41098 | L25: =+K25-J25 -> -335.08239 | M25: =SUM(M8:M11) -> 179.04149 | N25: =+K25-M25 -> 179.36949 | O25: =SUM(O8:O11) -> 210.52092 | P25: =SUM(P8:P11) -> -145.57199 | Q25: =+P25-O25 -> -356.09291 | R25: =SUM(R8:R11) -> -258.61765 | S25: =+P25-R25 -> 113.04567 | T25: =SUM(T8:T11) -> 608.96046 | U25: =SUM(U8:U11) -> 149.75156 | V25: =+U25-T25 -> -459.2089 | W25: =SUM(W8:W11) -> 52.663745 | X25: =+U25-W25 -> 97.087813 | Y25: =SUM(Y8:Y11) -> -987.40823 | Z25: =SUM(Z8:Z11) -> -1545.5705 | AA25: =+Z25-Y25 -> -558.16231 | AB25: =SUM(AB8:AB11) -> -1312.2228 | AC25: =+Z25-AB25 -> -233.34776
I26: 영남권 | J26: =SUM(J12:J19) -> 1023.7331 | K26: =SUM(K12:K19) -> 643.6426 | L26: =+K26-J26 -> -380.09045 | M26: =SUM(M12:M19) -> 966.84601 | N26: =+K26-M26 -> -323.20341 | O26: =SUM(O12:O19) -> 444.73395 | P26: =SUM(P12:P19) -> 112.16845 | Q26: =+P26-O26 -> -332.56549 | R26: =SUM(R12:R19) -> 350.29536 | S26: =+P26-R26 -> -238.1269 | T26: =SUM(T12:T19) -> 1191.7451 | U26: =SUM(U12:U19) -> 855.47517 | V26: =+U26-T26 -> -336.26994 | W26: =SUM(W12:W19) -> 1614.9243 | X26: =+U26-W26 -> -759.44911 | Y26: =SUM(Y12:Y19) -> -881.59635 | Z26: =SUM(Z12:Z19) -> -1149.4724 | AA26: =+Z26-Y26 -> -267.87602 | AB26: =SUM(AB12:AB19) -> -373.29676 | AC26: =+Z26-AB26 -> -776.17562
I27: 중부권 | J27: =SUM(J20:J24) -> 349.9537 | K27: =SUM(K20:K24) -> 412.4022 | L27: =+K27-J27 -> 62.448506 | M27: =SUM(M20:M24) -> 546.99923 | N27: =+K27-M27 -> -134.59703 | O27: =SUM(O20:O24) -> 122.4144 | P27: =SUM(P20:P24) -> 153.2961 | Q27: =+P27-O27 -> 30.8817 | R27: =SUM(R20:R24) -> 262.46455 | S27: =+P27-R27 -> -109.16845 | T27: =SUM(T20:T24) -> 296.14308 | U27: =SUM(U20:U24) -> 276.38874 | V27: =+U27-T27 -> -19.754339 | W27: =SUM(W20:W24) -> 990.4096 | X27: =+U27-W27 -> -714.02086 | Y27: =SUM(Y20:Y24) -> -391.5736 | Z27: =SUM(Z20:Z24) -> -531.98935 | AA27: =+Z27-Y27 -> -140.41575 | AB27: =SUM(AB20:AB24) -> 90.684596 | AC27: =+Z27-AB27 -> -622.67395
H28: 레미콘 계 | J28: =SUM(J25:J27) -> 2067.1801 | K28: =SUM(K25:K27) -> 1414.4558 | L28: =+K28-J28 -> -652.72434 | M28: =SUM(M25:M27) -> 1692.8867 | N28: =+K28-M28 -> -278.43095 | O28: =SUM(O25:O27) -> 777.66927 | P28: =SUM(P25:P27) -> 119.89257 | Q28: =+P28-O28 -> -657.7767 | R28: =SUM(R25:R27) -> 354.14225 | S28: =+P28-R28 -> -234.24969 | T28: =SUM(T25:T27) -> 2096.8487 | U28: =SUM(U25:U27) -> 1281.6155 | V28: =+U28-T28 -> -815.23318 | W28: =SUM(W25:W27) -> 2657.9976 | X28: =+U28-W28 -> -1376.3822 | Y28: =SUM(Y25:Y27) -> -2260.5782 | Z28: =SUM(Z25:Z27) -> -3227.0323 | AA28: =+Z28-Y28 -> -966.45408 | AB28: =SUM(AB25:AB27) -> -1594.8349 | AC28: =+Z28-AB28 -> -1632.1973

Sheet 사업장별(당월)
H3: □ 사업장별 손익실적(2026-03)
AG4: [단위 : 천㎥, 톤, 백만원]
H5: 구분 | J5: 물량 | O5: 매출 | T5: 영업이익(공통비 배부전) | Y5: 판매단가 | AB5: 변동비 | AE5: 공헌이익 | AI5: 판매비중
A6: 2024년 3월 마감 손익 | J6: 계획 | K6: 실적 | L6: 차이 | M6: 전년 | N6: 차이 | O6: 계획 | P6: 실적 | Q6: 차이 | R6: 전년 | S6: 차이 | T6: 계획 | U6: 실적 | V6: 차이 | W6: 전년 | X6: 차이 | Y6: 계획 | Z6: 실적 | AA6: 전년 | AB6: 계획 | AC6: 실적 | AD6: 전년 | AE6: 계획 | AF6: 실적 | AG6: 전년 | AI6: 공장명 | AJ6: 계획 | AK6: 추정 | AL6: 차이 | AO6: 전월 | AP6: 차이
B7: 안양 | G7: =+I7 -> 안양 | H7: 레미콘 | I7: 안양 | J7: =+IFERROR(HLOOKUP($B7,'[1]3월'!$D$6:$BN$259,2,),)/1000 -> 39 | K7: =+IFERROR(HLOOKUP($B7,'[2]3월'!$F$6:$CP$99,2,),)/1000 -> 42.206 | L7: =+K7-J7 -> 3.206 | M7: =+IFERROR(HLOOKUP($B7,'[3]3월'!$F$6:$CC$57,2,),)/1000 -> 38.108 | N7: =+K7-M7 -> 4.098 | O7: =+IFERROR(HLOOKUP($B7,'[1]3월'!$D$6:$BN$259,3,),)/1000 -> 3831.7191 | P7: =+IFERROR(HLOOKUP($B7,'[2]3월'!$F$6:$CP$99,3,),)/1000 -> 4199.5077 | Q7: =+P7-O7 -> 367.78864 | R7: =+IFERROR(HLOOKUP($B7,'[3]3월'!$F$6:$CC$57,3,),)/1000 -> 3546.3356 | S7: =+P7-R7 -> 653.17209 | T7: =+IFERROR(HLOOKUP($B7,'[1]3월'!$D$6:$BN$259,16,),)/1000 -> 399.94344 | U7: =+IFERROR(HLOOKUP($B7,'[2]3월'!$F$6:$CP$99,16,),)/1000 -> 386.86276 | V7: =+U7-T7 -> -13.080678 | W7: =+IFERROR(HLOOKUP($B7,'[3]3월'!$F$6:$CC$57,16,),)/1000 -> 190.6149 | X7: =+U7-W7 -> 196.24786 | Y7: =+[4]안양!$Q$85 -> 98249.207 | Z7: =+[4]안양!$R$85 -> 99500.254 | AA7: =+[5]안양!$Q$85 -> 93013.191 | AB7: =+[4]안양!$Q$89 -> 79596.721 | AC7: =+[4]안양!$R$89 -> 82719.119 | AD7: =+[5]안양!$Q$89 -> 80028.849 | AE7: =+Y7-AB7 -> 18652.486 | AF7: =+Z7-AC7 -> 16781.135 | AG7: =+AA7-AD7 -> 12984.342 | AI7: =+I7 -> 안양 | AJ7: =+J7/$J$27 -> 0.15087041 | AK7: =+K7/$K$27 -> 0.17712998 | AL7: =+AK7-AJ7 -> 0.026259573 | AM7: =+Y7*AL7 -> 2579.9822 | AO7: =+[17]안양!$T$5/[17]합계!$T$5 -> 0.17133799 | AP7: =+AK7-AO7 -> 0.005791991 | AQ7: =+[17]안양!$Q$85*AP7 -> 605.48869
B8: 인천 | G8: =+I8 -> 인천 | H8: 직영 | I8: 인천 | J8: =+IFERROR(HLOOKUP($B8,'[1]3월'!$D$6:$BN$259,2,),)/1000 -> 35 | K8: =+IFERROR(HLOOKUP($B8,'[2]3월'!$F$6:$CP$99,2,),)/1000 -> 31.6865 | L8: =+K8-J8 -> -3.3135 | M8: =+IFERROR(HLOOKUP($B8,'[3]3월'!$F$6:$CC$57,2,),)/1000 -> 32.763 | N8: =+K8-M8 -> -1.0765 | O8: =+IFERROR(HLOOKUP($B8,'[1]3월'!$D$6:$BN$259,3,),)/1000 -> 3614.5473 | P8: =+IFERROR(HLOOKUP($B8,'[2]3월'!$F$6:$CP$99,3,),)/1000 -> 3164.436 | Q8: =+P8-O8 -> -450.11131 | R8: =+IFERROR(HLOOKUP($B8,'[3]3월'!$F$6:$CC$57,3,),)/1000 -> 3135.3549 | S8: =+P8-R8 -> 29.081045 | T8: =+IFERROR(HLOOKUP($B8,'[1]3월'!$D$6:$BN$259,16,),)/1000 -> 233.65111 | U8: =+IFERROR(HLOOKUP($B8,'[2]3월'!$F$6:$CP$99,16,),)/1000 -> 34.480905 | V8: =+U8-T8 -> -199.17021 | W8: =+IFERROR(HLOOKUP($B8,'[3]3월'!$F$6:$CC$57,16,),)/1000 -> 97.876781 | X8: =+U8-W8 -> -63.395876 | Y8: =+[4]인천!$Q$85 -> 103272.78 | Z8: =+[4]인천!$R$85 -> 100098.24 | AA8: =+[5]인천!$Q$85 -> 95722.432 | AB8: =+[4]인천!$Q$89 -> 86782.693 | AC8: =+[4]인천!$R$89 -> 88307.176 | AD8: =+[5]인천!$Q$89 -> 84108.984 | AE8: =+Y8-AB8 -> 16490.087 | AF8: =+Z8-AC8 -> 11791.065 | AG8: =+AA8-AD8 -> 11613.448 | AI8: =+I8 -> 인천 | AJ8: =+J8/$J$27 -> 0.13539652 | AK8: =+K8/$K$27 -> 0.13298178 | AL8: =+AK8-AJ8 -> -0.0024147367 | AM8: =+Y8*AL8 -> -249.37657 | AO8: =+[17]인천!$T$5/[17]합계!$T$5 -> 0.12629331 | AP8: =+AK8-AO8 -> 0.0066884678 | AQ8: =+[17]인천!$Q$85*AP8 -> 691.82482
B9: 파주 | G9: =+I9 -> 파주 | I9: 파주 | J9: =+IFERROR(HLOOKUP($B9,'[1]3월'!$D$6:$BN$259,2,),)/1000 -> 15 | K9: =+IFERROR(HLOOKUP($B9,'[2]3월'!$F$6:$CP$99,2,),)/1000 -> 11.21 | L9: =+K9-J9 -> -3.79 | M9: =+IFERROR(HLOOKUP($B9,'[3]3월'!$F$6:$CC$57,2,),)/1000 -> 10.788 | N9: =+K9-M9 -> 0.422 | O9: =+IFERROR(HLOOKUP($B9,'[1]3월'!$D$6:$BN$259,3,),)/1000 -> 1474.7735 | P9: =+IFERROR(HLOOKUP($B9,'[2]3월'!$F$6:$CP$99,3,),)/1000 -> 1096.9934 | Q9: =+P9-O9 -> -377.78006 | R9: =+IFERROR(HLOOKUP($B9,'[3]3월'!$F$6:$CC$57,3,),)/1000 -> 908.57352 | S9: =+P9-R9 -> 188.41988 | T9: =+IFERROR(HLOOKUP($B9,'[1]3월'!$D$6:$BN$259,16,),)/1000 -> 20.418977 | U9: =+IFERROR(HLOOKUP($B9,'[2]3월'!$F$6:$CP$99,16,),)/1000 -> -80.522035 | V9: =+U9-T9 -> -100.94101 | W9: =+IFERROR(HLOOKUP($B9,'[3]3월'!$F$6:$CC$57,16,),)/1000 -> -148.3122 | X9: =+U9-W9 -> 67.790166 | Y9: =+[4]파주!$Q$85 -> 98318.231 | Z9: =+[4]파주!$R$85 -> 97858.466 | AA9: =+[5]파주!$Q$85 -> 84220.756 | AB9: =+[4]파주!$Q$89 -> 80311.251 | AC9: =+[4]파주!$R$89 -> 87277.203 | AD9: =+[5]파주!$Q$89 -> 77980.048 | AE9: =+Y9-AB9 -> 18006.98 | AF9: =+Z9-AC9 -> 10581.263 | AG9: =+AA9-AD9 -> 6240.708 | AI9: =+I9 -> 파주 | AJ9: =+J9/$J$27 -> 0.058027079 | AK9: =+K9/$K$27 -> 0.047046085 | AL9: =+AK9-AJ9 -> -0.010980994 | AM9: =+Y9*AL9 -> -1079.6319 | AO9: =+[17]파주!$T$5/[17]합계!$T$5 -> 0.049850302 | AP9: =+AK9-AO9 -> -0.002804217 | AQ9: =+[17]파주!$Q$85*AP9 -> -274.01221
B10: 김포 | G10: =+I10 -> 김포 | I10: 김포 | J10: =+IFERROR(HLOOKUP($B10,'[1]3월'!$D$6:$BN$259,2,),)/1000 -> 13 | K10: =+IFERROR(HLOOKUP($B10,'[2]3월'!$F$6:$CP$99,2,),)/1000 -> 14.1485 | L10: =+K10-J10 -> 1.1485 | M10: =+IFERROR(HLOOKUP($B10,'[3]3월'!$F$6:$CC$57,2,),)/1000 -> 11.811 | N10: =+K10-M10 -> 2.3375 | O10: =+IFERROR(HLOOKUP($B10,'[1]3월'!$D$6:$BN$259,3,),)/1000 -> 1297.8521 | P10: =+IFERROR(HLOOKUP($B10,'[2]3월'!$F$6:$CP$99,3,),)/1000 -> 1343.0547 | Q10: =+P10-O10 -> 45.202604 | R10: =+IFERROR(HLOOKUP($B10,'[3]3월'!$F$6:$CC$57,3,),)/1000 -> 1104.7602 | S10: =+P10-R10 -> 238.29455 | T10: =+IFERROR(HLOOKUP($B10,'[1]3월'!$D$6:$BN$259,16,),)/1000 -> 39.479855 | U10: =+IFERROR(HLOOKUP($B10,'[2]3월'!$F$6:$CP$99,16,),)/1000 -> 17.589357 | V10: =+U10-T10 -> -21.890498 | W10: =+IFERROR(HLOOKUP($B10,'[3]3월'!$F$6:$CC$57,16,),)/1000 -> 38.862012 | X10: =+U10-W10 -> -21.272655 | Y10: =+[4]김포!$Q$85 -> 99834.778 | Z10: =+[4]김포!$R$85 -> 94963.241 | AA10: =+[5]김포!$Q$85 -> 93540.988 | AB10: =+[4]김포!$Q$89 -> 80824.079 | AC10: =+[4]김포!$R$89 -> 80146.743 | AD10: =+[5]김포!$Q$89 -> 75925.281 | AE10: =+Y10-AB10 -> 19010.7 | AF10: =+Z10-AC10 -> 14816.498 | AG10: =+AA10-AD10 -> 17615.707 | AI10: =+I10 -> 김포 | AJ10: =+J10/$J$27 -> 0.050290135 | AK10: =+K10/$K$27 -> 0.059378371 | AL10: =+AK10-AJ10 -> 0.0090882352 | AM10: =+Y10*AL10 -> 907.32194 | AO10: =+[17]김포!$T$5/[17]합계!$T$5 -> 0.045244664 | AP10: =+AK10-AO10 -> 0.014133707 | AQ10: =+[17]김포!$Q$85*AP10 -> 1383.9311
B11: 부산 | G11: =+I11 -> 부산 | I11: 부산 | J11: =+IFERROR(HLOOKUP($B11,'[1]3월'!$D$6:$BN$259,2,),)/1000 -> 20 | K11: =+IFERROR(HLOOKUP($B11,'[2]3월'!$F$6:$CP$99,2,),)/1000 -> 21.737 | L11: =+K11-J11 -> 1.737 | M11: =+IFERROR(HLOOKUP($B11,'[3]3월'!$F$6:$CC$57,2,),)/1000 -> 23.72 | N11: =+K11-M11 -> -1.983 | O11: =+IFERROR(HLOOKUP($B11,'[1]3월'!$D$6:$BN$259,3,),)/1000 -> 2226.0191 | P11: =+IFERROR(HLOOKUP($B11,'[2]3월'!$F$6:$CP$99,3,),)/1000 -> 2591.1933 | Q11: =+P11-O11 -> 365.17419 | R11: =+IFERROR(HLOOKUP($B11,'[3]3월'!$F$6:$CC$57,3,),)/1000 -> 2548.5624 | S11: =+P11-R11 -> 42.63088 | T11: =+IFERROR(HLOOKUP($B11,'[1]3월'!$D$6:$BN$259,16,),)/1000 -> 252.0269 | U11: =+IFERROR(HLOOKUP($B11,'[2]3월'!$F$6:$CP$99,16,),)/1000 -> 323.34982 | V11: =+U11-T11 -> 71.322921 | W11: =+IFERROR(HLOOKUP($B11,'[3]3월'!$F$6:$CC$57,16,),)/1000 -> 403.32277 | X11: =+U11-W11 -> -79.972956 | Y11: =+[4]부산!$Q$85 -> 111300.96 | Z11: =+[4]부산!$R$85 -> 119206.57 | AA11: =+[5]부산!$Q$85 -> 107443.61 | AB11: =+[4]부산!$Q$89 -> 85361.195 | AC11: =+[4]부산!$R$89 -> 93223.681 | AD11: =+[5]부산!$Q$89 -> 80237.381 | AE11: =+Y11-AB11 -> 25939.76 | AF11: =+Z11-AC11 -> 25982.893 | AG11: =+AA11-AD11 -> 27206.229 | AI11: =+I11 -> 부산 | AJ11: =+J11/$J$27 -> 0.077369439 | AK11: =+K11/$K$27 -> 0.091225758 | AL11: =+AK11-AJ11 -> 0.013856319 | AM11: =+Y11*AL11 -> 1542.2216 | AO11: =+[17]부산!$T$5/[17]합계!$T$5 -> 0.11544095 | AP11: =+AK11-AO11 -> -0.024215189 | AQ11: =+[17]부산!$Q$85*AP11 -> -2815.3147
B12: 서부산 | G12: =+I12 -> 서부산 | I12: 서부산 | J12: =+IFERROR(HLOOKUP($B12,'[1]3월'!$D$6:$BN$259,2,),)/1000 -> 20 | K12: =+IFERROR(HLOOKUP($B12,'[2]3월'!$F$6:$CP$99,2,),)/1000 -> 20.056 | L12: =+K12-J12 -> 0.056 | M12: =+IFERROR(HLOOKUP($B12,'[3]3월'!$F$6:$CC$57,2,),)/1000 -> 17.535 | N12: =+K12-M12 -> 2.521 | O12: =+IFERROR(HLOOKUP($B12,'[1]3월'!$D$6:$BN$259,3,),)/1000 -> 2081.7196 | P12: =+IFERROR(HLOOKUP($B12,'[2]3월'!$F$6:$CP$99,3,),)/1000 -> 2055.1996 | Q12: =+P12-O12 -> -26.519993 | R12: =+IFERROR(HLOOKUP($B12,'[3]3월'!$F$6:$CC$57,3,),)/1000 -> 1689.652 | S12: =+P12-R12 -> 365.54758 | T12: =+IFERROR(HLOOKUP($B12,'[1]3월'!$D$6:$BN$259,16,),)/1000 -> 303.00485 | U12: =+IFERROR(HLOOKUP($B12,'[2]3월'!$F$6:$CP$99,16,),)/1000 -> 209.67643 | V12: =+U12-T12 -> -93.328419 | W12: =+IFERROR(HLOOKUP($B12,'[3]3월'!$F$6:$CC$57,16,),)/1000 -> 146.35766 | X12: =+U12-W12 -> 63.318773 | Y12: =+[4]서부산!$Q$85 -> 104085.98 | Z12: =+[4]서부산!$R$85 -> 102473.06 | AA12: =+[5]서부산!$Q$85 -> 96358.826 | AB12: =+[4]서부산!$Q$89 -> 77887.256 | AC12: =+[4]서부산!$R$89 -> 81377.049 | AD12: =+[5]서부산!$Q$89 -> 75437.947 | AE12: =+Y12-AB12 -> 26198.724 | AF12: =+Z12-AC12 -> 21096.007 | AG12: =+AA12-AD12 -> 20920.879 | AI12: =+I12 -> 서부산 | AJ12: =+J12/$J$27 -> 0.077369439 | AK12: =+K12/$K$27 -> 0.084170944 | AL12: =+AK12-AJ12 -> 0.0068015048 | AM12: =+Y12*AL12 -> 707.94129 | AO12: =+[17]서부산!$T$5/[17]합계!$T$5 -> 0.069372798 | AP12: =+AK12-AO12 -> 0.014798146 | AQ12: =+[17]서부산!$Q$85*AP12 -> 1515.1393
B13: 김해 | G13: =+I13 -> 김해 | I13: 김해 | J13: =+IFERROR(HLOOKUP($B13,'[1]3월'!$D$6:$BN$259,2,),)/1000 -> 9 | K13: =+IFERROR(HLOOKUP($B13,'[2]3월'!$F$6:$CP$99,2,),)/1000 -> 7.2515 | L13: =+K13-J13 -> -1.7485 | M13: =+IFERROR(HLOOKUP($B13,'[3]3월'!$F$6:$CC$57,2,),)/1000 -> 12.503 | N13: =+K13-M13 -> -5.2515 | O13: =+IFERROR(HLOOKUP($B13,'[1]3월'!$D$6:$BN$259,3,),)/1000 -> 911.64043 | P13: =+IFERROR(HLOOKUP($B13,'[2]3월'!$F$6:$CP$99,3,),)/1000 -> 725.06585 | Q13: =+P13-O13 -> -186.57458 | R13: =+IFERROR(HLOOKUP($B13,'[3]3월'!$F$6:$CC$57,3,),)/1000 -> 1140.8359 | S13: =+P13-R13 -> -415.77005 | T13: =+IFERROR(HLOOKUP($B13,'[1]3월'!$D$6:$BN$259,16,),)/1000 -> 66.063919 | U13: =+IFERROR(HLOOKUP($B13,'[2]3월'!$F$6:$CP$99,16,),)/1000 -> 13.214121 | V13: =+U13-T13 -> -52.849798 | W13: =+IFERROR(HLOOKUP($B13,'[3]3월'!$F$6:$CC$57,16,),)/1000 -> 55.355958 | X13: =+U13-W13 -> -42.141837 | Y13: =+[4]김해!$Q$85 -> 101293.38 | Z13: =+[4]김해!$R$85 -> 99988.396 | AA13: =+[5]김해!$Q$85 -> 91228.592 | AB13: =+[4]김해!$Q$89 -> 78336.699 | AC13: =+[4]김해!$R$89 -> 80812.247 | AD13: =+[5]김해!$Q$89 -> 75407.766 | AE13: =+Y13-AB13 -> 22956.682 | AF13: =+Z13-AC13 -> 19176.148 | AG13: =+AA13-AD13 -> 15820.827 | AI13: =+I13 -> 김해 | AJ13: =+J13/$J$27 -> 0.034816248 | AK13: =+K13/$K$27 -> 0.030433067 | AL13: =+AK13-AJ13 -> -0.0043831802 | AM13: =+Y13*AL13 -> -443.98714 | AO13: =+[17]김해!$T$5/[17]합계!$T$5 -> 0.031068943 | AP13: =+AK13-AO13 -> -0.00063587601 | AQ13: =+[17]김해!$Q$85*AP13 -> -65.150409
B14: 정관 | G14: =+I14 -> 정관 | I14: 정관 | J14: =+IFERROR(HLOOKUP($B14,'[1]3월'!$D$6:$BN$259,2,),)/1000 -> 21 | K14: =+IFERROR(HLOOKUP($B14,'[2]3월'!$F$6:$CP$99,2,),)/1000 -> 12.903 | L14: =+K14-J14 -> -8.097 | M14: =+IFERROR(HLOOKUP($B14,'[3]3월'!$F$6:$CC$57,2,),)/1000 -> 19.81 | N14: =+K14-M14 -> -6.907 | O14: =+IFERROR(HLOOKUP($B14,'[1]3월'!$D$6:$BN$259,3,),)/1000 -> 2226.0583 | P14: =+IFERROR(HLOOKUP($B14,'[2]3월'!$F$6:$CP$99,3,),)/1000 -> 1392.4882 | Q14: =+P14-O14 -> -833.57013 | R14: =+IFERROR(HLOOKUP($B14,'[3]3월'!$F$6:$CC$57,3,),)/1000 -> 1937.8749 | S14: =+P14-R14 -> -545.38669 | T14: =+IFERROR(HLOOKUP($B14,'[1]3월'!$D$6:$BN$259,16,),)/1000 -> 240.64452 | U14: =+IFERROR(HLOOKUP($B14,'[2]3월'!$F$6:$CP$99,16,),)/1000 -> 69.741612 | V14: =+U14-T14 -> -170.90291 | W14: =+IFERROR(HLOOKUP($B14,'[3]3월'!$F$6:$CC$57,16,),)/1000 -> 121.8508 | X14: =+U14-W14 -> -52.109191 | Y14: =+[4]정관!$Q$85 -> 106002.78 | Z14: =+[4]정관!$R$85 -> 107919.72 | AA14: =+[5]정관!$Q$85 -> 97823.064 | AB14: =+[4]정관!$Q$89 -> 83788.687 | AC14: =+[4]정관!$R$89 -> 84591.566 | AD14: =+[5]정관!$Q$89 -> 82325.942 | AE14: =+Y14-AB14 -> 22214.091 | AF14: =+Z14-AC14 -> 23328.158 | AG14: =+AA14-AD14 -> 15497.121 | AI14: =+I14 -> 정관 | AJ14: =+J14/$J$27 -> 0.081237911 | AK14: =+K14/$K$27 -> 0.054151261 | AL14: =+AK14-AJ14 -> -0.02708665 | AM14: =+Y14*AL14 -> -2871.2601 | AO14: =+[17]정관!$T$5/[17]합계!$T$5 -> 0.061949661 | AP14: =+AK14-AO14 -> -0.0077984006 | AQ14: =+[17]정관!$Q$85*AP14 -> -846.544
B15: 양산 | G15: =+I15 -> 양산 | I15: 양산 | J15: =+IFERROR(HLOOKUP($B15,'[1]3월'!$D$6:$BN$259,2,),)/1000 -> 9 | K15: =+IFERROR(HLOOKUP($B15,'[2]3월'!$F$6:$CP$99,2,),)/1000 -> 4.772 | L15: =+K15-J15 -> -4.228 | M15: =+IFERROR(HLOOKUP($B15,'[3]3월'!$F$6:$CC$57,2,),)/1000 -> 9.625 | N15: =+K15-M15 -> -4.853 | O15: =+IFERROR(HLOOKUP($B15,'[1]3월'!$D$6:$BN$259,3,),)/1000 -> 907.45654 | P15: =+IFERROR(HLOOKUP($B15,'[2]3월'!$F$6:$CP$99,3,),)/1000 -> 504.3358 | Q15: =+P15-O15 -> -403.12074 | R15: =+IFERROR(HLOOKUP($B15,'[3]3월'!$F$6:$CC$57,3,),)/1000 -> 913.03398 | S15: =+P15-R15 -> -408.69818 | T15: =+IFERROR(HLOOKUP($B15,'[1]3월'!$D$6:$BN$259,16,),)/1000 -> 57.547751 | U15: =+IFERROR(HLOOKUP($B15,'[2]3월'!$F$6:$CP$99,16,),)/1000 -> 10.974981 | V15: =+U15-T15 -> -46.57277 | W15: =+IFERROR(HLOOKUP($B15,'[3]3월'!$F$6:$CC$57,16,),)/1000 -> 64.674861 | X15: =+U15-W15 -> -53.69988 | Y15: =+[4]양산!$Q$85 -> 100828.5 | Z15: =+[4]양산!$R$85 -> 105686.46 | AA15: =+[5]양산!$Q$85 -> 94860.673 | AB15: =+[4]양산!$Q$89 -> 77145.469 | AC15: =+[4]양산!$R$89 -> 78262.687 | AD15: =+[5]양산!$Q$89 -> 72164.361 | AE15: =+Y15-AB15 -> 23683.035 | AF15: =+Z15-AC15 -> 27423.776 | AG15: =+AA15-AD15 -> 22696.312 | AI15: =+I15 -> 양산 | AJ15: =+J15/$J$27 -> 0.034816248 | AK15: =+K15/$K$27 -> 0.020027111 | AL15: =+AK15-AJ15 -> -0.014789136 | AM15: =+Y15*AL15 -> -1491.1665 | AO15: =+[17]양산!$T$5/[17]합계!$T$5 -> 0.019957767 | AP15: =+AK15-AO15 -> 6.9344361e-05 | AQ15: =+[17]양산!$Q$85*AP15 -> 7.3688777
B16: 창원 | G16: =+I16 -> 창원 | I16: 창원 | J16: =+IFERROR(HLOOKUP($B16,'[1]3월'!$D$6:$BN$259,2,),)/1000 -> 12 | K16: =+IFERROR(HLOOKUP($B16,'[2]3월'!$F$6:$CP$99,2,),)/1000 -> 8.648 | L16: =+K16-J16 -> -3.352 | M16: =+IFERROR(HLOOKUP($B16,'[3]3월'!$F$6:$CC$57,2,),)/1000 -> 10.865 | N16: =+K16-M16 -> -2.217 | O16: =+IFERROR(HLOOKUP($B16,'[1]3월'!$D$6:$BN$259,3,),)/1000 -> 1163.0699 | P16: =+IFERROR(HLOOKUP($B16,'[2]3월'!$F$6:$CP$99,3,),)/1000 -> 851.405 | Q16: =+P16-O16 -> -311.66489 | R16: =+IFERROR(HLOOKUP($B16,'[3]3월'!$F$6:$CC$57,3,),)/1000 -> 1063.0202 | S16: =+P16-R16 -> -211.61523 | T16: =+IFERROR(HLOOKUP($B16,'[1]3월'!$D$6:$BN$259,16,),)/1000 -> 52.912265 | U16: =+IFERROR(HLOOKUP($B16,'[2]3월'!$F$6:$CP$99,16,),)/1000 -> 26.96316 | V16: =+U16-T16 -> -25.949105 | W16: =+IFERROR(HLOOKUP($B16,'[3]3월'!$F$6:$CC$57,16,),)/1000 -> 89.749104 | X16: =+U16-W16 -> -62.785944 | Y16: =+[4]창원!$Q$85 -> 96922.491 | Z16: =+[4]창원!$R$85 -> 98451.087 | AA16: =+[5]창원!$Q$85 -> 97838.954 | AB16: =+[4]창원!$Q$89 -> 77259.402 | AC16: =+[4]창원!$R$89 -> 74459.445 | AD16: =+[5]창원!$Q$89 -> 73565.78 | AE16: =+Y16-AB16 -> 19663.089 | AF16: =+Z16-AC16 -> 23991.642 | AG16: =+AA16-AD16 -> 24273.173 | AI16: =+I16 -> 창원 | AJ16: =+J16/$J$27 -> 0.046421663 | AK16: =+K16/$K$27 -> 0.036293893 | AL16: =+AK16-AJ16 -> -0.01012777 | AM16: =+Y16*AL16 -> -981.60872 | AO16: =+[17]창원!$T$5/[17]합계!$T$5 -> 0.05549118 | AP16: =+AK16-AO16 -> -0.019197287 | AQ16: =+[17]창원!$Q$85*AP16 -> -1809.4955
B17: 대구 | G17: =+I17 -> 대구 | I17: 대구 | J17: =+IFERROR(HLOOKUP($B17,'[1]3월'!$D$6:$BN$259,2,),)/1000 -> 7.5 | K17: =+IFERROR(HLOOKUP($B17,'[2]3월'!$F$6:$CP$99,2,),)/1000 -> 3.1665 | L17: =+K17-J17 -> -4.3335 | M17: =+IFERROR(HLOOKUP($B17,'[3]3월'!$F$6:$CC$57,2,),)/1000 -> 11.223 | N17: =+K17-M17 -> -8.0565 | O17: =+IFERROR(HLOOKUP($B17,'[1]3월'!$D$6:$BN$259,3,),)/1000 -> 682.33096 | P17: =+IFERROR(HLOOKUP($B17,'[2]3월'!$F$6:$CP$99,3,),)/1000 -> 269.20048 | Q17: =+P17-O17 -> -413.13048 | R17: =+IFERROR(HLOOKUP($B17,'[3]3월'!$F$6:$CC$57,3,),)/1000 -> 978.89496 | S17: =+P17-R17 -> -709.69448 | T17: =+IFERROR(HLOOKUP($B17,'[1]3월'!$D$6:$BN$259,16,),)/1000 -> -30.554162 | U17: =+IFERROR(HLOOKUP($B17,'[2]3월'!$F$6:$CP$99,16,),)/1000 -> -105.44824 | V17: =+U17-T17 -> -74.894079 | W17: =+IFERROR(HLOOKUP($B17,'[3]3월'!$F$6:$CC$57,16,),)/1000 -> -23.079407 | X17: =+U17-W17 -> -82.368834 | Y17: =+[4]대구!$Q$85 -> 90977.461 | Z17: =+[4]대구!$R$85 -> 85015.152 | AA17: =+[5]대구!$Q$85 -> 87222.219 | AB17: =+[4]대구!$Q$89 -> 71227.888 | AC17: =+[4]대구!$R$89 -> 71587.357 | AD17: =+[5]대구!$Q$89 -> 74076.489 | AE17: =+Y17-AB17 -> 19749.573 | AF17: =+Z17-AC17 -> 13427.796 | AG17: =+AA17-AD17 -> 13145.73 | AI17: =+I17 -> 대구 | AJ17: =+J17/$J$27 -> 0.02901354 | AK17: =+K17/$K$27 -> 0.013289155 | AL17: =+AK17-AJ17 -> -0.015724385 | AM17: =+Y17*AL17 -> -1430.5646 | AO17: =+[17]대구!$T$5/[17]합계!$T$5 -> 0.025839808 | AP17: =+AK17-AO17 -> -0.012550653 | AQ17: =+[17]대구!$Q$85*AP17 -> -1084.8611
B18: 울산 | G18: =+I18 -> 울산 | I18: 울산 | J18: =+IFERROR(HLOOKUP($B18,'[1]3월'!$D$6:$BN$259,2,),)/1000 -> 11.5 | K18: =+IFERROR(HLOOKUP($B18,'[2]3월'!$F$6:$CP$99,2,),)/1000 -> 11.961 | L18: =+K18-J18 -> 0.461 | M18: =+IFERROR(HLOOKUP($B18,'[3]3월'!$F$6:$CC$57,2,),)/1000 -> 12.057 | N18: =+K18-M18 -> -0.096 | O18: =+IFERROR(HLOOKUP($B18,'[1]3월'!$D$6:$BN$259,3,),)/1000 -> 1200.0602 | P18: =+IFERROR(HLOOKUP($B18,'[2]3월'!$F$6:$CP$99,3,),)/1000 -> 1252.0218 | Q18: =+P18-O18 -> 51.961589 | R18: =+IFERROR(HLOOKUP($B18,'[3]3월'!$F$6:$CC$57,3,),)/1000 -> 1257.1629 | S18: =+P18-R18 -> -5.1411 | T18: =+IFERROR(HLOOKUP($B18,'[1]3월'!$D$6:$BN$259,16,),)/1000 -> 82.087013 | U18: =+IFERROR(HLOOKUP($B18,'[2]3월'!$F$6:$CP$99,16,),)/1000 -> 95.170722 | V18: =+U18-T18 -> 13.083709 | W18: =+IFERROR(HLOOKUP($B18,'[3]3월'!$F$6:$CC$57,16,),)/1000 -> 108.61426 | X18: =+U18-W18 -> -13.443537 | Y18: =+[4]울산!$Q$85 -> 104353.06 | Z18: =+[4]울산!$R$85 -> 104675.34 | AA18: =+[5]울산!$Q$85 -> 104268.3 | AB18: =+[4]울산!$Q$89 -> 82849.095 | AC18: =+[4]울산!$R$89 -> 84513.552 | AD18: =+[5]울산!$Q$89 -> 83859.972 | AE18: =+Y18-AB18 -> 21503.967 | AF18: =+Z18-AC18 -> 20161.793 | AG18: =+AA18-AD18 -> 20408.329 | AI18: =+I18 -> 울산 | AJ18: =+J18/$J$27 -> 0.044487427 | AK18: =+K18/$K$27 -> 0.050197879 | AL18: =+AK18-AJ18 -> 0.0057104515 | AM18: =+Y18*AL18 -> 595.9031 | AO18: =+[17]울산!$T$5/[17]합계!$T$5 -> 0.055708815 | AP18: =+AK18-AO18 -> -0.0055109365 | AQ18: =+[17]울산!$Q$85*AP18 -> -607.79153
B19: 아산 | G19: =+I19 -> 아산 | I19: 아산 | J19: =+IFERROR(HLOOKUP($B19,'[1]3월'!$D$6:$BN$259,2,),)/1000 -> 22 | K19: =+IFERROR(HLOOKUP($B19,'[2]3월'!$F$6:$CP$99,2,),)/1000 -> 22.192 | L19: =+K19-J19 -> 0.192 | M19: =+IFERROR(HLOOKUP($B19,'[3]3월'!$F$6:$CC$57,2,),)/1000 -> 23.404 | N19: =+K19-M19 -> -1.212 | O19: =+IFERROR(HLOOKUP($B19,'[1]3월'!$D$6:$BN$259,3,),)/1000 -> 2123.7376 | P19: =+IFERROR(HLOOKUP($B19,'[2]3월'!$F$6:$CP$99,3,),)/1000 -> 2151.5586 | Q19: =+P19-O19 -> 27.820932 | R19: =+IFERROR(HLOOKUP($B19,'[3]3월'!$F$6:$CC$57,3,),)/1000 -> 2354.1826 | S19: =+P19-R19 -> -202.62407 | T19: =+IFERROR(HLOOKUP($B19,'[1]3월'!$D$6:$BN$259,16,),)/1000 -> 88.591762 | U19: =+IFERROR(HLOOKUP($B19,'[2]3월'!$F$6:$CP$99,16,),)/1000 -> 69.207642 | V19: =+U19-T19 -> -19.38412 | W19: =+IFERROR(HLOOKUP($B19,'[3]3월'!$F$6:$CC$57,16,),)/1000 -> 139.57025 | X19: =+U19-W19 -> -70.362605 | Y19: =+[4]아산!$Q$85 -> 96533.529 | Z19: =+[4]아산!$R$85 -> 96951.99 | AA19: =+[5]아산!$Q$85 -> 100519.81 | AB19: =+[4]아산!$Q$89 -> 80262.721 | AC19: =+[4]아산!$R$89 -> 82536.642 | AD19: =+[5]아산!$Q$89 -> 84239.872 | AE19: =+Y19-AB19 -> 16270.808 | AF19: =+Z19-AC19 -> 14415.348 | AG19: =+AA19-AD19 -> 16279.937 | AI19: =+I19 -> 아산 | AJ19: =+J19/$J$27 -> 0.085106383 | AK19: =+K19/$K$27 -> 0.093135301 | AL19: =+AK19-AJ19 -> 0.0080289175 | AM19: =+Y19*AL19 -> 775.05974 | AO19: =+[17]아산!$T$5/[17]합계!$T$5 -> 0.093518578 | AP19: =+AK19-AO19 -> -0.00038327792 | AQ19: =+[17]아산!$Q$85*AP19 -> -39.175475
B20: 전주 | G20: =+I20 -> 전주 | I20: 전주 | J20: =+IFERROR(HLOOKUP($B20,'[1]3월'!$D$6:$BN$259,2,),)/1000 -> 10 | K20: =+IFERROR(HLOOKUP($B20,'[2]3월'!$F$6:$CP$99,2,),)/1000 -> 13.624 | L20: =+K20-J20 -> 3.624 | M20: =+IFERROR(HLOOKUP($B20,'[3]3월'!$F$6:$CC$57,2,),)/1000 -> 17.8155 | N20: =+K20-M20 -> -4.1915 | O20: =+IFERROR(HLOOKUP($B20,'[1]3월'!$D$6:$BN$259,3,),)/1000 -> 1019.9031 | P20: =+IFERROR(HLOOKUP($B20,'[2]3월'!$F$6:$CP$99,3,),)/1000 -> 1366.0041 | Q20: =+P20-O20 -> 346.10096 | R20: =+IFERROR(HLOOKUP($B20,'[3]3월'!$F$6:$CC$57,3,),)/1000 -> 1722.0858 | S20: =+P20-R20 -> -356.08169 | T20: =+IFERROR(HLOOKUP($B20,'[1]3월'!$D$6:$BN$259,16,),)/1000 -> 64.392708 | U20: =+IFERROR(HLOOKUP($B20,'[2]3월'!$F$6:$CP$99,16,),)/1000 -> 138.57817 | V20: =+U20-T20 -> 74.185467 | W20: =+IFERROR(HLOOKUP($B20,'[3]3월'!$F$6:$CC$57,16,),)/1000 -> 206.10743 | X20: =+U20-W20 -> -67.529258 | Y20: =+[4]전주!$Q$85 -> 101990.31 | Z20: =+[4]전주!$R$85 -> 100264.54 | AA20: =+[5]전주!$Q$85 -> 96662.221 | AB20: =+[4]전주!$Q$89 -> 78111.504 | AC20: =+[4]전주!$R$89 -> 78560.188 | AD20: =+[5]전주!$Q$89 -> 75942.791 | AE20: =+Y20-AB20 -> 23878.81 | AF20: =+Z20-AC20 -> 21704.352 | AG20: =+AA20-AD20 -> 20719.429 | AI20: =+I20 -> 전주 | AJ20: =+J20/$J$27 -> 0.03868472 | AK20: =+K20/$K$27 -> 0.057177151 | AL20: =+AK20-AJ20 -> 0.018492431 | AM20: =+Y20*AL20 -> 1886.0489 | AO20: =+[17]전주!$T$5/[17]합계!$T$5 -> 0.039544965 | AP20: =+AK20-AO20 -> 0.017632186 | AQ20: =+[17]전주!$Q$85*AP20 -> 1680.5155
B21: 군산 | G21: =+I21 -> 군산 | I21: 군산 | J21: =+IFERROR(HLOOKUP($B21,'[1]3월'!$D$6:$BN$259,2,),)/1000 -> 4.5 | K21: =+IFERROR(HLOOKUP($B21,'[2]3월'!$F$6:$CP$99,2,),)/1000 -> 5.036 | L21: =+K21-J21 -> 0.536 | M21: =+IFERROR(HLOOKUP($B21,'[3]3월'!$F$6:$CC$57,2,),)/1000 -> 5.4375 | N21: =+K21-M21 -> -0.4015 | O21: =+IFERROR(HLOOKUP($B21,'[1]3월'!$D$6:$BN$259,3,),)/1000 -> 490.64128 | P21: =+IFERROR(HLOOKUP($B21,'[2]3월'!$F$6:$CP$99,3,),)/1000 -> 542.76393 | Q21: =+P21-O21 -> 52.122648 | R21: =+IFERROR(HLOOKUP($B21,'[3]3월'!$F$6:$CC$57,3,),)/1000 -> 622.1095 | S21: =+P21-R21 -> -79.34557 | T21: =+IFERROR(HLOOKUP($B21,'[1]3월'!$D$6:$BN$259,16,),)/1000 -> 75.349109 | U21: =+IFERROR(HLOOKUP($B21,'[2]3월'!$F$6:$CP$99,16,),)/1000 -> 88.678597 | V21: =+U21-T21 -> 13.329488 | W21: =+IFERROR(HLOOKUP($B21,'[3]3월'!$F$6:$CC$57,16,),)/1000 -> 131.89843 | X21: =+U21-W21 -> -43.21983 | Y21: =+[4]군산!$Q$85 -> 109031.4 | Z21: =+[4]군산!$R$85 -> 107776.79 | AA21: =+[5]군산!$Q$85 -> 114410.94 | AB21: =+[4]군산!$Q$89 -> 73107.154 | AC21: =+[4]군산!$R$89 -> 73736.204 | AD21: =+[5]군산!$Q$89 -> 74829.89 | AE21: =+Y21-AB21 -> 35924.242 | AF21: =+Z21-AC21 -> 34040.589 | AG21: =+AA21-AD21 -> 39581.053 | AI21: =+I21 -> 군산 | AJ21: =+J21/$J$27 -> 0.017408124 | AK21: =+K21/$K$27 -> 0.021135065 | AL21: =+AK21-AJ21 -> 0.0037269417 | AM21: =+Y21*AL21 -> 406.35366 | AO21: =+[17]군산!$T$5/[17]합계!$T$5 -> 0.011711145 | AP21: =+AK21-AO21 -> 0.0094239208 | AQ21: =+[17]군산!$Q$85*AP21 -> 1026.6921
B22: 원주 | G22: =+I22 -> 원주 | I22: 원주 | J22: =+IFERROR(HLOOKUP($B22,'[1]3월'!$D$6:$BN$259,2,),)/1000 -> 4 | K22: =+IFERROR(HLOOKUP($B22,'[2]3월'!$F$6:$CP$99,2,),)/1000 -> 3.6445 | L22: =+K22-J22 -> -0.3555 | M22: =+IFERROR(HLOOKUP($B22,'[3]3월'!$F$6:$CC$57,2,),)/1000 -> 2.4635 | N22: =+K22-M22 -> 1.181 | O22: =+IFERROR(HLOOKUP($B22,'[1]3월'!$D$6:$BN$259,3,),)/1000 -> 443.80848 | P22: =+IFERROR(HLOOKUP($B22,'[2]3월'!$F$6:$CP$99,3,),)/1000 -> 467.4732 | Q22: =+P22-O22 -> 23.664719 | R22: =+IFERROR(HLOOKUP($B22,'[3]3월'!$F$6:$CC$57,3,),)/1000 -> 229.70775 | S22: =+P22-R22 -> 237.76545 | T22: =+IFERROR(HLOOKUP($B22,'[1]3월'!$D$6:$BN$259,16,),)/1000 -> 57.095763 | U22: =+IFERROR(HLOOKUP($B22,'[2]3월'!$F$6:$CP$99,16,),)/1000 -> 93.604436 | V22: =+U22-T22 -> 36.508673 | W22: =+IFERROR(HLOOKUP($B22,'[3]3월'!$F$6:$CC$57,16,),)/1000 -> -35.664611 | X22: =+U22-W22 -> 129.26905 | Y22: =+[4]원주!$Q$85 -> 110952.12 | Z22: =+[4]원주!$R$85 -> 128270.07 | AA22: =+[5]원주!$Q$85 -> 93244.471 | AB22: =+[4]원주!$Q$89 -> 72014.763 | AC22: =+[4]원주!$R$89 -> 80707.768 | AD22: =+[5]원주!$Q$89 -> 72003.515 | AE22: =+Y22-AB22 -> 38937.357 | AF22: =+Z22-AC22 -> 47562.301 | AG22: =+AA22-AD22 -> 21240.956 | AI22: =+I22 -> 원주 | AJ22: =+J22/$J$27 -> 0.015473888 | AK22: =+K22/$K$27 -> 0.015295224 | AL22: =+AK22-AJ22 -> -0.00017866419 | AM22: =+Y22*AL22 -> -19.82317 | AO22: =+[17]원주!$T$5/[17]합계!$T$5 -> 0.0086760113 | AP22: =+AK22-AO22 -> 0.0066192124 | AQ22: =+[17]원주!$Q$85*AP22 -> 850.11734
B23: 제주 | F23: =+K27-J27 -> -20.223 | G23: =+I23 -> 제주 | I23: 제주 | J23: =+IFERROR(HLOOKUP($B23,'[1]3월'!$D$6:$BN$259,2,),)/1000 -> 6 | K23: =+IFERROR(HLOOKUP($B23,'[2]3월'!$F$6:$CP$99,2,),)/1000 -> 4.0345 | L23: =+K23-J23 -> -1.9655 | M23: =+IFERROR(HLOOKUP($B23,'[3]3월'!$F$6:$CC$57,2,),)/1000 -> 5.9985 | N23: =+K23-M23 -> -1.964 | O23: =+IFERROR(HLOOKUP($B23,'[1]3월'!$D$6:$BN$259,3,),)/1000 -> 736.26162 | P23: =+IFERROR(HLOOKUP($B23,'[2]3월'!$F$6:$CP$99,3,),)/1000 -> 512.59695 | Q23: =+P23-O23 -> -223.66467 | R23: =+IFERROR(HLOOKUP($B23,'[3]3월'!$F$6:$CC$57,3,),)/1000 -> 727.00038 | S23: =+P23-R23 -> -214.40344 | T23: =+IFERROR(HLOOKUP($B23,'[1]3월'!$D$6:$BN$259,16,),)/1000 -> 64.524357 | U23: =+IFERROR(HLOOKUP($B23,'[2]3월'!$F$6:$CP$99,16,),)/1000 -> 22.333354 | V23: =+U23-T23 -> -42.191003 | W23: =+IFERROR(HLOOKUP($B23,'[3]3월'!$F$6:$CC$57,16,),)/1000 -> 105.08774 | X23: =+U23-W23 -> -82.754384 | Y23: =+[4]제주!$Q$85 -> 122710.27 | Z23: =+[4]제주!$R$85 -> 127053.4 | AA23: =+[5]제주!$Q$85 -> 121197.03 | AB23: =+[4]제주!$Q$89 -> 94781.791 | AC23: =+[4]제주!$R$89 -> 98534.104 | AD23: =+[5]제주!$Q$89 -> 89275.848 | AE23: =+Y23-AB23 -> 27928.479 | AF23: =+Z23-AC23 -> 28519.297 | AG23: =+AA23-AD23 -> 31921.182 | AI23: =+I23 -> 제주 | AJ23: =+J23/$J$27 -> 0.023210832 | AK23: =+K23/$K$27 -> 0.016931974 | AL23: =+AK23-AJ23 -> -0.0062788576 | AM23: =+Y23*AL23 -> -770.48031 | AO23: =+[17]제주!$T$5/[17]합계!$T$5 -> 0.018993112 | AP23: =+AK23-AO23 -> -0.002061138 | AQ23: =+[17]제주!$Q$85*AP23 -> -265.94435
F24: =+K24/J24 -> 0.97304902 | G24: =+I24 -> 수도권 | I24: 수도권 | J24: =SUM(J7:J10) -> 102 | K24: =SUM(K7:K10) -> 99.251 | L24: =+K24-J24 -> -2.749 | M24: =SUM(M7:M10) -> 93.47 | N24: =+K24-M24 -> 5.781 | O24: =SUM(O7:O10) -> 10218.892 | P24: =SUM(P7:P10) -> 9803.9918 | Q24: =+P24-O24 -> -414.90012 | R24: =SUM(R7:R10) -> 8695.0243 | S24: =+P24-R24 -> 1108.9676 | T24: =SUM(T7:T10) -> 693.49338 | U24: =SUM(U7:U10) -> 358.41098 | V24: =+U24-T24 -> -335.08239 | W24: =SUM(W7:W10) -> 179.04149 | X24: =+U24-W24 -> 179.36949 | Y24: =+[4]수도권!$Q$85 -> 100185.22 | Z24: =+[4]수도권!$R$85 -> 98854.894 | AA24: =+[5]수도권!$Q$85 -> 93007.036 | AB24: =+[4]수도권!$Q$89 -> 82324.002 | AC24: =+[4]수도권!$R$89 -> 84635.267 | AD24: =+[5]수도권!$Q$89 -> 80706.855 | AE24: =+Y24-AB24 -> 17861.214 | AF24: =+Z24-AC24 -> 14219.627 | AG24: =+AA24-AD24 -> 12300.18 | AI24: =+I24 -> 수도권 | AJ24: =+J24/$J$27 -> 0.39458414 | AK24: =+K24/$K$27 -> 0.41653622 | AL24: =+AK24-AJ24 -> 0.021952077 | AM24: =+Y24*AL24 -> 2199.2736 | AO24: =+[17]수도권!$T$5/[17]합계!$T$5 -> 0.39272627 | AP24: =+AK24-AO24 -> 0.023809949 | AQ24: =+[17]수도권!$Q$85*AP24 -> 2441.7843
