Workbook

Sheet 표지
A6: 2026년 4월 마감 손익
A24: 레미콘사업본부

Sheet 손익총괄
C3: □ 건재사업본부 손익실적(2026-04)
X4: [단위 : 천㎥, 톤, 원/㎥, 원/톤, 백만원]
C5: 구분 | E5: 4월 | J5: 4월누계 | P5: 4월 주요지표
E6: 계획 | F6: 실적 | G6: 계획대비 | H6: 전년 | I6: 전년대비 | J6: 계획 | K6: 실적 | L6: 계획대비 | M6: 전년 | N6: 전년대비
C7: 물량 | D7: 레미콘 | E7: =+'[1]4월'!$Z$7/1000 -> 272 | F7: =+'[2]4월'!$Z$7/1000 -> 272.948 | G7: =+F7-E7 -> 0.948 | H7: =+'[3]4월'!$Z$7/1000 -> 276.853 | I7: =+F7-H7 -> -3.905 | J7: =+'[1]4월누계'!$Z$7/1000 -> 896.4998 | K7: =+'[2]4월누계'!$Z$7/1000 -> 857.3545 | L7: =+K7-J7 -> -39.1453 | M7: =+'[3]4월누계'!$Z$7/1000 -> 931.4385 | N7: =+K7-M7 -> -74.084 | Q7: □ 레미콘
D8: 골재 | E8: =+'[1]4월'!$AE$7/1000 -> 70.968284 | F8: =+'[2]4월'!$AN$7/1000 -> 71.493 | G8: =+F8-E8 -> 0.52471562 | H8: =+'[3]4월'!$AN$7/1000 -> 68.025 | I8: =+F8-H8 -> 3.468 | J8: =+'[1]4월누계'!$AE$7/1000 -> 273.38092 | K8: =+'[2]4월누계'!$AN$7/1000 -> 248.723 | L8: =+K8-J8 -> -24.657916 | M8: =+'[3]4월누계'!$AN$7/1000 -> 235.425 | N8: =+K8-M8 -> 13.298 | Q8: 구분 | S8: 계획 | T8: 실적 | U8: 계획대비 | V8: 전년 | W8: 전년대비
C9: 매출 | D9: 레미콘 | E9: =+'[1]4월'!$Z$8/1000 -> 27621.551 | F9: =+'[2]4월'!$Z$8/1000 -> 27522.435 | G9: =+F9-E9 -> -99.116007 | H9: =+'[3]4월'!$Z$8/1000 -> 27262.254 | I9: =+F9-H9 -> 260.18054 | J9: =+'[1]4월누계'!$Z$8/1000 -> 90924.329 | K9: =+'[2]4월누계'!$Z$8/1000 -> 88535.435 | L9: =+K9-J9 -> -2388.8946 | M9: =+'[3]4월누계'!$Z$8/1000 -> 92138.562 | N9: =+K9-M9 -> -3603.1271 | Q9: 물량 | R9: 수도권 | S9: =+[4]수도권!$T$5/1000 -> 107 | T9: =+[4]수도권!$U$5/1000 -> 114.6955 | U9: =+T9-S9 -> 7.6955 | V9: =+[5]수도권!$T$5/1000 -> 99.752 | W9: =+T9-V9 -> 14.9435
D10: 골재 | E10: =+'[1]4월'!$AE$8/1000 -> 1263.7214 | F10: =+'[2]4월'!$AN$8/1000 -> 1401.1751 | G10: =+F10-E10 -> 137.45375 | H10: =+'[3]4월'!$AN$8/1000 -> 1449.066 | I10: =+F10-H10 -> -47.8909 | J10: =+'[1]4월누계'!$AE$8/1000 -> 4932.0097 | K10: =+'[2]4월누계'!$AN$8/1000 -> 4940.8781 | L10: =+K10-J10 -> 8.8684321 | M10: =+'[3]4월누계'!$AN$8/1000 -> 5026.8145 | N10: =+K10-M10 -> -85.9364 | R10: 영남권 | S10: =+[4]영남권!$T$5/1000 -> 116 | T10: =+[4]영남권!$U$5/1000 -> 106.4505 | U10: =+T10-S10 -> -9.5495 | V10: =+[5]영남권!$T$5/1000 -> 119.871 | W10: =+T10-V10 -> -13.4205
D11: 기타 | E11: =+'[1]4월'!$E$8/1000-E9-E33-E10 -> 119.36667 | F11: =+('[2]4월'!$BJ$8+'[2]4월'!$BA$8+'[2]4월'!$AP$8+'[2]4월'!$AH$8)/1000 -> 56.508378 | G11: =+F11-E11 -> -62.858289 | H11: =+'[3]4월'!$F$8/1000-H9-H33-H10 -> 118.48886 | I11: =+F11-H11 -> -61.980486 | J11: =+'[1]4월누계'!$E$8/1000-J9-J33-J10 -> 485.26667 | K11: =+('[2]4월누계'!$BJ$8+'[2]4월누계'!$BA$8+'[2]4월누계'!$AP$8+'[2]4월누계'!$AH$8)/1000 -> 406.98072 | L11: =+K11-J11 -> -78.285946 | M11: =+'[3]4월누계'!$F$8/1000-M9-M33-M10 -> 591.32316 | N11: =+K11-M11 -> -184.34244 | R11: 중부권 | S11: =+[4]중부권!$T$5/1000 -> 49 | T11: =+[4]중부권!$U$5/1000 -> 51.802 | U11: =+T11-S11 -> 2.802 | V11: =+[5]중부권!$T$5/1000 -> 57.23 | W11: =+T11-V11 -> -5.428
C12: 계 | E12: =SUM(E9:E11) -> 29004.639 | F12: =SUM(F9:F11) -> 28980.118 | G12: =+F12-E12 -> -24.52055 | H12: =SUM(H9:H11) -> 28829.809 | I12: =+F12-H12 -> 150.30915 | J12: =SUM(J9:J11) -> 96341.605 | K12: =SUM(K9:K11) -> 93883.293 | L12: =+K12-J12 -> -2458.3121 | M12: =SUM(M9:M11) -> 97756.699 | N12: =+K12-M12 -> -3873.4059 | Q12: 계 | S12: =SUM(S9:S11) -> 272 | T12: =SUM(T9:T11) -> 272.948 | U12: =+T12-S12 -> 0.948 | V12: =SUM(V9:V11) -> 276.853 | W12: =+T12-V12 -> -3.905
C13: 매출원가 | D13: 레미콘 | E13: =+('[1]4월'!$Z$10+'[1]4월'!$Z$19)/1000 -> 24076.067 | F13: =+('[2]4월'!$Z$10+'[2]4월'!$Z$19)/1000 -> 25038.535 | G13: =+F13-E13 -> 962.46855 | H13: =+('[3]4월'!$Z$10+'[3]4월'!$Z$19)/1000 -> 24425.138 | I13: =+F13-H13 -> 613.39767 | J13: =+('[1]4월누계'!$Z$10+'[1]4월누계'!$Z$19)/1000 -> 83193.524 | K13: =+('[2]4월누계'!$Z$10+'[2]4월누계'!$Z$19)/1000 -> 82573.486 | L13: =+K13-J13 -> -620.03798 | M13: =+('[3]4월누계'!$Z$10+'[3]4월누계'!$Z$19)/1000 -> 84643.214 | N13: =+K13-M13 -> -2069.7275 | Q13: 판매단가 | R13: 수도권 | S13: =+[4]수도권!$T$61 -> 98524.097 | T13: =+[4]수도권!$U$61 -> 98815.723 | U13: =+T13-S13 -> 291.62623 | V13: =+[5]수도권!$Q$85 -> 96454.113 | W13: =+T13-V13 -> 2361.6094
D14: 골재 | E14: =+('[1]4월'!$AE$10+'[1]4월'!$AE$19)/1000 -> 1241.2551 | F14: =+('[2]4월'!$AN$10+'[2]4월'!$AN$19)/1000 -> 1462.1501 | G14: =+F14-E14 -> 220.89498 | H14: =+('[3]4월'!$AN$10+'[3]4월'!$AN$19)/1000 -> 1346.1014 | I14: =+F14-H14 -> 116.04864 | J14: =+('[1]4월누계'!$AE$10+'[1]4월누계'!$AE$19)/1000 -> 5011.8904 | K14: =+('[2]4월누계'!$AN$10+'[2]4월누계'!$AN$19)/1000 -> 5278.0794 | L14: =+K14-J14 -> 266.18899 | M14: =+('[3]4월누계'!$AN$10+'[3]4월누계'!$AN$19)/1000 -> 5287.1679 | N14: =+K14-M14 -> -9.088549 | R14: 영남권 | S14: =+[4]영남권!$T$61 -> 102882.75 | T14: =+[4]영남권!$U$61 -> 101778.55 | U14: =+T14-S14 -> -1104.2004 | V14: =+[5]영남권!$Q$85 -> 98385.129 | W14: =+T14-V14 -> 3393.4174
D15: 기타 | E15: =+('[1]4월'!$AL$10+'[1]4월'!$AL$19+'[1]4월'!$AV$10+'[1]4월'!$AV$19)/1000 -> 54.346293 | F15: =+('[2]4월'!$AH$10+'[2]4월'!$AH$19+'[2]4월'!$AP$10+'[2]4월'!$AP$19+'[2]4월'!$BA$10+'[2]4월'!$BA$19+'[2]4월'!$BJ$10+'[2]4월'!$BJ$19)/1000 -> 19.270152 | G15: =+F15-E15 -> -35.076141 | H15: =+('[3]4월'!$F$10+'[3]4월'!$F$19)/1000-H13-H14-('[3]4월'!$AO$10+'[3]4월'!$AO$19)/1000 -> 22.623855 | I15: =+F15-H15 -> -3.353703 | J15: =+('[1]4월누계'!$AL$10+'[1]4월누계'!$AL$19+'[1]4월누계'!$AV$10+'[1]4월누계'!$AV$19)/1000 -> -219.24914 | K15: =+('[2]4월누계'!$AH$10+'[2]4월누계'!$AH$19+'[2]4월누계'!$AP$10+'[2]4월누계'!$AP$19+'[2]4월누계'!$BA$10+'[2]4월누계'!$BA$19+'[2]4월누계'!$BJ$10+'[2]4월누계'!$BJ$19)/1000 -> -430.54186 | L15: =+K15-J15 -> -211.29272 | M15: =+('[3]4월누계'!$F$10+'[3]4월누계'!$F$19)/1000-M13-M14-('[3]4월누계'!$AO$10+'[3]4월누계'!$AO$19)/1000 -> 404.22394 | N15: =+K15-M15 -> -834.7658 | R15: 중부권 | S15: =+[4]중부권!$T$61 -> 105001.51 | T15: =+[4]중부권!$U$61 -> 103655.65 | U15: =+T15-S15 -> -1345.8529 | V15: =+[5]중부권!$Q$85 -> 102148.63 | W15: =+T15-V15 -> 1507.0236
C16: 계 | E16: =SUM(E13:E15) -> 25371.668 | F16: =SUM(F13:F15) -> 26519.956 | G16: =+F16-E16 -> 1148.2874 | H16: =SUM(H13:H15) -> 25793.863 | I16: =+F16-H16 -> 726.09261 | J16: =SUM(J13:J15) -> 87986.165 | K16: =SUM(K13:K15) -> 87421.024 | L16: =+K16-J16 -> -565.14171 | M16: =SUM(M13:M15) -> 90334.605 | N16: =+K16-M16 -> -2913.5818 | Q16: 계 | S16: =+[4]합계!$T$61 -> 101549.82 | T16: =+[4]합계!$U$61 -> 100907.33 | U16: =+T16-S16 -> -642.48832 | V16: =+[5]합계!$Q$85 -> 98470.346 | W16: =+T16-V16 -> 2436.9844
C17: 매출이익 | D17: 레미콘 | E17: =+E9-E13 -> 3545.484 | F17: =+F9-F13 -> 2483.8994 | G17: =+F17-E17 -> -1061.5846 | H17: =+H9-H13 -> 2837.1165 | I17: =+F17-H17 -> -353.21714 | J17: =+J9-J13 -> 7730.8051 | K17: =+K9-K13 -> 5961.9485 | L17: =+K17-J17 -> -1768.8566 | M17: =+M9-M13 -> 7495.3481 | N17: =+K17-M17 -> -1533.3996 | Q17: 공헌이익 | R17: 수도권 | S17: =+[4]수도권!$Q$90 -> 18719.086 | T17: =+[4]수도권!$R$90 -> 15872.128 | U17: =+T17-S17 -> -2846.9586 | V17: =+[5]수도권!$Q$90 -> 16372.588 | W17: =+T17-V17 -> -500.4606
D18: 골재 | E18: =+E10-E14 -> 22.466265 | F18: =+F10-F14 -> -60.974968 | G18: =+F18-E18 -> -83.441233 | H18: =+H10-H14 -> 102.96457 | I18: =+F18-H18 -> -163.93954 | J18: =+J10-J14 -> -79.880714 | K18: =+K10-K14 -> -337.20127 | L18: =+K18-J18 -> -257.32055 | M18: =+M10-M14 -> -260.35342 | N18: =+K18-M18 -> -76.847851 | R18: 영남권 | S18: =+[4]영남권!$Q$90 -> 24105.58 | T18: =+[4]영남권!$R$90 -> 20469.32 | U18: =+T18-S18 -> -3636.2605 | V18: =+[5]영남권!$Q$90 -> 19312.771 | W18: =+T18-V18 -> 1156.5488
D19: 기타 | E19: =+E11-E15 -> 65.020374 | F19: =+F11-F15 -> 37.238226 | G19: =+F19-E19 -> -27.782148 | H19: =+H11-H15 -> 95.865009 | I19: =+F19-H19 -> -58.626783 | J19: =+J11-J15 -> 704.51581 | K19: =+K11-K15 -> 837.52258 | L19: =+K19-J19 -> 133.00678 | M19: =+M11-M15 -> 187.09921 | N19: =+K19-M19 -> 650.42337 | R19: 중부권 | S19: =+[4]중부권!$Q$90 -> 26543.509 | T19: =+[4]중부권!$R$90 -> 21439.318 | U19: =+T19-S19 -> -5104.1912 | V19: =+[5]중부권!$Q$90 -> 24648.008 | W19: =+T19-V19 -> -3208.6898
C20: 계 | E20: =SUM(E17:E19) -> 3632.9706 | F20: =SUM(F17:F19) -> 2460.1626 | G20: =+F20-E20 -> -1172.8079 | H20: =SUM(H17:H19) -> 3035.9461 | I20: =+F20-H20 -> -575.78346 | J20: =SUM(J17:J19) -> 8355.4402 | K20: =SUM(K17:K19) -> 6462.2698 | L20: =+K20-J20 -> -1893.1704 | M20: =SUM(M17:M19) -> 7422.0939 | N20: =+K20-M20 -> -959.8241 | Q20: 계 | S20: =+[4]합계!$Q$90 -> 22425.814 | T20: =+[4]합계!$R$90 -> 18745.931 | U20: =+T20-S20 -> -3679.8837 | V20: =+[5]합계!$Q$90 -> 19361.122 | W20: =+T20-V20 -> -615.1909
C21: 판관비 | D21: 레미콘 | E21: =+('[1]4월'!$Z$13+'[1]4월'!$Z$20+'[1]4월'!$Z$22)/1000 -> 2328.7165 | F21: =+('[2]4월'!$Z$13+'[2]4월'!$Z$20+'[2]4월'!$Z$22)/1000 -> 2339.6024 | G21: =+F21-E21 -> 10.885864 | H21: =+('[3]4월'!$Z$13+'[3]4월'!$Z$20+'[3]4월'!$Z$22)/1000 -> 2326.3461 | I21: =+F21-H21 -> 13.256224 | J21: =+('[1]4월누계'!$Z$13+'[1]4월누계'!$Z$20+'[1]4월누계'!$Z$22)/1000 -> 8774.6158 | K21: =+('[2]4월누계'!$Z$13+'[2]4월누계'!$Z$20+'[2]4월누계'!$Z$22)/1000 -> 9044.6837 | L21: =+K21-J21 -> 270.06789 | M21: =+('[3]4월누계'!$Z$13+'[3]4월누계'!$Z$20+'[3]4월누계'!$Z$22)/1000 -> 8579.4127 | N21: =+K21-M21 -> 465.27107 | Q21: □ 골재
D22: 골재 | E22: =+('[1]4월'!$AE$13+'[1]4월'!$AE$20+'[1]4월'!$AE$22)/1000 -> 49.487315 | F22: =+('[2]4월'!$AN$13+'[2]4월'!$AN$20+'[2]4월'!$AN$22)/1000 -> 49.154012 | G22: =+F22-E22 -> -0.33330319 | H22: =+('[3]4월'!$AN$13+'[3]4월'!$AN$20+'[3]4월'!$AN$22)/1000 -> 45.658013 | I22: =+F22-H22 -> 3.495999 | J22: =+('[1]4월누계'!$AE$13+'[1]4월누계'!$AE$20+'[1]4월누계'!$AE$22)/1000 -> 202.39497 | K22: =+('[2]4월누계'!$AN$13+'[2]4월누계'!$AN$20+'[2]4월누계'!$AN$22)/1000 -> 204.99205 | L22: =+K22-J22 -> 2.597083 | M22: =+('[3]4월누계'!$AN$13+'[3]4월누계'!$AN$20+'[3]4월누계'!$AN$22)/1000 -> 187.38509 | N22: =+K22-M22 -> 17.606964 | Q22: 구분 | S22: 계획 | T22: 실적 | U22: 계획대비 | V22: 전년 | W22: 전년대비
D23: 기타 | E23: =+('[1]4월'!$AL$13+'[1]4월'!$AV$13+'[1]4월'!$AL$20+'[1]4월'!$AV$20+'[1]4월'!$AL$22+'[1]4월'!$AV$22)/1000 -> 81.055169 | F23: =+('[2]4월'!$F$13+'[2]4월'!$F$20+'[2]4월'!$F$22)/1000-F21-F22-('[2]4월'!$AO$13+'[2]4월'!$AO$20+'[2]4월'!$AO$22)/1000 -> 58.292378 | G23: =+F23-E23 -> -22.762791 | H23: =+('[3]4월'!$F$13+'[3]4월'!$F$20+'[3]4월'!$F$22)/1000-H21-H22-('[3]4월'!$AO$13+'[3]4월'!$AO$20+'[3]4월'!$AO$22)/1000 -> 56.121236 | I23: =+F23-H23 -> 2.171142 | J23: =+('[1]4월누계'!$AL$13+'[1]4월누계'!$AV$13+'[1]4월누계'!$AL$20+'[1]4월누계'!$AV$20+'[1]4월누계'!$AL$22+'[1]4월누계'!$AV$22)/1000 -> 238.20217 | K23: =+('[2]4월누계'!$F$13+'[2]4월누계'!$F$20+'[2]4월누계'!$F$22)/1000-K21-K22-('[2]4월누계'!$AO$13+'[2]4월누계'!$AO$20+'[2]4월누계'!$AO$22)/1000 -> 10.092244 | L23: =+K23-J23 -> -228.10993 | M23: =+('[3]4월누계'!$F$13+'[3]4월누계'!$F$20+'[3]4월누계'!$F$22)/1000-M21-M22-('[3]4월누계'!$AO$13+'[3]4월누계'!$AO$20+'[3]4월누계'!$AO$22)/1000 -> 1150.5075 | N23: =+K23-M23 -> -1140.4153 | Q23: 판매량 | R23: 자가 | S23: =+[6]원가손익!$W$10+[7]원가손익!$U$27+[8]손익!$F$10 -> 45808.284 | T23: =+[6]원가손익!$X$10+[7]원가손익!$V$27+[8]손익!$G$10 -> 50775 | U23: =+T23-S23 -> 4966.7156 | V23: =+[9]원가손익!$X$10+[10]원가손익!$V$27+[11]손익!$Y$25 -> 43755 | W23: =+T23-V23 -> 7020
C24: 계 | E24: =SUM(E21:E23) -> 2459.259 | F24: =SUM(F21:F23) -> 2447.0487 | G24: =+F24-E24 -> -12.21023 | H24: =SUM(H21:H23) -> 2428.1254 | I24: =+F24-H24 -> 18.923365 | J24: =SUM(J21:J23) -> 9215.213 | K24: =SUM(K21:K23) -> 9259.768 | L24: =+K24-J24 -> 44.555044 | M24: =SUM(M21:M23) -> 9917.3053 | N24: =+K24-M24 -> -657.53723 | R24: 외판 | S24: =+[6]원가손익!$W$14+[7]원가손익!$U$29+[8]손익!$F$12 -> 25160 | T24: =+[6]원가손익!$X$14+[7]원가손익!$V$29+[8]손익!$G$12 -> 20718 | U24: =+T24-S24 -> -4442 | V24: =+[9]원가손익!$X$14+[10]원가손익!$V$29+[11]손익!$Y$27 -> 24270 | W24: =+T24-V24 -> -3552
C25: 영업이익 | D25: 레미콘 | E25: =+E17-E21 -> 1216.7675 | F25: =+F17-F21 -> 144.29704 | G25: =+F25-E25 -> -1072.4704 | H25: =+H17-H21 -> 510.7704 | I25: =+F25-H25 -> -366.47336 | J25: =+J17-J21 -> -1043.8107 | K25: =+K17-K21 -> -3082.7352 | L25: =+K25-J25 -> -2038.9245 | M25: =+M17-M21 -> -1084.0645 | N25: =+K25-M25 -> -1998.6707 | Q25: 합 계 | S25: =SUM(S23:S24) -> 70968.284 | T25: =SUM(T23:T24) -> 71493 | U25: =+T25-S25 -> 524.71562 | V25: =SUM(V23:V24) -> 68025 | W25: =+T25-V25 -> 3468
D26: % | E26: =+E25/E9 -> 0.044051381 | F26: =+F25/F9 -> 0.0052428878 | G26: =+F26-E26 -> -0.038808493 | H26: =+H25/H9 -> 0.018735443 | I26: =+F26-H26 -> -0.013492555 | J26: =+J25/J9 -> -0.011479994 | K26: =+K25/K9 -> -0.034819225 | L26: =+K26-J26 -> -0.023339231 | M26: =+M25/M9 -> -0.01176559 | N26: =+K26-M26 -> -0.023053635 | Q26: □ 기타내역(영업이익)
D27: 골재 | E27: =+E18-E22 -> -27.021051 | F27: =+F18-F22 -> -110.12898 | G27: =+F27-E27 -> -83.10793 | H27: =+H18-H22 -> 57.306559 | I27: =+F27-H27 -> -167.43554 | J27: =+J18-J22 -> -282.27568 | K27: =+K18-K22 -> -542.19332 | L27: =+K27-J27 -> -259.91764 | M27: =+M18-M22 -> -447.7385 | N27: =+K27-M27 -> -94.454815 | Q27: 구분 | S27: 계획 | T27: 실적 | U27: 계획대비 | V27: 전년 | W27: 전년대비
D28: 기타 | E28: =+E19-E23 -> -16.034795 | F28: =+F19-F23 -> -21.054152 | G28: =+F28-E28 -> -5.0193567 | H28: =+H19-H23 -> 39.743773 | I28: =+F28-H28 -> -60.797925 | J28: =+J19-J23 -> 466.31364 | K28: =+K19-K23 -> 827.43034 | L28: =+K28-J28 -> 361.1167 | M28: =+M19-M23 -> -963.4083 | N28: =+K28-M28 -> 1790.8386 | Q28: 레미콘임대 | S28: =+'사업장별(당월)'!T32 -> 25.462031 | T28: =+'사업장별(당월)'!U32 -> 22.270322 | U28: =+T28-S28 -> -3.191709 | V28: =+'사업장별(당월)'!W32 -> 23.021931 | W28: =+T28-V28 -> -0.751609
C29: 계 | E29: =+E25+E27+E28 -> 1173.7116 | F29: =+F25+F27+F28 -> 13.113905 | G29: =+F29-E29 -> -1160.5977 | H29: =+H25+H27+H28 -> 607.82073 | I29: =+F29-H29 -> -594.70683 | J29: =+J25+J27+J28 -> -859.77277 | K29: =+K25+K27+K28 -> -2797.4982 | L29: =+K29-J29 -> -1937.7254 | M29: =+M25+M27+M28 -> -2495.2113 | N29: =+K29-M29 -> -302.28687 | Q29: 임대 | S29: =+'사업장별(당월)'!T33 -> 72.847673 | T29: =+'사업장별(당월)'!U33 -> 4.334114 | U29: =+T29-S29 -> -68.513559 | V29: =+'사업장별(당월)'!W33 -> 63.367074 | W29: =+T29-V29 -> -59.03296
D30: % | E30: =+E29/E12 -> 0.040466341 | F30: =+F29/F12 -> 0.00045251385 | G30: =+F30-E30 -> -0.040013828 | H30: =+H29/H12 -> 0.021083065 | I30: =+F30-H30 -> -0.020630551 | J30: =+J29/J12 -> -0.0089242105 | K30: =+K29/K12 -> -0.029797615 | L30: =+K30-J30 -> -0.020873404 | M30: =+M29/M12 -> -0.025524709 | N30: =+K30-M30 -> -0.0042729053 | Q30: 공통비 | S30: =+'사업장별(당월)'!T34 -> -1643.534 | T30: =+'사업장별(당월)'!U34 -> -1645.635 | U30: =+T30-S30 -> -2.101069 | V30: =+'사업장별(당월)'!W34 -> -1654.8985 | W30: =+T30-V30 -> 9.263444
C31: * 건자재 | Q31: 기타 | S31: =+S32-S28-S29-S30 -> -114.3445 | T31: =+T32-T28-T29-T30 -> -47.658588 | U31: =+T31-S31 -> 66.685911 | V31: =+V32-V28-V29-V30 -> -46.645232 | W31: =+T31-V31 -> -1.013356
C32: 물량 | E32: =+IFERROR(HLOOKUP($E$5,[12]손익!$G$5:$AI$54,2,),) -> 9400 | F32: =+'[2]4월'!$AO$7 -> 3426.716 | G32: =+F32-E32 -> -5973.284 | H32: =+'[3]4월'!$AO$7 -> 11123.665 | I32: =+F32-H32 -> -7696.949 | J32: =+'[1]4월누계'!$AA$7 -> 32900 | K32: =+'[2]4월누계'!$AO$7 -> 17304.954 | L32: =+K32-J32 -> -15595.046 | M32: =+'[3]4월누계'!$AO$7 -> 45346.46 | N32: =+K32-M32 -> -28041.506 | Q32: 합계 | S32: =+'사업장별(당월)'!T40 -> -1659.5688 | T32: =+'사업장별(당월)'!U40 -> -1666.6892 | U32: =+T32-S32 -> -7.1204256 | V32: =+'사업장별(당월)'!W40 -> -1615.1547 | W32: =+T32-V32 -> -51.534481
C33: 매출 | E33: =+IFERROR(HLOOKUP($E$5,[12]손익!$G$5:$AI$54,3,),)/1000 -> 9270.2921 | F33: =+'[2]4월'!$AO$8/1000 -> 4012.7001 | G33: =+F33-E33 -> -5257.592 | H33: =+'[3]4월'!$AO$8/1000 -> 10147.504 | I33: =+F33-H33 -> -6134.8041 | J33: =+'[1]4월누계'!$AA$8/1000 -> 31857.361 | K33: =+'[2]4월누계'!$AO$8/1000 -> 18007.082 | L33: =+K33-J33 -> -13850.28 | M33: =+'[3]4월누계'!$AO$8/1000 -> 38439.848 | N33: =+K33-M33 -> -20432.766
C34: 매출이익 | E34: =+IFERROR(HLOOKUP($E$5,[12]손익!$G$5:$AI$54,7,),)/1000 -> 222.93703 | F34: =+'[2]4월'!$AO$12/1000 -> 113.28871 | G34: =+F34-E34 -> -109.64832 | H34: =+'[3]4월'!$AO$12/1000 -> 167.74386 | I34: =+F34-H34 -> -54.455144 | J34: =+'[1]4월누계'!$AA$12/1000 -> 705.68334 | K34: =+'[2]4월누계'!$AO$12/1000 -> 445.18366 | L34: =+K34-J34 -> -260.49967 | M34: =+'[3]4월누계'!$AO$12/1000 -> 500.15996 | N34: =+K34-M34 -> -54.976294 | Q34: □ 건자재
C35: (%) | E35: =+E34/E33 -> 0.024048544 | F35: =+F34/F33 -> 0.028232539 | G35: =+F35-E35 -> 0.0041839952 | H35: =+H34/H33 -> 0.016530553 | I35: =+I34/I33 -> 0.0088764276 | J35: =+J34/J33 -> 0.022151343 | K35: =+K34/K33 -> 0.024722699 | L35: =+K35-J35 -> 0.002571356 | M35: =+M34/M33 -> 0.013011497 | N35: =+K35-M35 -> 0.011711202 | Q35: 구분 | S35: 계획 | T35: 실적 | U35: 계획대비 | V35: 전년 | W35: 전년대비
C36: 영업이익 | E36: =+IFERROR(HLOOKUP($E$5,[12]손익!$G$5:$AI$54,20,),)/1000 -> 2.0257729 | F36: =+'[2]4월'!$AO$26/1000 -> -75.818011 | G36: =+F36-E36 -> -77.843784 | H36: =+'[3]4월'!$AO$26/1000 -> -0.271546 | I36: =+F36-H36 -> -75.546465 | J36: =+'[1]4월누계'!$AA$26/1000 -> -83.401738 | K36: =+'[2]4월누계'!$AO$26/1000 -> -173.31428 | L36: =+K36-J36 -> -89.912538 | M36: =+'[3]4월누계'!$AO$26/1000 -> -106.58293 | N36: =+K36-M36 -> -66.731344 | Q36: 철강재 판매단가 | S36: =+'[13]4월'!$F$10 -> 766053.19 | T36: =+'[13]4월'!$G$10 -> 844269.96 | U36: =+T36-S36 -> 78216.769 | V36: =+'[14]4월'!$G$10 -> 800210.93 | W36: =+T36-V36 -> 44059.028
C37: (%) | E37: =+E36/E33 -> 0.00021852309 | F37: =+F36/F33 -> -0.018894512 | G37: =+F37-E37 -> -0.019113035 | H37: =+H36/H33 -> -2.675988e-05 | I37: =+F37-H37 -> -0.018867752 | J37: =+J36/J33 -> -0.0026179738 | K37: =+K36/K33 -> -0.0096247841 | L37: =+K37-J37 -> -0.0070068103 | M37: =+M36/M33 -> -0.0027727199 | N37: =+K37-M37 -> -0.0068520642 | Q37: 철강재 마진률 | S37: =+'[13]4월'!$F$15 -> 0.020025275 | T37: =+'[13]4월'!$G$15 -> 0.029344534 | U37: =+T37-S37 -> 0.0093192589 | V37: =+'[14]4월'!$G$15 -> 0.014249312 | W37: =+T37-V37 -> 0.015095221
E39: =+'[1]4월'!$E$26/1000 -> 1175.7374 | F39: =+'[2]4월'!$F$26/1000 -> -62.704106 | H39: =+'[3]4월'!$F$26/1000 -> 607.54919 | J39: =+'[1]4월누계'!$E$26/1000 -> -943.17451 | K39: =+'[2]4월누계'!$F$26/1000 -> -2970.8125 | M39: =+'[3]4월누계'!$F$26/1000 -> -2601.7943
E40: =+(E29+E36)-E39 -> 3.4106051e-12 | F40: =+(F29+F36)-F39 -> 1.6342483e-13 | H40: =+(H29+H36)-H39 -> 3.9790393e-12 | J40: =+(J29+J36)-J39 -> -1.5347723e-11 | K40: =+(K29+K36)-K39 -> 1.2278178e-11 | M40: =+(M29+M36)-M39 -> -5.0022209e-12

Sheet 레미콘 영업이익
H3: □ 레미콘 영업이익(4월)
H5: 구분 | J5: 4월 | T5: 4월누계
J6: 영업이익(공통비 배부전) | O6: 영업이익(공통비 배부후) | T6: 영업이익(공통비 배부전) | Y6: 영업이익(공통비 배부전)
A7: 2024년 1월 마감 손익 | J7: 계획 | K7: 실적 | L7: 차이 | M7: 전년 | N7: 차이 | O7: 계획 | P7: 실적 | Q7: 차이 | R7: 전년 | S7: 차이 | T7: 계획 | U7: 실적 | V7: 차이 | W7: 전년 | X7: 차이 | Y7: 계획 | Z7: 실적 | AA7: 차이 | AB7: 전년 | AC7: 차이
B8: 안양 | H8: 레미콘 | I8: 안양 | J8: =+[4]안양!$H$86/1000 -> 492.29041 | K8: =+[4]안양!$I$86/1000 -> 358.71954 | L8: =+K8-J8 -> -133.57087 | M8: =+[5]안양!$H$86/1000 -> 321.01658 | N8: =+K8-M8 -> 37.70296 | O8: =+[4]안양!$H$92/1000 -> 264.60241 | P8: =+[4]안양!$I$92/1000 -> 119.45107 | Q8: =+P8-O8 -> -145.15134 | R8: =+[5]안양!$H$92/1000 -> 93.12533 | S8: =+P8-R8 -> 26.32574 | T8: =+[15]안양!$H$86/1000 -> 1177.9873 | U8: =+[15]안양!$I$86/1000 -> 1130.2213 | V8: =+U8-T8 -> -47.765941 | W8: =+[16]안양!$H$86/1000 -> 865.27363 | X8: =+U8-W8 -> 264.94771 | Y8: =+[15]안양!$H$92/1000 -> 314.75372 | Z8: =+[15]안양!$I$92/1000 -> 129.53938 | AA8: =+Z8-Y8 -> -185.21434 | AB8: =+[16]안양!$H$92/1000 -> 18.075364 | AC8: =+Z8-AB8 -> 111.46402
B9: 인천 | H9: 직영 | I9: 인천 | J9: =+[4]인천!$H$86/1000 -> 290.24791 | K9: =+[4]인천!$I$86/1000 -> 121.58991 | L9: =+K9-J9 -> -168.658 | M9: =+[5]인천!$H$86/1000 -> 222.53657 | N9: =+K9-M9 -> -100.94666 | O9: =+[4]인천!$H$92/1000 -> 87.210876 | P9: =+[4]인천!$I$92/1000 -> -84.650801 | Q9: =+P9-O9 -> -171.86168 | R9: =+[5]인천!$H$92/1000 -> 25.466828 | S9: =+P9-R9 -> -110.11763 | T9: =+[15]인천!$H$86/1000 -> 458.58091 | U9: =+[15]인천!$I$86/1000 -> 47.265004 | V9: =+U9-T9 -> -411.3159 | W9: =+[16]인천!$H$86/1000 -> 143.88325 | X9: =+U9-W9 -> -96.618244 | Y9: =+[15]인천!$H$92/1000 -> -298.43559 | Z9: =+[15]인천!$I$92/1000 -> -705.61162 | AA9: =+Z9-Y9 -> -407.17603 | AB9: =+[16]인천!$H$92/1000 -> -477.46227 | AC9: =+Z9-AB9 -> -228.14935
B10: 파주 | I10: 파주 | J10: =+[4]파주!$H$86/1000 -> 74.264373 | K10: =+[4]파주!$I$86/1000 -> 129.07579 | L10: =+K10-J10 -> 54.81142 | M10: =+[5]파주!$H$86/1000 -> -15.154132 | N10: =+K10-M10 -> 144.22993 | O10: =+[4]파주!$H$92/1000 -> -23.246892 | P10: =+[4]파주!$I$92/1000 -> 14.777372 | Q10: =+P10-O10 -> 38.024264 | R10: =+[5]파주!$H$92/1000 -> -90.483073 | S10: =+P10-R10 -> 105.26044 | T10: =+[15]파주!$H$86/1000 -> -113.85017 | U10: =+[15]파주!$I$86/1000 -> -215.00812 | V10: =+U10-T10 -> -101.15795 | W10: =+[16]파주!$H$86/1000 -> -312.75035 | X10: =+U10-W10 -> 97.742226 | Y10: =+[15]파주!$H$92/1000 -> -426.82499 | Z10: =+[15]파주!$I$92/1000 -> -523.85204 | AA10: =+Z10-Y10 -> -97.027055 | AB10: =+[16]파주!$H$92/1000 -> -565.26699 | AC10: =+Z10-AB10 -> 41.414944
B11: 김포 | I11: 김포 | J11: =+[4]김포!$H$86/1000 -> 92.029372 | K11: =+[4]김포!$I$86/1000 -> 110.17716 | L11: =+K11-J11 -> 18.147787 | M11: =+[5]김포!$H$86/1000 -> 64.83259 | N11: =+K11-M11 -> 45.344569 | O11: =+[4]김포!$H$92/1000 -> 7.6733731 | P11: =+[4]김포!$I$92/1000 -> 8.3064531 | Q11: =+P11-O11 -> 0.63308 | R11: =+[5]김포!$H$92/1000 -> -5.310725 | S11: =+P11-R11 -> 13.617178 | T11: =+[15]김포!$H$86/1000 -> 35.074517 | U11: =+[15]김포!$I$86/1000 -> -93.164257 | V11: =+U11-T11 -> -128.23877 | W11: =+[16]김포!$H$86/1000 -> -50.511174 | X11: =+U11-W11 -> -42.653083 | Y11: =+[15]김포!$H$92/1000 -> -240.6616 | Z11: =+[15]김포!$I$92/1000 -> -387.76216 | AA11: =+Z11-Y11 -> -147.10056 | AB11: =+[16]김포!$H$92/1000 -> -264.77053 | AC11: =+Z11-AB11 -> -122.99163
B12: 부산 | I12: 부산 | J12: =+[4]부산!$H$86/1000 -> 229.16261 | K12: =+[4]부산!$I$86/1000 -> 200.10526 | L12: =+K12-J12 -> -29.057352 | M12: =+[5]부산!$H$86/1000 -> 112.51179 | N12: =+K12-M12 -> 87.593469 | O12: =+[4]부산!$H$92/1000 -> 96.313095 | P12: =+[4]부산!$I$92/1000 -> 52.00417 | Q12: =+P12-O12 -> -44.308925 | R12: =+[5]부산!$H$92/1000 -> -21.087948 | S12: =+P12-R12 -> 73.092118 | T12: =+[15]부산!$H$86/1000 -> 642.36279 | U12: =+[15]부산!$I$86/1000 -> 1003.604 | V12: =+U12-T12 -> 361.2412 | W12: =+[16]부산!$H$86/1000 -> 676.07838 | X12: =+U12-W12 -> 327.52561 | Y12: =+[15]부산!$H$92/1000 -> 82.293803 | Z12: =+[15]부산!$I$92/1000 -> 276.71733 | AA12: =+Z12-Y12 -> 194.42353 | AB12: =+[16]부산!$H$92/1000 -> 158.47277 | AC12: =+Z12-AB12 -> 118.24457
B13: 서부산 | I13: 서부산 | J13: =+[4]서부산!$H$86/1000 -> 350.38968 | K13: =+[4]서부산!$I$86/1000 -> 165.79219 | L13: =+K13-J13 -> -184.59749 | M13: =+[5]서부산!$H$86/1000 -> 155.86617 | N13: =+K13-M13 -> 9.926026 | O13: =+[4]서부산!$H$92/1000 -> 216.43259 | P13: =+[4]서부산!$I$92/1000 -> 27.845856 | Q13: =+P13-O13 -> -188.58673 | R13: =+[5]서부산!$H$92/1000 -> 37.372246 | S13: =+P13-R13 -> -9.5263892 | T13: =+[15]서부산!$H$86/1000 -> 910.42828 | U13: =+[15]서부산!$I$86/1000 -> 554.00182 | V13: =+U13-T13 -> -356.42646 | W13: =+[16]서부산!$H$86/1000 -> 414.88535 | X13: =+U13-W13 -> 139.11648 | Y13: =+[15]서부산!$H$92/1000 -> 379.12548 | Z13: =+[15]서부산!$I$92/1000 -> 43.590912 | AA13: =+Z13-Y13 -> -335.53457 | AB13: =+[16]서부산!$H$92/1000 -> -14.663704 | AC13: =+Z13-AB13 -> 58.254617
B14: 김해 | I14: 김해 | J14: =+[4]김해!$H$86/1000 -> 79.709608 | K14: =+[4]김해!$I$86/1000 -> -7.402545 | L14: =+K14-J14 -> -87.112153 | M14: =+[5]김해!$H$86/1000 -> -22.904841 | N14: =+K14-M14 -> 15.502296 | O14: =+[4]김해!$H$92/1000 -> 17.583949 | P14: =+[4]김해!$I$92/1000 -> -46.057923 | Q14: =+P14-O14 -> -63.641873 | R14: =+[5]김해!$H$92/1000 -> -87.332458 | S14: =+P14-R14 -> 41.274535 | T14: =+[15]김해!$H$86/1000 -> 74.222074 | U14: =+[15]김해!$I$86/1000 -> -125.69932 | V14: =+U14-T14 -> -199.9214 | W14: =+[16]김해!$H$86/1000 -> -105.52443 | X14: =+U14-W14 -> -20.174892 | Y14: =+[15]김해!$H$92/1000 -> -148.45447 | Z14: =+[15]김해!$I$92/1000 -> -293.76238 | AA14: =+Z14-Y14 -> -145.30791 | AB14: =+[16]김해!$H$92/1000 -> -305.45462 | AC14: =+Z14-AB14 -> 11.692242
B15: 정관 | I15: 정관 | J15: =+[4]정관!$H$86/1000 -> 322.85639 | K15: =+[4]정관!$I$86/1000 -> 160.08659 | L15: =+K15-J15 -> -162.7698 | M15: =+[5]정관!$H$86/1000 -> 280.09121 | N15: =+K15-M15 -> -120.00463 | O15: =+[4]정관!$H$92/1000 -> 179.6834 | P15: =+[4]정관!$I$92/1000 -> 43.877797 | Q15: =+P15-O15 -> -135.8056 | R15: =+[5]정관!$H$92/1000 -> 126.85838 | S15: =+P15-R15 -> -82.980581 | T15: =+[15]정관!$H$86/1000 -> 699.57932 | U15: =+[15]정관!$I$86/1000 -> 116.17425 | V15: =+U15-T15 -> -583.40507 | W15: =+[16]정관!$H$86/1000 -> 647.1619 | X15: =+U15-W15 -> -530.98765 | Y15: =+[15]정관!$H$92/1000 -> 127.73051 | Z15: =+[15]정관!$I$92/1000 -> -276.72599 | AA15: =+Z15-Y15 -> -404.4565 | AB15: =+[16]정관!$H$92/1000 -> 114.93199 | AC15: =+Z15-AB15 -> -391.65798
B16: 양산 | I16: 양산 | J16: =+[4]양산!$H$86/1000 -> 116.98911 | K16: =+[4]양산!$I$86/1000 -> 18.913598 | L16: =+K16-J16 -> -98.075508 | M16: =+[5]양산!$H$86/1000 -> -26.417206 | N16: =+K16-M16 -> 45.330804 | O16: =+[4]양산!$H$92/1000 -> 55.15985 | P16: =+[4]양산!$I$92/1000 -> -24.986757 | Q16: =+P16-O16 -> -80.146606 | R16: =+[5]양산!$H$92/1000 -> -62.652885 | S16: =+P16-R16 -> 37.666128 | T16: =+[15]양산!$H$86/1000 -> 103.39075 | U16: =+[15]양산!$I$86/1000 -> -65.455742 | V16: =+U16-T16 -> -168.84649 | W16: =+[16]양산!$H$86/1000 -> 20.936167 | X16: =+U16-W16 -> -86.391909 | Y16: =+[15]양산!$H$92/1000 -> -102.46433 | Z16: =+[15]양산!$I$92/1000 -> -213.02398 | AA16: =+Z16-Y16 -> -110.55965 | AB16: =+[16]양산!$H$92/1000 -> -164.19528 | AC16: =+Z16-AB16 -> -48.828695
B17: 창원 | I17: 창원 | J17: =+[4]창원!$H$86/1000 -> 98.886576 | K17: =+[4]창원!$I$86/1000 -> 73.953798 | L17: =+K17-J17 -> -24.932778 | M17: =+[5]창원!$H$86/1000 -> 126.42044 | N17: =+K17-M17 -> -52.466639 | O17: =+[4]창원!$H$92/1000 -> 21.242037 | P17: =+[4]창원!$I$92/1000 -> 6.9318965 | Q17: =+P17-O17 -> -14.31014 | R17: =+[5]창원!$H$92/1000 -> 51.247643 | S17: =+P17-R17 -> -44.315746 | T17: =+[15]창원!$H$86/1000 -> 110.51912 | U17: =+[15]창원!$I$86/1000 -> 82.022063 | V17: =+U17-T17 -> -28.497058 | W17: =+[16]창원!$H$86/1000 -> 332.12888 | X17: =+U17-W17 -> -250.10682 | Y17: =+[15]창원!$H$92/1000 -> -168.50854 | Z17: =+[15]창원!$I$92/1000 -> -185.186 | AA17: =+Z17-Y17 -> -16.677462 | AB17: =+[16]창원!$H$92/1000 -> 46.431076 | AC17: =+Z17-AB17 -> -231.61707
B18: 대구 | I18: 대구 | J18: =+[4]대구!$H$86/1000 -> 19.577609 | K18: =+[4]대구!$I$86/1000 -> -79.863768 | L18: =+K18-J18 -> -99.441377 | M18: =+[5]대구!$H$86/1000 -> 50.698716 | N18: =+K18-M18 -> -130.56248 | O18: =+[4]대구!$H$92/1000 -> -27.488533 | P18: =+[4]대구!$I$92/1000 -> -107.28071 | Q18: =+P18-O18 -> -79.792172 | R18: =+[5]대구!$H$92/1000 -> -15.464187 | S18: =+P18-R18 -> -91.816519 | T18: =+[15]대구!$H$86/1000 -> -85.566447 | U18: =+[15]대구!$I$86/1000 -> -368.22257 | V18: =+U18-T18 -> -282.65613 | W18: =+[16]대구!$H$86/1000 -> 61.16904 | X18: =+U18-W18 -> -429.39161 | Y18: =+[15]대구!$H$92/1000 -> -267.68118 | Z18: =+[15]대구!$I$92/1000 -> -470.77233 | AA18: =+Z18-Y18 -> -203.09114 | AB18: =+[16]대구!$H$92/1000 -> -199.82177 | AC18: =+Z18-AB18 -> -270.95056
B19: 울산 | I19: 울산 | J19: =+[4]울산!$H$86/1000 -> 94.836244 | K19: =+[4]울산!$I$86/1000 -> 114.37949 | L19: =+K19-J19 -> 19.543248 | M19: =+[5]울산!$H$86/1000 -> 174.90096 | N19: =+K19-M19 -> -60.521464 | O19: =+[4]울산!$H$92/1000 -> 21.51616 | P19: =+[4]울산!$I$92/1000 -> 23.572614 | Q19: =+P19-O19 -> 2.0564541 | R19: =+[5]울산!$H$92/1000 -> 84.876796 | S19: =+P19-R19 -> -61.304182 | T19: =+[15]울산!$H$86/1000 -> 49.217038 | U19: =+[15]울산!$I$86/1000 -> 305.0153 | V19: =+U19-T19 -> 255.79826 | W19: =+[16]울산!$H$86/1000 -> 419.25622 | X19: =+U19-W19 -> -114.24092 | Y19: =+[15]울산!$H$92/1000 -> -203.19508 | Z19: =+[15]울산!$I$92/1000 -> -54.403005 | AA19: =+Z19-Y19 -> 148.79208 | AB19: =+[16]울산!$H$92/1000 -> 104.82036 | AC19: =+Z19-AB19 -> -159.22336
B20: 아산 | I20: 아산 | J20: =+[4]아산!$H$86/1000 -> 230.1545 | K20: =+[4]아산!$I$86/1000 -> 133.83138 | L20: =+K20-J20 -> -96.323125 | M20: =+[5]아산!$H$86/1000 -> 177.27361 | N20: =+K20-M20 -> -43.442233 | O20: =+[4]아산!$H$92/1000 -> 97.573624 | P20: =+[4]아산!$I$92/1000 -> -7.8511643 | Q20: =+P20-O20 -> -105.42479 | R20: =+[5]아산!$H$92/1000 -> 46.164839 | S20: =+P20-R20 -> -54.016003 | T20: =+[15]아산!$H$86/1000 -> 189.96502 | U20: =+[15]아산!$I$86/1000 -> 197.6079 | V20: =+U20-T20 -> 7.6428799 | W20: =+[16]아산!$H$86/1000 -> 357.75961 | X20: =+U20-W20 -> -160.15171 | Y20: =+[15]아산!$H$92/1000 -> -202.53093 | Z20: =+[15]아산!$I$92/1000 -> -327.99611 | AA20: =+Z20-Y20 -> -125.46518 | AB20: =+[16]아산!$H$92/1000 -> -150.25035 | AC20: =+Z20-AB20 -> -177.74576
B21: 전주 | I21: 전주 | J21: =+[4]전주!$H$86/1000 -> 129.22282 | K21: =+[4]전주!$I$86/1000 -> 61.431893 | L21: =+K21-J21 -> -67.790928 | M21: =+[5]전주!$H$86/1000 -> 227.34832 | N21: =+K21-M21 -> -165.91642 | O21: =+[4]전주!$H$92/1000 -> 64.113088 | P21: =+[4]전주!$I$92/1000 -> -15.366353 | Q21: =+P21-O21 -> -79.479441 | R21: =+[5]전주!$H$92/1000 -> 127.06563 | S21: =+P21-R21 -> -142.43198 | T21: =+[15]전주!$H$86/1000 -> 121.85629 | U21: =+[15]전주!$I$86/1000 -> 108.54904 | V21: =+U21-T21 -> -13.307244 | W21: =+[16]전주!$H$86/1000 -> 686.34032 | X21: =+U21-W21 -> -577.79127 | Y21: =+[15]전주!$H$92/1000 -> -80.949469 | Z21: =+[15]전주!$I$92/1000 -> -161.65745 | AA21: =+Z21-Y21 -> -80.707985 | AB21: =+[16]전주!$H$92/1000 -> 321.63721 | AC21: =+Z21-AB21 -> -483.29466
B22: 군산 | I22: 군산 | J22: =+[4]군산!$H$86/1000 -> 105.79383 | K22: =+[4]군산!$I$86/1000 -> 96.361313 | L22: =+K22-J22 -> -9.4325207 | M22: =+[5]군산!$H$86/1000 -> 173.95167 | N22: =+K22-M22 -> -77.590357 | O22: =+[4]군산!$H$92/1000 -> 73.228025 | P22: =+[4]군산!$I$92/1000 -> 63.160553 | Q22: =+P22-O22 -> -10.067472 | R22: =+[5]군산!$H$92/1000 -> 129.41627 | S22: =+P22-R22 -> -66.25572 | T22: =+[15]군산!$H$86/1000 -> 198.73914 | U22: =+[15]군산!$I$86/1000 -> 168.4954 | V22: =+U22-T22 -> -30.243744 | W22: =+[16]군산!$H$86/1000 -> 373.7742 | X22: =+U22-W22 -> -205.27881 | Y22: =+[15]군산!$H$92/1000 -> 96.204018 | Z22: =+[15]군산!$I$92/1000 -> 67.980951 | AA22: =+Z22-Y22 -> -28.223066 | AB22: =+[16]군산!$H$92/1000 -> 247.28632 | AC22: =+Z22-AB22 -> -179.30537
B23: 원주 | I23: 원주 | J23: =+[4]원주!$H$86/1000 -> 68.337597 | K23: =+[4]원주!$I$86/1000 -> 103.45074 | L23: =+K23-J23 -> 35.113145 | M23: =+[5]원주!$H$86/1000 -> 14.251573 | N23: =+K23-M23 -> 89.199169 | O23: =+[4]원주!$H$92/1000 -> 42.388356 | P23: =+[4]원주!$I$92/1000 -> 72.597246 | Q23: =+P23-O23 -> 30.20889 | R23: =+[5]원주!$H$92/1000 -> -2.9603054 | S23: =+P23-R23 -> 75.557551 | T23: =+[15]원주!$H$86/1000 -> 177.06889 | U23: =+[15]원주!$I$86/1000 -> 179.33825 | V23: =+U23-T23 -> 2.2693616 | W23: =+[16]원주!$H$86/1000 -> -61.959749 | X23: =+U23-W23 -> 241.298 | Y23: =+[15]원주!$H$92/1000 -> 74.493354 | Z23: =+[15]원주!$I$92/1000 -> 86.653014 | AA23: =+Z23-Y23 -> 12.15966 | AB23: =+[16]원주!$H$92/1000 -> -121.0319 | AC23: =+Z23-AB23 -> 207.68491
B24: 제주 | I24: 제주 | J24: =+[4]제주!$H$86/1000 -> 65.55279 | K24: =+[4]제주!$I$86/1000 -> 29.329734 | L24: =+K24-J24 -> -36.223056 | M24: =+[5]제주!$H$86/1000 -> 128.44487 | N24: =+K24-M24 -> -99.115137 | O24: =+[4]제주!$H$92/1000 -> 22.782055 | P24: =+[4]제주!$I$92/1000 -> -2.0342868 | Q24: =+P24-O24 -> -24.816342 | R24: =+[5]제주!$H$92/1000 -> 74.468017 | S24: =+P24-R24 -> -76.502303 | T24: =+[15]제주!$H$86/1000 -> 207.57528 | U24: =+[15]제주!$I$86/1000 -> 46.803205 | V24: =+U24-T24 -> -160.77208 | W24: =+[16]제주!$H$86/1000 -> 355.76526 | X24: =+U24-W24 -> -308.96206 | Y24: =+[15]제주!$H$92/1000 -> 21.294573 | Z24: =+[15]제주!$I$92/1000 -> -86.463755 | AA24: =+Z24-Y24 -> -107.75833 | AB24: =+[16]제주!$H$92/1000 -> 167.19777 | AC24: =+Z24-AB24 -> -253.66153
I25: 수도권 | J25: =SUM(J8:J11) -> 948.83207 | K25: =SUM(K8:K11) -> 719.5624 | L25: =+K25-J25 -> -229.26967 | M25: =SUM(M8:M11) -> 593.23161 | N25: =+K25-M25 -> 126.33079 | O25: =SUM(O8:O11) -> 336.23977 | P25: =SUM(P8:P11) -> 57.884094 | Q25: =+P25-O25 -> -278.35568 | R25: =SUM(R8:R11) -> 22.798359 | S25: =+P25-R25 -> 35.085735 | T25: =SUM(T8:T11) -> 1557.7925 | U25: =SUM(U8:U11) -> 869.31396 | V25: =+U25-T25 -> -688.47857 | W25: =SUM(W8:W11) -> 645.89535 | X25: =+U25-W25 -> 223.41861 | Y25: =SUM(Y8:Y11) -> -651.16846 | Z25: =SUM(Z8:Z11) -> -1487.6864 | AA25: =+Z25-Y25 -> -836.51799 | AB25: =SUM(AB8:AB11) -> -1289.4244 | AC25: =+Z25-AB25 -> -198.26203
I26: 영남권 | J26: =SUM(J12:J19) -> 1312.4078 | K26: =SUM(K12:K19) -> 645.96462 | L26: =+K26-J26 -> -666.44321 | M26: =SUM(M12:M19) -> 851.16723 | N26: =+K26-M26 -> -205.20262 | O26: =SUM(O12:O19) -> 580.44254 | P26: =SUM(P12:P19) -> -24.093052 | Q26: =+P26-O26 -> -604.5356 | R26: =SUM(R12:R19) -> 113.81758 | S26: =+P26-R26 -> -137.91064 | T26: =SUM(T12:T19) -> 2504.1529 | U26: =SUM(U12:U19) -> 1501.4398 | V26: =+U26-T26 -> -1002.7131 | W26: =SUM(W12:W19) -> 2466.0915 | X26: =+U26-W26 -> -964.65172 | Y26: =SUM(Y12:Y19) -> -301.15381 | Z26: =SUM(Z12:Z19) -> -1173.5654 | AA26: =+Z26-Y26 -> -872.41162 | AB26: =SUM(AB12:AB19) -> -259.47918 | AC26: =+Z26-AB26 -> -914.08625
I27: 중부권 | J27: =SUM(J20:J24) -> 599.06154 | K27: =SUM(K20:K24) -> 424.40506 | L27: =+K27-J27 -> -174.65648 | M27: =SUM(M20:M24) -> 721.27004 | N27: =+K27-M27 -> -296.86498 | O27: =SUM(O20:O24) -> 300.08515 | P27: =SUM(P20:P24) -> 110.50599 | Q27: =+P27-O27 -> -189.57915 | R27: =SUM(R20:R24) -> 374.15445 | S27: =+P27-R27 -> -263.64846 | T27: =SUM(T20:T24) -> 895.20462 | U27: =SUM(U20:U24) -> 700.7938 | V27: =+U27-T27 -> -194.41082 | W27: =SUM(W20:W24) -> 1711.6796 | X27: =+U27-W27 -> -1010.8858 | Y27: =SUM(Y20:Y24) -> -91.488455 | Z27: =SUM(Z20:Z24) -> -421.48336 | AA27: =+Z27-Y27 -> -329.9949 | AB27: =SUM(AB20:AB24) -> 464.83905 | AC27: =+Z27-AB27 -> -886.32241
H28: 레미콘 계 | J28: =SUM(J25:J27) -> 2860.3014 | K28: =SUM(K25:K27) -> 1789.9321 | L28: =+K28-J28 -> -1070.3694 | M28: =SUM(M25:M27) -> 2165.6689 | N28: =+K28-M28 -> -375.73681 | O28: =SUM(O25:O27) -> 1216.7675 | P28: =SUM(P25:P27) -> 144.29704 | Q28: =+P28-O28 -> -1072.4704 | R28: =SUM(R25:R27) -> 510.7704 | S28: =+P28-R28 -> -366.47336 | T28: =SUM(T25:T27) -> 4957.1501 | U28: =SUM(U25:U27) -> 3071.5475 | V28: =+U28-T28 -> -1885.6025 | W28: =SUM(W25:W27) -> 4823.6665 | X28: =+U28-W28 -> -1752.119 | Y28: =SUM(Y25:Y27) -> -1043.8107 | Z28: =SUM(Z25:Z27) -> -3082.7352 | AA28: =+Z28-Y28 -> -2038.9245 | AB28: =SUM(AB25:AB27) -> -1084.0645 | AC28: =+Z28-AB28 -> -1998.6707

Sheet 사업장별(당월)
H3: □ 사업장별 손익실적(2026-04)
AG4: [단위 : 천㎥, 톤, 백만원]
H5: 구분 | J5: 물량 | O5: 매출 | T5: 영업이익(공통비 배부전) | Y5: 판매단가 | AB5: 변동비 | AE5: 공헌이익 | AI5: 판매비중
A6: 2024년 4월 마감 손익 | J6: 계획 | K6: 실적 | L6: 차이 | M6: 전년 | N6: 차이 | O6: 계획 | P6: 실적 | Q6: 차이 | R6: 전년 | S6: 차이 | T6: 계획 | U6: 실적 | V6: 차이 | W6: 전년 | X6: 차이 | Y6: 계획 | Z6: 실적 | AA6: 전년 | AB6: 계획 | AC6: 실적 | AD6: 전년 | AE6: 계획 | AF6: 실적 | AG6: 전년 | AI6: 공장명 | AJ6: 계획 | AK6: 추정 | AL6: 차이 | AO6: 전월 | AP6: 차이
B7: 안양 | G7: =+I7 -> 안양 | H7: 레미콘 | I7: 안양 | J7: =+IFERROR(HLOOKUP($B7,'[1]4월'!$D$6:$BN$259,2,),)/1000 -> 40 | K7: =+IFERROR(HLOOKUP($B7,'[2]4월'!$F$6:$CP$99,2,),)/1000 -> 42.104 | L7: =+K7-J7 -> 2.104 | M7: =+IFERROR(HLOOKUP($B7,'[3]4월'!$F$6:$CC$57,2,),)/1000 -> 40.25 | N7: =+K7-M7 -> 1.854 | O7: =+IFERROR(HLOOKUP($B7,'[1]4월'!$D$6:$BN$259,3,),)/1000 -> 3918.2744 | P7: =+IFERROR(HLOOKUP($B7,'[2]4월'!$F$6:$CP$99,3,),)/1000 -> 4092.8851 | Q7: =+P7-O7 -> 174.61068 | R7: =+IFERROR(HLOOKUP($B7,'[3]4월'!$F$6:$CC$57,3,),)/1000 -> 3841.7711 | S7: =+P7-R7 -> 251.11395 | T7: =+IFERROR(HLOOKUP($B7,'[1]4월'!$D$6:$BN$259,16,),)/1000 -> 492.29041 | U7: =+IFERROR(HLOOKUP($B7,'[2]4월'!$F$6:$CP$99,16,),)/1000 -> 358.71954 | V7: =+U7-T7 -> -133.57087 | W7: =+IFERROR(HLOOKUP($B7,'[3]4월'!$F$6:$CC$57,16,),)/1000 -> 321.01658 | X7: =+U7-W7 -> 37.70296 | Y7: =+[4]안양!$Q$85 -> 97956.859 | Z7: =+[4]안양!$R$85 -> 97182.938 | AA7: =+[5]안양!$Q$85 -> 95439.9 | AB7: =+[4]안양!$Q$89 -> 77811.025 | AC7: =+[4]안양!$R$89 -> 80916.611 | AD7: =+[5]안양!$Q$89 -> 79659.206 | AE7: =+Y7-AB7 -> 20145.835 | AF7: =+Z7-AC7 -> 16266.327 | AG7: =+AA7-AD7 -> 15780.694 | AI7: =+I7 -> 안양 | AJ7: =+J7/$J$27 -> 0.14705882 | AK7: =+K7/$K$27 -> 0.15425649 | AL7: =+AK7-AJ7 -> 0.0071976649 | AM7: =+Y7*AL7 -> 705.06065 | AO7: =+[17]안양!$T$5/[17]합계!$T$5 -> 0.17712998 | AP7: =+AK7-AO7 -> -0.022873491 | AQ7: =+[17]안양!$Q$85*AP7 -> -2275.9181
B8: 인천 | G8: =+I8 -> 인천 | H8: 직영 | I8: 인천 | J8: =+IFERROR(HLOOKUP($B8,'[1]4월'!$D$6:$BN$259,2,),)/1000 -> 35 | K8: =+IFERROR(HLOOKUP($B8,'[2]4월'!$F$6:$CP$99,2,),)/1000 -> 35.4185 | L8: =+K8-J8 -> 0.4185 | M8: =+IFERROR(HLOOKUP($B8,'[3]4월'!$F$6:$CC$57,2,),)/1000 -> 33.57 | N8: =+K8-M8 -> 1.8485 | O8: =+IFERROR(HLOOKUP($B8,'[1]4월'!$D$6:$BN$259,3,),)/1000 -> 3494.0569 | P8: =+IFERROR(HLOOKUP($B8,'[2]4월'!$F$6:$CP$99,3,),)/1000 -> 3527.9179 | Q8: =+P8-O8 -> 33.860949 | R8: =+IFERROR(HLOOKUP($B8,'[3]4월'!$F$6:$CC$57,3,),)/1000 -> 3322.1847 | S8: =+P8-R8 -> 205.73312 | T8: =+IFERROR(HLOOKUP($B8,'[1]4월'!$D$6:$BN$259,16,),)/1000 -> 290.24791 | U8: =+IFERROR(HLOOKUP($B8,'[2]4월'!$F$6:$CP$99,16,),)/1000 -> 121.58991 | V8: =+U8-T8 -> -168.658 | W8: =+IFERROR(HLOOKUP($B8,'[3]4월'!$F$6:$CC$57,16,),)/1000 -> 222.53657 | X8: =+U8-W8 -> -100.94666 | Y8: =+[4]인천!$Q$85 -> 99830.197 | Z8: =+[4]인천!$R$85 -> 99671.436 | AA8: =+[5]인천!$Q$85 -> 98978.103 | AB8: =+[4]인천!$Q$89 -> 82171.29 | AC8: =+[4]인천!$R$89 -> 86956.36 | AD8: =+[5]인천!$Q$89 -> 82750.98 | AE8: =+Y8-AB8 -> 17658.908 | AF8: =+Z8-AC8 -> 12715.076 | AG8: =+AA8-AD8 -> 16227.123 | AI8: =+I8 -> 인천 | AJ8: =+J8/$J$27 -> 0.12867647 | AK8: =+K8/$K$27 -> 0.12976281 | AL8: =+AK8-AJ8 -> 0.0010863414 | AM8: =+Y8*AL8 -> 108.44967 | AO8: =+[17]인천!$T$5/[17]합계!$T$5 -> 0.13298178 | AP8: =+AK8-AO8 -> -0.0032189697 | AQ8: =+[17]인천!$Q$85*AP8 -> -322.21321
B9: 파주 | G9: =+I9 -> 파주 | I9: 파주 | J9: =+IFERROR(HLOOKUP($B9,'[1]4월'!$D$6:$BN$259,2,),)/1000 -> 17 | K9: =+IFERROR(HLOOKUP($B9,'[2]4월'!$F$6:$CP$99,2,),)/1000 -> 19.506 | L9: =+K9-J9 -> 2.506 | M9: =+IFERROR(HLOOKUP($B9,'[3]4월'!$F$6:$CC$57,2,),)/1000 -> 13.605 | N9: =+K9-M9 -> 5.901 | O9: =+IFERROR(HLOOKUP($B9,'[1]4월'!$D$6:$BN$259,3,),)/1000 -> 1678.0678 | P9: =+IFERROR(HLOOKUP($B9,'[2]4월'!$F$6:$CP$99,3,),)/1000 -> 1955.169 | Q9: =+P9-O9 -> 277.10123 | R9: =+IFERROR(HLOOKUP($B9,'[3]4월'!$F$6:$CC$57,3,),)/1000 -> 1269.8888 | S9: =+P9-R9 -> 685.2802 | T9: =+IFERROR(HLOOKUP($B9,'[1]4월'!$D$6:$BN$259,16,),)/1000 -> 74.264373 | U9: =+IFERROR(HLOOKUP($B9,'[2]4월'!$F$6:$CP$99,16,),)/1000 -> 129.07579 | V9: =+U9-T9 -> 54.81142 | W9: =+IFERROR(HLOOKUP($B9,'[3]4월'!$F$6:$CC$57,16,),)/1000 -> -15.154132 | X9: =+U9-W9 -> 144.22993 | Y9: =+[4]파주!$Q$85 -> 98709.869 | Z9: =+[4]파주!$R$85 -> 100911.58 | AA9: =+[5]파주!$Q$85 -> 93525.185 | AB9: =+[4]파주!$Q$89 -> 81229.59 | AC9: =+[4]파주!$R$89 -> 81797.705 | AD9: =+[5]파주!$Q$89 -> 78035.926 | AE9: =+Y9-AB9 -> 17480.279 | AF9: =+Z9-AC9 -> 19113.875 | AG9: =+AA9-AD9 -> 15489.259 | AI9: =+I9 -> 파주 | AJ9: =+J9/$J$27 -> 0.0625 | AK9: =+K9/$K$27 -> 0.071464162 | AL9: =+AK9-AJ9 -> 0.0089641617 | AM9: =+Y9*AL9 -> 884.85122 | AO9: =+[17]파주!$T$5/[17]합계!$T$5 -> 0.047046085 | AP9: =+AK9-AO9 -> 0.024418077 | AQ9: =+[17]파주!$Q$85*AP9 -> 2389.5155
B10: 김포 | G10: =+I10 -> 김포 | I10: 김포 | J10: =+IFERROR(HLOOKUP($B10,'[1]4월'!$D$6:$BN$259,2,),)/1000 -> 15 | K10: =+IFERROR(HLOOKUP($B10,'[2]4월'!$F$6:$CP$99,2,),)/1000 -> 17.667 | L10: =+K10-J10 -> 2.667 | M10: =+IFERROR(HLOOKUP($B10,'[3]4월'!$F$6:$CC$57,2,),)/1000 -> 12.327 | N10: =+K10-M10 -> 5.34 | O10: =+IFERROR(HLOOKUP($B10,'[1]4월'!$D$6:$BN$259,3,),)/1000 -> 1451.6793 | P10: =+IFERROR(HLOOKUP($B10,'[2]4월'!$F$6:$CP$99,3,),)/1000 -> 1742.5827 | Q10: =+P10-O10 -> 290.90337 | R10: =+IFERROR(HLOOKUP($B10,'[3]4월'!$F$6:$CC$57,3,),)/1000 -> 1182.47 | S10: =+P10-R10 -> 560.11269 | T10: =+IFERROR(HLOOKUP($B10,'[1]4월'!$D$6:$BN$259,16,),)/1000 -> 92.029372 | U10: =+IFERROR(HLOOKUP($B10,'[2]4월'!$F$6:$CP$99,16,),)/1000 -> 110.17716 | V10: =+U10-T10 -> 18.147787 | W10: =+IFERROR(HLOOKUP($B10,'[3]4월'!$F$6:$CC$57,16,),)/1000 -> 64.83259 | X10: =+U10-W10 -> 45.344569 | Y10: =+[4]김포!$Q$85 -> 96778.619 | Z10: =+[4]김포!$R$85 -> 98832.579 | AA10: =+[5]김포!$Q$85 -> 96085.257 | AB10: =+[4]김포!$Q$89 -> 77986.462 | AC10: =+[4]김포!$R$89 -> 80880.656 | AD10: =+[5]김포!$Q$89 -> 76364.794 | AE10: =+Y10-AB10 -> 18792.158 | AF10: =+Z10-AC10 -> 17951.923 | AG10: =+AA10-AD10 -> 19720.464 | AI10: =+I10 -> 김포 | AJ10: =+J10/$J$27 -> 0.055147059 | AK10: =+K10/$K$27 -> 0.064726615 | AL10: =+AK10-AJ10 -> 0.0095795558 | AM10: =+Y10*AL10 -> 927.09618 | AO10: =+[17]김포!$T$5/[17]합계!$T$5 -> 0.059378371 | AP10: =+AK10-AO10 -> 0.005348244 | AQ10: =+[17]김포!$Q$85*AP10 -> 507.88659
B11: 부산 | G11: =+I11 -> 부산 | I11: 부산 | J11: =+IFERROR(HLOOKUP($B11,'[1]4월'!$D$6:$BN$259,2,),)/1000 -> 20 | K11: =+IFERROR(HLOOKUP($B11,'[2]4월'!$F$6:$CP$99,2,),)/1000 -> 20.768 | L11: =+K11-J11 -> 0.768 | M11: =+IFERROR(HLOOKUP($B11,'[3]4월'!$F$6:$CC$57,2,),)/1000 -> 20.499 | N11: =+K11-M11 -> 0.269 | O11: =+IFERROR(HLOOKUP($B11,'[1]4월'!$D$6:$BN$259,3,),)/1000 -> 2166.0578 | P11: =+IFERROR(HLOOKUP($B11,'[2]4월'!$F$6:$CP$99,3,),)/1000 -> 2394.694 | Q11: =+P11-O11 -> 228.63619 | R11: =+IFERROR(HLOOKUP($B11,'[3]4월'!$F$6:$CC$57,3,),)/1000 -> 2136.8245 | S11: =+P11-R11 -> 257.8695 | T11: =+IFERROR(HLOOKUP($B11,'[1]4월'!$D$6:$BN$259,16,),)/1000 -> 229.16261 | U11: =+IFERROR(HLOOKUP($B11,'[2]4월'!$F$6:$CP$99,16,),)/1000 -> 200.10526 | V11: =+U11-T11 -> -29.057352 | W11: =+IFERROR(HLOOKUP($B11,'[3]4월'!$F$6:$CC$57,16,),)/1000 -> 112.51179 | X11: =+U11-W11 -> 87.593469 | Y11: =+[4]부산!$Q$85 -> 108302.89 | Z11: =+[4]부산!$R$85 -> 115306.91 | AA11: =+[5]부산!$Q$85 -> 104240.43 | AB11: =+[4]부산!$Q$89 -> 83382.209 | AC11: =+[4]부산!$R$89 -> 91984.368 | AD11: =+[5]부산!$Q$89 -> 86169.896 | AE11: =+Y11-AB11 -> 24920.681 | AF11: =+Z11-AC11 -> 23322.546 | AG11: =+AA11-AD11 -> 18070.53 | AI11: =+I11 -> 부산 | AJ11: =+J11/$J$27 -> 0.073529412 | AK11: =+K11/$K$27 -> 0.076087753 | AL11: =+AK11-AJ11 -> 0.0025583412 | AM11: =+Y11*AL11 -> 277.07575 | AO11: =+[17]부산!$T$5/[17]합계!$T$5 -> 0.091225758 | AP11: =+AK11-AO11 -> -0.015138005 | AQ11: =+[17]부산!$Q$85*AP11 -> -1804.5497
B12: 서부산 | G12: =+I12 -> 서부산 | I12: 서부산 | J12: =+IFERROR(HLOOKUP($B12,'[1]4월'!$D$6:$BN$259,2,),)/1000 -> 21 | K12: =+IFERROR(HLOOKUP($B12,'[2]4월'!$F$6:$CP$99,2,),)/1000 -> 22.096 | L12: =+K12-J12 -> 1.096 | M12: =+IFERROR(HLOOKUP($B12,'[3]4월'!$F$6:$CC$57,2,),)/1000 -> 19.392 | N12: =+K12-M12 -> 2.704 | O12: =+IFERROR(HLOOKUP($B12,'[1]4월'!$D$6:$BN$259,3,),)/1000 -> 2184.1163 | P12: =+IFERROR(HLOOKUP($B12,'[2]4월'!$F$6:$CP$99,3,),)/1000 -> 2230.4985 | Q12: =+P12-O12 -> 46.382183 | R12: =+IFERROR(HLOOKUP($B12,'[3]4월'!$F$6:$CC$57,3,),)/1000 -> 1895.2186 | S12: =+P12-R12 -> 335.2799 | T12: =+IFERROR(HLOOKUP($B12,'[1]4월'!$D$6:$BN$259,16,),)/1000 -> 350.38968 | U12: =+IFERROR(HLOOKUP($B12,'[2]4월'!$F$6:$CP$99,16,),)/1000 -> 165.79219 | V12: =+U12-T12 -> -184.59749 | W12: =+IFERROR(HLOOKUP($B12,'[3]4월'!$F$6:$CC$57,16,),)/1000 -> 155.86617 | X12: =+U12-W12 -> 9.926026 | Y12: =+[4]서부산!$Q$85 -> 104005.54 | Z12: =+[4]서부산!$R$85 -> 100945.8 | AA12: =+[5]서부산!$Q$85 -> 97731.982 | AB12: =+[4]서부산!$Q$89 -> 76690.929 | AC12: =+[4]서부산!$R$89 -> 81435.024 | AD12: =+[5]서부산!$Q$89 -> 77327.458 | AE12: =+Y12-AB12 -> 27314.61 | AF12: =+Z12-AC12 -> 19510.78 | AG12: =+AA12-AD12 -> 20404.524 | AI12: =+I12 -> 서부산 | AJ12: =+J12/$J$27 -> 0.077205882 | AK12: =+K12/$K$27 -> 0.080953149 | AL12: =+AK12-AJ12 -> 0.0037472662 | AM12: =+Y12*AL12 -> 389.73644 | AO12: =+[17]서부산!$T$5/[17]합계!$T$5 -> 0.084170944 | AP12: =+AK12-AO12 -> -0.0032177953 | AQ12: =+[17]서부산!$Q$85*AP12 -> -329.73732
B13: 김해 | G13: =+I13 -> 김해 | I13: 김해 | J13: =+IFERROR(HLOOKUP($B13,'[1]4월'!$D$6:$BN$259,2,),)/1000 -> 10 | K13: =+IFERROR(HLOOKUP($B13,'[2]4월'!$F$6:$CP$99,2,),)/1000 -> 6.351 | L13: =+K13-J13 -> -3.649 | M13: =+IFERROR(HLOOKUP($B13,'[3]4월'!$F$6:$CC$57,2,),)/1000 -> 11.975 | N13: =+K13-M13 -> -5.624 | O13: =+IFERROR(HLOOKUP($B13,'[1]4월'!$D$6:$BN$259,3,),)/1000 -> 1012.9338 | P13: =+IFERROR(HLOOKUP($B13,'[2]4월'!$F$6:$CP$99,3,),)/1000 -> 625.0312 | Q13: =+P13-O13 -> -387.90261 | R13: =+IFERROR(HLOOKUP($B13,'[3]4월'!$F$6:$CC$57,3,),)/1000 -> 1030.4699 | S13: =+P13-R13 -> -405.4387 | T13: =+IFERROR(HLOOKUP($B13,'[1]4월'!$D$6:$BN$259,16,),)/1000 -> 79.709608 | U13: =+IFERROR(HLOOKUP($B13,'[2]4월'!$F$6:$CP$99,16,),)/1000 -> -7.402545 | V13: =+U13-T13 -> -87.112153 | W13: =+IFERROR(HLOOKUP($B13,'[3]4월'!$F$6:$CC$57,16,),)/1000 -> -22.904841 | X13: =+U13-W13 -> 15.502296 | Y13: =+[4]김해!$Q$85 -> 101293.38 | Z13: =+[4]김해!$R$85 -> 98414.612 | AA13: =+[5]김해!$Q$85 -> 86017.766 | AB13: =+[4]김해!$Q$89 -> 77893.197 | AC13: =+[4]김해!$R$89 -> 77229.786 | AD13: =+[5]김해!$Q$89 -> 75417.831 | AE13: =+Y13-AB13 -> 23400.184 | AF13: =+Z13-AC13 -> 21184.826 | AG13: =+AA13-AD13 -> 10599.936 | AI13: =+I13 -> 김해 | AJ13: =+J13/$J$27 -> 0.036764706 | AK13: =+K13/$K$27 -> 0.023268168 | AL13: =+AK13-AJ13 -> -0.013496538 | AM13: =+Y13*AL13 -> -1367.1099 | AO13: =+[17]김해!$T$5/[17]합계!$T$5 -> 0.030433067 | AP13: =+AK13-AO13 -> -0.0071648991 | AQ13: =+[17]김해!$Q$85*AP13 -> -716.40677
B14: 정관 | G14: =+I14 -> 정관 | I14: 정관 | J14: =+IFERROR(HLOOKUP($B14,'[1]4월'!$D$6:$BN$259,2,),)/1000 -> 22 | K14: =+IFERROR(HLOOKUP($B14,'[2]4월'!$F$6:$CP$99,2,),)/1000 -> 18.285 | L14: =+K14-J14 -> -3.715 | M14: =+IFERROR(HLOOKUP($B14,'[3]4월'!$F$6:$CC$57,2,),)/1000 -> 23.6285 | N14: =+K14-M14 -> -5.3435 | O14: =+IFERROR(HLOOKUP($B14,'[1]4월'!$D$6:$BN$259,3,),)/1000 -> 2334.3779 | P14: =+IFERROR(HLOOKUP($B14,'[2]4월'!$F$6:$CP$99,3,),)/1000 -> 1879.0172 | Q14: =+P14-O14 -> -455.36065 | R14: =+IFERROR(HLOOKUP($B14,'[3]4월'!$F$6:$CC$57,3,),)/1000 -> 2450.8407 | S14: =+P14-R14 -> -571.8235 | T14: =+IFERROR(HLOOKUP($B14,'[1]4월'!$D$6:$BN$259,16,),)/1000 -> 322.85639 | U14: =+IFERROR(HLOOKUP($B14,'[2]4월'!$F$6:$CP$99,16,),)/1000 -> 160.08659 | V14: =+U14-T14 -> -162.7698 | W14: =+IFERROR(HLOOKUP($B14,'[3]4월'!$F$6:$CC$57,16,),)/1000 -> 280.09121 | X14: =+U14-W14 -> -120.00463 | Y14: =+[4]정관!$Q$85 -> 106108.08 | Z14: =+[4]정관!$R$85 -> 102762.77 | AA14: =+[5]정관!$Q$85 -> 103723.92 | AB14: =+[4]정관!$Q$89 -> 80924.319 | AC14: =+[4]정관!$R$89 -> 81626.34 | AD14: =+[5]정관!$Q$89 -> 83859.793 | AE14: =+Y14-AB14 -> 25183.765 | AF14: =+Z14-AC14 -> 21136.427 | AG14: =+AA14-AD14 -> 19864.129 | AI14: =+I14 -> 정관 | AJ14: =+J14/$J$27 -> 0.080882353 | AK14: =+K14/$K$27 -> 0.066990782 | AL14: =+AK14-AJ14 -> -0.013891571 | AM14: =+Y14*AL14 -> -1474.008 | AO14: =+[17]정관!$T$5/[17]합계!$T$5 -> 0.054151261 | AP14: =+AK14-AO14 -> 0.012839521 | AQ14: =+[17]정관!$Q$85*AP14 -> 1385.6376
B15: 양산 | G15: =+I15 -> 양산 | I15: 양산 | J15: =+IFERROR(HLOOKUP($B15,'[1]4월'!$D$6:$BN$259,2,),)/1000 -> 10 | K15: =+IFERROR(HLOOKUP($B15,'[2]4월'!$F$6:$CP$99,2,),)/1000 -> 7.209 | L15: =+K15-J15 -> -2.791 | M15: =+IFERROR(HLOOKUP($B15,'[3]4월'!$F$6:$CC$57,2,),)/1000 -> 6.277 | N15: =+K15-M15 -> 0.932 | O15: =+IFERROR(HLOOKUP($B15,'[1]4월'!$D$6:$BN$259,3,),)/1000 -> 1008.1011 | P15: =+IFERROR(HLOOKUP($B15,'[2]4월'!$F$6:$CP$99,3,),)/1000 -> 709.8389 | Q15: =+P15-O15 -> -298.26219 | R15: =+IFERROR(HLOOKUP($B15,'[3]4월'!$F$6:$CC$57,3,),)/1000 -> 579.56165 | S15: =+P15-R15 -> 130.27725 | T15: =+IFERROR(HLOOKUP($B15,'[1]4월'!$D$6:$BN$259,16,),)/1000 -> 116.98911 | U15: =+IFERROR(HLOOKUP($B15,'[2]4월'!$F$6:$CP$99,16,),)/1000 -> 18.913598 | V15: =+U15-T15 -> -98.075508 | W15: =+IFERROR(HLOOKUP($B15,'[3]4월'!$F$6:$CC$57,16,),)/1000 -> -26.417206 | X15: =+U15-W15 -> 45.330804 | Y15: =+[4]양산!$Q$85 -> 100810.11 | Z15: =+[4]양산!$R$85 -> 98465.654 | AA15: =+[5]양산!$Q$85 -> 92330.994 | AB15: =+[4]양산!$Q$89 -> 74915.738 | AC15: =+[4]양산!$R$89 -> 76673.599 | AD15: =+[5]양산!$Q$89 -> 72880.116 | AE15: =+Y15-AB15 -> 25894.371 | AF15: =+Z15-AC15 -> 21792.055 | AG15: =+AA15-AD15 -> 19450.879 | AI15: =+I15 -> 양산 | AJ15: =+J15/$J$27 -> 0.036764706 | AK15: =+K15/$K$27 -> 0.026411624 | AL15: =+AK15-AJ15 -> -0.010353082 | AM15: =+Y15*AL15 -> -1043.6953 | AO15: =+[17]양산!$T$5/[17]합계!$T$5 -> 0.020027111 | AP15: =+AK15-AO15 -> 0.0063845129 | AQ15: =+[17]양산!$Q$85*AP15 -> 674.75658
B16: 창원 | G16: =+I16 -> 창원 | I16: 창원 | J16: =+IFERROR(HLOOKUP($B16,'[1]4월'!$D$6:$BN$259,2,),)/1000 -> 13 | K16: =+IFERROR(HLOOKUP($B16,'[2]4월'!$F$6:$CP$99,2,),)/1000 -> 11.571 | L16: =+K16-J16 -> -1.429 | M16: =+IFERROR(HLOOKUP($B16,'[3]4월'!$F$6:$CC$57,2,),)/1000 -> 12.462 | N16: =+K16-M16 -> -0.891 | O16: =+IFERROR(HLOOKUP($B16,'[1]4월'!$D$6:$BN$259,3,),)/1000 -> 1265.9629 | P16: =+IFERROR(HLOOKUP($B16,'[2]4월'!$F$6:$CP$99,3,),)/1000 -> 1083.6986 | Q16: =+P16-O16 -> -182.2643 | R16: =+IFERROR(HLOOKUP($B16,'[3]4월'!$F$6:$CC$57,3,),)/1000 -> 1202.3307 | S16: =+P16-R16 -> -118.6321 | T16: =+IFERROR(HLOOKUP($B16,'[1]4월'!$D$6:$BN$259,16,),)/1000 -> 98.886576 | U16: =+IFERROR(HLOOKUP($B16,'[2]4월'!$F$6:$CP$99,16,),)/1000 -> 73.953798 | V16: =+U16-T16 -> -24.932778 | W16: =+IFERROR(HLOOKUP($B16,'[3]4월'!$F$6:$CC$57,16,),)/1000 -> 126.42044 | X16: =+U16-W16 -> -52.466639 | Y16: =+[4]창원!$Q$85 -> 97381.761 | Z16: =+[4]창원!$R$85 -> 93656.434 | AA16: =+[5]창원!$Q$85 -> 96479.754 | AB16: =+[4]창원!$Q$89 -> 76890.343 | AC16: =+[4]창원!$R$89 -> 72300.838 | AD16: =+[5]창원!$Q$89 -> 72322.007 | AE16: =+Y16-AB16 -> 20491.419 | AF16: =+Z16-AC16 -> 21355.597 | AG16: =+AA16-AD16 -> 24157.748 | AI16: =+I16 -> 창원 | AJ16: =+J16/$J$27 -> 0.047794118 | AK16: =+K16/$K$27 -> 0.04239269 | AL16: =+AK16-AJ16 -> -0.0054014275 | AM16: =+Y16*AL16 -> -526.00052 | AO16: =+[17]창원!$T$5/[17]합계!$T$5 -> 0.036293893 | AP16: =+AK16-AO16 -> 0.0060987969 | AQ16: =+[17]창원!$Q$85*AP16 -> 600.43319
B17: 대구 | G17: =+I17 -> 대구 | I17: 대구 | J17: =+IFERROR(HLOOKUP($B17,'[1]4월'!$D$6:$BN$259,2,),)/1000 -> 8.5 | K17: =+IFERROR(HLOOKUP($B17,'[2]4월'!$F$6:$CP$99,2,),)/1000 -> 5.7135 | L17: =+K17-J17 -> -2.7865 | M17: =+IFERROR(HLOOKUP($B17,'[3]4월'!$F$6:$CC$57,2,),)/1000 -> 11.7315 | N17: =+K17-M17 -> -6.018 | O17: =+IFERROR(HLOOKUP($B17,'[1]4월'!$D$6:$BN$259,3,),)/1000 -> 767.39446 | P17: =+IFERROR(HLOOKUP($B17,'[2]4월'!$F$6:$CP$99,3,),)/1000 -> 443.31325 | Q17: =+P17-O17 -> -324.08122 | R17: =+IFERROR(HLOOKUP($B17,'[3]4월'!$F$6:$CC$57,3,),)/1000 -> 1058.2244 | S17: =+P17-R17 -> -614.9112 | T17: =+IFERROR(HLOOKUP($B17,'[1]4월'!$D$6:$BN$259,16,),)/1000 -> 19.577609 | U17: =+IFERROR(HLOOKUP($B17,'[2]4월'!$F$6:$CP$99,16,),)/1000 -> -79.863768 | V17: =+U17-T17 -> -99.441377 | W17: =+IFERROR(HLOOKUP($B17,'[3]4월'!$F$6:$CC$57,16,),)/1000 -> 50.698716 | X17: =+U17-W17 -> -130.56248 | Y17: =+[4]대구!$Q$85 -> 90281.702 | Z17: =+[4]대구!$R$85 -> 77590.487 | AA17: =+[5]대구!$Q$85 -> 90203.678 | AB17: =+[4]대구!$Q$89 -> 70982.512 | AC17: =+[4]대구!$R$89 -> 68045.817 | AD17: =+[5]대구!$Q$89 -> 72248.873 | AE17: =+Y17-AB17 -> 19299.189 | AF17: =+Z17-AC17 -> 9544.6702 | AG17: =+AA17-AD17 -> 17954.805 | AI17: =+I17 -> 대구 | AJ17: =+J17/$J$27 -> 0.03125 | AK17: =+K17/$K$27 -> 0.020932559 | AL17: =+AK17-AJ17 -> -0.010317441 | AM17: =+Y17*AL17 -> -931.47617 | AO17: =+[17]대구!$T$5/[17]합계!$T$5 -> 0.013289155 | AP17: =+AK17-AO17 -> 0.0076434035 | AQ17: =+[17]대구!$Q$85*AP17 -> 649.80512
B18: 울산 | G18: =+I18 -> 울산 | I18: 울산 | J18: =+IFERROR(HLOOKUP($B18,'[1]4월'!$D$6:$BN$259,2,),)/1000 -> 11.5 | K18: =+IFERROR(HLOOKUP($B18,'[2]4월'!$F$6:$CP$99,2,),)/1000 -> 14.457 | L18: =+K18-J18 -> 2.957 | M18: =+IFERROR(HLOOKUP($B18,'[3]4월'!$F$6:$CC$57,2,),)/1000 -> 13.906 | N18: =+K18-M18 -> 0.551 | O18: =+IFERROR(HLOOKUP($B18,'[1]4월'!$D$6:$BN$259,3,),)/1000 -> 1195.4544 | P18: =+IFERROR(HLOOKUP($B18,'[2]4월'!$F$6:$CP$99,3,),)/1000 -> 1468.2855 | Q18: =+P18-O18 -> 272.83111 | R18: =+IFERROR(HLOOKUP($B18,'[3]4월'!$F$6:$CC$57,3,),)/1000 -> 1439.8668 | S18: =+P18-R18 -> 28.4187 | T18: =+IFERROR(HLOOKUP($B18,'[1]4월'!$D$6:$BN$259,16,),)/1000 -> 94.836244 | U18: =+IFERROR(HLOOKUP($B18,'[2]4월'!$F$6:$CP$99,16,),)/1000 -> 114.37949 | V18: =+U18-T18 -> 19.543248 | W18: =+IFERROR(HLOOKUP($B18,'[3]4월'!$F$6:$CC$57,16,),)/1000 -> 174.90096 | X18: =+U18-W18 -> -60.521464 | Y18: =+[4]울산!$Q$85 -> 103952.56 | Z18: =+[4]울산!$R$85 -> 101562.25 | AA18: =+[5]울산!$Q$85 -> 103542.84 | AB18: =+[4]울산!$Q$89 -> 82491.081 | AC18: =+[4]울산!$R$89 -> 81917.157 | AD18: =+[5]울산!$Q$89 -> 80692.96 | AE18: =+Y18-AB18 -> 21461.475 | AF18: =+Z18-AC18 -> 19645.097 | AG18: =+AA18-AD18 -> 22849.885 | AI18: =+I18 -> 울산 | AJ18: =+J18/$J$27 -> 0.042279412 | AK18: =+K18/$K$27 -> 0.052966133 | AL18: =+AK18-AJ18 -> 0.010686721 | AM18: =+Y18*AL18 -> 1110.912 | AO18: =+[17]울산!$T$5/[17]합계!$T$5 -> 0.050197879 | AP18: =+AK18-AO18 -> 0.0027682538 | AQ18: =+[17]울산!$Q$85*AP18 -> 289.76792
B19: 아산 | G19: =+I19 -> 아산 | I19: 아산 | J19: =+IFERROR(HLOOKUP($B19,'[1]4월'!$D$6:$BN$259,2,),)/1000 -> 23 | K19: =+IFERROR(HLOOKUP($B19,'[2]4월'!$F$6:$CP$99,2,),)/1000 -> 24.258 | L19: =+K19-J19 -> 1.258 | M19: =+IFERROR(HLOOKUP($B19,'[3]4월'!$F$6:$CC$57,2,),)/1000 -> 23.173 | N19: =+K19-M19 -> 1.085 | O19: =+IFERROR(HLOOKUP($B19,'[1]4월'!$D$6:$BN$259,3,),)/1000 -> 2281.5794 | P19: =+IFERROR(HLOOKUP($B19,'[2]4월'!$F$6:$CP$99,3,),)/1000 -> 2423.597 | Q19: =+P19-O19 -> 142.01756 | R19: =+IFERROR(HLOOKUP($B19,'[3]4월'!$F$6:$CC$57,3,),)/1000 -> 2210.5821 | S19: =+P19-R19 -> 213.01493 | T19: =+IFERROR(HLOOKUP($B19,'[1]4월'!$D$6:$BN$259,16,),)/1000 -> 230.1545 | U19: =+IFERROR(HLOOKUP($B19,'[2]4월'!$F$6:$CP$99,16,),)/1000 -> 133.83138 | V19: =+U19-T19 -> -96.323125 | W19: =+IFERROR(HLOOKUP($B19,'[3]4월'!$F$6:$CC$57,16,),)/1000 -> 177.27361 | X19: =+U19-W19 -> -43.442233 | Y19: =+[4]아산!$Q$85 -> 99199.106 | Z19: =+[4]아산!$R$85 -> 99909.185 | AA19: =+[5]아산!$Q$85 -> 95394.73 | AB19: =+[4]아산!$Q$89 -> 78425.862 | AC19: =+[4]아산!$R$89 -> 84099.709 | AD19: =+[5]아산!$Q$89 -> 77222.153 | AE19: =+Y19-AB19 -> 20773.244 | AF19: =+Z19-AC19 -> 15809.475 | AG19: =+AA19-AD19 -> 18172.577 | AI19: =+I19 -> 아산 | AJ19: =+J19/$J$27 -> 0.084558824 | AK19: =+K19/$K$27 -> 0.088874071 | AL19: =+AK19-AJ19 -> 0.0043152477 | AM19: =+Y19*AL19 -> 428.06872 | AO19: =+[17]아산!$T$5/[17]합계!$T$5 -> 0.093135301 | AP19: =+AK19-AO19 -> -0.0042612293 | AQ19: =+[17]아산!$Q$85*AP19 -> -413.13466
B20: 전주 | G20: =+I20 -> 전주 | I20: 전주 | J20: =+IFERROR(HLOOKUP($B20,'[1]4월'!$D$6:$BN$259,2,),)/1000 -> 11 | K20: =+IFERROR(HLOOKUP($B20,'[2]4월'!$F$6:$CP$99,2,),)/1000 -> 13.51 | L20: =+K20-J20 -> 2.51 | M20: =+IFERROR(HLOOKUP($B20,'[3]4월'!$F$6:$CC$57,2,),)/1000 -> 17.106 | N20: =+K20-M20 -> -3.596 | O20: =+IFERROR(HLOOKUP($B20,'[1]4월'!$D$6:$BN$259,3,),)/1000 -> 1120.471 | P20: =+IFERROR(HLOOKUP($B20,'[2]4월'!$F$6:$CP$99,3,),)/1000 -> 1313.6975 | Q20: =+P20-O20 -> 193.2265 | R20: =+IFERROR(HLOOKUP($B20,'[3]4월'!$F$6:$CC$57,3,),)/1000 -> 1690.8336 | S20: =+P20-R20 -> -377.13605 | T20: =+IFERROR(HLOOKUP($B20,'[1]4월'!$D$6:$BN$259,16,),)/1000 -> 129.22282 | U20: =+IFERROR(HLOOKUP($B20,'[2]4월'!$F$6:$CP$99,16,),)/1000 -> 61.431893 | V20: =+U20-T20 -> -67.790928 | W20: =+IFERROR(HLOOKUP($B20,'[3]4월'!$F$6:$CC$57,16,),)/1000 -> 227.34832 | X20: =+U20-W20 -> -165.91642 | Y20: =+[4]전주!$Q$85 -> 101861 | Z20: =+[4]전주!$R$85 -> 97239.59 | AA20: =+[5]전주!$Q$85 -> 98858.36 | AB20: =+[4]전주!$Q$89 -> 75566.133 | AC20: =+[4]전주!$R$89 -> 80669.539 | AD20: =+[5]전주!$Q$89 -> 76136.612 | AE20: =+Y20-AB20 -> 26294.867 | AF20: =+Z20-AC20 -> 16570.05 | AG20: =+AA20-AD20 -> 22721.748 | AI20: =+I20 -> 전주 | AJ20: =+J20/$J$27 -> 0.040441176 | AK20: =+K20/$K$27 -> 0.049496607 | AL20: =+AK20-AJ20 -> 0.0090554309 | AM20: =+Y20*AL20 -> 922.39525 | AO20: =+[17]전주!$T$5/[17]합계!$T$5 -> 0.057177151 | AP20: =+AK20-AO20 -> -0.0076805436 | AQ20: =+[17]전주!$Q$85*AP20 -> -770.08617
B21: 군산 | G21: =+I21 -> 군산 | I21: 군산 | J21: =+IFERROR(HLOOKUP($B21,'[1]4월'!$D$6:$BN$259,2,),)/1000 -> 5 | K21: =+IFERROR(HLOOKUP($B21,'[2]4월'!$F$6:$CP$99,2,),)/1000 -> 5.101 | L21: =+K21-J21 -> 0.101 | M21: =+IFERROR(HLOOKUP($B21,'[3]4월'!$F$6:$CC$57,2,),)/1000 -> 7.043 | N21: =+K21-M21 -> -1.942 | O21: =+IFERROR(HLOOKUP($B21,'[1]4월'!$D$6:$BN$259,3,),)/1000 -> 560.4238 | P21: =+IFERROR(HLOOKUP($B21,'[2]4월'!$F$6:$CP$99,3,),)/1000 -> 567.92645 | Q21: =+P21-O21 -> 7.50265 | R21: =+IFERROR(HLOOKUP($B21,'[3]4월'!$F$6:$CC$57,3,),)/1000 -> 750.89675 | S21: =+P21-R21 -> -182.9703 | T21: =+IFERROR(HLOOKUP($B21,'[1]4월'!$D$6:$BN$259,16,),)/1000 -> 105.79383 | U21: =+IFERROR(HLOOKUP($B21,'[2]4월'!$F$6:$CP$99,16,),)/1000 -> 96.361313 | V21: =+U21-T21 -> -9.4325207 | W21: =+IFERROR(HLOOKUP($B21,'[3]4월'!$F$6:$CC$57,16,),)/1000 -> 173.95167 | X21: =+U21-W21 -> -77.590357 | Y21: =+[4]군산!$Q$85 -> 112084.76 | Z21: =+[4]군산!$R$85 -> 111336.3 | AA21: =+[5]군산!$Q$85 -> 106616.04 | AB21: =+[4]군산!$Q$89 -> 72924.397 | AC21: =+[4]군산!$R$89 -> 74603.418 | AD21: =+[5]군산!$Q$89 -> 69387.862 | AE21: =+Y21-AB21 -> 39160.363 | AF21: =+Z21-AC21 -> 36732.879 | AG21: =+AA21-AD21 -> 37228.175 | AI21: =+I21 -> 군산 | AJ21: =+J21/$J$27 -> 0.018382353 | AK21: =+K21/$K$27 -> 0.018688541 | AL21: =+AK21-AJ21 -> 0.00030618847 | AM21: =+Y21*AL21 -> 34.319061 | AO21: =+[17]군산!$T$5/[17]합계!$T$5 -> 0.021135065 | AP21: =+AK21-AO21 -> -0.0024465241 | AQ21: =+[17]군산!$Q$85*AP21 -> -263.67852
B22: 원주 | G22: =+I22 -> 원주 | I22: 원주 | J22: =+IFERROR(HLOOKUP($B22,'[1]4월'!$D$6:$BN$259,2,),)/1000 -> 4 | K22: =+IFERROR(HLOOKUP($B22,'[2]4월'!$F$6:$CP$99,2,),)/1000 -> 4.844 | L22: =+K22-J22 -> 0.844 | M22: =+IFERROR(HLOOKUP($B22,'[3]4월'!$F$6:$CC$57,2,),)/1000 -> 2.5685 | N22: =+K22-M22 -> 2.2755 | O22: =+IFERROR(HLOOKUP($B22,'[1]4월'!$D$6:$BN$259,3,),)/1000 -> 446.55954 | P22: =+IFERROR(HLOOKUP($B22,'[2]4월'!$F$6:$CP$99,3,),)/1000 -> 527.77456 | Q22: =+P22-O22 -> 81.215024 | R22: =+IFERROR(HLOOKUP($B22,'[3]4월'!$F$6:$CC$57,3,),)/1000 -> 290.20385 | S22: =+P22-R22 -> 237.57071 | T22: =+IFERROR(HLOOKUP($B22,'[1]4월'!$D$6:$BN$259,16,),)/1000 -> 68.337597 | U22: =+IFERROR(HLOOKUP($B22,'[2]4월'!$F$6:$CP$99,16,),)/1000 -> 103.45074 | V22: =+U22-T22 -> 35.113145 | W22: =+IFERROR(HLOOKUP($B22,'[3]4월'!$F$6:$CC$57,16,),)/1000 -> 14.251573 | X22: =+U22-W22 -> 89.199169 | Y22: =+[4]원주!$Q$85 -> 111639.88 | Z22: =+[4]원주!$R$85 -> 108954.29 | AA22: =+[5]원주!$Q$85 -> 112985.73 | AB22: =+[4]원주!$Q$89 -> 70810.163 | AC22: =+[4]원주!$R$89 -> 69912.46 | AD22: =+[5]원주!$Q$89 -> 73010.818 | AE22: =+Y22-AB22 -> 40829.721 | AF22: =+Z22-AC22 -> 39041.825 | AG22: =+AA22-AD22 -> 39974.913 | AI22: =+I22 -> 원주 | AJ22: =+J22/$J$27 -> 0.014705882 | AK22: =+K22/$K$27 -> 0.01774697 | AL22: =+AK22-AJ22 -> 0.0030410878 | AM22: =+Y22*AL22 -> 339.50669 | AO22: =+[17]원주!$T$5/[17]합계!$T$5 -> 0.015295224 | AP22: =+AK22-AO22 -> 0.0024517465 | AQ22: =+[17]원주!$Q$85*AP22 -> 314.48569
B23: 제주 | F23: =+K27-J27 -> 0.948 | G23: =+I23 -> 제주 | I23: 제주 | J23: =+IFERROR(HLOOKUP($B23,'[1]4월'!$D$6:$BN$259,2,),)/1000 -> 6 | K23: =+IFERROR(HLOOKUP($B23,'[2]4월'!$F$6:$CP$99,2,),)/1000 -> 4.089 | L23: =+K23-J23 -> -1.911 | M23: =+IFERROR(HLOOKUP($B23,'[3]4월'!$F$6:$CC$57,2,),)/1000 -> 7.3395 | N23: =+K23-M23 -> -3.2505 | O23: =+IFERROR(HLOOKUP($B23,'[1]4월'!$D$6:$BN$259,3,),)/1000 -> 736.04 | P23: =+IFERROR(HLOOKUP($B23,'[2]4월'!$F$6:$CP$99,3,),)/1000 -> 536.50751 | Q23: =+P23-O23 -> -199.53249 | R23: =+IFERROR(HLOOKUP($B23,'[3]4월'!$F$6:$CC$57,3,),)/1000 -> 910.08608 | S23: =+P23-R23 -> -373.57857 | T23: =+IFERROR(HLOOKUP($B23,'[1]4월'!$D$6:$BN$259,16,),)/1000 -> 65.55279 | U23: =+IFERROR(HLOOKUP($B23,'[2]4월'!$F$6:$CP$99,16,),)/1000 -> 29.329734 | V23: =+U23-T23 -> -36.223056 | W23: =+IFERROR(HLOOKUP($B23,'[3]4월'!$F$6:$CC$57,16,),)/1000 -> 128.44487 | X23: =+U23-W23 -> -99.115137 | Y23: =+[4]제주!$Q$85 -> 122673.33 | Z23: =+[4]제주!$R$85 -> 131207.51 | AA23: =+[5]제주!$Q$85 -> 123584.35 | AB23: =+[4]제주!$Q$89 -> 93592.816 | AC23: =+[4]제주!$R$89 -> 100213.87 | AD23: =+[5]제주!$Q$89 -> 91260.284 | AE23: =+Y23-AB23 -> 29080.517 | AF23: =+Z23-AC23 -> 30993.643 | AG23: =+AA23-AD23 -> 32324.069 | AI23: =+I23 -> 제주 | AJ23: =+J23/$J$27 -> 0.022058824 | AK23: =+K23/$K$27 -> 0.014980875 | AL23: =+AK23-AJ23 -> -0.0070779481 | AM23: =+Y23*AL23 -> -868.27548 | AO23: =+[17]제주!$T$5/[17]합계!$T$5 -> 0.016931974 | AP23: =+AK23-AO23 -> -0.0019510987 | AQ23: =+[17]제주!$Q$85*AP23 -> -247.89372
F24: =+K24/J24 -> 1.0719206 | G24: =+I24 -> 수도권 | I24: 수도권 | J24: =SUM(J7:J10) -> 107 | K24: =SUM(K7:K10) -> 114.6955 | L24: =+K24-J24 -> 7.6955 | M24: =SUM(M7:M10) -> 99.752 | N24: =+K24-M24 -> 14.9435 | O24: =SUM(O7:O10) -> 10542.078 | P24: =SUM(P7:P10) -> 11318.555 | Q24: =+P24-O24 -> 776.47622 | R24: =SUM(R7:R10) -> 9616.3146 | S24: =+P24-R24 -> 1702.24 | T24: =SUM(T7:T10) -> 948.83207 | U24: =SUM(U7:U10) -> 719.5624 | V24: =+U24-T24 -> -229.26967 | W24: =SUM(W7:W10) -> 593.23161 | X24: =+U24-W24 -> 126.33079 | Y24: =+[4]수도권!$Q$85 -> 98524.097 | Z24: =+[4]수도권!$R$85 -> 98815.723 | AA24: =+[5]수도권!$Q$85 -> 96454.113 | AB24: =+[4]수도권!$Q$89 -> 79805.01 | AC24: =+[4]수도권!$R$89 -> 82943.595 | AD24: =+[5]수도권!$Q$89 -> 80081.525 | AE24: =+Y24-AB24 -> 18719.086 | AF24: =+Z24-AC24 -> 15872.128 | AG24: =+AA24-AD24 -> 16372.588 | AI24: =+I24 -> 수도권 | AJ24: =+J24/$J$27 -> 0.39338235 | AK24: =+K24/$K$27 -> 0.42021008 | AL24: =+AK24-AJ24 -> 0.026827724 | AM24: =+Y24*AL24 -> 2643.1772 | AO24: =+[17]수도권!$T$5/[17]합계!$T$5 -> 0.41653622 | AP24: =+AK24-AO24 -> 0.0036738604 | AQ24: =+[17]수도권!$Q$85*AP24 -> 363.17908
