Workbook

Sheet 표지
A6: 2026년 1월 마감 손익
A24: 레미콘사업본부

Sheet 손익총괄
C3: □ 건재사업본부 손익실적(2026-01)
X4: [단위 : 천㎥, 톤, 원/㎥, 원/톤, 백만원]
C5: 구분 | E5: 1월 | J5: 1월 누계 | P5: 1월 주요지표
E6: 계획 | F6: 실적 | G6: 계획대비 | H6: 전년 | I6: 전년대비 | J6: 계획 | K6: 실적 | L6: 계획대비 | M6: 전년 | N6: 전년대비
C7: 물량 | D7: 레미콘 | E7: =+'[1]1월'!$Z$7/1000 -> 189 | F7: =+'[2]1월'!$Z$7/1000 -> 176.1205 | G7: =+F7-E7 -> -12.8795 | H7: =+'[3]1월'!$Z$7/1000 -> 177.8795 | I7: =+F7-H7 -> -1.759 | J7: =+'[1]1월'!$Z$7/1000 -> 189 | K7: =+'[2]1월'!$Z$7/1000 -> 176.1205 | L7: =+K7-J7 -> -12.8795 | M7: =+'[3]1월'!$Z$7/1000 -> 177.8795 | N7: =+K7-M7 -> -1.759 | Q7: □ 레미콘
D8: 골재 | E8: =+'[1]1월'!$AE$7/1000 -> 74.758127 | F8: =+'[2]1월'!$AN$7/1000 -> 55.493 | G8: =+F8-E8 -> -19.265127 | H8: =+'[3]1월'!$AN$7/1000 -> 48.252 | I8: =+F8-H8 -> 7.241 | J8: =+'[1]1월'!$AE$7/1000 -> 74.758127 | K8: =+'[2]1월'!$AN$7/1000 -> 55.493 | L8: =+K8-J8 -> -19.265127 | M8: =+'[3]1월'!$AN$7/1000 -> 48.252 | N8: =+K8-M8 -> 7.241 | Q8: 구분 | S8: 계획 | T8: 실적 | U8: 계획대비 | V8: 전년 | W8: 전년대비
C9: 매출 | D9: 레미콘 | E9: =+'[1]1월'!$Z$8/1000 -> 19072.612 | F9: =+'[2]1월'!$Z$8/1000 -> 18745.855 | G9: =+F9-E9 -> -326.75709 | H9: =+'[3]1월'!$Z$8/1000 -> 17974.392 | I9: =+F9-H9 -> 771.46287 | J9: =+'[1]1월'!$Z$8/1000 -> 19072.612 | K9: =+'[2]1월'!$Z$8/1000 -> 18745.855 | L9: =+K9-J9 -> -326.75709 | M9: =+'[3]1월'!$Z$8/1000 -> 17974.392 | N9: =+K9-M9 -> 771.46287 | Q9: 물량 | R9: 수도권 | S9: =+[4]수도권!$T$5/1000 -> 72 | T9: =+[4]수도권!$U$5/1000 -> 66.817 | U9: =+T9-S9 -> -5.183 | V9: =+[5]수도권!$T$5/1000 -> 56.9285 | W9: =+T9-V9 -> 9.8885
D10: 골재 | E10: =+'[1]1월'!$AE$8/1000 -> 1407.6886 | F10: =+'[2]1월'!$AN$8/1000 -> 1129.7404 | G10: =+F10-E10 -> -277.9482 | H10: =+'[3]1월'!$AN$8/1000 -> 1051.748 | I10: =+F10-H10 -> 77.9924 | J10: =+'[1]1월'!$AE$8/1000 -> 1407.6886 | K10: =+'[2]1월'!$AN$8/1000 -> 1129.7404 | L10: =+K10-J10 -> -277.9482 | M10: =+'[3]1월'!$AN$8/1000 -> 1051.748 | N10: =+K10-M10 -> 77.9924 | R10: 영남권 | S10: =+[4]영남권!$T$5/1000 -> 90.5 | T10: =+[4]영남권!$U$5/1000 -> 78.6105 | U10: =+T10-S10 -> -11.8895 | V10: =+[5]영남권!$T$5/1000 -> 81.123 | W10: =+T10-V10 -> -2.5125
D11: 기타 | E11: =+'[1]1월'!$E$8/1000-E9-E33-E10 -> 118.83333 | F11: =+('[2]1월'!$BJ$8+'[2]1월'!$BA$8+'[2]1월'!$AP$8+'[2]1월'!$AH$8)/1000 -> 52.334878 | G11: =+F11-E11 -> -66.498455 | H11: =+'[3]1월'!$F$8/1000-H9-H33-H10 -> 167.2526 | I11: =+F11-H11 -> -114.91772 | J11: =+'[1]1월'!$E$8/1000-J9-J33-J10 -> 118.83333 | K11: =+('[2]1월'!$BJ$8+'[2]1월'!$BA$8+'[2]1월'!$AP$8+'[2]1월'!$AH$8)/1000 -> 52.334878 | L11: =+K11-J11 -> -66.498455 | M11: =+'[3]1월'!$F$8/1000-M9-M33-M10 -> 167.2526 | N11: =+K11-M11 -> -114.91772 | R11: 중부권 | S11: =+[4]중부권!$T$5/1000 -> 26.5 | T11: =+[4]중부권!$U$5/1000 -> 30.693 | U11: =+T11-S11 -> 4.193 | V11: =+[5]중부권!$T$5/1000 -> 39.828 | W11: =+T11-V11 -> -9.135
C12: 계 | E12: =SUM(E9:E11) -> 20599.134 | F12: =SUM(F9:F11) -> 19927.93 | G12: =+F12-E12 -> -671.20375 | H12: =SUM(H9:H11) -> 19193.393 | I12: =+F12-H12 -> 734.53755 | J12: =SUM(J9:J11) -> 20599.134 | K12: =SUM(K9:K11) -> 19927.93 | L12: =+K12-J12 -> -671.20375 | M12: =SUM(M9:M11) -> 19193.393 | N12: =+K12-M12 -> 734.53755 | Q12: 계 | S12: =SUM(S9:S11) -> 189 | T12: =SUM(T9:T11) -> 176.1205 | U12: =+T12-S12 -> -12.8795 | V12: =SUM(V9:V11) -> 177.8795 | W12: =+T12-V12 -> -1.759
C13: 매출원가 | D13: 레미콘 | E13: =+('[1]1월'!$Z$10+'[1]1월'!$Z$19)/1000 -> 18357.16 | F13: =+('[2]1월'!$Z$10+'[2]1월'!$Z$19)/1000 -> 17847.352 | G13: =+F13-E13 -> -509.80781 | H13: =+('[3]1월'!$Z$10+'[3]1월'!$Z$19)/1000 -> 17240.725 | I13: =+F13-H13 -> 606.62647 | J13: =+('[1]1월'!$Z$10+'[1]1월'!$Z$19)/1000 -> 18357.16 | K13: =+('[2]1월'!$Z$10+'[2]1월'!$Z$19)/1000 -> 17847.352 | L13: =+K13-J13 -> -509.80781 | M13: =+('[3]1월'!$Z$10+'[3]1월'!$Z$19)/1000 -> 17240.725 | N13: =+K13-M13 -> 606.62647 | Q13: 판매단가 | R13: 수도권 | S13: =+[4]수도권!$T$61 -> 98950.866 | T13: =+[4]수도권!$U$61 -> 104188.77 | U13: =+T13-S13 -> 5237.9089 | V13: =+[5]수도권!$Q$85 -> 99000.139 | W13: =+T13-V13 -> 5188.6358
D14: 골재 | E14: =+('[1]1월'!$AE$10+'[1]1월'!$AE$19)/1000 -> 1446.0693 | F14: =+('[2]1월'!$AN$10+'[2]1월'!$AN$19)/1000 -> 1253.2515 | G14: =+F14-E14 -> -192.81783 | H14: =+('[3]1월'!$AN$10+'[3]1월'!$AN$19)/1000 -> 1282.2655 | I14: =+F14-H14 -> -29.014042 | J14: =+('[1]1월'!$AE$10+'[1]1월'!$AE$19)/1000 -> 1446.0693 | K14: =+('[2]1월'!$AN$10+'[2]1월'!$AN$19)/1000 -> 1253.2515 | L14: =+K14-J14 -> -192.81783 | M14: =+('[3]1월'!$AN$10+'[3]1월'!$AN$19)/1000 -> 1282.2655 | N14: =+K14-M14 -> -29.014042 | R14: 영남권 | S14: =+[4]영남권!$T$61 -> 100438.34 | T14: =+[4]영남권!$U$61 -> 107645.52 | U14: =+T14-S14 -> 7207.1744 | V14: =+[5]영남권!$Q$85 -> 100960.81 | W14: =+T14-V14 -> 6684.7004
D15: 기타 | E15: =+('[1]1월'!$AL$10+'[1]1월'!$AL$19+'[1]1월'!$AV$10+'[1]1월'!$AV$19)/1000 -> 19.286963 | F15: =+('[2]1월'!$AH$10+'[2]1월'!$AH$19+'[2]1월'!$AP$10+'[2]1월'!$AP$19+'[2]1월'!$BA$10+'[2]1월'!$BA$19+'[2]1월'!$BJ$10+'[2]1월'!$BJ$19)/1000 -> 19.263581 | G15: =+F15-E15 -> -0.023382 | H15: =+('[3]1월'!$F$10+'[3]1월'!$F$19)/1000-H13-H14-('[3]1월'!$AO$10+'[3]1월'!$AO$19)/1000 -> 331.19036 | I15: =+F15-H15 -> -311.92678 | J15: =+('[1]1월'!$AL$10+'[1]1월'!$AL$19+'[1]1월'!$AV$10+'[1]1월'!$AV$19)/1000 -> 19.286963 | K15: =+('[2]1월'!$AH$10+'[2]1월'!$AH$19+'[2]1월'!$AP$10+'[2]1월'!$AP$19+'[2]1월'!$BA$10+'[2]1월'!$BA$19+'[2]1월'!$BJ$10+'[2]1월'!$BJ$19)/1000 -> 19.263581 | L15: =+K15-J15 -> -0.023382 | M15: =+('[3]1월'!$F$10+'[3]1월'!$F$19)/1000-M13-M14-('[3]1월'!$AO$10+'[3]1월'!$AO$19)/1000 -> 331.19036 | N15: =+K15-M15 -> -311.92678 | R15: 중부권 | S15: =+[4]중부권!$T$61 -> 107867.16 | T15: =+[4]중부권!$U$61 -> 108148.79 | U15: =+T15-S15 -> 281.62351 | V15: =+[5]중부권!$Q$85 -> 103685.34 | W15: =+T15-V15 -> 4463.4456
C16: 계 | E16: =SUM(E13:E15) -> 19822.516 | F16: =SUM(F13:F15) -> 19119.867 | G16: =+F16-E16 -> -702.64902 | H16: =SUM(H13:H15) -> 18854.181 | I16: =+F16-H16 -> 265.68565 | J16: =SUM(J13:J15) -> 19822.516 | K16: =SUM(K13:K15) -> 19119.867 | L16: =+K16-J16 -> -702.64902 | M16: =SUM(M13:M15) -> 18854.181 | N16: =+K16-M16 -> 265.68565 | Q16: 계 | S16: =+[4]합계!$T$61 -> 100913.29 | T16: =+[4]합계!$U$61 -> 106420.86 | U16: =+T16-S16 -> 5507.5656 | V16: =+[5]합계!$Q$85 -> 100932.18 | W16: =+T16-V16 -> 5488.6757
C17: 매출이익 | D17: 레미콘 | E17: =+E9-E13 -> 715.45235 | F17: =+F9-F13 -> 898.50307 | G17: =+F17-E17 -> 183.05072 | H17: =+H9-H13 -> 733.66668 | I17: =+F17-H17 -> 164.8364 | J17: =+J9-J13 -> 715.45235 | K17: =+K9-K13 -> 898.50307 | L17: =+K17-J17 -> 183.05072 | M17: =+M9-M13 -> 733.66668 | N17: =+K17-M17 -> 164.8364 | Q17: 공헌이익 | R17: 수도권 | S17: =+[4]수도권!$Q$90 -> 15450.46 | T17: =+[4]수도권!$R$90 -> 14405.036 | U17: =+T17-S17 -> -1045.4238 | V17: =+[5]수도권!$Q$90 -> 13670.147 | W17: =+T17-V17 -> 734.88933
D18: 골재 | E18: =+E10-E14 -> -38.380732 | F18: =+F10-F14 -> -123.5111 | G18: =+F18-E18 -> -85.130368 | H18: =+H10-H14 -> -230.51754 | I18: =+F18-H18 -> 107.00644 | J18: =+J10-J14 -> -38.380732 | K18: =+K10-K14 -> -123.5111 | L18: =+K18-J18 -> -85.130368 | M18: =+M10-M14 -> -230.51754 | N18: =+K18-M18 -> 107.00644 | R18: 영남권 | S18: =+[4]영남권!$Q$90 -> 18625.144 | T18: =+[4]영남권!$R$90 -> 21506.306 | U18: =+T18-S18 -> 2881.1614 | V18: =+[5]영남권!$Q$90 -> 20157.906 | W18: =+T18-V18 -> 1348.3998
D19: 기타 | E19: =+E11-E15 -> 99.54637 | F19: =+F11-F15 -> 33.071297 | G19: =+F19-E19 -> -66.475073 | H19: =+H11-H15 -> -163.93776 | I19: =+F19-H19 -> 197.00906 | J19: =+J11-J15 -> 99.54637 | K19: =+K11-K15 -> 33.071297 | L19: =+K19-J19 -> -66.475073 | M19: =+M11-M15 -> -163.93776 | N19: =+K19-M19 -> 197.00906 | R19: 중부권 | S19: =+[4]중부권!$Q$90 -> 25419.147 | T19: =+[4]중부권!$R$90 -> 21490.416 | U19: =+T19-S19 -> -3928.7307 | V19: =+[5]중부권!$Q$90 -> 20761.141 | W19: =+T19-V19 -> 729.27531
C20: 계 | E20: =SUM(E17:E19) -> 776.61799 | F20: =SUM(F17:F19) -> 808.06327 | G20: =+F20-E20 -> 31.445277 | H20: =SUM(H17:H19) -> 339.21137 | I20: =+F20-H20 -> 468.85189 | J20: =SUM(J17:J19) -> 776.61799 | K20: =SUM(K17:K19) -> 808.06327 | L20: =+K20-J20 -> 31.445277 | M20: =SUM(M17:M19) -> 339.21137 | N20: =+K20-M20 -> 468.85189 | Q20: 계 | S20: =+[4]합계!$Q$90 -> 18368.339 | T20: =+[4]합계!$R$90 -> 18810.282 | U20: =+T20-S20 -> 441.94348 | V20: =+[5]합계!$Q$90 -> 18230.839 | W20: =+T20-V20 -> 579.44333
C21: 판관비 | D21: 레미콘 | E21: =+('[1]1월'!$Z$13+'[1]1월'!$Z$20+'[1]1월'!$Z$22)/1000 -> 2472.9235 | F21: =+('[2]1월'!$Z$13+'[2]1월'!$Z$20+'[2]1월'!$Z$22)/1000 -> 1900.9497 | G21: =+F21-E21 -> -571.97377 | H21: =+('[3]1월'!$Z$13+'[3]1월'!$Z$20+'[3]1월'!$Z$22)/1000 -> 2347.7194 | I21: =+F21-H21 -> -446.76971 | J21: =+('[1]1월'!$Z$13+'[1]1월'!$Z$20+'[1]1월'!$Z$22)/1000 -> 2472.9235 | K21: =+('[2]1월'!$Z$13+'[2]1월'!$Z$20+'[2]1월'!$Z$22)/1000 -> 1900.9497 | L21: =+K21-J21 -> -571.97377 | M21: =+('[3]1월'!$Z$13+'[3]1월'!$Z$20+'[3]1월'!$Z$22)/1000 -> 2347.7194 | N21: =+K21-M21 -> -446.76971 | Q21: □ 골재
D22: 골재 | E22: =+('[1]1월'!$AE$13+'[1]1월'!$AE$20+'[1]1월'!$AE$22)/1000 -> 50.11538 | F22: =+('[2]1월'!$AN$13+'[2]1월'!$AN$20+'[2]1월'!$AN$22)/1000 -> 46.765619 | G22: =+F22-E22 -> -3.349761 | H22: =+('[3]1월'!$AN$13+'[3]1월'!$AN$20+'[3]1월'!$AN$22)/1000 -> 49.569914 | I22: =+F22-H22 -> -2.8042952 | J22: =+('[1]1월'!$AE$13+'[1]1월'!$AE$20+'[1]1월'!$AE$22)/1000 -> 50.11538 | K22: =+('[2]1월'!$AN$13+'[2]1월'!$AN$20+'[2]1월'!$AN$22)/1000 -> 46.765619 | L22: =+K22-J22 -> -3.349761 | M22: =+('[3]1월'!$AN$13+'[3]1월'!$AN$20+'[3]1월'!$AN$22)/1000 -> 49.569914 | N22: =+K22-M22 -> -2.8042952 | Q22: 구분 | S22: 계획 | T22: 실적 | U22: 계획대비 | V22: 전년 | W22: 전년대비
D23: 기타 | E23: =+('[1]1월'!$AL$13+'[1]1월'!$AV$13+'[1]1월'!$AL$20+'[1]1월'!$AV$20+'[1]1월'!$AL$22+'[1]1월'!$AV$22)/1000 -> 61.885059 | F23: =+('[2]1월'!$F$13+'[2]1월'!$F$20+'[2]1월'!$F$22)/1000-F21-F22-('[2]1월'!$AO$13+'[2]1월'!$AO$20+'[2]1월'!$AO$22)/1000 -> 63.174249 | G23: =+F23-E23 -> 1.28919 | H23: =+('[3]1월'!$F$13+'[3]1월'!$F$20+'[3]1월'!$F$22)/1000-H21-H22-('[3]1월'!$AO$13+'[3]1월'!$AO$20+'[3]1월'!$AO$22)/1000 -> 507.58097 | I23: =+F23-H23 -> -444.40672 | J23: =+('[1]1월'!$AL$13+'[1]1월'!$AV$13+'[1]1월'!$AL$20+'[1]1월'!$AV$20+'[1]1월'!$AL$22+'[1]1월'!$AV$22)/1000 -> 61.885059 | K23: =+('[2]1월'!$F$13+'[2]1월'!$F$20+'[2]1월'!$F$22)/1000-K21-K22-('[2]1월'!$AO$13+'[2]1월'!$AO$20+'[2]1월'!$AO$22)/1000 -> 63.174249 | L23: =+K23-J23 -> 1.28919 | M23: =+('[3]1월'!$F$13+'[3]1월'!$F$20+'[3]1월'!$F$22)/1000-M21-M22-('[3]1월'!$AO$13+'[3]1월'!$AO$20+'[3]1월'!$AO$22)/1000 -> 507.58097 | N23: =+K23-M23 -> -444.40672 | Q23: 판매량 | R23: 자가 | S23: =+[6]원가손익!$W$10+[7]원가손익!$U$27+[8]손익!$F$10 -> 47918.127 | T23: =+[6]원가손익!$X$10+[7]원가손익!$V$27+[8]손익!$G$10 -> 42752 | U23: =+T23-S23 -> -5166.1269 | V23: =+[9]원가손익!$X$10+[10]원가손익!$V$27+[11]손익!$Y$25 -> 30260 | W23: =+T23-V23 -> 12492
C24: 계 | E24: =SUM(E21:E23) -> 2584.9239 | F24: =SUM(F21:F23) -> 2010.8896 | G24: =+F24-E24 -> -574.03434 | H24: =SUM(H21:H23) -> 2904.8703 | I24: =+F24-H24 -> -893.98073 | J24: =SUM(J21:J23) -> 2584.9239 | K24: =SUM(K21:K23) -> 2010.8896 | L24: =+K24-J24 -> -574.03434 | M24: =SUM(M21:M23) -> 2904.8703 | N24: =+K24-M24 -> -893.98073 | R24: 외판 | S24: =+[6]원가손익!$W$14+[7]원가손익!$U$29+[8]손익!$F$12 -> 26840 | T24: =+[6]원가손익!$X$14+[7]원가손익!$V$29+[8]손익!$G$12 -> 12741 | U24: =+T24-S24 -> -14099 | V24: =+[9]원가손익!$X$14+[10]원가손익!$V$29+[11]손익!$Y$27 -> 17992 | W24: =+T24-V24 -> -5251
C25: 영업이익 | D25: 레미콘 | E25: =+E17-E21 -> -1757.4711 | F25: =+F17-F21 -> -1002.4466 | G25: =+F25-E25 -> 755.02449 | H25: =+H17-H21 -> -1614.0527 | I25: =+F25-H25 -> 611.60611 | J25: =+J17-J21 -> -1757.4711 | K25: =+K17-K21 -> -1002.4466 | L25: =+K25-J25 -> 755.02449 | M25: =+M17-M21 -> -1614.0527 | N25: =+K25-M25 -> 611.60611 | Q25: 합 계 | S25: =SUM(S23:S24) -> 74758.127 | T25: =SUM(T23:T24) -> 55493 | U25: =+T25-S25 -> -19265.127 | V25: =SUM(V23:V24) -> 48252 | W25: =+T25-V25 -> 7241
D26: % | E26: =+E25/E9 -> -0.092146326 | F26: =+F25/F9 -> -0.053475642 | G26: =+F26-E26 -> 0.038670683 | H26: =+H25/H9 -> -0.089797348 | I26: =+F26-H26 -> 0.036321706 | J26: =+J25/J9 -> -0.092146326 | K26: =+K25/K9 -> -0.053475642 | L26: =+K26-J26 -> 0.038670683 | M26: =+M25/M9 -> -0.089797348 | N26: =+K26-M26 -> 0.036321706 | Q26: □ 기타내역(영업이익)
D27: 골재 | E27: =+E18-E22 -> -88.496111 | F27: =+F18-F22 -> -170.27672 | G27: =+F27-E27 -> -81.780607 | H27: =+H18-H22 -> -280.08746 | I27: =+F27-H27 -> 109.81074 | J27: =+J18-J22 -> -88.496111 | K27: =+K18-K22 -> -170.27672 | L27: =+K27-J27 -> -81.780607 | M27: =+M18-M22 -> -280.08746 | N27: =+K27-M27 -> 109.81074 | Q27: 구분 | S27: 계획 | T27: 실적 | U27: 계획대비 | V27: 전년 | W27: 전년대비
D28: 기타 | E28: =+E19-E23 -> 37.661311 | F28: =+F19-F23 -> -30.102952 | G28: =+F28-E28 -> -67.764263 | H28: =+H19-H23 -> -671.51872 | I28: =+F28-H28 -> 641.41577 | J28: =+J19-J23 -> 37.661311 | K28: =+K19-K23 -> -30.102952 | L28: =+K28-J28 -> -67.764263 | M28: =+M19-M23 -> -671.51872 | N28: =+K28-M28 -> 641.41577 | Q28: 레미콘임대 | S28: =+'사업장별(당월)'!T32 -> 29.628698 | T28: =+'사업장별(당월)'!U32 -> 23.441662 | U28: =+T28-S28 -> -6.1870357 | V28: =+'사업장별(당월)'!W32 -> 72.305275 | W28: =+T28-V28 -> -48.863613
C29: 계 | E29: =+E25+E27+E28 -> -1808.3059 | F29: =+F25+F27+F28 -> -1202.8263 | G29: =+F29-E29 -> 605.47962 | H29: =+H25+H27+H28 -> -2565.6589 | I29: =+F29-H29 -> 1362.8326 | J29: =+J25+J27+J28 -> -1808.3059 | K29: =+K25+K27+K28 -> -1202.8263 | L29: =+K29-J29 -> 605.47962 | M29: =+M25+M27+M28 -> -2565.6589 | N29: =+K29-M29 -> 1362.8326 | Q29: 임대 | S29: =+'사업장별(당월)'!T33 -> 68.147673 | T29: =+'사업장별(당월)'!U33 -> 0.104109 | U29: =+T29-S29 -> -68.043564 | V29: =+'사업장별(당월)'!W33 -> 64.600993 | W29: =+T29-V29 -> -64.496884
D30: % | E30: =+E29/E12 -> -0.087785531 | F30: =+F29/F12 -> -0.060358818 | G30: =+F30-E30 -> 0.027426714 | H30: =+H29/H12 -> -0.13367407 | I30: =+F30-H30 -> 0.073315253 | J30: =+J29/J12 -> -0.087785531 | K30: =+K29/K12 -> -0.060358818 | L30: =+K30-J30 -> 0.027426714 | M30: =+M29/M12 -> -0.13367407 | N30: =+K30-M30 -> 0.073315253 | Q30: 공통비 | S30: =+'사업장별(당월)'!T34 -> -1782.6186 | T30: =+'사업장별(당월)'!U34 -> -1251.4257 | U30: =+T30-S30 -> 531.19295 | V30: =+'사업장별(당월)'!W34 -> -1637.191 | W30: =+T30-V30 -> 385.76533
C31: * 건자재 | Q31: 기타 | S31: =+S32-S28-S29-S30 -> -60.115059 | T31: =+T32-T28-T29-T30 -> -53.648723 | U31: =+T31-S31 -> 6.466336 | V31: =+V32-V28-V29-V30 -> -808.42499 | W31: =+T31-V31 -> 754.77627
C32: 물량 | E32: =+IFERROR(HLOOKUP($E$5,[12]손익!$G$5:$AI$54,2,),) -> 8000 | F32: =+'[2]1월'!$AO$7 -> 4969.838 | G32: =+F32-E32 -> -3030.162 | H32: =+'[3]1월'!$AO$7 -> 8735.502 | I32: =+F32-H32 -> -3765.664 | J32: =+'[1]1월'!$AA$7 -> 8000 | K32: =+'[2]1월'!$AO$7 -> 4969.838 | L32: =+K32-J32 -> -3030.162 | M32: =+'[3]1월'!$AO$7 -> 8735.502 | N32: =+K32-M32 -> -3765.664 | Q32: 합계 | S32: =+'사업장별(당월)'!T40 -> -1744.9573 | T32: =+'사업장별(당월)'!U40 -> -1281.5286 | U32: =+T32-S32 -> 463.42868 | V32: =+'사업장별(당월)'!W40 -> -2308.7097 | W32: =+T32-V32 -> 1027.1811
C33: 매출 | E33: =+IFERROR(HLOOKUP($E$5,[12]손익!$G$5:$AI$54,3,),)/1000 -> 7664.8434 | F33: =+'[2]1월'!$AO$8/1000 -> 5099.8867 | G33: =+F33-E33 -> -2564.9567 | H33: =+'[3]1월'!$AO$8/1000 -> 7480.1197 | I33: =+F33-H33 -> -2380.2329 | J33: =+'[1]1월'!$AA$8/1000 -> 7664.8434 | K33: =+'[2]1월'!$AO$8/1000 -> 5099.8867 | L33: =+K33-J33 -> -2564.9567 | M33: =+'[3]1월'!$AO$8/1000 -> 7480.1197 | N33: =+K33-M33 -> -2380.2329
C34: 매출이익 | E34: =+IFERROR(HLOOKUP($E$5,[12]손익!$G$5:$AI$54,7,),)/1000 -> 167.79838 | F34: =+'[2]1월'!$AO$12/1000 -> 127.93008 | G34: =+F34-E34 -> -39.868304 | H34: =+'[3]1월'!$AO$12/1000 -> 145.91049 | I34: =+F34-H34 -> -17.980414 | J34: =+'[1]1월'!$AA$12/1000 -> 167.79838 | K34: =+'[2]1월'!$AO$12/1000 -> 127.93008 | L34: =+K34-J34 -> -39.868304 | M34: =+'[3]1월'!$AO$12/1000 -> 145.91049 | N34: =+K34-M34 -> -17.980414 | Q34: □ 건자재
C35: (%) | E35: =+E34/E33 -> 0.021891952 | F35: =+F34/F33 -> 0.025084886 | G35: =+F35-E35 -> 0.0031929344 | H35: =+H34/H33 -> 0.019506438 | I35: =+I34/I33 -> 0.0075540565 | J35: =+J34/J33 -> 0.021891952 | K35: =+K34/K33 -> 0.025084886 | L35: =+K35-J35 -> 0.0031929344 | M35: =+M34/M33 -> 0.019506438 | N35: =+K35-M35 -> 0.0055784479 | Q35: 구분 | S35: 계획 | T35: 실적 | U35: 계획대비 | V35: 전년 | W35: 전년대비
C36: 영업이익 | E36: =+IFERROR(HLOOKUP($E$5,[12]손익!$G$5:$AI$54,20,),)/1000 -> -46.217593 | F36: =+'[2]1월'!$AO$26/1000 -> -38.815401 | G36: =+F36-E36 -> 7.4021919 | H36: =+'[3]1월'!$AO$26/1000 -> 1.697249 | I36: =+F36-H36 -> -40.51265 | J36: =+'[1]1월'!$AA$26/1000 -> -46.217593 | K36: =+'[2]1월'!$AO$26/1000 -> -38.815401 | L36: =+K36-J36 -> 7.4021919 | M36: =+'[3]1월'!$AO$26/1000 -> 1.697249 | N36: =+K36-M36 -> -40.51265 | Q36: 철강재 판매단가 | S36: =+'[13]1월'!$F$10 -> 743250 | T36: =+'[13]1월'!$G$10 -> 796801.18 | U36: =+T36-S36 -> 53551.181 | V36: =+'[14]1월'!$G$10 -> 756420.01 | W36: =+T36-V36 -> 40381.17
C37: (%) | E37: =+E36/E33 -> -0.0060298156 | F37: =+F36/F33 -> -0.007611032 | G37: =+F37-E37 -> -0.0015812163 | H37: =+H36/H33 -> 0.00022690132 | I37: =+F37-H37 -> -0.0078379333 | J37: =+J36/J33 -> -0.0060298156 | K37: =+K36/K33 -> -0.007611032 | L37: =+K37-J37 -> -0.0015812163 | M37: =+M36/M33 -> 0.00022690132 | N37: =+K37-M37 -> -0.0078379333 | Q37: 철강재 마진률 | S37: =+'[13]1월'!$F$15 -> 0.016448032 | T37: =+'[13]1월'!$G$15 -> 0.020621617 | U37: =+T37-S37 -> 0.0041735844 | V37: =+'[14]1월'!$G$15 -> 0.017727214 | W37: =+T37-V37 -> 0.0028944022
E39: =+'[1]1월'!$E$26/1000 -> -1854.5235 | F39: =+'[2]1월'!$F$26/1000 -> -1241.6417 | H39: =+'[3]1월'!$F$26/1000 -> -2563.9617 | J39: =+'[1]1월'!$E$26/1000 -> -1854.5235 | K39: =+'[2]1월'!$F$26/1000 -> -1241.6417 | M39: =+'[3]1월'!$F$26/1000 -> -2563.9617
E40: =+(E29+E36)-E39 -> 0 | F40: =+(F29+F36)-F39 -> 0 | H40: =+(H29+H36)-H39 -> 0 | J40: =+(J29+J36)-J39 -> 0 | K40: =+(K29+K36)-K39 -> 0 | M40: =+(M29+M36)-M39 -> 0

Sheet 레미콘 영업이익
H3: □ 레미콘 영업이익(1월)
H5: 구분 | J5: 1월 | T5: 1월누계
J6: 영업이익(공통비 배부전) | O6: 영업이익(공통비 배부후) | T6: 영업이익(공통비 배부전) | Y6: 영업이익(공통비 배부전)
A7: 2024년 1월 마감 손익 | J7: 계획 | K7: 실적 | L7: 차이 | M7: 전년 | N7: 차이 | O7: 계획 | P7: 실적 | Q7: 차이 | R7: 전년 | S7: 차이 | T7: 계획 | U7: 실적 | V7: 차이 | W7: 전년 | X7: 차이 | Y7: 계획 | Z7: 실적 | AA7: 차이 | AB7: 전년 | AC7: 차이
B8: 안양 | H8: 레미콘 | I8: 안양 | J8: =+[4]안양!$H$86/1000 -> 174.44457 | K8: =+[4]안양!$I$86/1000 -> 231.23201 | L8: =+K8-J8 -> 56.787441 | M8: =+[5]안양!$H$86/1000 -> 88.057685 | N8: =+K8-M8 -> 143.17433 | O8: =+[4]안양!$H$92/1000 -> -88.266655 | P8: =+[4]안양!$I$92/1000 -> 15.073585 | Q8: =+P8-O8 -> 103.34024 | R8: =+[5]안양!$H$92/1000 -> -153.00896 | S8: =+P8-R8 -> 168.08254 | T8: =+[4]안양!$H$86/1000 -> 174.44457 | U8: =+[4]안양!$I$86/1000 -> 231.23201 | V8: =+U8-T8 -> 56.787441 | W8: =+[5]안양!$H$86/1000 -> 88.057685 | X8: =+U8-W8 -> 143.17433 | Y8: =+[4]안양!$H$92/1000 -> -88.266655 | Z8: =+[4]안양!$I$92/1000 -> 15.073585 | AA8: =+Z8-Y8 -> 103.34024 | AB8: =+[5]안양!$H$92/1000 -> -153.00896 | AC8: =+Z8-AB8 -> 168.08254
B9: 인천 | H9: 직영 | I9: 인천 | J9: =+[4]인천!$H$86/1000 -> -29.440006 | K9: =+[4]인천!$I$86/1000 -> -30.5667 | L9: =+K9-J9 -> -1.1266943 | M9: =+[5]인천!$H$86/1000 -> -127.14974 | N9: =+K9-M9 -> 96.583042 | O9: =+[4]인천!$H$92/1000 -> -258.38515 | P9: =+[4]인천!$I$92/1000 -> -174.53713 | Q9: =+P9-O9 -> 83.848015 | R9: =+[5]인천!$H$92/1000 -> -269.87633 | S9: =+P9-R9 -> 95.339203 | T9: =+[4]인천!$H$86/1000 -> -29.440006 | U9: =+[4]인천!$I$86/1000 -> -30.5667 | V9: =+U9-T9 -> -1.1266943 | W9: =+[5]인천!$H$86/1000 -> -127.14974 | X9: =+U9-W9 -> 96.583042 | Y9: =+[4]인천!$H$92/1000 -> -258.38515 | Z9: =+[4]인천!$I$92/1000 -> -174.53713 | AA9: =+Z9-Y9 -> 83.848015 | AB9: =+[5]인천!$H$92/1000 -> -269.87633 | AC9: =+Z9-AB9 -> 95.339203
B10: 파주 | I10: 파주 | J10: =+[4]파주!$H$86/1000 -> -87.864332 | K10: =+[4]파주!$I$86/1000 -> -117.52526 | L10: =+K10-J10 -> -29.660927 | M10: =+[5]파주!$H$86/1000 -> -106.54515 | N10: =+K10-M10 -> -10.980112 | O10: =+[4]파주!$H$92/1000 -> -174.36828 | P10: =+[4]파주!$I$92/1000 -> -166.10407 | Q10: =+P10-O10 -> 8.2642122 | R10: =+[5]파주!$H$92/1000 -> -177.9112 | S10: =+P10-R10 -> 11.807128 | T10: =+[4]파주!$H$86/1000 -> -87.864332 | U10: =+[4]파주!$I$86/1000 -> -117.52526 | V10: =+U10-T10 -> -29.660927 | W10: =+[5]파주!$H$86/1000 -> -106.54515 | X10: =+U10-W10 -> -10.980112 | Y10: =+[4]파주!$H$92/1000 -> -174.36828 | Z10: =+[4]파주!$I$92/1000 -> -166.10407 | AA10: =+Z10-Y10 -> 8.2642122 | AB10: =+[5]파주!$H$92/1000 -> -177.9112 | AC10: =+Z10-AB10 -> 11.807128
B11: 김포 | I11: 김포 | J11: =+[4]김포!$H$86/1000 -> -57.447522 | K11: =+[4]김포!$I$86/1000 -> -99.529529 | L11: =+K11-J11 -> -42.082007 | M11: =+[5]김포!$H$86/1000 -> -107.3369 | N11: =+K11-M11 -> 7.807367 | O11: =+[4]김포!$H$92/1000 -> -130.98855 | P11: =+[4]김포!$I$92/1000 -> -141.74812 | Q11: =+P11-O11 -> -10.759563 | R11: =+[5]김포!$H$92/1000 -> -154.20977 | S11: =+P11-R11 -> 12.461655 | T11: =+[4]김포!$H$86/1000 -> -57.447522 | U11: =+[4]김포!$I$86/1000 -> -99.529529 | V11: =+U11-T11 -> -42.082007 | W11: =+[5]김포!$H$86/1000 -> -107.3369 | X11: =+U11-W11 -> 7.807367 | Y11: =+[4]김포!$H$92/1000 -> -130.98855 | Z11: =+[4]김포!$I$92/1000 -> -141.74812 | AA11: =+Z11-Y11 -> -10.759563 | AB11: =+[5]김포!$H$92/1000 -> -154.20977 | AC11: =+Z11-AB11 -> 12.461655
B12: 부산 | I12: 부산 | J12: =+[4]부산!$H$86/1000 -> 86.20839 | K12: =+[4]부산!$I$86/1000 -> 272.4134 | L12: =+K12-J12 -> 186.20501 | M12: =+[5]부산!$H$86/1000 -> 26.931239 | N12: =+K12-M12 -> 245.48216 | O12: =+[4]부산!$H$92/1000 -> -99.466258 | P12: =+[4]부산!$I$92/1000 -> 94.701169 | Q12: =+P12-O12 -> 194.16743 | R12: =+[5]부산!$H$92/1000 -> -108.26756 | S12: =+P12-R12 -> 202.96873 | T12: =+[4]부산!$H$86/1000 -> 86.20839 | U12: =+[4]부산!$I$86/1000 -> 272.4134 | V12: =+U12-T12 -> 186.20501 | W12: =+[5]부산!$H$86/1000 -> 26.931239 | X12: =+U12-W12 -> 245.48216 | Y12: =+[4]부산!$H$92/1000 -> -99.466258 | Z12: =+[4]부산!$I$92/1000 -> 94.701169 | AA12: =+Z12-Y12 -> 194.16743 | AB12: =+[5]부산!$H$92/1000 -> -108.26756 | AC12: =+Z12-AB12 -> 202.96873
B13: 서부산 | I13: 서부산 | J13: =+[4]서부산!$H$86/1000 -> 138.70125 | K13: =+[4]서부산!$I$86/1000 -> 184.52322 | L13: =+K13-J13 -> 45.821973 | M13: =+[5]서부산!$H$86/1000 -> 35.159033 | N13: =+K13-M13 -> 149.36419 | O13: =+[4]서부산!$H$92/1000 -> -33.57922 | P13: =+[4]서부산!$I$92/1000 -> 62.015125 | Q13: =+P13-O13 -> 95.594345 | R13: =+[5]서부산!$H$92/1000 -> -78.874481 | S13: =+P13-R13 -> 140.88961 | T13: =+[4]서부산!$H$86/1000 -> 138.70125 | U13: =+[4]서부산!$I$86/1000 -> 184.52322 | V13: =+U13-T13 -> 45.821973 | W13: =+[5]서부산!$H$86/1000 -> 35.159033 | X13: =+U13-W13 -> 149.36419 | Y13: =+[4]서부산!$H$92/1000 -> -33.57922 | Z13: =+[4]서부산!$I$92/1000 -> 62.015125 | AA13: =+Z13-Y13 -> 95.594345 | AB13: =+[5]서부산!$H$92/1000 -> -78.874481 | AC13: =+Z13-AB13 -> 140.88961
B14: 김해 | I14: 김해 | J14: =+[4]김해!$H$86/1000 -> -57.016563 | K14: =+[4]김해!$I$86/1000 -> -95.230254 | L14: =+K14-J14 -> -38.213691 | M14: =+[5]김해!$H$86/1000 -> -64.487721 | N14: =+K14-M14 -> -30.742533 | O14: =+[4]김해!$H$92/1000 -> -120.20139 | P14: =+[4]김해!$I$92/1000 -> -123.42139 | Q14: =+P14-O14 -> -3.2200004 | R14: =+[5]김해!$H$92/1000 -> -110.54286 | S14: =+P14-R14 -> -12.878532 | T14: =+[4]김해!$H$86/1000 -> -57.016563 | U14: =+[4]김해!$I$86/1000 -> -95.230254 | V14: =+U14-T14 -> -38.213691 | W14: =+[5]김해!$H$86/1000 -> -64.487721 | X14: =+U14-W14 -> -30.742533 | Y14: =+[4]김해!$H$92/1000 -> -120.20139 | Z14: =+[4]김해!$I$92/1000 -> -123.42139 | AA14: =+Z14-Y14 -> -3.2200004 | AB14: =+[5]김해!$H$92/1000 -> -110.54286 | AC14: =+Z14-AB14 -> -12.878532
B15: 정관 | I15: 정관 | J15: =+[4]정관!$H$86/1000 -> 64.322338 | K15: =+[4]정관!$I$86/1000 -> -66.073097 | L15: =+K15-J15 -> -130.39544 | M15: =+[5]정관!$H$86/1000 -> 94.40849 | N15: =+K15-M15 -> -160.48159 | O15: =+[4]정관!$H$92/1000 -> -117.2623 | P15: =+[4]정관!$I$92/1000 -> -136.61454 | Q15: =+P15-O15 -> -19.352241 | R15: =+[5]정관!$H$92/1000 -> -61.268051 | S15: =+P15-R15 -> -75.346487 | T15: =+[4]정관!$H$86/1000 -> 64.322338 | U15: =+[4]정관!$I$86/1000 -> -66.073097 | V15: =+U15-T15 -> -130.39544 | W15: =+[5]정관!$H$86/1000 -> 94.40849 | X15: =+U15-W15 -> -160.48159 | Y15: =+[4]정관!$H$92/1000 -> -117.2623 | Z15: =+[4]정관!$I$92/1000 -> -136.61454 | AA15: =+Z15-Y15 -> -19.352241 | AB15: =+[5]정관!$H$92/1000 -> -61.268051 | AC15: =+Z15-AB15 -> -75.346487
B16: 양산 | I16: 양산 | J16: =+[4]양산!$H$86/1000 -> -44.19669 | K16: =+[4]양산!$I$86/1000 -> -29.110635 | L16: =+K16-J16 -> 15.086055 | M16: =+[5]양산!$H$86/1000 -> -50.209252 | N16: =+K16-M16 -> 21.098617 | O16: =+[4]양산!$H$92/1000 -> -99.142484 | P16: =+[4]양산!$I$92/1000 -> -64.171547 | Q16: =+P16-O16 -> 34.970937 | R16: =+[5]양산!$H$92/1000 -> -100.63538 | S16: =+P16-R16 -> 36.463832 | T16: =+[4]양산!$H$86/1000 -> -44.19669 | U16: =+[4]양산!$I$86/1000 -> -29.110635 | V16: =+U16-T16 -> 15.086055 | W16: =+[5]양산!$H$86/1000 -> -50.209252 | X16: =+U16-W16 -> 21.098617 | Y16: =+[4]양산!$H$92/1000 -> -99.142484 | Z16: =+[4]양산!$I$92/1000 -> -64.171547 | AA16: =+Z16-Y16 -> 34.970937 | AB16: =+[5]양산!$H$92/1000 -> -100.63538 | AC16: =+Z16-AB16 -> 36.463832
B17: 창원 | I17: 창원 | J17: =+[4]창원!$H$86/1000 -> -34.965427 | K17: =+[4]창원!$I$86/1000 -> 6.97758 | L17: =+K17-J17 -> 41.943007 | M17: =+[5]창원!$H$86/1000 -> 7.209117 | N17: =+K17-M17 -> -0.231537 | O17: =+[4]창원!$H$92/1000 -> -115.09261 | P17: =+[4]창원!$I$92/1000 -> -45.638644 | Q17: =+P17-O17 -> 69.453968 | R17: =+[5]창원!$H$92/1000 -> -78.364887 | S17: =+P17-R17 -> 32.726242 | T17: =+[4]창원!$H$86/1000 -> -34.965427 | U17: =+[4]창원!$I$86/1000 -> 6.97758 | V17: =+U17-T17 -> 41.943007 | W17: =+[5]창원!$H$86/1000 -> 7.209117 | X17: =+U17-W17 -> -0.231537 | Y17: =+[4]창원!$H$92/1000 -> -115.09261 | Z17: =+[4]창원!$I$92/1000 -> -45.638644 | AA17: =+Z17-Y17 -> 69.453968 | AB17: =+[5]창원!$H$92/1000 -> -78.364887 | AC17: =+Z17-AB17 -> 32.726242
B18: 대구 | I18: 대구 | J18: =+[4]대구!$H$86/1000 -> -49.481991 | K18: =+[4]대구!$I$86/1000 -> -93.809217 | L18: =+K18-J18 -> -44.327226 | M18: =+[5]대구!$H$86/1000 -> 22.030702 | N18: =+K18-M18 -> -115.83992 | O18: =+[4]대구!$H$92/1000 -> -106.14907 | P18: =+[4]대구!$I$92/1000 -> -111.12814 | Q18: =+P18-O18 -> -4.9790751 | R18: =+[5]대구!$H$92/1000 -> -65.102494 | S18: =+P18-R18 -> -46.025647 | T18: =+[4]대구!$H$86/1000 -> -49.481991 | U18: =+[4]대구!$I$86/1000 -> -93.809217 | V18: =+U18-T18 -> -44.327226 | W18: =+[5]대구!$H$86/1000 -> 22.030702 | X18: =+U18-W18 -> -115.83992 | Y18: =+[4]대구!$H$92/1000 -> -106.14907 | Z18: =+[4]대구!$I$92/1000 -> -111.12814 | AA18: =+Z18-Y18 -> -4.9790751 | AB18: =+[5]대구!$H$92/1000 -> -65.102494 | AC18: =+Z18-AB18 -> -46.025647
B19: 울산 | I19: 울산 | J19: =+[4]울산!$H$86/1000 -> -45.89881 | K19: =+[4]울산!$I$86/1000 -> 84.076425 | L19: =+K19-J19 -> 129.97523 | M19: =+[5]울산!$H$86/1000 -> 57.724488 | N19: =+K19-M19 -> 26.351937 | O19: =+[4]울산!$H$92/1000 -> -120.87555 | P19: =+[4]울산!$I$92/1000 -> 2.6963872 | Q19: =+P19-O19 -> 123.57193 | R19: =+[5]울산!$H$92/1000 -> -33.776092 | S19: =+P19-R19 -> 36.472479 | T19: =+[4]울산!$H$86/1000 -> -45.89881 | U19: =+[4]울산!$I$86/1000 -> 84.076425 | V19: =+U19-T19 -> 129.97523 | W19: =+[5]울산!$H$86/1000 -> 57.724488 | X19: =+U19-W19 -> 26.351937 | Y19: =+[4]울산!$H$92/1000 -> -120.87555 | Z19: =+[4]울산!$I$92/1000 -> 2.6963872 | AA19: =+Z19-Y19 -> 123.57193 | AB19: =+[5]울산!$H$92/1000 -> -33.776092 | AC19: =+Z19-AB19 -> 36.472479
B20: 아산 | I20: 아산 | J20: =+[4]아산!$H$86/1000 -> -64.25007 | K20: =+[4]아산!$I$86/1000 -> 3.85639 | L20: =+K20-J20 -> 68.10646 | M20: =+[5]아산!$H$86/1000 -> -30.781557 | N20: =+K20-M20 -> 34.637947 | O20: =+[4]아산!$H$92/1000 -> -154.55142 | P20: =+[4]아산!$I$92/1000 -> -93.686939 | Q20: =+P20-O20 -> 60.864485 | R20: =+[5]아산!$H$92/1000 -> -183.92874 | S20: =+P20-R20 -> 90.241797 | T20: =+[4]아산!$H$86/1000 -> -64.25007 | U20: =+[4]아산!$I$86/1000 -> 3.85639 | V20: =+U20-T20 -> 68.10646 | W20: =+[5]아산!$H$86/1000 -> -30.781557 | X20: =+U20-W20 -> 34.637947 | Y20: =+[4]아산!$H$92/1000 -> -154.55142 | Z20: =+[4]아산!$I$92/1000 -> -93.686939 | AA20: =+Z20-Y20 -> 60.864485 | AB20: =+[5]아산!$H$92/1000 -> -183.92874 | AC20: =+Z20-AB20 -> 90.241797
B21: 전주 | I21: 전주 | J21: =+[4]전주!$H$86/1000 -> -43.61723 | K21: =+[4]전주!$I$86/1000 -> -15.873017 | L21: =+K21-J21 -> 27.744213 | M21: =+[5]전주!$H$86/1000 -> 103.70416 | N21: =+K21-M21 -> -119.57718 | O21: =+[4]전주!$H$92/1000 -> -90.282978 | P21: =+[4]전주!$I$92/1000 -> -69.751996 | Q21: =+P21-O21 -> 20.530983 | R21: =+[5]전주!$H$92/1000 -> 0.16470498 | S21: =+P21-R21 -> -69.916701 | T21: =+[4]전주!$H$86/1000 -> -43.61723 | U21: =+[4]전주!$I$86/1000 -> -15.873017 | V21: =+U21-T21 -> 27.744213 | W21: =+[5]전주!$H$86/1000 -> 103.70416 | X21: =+U21-W21 -> -119.57718 | Y21: =+[4]전주!$H$92/1000 -> -90.282978 | Z21: =+[4]전주!$I$92/1000 -> -69.751996 | AA21: =+Z21-Y21 -> 20.530983 | AB21: =+[5]전주!$H$92/1000 -> 0.16470498 | AC21: =+Z21-AB21 -> -69.916701
B22: 군산 | I22: 군산 | J22: =+[4]군산!$H$86/1000 -> 6.2266766 | K22: =+[4]군산!$I$86/1000 -> 3.845768 | L22: =+K22-J22 -> -2.3809086 | M22: =+[5]군산!$H$86/1000 -> 10.0572 | N22: =+K22-M22 -> -6.211432 | O22: =+[4]군산!$H$92/1000 -> -20.251216 | P22: =+[4]군산!$I$92/1000 -> -12.104515 | Q22: =+P22-O22 -> 8.1467011 | R22: =+[5]군산!$H$92/1000 -> -16.092249 | S22: =+P22-R22 -> 3.9877338 | T22: =+[4]군산!$H$86/1000 -> 6.2266766 | U22: =+[4]군산!$I$86/1000 -> 3.845768 | V22: =+U22-T22 -> -2.3809086 | W22: =+[5]군산!$H$86/1000 -> 10.0572 | X22: =+U22-W22 -> -6.211432 | Y22: =+[4]군산!$H$92/1000 -> -20.251216 | Z22: =+[4]군산!$I$92/1000 -> -12.104515 | AA22: =+Z22-Y22 -> 8.1467011 | AB22: =+[5]군산!$H$92/1000 -> -16.092249 | AC22: =+Z22-AB22 -> 3.9877338
B23: 원주 | I23: 원주 | J23: =+[4]원주!$H$86/1000 -> 18.286728 | K23: =+[4]원주!$I$86/1000 -> 7.133797 | L23: =+K23-J23 -> -11.152931 | M23: =+[5]원주!$H$86/1000 -> -4.029704 | N23: =+K23-M23 -> 11.163501 | O23: =+[4]원주!$H$92/1000 -> -13.209295 | P23: =+[4]원주!$I$92/1000 -> -10.176581 | Q23: =+P23-O23 -> 3.0327141 | R23: =+[5]원주!$H$92/1000 -> -26.154029 | S23: =+P23-R23 -> 15.977447 | T23: =+[4]원주!$H$86/1000 -> 18.286728 | U23: =+[4]원주!$I$86/1000 -> 7.133797 | V23: =+U23-T23 -> -11.152931 | W23: =+[5]원주!$H$86/1000 -> -4.029704 | X23: =+U23-W23 -> 11.163501 | Y23: =+[4]원주!$H$92/1000 -> -13.209295 | Z23: =+[4]원주!$I$92/1000 -> -10.176581 | AA23: =+Z23-Y23 -> 3.0327141 | AB23: =+[5]원주!$H$92/1000 -> -26.154029 | AC23: =+Z23-AB23 -> 15.977447
B24: 제주 | I24: 제주 | J24: =+[4]제주!$H$86/1000 -> 51.136169 | K24: =+[4]제주!$I$86/1000 -> 2.638132 | L24: =+K24-J24 -> -48.498037 | M24: =+[5]제주!$H$86/1000 -> 68.396145 | N24: =+K24-M24 -> -65.758013 | O24: =+[4]제주!$H$92/1000 -> -15.398707 | P24: =+[4]제주!$I$92/1000 -> -27.849297 | Q24: =+P24-O24 -> -12.450591 | R24: =+[5]제주!$H$92/1000 -> 3.7956202 | S24: =+P24-R24 -> -31.644918 | T24: =+[4]제주!$H$86/1000 -> 51.136169 | U24: =+[4]제주!$I$86/1000 -> 2.638132 | V24: =+U24-T24 -> -48.498037 | W24: =+[5]제주!$H$86/1000 -> 68.396145 | X24: =+U24-W24 -> -65.758013 | Y24: =+[4]제주!$H$92/1000 -> -15.398707 | Z24: =+[4]제주!$I$92/1000 -> -27.849297 | AA24: =+Z24-Y24 -> -12.450591 | AB24: =+[5]제주!$H$92/1000 -> 3.7956202 | AC24: =+Z24-AB24 -> -31.644918
I25: 수도권 | J25: =SUM(J8:J11) -> -0.30728829 | K25: =SUM(K8:K11) -> -16.389475 | L25: =+K25-J25 -> -16.082187 | M25: =SUM(M8:M11) -> -252.9741 | N25: =+K25-M25 -> 236.58462 | O25: =SUM(O8:O11) -> -652.00863 | P25: =SUM(P8:P11) -> -467.31573 | Q25: =+P25-O25 -> 184.6929 | R25: =SUM(R8:R11) -> -755.00626 | S25: =+P25-R25 -> 287.69053 | T25: =SUM(T8:T11) -> -0.30728829 | U25: =SUM(U8:U11) -> -16.389475 | V25: =+U25-T25 -> -16.082187 | W25: =SUM(W8:W11) -> -252.9741 | X25: =+U25-W25 -> 236.58462 | Y25: =SUM(Y8:Y11) -> -652.00863 | Z25: =SUM(Z8:Z11) -> -467.31573 | AA25: =+Z25-Y25 -> 184.6929 | AB25: =SUM(AB8:AB11) -> -755.00626 | AC25: =+Z25-AB25 -> 287.69053
I26: 영남권 | J26: =SUM(J12:J19) -> 57.672495 | K26: =SUM(K12:K19) -> 263.76743 | L26: =+K26-J26 -> 206.09493 | M26: =SUM(M12:M19) -> 128.7661 | N26: =+K26-M26 -> 135.00133 | O26: =SUM(O12:O19) -> -811.76887 | P26: =SUM(P12:P19) -> -321.56158 | Q26: =+P26-O26 -> 490.20729 | R26: =SUM(R12:R19) -> -636.8318 | S26: =+P26-R26 -> 315.27022 | T26: =SUM(T12:T19) -> 57.672495 | U26: =SUM(U12:U19) -> 263.76743 | V26: =+U26-T26 -> 206.09493 | W26: =SUM(W12:W19) -> 128.7661 | X26: =+U26-W26 -> 135.00133 | Y26: =SUM(Y12:Y19) -> -811.76887 | Z26: =SUM(Z12:Z19) -> -321.56158 | AA26: =+Z26-Y26 -> 490.20729 | AB26: =SUM(AB12:AB19) -> -636.8318 | AC26: =+Z26-AB26 -> 315.27022
I27: 중부권 | J27: =SUM(J20:J24) -> -32.217726 | K27: =SUM(K20:K24) -> 1.60107 | L27: =+K27-J27 -> 33.818796 | M27: =SUM(M20:M24) -> 147.34624 | N27: =+K27-M27 -> -145.74517 | O27: =SUM(O20:O24) -> -293.69362 | P27: =SUM(P20:P24) -> -213.56933 | Q27: =+P27-O27 -> 80.124292 | R27: =SUM(R20:R24) -> -222.21469 | S27: =+P27-R27 -> 8.6453603 | T27: =SUM(T20:T24) -> -32.217726 | U27: =SUM(U20:U24) -> 1.60107 | V27: =+U27-T27 -> 33.818796 | W27: =SUM(W20:W24) -> 147.34624 | X27: =+U27-W27 -> -145.74517 | Y27: =SUM(Y20:Y24) -> -293.69362 | Z27: =SUM(Z20:Z24) -> -213.56933 | AA27: =+Z27-Y27 -> 80.124292 | AB27: =SUM(AB20:AB24) -> -222.21469 | AC27: =+Z27-AB27 -> 8.6453603
H28: 레미콘 계 | J28: =SUM(J25:J27) -> 25.147481 | K28: =SUM(K25:K27) -> 248.97902 | L28: =+K28-J28 -> 223.83154 | M28: =SUM(M25:M27) -> 23.138241 | N28: =+K28-M28 -> 225.84078 | O28: =SUM(O25:O27) -> -1757.4711 | P28: =SUM(P25:P27) -> -1002.4466 | Q28: =+P28-O28 -> 755.02449 | R28: =SUM(R25:R27) -> -1614.0527 | S28: =+P28-R28 -> 611.60611 | T28: =SUM(T25:T27) -> 25.147481 | U28: =SUM(U25:U27) -> 248.97902 | V28: =+U28-T28 -> 223.83154 | W28: =SUM(W25:W27) -> 23.138241 | X28: =+U28-W28 -> 225.84078 | Y28: =SUM(Y25:Y27) -> -1757.4711 | Z28: =SUM(Z25:Z27) -> -1002.4466 | AA28: =+Z28-Y28 -> 755.02449 | AB28: =SUM(AB25:AB27) -> -1614.0527 | AC28: =+Z28-AB28 -> 611.60611

Sheet 사업장별(당월)
H3: □ 사업장별 손익실적(2026-01)
AG4: [단위 : 천㎥, 톤, 백만원]
H5: 구분 | J5: 물량 | O5: 매출 | T5: 영업이익(공통비 배부전) | Y5: 판매단가 | AB5: 변동비 | AE5: 공헌이익
A6: 2024년 1월 마감 손익 | J6: 계획 | K6: 실적 | L6: 차이 | M6: 전년 | N6: 차이 | O6: 계획 | P6: 실적 | Q6: 차이 | R6: 전년 | S6: 차이 | T6: 계획 | U6: 실적 | V6: 차이 | W6: 전년 | X6: 차이 | Y6: 계획 | Z6: 실적 | AA6: 전년 | AB6: 계획 | AC6: 실적 | AD6: 전년 | AE6: 계획 | AF6: 실적 | AG6: 전년
B7: 안양 | G7: =+I7 -> 안양 | H7: 레미콘 | I7: 안양 | J7: =+IFERROR(HLOOKUP($B7,'[1]1월'!$D$6:$BN$259,2,),)/1000 -> 29 | K7: =+IFERROR(HLOOKUP($B7,'[2]1월'!$F$6:$CP$99,2,),)/1000 -> 30.862 | L7: =+K7-J7 -> 1.862 | M7: =+IFERROR(HLOOKUP($B7,'[3]1월'!$F$6:$CC$57,2,),)/1000 -> 27.197 | N7: =+K7-M7 -> 3.665 | O7: =+IFERROR(HLOOKUP($B7,'[1]1월'!$D$6:$BN$259,3,),)/1000 -> 2871.9846 | P7: =+IFERROR(HLOOKUP($B7,'[2]1월'!$F$6:$CP$99,3,),)/1000 -> 3337.1809 | Q7: =+P7-O7 -> 465.19629 | R7: =+IFERROR(HLOOKUP($B7,'[3]1월'!$F$6:$CC$57,3,),)/1000 -> 2706.27 | S7: =+P7-R7 -> 630.91088 | T7: =+IFERROR(HLOOKUP($B7,'[1]1월'!$D$6:$BN$259,16,),)/1000 -> 174.44457 | U7: =+IFERROR(HLOOKUP($B7,'[2]1월'!$F$6:$CP$99,16,),)/1000 -> 231.23201 | V7: =+U7-T7 -> 56.787441 | W7: =+IFERROR(HLOOKUP($B7,'[3]1월'!$F$6:$CC$57,16,),)/1000 -> 88.057685 | X7: =+U7-W7 -> 143.17433 | Y7: =+[4]안양!$Q$85 -> 99033.952 | Z7: =+[4]안양!$R$85 -> 108132.36 | AA7: =+[5]안양!$Q$85 -> 99506.197 | AB7: =+[4]안양!$Q$89 -> 81955.946 | AC7: =+[4]안양!$R$89 -> 90380.612 | AD7: =+[5]안양!$Q$89 -> 84769.104 | AE7: =+Y7-AB7 -> 17078.007 | AF7: =+Z7-AC7 -> 17751.749 | AG7: =+AA7-AD7 -> 14737.092
B8: 인천 | G8: =+I8 -> 인천 | H8: 직영 | I8: 인천 | J8: =+IFERROR(HLOOKUP($B8,'[1]1월'!$D$6:$BN$259,2,),)/1000 -> 25 | K8: =+IFERROR(HLOOKUP($B8,'[2]1월'!$F$6:$CP$99,2,),)/1000 -> 21.869 | L8: =+K8-J8 -> -3.131 | M8: =+IFERROR(HLOOKUP($B8,'[3]1월'!$F$6:$CC$57,2,),)/1000 -> 15.904 | N8: =+K8-M8 -> 5.965 | O8: =+IFERROR(HLOOKUP($B8,'[1]1월'!$D$6:$BN$259,3,),)/1000 -> 2502.8505 | P8: =+IFERROR(HLOOKUP($B8,'[2]1월'!$F$6:$CP$99,3,),)/1000 -> 2222.7002 | Q8: =+P8-O8 -> -280.15033 | R8: =+IFERROR(HLOOKUP($B8,'[3]1월'!$F$6:$CC$57,3,),)/1000 -> 1602.2818 | S8: =+P8-R8 -> 620.41836 | T8: =+IFERROR(HLOOKUP($B8,'[1]1월'!$D$6:$BN$259,16,),)/1000 -> -29.440006 | U8: =+IFERROR(HLOOKUP($B8,'[2]1월'!$F$6:$CP$99,16,),)/1000 -> -30.5667 | V8: =+U8-T8 -> -1.1266943 | W8: =+IFERROR(HLOOKUP($B8,'[3]1월'!$F$6:$CC$57,16,),)/1000 -> -127.14974 | X8: =+U8-W8 -> 96.583042 | Y8: =+[4]인천!$Q$85 -> 100114.02 | Z8: =+[4]인천!$R$85 -> 101637.03 | AA8: =+[5]인천!$Q$85 -> 100747.1 | AB8: =+[4]인천!$Q$89 -> 86964.531 | AC8: =+[4]인천!$R$89 -> 89925.952 | AD8: =+[5]인천!$Q$89 -> 88700.837 | AE8: =+Y8-AB8 -> 13149.489 | AF8: =+Z8-AC8 -> 11711.076 | AG8: =+AA8-AD8 -> 12046.259
B9: 파주 | G9: =+I9 -> 파주 | I9: 파주 | J9: =+IFERROR(HLOOKUP($B9,'[1]1월'!$D$6:$BN$259,2,),)/1000 -> 10 | K9: =+IFERROR(HLOOKUP($B9,'[2]1월'!$F$6:$CP$99,2,),)/1000 -> 7.45 | L9: =+K9-J9 -> -2.55 | M9: =+IFERROR(HLOOKUP($B9,'[3]1월'!$F$6:$CC$57,2,),)/1000 -> 8.443 | N9: =+K9-M9 -> -0.993 | O9: =+IFERROR(HLOOKUP($B9,'[1]1월'!$D$6:$BN$259,3,),)/1000 -> 945.66955 | P9: =+IFERROR(HLOOKUP($B9,'[2]1월'!$F$6:$CP$99,3,),)/1000 -> 749.9882 | Q9: =+P9-O9 -> -195.68135 | R9: =+IFERROR(HLOOKUP($B9,'[3]1월'!$F$6:$CC$57,3,),)/1000 -> 801.1718 | S9: =+P9-R9 -> -51.1836 | T9: =+IFERROR(HLOOKUP($B9,'[1]1월'!$D$6:$BN$259,16,),)/1000 -> -87.864332 | U9: =+IFERROR(HLOOKUP($B9,'[2]1월'!$F$6:$CP$99,16,),)/1000 -> -117.52526 | V9: =+U9-T9 -> -29.660927 | W9: =+IFERROR(HLOOKUP($B9,'[3]1월'!$F$6:$CC$57,16,),)/1000 -> -106.54515 | X9: =+U9-W9 -> -10.980112 | Y9: =+[4]파주!$Q$85 -> 94566.955 | Z9: =+[4]파주!$R$85 -> 100634.01 | AA9: =+[5]파주!$Q$85 -> 94891.839 | AB9: =+[4]파주!$Q$89 -> 80036.984 | AC9: =+[4]파주!$R$89 -> 89104.397 | AD9: =+[5]파주!$Q$89 -> 79812.611 | AE9: =+Y9-AB9 -> 14529.971 | AF9: =+Z9-AC9 -> 11529.613 | AG9: =+AA9-AD9 -> 15079.228
B10: 김포 | G10: =+I10 -> 김포 | I10: 김포 | J10: =+IFERROR(HLOOKUP($B10,'[1]1월'!$D$6:$BN$259,2,),)/1000 -> 8 | K10: =+IFERROR(HLOOKUP($B10,'[2]1월'!$F$6:$CP$99,2,),)/1000 -> 6.636 | L10: =+K10-J10 -> -1.364 | M10: =+IFERROR(HLOOKUP($B10,'[3]1월'!$F$6:$CC$57,2,),)/1000 -> 5.3845 | N10: =+K10-M10 -> 1.2515 | O10: =+IFERROR(HLOOKUP($B10,'[1]1월'!$D$6:$BN$259,3,),)/1000 -> 803.95768 | P10: =+IFERROR(HLOOKUP($B10,'[2]1월'!$F$6:$CP$99,3,),)/1000 -> 651.79537 | Q10: =+P10-O10 -> -152.16231 | R10: =+IFERROR(HLOOKUP($B10,'[3]1월'!$F$6:$CC$57,3,),)/1000 -> 526.20577 | S10: =+P10-R10 -> 125.5896 | T10: =+IFERROR(HLOOKUP($B10,'[1]1월'!$D$6:$BN$259,16,),)/1000 -> -57.447522 | U10: =+IFERROR(HLOOKUP($B10,'[2]1월'!$F$6:$CP$99,16,),)/1000 -> -99.529529 | V10: =+U10-T10 -> -42.082007 | W10: =+IFERROR(HLOOKUP($B10,'[3]1월'!$F$6:$CC$57,16,),)/1000 -> -107.3369 | X10: =+U10-W10 -> 7.807367 | Y10: =+[4]김포!$Q$85 -> 100494.71 | Z10: =+[4]김포!$R$85 -> 98214.709 | AA10: =+[5]김포!$Q$85 -> 97726.022 | AB10: =+[4]김포!$Q$89 -> 82602.962 | AC10: =+[4]김포!$R$89 -> 87320.72 | AD10: =+[5]김포!$Q$89 -> 86838.295 | AE10: =+Y10-AB10 -> 17891.748 | AF10: =+Z10-AC10 -> 10893.99 | AG10: =+AA10-AD10 -> 10887.727
B11: 부산 | G11: =+I11 -> 부산 | I11: 부산 | J11: =+IFERROR(HLOOKUP($B11,'[1]1월'!$D$6:$BN$259,2,),)/1000 -> 18 | K11: =+IFERROR(HLOOKUP($B11,'[2]1월'!$F$6:$CP$99,2,),)/1000 -> 21.564 | L11: =+K11-J11 -> 3.564 | M11: =+IFERROR(HLOOKUP($B11,'[3]1월'!$F$6:$CC$57,2,),)/1000 -> 13.731 | N11: =+K11-M11 -> 7.833 | O11: =+IFERROR(HLOOKUP($B11,'[1]1월'!$D$6:$BN$259,3,),)/1000 -> 1941.1559 | P11: =+IFERROR(HLOOKUP($B11,'[2]1월'!$F$6:$CP$99,3,),)/1000 -> 2569.2349 | Q11: =+P11-O11 -> 628.07898 | R11: =+IFERROR(HLOOKUP($B11,'[3]1월'!$F$6:$CC$57,3,),)/1000 -> 1446.2366 | S11: =+P11-R11 -> 1122.9983 | T11: =+IFERROR(HLOOKUP($B11,'[1]1월'!$D$6:$BN$259,16,),)/1000 -> 86.20839 | U11: =+IFERROR(HLOOKUP($B11,'[2]1월'!$F$6:$CP$99,16,),)/1000 -> 272.4134 | V11: =+U11-T11 -> 186.20501 | W11: =+IFERROR(HLOOKUP($B11,'[3]1월'!$F$6:$CC$57,16,),)/1000 -> 26.931239 | X11: =+U11-W11 -> 245.48216 | Y11: =+[4]부산!$Q$85 -> 107842 | Z11: =+[4]부산!$R$85 -> 119144.63 | AA11: =+[5]부산!$Q$85 -> 105326.39 | AB11: =+[4]부산!$Q$89 -> 86918.198 | AC11: =+[4]부산!$R$89 -> 94848.512 | AD11: =+[5]부산!$Q$89 -> 84695.366 | AE11: =+Y11-AB11 -> 20923.797 | AF11: =+Z11-AC11 -> 24296.123 | AG11: =+AA11-AD11 -> 20631.019
B12: 서부산 | G12: =+I12 -> 서부산 | I12: 서부산 | J12: =+IFERROR(HLOOKUP($B12,'[1]1월'!$D$6:$BN$259,2,),)/1000 -> 18 | K12: =+IFERROR(HLOOKUP($B12,'[2]1월'!$F$6:$CP$99,2,),)/1000 -> 16.48 | L12: =+K12-J12 -> -1.52 | M12: =+IFERROR(HLOOKUP($B12,'[3]1월'!$F$6:$CC$57,2,),)/1000 -> 12.446 | N12: =+K12-M12 -> 4.034 | O12: =+IFERROR(HLOOKUP($B12,'[1]1월'!$D$6:$BN$259,3,),)/1000 -> 1801.125 | P12: =+IFERROR(HLOOKUP($B12,'[2]1월'!$F$6:$CP$99,3,),)/1000 -> 1771.1334 | Q12: =+P12-O12 -> -29.991591 | R12: =+IFERROR(HLOOKUP($B12,'[3]1월'!$F$6:$CC$57,3,),)/1000 -> 1219.8292 | S12: =+P12-R12 -> 551.30421 | T12: =+IFERROR(HLOOKUP($B12,'[1]1월'!$D$6:$BN$259,16,),)/1000 -> 138.70125 | U12: =+IFERROR(HLOOKUP($B12,'[2]1월'!$F$6:$CP$99,16,),)/1000 -> 184.52322 | V12: =+U12-T12 -> 45.821973 | W12: =+IFERROR(HLOOKUP($B12,'[3]1월'!$F$6:$CC$57,16,),)/1000 -> 35.159033 | X12: =+U12-W12 -> 149.36419 | Y12: =+[4]서부산!$Q$85 -> 100062.5 | Z12: =+[4]서부산!$R$85 -> 107459.83 | AA12: =+[5]서부산!$Q$85 -> 98009.738 | AB12: =+[4]서부산!$Q$89 -> 78653.719 | AC12: =+[4]서부산!$R$89 -> 82419.854 | AD12: =+[5]서부산!$Q$89 -> 77288.175 | AE12: =+Y12-AB12 -> 21408.781 | AF12: =+Z12-AC12 -> 25039.977 | AG12: =+AA12-AD12 -> 20721.563
B13: 김해 | G13: =+I13 -> 김해 | I13: 김해 | J13: =+IFERROR(HLOOKUP($B13,'[1]1월'!$D$6:$BN$259,2,),)/1000 -> 7 | K13: =+IFERROR(HLOOKUP($B13,'[2]1월'!$F$6:$CP$99,2,),)/1000 -> 4.548 | L13: =+K13-J13 -> -2.452 | M13: =+IFERROR(HLOOKUP($B13,'[3]1월'!$F$6:$CC$57,2,),)/1000 -> 5.217 | N13: =+K13-M13 -> -0.669 | O13: =+IFERROR(HLOOKUP($B13,'[1]1월'!$D$6:$BN$259,3,),)/1000 -> 660.57265 | P13: =+IFERROR(HLOOKUP($B13,'[2]1월'!$F$6:$CP$99,3,),)/1000 -> 407.567 | Q13: =+P13-O13 -> -253.00565 | R13: =+IFERROR(HLOOKUP($B13,'[3]1월'!$F$6:$CC$57,3,),)/1000 -> 492.6569 | S13: =+P13-R13 -> -85.0899 | T13: =+IFERROR(HLOOKUP($B13,'[1]1월'!$D$6:$BN$259,16,),)/1000 -> -57.016563 | U13: =+IFERROR(HLOOKUP($B13,'[2]1월'!$F$6:$CP$99,16,),)/1000 -> -95.230254 | V13: =+U13-T13 -> -38.213691 | W13: =+IFERROR(HLOOKUP($B13,'[3]1월'!$F$6:$CC$57,16,),)/1000 -> -64.487721 | X13: =+U13-W13 -> -30.742533 | Y13: =+[4]김해!$Q$85 -> 94367.521 | Z13: =+[4]김해!$R$85 -> 89614.556 | AA13: =+[5]김해!$Q$85 -> 94432.372 | AB13: =+[4]김해!$Q$89 -> 80102.378 | AC13: =+[4]김해!$R$89 -> 79980.794 | AD13: =+[5]김해!$Q$89 -> 76391.455 | AE13: =+Y13-AB13 -> 14265.143 | AF13: =+Z13-AC13 -> 9633.7617 | AG13: =+AA13-AD13 -> 18040.917
B14: 정관 | G14: =+I14 -> 정관 | I14: 정관 | J14: =+IFERROR(HLOOKUP($B14,'[1]1월'!$D$6:$BN$259,2,),)/1000 -> 19 | K14: =+IFERROR(HLOOKUP($B14,'[2]1월'!$F$6:$CP$99,2,),)/1000 -> 10.089 | L14: =+K14-J14 -> -8.911 | M14: =+IFERROR(HLOOKUP($B14,'[3]1월'!$F$6:$CC$57,2,),)/1000 -> 16.167 | N14: =+K14-M14 -> -6.078 | O14: =+IFERROR(HLOOKUP($B14,'[1]1월'!$D$6:$BN$259,3,),)/1000 -> 1898.3964 | P14: =+IFERROR(HLOOKUP($B14,'[2]1월'!$F$6:$CP$99,3,),)/1000 -> 1019.8371 | Q14: =+P14-O14 -> -878.55932 | R14: =+IFERROR(HLOOKUP($B14,'[3]1월'!$F$6:$CC$57,3,),)/1000 -> 1665.2893 | S14: =+P14-R14 -> -645.4522 | T14: =+IFERROR(HLOOKUP($B14,'[1]1월'!$D$6:$BN$259,16,),)/1000 -> 64.322338 | U14: =+IFERROR(HLOOKUP($B14,'[2]1월'!$F$6:$CP$99,16,),)/1000 -> -66.073097 | V14: =+U14-T14 -> -130.39544 | W14: =+IFERROR(HLOOKUP($B14,'[3]1월'!$F$6:$CC$57,16,),)/1000 -> 94.40849 | X14: =+U14-W14 -> -160.48159 | Y14: =+[4]정관!$Q$85 -> 99915.601 | Z14: =+[4]정관!$R$85 -> 101084.06 | AA14: =+[5]정관!$Q$85 -> 103005.46 | AB14: =+[4]정관!$Q$89 -> 83851.178 | AC14: =+[4]정관!$R$89 -> 86691.466 | AD14: =+[5]정관!$Q$89 -> 85293.934 | AE14: =+Y14-AB14 -> 16064.423 | AF14: =+Z14-AC14 -> 14392.596 | AG14: =+AA14-AD14 -> 17711.527
B15: 양산 | G15: =+I15 -> 양산 | I15: 양산 | J15: =+IFERROR(HLOOKUP($B15,'[1]1월'!$D$6:$BN$259,2,),)/1000 -> 6 | K15: =+IFERROR(HLOOKUP($B15,'[2]1월'!$F$6:$CP$99,2,),)/1000 -> 5.181 | L15: =+K15-J15 -> -0.819 | M15: =+IFERROR(HLOOKUP($B15,'[3]1월'!$F$6:$CC$57,2,),)/1000 -> 5.826 | N15: =+K15-M15 -> -0.645 | O15: =+IFERROR(HLOOKUP($B15,'[1]1월'!$D$6:$BN$259,3,),)/1000 -> 574.43681 | P15: =+IFERROR(HLOOKUP($B15,'[2]1월'!$F$6:$CP$99,3,),)/1000 -> 506.8853 | Q15: =+P15-O15 -> -67.551515 | R15: =+IFERROR(HLOOKUP($B15,'[3]1월'!$F$6:$CC$57,3,),)/1000 -> 539.4139 | S15: =+P15-R15 -> -32.5286 | T15: =+IFERROR(HLOOKUP($B15,'[1]1월'!$D$6:$BN$259,16,),)/1000 -> -44.19669 | U15: =+IFERROR(HLOOKUP($B15,'[2]1월'!$F$6:$CP$99,16,),)/1000 -> -29.110635 | V15: =+U15-T15 -> 15.086055 | W15: =+IFERROR(HLOOKUP($B15,'[3]1월'!$F$6:$CC$57,16,),)/1000 -> -50.209252 | X15: =+U15-W15 -> 21.098617 | Y15: =+[4]양산!$Q$85 -> 95739.469 | Z15: =+[4]양산!$R$85 -> 97835.418 | AA15: =+[5]양산!$Q$85 -> 92587.35 | AB15: =+[4]양산!$Q$89 -> 77007.957 | AC15: =+[4]양산!$R$89 -> 79768.281 | AD15: =+[5]양산!$Q$89 -> 75380.246 | AE15: =+Y15-AB15 -> 18731.512 | AF15: =+Z15-AC15 -> 18067.137 | AG15: =+AA15-AD15 -> 17207.103
B16: 창원 | G16: =+I16 -> 창원 | I16: 창원 | J16: =+IFERROR(HLOOKUP($B16,'[1]1월'!$D$6:$BN$259,2,),)/1000 -> 8.5 | K16: =+IFERROR(HLOOKUP($B16,'[2]1월'!$F$6:$CP$99,2,),)/1000 -> 7.5 | L16: =+K16-J16 -> -1 | M16: =+IFERROR(HLOOKUP($B16,'[3]1월'!$F$6:$CC$57,2,),)/1000 -> 9.07 | N16: =+K16-M16 -> -1.57 | O16: =+IFERROR(HLOOKUP($B16,'[1]1월'!$D$6:$BN$259,3,),)/1000 -> 837.69842 | P16: =+IFERROR(HLOOKUP($B16,'[2]1월'!$F$6:$CP$99,3,),)/1000 -> 760.6873 | Q16: =+P16-O16 -> -77.011123 | R16: =+IFERROR(HLOOKUP($B16,'[3]1월'!$F$6:$CC$57,3,),)/1000 -> 915.39465 | S16: =+P16-R16 -> -154.70735 | T16: =+IFERROR(HLOOKUP($B16,'[1]1월'!$D$6:$BN$259,16,),)/1000 -> -34.965427 | U16: =+IFERROR(HLOOKUP($B16,'[2]1월'!$F$6:$CP$99,16,),)/1000 -> 6.97758 | V16: =+U16-T16 -> 41.943007 | W16: =+IFERROR(HLOOKUP($B16,'[3]1월'!$F$6:$CC$57,16,),)/1000 -> 7.209117 | X16: =+U16-W16 -> -0.231537 | Y16: =+[4]창원!$Q$85 -> 98552.756 | Z16: =+[4]창원!$R$85 -> 101424.97 | AA16: =+[5]창원!$Q$85 -> 100925.54 | AB16: =+[4]창원!$Q$89 -> 79280.942 | AC16: =+[4]창원!$R$89 -> 76041.736 | AD16: =+[5]창원!$Q$89 -> 77749.251 | AE16: =+Y16-AB16 -> 19271.813 | AF16: =+Z16-AC16 -> 25383.237 | AG16: =+AA16-AD16 -> 23176.289
B17: 대구 | G17: =+I17 -> 대구 | I17: 대구 | J17: =+IFERROR(HLOOKUP($B17,'[1]1월'!$D$6:$BN$259,2,),)/1000 -> 6.5 | K17: =+IFERROR(HLOOKUP($B17,'[2]1월'!$F$6:$CP$99,2,),)/1000 -> 2.6985 | L17: =+K17-J17 -> -3.8015 | M17: =+IFERROR(HLOOKUP($B17,'[3]1월'!$F$6:$CC$57,2,),)/1000 -> 9.533 | N17: =+K17-M17 -> -6.8345 | O17: =+IFERROR(HLOOKUP($B17,'[1]1월'!$D$6:$BN$259,3,),)/1000 -> 592.43213 | P17: =+IFERROR(HLOOKUP($B17,'[2]1월'!$F$6:$CP$99,3,),)/1000 -> 250.38447 | Q17: =+P17-O17 -> -342.04766 | R17: =+IFERROR(HLOOKUP($B17,'[3]1월'!$F$6:$CC$57,3,),)/1000 -> 932.0735 | S17: =+P17-R17 -> -681.68903 | T17: =+IFERROR(HLOOKUP($B17,'[1]1월'!$D$6:$BN$259,16,),)/1000 -> -49.481991 | U17: =+IFERROR(HLOOKUP($B17,'[2]1월'!$F$6:$CP$99,16,),)/1000 -> -93.809217 | V17: =+U17-T17 -> -44.327226 | W17: =+IFERROR(HLOOKUP($B17,'[3]1월'!$F$6:$CC$57,16,),)/1000 -> 22.030702 | X17: =+U17-W17 -> -115.83992 | Y17: =+[4]대구!$Q$85 -> 91143.404 | Z17: =+[4]대구!$R$85 -> 92786.535 | AA17: =+[5]대구!$Q$85 -> 97773.366 | AB17: =+[4]대구!$Q$89 -> 73245.54 | AC17: =+[4]대구!$R$89 -> 75492.251 | AD17: =+[5]대구!$Q$89 -> 77456.301 | AE17: =+Y17-AB17 -> 17897.864 | AF17: =+Z17-AC17 -> 17294.285 | AG17: =+AA17-AD17 -> 20317.065
B18: 울산 | G18: =+I18 -> 울산 | I18: 울산 | J18: =+IFERROR(HLOOKUP($B18,'[1]1월'!$D$6:$BN$259,2,),)/1000 -> 7.5 | K18: =+IFERROR(HLOOKUP($B18,'[2]1월'!$F$6:$CP$99,2,),)/1000 -> 10.55 | L18: =+K18-J18 -> 3.05 | M18: =+IFERROR(HLOOKUP($B18,'[3]1월'!$F$6:$CC$57,2,),)/1000 -> 9.133 | N18: =+K18-M18 -> 1.417 | O18: =+IFERROR(HLOOKUP($B18,'[1]1월'!$D$6:$BN$259,3,),)/1000 -> 783.85249 | P18: =+IFERROR(HLOOKUP($B18,'[2]1월'!$F$6:$CP$99,3,),)/1000 -> 1176.5337 | Q18: =+P18-O18 -> 392.68121 | R18: =+IFERROR(HLOOKUP($B18,'[3]1월'!$F$6:$CC$57,3,),)/1000 -> 978.7919 | S18: =+P18-R18 -> 197.7418 | T18: =+IFERROR(HLOOKUP($B18,'[1]1월'!$D$6:$BN$259,16,),)/1000 -> -45.89881 | U18: =+IFERROR(HLOOKUP($B18,'[2]1월'!$F$6:$CP$99,16,),)/1000 -> 84.076425 | V18: =+U18-T18 -> 129.97523 | W18: =+IFERROR(HLOOKUP($B18,'[3]1월'!$F$6:$CC$57,16,),)/1000 -> 57.724488 | X18: =+U18-W18 -> 26.351937 | Y18: =+[4]울산!$Q$85 -> 104513.67 | Z18: =+[4]울산!$R$85 -> 111519.78 | AA18: =+[5]울산!$Q$85 -> 107170.91 | AB18: =+[4]울산!$Q$89 -> 87717.198 | AC18: =+[4]울산!$R$89 -> 89406.121 | AD18: =+[5]울산!$Q$89 -> 85147.593 | AE18: =+Y18-AB18 -> 16796.467 | AF18: =+Z18-AC18 -> 22113.661 | AG18: =+AA18-AD18 -> 22023.314
B19: 아산 | G19: =+I19 -> 아산 | I19: 아산 | J19: =+IFERROR(HLOOKUP($B19,'[1]1월'!$D$6:$BN$259,2,),)/1000 -> 10 | K19: =+IFERROR(HLOOKUP($B19,'[2]1월'!$F$6:$CP$99,2,),)/1000 -> 14.503 | L19: =+K19-J19 -> 4.503 | M19: =+IFERROR(HLOOKUP($B19,'[3]1월'!$F$6:$CC$57,2,),)/1000 -> 16.996 | N19: =+K19-M19 -> -2.493 | O19: =+IFERROR(HLOOKUP($B19,'[1]1월'!$D$6:$BN$259,3,),)/1000 -> 987.18316 | P19: =+IFERROR(HLOOKUP($B19,'[2]1월'!$F$6:$CP$99,3,),)/1000 -> 1505.9313 | Q19: =+P19-O19 -> 518.74811 | R19: =+IFERROR(HLOOKUP($B19,'[3]1월'!$F$6:$CC$57,3,),)/1000 -> 1719.2657 | S19: =+P19-R19 -> -213.33447 | T19: =+IFERROR(HLOOKUP($B19,'[1]1월'!$D$6:$BN$259,16,),)/1000 -> -64.25007 | U19: =+IFERROR(HLOOKUP($B19,'[2]1월'!$F$6:$CP$99,16,),)/1000 -> 3.85639 | V19: =+U19-T19 -> 68.10646 | W19: =+IFERROR(HLOOKUP($B19,'[3]1월'!$F$6:$CC$57,16,),)/1000 -> -30.781557 | X19: =+U19-W19 -> 34.637947 | Y19: =+[4]아산!$Q$85 -> 98718.316 | Z19: =+[4]아산!$R$85 -> 103835.85 | AA19: =+[5]아산!$Q$85 -> 101157.08 | AB19: =+[4]아산!$Q$89 -> 80070.67 | AC19: =+[4]아산!$R$89 -> 86561.113 | AD19: =+[5]아산!$Q$89 -> 88061.244 | AE19: =+Y19-AB19 -> 18647.646 | AF19: =+Z19-AC19 -> 17274.732 | AG19: =+AA19-AD19 -> 13095.836
B20: 전주 | G20: =+I20 -> 전주 | I20: 전주 | J20: =+IFERROR(HLOOKUP($B20,'[1]1월'!$D$6:$BN$259,2,),)/1000 -> 5 | K20: =+IFERROR(HLOOKUP($B20,'[2]1월'!$F$6:$CP$99,2,),)/1000 -> 8.1605 | L20: =+K20-J20 -> 3.1605 | M20: =+IFERROR(HLOOKUP($B20,'[3]1월'!$F$6:$CC$57,2,),)/1000 -> 12.05 | N20: =+K20-M20 -> -3.8895 | O20: =+IFERROR(HLOOKUP($B20,'[1]1월'!$D$6:$BN$259,3,),)/1000 -> 510.15449 | P20: =+IFERROR(HLOOKUP($B20,'[2]1월'!$F$6:$CP$99,3,),)/1000 -> 831.81535 | Q20: =+P20-O20 -> 321.66086 | R20: =+IFERROR(HLOOKUP($B20,'[3]1월'!$F$6:$CC$57,3,),)/1000 -> 1162.3579 | S20: =+P20-R20 -> -330.54259 | T20: =+IFERROR(HLOOKUP($B20,'[1]1월'!$D$6:$BN$259,16,),)/1000 -> -43.61723 | U20: =+IFERROR(HLOOKUP($B20,'[2]1월'!$F$6:$CP$99,16,),)/1000 -> -15.873017 | V20: =+U20-T20 -> 27.744213 | W20: =+IFERROR(HLOOKUP($B20,'[3]1월'!$F$6:$CC$57,16,),)/1000 -> 103.70416 | X20: =+U20-W20 -> -119.57718 | Y20: =+[4]전주!$Q$85 -> 102030.9 | Z20: =+[4]전주!$R$85 -> 101995.86 | AA20: =+[5]전주!$Q$85 -> 96461.24 | AB20: =+[4]전주!$Q$89 -> 79728.812 | AC20: =+[4]전주!$R$89 -> 84565.635 | AD20: =+[5]전주!$Q$89 -> 74948.096 | AE20: =+Y20-AB20 -> 22302.086 | AF20: =+Z20-AC20 -> 17430.223 | AG20: =+AA20-AD20 -> 21513.144
B21: 군산 | G21: =+I21 -> 군산 | I21: 군산 | J21: =+IFERROR(HLOOKUP($B21,'[1]1월'!$D$6:$BN$259,2,),)/1000 -> 2.5 | K21: =+IFERROR(HLOOKUP($B21,'[2]1월'!$F$6:$CP$99,2,),)/1000 -> 2.0675 | L21: =+K21-J21 -> -0.4325 | M21: =+IFERROR(HLOOKUP($B21,'[3]1월'!$F$6:$CC$57,2,),)/1000 -> 2.6255 | N21: =+K21-M21 -> -0.558 | O21: =+IFERROR(HLOOKUP($B21,'[1]1월'!$D$6:$BN$259,3,),)/1000 -> 289.45889 | P21: =+IFERROR(HLOOKUP($B21,'[2]1월'!$F$6:$CP$99,3,),)/1000 -> 246.24985 | Q21: =+P21-O21 -> -43.209044 | R21: =+IFERROR(HLOOKUP($B21,'[3]1월'!$F$6:$CC$57,3,),)/1000 -> 293.55978 | S21: =+P21-R21 -> -47.309927 | T21: =+IFERROR(HLOOKUP($B21,'[1]1월'!$D$6:$BN$259,16,),)/1000 -> 6.2266766 | U21: =+IFERROR(HLOOKUP($B21,'[2]1월'!$F$6:$CP$99,16,),)/1000 -> 3.845768 | V21: =+U21-T21 -> -2.3809086 | W21: =+IFERROR(HLOOKUP($B21,'[3]1월'!$F$6:$CC$57,16,),)/1000 -> 10.0572 | X21: =+U21-W21 -> -6.211432 | Y21: =+[4]군산!$Q$85 -> 115783.56 | Z21: =+[4]군산!$R$85 -> 119136.61 | AA21: =+[5]군산!$Q$85 -> 111811 | AB21: =+[4]군산!$Q$89 -> 76852.941 | AC21: =+[4]군산!$R$89 -> 77712.064 | AD21: =+[5]군산!$Q$89 -> 76532.785 | AE21: =+Y21-AB21 -> 38930.616 | AF21: =+Z21-AC21 -> 41424.546 | AG21: =+AA21-AD21 -> 35278.214
B22: 원주 | G22: =+I22 -> 원주 | I22: 원주 | J22: =+IFERROR(HLOOKUP($B22,'[1]1월'!$D$6:$BN$259,2,),)/1000 -> 3 | K22: =+IFERROR(HLOOKUP($B22,'[2]1월'!$F$6:$CP$99,2,),)/1000 -> 2.1455 | L22: =+K22-J22 -> -0.8545 | M22: =+IFERROR(HLOOKUP($B22,'[3]1월'!$F$6:$CC$57,2,),)/1000 -> 2.178 | N22: =+K22-M22 -> -0.0325 | O22: =+IFERROR(HLOOKUP($B22,'[1]1월'!$D$6:$BN$259,3,),)/1000 -> 344.31759 | P22: =+IFERROR(HLOOKUP($B22,'[2]1월'!$F$6:$CP$99,3,),)/1000 -> 267.2478 | Q22: =+P22-O22 -> -77.069785 | R22: =+IFERROR(HLOOKUP($B22,'[3]1월'!$F$6:$CC$57,3,),)/1000 -> 248.3728 | S22: =+P22-R22 -> 18.875 | T22: =+IFERROR(HLOOKUP($B22,'[1]1월'!$D$6:$BN$259,16,),)/1000 -> 18.286728 | U22: =+IFERROR(HLOOKUP($B22,'[2]1월'!$F$6:$CP$99,16,),)/1000 -> 7.133797 | V22: =+U22-T22 -> -11.152931 | W22: =+IFERROR(HLOOKUP($B22,'[3]1월'!$F$6:$CC$57,16,),)/1000 -> -4.029704 | X22: =+U22-W22 -> 11.163501 | Y22: =+[4]원주!$Q$85 -> 114772.53 | Z22: =+[4]원주!$R$85 -> 124562.01 | AA22: =+[5]원주!$Q$85 -> 114037.1 | AB22: =+[4]원주!$Q$89 -> 74865.248 | AC22: =+[4]원주!$R$89 -> 83894.3 | AD22: =+[5]원주!$Q$89 -> 75778.687 | AE22: =+Y22-AB22 -> 39907.28 | AF22: =+Z22-AC22 -> 40667.714 | AG22: =+AA22-AD22 -> 38258.411
B23: 제주 | F23: =+K27-J27 -> -12.8795 | G23: =+I23 -> 제주 | I23: 제주 | J23: =+IFERROR(HLOOKUP($B23,'[1]1월'!$D$6:$BN$259,2,),)/1000 -> 6 | K23: =+IFERROR(HLOOKUP($B23,'[2]1월'!$F$6:$CP$99,2,),)/1000 -> 3.8165 | L23: =+K23-J23 -> -2.1835 | M23: =+IFERROR(HLOOKUP($B23,'[3]1월'!$F$6:$CC$57,2,),)/1000 -> 5.9785 | N23: =+K23-M23 -> -2.162 | O23: =+IFERROR(HLOOKUP($B23,'[1]1월'!$D$6:$BN$259,3,),)/1000 -> 727.36572 | P23: =+IFERROR(HLOOKUP($B23,'[2]1월'!$F$6:$CP$99,3,),)/1000 -> 470.68286 | Q23: =+P23-O23 -> -256.68286 | R23: =+IFERROR(HLOOKUP($B23,'[3]1월'!$F$6:$CC$57,3,),)/1000 -> 725.22047 | S23: =+P23-R23 -> -254.53761 | T23: =+IFERROR(HLOOKUP($B23,'[1]1월'!$D$6:$BN$259,16,),)/1000 -> 51.136169 | U23: =+IFERROR(HLOOKUP($B23,'[2]1월'!$F$6:$CP$99,16,),)/1000 -> 2.638132 | V23: =+U23-T23 -> -48.498037 | W23: =+IFERROR(HLOOKUP($B23,'[3]1월'!$F$6:$CC$57,16,),)/1000 -> 68.396145 | X23: =+U23-W23 -> -65.758013 | Y23: =+[4]제주!$Q$85 -> 121227.62 | Z23: =+[4]제주!$R$85 -> 122993.41 | AA23: =+[5]제주!$Q$85 -> 120069.69 | AB23: =+[4]제주!$Q$89 -> 94798.934 | AC23: =+[4]제주!$R$89 -> 98282.643 | AD23: =+[5]제주!$Q$89 -> 90756.928 | AE23: =+Y23-AB23 -> 26428.686 | AF23: =+Z23-AC23 -> 24710.771 | AG23: =+AA23-AD23 -> 29312.767
F24: =+K24/J24 -> 0.92801389 | G24: =+I24 -> 수도권 | I24: 수도권 | J24: =SUM(J7:J10) -> 72 | K24: =SUM(K7:K10) -> 66.817 | L24: =+K24-J24 -> -5.183 | M24: =SUM(M7:M10) -> 56.9285 | N24: =+K24-M24 -> 9.8885 | O24: =SUM(O7:O10) -> 7124.4623 | P24: =SUM(P7:P10) -> 6961.6646 | Q24: =+P24-O24 -> -162.7977 | R24: =SUM(R7:R10) -> 5635.9294 | S24: =+P24-R24 -> 1325.7352 | T24: =SUM(T7:T10) -> -0.30728829 | U24: =SUM(U7:U10) -> -16.389475 | V24: =+U24-T24 -> -16.082187 | W24: =SUM(W7:W10) -> -252.9741 | X24: =+U24-W24 -> 236.58462 | Y24: =+[4]수도권!$Q$85 -> 98950.866 | Z24: =+[4]수도권!$R$85 -> 104188.77 | AA24: =+[5]수도권!$Q$85 -> 99000.139 | AB24: =+[4]수도권!$Q$89 -> 83500.406 | AC24: =+[4]수도권!$R$89 -> 89783.739 | AD24: =+[5]수도권!$Q$89 -> 85329.992 | AE24: =+Y24-AB24 -> 15450.46 | AF24: =+Z24-AC24 -> 14405.036 | AG24: =+AA24-AD24 -> 13670.147
F25: =+K25/J25 -> 0.86862431 | G25: =+I25 -> 영남권 | I25: 영남권 | J25: =SUM(J11:J18) -> 90.5 | K25: =SUM(K11:K18) -> 78.6105 | L25: =+K25-J25 -> -11.8895 | M25: =SUM(M11:M18) -> 81.123 | N25: =+K25-M25 -> -2.5125 | O25: =SUM(O11:O18) -> 9089.6698 | P25: =SUM(P11:P18) -> 8462.2632 | Q25: =+P25-O25 -> -627.40667 | R25: =SUM(R11:R18) -> 8189.686 | S25: =+P25-R25 -> 272.57723 | T25: =SUM(T11:T18) -> 57.672495 | U25: =SUM(U11:U18) -> 263.76743 | V25: =+U25-T25 -> 206.09493 | W25: =SUM(W11:W18) -> 128.7661 | X25: =+U25-W25 -> 135.00133 | Y25: =+[4]영남권!$Q$85 -> 100438.34 | Z25: =+[4]영남권!$R$85 -> 107645.52 | AA25: =+[5]영남권!$Q$85 -> 100960.81 | AB25: =+[4]영남권!$Q$89 -> 81813.197 | AC25: =+[4]영남권!$R$89 -> 86139.21 | AD25: =+[5]영남권!$Q$89 -> 80802.909 | AE25: =+Y25-AB25 -> 18625.144 | AF25: =+Z25-AC25 -> 21506.306 | AG25: =+AA25-AD25 -> 20157.906
F26: =+K26/J26 -> 1.1582264 | G26: =+I26 -> 중부권 | I26: 중부권 | J26: =SUM(J19:J23) -> 26.5 | K26: =SUM(K19:K23) -> 30.693 | L26: =+K26-J26 -> 4.193 | M26: =SUM(M19:M23) -> 39.828 | N26: =+K26-M26 -> -9.135 | O26: =SUM(O19:O23) -> 2858.4798 | P26: =SUM(P19:P23) -> 3321.9271 | Q26: =+P26-O26 -> 463.44728 | R26: =SUM(R19:R23) -> 4148.7767 | S26: =+P26-R26 -> -826.84959 | T26: =SUM(T19:T23) -> -32.217726 | U26: =SUM(U19:U23) -> 1.60107 | V26: =+U26-T26 -> 33.818796 | W26: =SUM(W19:W23) -> 147.34624 | X26: =+U26-W26 -> -145.74517 | Y26: =+[4]중부권!$Q$85 -> 107867.16 | Z26: =+[4]중부권!$R$85 -> 108148.79 | AA26: =+[5]중부권!$Q$85 -> 103685.34 | AB26: =+[4]중부권!$Q$89 -> 82448.017 | AC26: =+[4]중부권!$R$89 -> 86658.372 | AD26: =+[5]중부권!$Q$89 -> 82924.201 | AE26: =+Y26-AB26 -> 25419.147 | AF26: =+Z26-AC26 -> 21490.416 | AG26: =+AA26-AD26 -> 20761.141
F27: =+K27/M27 -> 0.99011128 | G27: =+K27/J27 -> 0.9318545 | H27: 레미콘 계 | J27: =SUM(J24:J26) -> 189 | K27: =SUM(K24:K26) -> 176.1205 | L27: =+K27-J27 -> -12.8795 | M27: =SUM(M24:M26) -> 177.8795 | N27: =+K27-M27 -> -1.759 | O27: =SUM(O24:O26) -> 19072.612 | P27: =SUM(P24:P26) -> 18745.855 | Q27: =+P27-O27 -> -326.75709 | R27: =SUM(R24:R26) -> 17974.392 | S27: =+P27-R27 -> 771.46287 | T27: =SUM(T24:T26) -> 25.147481 | U27: =SUM(U24:U26) -> 248.97902 | V27: =+U27-T27 -> 223.83154 | W27: =SUM(W24:W26) -> 23.138241 | X27: =+U27-W27 -> 225.84078 | Y27: =+[4]합계!$Q$85 -> 100913.29 | Z27: =+[4]합계!$R$85 -> 106420.86 | AA27: =+[5]합계!$Q$85 -> 100932.18 | AB27: =+[4]합계!$Q$89 -> 82544.952 | AC27: =+[4]합계!$R$89 -> 87610.574 | AD27: =+[5]합계!$Q$89 -> 82701.342 | AE27: =+Y27-AB27 -> 18368.339 | AF27: =+Z27-AC27 -> 18810.282 | AG27: =+AA27-AD27 -> 18230.839 | AI27: =+AF27-AE27 -> 441.94348 | AJ27: =+AF27-AG27 -> 579.44333
B28: 건자재 | E28: 건자재영업 | G28: 건자재 | H28: 골재 | I28: 부산모래장 | J28: =+IFERROR(HLOOKUP($B29,'[1]1월'!$D$6:$BN$259,2,),)/1000 -> 19.75348 | K28: =+IFERROR(HLOOKUP($C29,'[2]1월'!$F$6:$CP$99,2,),)/1000 -> 16.354 | L28: =+K28-J28 -> -3.3994803 | M28: =+IFERROR(HLOOKUP($C29,'[3]1월'!$F$6:$CC$57,2,),)/1000 -> 20.58 | N28: =+K28-M28 -> -4.226 | O28: =+IFERROR(HLOOKUP($B29,'[1]1월'!$D$6:$BN$259,3,),)/1000 -> 562.76833 | P28: =+IFERROR(HLOOKUP($C29,'[2]1월'!$F$6:$CP$99,3,),)/1000 -> 471.3175 | Q28: =+P28-O28 -> -91.45083 | R28: =+IFERROR(HLOOKUP($C29,'[3]1월'!$F$6:$CC$57,3,),)/1000 -> 571.868 | S28: =+P28-R28 -> -100.5505 | T28: =+IFERROR(HLOOKUP($B29,'[1]1월'!$D$6:$BN$259,21,),)/1000 -> 2.7747477 | U28: =+IFERROR(HLOOKUP($C29,'[2]1월'!$F$6:$CP$99,21,),)/1000 -> 25.856171 | V28: =+U28-T28 -> 23.081423 | W28: =+IFERROR(HLOOKUP($C29,'[3]1월'!$F$6:$CC$57,21,),)/1000 -> -2.7785453 | X28: =+U28-W28 -> 28.634716
B29: 부산모래장 | C29: 부산골재 | G29: =+I28 -> 부산모래장 | I29: 서부산CR | J29: =+IFERROR(HLOOKUP($B30,'[1]1월'!$D$6:$BN$259,2,),)/1000 -> 36.787407 | K29: =+IFERROR(HLOOKUP($C30,'[2]1월'!$F$6:$CP$99,2,),)/1000 -> 21.688 | L29: =+K29-J29 -> -15.099407 | M29: =+IFERROR(HLOOKUP($C30,'[3]1월'!$F$6:$CC$57,2,),)/1000 -> 1 | N29: =+K29-M29 -> 20.688 | O29: =+IFERROR(HLOOKUP($B30,'[1]1월'!$D$6:$BN$259,3,),)/1000 -> 477.21191 | P29: =+IFERROR(HLOOKUP($C30,'[2]1월'!$F$6:$CP$99,3,),)/1000 -> 314.32 | Q29: =+P29-O29 -> -162.89191 | R29: =+IFERROR(HLOOKUP($C30,'[3]1월'!$F$6:$CC$57,3,),)/1000 -> 11.5 | S29: =+P29-R29 -> 302.82 | T29: =+IFERROR(HLOOKUP($B30,'[1]1월'!$D$6:$BN$259,21,),)/1000 -> 9.5038904 | U29: =+IFERROR(HLOOKUP($C30,'[2]1월'!$F$6:$CP$99,21,),)/1000 -> -89.060438 | V29: =+U29-T29 -> -98.564328 | W29: =+IFERROR(HLOOKUP($C30,'[3]1월'!$F$6:$CC$57,21,),)/1000 -> -119.39961 | X29: =+U29-W29 -> 30.339168
B30: 서부산크라샤 | C30: 서부산골재 | G30: =+I29 -> 서부산CR | I30: 부산CR | J30: =+IFERROR(HLOOKUP($B31,'[1]1월'!$D$6:$BN$259,2,),)/1000 -> 18.21724 | K30: =+IFERROR(HLOOKUP($C31,'[2]1월'!$F$6:$CP$99,2,),)/1000 -> 17.451 | L30: =+K30-J30 -> -0.76624 | M30: =+IFERROR(HLOOKUP($C31,'[3]1월'!$F$6:$CC$57,2,),)/1000 -> 26.672 | N30: =+K30-M30 -> -9.221 | O30: =+IFERROR(HLOOKUP($B31,'[1]1월'!$D$6:$BN$259,3,),)/1000 -> 367.70836 | P30: =+IFERROR(HLOOKUP($C31,'[2]1월'!$F$6:$CP$99,3,),)/1000 -> 344.1029 | Q30: =+P30-O30 -> -23.60546 | R30: =+IFERROR(HLOOKUP($C31,'[3]1월'!$F$6:$CC$57,3,),)/1000 -> 468.38 | S30: =+P30-R30 -> -124.2771 | T30: =+IFERROR(HLOOKUP($B31,'[1]1월'!$D$6:$BN$259,21,),)/1000 -> -100.77475 | U30: =+IFERROR(HLOOKUP($C31,'[2]1월'!$F$6:$CP$99,21,),)/1000 -> -107.07245 | V30: =+U30-T30 -> -6.2977025 | W30: =+IFERROR(HLOOKUP($C31,'[3]1월'!$F$6:$CC$57,21,),)/1000 -> -157.90931 | X30: =+U30-W30 -> 50.836853
B31: 부산크라샤 | C31: 부산크라샤 | G31: =+I30 -> 부산CR | H31: 골재 계 | J31: =SUM(J28:J30) -> 74.758127 | K31: =SUM(K28:K30) -> 55.493 | L31: =+K31-J31 -> -19.265127 | M31: =SUM(M28:M30) -> 48.252 | N31: =+K31-M31 -> 7.241 | O31: =SUM(O28:O30) -> 1407.6886 | P31: =SUM(P28:P30) -> 1129.7404 | Q31: =+P31-O31 -> -277.9482 | R31: =SUM(R28:R30) -> 1051.748 | S31: =+P31-R31 -> 77.9924 | T31: =SUM(T28:T30) -> -88.496111 | U31: =SUM(U28:U30) -> -170.27672 | V31: =+U31-T31 -> -81.780607 | W31: =SUM(W28:W30) -> -280.08746 | X31: =+U31-W31 -> 109.81074
