Workbook

Sheet 표지
A6: 2024년 12월 마감 손익
A24: 건재사업본부

Sheet 손익총괄
C3: □ 건재사업본부 손익실적(2024-12) | Z3: □ 건재부문 실적(12월)
X4: [단위 : 천㎥, 톤, 원/㎥, 원/톤, 백만원] | AK4: (단위 : 천㎥, 천톤, 억원)
C5: 구분 | E5: 12월 | J5: 12월 누계 | P5: 12월 주요지표 | Z5: 구분 | AB5: =+E5 -> 12월 | AG5: =+J5 -> 12월 누계
A6: 2024년 11월 마감 손익 | E6: 계획 | F6: 실적 | G6: 계획대비 | H6: 전년 | I6: 전년대비 | J6: 계획 | K6: 실적 | L6: 계획대비 | M6: 전년 | N6: 전년대비 | AB6: =+E6 -> 계획 | AC6: =+F6 -> 실적 | AD6: =+G6 -> 계획대비 | AE6: =+H6 -> 전년 | AF6: =+I6 -> 전년대비 | AG6: =+J6 -> 계획 | AH6: =+K6 -> 실적 | AI6: =+L6 -> 계획대비 | ... AK6: =+N6 -> 전년대비
A7: =+F7/E7 -> 0.88549268 | B7: =+K7/J7 -> 0.965208 | C7: 물량 | D7: 레미콘 | E7: =+'[1]12월'!$Z$7/1000 -> 307.5 | F7: =+'[2]12월'!$Z$7/1000 -> 272.289 | G7: =+F7-E7 -> -35.211 | H7: =+'[3]12월'!$Z$7/1000 -> 283.9095 | I7: =+F7-H7 -> -11.6205 | J7: =+[4]손익총괄!J7+E7 -> 3500 | K7: =+[4]손익총괄!K7+F7 -> 3378.228 | L7: =+K7-J7 -> -121.772 | M7: =+[4]손익총괄!M7+H7 -> 3843.6277 | N7: =+K7-M7 -> -465.39968 | Q7: □ 레미콘 | Z7: 물량 | AA7: =+D7 -> 레미콘 | AB7: =+E7 -> 307.5 | AC7: =+F7 -> 272.289 | AD7: =+AC7-AB7 -> -35.211 | AE7: =+H7 -> 283.9095 | AF7: =+AC7-AE7 -> -11.6205 | AG7: =+J7 -> 3500 | AH7: =+K7 -> 3378.228 | AI7: =+AH7-AG7 -> -121.772 | AJ7: =+M7 -> 3843.6277 | AK7: =+AH7-AJ7 -> -465.39968
D8: 철강재 | E8: =+'[1]12월'!$AA$7 -> 8600 | F8: =+'[2]12월'!$AO$7 -> 8003.057 | G8: =+F8-E8 -> -596.943 | H8: =+'[3]12월'!$AO$7 -> 7811.91 | I8: =+F8-H8 -> 191.147 | J8: =+[4]손익총괄!J8+E8 -> 90000 | K8: =+[4]손익총괄!K8+F8 -> 105164.21 | L8: =+K8-J8 -> 15164.211 | M8: =+[4]손익총괄!M8+H8 -> 96546.947 | N8: =+K8-M8 -> 8617.264 | Q8: 구분 | S8: 계획 | T8: 실적 | U8: 계획대비 | V8: 전년 | W8: 전년대비 | AA8: =+D8 -> 철강재 | AB8: =+E8/1000 -> 8.6 | AC8: =+F8/1000 -> 8.003057 | AD8: =+AC8-AB8 -> -0.596943 | AE8: =+H8/1000 -> 7.81191 | AF8: =+AC8-AE8 -> 0.191147 | AG8: =+J8/1000 -> 90 | AH8: =+K8/1000 -> 105.16421 | AI8: =+AH8-AG8 -> 15.164211 | AJ8: =+M8/1000 -> 96.546947 | AK8: =+AH8-AJ8 -> 8.617264
D9: 골재 | E9: =+'[1]12월'!$AE$7/1000 -> 120.90523 | F9: =+'[2]12월'!$AN$7/1000 -> 59.68 | G9: =+F9-E9 -> -61.225227 | H9: =+'[3]12월'!$AN$7/1000 -> 70.233 | I9: =+F9-H9 -> -10.553 | J9: =+[4]손익총괄!J9+E9 -> 1225.9994 | K9: =+[4]손익총괄!K9+F9 -> 840.111 | L9: =+K9-J9 -> -385.88844 | M9: =+[4]손익총괄!M9+H9 -> 848.1 | N9: =+K9-M9 -> -7.989 | Q9: 물량 | R9: 수도권 | S9: =+[5]수도권!$T$5/1000 -> 113.5 | T9: =+[5]수도권!$U$5/1000 -> 94.7535 | U9: =+T9-S9 -> -18.7465 | V9: =+[6]수도권!$T$5/1000 -> 105.14 | W9: =+T9-V9 -> -10.3865 | AA9: =+D9 -> 골재 | AB9: =+E9 -> 120.90523 | AC9: =+F9 -> 59.68 | AD9: =+AC9-AB9 -> -61.225227 | AE9: =+H9 -> 70.233 | AF9: =+AC9-AE9 -> -10.553 | AG9: =+J9 -> 1225.9994 | AH9: =+K9 -> 840.111 | AI9: =+AH9-AG9 -> -385.88844 | AJ9: =+M9 -> 848.1 | AK9: =+AH9-AJ9 -> -7.989
C10: 매출 | D10: 레미콘 | E10: =+'[1]12월'!$Z$8/1000 -> 31719.971 | F10: =+'[2]12월'!$Z$8/1000 -> 27172.709 | G10: =+F10-E10 -> -4547.2616 | H10: =+'[3]12월'!$Z$8/1000 -> 27842.237 | I10: =+F10-H10 -> -669.52837 | J10: =+[4]손익총괄!J10+E10 -> 357471.32 | K10: =+[4]손익총괄!K10+F10 -> 339565.24 | L10: =+K10-J10 -> -17906.082 | M10: =+[4]손익총괄!M10+H10 -> 371786.18 | N10: =+K10-M10 -> -32220.942 | R10: 영남권 | S10: =+[5]영남권!$T$5/1000 -> 138 | T10: =+[5]영남권!$U$5/1000 -> 129.272 | U10: =+T10-S10 -> -8.728 | V10: =+[6]영남권!$T$5/1000 -> 130.01 | W10: =+T10-V10 -> -0.738 | Z10: 매출액 | AA10: =+D10 -> 레미콘 | AB10: =+E10/100 -> 317.19971 | AC10: =+F10/100 -> 271.72709 | AD10: =+AC10-AB10 -> -45.472616 | AE10: =+H10/100 -> 278.42237 | AF10: =+AC10-AE10 -> -6.6952837 | AG10: =+J10/100 -> 3574.7132 | AH10: =+K10/100 -> 3395.6524 | AI10: =+AH10-AG10 -> -179.06082 | AJ10: =+M10/100 -> 3717.8618 | AK10: =+AH10-AJ10 -> -322.20942
D11: 건자재 | E11: =+'[1]12월'!$AA$8/1000 -> 10504.632 | F11: =+'[2]12월'!$AO$8/1000 -> 7445.9016 | G11: =+F11-E11 -> -3058.73 | H11: =+'[3]12월'!$AO$8/1000 -> 9622.7532 | I11: =+F11-H11 -> -2176.8516 | J11: =+[4]손익총괄!J11+E11 -> 110033.79 | K11: =+[4]손익총괄!K11+F11 -> 103999.85 | L11: =+K11-J11 -> -6033.9467 | M11: =+[4]손익총괄!M11+H11 -> 118368.38 | N11: =+K11-M11 -> -14368.53 | R11: 중부권 | S11: =+[5]중부권!$T$5/1000 -> 56 | T11: =+[5]중부권!$U$5/1000 -> 48.2635 | U11: =+T11-S11 -> -7.7365 | V11: =+[6]중부권!$T$5/1000 -> 48.7595 | W11: =+T11-V11 -> -0.496 | AA11: =+D11 -> 건자재 | AB11: =+E11/100 -> 105.04632 | AC11: =+F11/100 -> 74.459016 | AD11: =+AC11-AB11 -> -30.5873 | AE11: =+H11/100 -> 96.227532 | AF11: =+AC11-AE11 -> -21.768516 | AG11: =+J11/100 -> 1100.3379 | AH11: =+K11/100 -> 1039.9985 | AI11: =+AH11-AG11 -> -60.339467 | AJ11: =+M11/100 -> 1183.6838 | AK11: =+AH11-AJ11 -> -143.6853
D12: 골재 | E12: =+'[1]12월'!$AE$8/1000 -> 2204.6877 | F12: =+'[2]12월'!$AN$8/1000 -> 1280.5145 | G12: =+F12-E12 -> -924.17317 | H12: =+'[3]12월'!$AN$8/1000 -> 1401.273 | I12: =+F12-H12 -> -120.7585 | J12: =+[4]손익총괄!J12+E12 -> 23080.254 | K12: =+[4]손익총괄!K12+F12 -> 17070.144 | L12: =+K12-J12 -> -6010.1094 | M12: =+[4]손익총괄!M12+H12 -> 16274.226 | N12: =+K12-M12 -> 795.91768 | Q12: 계 | S12: =SUM(S9:S11) -> 307.5 | T12: =SUM(T9:T11) -> 272.289 | U12: =+T12-S12 -> -35.211 | V12: =SUM(V9:V11) -> 283.9095 | W12: =+T12-V12 -> -11.6205 | AA12: =+D12 -> 골재 | AB12: =+E12/100 -> 22.046877 | AC12: =+F12/100 -> 12.805145 | AD12: =+AC12-AB12 -> -9.2417317 | AE12: =+H12/100 -> 14.01273 | AF12: =+AC12-AE12 -> -1.207585 | AG12: =+J12/100 -> 230.80254 | AH12: =+K12/100 -> 170.70144 | AI12: =+AH12-AG12 -> -60.101094 | AJ12: =+M12/100 -> 162.74226 | AK12: =+AH12-AJ12 -> 7.9591768
D13: 기타 | E13: =+'[1]12월'!$E$8/1000-E10-E11-E12 -> 164.9075 | F13: =+'[2]12월'!$F$8/1000-F10-F11-F12 -> 165.21179 | G13: =+F13-E13 -> 0.30428967 | H13: =+'[3]12월'!$F$8/1000-H10-H11-H12 -> 171.20834 | I13: =+F13-H13 -> -5.996551 | J13: =+[4]손익총괄!J13+E13 -> 1979.49 | K13: =+[4]손익총괄!K13+F13 -> 1986.9073 | L13: =+K13-J13 -> 7.417316 | M13: =+[4]손익총괄!M13+H13 -> 2313.064 | N13: =+K13-M13 -> -326.15667 | Q13: 판매단가 | R13: 수도권 | S13: =+[5]수도권!$T$61 -> 102392.87 | T13: =+[5]수도권!$U$61 -> 95753.183 | U13: =+T13-S13 -> -6639.6874 | V13: =+[6]수도권!$Q$85 -> 97106.847 | W13: =+T13-V13 -> -1353.6641 | AA13: =+D13 -> 기타 | AB13: =+E13/100 -> 1.649075 | AC13: =+F13/100 -> 1.6521179 | AD13: =+AC13-AB13 -> 0.0030428967 | AE13: =+H13/100 -> 1.7120834 | AF13: =+AC13-AE13 -> -0.05996551 | AG13: =+J13/100 -> 19.7949 | AH13: =+K13/100 -> 19.869073 | AI13: =+AH13-AG13 -> 0.07417316 | AJ13: =+M13/100 -> 23.13064 | AK13: =+AH13-AJ13 -> -3.2615667
A14: =+F14/E14 -> 0.80872264 | B14: =+K14/J14 -> 0.9392106 | C14: 계 | E14: =SUM(E10:E13) -> 44594.197 | F14: =SUM(F10:F13) -> 36064.337 | G14: =+F14-E14 -> -8529.8605 | H14: =SUM(H10:H13) -> 39037.472 | I14: =+F14-H14 -> -2973.135 | J14: =SUM(J10:J13) -> 492564.86 | K14: =SUM(K10:K13) -> 462622.14 | L14: =+K14-J14 -> -29942.721 | M14: =SUM(M10:M13) -> 508741.85 | N14: =+K14-M14 -> -46119.711 | R14: 영남권 | S14: =+[5]영남권!$T$61 -> 102613.4 | T14: =+[5]영남권!$U$61 -> 101138.02 | U14: =+T14-S14 -> -1475.3866 | V14: =+[6]영남권!$Q$85 -> 98238.787 | W14: =+T14-V14 -> 2899.2285 | AA14: 계 | AB14: =SUM(AB10:AB13) -> 445.94197 | AC14: =SUM(AC10:AC13) -> 360.64337 | AD14: =+AC14-AB14 -> -85.298605 | AE14: =SUM(AE10:AE13) -> 390.37472 | AF14: =+AC14-AE14 -> -29.73135 | AG14: =SUM(AG10:AG13) -> 4925.6486 | AH14: =SUM(AH10:AH13) -> 4626.2214 | AI14: =+AH14-AG14 -> -299.42721 | AJ14: =SUM(AJ10:AJ13) -> 5087.4185 | AK14: =+AH14-AJ14 -> -461.19711
C15: 매출원가 | D15: 레미콘 | E15: =+('[1]12월'!$Z$10+'[1]12월'!$Z$19)/1000 -> 26400.913 | F15: =+('[2]12월'!$Z$10+'[2]12월'!$Z$19)/1000 -> 25598.441 | G15: =+F15-E15 -> -802.47117 | H15: =+('[3]12월'!$Z$10+'[3]12월'!$Z$19)/1000 -> 26515.438 | I15: =+F15-H15 -> -916.99646 | J15: =+[4]손익총괄!J15+E15 -> 297562.86 | K15: =+[4]손익총괄!K15+F15 -> 297938.73 | L15: =+K15-J15 -> 375.8675 | M15: =+[4]손익총괄!M15+H15 -> 311485.48 | N15: =+K15-M15 -> -13546.746 | R15: 중부권 | S15: =+[5]중부권!$T$61 -> 106030.9 | T15: =+[5]중부권!$U$61 -> 104182.09 | U15: =+T15-S15 -> -1848.8063 | V15: =+[6]중부권!$Q$85 -> 99522.849 | W15: =+T15-V15 -> 4659.2422 | Z15: 영업이익 | AA15: =+D30 -> 레미콘 | AB15: =+E30/100 -> 46.480806 | AC15: =+F30/100 -> 5.6822379 | AD15: =+AC15-AB15 -> -40.798568 | AE15: =+H30/100 -> -1.5238965 | AF15: =+AC15-AE15 -> 7.2061344 | AG15: =+J30/100 -> 519.77524 | AH15: =+K30/100 -> 330.37284 | AI15: =+AH15-AG15 -> -189.4024 | AJ15: =+M30/100 -> 513.90873 | AK15: =+AH15-AJ15 -> -183.53589
D16: 건자재 | E16: =+('[1]12월'!$AA$10+'[1]12월'!$AA$19)/1000 -> 10235.76 | F16: =+('[2]12월'!$AO$10+'[2]12월'!$AO$19)/1000 -> 7310.0571 | G16: =+F16-E16 -> -2925.7032 | H16: =+('[3]12월'!$AO$10+'[3]12월'!$AO$19)/1000 -> 9423.1194 | I16: =+F16-H16 -> -2113.0624 | J16: =+[4]손익총괄!J16+E16 -> 107219.19 | K16: =+[4]손익총괄!K16+F16 -> 101702.99 | L16: =+K16-J16 -> -5516.2026 | M16: =+[4]손익총괄!M16+H16 -> 115981.89 | N16: =+K16-M16 -> -14278.903 | Q16: 계 | S16: =+[5]합계!$T$61 -> 103154.38 | T16: =+[5]합계!$U$61 -> 99802.99 | U16: =+T16-S16 -> -3351.3862 | V16: =+[6]합계!$Q$85 -> 98036.161 | W16: =+T16-V16 -> 1766.8288 | AA16: =+D31 -> % | AB16: =+E31 -> 0.14653483 | AC16: =+F31 -> 0.020911562 | AD16: =+AC16-AB16 -> -0.12562327 | AE16: =+H31 -> -0.0054733264 | AF16: =+AC16-AE16 -> 0.026384888 | AG16: =+J31 -> 0.14540334 | AH16: =+K31 -> 0.097292891 | AI16: =+AH16-AG16 -> -0.048110448 | AJ16: =+M31 -> 0.13822696 | AK16: =+AH16-AJ16 -> -0.040934067
D17: 골재 | E17: =+('[1]12월'!$AE$10+'[1]12월'!$AE$19)/1000 -> 1869.1606 | F17: =+('[2]12월'!$AN$10+'[2]12월'!$AN$19)/1000 -> 1654.2001 | G17: =+F17-E17 -> -214.96049 | H17: =+('[3]12월'!$AN$10+'[3]12월'!$AN$19)/1000 -> 1788.5121 | I17: =+F17-H17 -> -134.31198 | J17: =+[4]손익총괄!J17+E17 -> 20355.934 | K17: =+[4]손익총괄!K17+F17 -> 17064.11 | L17: =+K17-J17 -> -3291.8238 | M17: =+[4]손익총괄!M17+H17 -> 15468.447 | N17: =+K17-M17 -> 1595.6625 | Q17: 공헌이익 | R17: 수도권 | S17: =+[5]수도권!$Q$90 -> 22434.814 | T17: =+[5]수도권!$R$90 -> 11822.292 | U17: =+T17-S17 -> -10612.522 | V17: =+[6]수도권!$Q$90 -> 15397.43 | W17: =+T17-V17 -> -3575.1381 | AA17: =+D32 -> 건자재 | AB17: =+E32/100 -> 1.3904025 | AC17: =+F32/100 -> -1.0110207 | AD17: =+AC17-AB17 -> -2.4014232 | AE17: =+H32/100 -> -0.86633557 | AF17: =+AC17-AE17 -> -0.14468516 | AG17: =+J32/100 -> 13.004307 | AH17: =+K32/100 -> 5.0075828 | AI17: =+AH17-AG17 -> -7.996724 | AJ17: =+M32/100 -> 7.8164686 | AK17: =+AH17-AJ17 -> -2.8088858
D18: 기타 | E18: =+('[1]12월'!$E$10+'[1]12월'!$E$19)/1000-E15-E16-E17 -> 49.561638 | F18: =+('[2]12월'!$F$10+'[2]12월'!$F$19)/1000-F15-F16-F17 -> -311.60497 | G18: =+F18-E18 -> -361.16661 | H18: =+('[3]12월'!$F$10+'[3]12월'!$F$19)/1000-H15-H16-H17 -> -996.93786 | I18: =+F18-H18 -> 685.33289 | J18: =+[4]손익총괄!J18+E18 -> -620.37423 | K18: =+[4]손익총괄!K18+F18 -> -850.21687 | L18: =+K18-J18 -> -229.84264 | M18: =+[4]손익총괄!M18+H18 -> -411.59991 | N18: =+K18-M18 -> -438.61696 | R18: 영남권 | S18: =+[5]영남권!$Q$90 -> 25369.073 | T18: =+[5]영남권!$R$90 -> 19812.809 | U18: =+T18-S18 -> -5556.2633 | V18: =+[6]영남권!$Q$90 -> 19738.655 | W18: =+T18-V18 -> 74.154024 | AA18: =+D33 -> 골재 | AB18: =+E33/100 -> 2.9884234 | AC18: =+F33/100 -> -4.6720224 | AD18: =+AC18-AB18 -> -7.6604457 | AE18: =+H33/100 -> -4.1100052 | AF18: =+AC18-AE18 -> -0.5620171 | AG18: =+J33/100 -> 21.051591 | AH18: =+K33/100 -> -7.6130637 | AI18: =+AH18-AG18 -> -28.664655 | AJ18: =+M33/100 -> 4.8053905 | AK18: =+AH18-AJ18 -> -12.418454
C19: 계 | E19: =SUM(E15:E18) -> 38555.395 | F19: =SUM(F15:F18) -> 34251.094 | G19: =+F19-E19 -> -4304.3015 | H19: =SUM(H15:H18) -> 36730.132 | I19: =+F19-H19 -> -2479.0379 | J19: =SUM(J15:J18) -> 424517.61 | K19: =SUM(K15:K18) -> 415855.61 | L19: =+K19-J19 -> -8662.0015 | M19: =SUM(M15:M18) -> 442524.21 | N19: =+K19-M19 -> -26668.604 | R19: 중부권 | S19: =+[5]중부권!$Q$90 -> 27704.123 | T19: =+[5]중부권!$R$90 -> 22923.655 | U19: =+T19-S19 -> -4780.4682 | V19: =+[6]중부권!$Q$90 -> 24134.208 | W19: =+T19-V19 -> -1210.5524 | AA19: 공통비 | AB19: =+'사업장별(당월)'!T35/100 -> -12.131221 | AC19: =+'사업장별(당월)'!U35/100 -> -20.896312 | AD19: =+AC19-AB19 -> -8.7650913 | AE19: =+'사업장별(당월)'!W35/100 -> -30.088593 | AF19: =+AC19-AE19 -> 9.1922813 | AG19: =+'사업장별(누계)'!T35/100 -> -161.84901 | AH19: =+'사업장별(누계)'!U35/100 -> -174.43479 | AI19: =+AH19-AG19 -> -12.585787 | AJ19: =+'사업장별(누계)'!W35/100 -> -159.38368 | AK19: =+AH19-AJ19 -> -15.051112
C20: 매출이익 | D20: 레미콘 | E20: =+E10-E15 -> 5319.058 | F20: =+F10-F15 -> 1574.2675 | G20: =+F20-E20 -> -3744.7904 | H20: =+H10-H15 -> 1326.7994 | I20: =+F20-H20 -> 247.46808 | J20: =+J10-J15 -> 59908.46 | K20: =+K10-K15 -> 41626.51 | L20: =+K20-J20 -> -18281.95 | M20: =+M10-M15 -> 60300.705 | N20: =+K20-M20 -> -18674.195 | Q20: 계 | S20: =+[5]합계!$Q$90 -> 24711.266 | T20: =+[5]합계!$R$90 -> 17589.968 | U20: =+T20-S20 -> -7121.2982 | V20: =+[6]합계!$Q$90 -> 18871.68 | W20: =+T20-V20 -> -1281.7117 | AA20: =+'사업장별(누계)'!I34 -> 임대 | AB20: =+('사업장별(당월)'!T33+'사업장별(당월)'!T34)/100 -> 1.4998369 | AC20: =+('사업장별(당월)'!U33+'사업장별(당월)'!U34)/100 -> 1.512218 | AD20: =+AC20-AB20 -> 0.012381077 | AE20: =+('사업장별(당월)'!W33+'사업장별(당월)'!W34)/100 -> 1.5979374 | AF20: =+AC20-AE20 -> -0.08571941 | AG20: =+('사업장별(누계)'!T33+'사업장별(누계)'!T34)/100 -> 16.130025 | AH20: =+('사업장별(누계)'!U33+'사업장별(누계)'!U34)/100 -> 15.7234 | AI20: =+AH20-AG20 -> -0.40662486 | AJ20: =+('사업장별(누계)'!W33+'사업장별(누계)'!W34)/100 -> 14.789888 | AK20: =+AH20-AJ20 -> 0.93351265
D21: 건자재 | E21: =+E11-E16 -> 268.87129 | F21: =+F11-F16 -> 135.84455 | G21: =+F21-E21 -> -133.02673 | H21: =+H11-H16 -> 199.63376 | I21: =+F21-H21 -> -63.789206 | J21: =+J11-J16 -> 2814.6049 | K21: =+K11-K16 -> 2296.8608 | L21: =+K21-J21 -> -517.74418 | M21: =+M11-M16 -> 2386.488 | N21: =+K21-M21 -> -89.627204 | Q21: □ 건자재 | AA21: =+'사업장별(누계)'!I37 -> 대손 | AB21: =+'사업장별(당월)'!T37/100 -> 0 | AC21: =+'사업장별(당월)'!U37/100 -> 3.1951271 | AD21: =+AC21-AB21 -> 3.1951271 | AE21: =+'사업장별(당월)'!W37/100 -> -9.8377338 | AF21: =+AC21-AE21 -> 13.032861 | AG21: =+'사업장별(누계)'!T37/100 -> 0 | AH21: =+'사업장별(누계)'!U37/100 -> -2.5434662 | AI21: =+AH21-AG21 -> -2.5434662 | AJ21: =+'사업장별(누계)'!W37/100 -> -29.579954 | AK21: =+AH21-AJ21 -> 27.036487
D22: 골재 | E22: =+E12-E17 -> 335.52709 | F22: =+F12-F17 -> -373.6856 | G22: =+F22-E22 -> -709.21269 | H22: =+H12-H17 -> -387.23908 | I22: =+F22-H22 -> 13.553478 | J22: =+J12-J17 -> 2724.3198 | K22: =+K12-K17 -> 6.034136 | L22: =+K22-J22 -> -2718.2857 | M22: =+M12-M17 -> 805.77899 | N22: =+K22-M22 -> -799.74485 | Q22: 구분 | S22: 계획 | T22: 실적 | U22: 계획대비 | V22: 전년 | W22: 전년대비 | AA22: =+D34 -> 기타 | AB22: =+AB26-AB19-AB20-AB21 -> -0.71500726 | AC22: =+AC26-AC19-AC20-AC21 -> 3.1276688 | AD22: =+AC22-AB22 -> 3.842676 | AE22: =+AE26-AE19-AE20-AE21 -> 9.9775078 | AF22: =+AC22-AE22 -> -6.8498391 | AG22: =+AG26-AG19-AG20-AG21 -> 2.0315411 | AH22: =+AH26-AH19-AH20-AH21 -> 6.6650168 | AI22: =+AH22-AG22 -> 4.6334757 | AJ22: =+AJ26-AJ19-AJ20-AJ21 -> 6.203462 | AK22: =+AH22-AJ22 -> 0.46155472
D23: 기타 | E23: =+E13-E18 -> 115.34586 | F23: =+F13-F18 -> 476.81676 | G23: =+F23-E23 -> 361.4709 | H23: =+H13-H18 -> 1168.1462 | I23: =+F23-H23 -> -691.32944 | J23: =+J13-J18 -> 2599.8642 | K23: =+K13-K18 -> 2837.1242 | L23: =+K23-J23 -> 237.25996 | M23: =+M13-M18 -> 2724.6639 | N23: =+K23-M23 -> 112.46029 | Q23: 철강재 판매단가 | S23: =+'[7]12월'!$F$10 -> 977906.98 | T23: =+'[7]12월'!$G$10 -> 752238.02 | U23: =+T23-S23 -> -225668.96 | V23: =+'[8]12월'!$G$10 -> 951341.43 | W23: =+T23-V23 -> -199103.41 | AA23: 계 | AB23: =SUM(AB15,AB17:AB22) -> 39.513241 | AC23: =SUM(AC15,AC17:AC22) -> -13.062103 | AD23: =+AC23-AB23 -> -52.575344 | AE23: =SUM(AE15,AE17:AE22) -> -34.851119 | AF23: =+AC23-AE23 -> 21.789016 | AG23: =SUM(AG15,AG17:AG22) -> 410.14369 | AH23: =SUM(AH15,AH17:AH22) -> 173.17751 | AI23: =+AH23-AG23 -> -236.96618 | AJ23: =SUM(AJ15,AJ17:AJ22) -> 358.5603 | AK23: =+AH23-AJ23 -> -185.38279
C24: 계 | E24: =SUM(E20:E23) -> 6038.8022 | F24: =SUM(F20:F23) -> 1813.2432 | G24: =+F24-E24 -> -4225.559 | H24: =SUM(H20:H23) -> 2307.3403 | I24: =+F24-H24 -> -494.09708 | J24: =SUM(J20:J23) -> 68047.249 | K24: =SUM(K20:K23) -> 46766.529 | L24: =+K24-J24 -> -21280.72 | M24: =SUM(M20:M23) -> 66217.636 | N24: =+K24-M24 -> -19451.107 | Q24: 철강재 마진률 | S24: =+'[7]12월'!$F$15 -> 0.023307967 | T24: =+'[7]12월'!$G$15 -> 0.014154492 | U24: =+T24-S24 -> -0.0091534745 | V24: =+'[8]12월'!$G$15 -> 0.0202125 | W24: =+T24-V24 -> -0.0060580081 | AA24: =+D36 -> % | AB24: =+E36 -> 0.088606238 | AC24: =+F36 -> -0.036218892 | AD24: =+G36 -> -0.12482513 | AE24: =+H36 -> -0.089276066 | AF24: =+I36 -> 0.053057174 | AG24: =+J36 -> 0.083266942 | AH24: =+K36 -> 0.037433901 | ... AK24: =+N36 -> -0.033045911
C25: 판관비 | D25: 레미콘 | E25: =+('[1]12월'!$Z$13+'[1]12월'!$Z$20)/1000 -> 670.97737 | F25: =+('[2]12월'!$Z$13+'[2]12월'!$Z$20)/1000 -> 1006.0437 | G25: =+F25-E25 -> 335.06637 | H25: =+('[3]12월'!$Z$13+'[3]12월'!$Z$20)/1000 -> 1479.1891 | I25: =+F25-H25 -> -473.14535 | J25: =+[4]손익총괄!J25+E25 -> 7930.9359 | K25: =+[4]손익총괄!K25+F25 -> 8589.226 | L25: =+K25-J25 -> 658.29003 | M25: =+[4]손익총괄!M25+H25 -> 8909.8323 | N25: =+K25-M25 -> -320.60635 | Q25: □ 골재
D26: 건자재 | E26: =+('[1]12월'!$AA$13+'[1]12월'!$AA$20)/1000 -> 129.83104 | F26: =+('[2]12월'!$AO$13+'[2]12월'!$AO$20)/1000 -> 236.94663 | G26: =+F26-E26 -> 107.11559 | H26: =+('[3]12월'!$AO$13+'[3]12월'!$AO$20)/1000 -> 286.26731 | I26: =+F26-H26 -> -49.32069 | J26: =+[4]손익총괄!J26+E26 -> 1514.1743 | K26: =+[4]손익총괄!K26+F26 -> 1796.1025 | L26: =+K26-J26 -> 281.92822 | M26: =+[4]손익총괄!M26+H26 -> 1604.8411 | N26: =+K26-M26 -> 191.26138 | Q26: 구분 | S26: 계획 | T26: 실적 | U26: 계획대비 | V26: 전년 | W26: 전년대비 | AB26: =+'사업장별(당월)'!T41/100 -> -11.346391 | AC26: =+'사업장별(당월)'!U41/100 -> -13.061298 | AD26: =+AC26-AB26 -> -1.7149071 | AE26: =+'사업장별(당월)'!W41/100 -> -28.350882 | AF26: =+AE26-AD26 -> -26.635975 | AG26: =+'사업장별(누계)'!T41/100 -> -143.68744 | AH26: =+'사업장별(누계)'!U41/100 -> -154.58984 | AJ26: =+'사업장별(누계)'!W41/100 -> -167.97029
D27: 골재 | E27: =+('[1]12월'!$AE$13+'[1]12월'!$AE$20+'[1]12월'!$AE$22)/1000 -> 36.68475 | F27: =+('[2]12월'!$AN$13+'[2]12월'!$AN$20+'[2]12월'!$AN$22)/1000 -> 93.516636 | G27: =+F27-E27 -> 56.831886 | H27: =+('[3]12월'!$AN$13+'[3]12월'!$AN$20+'[3]12월'!$AN$22)/1000 -> 23.761448 | I27: =+F27-H27 -> 69.755188 | J27: =+[4]손익총괄!J27+E27 -> 619.16069 | K27: =+[4]손익총괄!K27+F27 -> 767.34051 | L27: =+K27-J27 -> 148.17983 | M27: =+[4]손익총괄!M27+H27 -> 325.23994 | N27: =+K27-M27 -> 442.10057 | Q27: 판매량 | R27: 자가 | S27: =(+'[9]서부산크라샤(당월)'!$N$66+'[9]부산모래장(당월)'!$Q$48+'[9]부산크라샤(당월)'!$N$66)/1000 -> 63.755227 | T27: =(+'[9]서부산크라샤(당월)'!$O$66+'[9]부산모래장(당월)'!$R$48+'[9]부산크라샤(당월)'!$O$66)/1000 -> 38.16 | U27: =+T27-S27 -> -25.595227 | V27: =('[10]부산골재(당월)'!$R$48+'[10]서부산골재(당월)'!$O$66+'[10]부산크라샤(당월)'!$O$66)/1000 -> 48.335 | W27: =+T27-V27 -> -10.175
D28: 기타 | E28: =+('[1]12월'!$E$13+'[1]12월'!$E$20)/1000-E25-E26-E27+('[1]12월'!$E$22/1000) -> 1249.985 | F28: =+('[2]12월'!$F$13+'[2]12월'!$F$20)/1000-F25-F26-F27+'[2]12월'!$F$22/1000 -> 1782.9466 | G28: =+F28-E28 -> 532.96161 | H28: =+('[3]12월'!$F$13+'[3]12월'!$F$20)/1000-H25-H26-H27+'[3]12월'!$F$22/1000 -> 4003.2344 | I28: =+F28-H28 -> -2220.2878 | J28: =+[4]손익총괄!J28+E28 -> 16968.608 | K28: =+[4]손익총괄!K28+F28 -> 18296.109 | L28: =+K28-J28 -> 1327.5002 | M28: =+[4]손익총괄!M28+H28 -> 19521.693 | N28: =+K28-M28 -> -1225.584 | R28: 외판 | S28: =(+'[9]서부산크라샤(당월)'!$N$59+'[9]부산모래장(당월)'!$Q$47+'[9]부산크라샤(당월)'!$N$59)/1000 -> 57.15 | T28: =(+'[9]서부산크라샤(당월)'!$O$59+'[9]부산모래장(당월)'!$R$47+'[9]부산크라샤(당월)'!$O$59)/1000 -> 21.52 | U28: =+T28-S28 -> -35.63 | V28: =+('[10]부산골재(당월)'!$R$47+'[10]서부산골재(당월)'!$O$59+'[10]부산크라샤(당월)'!$O$59)/1000 -> 21.898 | W28: =+T28-V28 -> -0.378 | AA28: =365/2.3 -> 158.69565
C29: 계 | E29: =SUM(E25:E28) -> 2087.4781 | F29: =SUM(F25:F28) -> 3119.4536 | G29: =+F29-E29 -> 1031.9754 | H29: =SUM(H25:H28) -> 5792.4522 | I29: =+F29-H29 -> -2672.9987 | J29: =SUM(J25:J28) -> 27032.879 | K29: =SUM(K25:K28) -> 29448.778 | L29: =+K29-J29 -> 2415.8983 | M29: =SUM(M25:M28) -> 30361.606 | N29: =+K29-M29 -> -912.82838 | Q29: 합 계 | S29: =SUM(S27:S28) -> 120.90523 | T29: =SUM(T27:T28) -> 59.68 | U29: =+T29-S29 -> -61.225227 | V29: =SUM(V27:V28) -> 70.233 | W29: =+T29-V29 -> -10.553
C30: 영업이익 | D30: 레미콘 | E30: =+E20-E25 -> 4648.0806 | F30: =+F20-F25 -> 568.22379 | G30: =+F30-E30 -> -4079.8568 | H30: =+H20-H25 -> -152.38965 | I30: =+F30-H30 -> 720.61344 | J30: =+J20-J25 -> 51977.524 | K30: =+K20-K25 -> 33037.284 | L30: =+K30-J30 -> -18940.24 | M30: =+M20-M25 -> 51390.873 | N30: =+K30-M30 -> -18353.589 | Q30: □ 기타내역(영업이익)
D31: % | E31: =+E30/E10 -> 0.14653483 | F31: =+F30/F10 -> 0.020911562 | G31: =+F31-E31 -> -0.12562327 | H31: =+H30/H10 -> -0.0054733264 | I31: =+F31-H31 -> 0.026384888 | J31: =+J30/J10 -> 0.14540334 | K31: =+K30/K10 -> 0.097292891 | L31: =+K31-J31 -> -0.048110448 | M31: =+M30/M10 -> 0.13822696 | N31: =+K31-M31 -> -0.040934067 | Q31: 구분 | S31: 계획 | T31: 실적 | U31: 계획대비 | V31: 전년 | W31: 전년대비
D32: 건자재 | E32: =+E21-E26 -> 139.04025 | F32: =+F21-F26 -> -101.10207 | G32: =+F32-E32 -> -240.14232 | H32: =+H21-H26 -> -86.633557 | I32: =+F32-H32 -> -14.468516 | J32: =+J21-J26 -> 1300.4307 | K32: =+K21-K26 -> 500.75828 | L32: =+K32-J32 -> -799.6724 | M32: =+M21-M26 -> 781.64686 | N32: =+K32-M32 -> -280.88858 | Q32: 레미콘임대 | S32: =+'사업장별(당월)'!T33 -> 75.360275 | T32: =+'사업장별(당월)'!U33 -> 76.068675 | U32: =+T32-S32 -> 0.7084 | V32: =+'사업장별(당월)'!W33 -> 73.170018 | W32: =+T32-V32 -> 2.898657
D33: 골재 | E33: =+E22-E27 -> 298.84234 | F33: =+F22-F27 -> -467.20224 | G33: =+F33-E33 -> -766.04457 | H33: =+H22-H27 -> -411.00052 | I33: =+F33-H33 -> -56.20171 | J33: =+J22-J27 -> 2105.1591 | K33: =+K22-K27 -> -761.30637 | L33: =+K33-J33 -> -2866.4655 | M33: =+M22-M27 -> 480.53905 | N33: =+K33-M33 -> -1241.8454 | Q33: 임대 | S33: =+'사업장별(당월)'!T34 -> 74.623417 | T33: =+'사업장별(당월)'!U34 -> 75.153125 | U33: =+T33-S33 -> 0.52970767 | V33: =+'사업장별(당월)'!W34 -> 86.623723 | W33: =+T33-V33 -> -11.470598
D34: 기타 | E34: =+E23-E28 -> -1134.6391 | F34: =+F23-F28 -> -1306.1298 | G34: =+F34-E34 -> -171.49071 | H34: =+H23-H28 -> -2835.0882 | I34: =+F34-H34 -> 1528.9584 | J34: =+J23-J28 -> -14368.744 | K34: =+K23-K28 -> -15458.984 | L34: =+K34-J34 -> -1090.2403 | M34: =+M23-M28 -> -16797.029 | N34: =+K34-M34 -> 1338.0443 | Q34: 공통비 | S34: =+'사업장별(당월)'!T35 -> -1213.1221 | T34: =+'사업장별(당월)'!U35 -> -2089.6312 | U34: =+T34-S34 -> -876.50913 | V34: =+'사업장별(당월)'!W35 -> -3008.8593 | W34: =+T34-V34 -> 919.22813
C35: 계 | E35: =SUM(E30,E32:E34) -> 3951.3241 | F35: =SUM(F30,F32:F34) -> -1306.2103 | G35: =+F35-E35 -> -5257.5344 | H35: =SUM(H30,H32:H34) -> -3485.1119 | I35: =+F35-H35 -> 2178.9016 | J35: =SUM(J30,J32:J34) -> 41014.369 | K35: =SUM(K30,K32:K34) -> 17317.751 | L35: =+K35-J35 -> -23696.618 | M35: =SUM(M30,M32:M34) -> 35856.03 | N35: =+K35-M35 -> -18538.279 | Q35: 기타 | S35: =+S36-S32-S33-S34 -> -71.500726 | T35: =+T36-T32-T33-T34 -> 632.27959 | U35: =+T35-S35 -> 703.78031 | V35: =+V36-V32-V33-V34 -> 13.977405 | W35: =+T35-V35 -> 618.30218
D36: % | E36: =+E35/E14 -> 0.088606238 | F36: =+F35/F14 -> -0.036218892 | G36: =+F36-E36 -> -0.12482513 | H36: =+H35/H14 -> -0.089276066 | I36: =+F36-H36 -> 0.053057174 | J36: =+J35/J14 -> 0.083266942 | K36: =+K35/K14 -> 0.037433901 | L36: =+K36-J36 -> -0.045833041 | M36: =+M35/M14 -> 0.070479813 | N36: =+K36-M36 -> -0.033045911 | Q36: 합계 | S36: =+'사업장별(당월)'!T41 -> -1134.6391 | T36: =+'사업장별(당월)'!U41 -> -1306.1298 | U36: =+T36-S36 -> -171.49071 | V36: =+'사업장별(당월)'!W41 -> -2835.0882 | W36: =+T36-V36 -> 1528.9584
E38: =+'[1]12월'!$E$26/1000 -> 3951.3241 | F38: =+'[2]12월'!$F$26/1000 -> -1306.2103 | H38: =+'[3]12월'!$F$26/1000 -> -3485.1119 | J38: =+[4]손익총괄!J38+E38 -> 41014.369 | K38: =+[4]손익총괄!K38+F38 -> 17317.751 | M38: =+[4]손익총괄!M38+H38 -> 35856.03
E39: =+E35=E38 -> FALSE | F39: =+F35=F38 -> FALSE | H39: =+H35=H38 -> TRUE | J39: =+J35=J38 -> TRUE | K39: =+K35=K38 -> FALSE | M39: =+M35=M38 -> TRUE
E40: =+E35-E38 -> 0 | F40: =+F35-F38 -> 2.7284841e-12 | H40: =+H35-H38 -> 0 | J40: =+J35-J38 -> 0 | K40: =+K35-K38 -> 0 | M40: =+M35-M38 -> 0

Sheet 사업장별(당월)
H3: □ 사업장별 손익실적(2024-12)
AG4: [단위 : 천㎥, 톤, 백만원]
H5: 구분 | J5: 물량 | O5: 매출 | T5: 영업이익(공통비 배부전) | Y5: 판매단가 | AB5: 변동비 | AE5: 공헌이익
A6: 2024년 12월 마감 손익 | J6: 계획 | K6: 실적 | L6: 차이 | M6: 전년 | N6: 차이 | O6: 계획 | P6: 실적 | Q6: 차이 | R6: 전년 | S6: 차이 | T6: 계획 | U6: 실적 | V6: 차이 | W6: 전년 | X6: 차이 | Y6: 계획 | Z6: 실적 | AA6: 전년 | AB6: 계획 | AC6: 실적 | AD6: 전년 | AE6: 계획 | AF6: 실적 | AG6: 전년
B7: 안양 | G7: =+I7 -> 안양 | H7: 레미콘 | I7: 안양 | J7: =+IFERROR(HLOOKUP($B7,'[1]12월'!$D$6:$BN$259,2,),)/1000 -> 42 | K7: =+IFERROR(HLOOKUP($B7,'[2]12월'!$F$6:$CP$99,2,),)/1000 -> 34.67 | L7: =+K7-J7 -> -7.33 | M7: =+IFERROR(HLOOKUP($B7,'[3]12월'!$F$6:$CC$57,2,),)/1000 -> 41.036 | N7: =+K7-M7 -> -6.366 | O7: =+IFERROR(HLOOKUP($B7,'[1]12월'!$D$6:$BN$259,3,),)/1000 -> 4277.4152 | P7: =+IFERROR(HLOOKUP($B7,'[2]12월'!$F$6:$CP$99,3,),)/1000 -> 3342.2601 | Q7: =+P7-O7 -> -935.15506 | R7: =+IFERROR(HLOOKUP($B7,'[3]12월'!$F$6:$CC$57,3,),)/1000 -> 3916.1936 | S7: =+P7-R7 -> -573.93351 | T7: =+IFERROR(HLOOKUP($B7,'[1]12월'!$D$6:$BN$259,16,),)/1000 -> 607.52947 | U7: =+IFERROR(HLOOKUP($B7,'[2]12월'!$F$6:$CP$99,16,),)/1000 -> 51.528149 | V7: =+U7-T7 -> -556.00132 | W7: =+IFERROR(HLOOKUP($B7,'[3]12월'!$F$6:$CC$57,16,),)/1000 -> 32.938006 | X7: =+U7-W7 -> 18.590143 | Y7: =+[5]안양!$Q$85 -> 101843.22 | Z7: =+[5]안양!$R$85 -> 96402.081 | AA7: =+[6]안양!$Q$85 -> 95433.123 | AB7: =+[5]안양!$Q$89 -> 80543.283 | AC7: =+[5]안양!$R$89 -> 82908.854 | AD7: =+[6]안양!$Q$89 -> 80364.232 | AE7: =+Y7-AB7 -> 21299.936 | AF7: =+Z7-AC7 -> 13493.227 | AG7: =+AA7-AD7 -> 15068.891
B8: 인천 | G8: =+I8 -> 인천 | H8: 직영 | I8: 인천 | J8: =+IFERROR(HLOOKUP($B8,'[1]12월'!$D$6:$BN$259,2,),)/1000 -> 36 | K8: =+IFERROR(HLOOKUP($B8,'[2]12월'!$F$6:$CP$99,2,),)/1000 -> 30.362 | L8: =+K8-J8 -> -5.638 | M8: =+IFERROR(HLOOKUP($B8,'[3]12월'!$F$6:$CC$57,2,),)/1000 -> 27.74 | N8: =+K8-M8 -> 2.622 | O8: =+IFERROR(HLOOKUP($B8,'[1]12월'!$D$6:$BN$259,3,),)/1000 -> 3835.5608 | P8: =+IFERROR(HLOOKUP($B8,'[2]12월'!$F$6:$CP$99,3,),)/1000 -> 2969.3944 | Q8: =+P8-O8 -> -866.16644 | R8: =+IFERROR(HLOOKUP($B8,'[3]12월'!$F$6:$CC$57,3,),)/1000 -> 2752.5621 | S8: =+P8-R8 -> 216.83234 | T8: =+IFERROR(HLOOKUP($B8,'[1]12월'!$D$6:$BN$259,16,),)/1000 -> 577.09052 | U8: =+IFERROR(HLOOKUP($B8,'[2]12월'!$F$6:$CP$99,16,),)/1000 -> -49.54122 | V8: =+U8-T8 -> -626.63174 | W8: =+IFERROR(HLOOKUP($B8,'[3]12월'!$F$6:$CC$57,16,),)/1000 -> -86.728501 | X8: =+U8-W8 -> 37.187281 | Y8: =+[5]인천!$Q$85 -> 106543.36 | Z8: =+[5]인천!$R$85 -> 97799.697 | AA8: =+[6]인천!$Q$85 -> 99227.183 | AB8: =+[5]인천!$Q$89 -> 82512.19 | AC8: =+[5]인천!$R$89 -> 86503.735 | AD8: =+[6]인천!$Q$89 -> 82946.13 | AE8: =+Y8-AB8 -> 24031.167 | AF8: =+Z8-AC8 -> 11295.962 | AG8: =+AA8-AD8 -> 16281.053
B9: 파주 | G9: =+I9 -> 파주 | I9: 파주 | J9: =+IFERROR(HLOOKUP($B9,'[1]12월'!$D$6:$BN$259,2,),)/1000 -> 22 | K9: =+IFERROR(HLOOKUP($B9,'[2]12월'!$F$6:$CP$99,2,),)/1000 -> 16.303 | L9: =+K9-J9 -> -5.697 | M9: =+IFERROR(HLOOKUP($B9,'[3]12월'!$F$6:$CC$57,2,),)/1000 -> 23.44 | N9: =+K9-M9 -> -7.137 | O9: =+IFERROR(HLOOKUP($B9,'[1]12월'!$D$6:$BN$259,3,),)/1000 -> 2212.4212 | P9: =+IFERROR(HLOOKUP($B9,'[2]12월'!$F$6:$CP$99,3,),)/1000 -> 1513.0633 | Q9: =+P9-O9 -> -699.3579 | R9: =+IFERROR(HLOOKUP($B9,'[3]12월'!$F$6:$CC$57,3,),)/1000 -> 2319.5423 | S9: =+P9-R9 -> -806.479 | T9: =+IFERROR(HLOOKUP($B9,'[1]12월'!$D$6:$BN$259,16,),)/1000 -> 273.09847 | U9: =+IFERROR(HLOOKUP($B9,'[2]12월'!$F$6:$CP$99,16,),)/1000 -> -160.22943 | V9: =+U9-T9 -> -433.3279 | W9: =+IFERROR(HLOOKUP($B9,'[3]12월'!$F$6:$CC$57,16,),)/1000 -> -76.952821 | X9: =+U9-W9 -> -83.276605 | Y9: =+[5]파주!$Q$85 -> 100564.6 | Z9: =+[5]파주!$R$85 -> 92808.89 | AA9: =+[6]파주!$Q$85 -> 98896.411 | AB9: =+[5]파주!$Q$89 -> 78672.484 | AC9: =+[5]파주!$R$89 -> 85217.769 | AD9: =+[6]파주!$Q$89 -> 84926.888 | AE9: =+Y9-AB9 -> 21892.118 | AF9: =+Z9-AC9 -> 7591.1217 | AG9: =+AA9-AD9 -> 13969.523
B10: 김포 | G10: =+I10 -> 김포 | I10: 김포 | J10: =+IFERROR(HLOOKUP($B10,'[1]12월'!$D$6:$BN$259,2,),)/1000 -> 13.5 | K10: =+IFERROR(HLOOKUP($B10,'[2]12월'!$F$6:$CP$99,2,),)/1000 -> 13.4185 | L10: =+K10-J10 -> -0.0815 | M10: =+IFERROR(HLOOKUP($B10,'[3]12월'!$F$6:$CC$57,2,),)/1000 -> 12.924 | N10: =+K10-M10 -> 0.4945 | O10: =+IFERROR(HLOOKUP($B10,'[1]12월'!$D$6:$BN$259,3,),)/1000 -> 1296.1935 | P10: =+IFERROR(HLOOKUP($B10,'[2]12월'!$F$6:$CP$99,3,),)/1000 -> 1247.6161 | Q10: =+P10-O10 -> -48.577354 | R10: =+IFERROR(HLOOKUP($B10,'[3]12월'!$F$6:$CC$57,3,),)/1000 -> 1223.3612 | S10: =+P10-R10 -> 24.254966 | T10: =+IFERROR(HLOOKUP($B10,'[1]12월'!$D$6:$BN$259,16,),)/1000 -> 147.2032 | U10: =+IFERROR(HLOOKUP($B10,'[2]12월'!$F$6:$CP$99,16,),)/1000 -> -46.29355 | V10: =+U10-T10 -> -193.49675 | W10: =+IFERROR(HLOOKUP($B10,'[3]12월'!$F$6:$CC$57,16,),)/1000 -> -72.352114 | X10: =+U10-W10 -> 26.058564 | Y10: =+[5]김포!$Q$85 -> 96014.333 | Z10: =+[5]김포!$R$85 -> 93010.903 | AA10: =+[6]김포!$Q$85 -> 94658.092 | AB10: =+[5]김포!$Q$89 -> 73421.333 | AC10: =+[5]김포!$R$89 -> 79168.533 | AD10: =+[6]김포!$Q$89 -> 77549.906 | AE10: =+Y10-AB10 -> 22593 | AF10: =+Z10-AC10 -> 13842.37 | AG10: =+AA10-AD10 -> 17108.186
B11: 부산 | G11: =+I11 -> 부산 | I11: 부산 | J11: =+IFERROR(HLOOKUP($B11,'[1]12월'!$D$6:$BN$259,2,),)/1000 -> 24 | K11: =+IFERROR(HLOOKUP($B11,'[2]12월'!$F$6:$CP$99,2,),)/1000 -> 17.339 | L11: =+K11-J11 -> -6.661 | M11: =+IFERROR(HLOOKUP($B11,'[3]12월'!$F$6:$CC$57,2,),)/1000 -> 20.362 | N11: =+K11-M11 -> -3.023 | O11: =+IFERROR(HLOOKUP($B11,'[1]12월'!$D$6:$BN$259,3,),)/1000 -> 2582.4103 | P11: =+IFERROR(HLOOKUP($B11,'[2]12월'!$F$6:$CP$99,3,),)/1000 -> 1980.4694 | Q11: =+P11-O11 -> -601.9409 | R11: =+IFERROR(HLOOKUP($B11,'[3]12월'!$F$6:$CC$57,3,),)/1000 -> 2088.935 | S11: =+P11-R11 -> -108.4656 | T11: =+IFERROR(HLOOKUP($B11,'[1]12월'!$D$6:$BN$259,16,),)/1000 -> 351.02035 | U11: =+IFERROR(HLOOKUP($B11,'[2]12월'!$F$6:$CP$99,16,),)/1000 -> 92.183809 | V11: =+U11-T11 -> -258.83654 | W11: =+IFERROR(HLOOKUP($B11,'[3]12월'!$F$6:$CC$57,16,),)/1000 -> -64.129509 | X11: =+U11-W11 -> 156.31332 | Y11: =+[5]부산!$Q$85 -> 107600.43 | Z11: =+[5]부산!$R$85 -> 114220.51 | AA11: =+[6]부산!$Q$85 -> 102589.87 | AB11: =+[5]부산!$Q$89 -> 82245.678 | AC11: =+[5]부산!$R$89 -> 90394.221 | AD11: =+[6]부산!$Q$89 -> 84012.412 | AE11: =+Y11-AB11 -> 25354.751 | AF11: =+Z11-AC11 -> 23826.288 | AG11: =+AA11-AD11 -> 18577.461
B12: 서부산 | G12: =+I12 -> 서부산 | I12: 서부산 | J12: =+IFERROR(HLOOKUP($B12,'[1]12월'!$D$6:$BN$259,2,),)/1000 -> 26 | K12: =+IFERROR(HLOOKUP($B12,'[2]12월'!$F$6:$CP$99,2,),)/1000 -> 24.067 | L12: =+K12-J12 -> -1.933 | M12: =+IFERROR(HLOOKUP($B12,'[3]12월'!$F$6:$CC$57,2,),)/1000 -> 21.623 | N12: =+K12-M12 -> 2.444 | O12: =+IFERROR(HLOOKUP($B12,'[1]12월'!$D$6:$BN$259,3,),)/1000 -> 2719.0035 | P12: =+IFERROR(HLOOKUP($B12,'[2]12월'!$F$6:$CP$99,3,),)/1000 -> 2361.636 | Q12: =+P12-O12 -> -357.36752 | R12: =+IFERROR(HLOOKUP($B12,'[3]12월'!$F$6:$CC$57,3,),)/1000 -> 2070.2657 | S12: =+P12-R12 -> 291.3703 | T12: =+IFERROR(HLOOKUP($B12,'[1]12월'!$D$6:$BN$259,16,),)/1000 -> 500.34998 | U12: =+IFERROR(HLOOKUP($B12,'[2]12월'!$F$6:$CP$99,16,),)/1000 -> 163.09231 | V12: =+U12-T12 -> -337.25767 | W12: =+IFERROR(HLOOKUP($B12,'[3]12월'!$F$6:$CC$57,16,),)/1000 -> -32.57263 | X12: =+U12-W12 -> 195.66494 | Y12: =+[5]서부산!$Q$85 -> 104577.06 | Z12: =+[5]서부산!$R$85 -> 98127.561 | AA12: =+[6]서부산!$Q$85 -> 95743.685 | AB12: =+[5]서부산!$Q$89 -> 77522.344 | AC12: =+[5]서부산!$R$89 -> 78950.52 | AD12: =+[6]서부산!$Q$89 -> 80776.028 | AE12: =+Y12-AB12 -> 27054.715 | AF12: =+Z12-AC12 -> 19177.041 | AG12: =+AA12-AD12 -> 14967.657
B13: 김해 | G13: =+I13 -> 김해 | I13: 김해 | J13: =+IFERROR(HLOOKUP($B13,'[1]12월'!$D$6:$BN$259,2,),)/1000 -> 14 | K13: =+IFERROR(HLOOKUP($B13,'[2]12월'!$F$6:$CP$99,2,),)/1000 -> 12.184 | L13: =+K13-J13 -> -1.816 | M13: =+IFERROR(HLOOKUP($B13,'[3]12월'!$F$6:$CC$57,2,),)/1000 -> 12.437 | N13: =+K13-M13 -> -0.253 | O13: =+IFERROR(HLOOKUP($B13,'[1]12월'!$D$6:$BN$259,3,),)/1000 -> 1414.0056 | P13: =+IFERROR(HLOOKUP($B13,'[2]12월'!$F$6:$CP$99,3,),)/1000 -> 1145.9621 | Q13: =+P13-O13 -> -268.0435 | R13: =+IFERROR(HLOOKUP($B13,'[3]12월'!$F$6:$CC$57,3,),)/1000 -> 1240.7524 | S13: =+P13-R13 -> -94.7903 | T13: =+IFERROR(HLOOKUP($B13,'[1]12월'!$D$6:$BN$259,16,),)/1000 -> 187.05963 | U13: =+IFERROR(HLOOKUP($B13,'[2]12월'!$F$6:$CP$99,16,),)/1000 -> -58.225946 | V13: =+U13-T13 -> -245.28558 | W13: =+IFERROR(HLOOKUP($B13,'[3]12월'!$F$6:$CC$57,16,),)/1000 -> -41.18773 | X13: =+U13-W13 -> -17.038216 | Y13: =+[5]김해!$Q$85 -> 101000.4 | Z13: =+[5]김해!$R$85 -> 94036.649 | AA13: =+[6]김해!$Q$85 -> 99762.998 | AB13: =+[5]김해!$Q$89 -> 77306.919 | AC13: =+[5]김해!$R$89 -> 80796.704 | AD13: =+[6]김해!$Q$89 -> 81505.826 | AE13: =+Y13-AB13 -> 23693.481 | AF13: =+Z13-AC13 -> 13239.945 | AG13: =+AA13-AD13 -> 18257.171
B14: 정관 | G14: =+I14 -> 정관 | I14: 정관 | J14: =+IFERROR(HLOOKUP($B14,'[1]12월'!$D$6:$BN$259,2,),)/1000 -> 19 | K14: =+IFERROR(HLOOKUP($B14,'[2]12월'!$F$6:$CP$99,2,),)/1000 -> 22.034 | L14: =+K14-J14 -> 3.034 | M14: =+IFERROR(HLOOKUP($B14,'[3]12월'!$F$6:$CC$57,2,),)/1000 -> 19.458 | N14: =+K14-M14 -> 2.576 | O14: =+IFERROR(HLOOKUP($B14,'[1]12월'!$D$6:$BN$259,3,),)/1000 -> 1976 | P14: =+IFERROR(HLOOKUP($B14,'[2]12월'!$F$6:$CP$99,3,),)/1000 -> 2288.9945 | Q14: =+P14-O14 -> 312.9945 | R14: =+IFERROR(HLOOKUP($B14,'[3]12월'!$F$6:$CC$57,3,),)/1000 -> 1970.3819 | S14: =+P14-R14 -> 318.6126 | T14: =+IFERROR(HLOOKUP($B14,'[1]12월'!$D$6:$BN$259,16,),)/1000 -> 274.98355 | U14: =+IFERROR(HLOOKUP($B14,'[2]12월'!$F$6:$CP$99,16,),)/1000 -> 101.28182 | V14: =+U14-T14 -> -173.70174 | W14: =+IFERROR(HLOOKUP($B14,'[3]12월'!$F$6:$CC$57,16,),)/1000 -> 23.55043 | X14: =+U14-W14 -> 77.731387 | Y14: =+[5]정관!$Q$85 -> 104000 | Z14: =+[5]정관!$R$85 -> 103884.66 | AA14: =+[6]정관!$Q$85 -> 101263.33 | AB14: =+[5]정관!$Q$89 -> 79201.727 | AC14: =+[5]정관!$R$89 -> 86215.634 | AD14: =+[6]정관!$Q$89 -> 81557.376 | AE14: =+Y14-AB14 -> 24798.273 | AF14: =+Z14-AC14 -> 17669.022 | AG14: =+AA14-AD14 -> 19705.955
B15: 양산 | G15: =+I15 -> 양산 | I15: 양산 | J15: =+IFERROR(HLOOKUP($B15,'[1]12월'!$D$6:$BN$259,2,),)/1000 -> 12 | K15: =+IFERROR(HLOOKUP($B15,'[2]12월'!$F$6:$CP$99,2,),)/1000 -> 10.174 | L15: =+K15-J15 -> -1.826 | M15: =+IFERROR(HLOOKUP($B15,'[3]12월'!$F$6:$CC$57,2,),)/1000 -> 12.654 | N15: =+K15-M15 -> -2.48 | O15: =+IFERROR(HLOOKUP($B15,'[1]12월'!$D$6:$BN$259,3,),)/1000 -> 1166.5218 | P15: =+IFERROR(HLOOKUP($B15,'[2]12월'!$F$6:$CP$99,3,),)/1000 -> 958.2302 | Q15: =+P15-O15 -> -208.29163 | R15: =+IFERROR(HLOOKUP($B15,'[3]12월'!$F$6:$CC$57,3,),)/1000 -> 1163.1534 | S15: =+P15-R15 -> -204.92321 | T15: =+IFERROR(HLOOKUP($B15,'[1]12월'!$D$6:$BN$259,16,),)/1000 -> 159.93477 | U15: =+IFERROR(HLOOKUP($B15,'[2]12월'!$F$6:$CP$99,16,),)/1000 -> -28.828367 | V15: =+U15-T15 -> -188.76314 | W15: =+IFERROR(HLOOKUP($B15,'[3]12월'!$F$6:$CC$57,16,),)/1000 -> -41.122997 | X15: =+U15-W15 -> 12.29463 | Y15: =+[5]양산!$Q$85 -> 97210.153 | Z15: =+[5]양산!$R$85 -> 94184.215 | AA15: =+[6]양산!$Q$85 -> 91919.82 | AB15: =+[5]양산!$Q$89 -> 72466.137 | AC15: =+[5]양산!$R$89 -> 78064.419 | AD15: =+[6]양산!$Q$89 -> 73068.839 | AE15: =+Y15-AB15 -> 24744.015 | AF15: =+Z15-AC15 -> 16119.796 | AG15: =+AA15-AD15 -> 18850.981
B16: 창원 | G16: =+I16 -> 창원 | I16: 창원 | J16: =+IFERROR(HLOOKUP($B16,'[1]12월'!$D$6:$BN$259,2,),)/1000 -> 15 | K16: =+IFERROR(HLOOKUP($B16,'[2]12월'!$F$6:$CP$99,2,),)/1000 -> 12.315 | L16: =+K16-J16 -> -2.685 | M16: =+IFERROR(HLOOKUP($B16,'[3]12월'!$F$6:$CC$57,2,),)/1000 -> 19.115 | N16: =+K16-M16 -> -6.8 | O16: =+IFERROR(HLOOKUP($B16,'[1]12월'!$D$6:$BN$259,3,),)/1000 -> 1523.358 | P16: =+IFERROR(HLOOKUP($B16,'[2]12월'!$F$6:$CP$99,3,),)/1000 -> 1261.8106 | Q16: =+P16-O16 -> -261.54745 | R16: =+IFERROR(HLOOKUP($B16,'[3]12월'!$F$6:$CC$57,3,),)/1000 -> 1861.5654 | S16: =+P16-R16 -> -599.75485 | T16: =+IFERROR(HLOOKUP($B16,'[1]12월'!$D$6:$BN$259,16,),)/1000 -> 245.30851 | U16: =+IFERROR(HLOOKUP($B16,'[2]12월'!$F$6:$CP$99,16,),)/1000 -> 72.758357 | V16: =+U16-T16 -> -172.55015 | W16: =+IFERROR(HLOOKUP($B16,'[3]12월'!$F$6:$CC$57,16,),)/1000 -> 121.08234 | X16: =+U16-W16 -> -48.323983 | Y16: =+[5]창원!$Q$85 -> 101557.2 | Z16: =+[5]창원!$R$85 -> 102461.27 | AA16: =+[6]창원!$Q$85 -> 97387.675 | AB16: =+[5]창원!$Q$89 -> 72797.601 | AC16: =+[5]창원!$R$89 -> 76573.527 | AD16: =+[6]창원!$Q$89 -> 72941.793 | AE16: =+Y16-AB16 -> 28759.599 | AF16: =+Z16-AC16 -> 25887.744 | AG16: =+AA16-AD16 -> 24445.881
B17: 대구 | G17: =+I17 -> 대구 | I17: 대구 | J17: =+IFERROR(HLOOKUP($B17,'[1]12월'!$D$6:$BN$259,2,),)/1000 -> 16 | K17: =+IFERROR(HLOOKUP($B17,'[2]12월'!$F$6:$CP$99,2,),)/1000 -> 18.708 | L17: =+K17-J17 -> 2.708 | M17: =+IFERROR(HLOOKUP($B17,'[3]12월'!$F$6:$CC$57,2,),)/1000 -> 17.634 | N17: =+K17-M17 -> 1.074 | O17: =+IFERROR(HLOOKUP($B17,'[1]12월'!$D$6:$BN$259,3,),)/1000 -> 1564.16 | P17: =+IFERROR(HLOOKUP($B17,'[2]12월'!$F$6:$CP$99,3,),)/1000 -> 1801.6908 | Q17: =+P17-O17 -> 237.53076 | R17: =+IFERROR(HLOOKUP($B17,'[3]12월'!$F$6:$CC$57,3,),)/1000 -> 1703.1217 | S17: =+P17-R17 -> 98.569064 | T17: =+IFERROR(HLOOKUP($B17,'[1]12월'!$D$6:$BN$259,16,),)/1000 -> 246.00736 | U17: =+IFERROR(HLOOKUP($B17,'[2]12월'!$F$6:$CP$99,16,),)/1000 -> 168.03998 | V17: =+U17-T17 -> -77.967379 | W17: =+IFERROR(HLOOKUP($B17,'[3]12월'!$F$6:$CC$57,16,),)/1000 -> 67.193584 | X17: =+U17-W17 -> 100.8464 | Y17: =+[5]대구!$Q$85 -> 97760 | Z17: =+[5]대구!$R$85 -> 96305.899 | AA17: =+[6]대구!$Q$85 -> 96581.7 | AB17: =+[5]대구!$Q$89 -> 72183.97 | AC17: =+[5]대구!$R$89 -> 73764.096 | AD17: =+[6]대구!$Q$89 -> 72751.844 | AE17: =+Y17-AB17 -> 25576.03 | AF17: =+Z17-AC17 -> 22541.803 | AG17: =+AA17-AD17 -> 23829.856
B18: 울산 | G18: =+I18 -> 울산 | I18: 울산 | J18: =+IFERROR(HLOOKUP($B18,'[1]12월'!$D$6:$BN$259,2,),)/1000 -> 12 | K18: =+IFERROR(HLOOKUP($B18,'[2]12월'!$F$6:$CP$99,2,),)/1000 -> 12.451 | L18: =+K18-J18 -> 0.451 | M18: =+IFERROR(HLOOKUP($B18,'[3]12월'!$F$6:$CC$57,2,),)/1000 -> 6.727 | N18: =+K18-M18 -> 5.724 | O18: =+IFERROR(HLOOKUP($B18,'[1]12월'!$D$6:$BN$259,3,),)/1000 -> 1215.1903 | P18: =+IFERROR(HLOOKUP($B18,'[2]12월'!$F$6:$CP$99,3,),)/1000 -> 1273.3891 | Q18: =+P18-O18 -> 58.1988 | R18: =+IFERROR(HLOOKUP($B18,'[3]12월'!$F$6:$CC$57,3,),)/1000 -> 673.84925 | S18: =+P18-R18 -> 599.53985 | T18: =+IFERROR(HLOOKUP($B18,'[1]12월'!$D$6:$BN$259,16,),)/1000 -> 108.93391 | U18: =+IFERROR(HLOOKUP($B18,'[2]12월'!$F$6:$CP$99,16,),)/1000 -> 24.366226 | V18: =+U18-T18 -> -84.567688 | W18: =+IFERROR(HLOOKUP($B18,'[3]12월'!$F$6:$CC$57,16,),)/1000 -> -94.482644 | X18: =+U18-W18 -> 118.84887 | Y18: =+[5]울산!$Q$85 -> 101265.86 | Z18: =+[5]울산!$R$85 -> 102272.03 | AA18: =+[6]울산!$Q$85 -> 100170.84 | AB18: =+[5]울산!$Q$89 -> 80550.789 | AC18: =+[5]울산!$R$89 -> 84277.211 | AD18: =+[6]울산!$Q$89 -> 81166.341 | AE18: =+Y18-AB18 -> 20715.07 | AF18: =+Z18-AC18 -> 17994.823 | AG18: =+AA18-AD18 -> 19004.5
B19: 아산 | G19: =+I19 -> 아산 | I19: 아산 | J19: =+IFERROR(HLOOKUP($B19,'[1]12월'!$D$6:$BN$259,2,),)/1000 -> 27 | K19: =+IFERROR(HLOOKUP($B19,'[2]12월'!$F$6:$CP$99,2,),)/1000 -> 22.732 | L19: =+K19-J19 -> -4.268 | M19: =+IFERROR(HLOOKUP($B19,'[3]12월'!$F$6:$CC$57,2,),)/1000 -> 21.023 | N19: =+K19-M19 -> 1.709 | O19: =+IFERROR(HLOOKUP($B19,'[1]12월'!$D$6:$BN$259,3,),)/1000 -> 2727 | P19: =+IFERROR(HLOOKUP($B19,'[2]12월'!$F$6:$CP$99,3,),)/1000 -> 2299.4823 | Q19: =+P19-O19 -> -427.5177 | R19: =+IFERROR(HLOOKUP($B19,'[3]12월'!$F$6:$CC$57,3,),)/1000 -> 2021.2951 | S19: =+P19-R19 -> 278.1872 | T19: =+IFERROR(HLOOKUP($B19,'[1]12월'!$D$6:$BN$259,16,),)/1000 -> 380.38225 | U19: =+IFERROR(HLOOKUP($B19,'[2]12월'!$F$6:$CP$99,16,),)/1000 -> 58.469241 | V19: =+U19-T19 -> -321.91301 | W19: =+IFERROR(HLOOKUP($B19,'[3]12월'!$F$6:$CC$57,16,),)/1000 -> 8.618231 | X19: =+U19-W19 -> 49.85101 | Y19: =+[5]아산!$Q$85 -> 101000 | Z19: =+[5]아산!$R$85 -> 101156.18 | AA19: =+[6]아산!$Q$85 -> 95785.019 | AB19: =+[5]아산!$Q$89 -> 79449.486 | AC19: =+[5]아산!$R$89 -> 85004.174 | AD19: =+[6]아산!$Q$89 -> 77943.486 | AE19: =+Y19-AB19 -> 21550.514 | AF19: =+Z19-AC19 -> 16152.007 | AG19: =+AA19-AD19 -> 17841.534
B20: 전주 | G20: =+I20 -> 전주 | I20: 전주 | J20: =+IFERROR(HLOOKUP($B20,'[1]12월'!$D$6:$BN$259,2,),)/1000 -> 11 | K20: =+IFERROR(HLOOKUP($B20,'[2]12월'!$F$6:$CP$99,2,),)/1000 -> 10.326 | L20: =+K20-J20 -> -0.674 | M20: =+IFERROR(HLOOKUP($B20,'[3]12월'!$F$6:$CC$57,2,),)/1000 -> 11.59 | N20: =+K20-M20 -> -1.264 | O20: =+IFERROR(HLOOKUP($B20,'[1]12월'!$D$6:$BN$259,3,),)/1000 -> 1127.8313 | P20: =+IFERROR(HLOOKUP($B20,'[2]12월'!$F$6:$CP$99,3,),)/1000 -> 1002.0519 | Q20: =+P20-O20 -> -125.77933 | R20: =+IFERROR(HLOOKUP($B20,'[3]12월'!$F$6:$CC$57,3,),)/1000 -> 1081.6514 | S20: =+P20-R20 -> -79.599472 | T20: =+IFERROR(HLOOKUP($B20,'[1]12월'!$D$6:$BN$259,16,),)/1000 -> 185.50495 | U20: =+IFERROR(HLOOKUP($B20,'[2]12월'!$F$6:$CP$99,16,),)/1000 -> 10.653327 | V20: =+U20-T20 -> -174.85162 | W20: =+IFERROR(HLOOKUP($B20,'[3]12월'!$F$6:$CC$57,16,),)/1000 -> 36.652521 | X20: =+U20-W20 -> -25.999194 | Y20: =+[5]전주!$Q$85 -> 102530.11 | Z20: =+[5]전주!$R$85 -> 97041.635 | AA20: =+[6]전주!$Q$85 -> 93361.374 | AB20: =+[5]전주!$Q$89 -> 73002.694 | AC20: =+[5]전주!$R$89 -> 74828.153 | AD20: =+[6]전주!$Q$89 -> 68175.181 | AE20: =+Y20-AB20 -> 29527.421 | AF20: =+Z20-AC20 -> 22213.483 | AG20: =+AA20-AD20 -> 25186.194
B21: 군산 | G21: =+I21 -> 군산 | I21: 군산 | J21: =+IFERROR(HLOOKUP($B21,'[1]12월'!$D$6:$BN$259,2,),)/1000 -> 7 | K21: =+IFERROR(HLOOKUP($B21,'[2]12월'!$F$6:$CP$99,2,),)/1000 -> 5.608 | L21: =+K21-J21 -> -1.392 | M21: =+IFERROR(HLOOKUP($B21,'[3]12월'!$F$6:$CC$57,2,),)/1000 -> 5.0555 | N21: =+K21-M21 -> 0.5525 | O21: =+IFERROR(HLOOKUP($B21,'[1]12월'!$D$6:$BN$259,3,),)/1000 -> 762.99903 | P21: =+IFERROR(HLOOKUP($B21,'[2]12월'!$F$6:$CP$99,3,),)/1000 -> 597.354 | Q21: =+P21-O21 -> -165.64503 | R21: =+IFERROR(HLOOKUP($B21,'[3]12월'!$F$6:$CC$57,3,),)/1000 -> 527.68332 | S21: =+P21-R21 -> 69.670678 | T21: =+IFERROR(HLOOKUP($B21,'[1]12월'!$D$6:$BN$259,16,),)/1000 -> 192.6416 | U21: =+IFERROR(HLOOKUP($B21,'[2]12월'!$F$6:$CP$99,16,),)/1000 -> 80.152254 | V21: =+U21-T21 -> -112.48935 | W21: =+IFERROR(HLOOKUP($B21,'[3]12월'!$F$6:$CC$57,16,),)/1000 -> 34.121359 | X21: =+U21-W21 -> 46.030895 | Y21: =+[5]군산!$Q$85 -> 108999.86 | Z21: =+[5]군산!$R$85 -> 106518.19 | AA21: =+[6]군산!$Q$85 -> 104623.27 | AB21: =+[5]군산!$Q$89 -> 70884.733 | AC21: =+[5]군산!$R$89 -> 73466.5 | AD21: =+[6]군산!$Q$89 -> 69954.422 | AE21: =+Y21-AB21 -> 38115.129 | AF21: =+Z21-AC21 -> 33051.688 | AG21: =+AA21-AD21 -> 34668.85
B22: 원주 | G22: =+I22 -> 원주 | I22: 원주 | J22: =+IFERROR(HLOOKUP($B22,'[1]12월'!$D$6:$BN$259,2,),)/1000 -> 4 | K22: =+IFERROR(HLOOKUP($B22,'[2]12월'!$F$6:$CP$99,2,),)/1000 -> 4.01 | L22: =+K22-J22 -> 0.01 | M22: =+IFERROR(HLOOKUP($B22,'[3]12월'!$F$6:$CC$57,2,),)/1000 -> 6.189 | N22: =+K22-M22 -> -2.179 | O22: =+IFERROR(HLOOKUP($B22,'[1]12월'!$D$6:$BN$259,3,),)/1000 -> 431.6 | P22: =+IFERROR(HLOOKUP($B22,'[2]12월'!$F$6:$CP$99,3,),)/1000 -> 460.867 | Q22: =+P22-O22 -> 29.267 | R22: =+IFERROR(HLOOKUP($B22,'[3]12월'!$F$6:$CC$57,3,),)/1000 -> 648.47726 | S22: =+P22-R22 -> -187.61025 | T22: =+IFERROR(HLOOKUP($B22,'[1]12월'!$D$6:$BN$259,16,),)/1000 -> 49.390684 | U22: =+IFERROR(HLOOKUP($B22,'[2]12월'!$F$6:$CP$99,16,),)/1000 -> 39.135277 | V22: =+U22-T22 -> -10.255407 | W22: =+IFERROR(HLOOKUP($B22,'[3]12월'!$F$6:$CC$57,16,),)/1000 -> 38.745038 | X22: =+U22-W22 -> 0.390239 | Y22: =+[5]원주!$Q$85 -> 107900 | Z22: =+[5]원주!$R$85 -> 114929.43 | AA22: =+[6]원주!$Q$85 -> 104784.9 | AB22: =+[5]원주!$Q$89 -> 75861.9 | AC22: =+[5]원주!$R$89 -> 76446.968 | AD22: =+[6]원주!$Q$89 -> 75081.703 | AE22: =+Y22-AB22 -> 32038.1 | AF22: =+Z22-AC22 -> 38482.458 | AG22: =+AA22-AD22 -> 29703.198
B23: 제주 | G23: =+I23 -> 제주 | I23: 제주 | J23: =+IFERROR(HLOOKUP($B23,'[1]12월'!$D$6:$BN$259,2,),)/1000 -> 7 | K23: =+IFERROR(HLOOKUP($B23,'[2]12월'!$F$6:$CP$99,2,),)/1000 -> 5.5875 | L23: =+K23-J23 -> -1.4125 | M23: =+IFERROR(HLOOKUP($B23,'[3]12월'!$F$6:$CC$57,2,),)/1000 -> 4.902 | N23: =+K23-M23 -> 0.6855 | O23: =+IFERROR(HLOOKUP($B23,'[1]12월'!$D$6:$BN$259,3,),)/1000 -> 888.3 | P23: =+IFERROR(HLOOKUP($B23,'[2]12월'!$F$6:$CP$99,3,),)/1000 -> 668.43715 | Q23: =+P23-O23 -> -219.86285 | R23: =+IFERROR(HLOOKUP($B23,'[3]12월'!$F$6:$CC$57,3,),)/1000 -> 579.44633 | S23: =+P23-R23 -> 88.990821 | T23: =+IFERROR(HLOOKUP($B23,'[1]12월'!$D$6:$BN$259,16,),)/1000 -> 161.64138 | U23: =+IFERROR(HLOOKUP($B23,'[2]12월'!$F$6:$CP$99,16,),)/1000 -> 49.681543 | V23: =+U23-T23 -> -111.95983 | W23: =+IFERROR(HLOOKUP($B23,'[3]12월'!$F$6:$CC$57,16,),)/1000 -> -5.762215 | X23: =+U23-W23 -> 55.443758 | Y23: =+[5]제주!$Q$85 -> 126900 | Z23: =+[5]제주!$R$85 -> 119630.81 | AA23: =+[6]제주!$Q$85 -> 118206.11 | AB23: =+[5]제주!$Q$89 -> 91213.272 | AC23: =+[5]제주!$R$89 -> 89066.435 | AD23: =+[6]제주!$Q$89 -> 87458.101 | AE23: =+Y23-AB23 -> 35686.728 | AF23: =+Z23-AC23 -> 30564.375 | AG23: =+AA23-AD23 -> 30748.004
G24: =+I24 -> 수도권 | I24: 수도권 | J24: =SUM(J7:J10) -> 113.5 | K24: =SUM(K7:K10) -> 94.7535 | L24: =+K24-J24 -> -18.7465 | M24: =SUM(M7:M10) -> 105.14 | N24: =+K24-M24 -> -10.3865 | O24: =SUM(O7:O10) -> 11621.591 | P24: =SUM(P7:P10) -> 9072.334 | Q24: =+P24-O24 -> -2549.2568 | R24: =SUM(R7:R10) -> 10211.659 | S24: =+P24-R24 -> -1139.3252 | T24: =SUM(T7:T10) -> 1604.9217 | U24: =SUM(U7:U10) -> -204.53605 | V24: =+U24-T24 -> -1809.4577 | W24: =SUM(W7:W10) -> -203.09543 | X24: =+U24-W24 -> -1.440617 | Y24: =+[5]수도권!$Q$85 -> 102392.87 | Z24: =+[5]수도권!$R$85 -> 95753.183 | AA24: =+[6]수도권!$Q$85 -> 97106.847 | AB24: =+[5]수도권!$Q$89 -> 79958.056 | AC24: =+[5]수도권!$R$89 -> 83930.891 | AD24: =+[6]수도권!$Q$89 -> 81709.417 | AE24: =+Y24-AB24 -> 22434.814 | AF24: =+Z24-AC24 -> 11822.292 | AG24: =+AA24-AD24 -> 15397.43
G25: =+I25 -> 영남권 | I25: 영남권 | J25: =SUM(J11:J18) -> 138 | K25: =SUM(K11:K18) -> 129.272 | L25: =+K25-J25 -> -8.728 | M25: =SUM(M11:M18) -> 130.01 | N25: =+K25-M25 -> -0.738 | O25: =SUM(O11:O18) -> 14160.65 | P25: =SUM(P11:P18) -> 13072.183 | Q25: =+P25-O25 -> -1088.4669 | R25: =SUM(R11:R18) -> 12772.025 | S25: =+P25-R25 -> 300.15786 | T25: =SUM(T11:T18) -> 2073.5981 | U25: =SUM(U11:U18) -> 534.66819 | V25: =+U25-T25 -> -1538.9299 | W25: =SUM(W11:W18) -> -61.669156 | X25: =+U25-W25 -> 596.33735 | Y25: =+[5]영남권!$Q$85 -> 102613.4 | Z25: =+[5]영남권!$R$85 -> 101138.02 | AA25: =+[6]영남권!$Q$85 -> 98238.787 | AB25: =+[5]영남권!$Q$89 -> 77244.33 | AC25: =+[5]영남권!$R$89 -> 81325.207 | AD25: =+[6]영남권!$Q$89 -> 78500.132 | AE25: =+Y25-AB25 -> 25369.073 | AF25: =+Z25-AC25 -> 19812.809 | AG25: =+AA25-AD25 -> 19738.655
G26: =+I26 -> 중부권 | I26: 중부권 | J26: =SUM(J19:J23) -> 56 | K26: =SUM(K19:K23) -> 48.2635 | L26: =+K26-J26 -> -7.7365 | M26: =SUM(M19:M23) -> 48.7595 | N26: =+K26-M26 -> -0.496 | O26: =SUM(O19:O23) -> 5937.7303 | P26: =SUM(P19:P23) -> 5028.1924 | Q26: =+P26-O26 -> -909.53791 | R26: =SUM(R19:R23) -> 4858.5534 | S26: =+P26-R26 -> 169.63897 | T26: =SUM(T19:T23) -> 969.56086 | U26: =SUM(U19:U23) -> 238.09164 | V26: =+U26-T26 -> -731.46922 | W26: =SUM(W19:W23) -> 112.37493 | X26: =+U26-W26 -> 125.71671 | Y26: =+[5]중부권!$Q$85 -> 106030.9 | Z26: =+[5]중부권!$R$85 -> 104182.09 | AA26: =+[6]중부권!$Q$85 -> 99522.849 | AB26: =+[5]중부권!$Q$89 -> 78326.775 | AC26: =+[5]중부권!$R$89 -> 81258.436 | AD26: =+[6]중부권!$Q$89 -> 75388.642 | AE26: =+Y26-AB26 -> 27704.123 | AF26: =+Z26-AC26 -> 22923.655 | AG26: =+AA26-AD26 -> 24134.208
G27: =+K27/J27 -> 0.88549268 | H27: 레미콘 계 | J27: =SUM(J24:J26) -> 307.5 | K27: =SUM(K24:K26) -> 272.289 | L27: =+K27-J27 -> -35.211 | M27: =SUM(M24:M26) -> 283.9095 | N27: =+K27-M27 -> -11.6205 | O27: =SUM(O24:O26) -> 31719.971 | P27: =SUM(P24:P26) -> 27172.709 | Q27: =+P27-O27 -> -4547.2616 | R27: =SUM(R24:R26) -> 27842.237 | S27: =+P27-R27 -> -669.52837 | T27: =SUM(T24:T26) -> 4648.0806 | U27: =SUM(U24:U26) -> 568.22379 | V27: =+U27-T27 -> -4079.8568 | W27: =SUM(W24:W26) -> -152.38965 | X27: =+U27-W27 -> 720.61344 | Y27: =+[5]합계!$Q$85 -> 103154.38 | Z27: =+[5]합계!$R$85 -> 99802.99 | AA27: =+[6]합계!$Q$85 -> 98036.161 | AB27: =+[5]합계!$Q$89 -> 78443.11 | AC27: =+[5]합계!$R$89 -> 82213.022 | AD27: =+[6]합계!$Q$89 -> 79164.481 | AE27: =+Y27-AB27 -> 24711.266 | AF27: =+Z27-AC27 -> 17589.968 | AG27: =+AA27-AD27 -> 18871.68
B28: 건자재 | E28: 건자재영업 | G28: 건자재 | H28: 건자재 | J28: =+IFERROR(HLOOKUP($B28,'[1]12월'!$D$6:$BN$259,2,),) -> 8600 | K28: =+IFERROR(HLOOKUP($E28,'[2]12월'!$F$6:$CP$99,2,),) -> 8003.057 | L28: =+K28-J28 -> -596.943 | M28: =+IFERROR(HLOOKUP($E28,'[3]12월'!$F$6:$CC$57,2,),) -> 7811.91 | N28: =+K28-M28 -> 191.147 | O28: =+IFERROR(HLOOKUP($B28,'[1]12월'!$D$6:$BN$259,3,),)/1000 -> 10504.632 | P28: =+IFERROR(HLOOKUP($E28,'[2]12월'!$F$6:$CP$99,3,),)/1000 -> 7445.9016 | Q28: =+P28-O28 -> -3058.73 | R28: =+IFERROR(HLOOKUP($E28,'[3]12월'!$F$6:$CC$57,3,),)/1000 -> 9622.7532 | S28: =+P28-R28 -> -2176.8516 | T28: =+IFERROR(HLOOKUP($B28,'[1]12월'!$D$6:$BN$259,16,),)/1000 -> 139.04025 | U28: =+IFERROR(HLOOKUP($E28,'[2]12월'!$F$6:$CP$99,16,),)/1000 -> -101.10207 | V28: =+U28-T28 -> -240.14232 | W28: =+IFERROR(HLOOKUP($E28,'[3]12월'!$F$6:$CC$57,16,),)/1000 -> -86.633557 | X28: =+U28-W28 -> -14.468516 | Y28: ■ 비고
B29: 부산모래장 | C29: 부산골재 | G29: =+I29 -> 부산모래장 | H29: 골재 | I29: 부산모래장 | J29: =+IFERROR(HLOOKUP($B29,'[1]12월'!$D$6:$BN$259,2,),)/1000 -> 28.532458 | K29: =+IFERROR(HLOOKUP($C29,'[2]12월'!$F$6:$CP$99,2,),)/1000 -> 23.035 | L29: =+K29-J29 -> -5.4974576 | M29: =+IFERROR(HLOOKUP($C29,'[3]12월'!$F$6:$CC$57,2,),)/1000 -> 24.924 | N29: =+K29-M29 -> -1.889 | O29: =+IFERROR(HLOOKUP($B29,'[1]12월'!$D$6:$BN$259,3,),)/1000 -> 811.06468 | P29: =+IFERROR(HLOOKUP($C29,'[2]12월'!$F$6:$CP$99,3,),)/1000 -> 638.333 | Q29: =+P29-O29 -> -172.73168 | R29: =+IFERROR(HLOOKUP($C29,'[3]12월'!$F$6:$CC$57,3,),)/1000 -> 710.713 | S29: =+P29-R29 -> -72.38 | T29: =+IFERROR(HLOOKUP($B29,'[1]12월'!$D$6:$BN$259,21,),)/1000 -> 62.971538 | U29: =+IFERROR(HLOOKUP($C29,'[2]12월'!$F$6:$CP$99,21,),)/1000 -> -21.304281 | V29: =+U29-T29 -> -84.275819 | W29: =+IFERROR(HLOOKUP($C29,'[3]12월'!$F$6:$CC$57,16,),)/1000 -> -21.164563 | X29: =+U29-W29 -> -0.13971837 | Y29: - 1군단가 소급분 : 3.5억
B30: 서부산크라샤 | C30: 서부산골재 | G30: =+I30 -> 서부산CR | I30: 서부산CR | J30: =+IFERROR(HLOOKUP($B30,'[1]12월'!$D$6:$BN$259,2,),)/1000 -> 50.439763 | K30: =+IFERROR(HLOOKUP($C30,'[2]12월'!$F$6:$CP$99,2,),)/1000 -> 1 | L30: =+K30-J30 -> -49.439763 | M30: =+IFERROR(HLOOKUP($C30,'[3]12월'!$F$6:$CC$57,2,),)/1000 -> 25.332 | N30: =+K30-M30 -> -24.332 | O30: =+IFERROR(HLOOKUP($B30,'[1]12월'!$D$6:$BN$259,3,),)/1000 -> 623.24578 | P30: =+IFERROR(HLOOKUP($C30,'[2]12월'!$F$6:$CP$99,3,),)/1000 -> 11.5 | Q30: =+P30-O30 -> -611.74578 | R30: =+IFERROR(HLOOKUP($C30,'[3]12월'!$F$6:$CC$57,3,),)/1000 -> 323.054 | S30: =+P30-R30 -> -311.554 | T30: =+IFERROR(HLOOKUP($B30,'[1]12월'!$D$6:$BN$259,21,),)/1000 -> 138.21488 | U30: =+IFERROR(HLOOKUP($C30,'[2]12월'!$F$6:$CP$99,21,),)/1000 -> -151.79414 | V30: =+U30-T30 -> -290.00903 | W30: =+IFERROR(HLOOKUP($C30,'[3]12월'!$F$6:$CC$57,16,),)/1000 -> -33.388204 | X30: =+U30-W30 -> -118.40594 | Y30: (DL건설 1.3억, 롯데건설 0.4억, 한라 0.6억 등)
B31: 부산크라샤 | C31: 부산크라샤 | G31: =+I31 -> 부산CR | I31: 부산CR | J31: =+IFERROR(HLOOKUP($B31,'[1]12월'!$D$6:$BN$259,2,),)/1000 -> 41.933006 | K31: =+IFERROR(HLOOKUP($C31,'[2]12월'!$F$6:$CP$99,2,),)/1000 -> 35.645 | L31: =+K31-J31 -> -6.2880061 | M31: =+IFERROR(HLOOKUP($C31,'[3]12월'!$F$6:$CC$57,2,),)/1000 -> 19.977 | N31: =+K31-M31 -> 15.668 | O31: =+IFERROR(HLOOKUP($B31,'[1]12월'!$D$6:$BN$259,3,),)/1000 -> 770.37721 | P31: =+IFERROR(HLOOKUP($C31,'[2]12월'!$F$6:$CP$99,3,),)/1000 -> 630.6815 | Q31: =+P31-O31 -> -139.69571 | R31: =+IFERROR(HLOOKUP($C31,'[3]12월'!$F$6:$CC$57,3,),)/1000 -> 367.506 | S31: =+P31-R31 -> 263.1755 | T31: =+IFERROR(HLOOKUP($B31,'[1]12월'!$D$6:$BN$259,21,),)/1000 -> 97.65592 | U31: =+IFERROR(HLOOKUP($C31,'[2]12월'!$F$6:$CP$99,21,),)/1000 -> -294.10381 | V31: =+U31-T31 -> -391.75973 | W31: =+IFERROR(HLOOKUP($C31,'[3]12월'!$F$6:$CC$57,16,),)/1000 -> -356.44776 | X31: =+U31-W31 -> 62.343949
H32: 골재 계 | J32: =SUM(J29:J31) -> 120.90523 | K32: =SUM(K29:K31) -> 59.68 | L32: =+K32-J32 -> -61.225227 | M32: =SUM(M29:M31) -> 70.233 | N32: =+K32-M32 -> -10.553 | O32: =SUM(O29:O31) -> 2204.6877 | P32: =SUM(P29:P31) -> 1280.5145 | Q32: =+P32-O32 -> -924.17317 | R32: =SUM(R29:R31) -> 1401.273 | S32: =+P32-R32 -> -120.7585 | T32: =SUM(T29:T31) -> 298.84234 | U32: =SUM(U29:U31) -> -467.20224 | V32: =+U32-T32 -> -766.04457 | W32: =SUM(W29:W31) -> -411.00052 | X32: =+U32-W32 -> -56.20171 | Y32: ▶ 운반비 소급
B33: 포항임대 | C33: 속초임대 | D33: 강릉임대 | E33: 레미콘임대 계 | G33: =+I33 -> 레미콘임대 | H33: 기타 | I33: 레미콘임대 | L33: =+K33-J33 -> 0 | N33: =+K33-M33 -> 0 | O33: =(IFERROR(HLOOKUP($B33,'[1]12월'!$D$6:$BN$259,3,),)++IFERROR(HLOOKUP($C33,'[1]12월'!$D$6:$BN$259,3,),)+IFERROR(HLOOKUP($D33,'[1]12월'!$D$6:$BN$259,3,),))/1000 -> 90.84 | P33: =+IFERROR(HLOOKUP($E33,'[2]12월'!$F$6:$CP$99,3,),)/1000 -> 90.84 | Q33: =+P33-O33 -> 0 | R33: =+IFERROR(HLOOKUP($E33,'[3]12월'!$F$6:$CC$57,3,),)/1000 -> 90.84 | S33: =+P33-R33 -> 0 | T33: =(IFERROR(HLOOKUP($B33,'[1]12월'!$D$6:$BN$259,21,),)++IFERROR(HLOOKUP($C33,'[1]12월'!$D$6:$BN$259,21,),)+IFERROR(HLOOKUP($D33,'[1]12월'!$D$6:$BN$259,21,),))/1000 -> 75.360275 | U33: =+IFERROR(HLOOKUP($E33,'[2]12월'!$F$6:$CP$99,16,),)/1000 -> 76.068675 | V33: =+U33-T33 -> 0.7084 | W33: =+IFERROR(HLOOKUP($E33,'[3]12월'!$F$6:$CC$57,16,),)/1000 -> 73.170018 | X33: =+U33-W33 -> 2.898657 | Y33: - 파주 : 75백만원
B34: 부동산임대 | C34: 주유소임대 | E34: 임대 계 | G34: =+I34 -> 임대 | I34: 임대 | L34: =+K34-J34 -> 0 | M34: 0 | N34: =+K34-M34 -> 0 | O34: =(+IFERROR(HLOOKUP($B34,'[1]12월'!$D$6:$BN$259,3,),)+IFERROR(HLOOKUP($C34,'[1]12월'!$D$6:$BN$259,3,),))/1000 -> 72.2975 | P34: =+IFERROR(HLOOKUP($E34,'[2]12월'!$F$6:$CP$99,3,),)/1000 -> 72.69194 | Q34: =+P34-O34 -> 0.39443967 | R34: =+IFERROR(HLOOKUP($E34,'[3]12월'!$F$6:$CC$57,3,),)/1000 -> 78.665941 | S34: =+P34-R34 -> -5.974001 | T34: =(+IFERROR(HLOOKUP($B34,'[1]12월'!$D$6:$BN$259,21,),)+IFERROR(HLOOKUP($C34,'[1]12월'!$D$6:$BN$259,21,),))/1000 -> 74.623417 | U34: =+IFERROR(HLOOKUP($E34,'[2]12월'!$F$6:$CP$99,16,),)/1000 -> 75.153125 | V34: =+U34-T34 -> 0.52970767 | W34: =+IFERROR(HLOOKUP($E34,'[3]12월'!$F$6:$CC$57,16,),)/1000 -> 86.623723 | X34: =+U34-W34 -> -11.470598
B35: 공 통 비 | G35: =+I35 -> 공통비 | I35: 공통비 | L35: =+K35-J35 -> 0 | N35: =+K35-M35 -> 0 | Q35: =+P35-O35 -> 0 | S35: =+P35-R35 -> 0 | T35: =-'[1]12월'!$Z$22/1000 -> -1213.1221 | U35: =+-'[2]12월'!$Z$22/1000 -> -2089.6312 | V35: =+U35-T35 -> -876.50913 | W35: =+-'[3]12월'!$Z$22/1000 -> -3008.8593 | X35: =+U35-W35 -> 919.22813
G36: =+I36 -> OPC 소급분 | I36: OPC 소급분 | N36: =+K36-M36 -> 0 | Q36: =+P36-O36 -> 0 | S36: =+P36-R36 -> 0 | T36: =+'[1]12월'!$AS$26/1000 -> 0 | U36: ='[2]12월'!$BD$26/1000 -> 300 | V36: =+U36-T36 -> 300 | W36: ='[3]12월'!$BD$26/1000 -> 1028.9851 | X36: =+U36-W36 -> -728.9851
G37: =+I37 -> 대손 | I37: 대손 | N37: =+K37-M37 -> 0 | Q37: =+P37-O37 -> 0 | S37: =+P37-R37 -> 0 | U37: ='[2]12월'!$BE$26/1000 -> 319.51271 | V37: =+U37-T37 -> 319.51271 | W37: ='[3]12월'!$BE$26/1000 -> -983.77338 | X37: =+U37-W37 -> 1303.2861
G38: =+I38 -> 미운영 공장 | I38: 미운영 공장 | M38: =SUM(M54:M59) -> 0 | N38: =+K38-M38 -> 0 | Q38: =+P38-O38 -> 0 | R38: =+IFERROR(HLOOKUP($I$38,'[3]12월'!$F$6:$BJ$50,3,),)/1000 -> 0 | S38: =+P38-R38 -> 0 | T38: =SUM('[1]12월'!$AM$26:$AQ$26)/1000 -> -3.4117974 | U38: =+'[2]12월'!$BF$26/1000 -> -3.689587 | V38: =+U38-T38 -> -0.27778956 | W38: =+'[3]12월'!$BF$26/1000 -> -6.898677 | X38: =+U38-W38 -> 3.20909
B39: 기타 계 | G39: =+I39 -> 기타 | I39: 기타 | L39: =+K39-J39 -> 0 | N39: =+K39-M39 -> 0 | O39: =IFERROR(HLOOKUP($B39,'[1]12월'!$D$6:$BN$259,3,),)/1000 -> 1.77 | P39: =+('[2]12월'!$F$8-SUM('[2]12월'!$Z$8,'[2]12월'!$AH$8,'[2]12월'!$AN$8,'[2]12월'!$AO$8,'[2]12월'!$BA$8,'[2]12월'!$BD$8,'[2]12월'!$BE$8,'[2]12월'!$BF$8))/1000 -> 1.67985 | Q39: =+P39-O39 -> -0.09015 | R39: =+('[3]12월'!$F$8-SUM('[3]12월'!$Z$8,'[3]12월'!$AH$8,'[3]12월'!$AN$8,'[3]12월'!$AO$8,'[3]12월'!$BA$8,'[3]12월'!$BD$8,'[3]12월'!$BE$8,'[3]12월'!$BF$8))/1000 -> 1.7024 | S39: =+P39-R39 -> -0.02255 | T39: =+('[1]12월'!$E$26-'[1]12월'!$Z$26-'[1]12월'!$AA$26-'[1]12월'!$AE$26-'[1]12월'!$AL$26-'[1]12월'!$AM$26-'[1]12월'!$AN$26-'[1]12월'!$AO$26-'[1]12월'!$AP$26-'[1]12월'!$AQ$26-'[1]12월'!$AS$26)/1000 -> -68.088929 | U39: =+('[2]12월'!$F$26-SUM('[2]12월'!$Z$26,'[2]12월'!$AH$26,'[2]12월'!$AN$26,'[2]12월'!$AO$26,'[2]12월'!$BA$26,'[2]12월'!$BD$26,'[2]12월'!$BE$26,'[2]12월'!$BF$26))/1000 -> 16.456465 | V39: =+U39-T39 -> 84.545394 | W39: =+('[3]12월'!$F$26-SUM('[3]12월'!$Z$26,'[3]12월'!$AH$26,'[3]12월'!$AN$26,'[3]12월'!$AO$26,'[3]12월'!$BA$26,'[3]12월'!$BD$26,'[3]12월'!$BE$26,'[3]12월'!$BF$26))/1000 -> -24.335643 | X39: =+U39-W39 -> 40.792108
N40: =+K40-M40 -> 0 | Q40: =+P40-O40 -> 0 | S40: =+P40-R40 -> 0 | V40: =+U40-T40 -> 0
H41: 기타 계 | J41: =SUM(J33:J40) -> 0 | K41: =SUM(K33:K40) -> 0 | L41: =+K41-J41 -> 0 | M41: =SUM(M33:M40) -> 0 | N41: =+K41-M41 -> 0 | O41: =SUM(O33:O40) -> 164.9075 | P41: =SUM(P33:P40) -> 165.21179 | Q41: =+P41-O41 -> 0.30428967 | R41: =SUM(R33:R40) -> 171.20834 | S41: =+P41-R41 -> -5.996551 | T41: =SUM(T33:T40) -> -1134.6391 | U41: =SUM(U33:U40) -> -1306.1298 | V41: =+U41-T41 -> -171.49071 | W41: =SUM(W33:W40) -> -2835.0882 | X41: =+U41-W41 -> 1528.9584
U42: 19 | V42: 12.4
...

Sheet 사업장별(누계)
H3: □ 사업장별 손익실적(2024-12누계)
AG4: [단위 : 천㎥, 톤, 백만원]
H5: 구분 | J5: 물량 | O5: 매출 | T5: 영업이익(공통비 배부전) | Y5: 판매단가 | AB5: 변동비 | AE5: 공헌이익
A6: 2024년 12월 마감 손익 | J6: 계획 | K6: 실적 | L6: 차이 | M6: 전년 | N6: 차이 | O6: 계획 | P6: 실적 | Q6: 차이 | R6: 전년 | S6: 차이 | T6: 계획 | U6: 실적 | V6: 차이 | W6: 전년 | X6: 차이 | Y6: 계획 | Z6: 실적 | AA6: 전년 | AB6: 계획 | AC6: 실적 | AD6: 전년 | AE6: 계획 | AF6: 실적 | AG6: 전년
B7: 안양 | F7: =+U7/T7 -> 0.5506912 | G7: =+K7/J7 -> 0.893814 | H7: 레미콘 | I7: 안양 | J7: =+'사업장별(당월)'!J7+'[4]사업장별(누계)'!J7 -> 500 | K7: =+'사업장별(당월)'!K7+'[4]사업장별(누계)'!K7 -> 446.907 | L7: =+K7-J7 -> -53.093 | M7: =+'사업장별(당월)'!M7+'[4]사업장별(누계)'!M7 -> 544.765 | N7: =+K7-M7 -> -97.858 | O7: =+'사업장별(당월)'!O7+'[4]사업장별(누계)'!O7 -> 50250.119 | P7: =+'사업장별(당월)'!P7+'[4]사업장별(누계)'!P7 -> 44168.65 | Q7: =+P7-O7 -> -6081.4697 | R7: =+'사업장별(당월)'!R7+'[4]사업장별(누계)'!R7 -> 50719.371 | S7: =+P7-R7 -> -6550.7215 | T7: =+'사업장별(당월)'!T7+'[4]사업장별(누계)'!T7 -> 6989.3154 | U7: =+'사업장별(당월)'!U7+'[4]사업장별(누계)'!U7 -> 3848.9545 | V7: =+U7-T7 -> -3140.3609 | W7: =+'사업장별(당월)'!W7+'[4]사업장별(누계)'!W7 -> 6550.2457 | X7: =+U7-W7 -> -2701.2912 | Y7: =+[11]안양!$Q$85 -> 100500.24 | Z7: =+[11]안양!$R$85 -> 98828.586 | AA7: =+[12]안양!$Q$85 -> 93081.061 | AB7: =+[11]안양!$Q$89 -> 79231.068 | AC7: =+[11]안양!$R$89 -> 81804.462 | AD7: =+[12]안양!$Q$89 -> 74052.677 | AE7: =+Y7-AB7 -> 21269.171 | AF7: =+Z7-AC7 -> 17024.125 | AG7: =+AA7-AD7 -> 19028.384 | AI7: =+U7/T7-1 -> -0.4493088 | AJ7: =+U7/T7 -> 0.5506912 | AK7: =+Z7-Y7 -> -1671.6524 | AL7: =+AC7-AB7 -> 2573.394 | AM7: =+AF7-AE7 -> -4245.0464
B8: 인천 | F8: =+U8/T8 -> 0.36086237 | G8: =+K8/J8 -> 0.86037895 | H8: 직영 | I8: 인천 | J8: =+'사업장별(당월)'!J8+'[4]사업장별(누계)'!J8 -> 380 | K8: =+'사업장별(당월)'!K8+'[4]사업장별(누계)'!K8 -> 326.944 | L8: =+K8-J8 -> -53.056 | M8: =+'사업장별(당월)'!M8+'[4]사업장별(누계)'!M8 -> 437.945 | N8: =+K8-M8 -> -111.001 | O8: =+'사업장별(당월)'!O8+'[4]사업장별(누계)'!O8 -> 39128.8 | P8: =+'사업장별(당월)'!P8+'[4]사업장별(누계)'!P8 -> 32487.436 | Q8: =+P8-O8 -> -6641.3644 | R8: =+'사업장별(당월)'!R8+'[4]사업장별(누계)'!R8 -> 42191.154 | S8: =+P8-R8 -> -9703.718 | T8: =+'사업장별(당월)'!T8+'[4]사업장별(누계)'!T8 -> 4669.8056 | U8: =+'사업장별(당월)'!U8+'[4]사업장별(누계)'!U8 -> 1685.1571 | V8: =+U8-T8 -> -2984.6485 | W8: =+'사업장별(당월)'!W8+'[4]사업장별(누계)'!W8 -> 4579.4671 | X8: =+U8-W8 -> -2894.31 | Y8: =+[11]인천!$Q$85 -> 102970.53 | Z8: =+[11]인천!$R$85 -> 99370.184 | AA8: =+[12]인천!$Q$85 -> 96316.253 | AB8: =+[11]인천!$Q$89 -> 81332.759 | AC8: =+[11]인천!$R$89 -> 83063.772 | AD8: =+[12]인천!$Q$89 -> 77106.068 | AE8: =+Y8-AB8 -> 21637.768 | AF8: =+Z8-AC8 -> 16306.412 | AG8: =+AA8-AD8 -> 19210.184 | AI8: =+U8/T8-1 -> -0.63913763 | AK8: =+Z8-Y8 -> -3600.3423 | AL8: =+AC8-AB8 -> 1731.0131 | AM8: =+AF8-AE8 -> -5331.3555
B9: 파주 | F9: =+U9/T9 -> 0.42226919 | G9: =+K9/J9 -> 0.97362759 | I9: 파주 | J9: =+'사업장별(당월)'!J9+'[4]사업장별(누계)'!J9 -> 290 | K9: =+'사업장별(당월)'!K9+'[4]사업장별(누계)'!K9 -> 282.352 | L9: =+K9-J9 -> -7.648 | M9: =+'사업장별(당월)'!M9+'[4]사업장별(누계)'!M9 -> 319.151 | N9: =+K9-M9 -> -36.799 | O9: =+'사업장별(당월)'!O9+'[4]사업장별(누계)'!O9 -> 28710 | P9: =+'사업장별(당월)'!P9+'[4]사업장별(누계)'!P9 -> 27203.18 | Q9: =+P9-O9 -> -1506.8199 | R9: =+'사업장별(당월)'!R9+'[4]사업장별(누계)'!R9 -> 29900.26 | S9: =+P9-R9 -> -2697.0796 | T9: =+'사업장별(당월)'!T9+'[4]사업장별(누계)'!T9 -> 3820.6954 | U9: =+'사업장별(당월)'!U9+'[4]사업장별(누계)'!U9 -> 1613.3619 | V9: =+U9-T9 -> -2207.3334 | W9: =+'사업장별(당월)'!W9+'[4]사업장별(누계)'!W9 -> 2798.536 | X9: =+U9-W9 -> -1185.1741 | Y9: =+[11]파주!$Q$85 -> 99000 | Z9: =+[11]파주!$R$85 -> 96350.004 | AA9: =+[12]파주!$Q$85 -> 93667.602 | AB9: =+[11]파주!$Q$89 -> 76707.816 | AC9: =+[11]파주!$R$89 -> 80693.655 | AD9: =+[12]파주!$Q$89 -> 75977.981 | AE9: =+Y9-AB9 -> 22292.184 | AF9: =+Z9-AC9 -> 15656.349 | AG9: =+AA9-AD9 -> 17689.621 | AI9: =+U9/T9-1 -> -0.57773081 | AK9: =+Z9-Y9 -> -2649.9959 | AL9: =+AC9-AB9 -> 3985.8389 | AM9: =+AF9-AE9 -> -6635.8348
