Workbook

Sheet 표지
A6: 2024년 1월 마감 손익
A24: 건재사업본부

Sheet 손익총괄
C3: □ 건재사업본부 손익실적(2024-01)
X4: [단위 : 천㎥, 톤, 원/㎥, 원/톤, 백만원]
C5: 구분 | E5: 1월 | J5: 1월 누계 | P5: 1월 주요지표
E6: 계획 | F6: 실적 | G6: 계획대비 | H6: 전년 | I6: 전년대비 | J6: 계획 | K6: 실적 | L6: 계획대비 | M6: 전년 | N6: 전년대비
C7: 물량 | D7: 레미콘 | E7: =+'[1]1월'!$Z$7/1000 -> 241 | F7: =+'[2]1월'!$Z$7/1000 -> 278.8855 | G7: =+F7-E7 -> 37.8855 | H7: =+'[3]1월'!$Z$7/1000 -> 268.581 | I7: =+F7-H7 -> 10.3045 | J7: =+E7 -> 241 | K7: =+F7 -> 278.8855 | L7: =+K7-J7 -> 37.8855 | M7: =+H7 -> 268.581 | N7: =+K7-M7 -> 10.3045 | Q7: □ 레미콘
D8: 철강재 | E8: =+'[1]1월'!$AA$7 -> 6900 | F8: =+'[2]1월'!$AO$7 -> 6425.093 | G8: =+F8-E8 -> -474.907 | H8: =+'[3]1월'!$AO$7 -> 6946.787 | I8: =+F8-H8 -> -521.694 | J8: =+E8 -> 6900 | K8: =+F8 -> 6425.093 | L8: =+K8-J8 -> -474.907 | M8: =+H8 -> 6946.787 | N8: =+K8-M8 -> -521.694 | Q8: 구분 | S8: 계획 | T8: 실적 | U8: 계획대비 | V8: 전년 | W8: 전년대비
D9: 골재 | E9: =+'[1]1월'!$AE$7/1000 -> 76.628971 | F9: =+'[2]1월'!$AN$7/1000 -> 84.517 | G9: =+F9-E9 -> 7.8880294 | H9: =+'[3]1월'!$AN$7/1000 -> 65.885 | I9: =+F9-H9 -> 18.632 | J9: =+E9 -> 76.628971 | K9: =+F9 -> 84.517 | L9: =+K9-J9 -> 7.8880294 | M9: =+H9 -> 65.885 | N9: =+K9-M9 -> 18.632 | Q9: 물량 | R9: 수도권 | S9: =+[4]수도권!$T$5/1000 -> 93 | T9: =+[4]수도권!$U$5/1000 -> 102.264 | U9: =+T9-S9 -> 9.264 | V9: =+[5]수도권!$T$5/1000 -> 93.376 | W9: =+T9-V9 -> 8.888
C10: 매출 | D10: 레미콘 | E10: =+'[1]1월'!$Z$8/1000 -> 24174.594 | F10: =+'[2]1월'!$Z$8/1000 -> 27875.646 | G10: =+F10-E10 -> 3701.052 | H10: =+'[3]1월'!$Z$8/1000 -> 24787.856 | I10: =+F10-H10 -> 3087.7903 | J10: =+E10 -> 24174.594 | K10: =+F10 -> 27875.646 | L10: =+K10-J10 -> 3701.052 | M10: =+H10 -> 24787.856 | N10: =+K10-M10 -> 3087.7903 | R10: 영남권 | S10: =+[4]영남권!$T$5/1000 -> 110.5 | T10: =+[4]영남권!$U$5/1000 -> 132.898 | U10: =+T10-S10 -> 22.398 | V10: =+[5]영남권!$T$5/1000 -> 132.135 | W10: =+T10-V10 -> 0.763
D11: 건자재 | E11: =+'[1]1월'!$AA$8/1000 -> 8447.9432 | F11: =+'[2]1월'!$AO$8/1000 -> 7407.9572 | G11: =+F11-E11 -> -1039.986 | H11: =+'[3]1월'!$AO$8/1000 -> 8813.6343 | I11: =+F11-H11 -> -1405.6771 | J11: =+E11 -> 8447.9432 | K11: =+F11 -> 7407.9572 | L11: =+K11-J11 -> -1039.986 | M11: =+H11 -> 8813.6343 | N11: =+K11-M11 -> -1405.6771 | R11: 중부권 | S11: =+[4]중부권!$T$5/1000 -> 37.5 | T11: =+[4]중부권!$U$5/1000 -> 43.7235 | U11: =+T11-S11 -> 6.2235 | V11: =+[5]중부권!$T$5/1000 -> 43.07 | W11: =+T11-V11 -> 0.6535
D12: 골재 | E12: =+'[1]1월'!$AE$8/1000 -> 1600.163 | F12: =+'[2]1월'!$AN$8/1000 -> 1719.52 | G12: =+F12-E12 -> 119.357 | H12: =+'[3]1월'!$AN$8/1000 -> 1298.828 | I12: =+F12-H12 -> 420.692 | J12: =+E12 -> 1600.163 | K12: =+F12 -> 1719.52 | L12: =+K12-J12 -> 119.357 | M12: =+H12 -> 1298.828 | N12: =+K12-M12 -> 420.692 | Q12: 계 | S12: =SUM(S9:S11) -> 241 | T12: =SUM(T9:T11) -> 278.8855 | U12: =+T12-S12 -> 37.8855 | V12: =SUM(V9:V11) -> 268.581 | W12: =+T12-V12 -> 10.3045
D13: 기타 | E13: =+'[1]1월'!$E$8/1000-E10-E11-E12 -> 164.9075 | F13: =+'[2]1월'!$F$8/1000-F10-F11-F12 -> 164.47551 | G13: =+F13-E13 -> -0.43198933 | H13: =+'[3]1월'!$F$8/1000-H10-H11-H12 -> 174.12202 | I13: =+F13-H13 -> -9.646507 | J13: =+E13 -> 164.9075 | K13: =+F13 -> 164.47551 | L13: =+K13-J13 -> -0.43198933 | M13: =+H13 -> 174.12202 | N13: =+K13-M13 -> -9.646507 | Q13: 판매단가 | R13: 수도권 | S13: =+[4]수도권!$T$61 -> 96584.296 | T13: =+[4]수도권!$U$61 -> 97064.272 | U13: =+T13-S13 -> 479.97601 | V13: =+[5]수도권!$Q$85 -> 88709.415 | W13: =+T13-V13 -> 8354.8575
C14: 계 | E14: =SUM(E10:E13) -> 34387.608 | F14: =SUM(F10:F13) -> 37167.599 | G14: =+F14-E14 -> 2779.991 | H14: =SUM(H10:H13) -> 35074.44 | I14: =+F14-H14 -> 2093.1587 | J14: =SUM(J10:J13) -> 34387.608 | K14: =SUM(K10:K13) -> 37167.599 | L14: =+K14-J14 -> 2779.991 | M14: =SUM(M10:M13) -> 35074.44 | N14: =+K14-M14 -> 2093.1587 | R14: 영남권 | S14: =+[4]영남권!$T$61 -> 101787.62 | T14: =+[4]영남권!$U$61 -> 101515.92 | U14: =+T14-S14 -> -271.69447 | V14: =+[5]영남권!$Q$85 -> 94314.373 | W14: =+T14-V14 -> 7201.5512
C15: 매출원가 | D15: 레미콘 | E15: =+('[1]1월'!$Z$10+'[1]1월'!$Z$19)/1000 -> 21260.178 | F15: =+('[2]1월'!$Z$10+'[2]1월'!$Z$19)/1000 -> 24879.532 | G15: =+F15-E15 -> 3619.354 | H15: =+('[3]1월'!$Z$10+'[3]1월'!$Z$19)/1000 -> 21521.109 | I15: =+F15-H15 -> 3358.423 | J15: =+E15 -> 21260.178 | K15: =+F15 -> 24879.532 | L15: =+K15-J15 -> 3619.354 | M15: =+H15 -> 21521.109 | N15: =+K15-M15 -> 3358.423 | R15: 중부권 | S15: =+[4]중부권!$T$61 -> 105192.6 | T15: =+[4]중부권!$U$61 -> 101965.11 | U15: =+T15-S15 -> -3227.486 | V15: =+[5]중부권!$Q$85 -> 94006.133 | W15: =+T15-V15 -> 7958.9802
D16: 건자재 | E16: =+('[1]1월'!$AA$10+'[1]1월'!$AA$19)/1000 -> 8231.947 | F16: =+('[2]1월'!$AO$10+'[2]1월'!$AO$19)/1000 -> 7210.525 | G16: =+F16-E16 -> -1021.422 | H16: =+('[3]1월'!$AO$10+'[3]1월'!$AO$19)/1000 -> 8643.8546 | I16: =+F16-H16 -> -1433.3297 | J16: =+E16 -> 8231.947 | K16: =+F16 -> 7210.525 | L16: =+K16-J16 -> -1021.422 | M16: =+H16 -> 8643.8546 | N16: =+K16-M16 -> -1433.3297 | Q16: 계 | S16: =+[4]합계!$T$61 -> 100309.52 | T16: =+[4]합계!$U$61 -> 99953.913 | U16: =+T16-S16 -> -355.60552 | V16: =+[5]합계!$Q$85 -> 92313.001 | W16: =+T16-V16 -> 7640.9112
D17: 골재 | E17: =+('[1]1월'!$AE$10+'[1]1월'!$AE$19)/1000 -> 1537.4161 | F17: =+('[2]1월'!$AN$10+'[2]1월'!$AN$19)/1000 -> 1493.2747 | G17: =+F17-E17 -> -44.141385 | H17: =+('[3]1월'!$AN$10+'[3]1월'!$AN$19)/1000 -> 1262.1867 | I17: =+F17-H17 -> 231.08795 | J17: =+E17 -> 1537.4161 | K17: =+F17 -> 1493.2747 | L17: =+K17-J17 -> -44.141385 | M17: =+H17 -> 1262.1867 | N17: =+K17-M17 -> 231.08795 | Q17: 공헌이익 | R17: 수도권 | S17: =+[4]수도권!$Q$90 -> 17067.215 | T17: =+[4]수도권!$R$90 -> 14738.448 | U17: =+T17-S17 -> -2328.7671 | V17: =+[5]수도권!$Q$90 -> 15348.166 | W17: =+T17-V17 -> -609.71745
D18: 기타 | E18: =+('[1]1월'!$E$10+'[1]1월'!$E$19)/1000-E15-E16-E17 -> 28.941068 | F18: =+('[2]1월'!$F$10+'[2]1월'!$F$19)/1000-F15-F16-F17 -> 28.511818 | G18: =+F18-E18 -> -0.42925 | H18: =+('[3]1월'!$F$10+'[3]1월'!$F$19)/1000-H15-H16-H17 -> 24.350789 | I18: =+F18-H18 -> 4.161029 | J18: =+E18 -> 28.941068 | K18: =+F18 -> 28.511818 | L18: =+K18-J18 -> -0.42925 | M18: =+H18 -> 24.350789 | N18: =+K18-M18 -> 4.161029 | R18: 영남권 | S18: =+[4]영남권!$Q$90 -> 25872.937 | T18: =+[4]영남권!$R$90 -> 22138.533 | U18: =+T18-S18 -> -3734.4037 | V18: =+[5]영남권!$Q$90 -> 23848.398 | W18: =+T18-V18 -> -1709.8647
C19: 계 | E19: =SUM(E15:E18) -> 31058.482 | F19: =SUM(F15:F18) -> 33611.844 | G19: =+F19-E19 -> 2553.3613 | H19: =SUM(H15:H18) -> 31451.501 | I19: =+F19-H19 -> 2160.3423 | J19: =SUM(J15:J18) -> 31058.482 | K19: =SUM(K15:K18) -> 33611.844 | L19: =+K19-J19 -> 2553.3613 | M19: =SUM(M15:M18) -> 31451.501 | N19: =+K19-M19 -> 2160.3423 | R19: 중부권 | S19: =+[4]중부권!$Q$90 -> 27936.218 | T19: =+[4]중부권!$R$90 -> 22621.219 | U19: =+T19-S19 -> -5314.9983 | V19: =+[5]중부권!$Q$90 -> 26408.326 | W19: =+T19-V19 -> -3787.1071
C20: 매출이익 | D20: 레미콘 | E20: =+E10-E15 -> 2914.4157 | F20: =+F10-F15 -> 2996.1137 | G20: =+F20-E20 -> 81.698016 | H20: =+H10-H15 -> 3266.7464 | I20: =+F20-H20 -> -270.63265 | J20: =+J10-J15 -> 2914.4157 | K20: =+K10-K15 -> 2996.1137 | L20: =+K20-J20 -> 81.698016 | M20: =+M10-M15 -> 3266.7464 | N20: =+K20-M20 -> -270.63265 | Q20: 계 | S20: =+[4]합계!$Q$90 -> 22795.928 | T20: =+[4]합계!$R$90 -> 19500.633 | U20: =+T20-S20 -> -3295.2957 | V20: =+[5]합계!$Q$90 -> 21283.131 | W20: =+T20-V20 -> -1782.4986
D21: 건자재 | E21: =+E11-E16 -> 215.99616 | F21: =+F11-F16 -> 197.43221 | G21: =+F21-E21 -> -18.563956 | H21: =+H11-H16 -> 169.77968 | I21: =+F21-H21 -> 27.652529 | J21: =+J11-J16 -> 215.99616 | K21: =+K11-K16 -> 197.43221 | L21: =+K21-J21 -> -18.563956 | M21: =+M11-M16 -> 169.77968 | N21: =+K21-M21 -> 27.652529 | Q21: □ 건자재
D22: 골재 | E22: =+E12-E17 -> 62.746914 | F22: =+F12-F17 -> 226.2453 | G22: =+F22-E22 -> 163.49839 | H22: =+H12-H17 -> 36.641259 | I22: =+F22-H22 -> 189.60405 | J22: =+J12-J17 -> 62.746914 | K22: =+K12-K17 -> 226.2453 | L22: =+K22-J22 -> 163.49839 | M22: =+M12-M17 -> 36.641259 | N22: =+K22-M22 -> 189.60405 | Q22: 구분 | S22: 계획 | T22: 실적 | U22: 계획대비 | V22: 전년 | W22: 전년대비
D23: 기타 | E23: =+E13-E18 -> 135.96643 | F23: =+F13-F18 -> 135.96369 | G23: =+F23-E23 -> -0.0027393333 | H23: =+H13-H18 -> 149.77123 | I23: =+F23-H23 -> -13.807536 | J23: =+J13-J18 -> 135.96643 | K23: =+K13-K18 -> 135.96369 | L23: =+K23-J23 -> -0.0027393333 | M23: =+M13-M18 -> 149.77123 | N23: =+K23-M23 -> -13.807536 | Q23: 철강재 판매단가 | S23: =+'[6]1월'!$F$10 -> 976086.96 | T23: =+'[6]1월'!$G$10 -> 920730.85 | U23: =+T23-S23 -> -55356.103 | V23: =+'[7]1월'!$G$10 -> 1098907.9 | W23: =+T23-V23 -> -178177.01
C24: 계 | E24: =SUM(E20:E23) -> 3329.1252 | F24: =SUM(F20:F23) -> 3555.7549 | G24: =+F24-E24 -> 226.62971 | H24: =SUM(H20:H23) -> 3622.9385 | I24: =+F24-H24 -> -67.183609 | J24: =SUM(J20:J23) -> 3329.1252 | K24: =SUM(K20:K23) -> 3555.7549 | L24: =+K24-J24 -> 226.62971 | M24: =SUM(M20:M23) -> 3622.9385 | N24: =+K24-M24 -> -67.183609 | Q24: 철강재 마진률 | S24: =+'[6]1월'!$F$15 -> 0.023224944 | T24: =+'[6]1월'!$G$15 -> 0.027823179 | U24: =+T24-S24 -> 0.0045982344 | V24: =+'[7]1월'!$G$15 -> 0.01948828 | W24: =+T24-V24 -> 0.0083348986
C25: 판관비 | D25: 레미콘 | E25: =+('[1]1월'!$Z$13+'[1]1월'!$Z$20)/1000 -> 653.67612 | F25: =+('[2]1월'!$Z$13+'[2]1월'!$Z$20)/1000 -> 671.52442 | G25: =+F25-E25 -> 17.848295 | H25: =+('[3]1월'!$Z$13+'[3]1월'!$Z$20)/1000 -> 725.33702 | I25: =+F25-H25 -> -53.812603 | J25: =+E25 -> 653.67612 | K25: =+F25 -> 671.52442 | L25: =+K25-J25 -> 17.848295 | M25: =+H25 -> 725.33702 | N25: =+K25-M25 -> -53.812603 | Q25: □ 골재
D26: 건자재 | E26: =+('[1]1월'!$AA$13+'[1]1월'!$AA$20)/1000 -> 121.24568 | F26: =+('[2]1월'!$AO$13+'[2]1월'!$AO$20)/1000 -> 122.165 | G26: =+F26-E26 -> 0.919316 | H26: =+('[3]1월'!$AO$13+'[3]1월'!$AO$20)/1000 -> 95.380744 | I26: =+F26-H26 -> 26.784252 | J26: =+E26 -> 121.24568 | K26: =+F26 -> 122.165 | L26: =+K26-J26 -> 0.919316 | M26: =+H26 -> 95.380744 | N26: =+K26-M26 -> 26.784252 | Q26: 구분 | S26: 계획 | T26: 실적 | U26: 계획대비 | V26: 전년 | W26: 전년대비
D27: 골재 | E27: =+('[1]1월'!$AE$13+'[1]1월'!$AE$20+'[1]1월'!$AE$22)/1000 -> 35.72189 | F27: =+('[2]1월'!$AN$13+'[2]1월'!$AN$20+'[2]1월'!$AN$22)/1000 -> 42.171572 | G27: =+F27-E27 -> 6.4496818 | H27: =+('[3]1월'!$AN$13+'[3]1월'!$AN$20+'[3]1월'!$AN$22)/1000 -> 18.206703 | I27: =+F27-H27 -> 23.964869 | J27: =+E27 -> 35.72189 | K27: =+F27 -> 42.171572 | L27: =+K27-J27 -> 6.4496818 | M27: =+H27 -> 18.206703 | N27: =+K27-M27 -> 23.964869 | Q27: 판매량 | R27: 자가 | S27: =(+'[8]서부산크라샤(당월)'!$N$66+'[8]부산모래장(당월)'!$Q$48+'[8]부산크라샤(당월)'!$N$66)/1000 -> 47.628971 | T27: =(+'[8]서부산크라샤(당월)'!$O$66+'[8]부산모래장(당월)'!$R$48+'[8]부산크라샤(당월)'!$O$66)/1000 -> 55.736 | U27: =+T27-S27 -> 8.1070294 | V27: =('[9]부산골재(당월)'!$R$48+'[9]서부산골재(당월)'!$O$66+'[9]부산크라샤(당월)'!$O$66)/1000 -> 42.542 | W27: =+T27-V27 -> 13.194
D28: 기타 | E28: =+('[1]1월'!$E$13+'[1]1월'!$E$20)/1000-E25-E26-E27+('[1]1월'!$E$22/1000) -> 1514.8179 | F28: =+('[2]1월'!$F$13+'[2]1월'!$F$20)/1000-F25-F26-F27+'[2]1월'!$F$22/1000 -> 1604.8254 | G28: =+F28-E28 -> 90.007512 | H28: =+('[3]1월'!$F$13+'[3]1월'!$F$20)/1000-H25-H26-H27+'[3]1월'!$F$22/1000 -> 1311.6563 | I28: =+F28-H28 -> 293.16906 | J28: =+E28 -> 1514.8179 | K28: =+F28 -> 1604.8254 | L28: =+K28-J28 -> 90.007512 | M28: =+H28 -> 1311.6563 | N28: =+K28-M28 -> 293.16906 | R28: 외판 | S28: =(+'[8]서부산크라샤(당월)'!$N$59+'[8]부산모래장(당월)'!$Q$47+'[8]부산크라샤(당월)'!$N$59)/1000 -> 29 | T28: =(+'[8]서부산크라샤(당월)'!$O$59+'[8]부산모래장(당월)'!$R$47+'[8]부산크라샤(당월)'!$O$59)/1000 -> 28.781 | U28: =+T28-S28 -> -0.219 | V28: =+('[9]부산골재(당월)'!$R$47+'[9]서부산골재(당월)'!$O$59+'[9]부산크라샤(당월)'!$O$59)/1000 -> 23.343 | W28: =+T28-V28 -> 5.438
C29: 계 | E29: =SUM(E25:E28) -> 2325.4616 | F29: =SUM(F25:F28) -> 2440.6864 | G29: =+F29-E29 -> 115.2248 | H29: =SUM(H25:H28) -> 2150.5808 | I29: =+F29-H29 -> 290.10558 | J29: =SUM(J25:J28) -> 2325.4616 | K29: =SUM(K25:K28) -> 2440.6864 | L29: =+K29-J29 -> 115.2248 | M29: =SUM(M25:M28) -> 2150.5808 | N29: =+K29-M29 -> 290.10558 | Q29: 합 계 | S29: =SUM(S27:S28) -> 76.628971 | T29: =SUM(T27:T28) -> 84.517 | U29: =+T29-S29 -> 7.8880294 | V29: =SUM(V27:V28) -> 65.885 | W29: =+T29-V29 -> 18.632
C30: 영업이익 | D30: 레미콘 | E30: =+E20-E25 -> 2260.7396 | F30: =+F20-F25 -> 2324.5893 | G30: =+F30-E30 -> 63.849721 | H30: =+H20-H25 -> 2541.4093 | I30: =+F30-H30 -> -216.82004 | J30: =+J20-J25 -> 2260.7396 | K30: =+K20-K25 -> 2324.5893 | L30: =+K30-J30 -> 63.849721 | M30: =+M20-M25 -> 2541.4093 | N30: =+K30-M30 -> -216.82004 | Q30: □ 기타내역(영업이익)
D31: % | E31: =+E30/E10 -> 0.093517168 | F31: =+F30/F10 -> 0.083391406 | G31: =+F31-E31 -> -0.010125763 | H31: =+H30/H10 -> 0.10252639 | I31: =+F31-H31 -> -0.019134984 | J31: =+J30/J10 -> 0.093517168 | K31: =+K30/K10 -> 0.083391406 | L31: =+K31-J31 -> -0.010125763 | M31: =+M30/M10 -> 0.10252639 | N31: =+K31-M31 -> -0.019134984 | Q31: 구분 | S31: 계획 | T31: 실적 | U31: 계획대비 | V31: 전년 | W31: 전년대비
D32: 건자재 | E32: =+E21-E26 -> 94.750483 | F32: =+F21-F26 -> 75.267211 | G32: =+F32-E32 -> -19.483272 | H32: =+H21-H26 -> 74.398934 | I32: =+F32-H32 -> 0.868277 | J32: =+J21-J26 -> 94.750483 | K32: =+K21-K26 -> 75.267211 | L32: =+K32-J32 -> -19.483272 | M32: =+M21-M26 -> 74.398934 | N32: =+K32-M32 -> 0.868277 | Q32: 레미콘임대 | S32: =+'사업장별(당월)'!T33 -> 72.165959 | T32: =+'사업장별(당월)'!U33 -> 71.79658 | U32: =+T32-S32 -> -0.369379 | V32: =+'사업장별(당월)'!W33 -> 59.685201 | W32: =+T32-V32 -> 12.111379
D33: 골재 | E33: =+E22-E27 -> 27.025024 | F33: =+F22-F27 -> 184.07373 | G33: =+F33-E33 -> 157.04871 | H33: =+H22-H27 -> 18.434556 | I33: =+F33-H33 -> 165.63918 | J33: =+J22-J27 -> 27.025024 | K33: =+K22-K27 -> 184.07373 | L33: =+K33-J33 -> 157.04871 | M33: =+M22-M27 -> 18.434556 | N33: =+K33-M33 -> 165.63918 | Q33: 임대 | S33: =+'사업장별(당월)'!T34 -> 62.030473 | T33: =+'사업장별(당월)'!U34 -> 61.824294 | U33: =+T33-S33 -> -0.20617933 | V33: =+'사업장별(당월)'!W34 -> 39.911628 | W33: =+T33-V33 -> 21.912666
D34: 기타 | E34: =+E23-E28 -> -1378.8514 | F34: =+F23-F28 -> -1468.8617 | G34: =+F34-E34 -> -90.010251 | H34: =+H23-H28 -> -1161.8851 | I34: =+F34-H34 -> -306.97659 | J34: =+J23-J28 -> -1378.8514 | K34: =+K23-K28 -> -1468.8617 | L34: =+K34-J34 -> -90.010251 | M34: =+M23-M28 -> -1161.8851 | N34: =+K34-M34 -> -306.97659 | Q34: 공통비 | S34: =+'사업장별(당월)'!T35 -> -1461.295 | T34: =+'사업장별(당월)'!U35 -> -1549.2991 | U34: =+T34-S34 -> -88.004163 | V34: =+'사업장별(당월)'!W35 -> -1236.2774 | W34: =+T34-V34 -> -313.02176
C35: 계 | E35: =SUM(E30,E32:E34) -> 1003.6636 | F35: =SUM(F30,F32:F34) -> 1115.0685 | G35: =+F35-E35 -> 111.40491 | H35: =SUM(H30,H32:H34) -> 1472.3577 | I35: =+F35-H35 -> -357.28919 | J35: =SUM(J30,J32:J34) -> 1003.6636 | K35: =SUM(K30,K32:K34) -> 1115.0685 | L35: =+K35-J35 -> 111.40491 | M35: =SUM(M30,M32:M34) -> 1472.3577 | N35: =+K35-M35 -> -357.28919 | Q35: 기타 | S35: =+S36-S32-S33-S34 -> -51.752892 | T35: =+T36-T32-T33-T34 -> -53.183423 | U35: =+T35-S35 -> -1.4305306 | V35: =+V36-V32-V33-V34 -> -25.204539 | W35: =+T35-V35 -> -27.978884
D36: % | E36: =+E35/E14 -> 0.029186783 | F36: =+F35/F14 -> 0.030001092 | G36: =+F36-E36 -> 0.00081430905 | H36: =+H35/H14 -> 0.041978082 | I36: =+F36-H36 -> -0.01197699 | J36: =+J35/J14 -> 0.029186783 | K36: =+K35/K14 -> 0.030001092 | L36: =+K36-J36 -> 0.00081430905 | M36: =+M35/M14 -> 0.041978082 | N36: =+K36-M36 -> -0.01197699 | Q36: 합계 | S36: =+'사업장별(당월)'!T41 -> -1378.8514 | T36: =+'사업장별(당월)'!U41 -> -1468.8617 | U36: =+T36-S36 -> -90.010251 | V36: =+'사업장별(당월)'!W41 -> -1161.8851 | W36: =+T36-V36 -> -306.97659
E38: =+'[1]1월'!$E$26/1000 -> 1003.6636 | F38: =+'[2]1월'!$F$26/1000 -> 1115.0685 | H38: =+'[3]1월'!$F$26/1000 -> 1472.3577 | J38: =+E38 -> 1003.6636 | K38: =+F38 -> 1115.0685 | M38: =+H38 -> 1472.3577
E39: =+E35=E38 -> TRUE | F39: =+F35=F38 -> TRUE | H39: =+H35=H38 -> TRUE | J39: =+J35=J38 -> TRUE | K39: =+K35=K38 -> TRUE | M39: =+M35=M38 -> TRUE
E40: =+E35-E38 -> 0 | F40: =+F35-F38 -> 4.3200998e-12 | H40: =+H35-H38 -> 0 | J40: =+J35-J38 -> 0 | K40: =+K35-K38 -> 4.3200998e-12 | M40: =+M35-M38 -> 0

Sheet 사업장별(당월)
H3: □ 사업장별 손익실적(2024-01)
AG4: [단위 : 천㎥, 톤, 백만원]
H5: 구분 | J5: 물량 | O5: 매출 | T5: 영업이익(공통비 배부전) | Y5: 판매단가 | AB5: 변동비 | AE5: 공헌이익
J6: 계획 | K6: 실적 | L6: 차이 | M6: 전년 | N6: 차이 | O6: 계획 | P6: 실적 | Q6: 차이 | R6: 전년 | S6: 차이 | T6: 계획 | U6: 실적 | V6: 차이 | W6: 전년 | X6: 차이 | Y6: 계획 | Z6: 실적 | AA6: 전년 | AB6: 계획 | AC6: 실적 | AD6: 전년 | AE6: 계획 | AF6: 실적 | AG6: 전년
B7: 안양 | G7: =+I7 -> 안양 | H7: 레미콘 | I7: 안양 | J7: =+IFERROR(HLOOKUP($B7,'[1]1월'!$D$6:$BN$259,2,),)/1000 -> 37 | K7: =+IFERROR(HLOOKUP($B7,'[2]1월'!$F$6:$CP$99,2,),)/1000 -> 45.761 | L7: =+K7-J7 -> 8.761 | M7: =+IFERROR(HLOOKUP($B7,'[3]1월'!$F$6:$CC$57,2,),)/1000 -> 39.266 | N7: =+K7-M7 -> 6.495 | O7: =+IFERROR(HLOOKUP($B7,'[1]1월'!$D$6:$BN$259,3,),)/1000 -> 3581.7519 | P7: =+IFERROR(HLOOKUP($B7,'[2]1월'!$F$6:$CP$99,3,),)/1000 -> 4371.1989 | Q7: =+P7-O7 -> 789.44705 | R7: =+IFERROR(HLOOKUP($B7,'[3]1월'!$F$6:$CC$57,3,),)/1000 -> 3529.8298 | S7: =+P7-R7 -> 841.3691 | T7: =+IFERROR(HLOOKUP($B7,'[1]1월'!$D$6:$BN$259,16,),)/1000 -> 326.89293 | U7: =+IFERROR(HLOOKUP($B7,'[2]1월'!$F$6:$CP$99,16,),)/1000 -> 337.22639 | V7: =+U7-T7 -> 10.333459 | W7: =+IFERROR(HLOOKUP($B7,'[3]1월'!$F$6:$CC$57,16,),)/1000 -> 393.29113 | X7: =+U7-W7 -> -56.06474 | Y7: =+[4]안양!$Q$85 -> 96804.104 | Z7: =+[4]안양!$R$85 -> 95522.364 | AA7: =+[5]안양!$Q$85 -> 89895.324 | AB7: =+[4]안양!$Q$89 -> 79892.321 | AC7: =+[4]안양!$R$89 -> 81107.602 | AD7: =+[5]안양!$Q$89 -> 72443.519 | AE7: =+Y7-AB7 -> 16911.783 | AF7: =+Z7-AC7 -> 14414.762 | AG7: =+AA7-AD7 -> 17451.805
B8: 인천 | G8: =+I8 -> 인천 | H8: 직영 | I8: 인천 | J8: =+IFERROR(HLOOKUP($B8,'[1]1월'!$D$6:$BN$259,2,),)/1000 -> 28 | K8: =+IFERROR(HLOOKUP($B8,'[2]1월'!$F$6:$CP$99,2,),)/1000 -> 28.34 | L8: =+K8-J8 -> 0.34 | M8: =+IFERROR(HLOOKUP($B8,'[3]1월'!$F$6:$CC$57,2,),)/1000 -> 24.957 | N8: =+K8-M8 -> 3.383 | O8: =+IFERROR(HLOOKUP($B8,'[1]1월'!$D$6:$BN$259,3,),)/1000 -> 2739.7515 | P8: =+IFERROR(HLOOKUP($B8,'[2]1월'!$F$6:$CP$99,3,),)/1000 -> 2766.8113 | Q8: =+P8-O8 -> 27.059798 | R8: =+IFERROR(HLOOKUP($B8,'[3]1월'!$F$6:$CC$57,3,),)/1000 -> 2220.1667 | S8: =+P8-R8 -> 546.64461 | T8: =+IFERROR(HLOOKUP($B8,'[1]1월'!$D$6:$BN$259,16,),)/1000 -> 125.23471 | U8: =+IFERROR(HLOOKUP($B8,'[2]1월'!$F$6:$CP$99,16,),)/1000 -> 102.92462 | V8: =+U8-T8 -> -22.31009 | W8: =+IFERROR(HLOOKUP($B8,'[3]1월'!$F$6:$CC$57,16,),)/1000 -> 29.293796 | X8: =+U8-W8 -> 73.630826 | Y8: =+[4]인천!$Q$85 -> 97848.269 | Z8: =+[4]인천!$R$85 -> 97629.193 | AA8: =+[5]인천!$Q$85 -> 88932.118 | AB8: =+[4]인천!$Q$89 -> 81867.136 | AC8: =+[4]인천!$R$89 -> 84063.445 | AD8: =+[5]인천!$Q$89 -> 74896.804 | AE8: =+Y8-AB8 -> 15981.133 | AF8: =+Z8-AC8 -> 13565.748 | AG8: =+AA8-AD8 -> 14035.314
B9: 파주 | G9: =+I9 -> 파주 | I9: 파주 | J9: =+IFERROR(HLOOKUP($B9,'[1]1월'!$D$6:$BN$259,2,),)/1000 -> 20 | K9: =+IFERROR(HLOOKUP($B9,'[2]1월'!$F$6:$CP$99,2,),)/1000 -> 22.882 | L9: =+K9-J9 -> 2.882 | M9: =+IFERROR(HLOOKUP($B9,'[3]1월'!$F$6:$CC$57,2,),)/1000 -> 20.905 | N9: =+K9-M9 -> 1.977 | O9: =+IFERROR(HLOOKUP($B9,'[1]1월'!$D$6:$BN$259,3,),)/1000 -> 1918.6197 | P9: =+IFERROR(HLOOKUP($B9,'[2]1월'!$F$6:$CP$99,3,),)/1000 -> 2301.3269 | Q9: =+P9-O9 -> 382.70724 | R9: =+IFERROR(HLOOKUP($B9,'[3]1월'!$F$6:$CC$57,3,),)/1000 -> 1836.6317 | S9: =+P9-R9 -> 464.69519 | T9: =+IFERROR(HLOOKUP($B9,'[1]1월'!$D$6:$BN$259,16,),)/1000 -> 141.9663 | U9: =+IFERROR(HLOOKUP($B9,'[2]1월'!$F$6:$CP$99,16,),)/1000 -> 116.27631 | V9: =+U9-T9 -> -25.689992 | W9: =+IFERROR(HLOOKUP($B9,'[3]1월'!$F$6:$CC$57,16,),)/1000 -> 0.643766 | X9: =+U9-W9 -> 115.63255 | Y9: =+[4]파주!$Q$85 -> 95930.984 | Z9: =+[4]파주!$R$85 -> 100573.68 | AA9: =+[5]파주!$Q$85 -> 87902.852 | AB9: =+[4]파주!$Q$89 -> 77860.175 | AC9: =+[4]파주!$R$89 -> 84086.773 | AD9: =+[5]파주!$Q$89 -> 76114 | AE9: =+Y9-AB9 -> 18070.809 | AF9: =+Z9-AC9 -> 16486.906 | AG9: =+AA9-AD9 -> 11788.851
B10: 김포 | G10: =+I10 -> 김포 | I10: 김포 | J10: =+IFERROR(HLOOKUP($B10,'[1]1월'!$D$6:$BN$259,2,),)/1000 -> 8 | K10: =+IFERROR(HLOOKUP($B10,'[2]1월'!$F$6:$CP$99,2,),)/1000 -> 5.281 | L10: =+K10-J10 -> -2.719 | M10: =+IFERROR(HLOOKUP($B10,'[3]1월'!$F$6:$CC$57,2,),)/1000 -> 8.248 | N10: =+K10-M10 -> -2.967 | O10: =+IFERROR(HLOOKUP($B10,'[1]1월'!$D$6:$BN$259,3,),)/1000 -> 742.2165 | P10: =+IFERROR(HLOOKUP($B10,'[2]1월'!$F$6:$CP$99,3,),)/1000 -> 486.8436 | Q10: =+P10-O10 -> -255.3729 | R10: =+IFERROR(HLOOKUP($B10,'[3]1월'!$F$6:$CC$57,3,),)/1000 -> 695.81949 | S10: =+P10-R10 -> -208.97589 | T10: =+IFERROR(HLOOKUP($B10,'[1]1월'!$D$6:$BN$259,16,),)/1000 -> -13.085594 | U10: =+IFERROR(HLOOKUP($B10,'[2]1월'!$F$6:$CP$99,16,),)/1000 -> -70.351562 | V10: =+U10-T10 -> -57.265968 | W10: =+IFERROR(HLOOKUP($B10,'[3]1월'!$F$6:$CC$57,16,),)/1000 -> -15.683073 | X10: =+U10-W10 -> -54.668489 | Y10: =+[4]김포!$Q$85 -> 92777.062 | Z10: =+[4]김포!$R$85 -> 92187.767 | AA10: =+[5]김포!$Q$85 -> 84362.208 | AB10: =+[4]김포!$Q$89 -> 73698.667 | AC10: =+[4]김포!$R$89 -> 75942.492 | AD10: =+[5]김포!$Q$89 -> 66383.614 | AE10: =+Y10-AB10 -> 19078.396 | AF10: =+Z10-AC10 -> 16245.275 | AG10: =+AA10-AD10 -> 17978.594
B11: 부산 | G11: =+I11 -> 부산 | I11: 부산 | J11: =+IFERROR(HLOOKUP($B11,'[1]1월'!$D$6:$BN$259,2,),)/1000 -> 18 | K11: =+IFERROR(HLOOKUP($B11,'[2]1월'!$F$6:$CP$99,2,),)/1000 -> 23.815 | L11: =+K11-J11 -> 5.815 | M11: =+IFERROR(HLOOKUP($B11,'[3]1월'!$F$6:$CC$57,2,),)/1000 -> 24.118 | N11: =+K11-M11 -> -0.303 | O11: =+IFERROR(HLOOKUP($B11,'[1]1월'!$D$6:$BN$259,3,),)/1000 -> 1936.7942 | P11: =+IFERROR(HLOOKUP($B11,'[2]1월'!$F$6:$CP$99,3,),)/1000 -> 2518.1609 | Q11: =+P11-O11 -> 581.36664 | R11: =+IFERROR(HLOOKUP($B11,'[3]1월'!$F$6:$CC$57,3,),)/1000 -> 2452.0565 | S11: =+P11-R11 -> 66.104366 | T11: =+IFERROR(HLOOKUP($B11,'[1]1월'!$D$6:$BN$259,16,),)/1000 -> 245.36511 | U11: =+IFERROR(HLOOKUP($B11,'[2]1월'!$F$6:$CP$99,16,),)/1000 -> 298.81115 | V11: =+U11-T11 -> 53.44604 | W11: =+IFERROR(HLOOKUP($B11,'[3]1월'!$F$6:$CC$57,16,),)/1000 -> 433.03577 | X11: =+U11-W11 -> -134.22462 | Y11: =+[4]부산!$Q$85 -> 107599.68 | Z11: =+[4]부산!$R$85 -> 105738.44 | AA11: =+[5]부산!$Q$85 -> 101668.21 | AB11: =+[4]부산!$Q$89 -> 78358.379 | AC11: =+[4]부산!$R$89 -> 82993.734 | AD11: =+[5]부산!$Q$89 -> 73283.728 | AE11: =+Y11-AB11 -> 29241.301 | AF11: =+Z11-AC11 -> 22744.702 | AG11: =+AA11-AD11 -> 28384.483
B12: 서부산 | G12: =+I12 -> 서부산 | I12: 서부산 | J12: =+IFERROR(HLOOKUP($B12,'[1]1월'!$D$6:$BN$259,2,),)/1000 -> 21 | K12: =+IFERROR(HLOOKUP($B12,'[2]1월'!$F$6:$CP$99,2,),)/1000 -> 23.91 | L12: =+K12-J12 -> 2.91 | M12: =+IFERROR(HLOOKUP($B12,'[3]1월'!$F$6:$CC$57,2,),)/1000 -> 20.168 | N12: =+K12-M12 -> 3.742 | O12: =+IFERROR(HLOOKUP($B12,'[1]1월'!$D$6:$BN$259,3,),)/1000 -> 2165.1353 | P12: =+IFERROR(HLOOKUP($B12,'[2]1월'!$F$6:$CP$99,3,),)/1000 -> 2338.4863 | Q12: =+P12-O12 -> 173.35098 | R12: =+IFERROR(HLOOKUP($B12,'[3]1월'!$F$6:$CC$57,3,),)/1000 -> 1845.0339 | S12: =+P12-R12 -> 493.4524 | T12: =+IFERROR(HLOOKUP($B12,'[1]1월'!$D$6:$BN$259,16,),)/1000 -> 313.84242 | U12: =+IFERROR(HLOOKUP($B12,'[2]1월'!$F$6:$CP$99,16,),)/1000 -> 198.0884 | V12: =+U12-T12 -> -115.75402 | W12: =+IFERROR(HLOOKUP($B12,'[3]1월'!$F$6:$CC$57,16,),)/1000 -> 187.27144 | X12: =+U12-W12 -> 10.816962 | Y12: =+[4]서부산!$Q$85 -> 103101.68 | Z12: =+[4]서부산!$R$85 -> 97803.693 | AA12: =+[5]서부산!$Q$85 -> 91483.236 | AB12: =+[4]서부산!$Q$89 -> 77368.389 | AC12: =+[4]서부산!$R$89 -> 79885.068 | AD12: =+[5]서부산!$Q$89 -> 71161.531 | AE12: =+Y12-AB12 -> 25733.292 | AF12: =+Z12-AC12 -> 17918.625 | AG12: =+AA12-AD12 -> 20321.705
B13: 김해 | G13: =+I13 -> 김해 | I13: 김해 | J13: =+IFERROR(HLOOKUP($B13,'[1]1월'!$D$6:$BN$259,2,),)/1000 -> 10 | K13: =+IFERROR(HLOOKUP($B13,'[2]1월'!$F$6:$CP$99,2,),)/1000 -> 12.339 | L13: =+K13-J13 -> 2.339 | M13: =+IFERROR(HLOOKUP($B13,'[3]1월'!$F$6:$CC$57,2,),)/1000 -> 11.598 | N13: =+K13-M13 -> 0.741 | O13: =+IFERROR(HLOOKUP($B13,'[1]1월'!$D$6:$BN$259,3,),)/1000 -> 1009.996 | P13: =+IFERROR(HLOOKUP($B13,'[2]1월'!$F$6:$CP$99,3,),)/1000 -> 1225.7102 | Q13: =+P13-O13 -> 215.7142 | R13: =+IFERROR(HLOOKUP($B13,'[3]1월'!$F$6:$CC$57,3,),)/1000 -> 1096.6881 | S13: =+P13-R13 -> 129.0221 | T13: =+IFERROR(HLOOKUP($B13,'[1]1월'!$D$6:$BN$259,16,),)/1000 -> 74.513101 | U13: =+IFERROR(HLOOKUP($B13,'[2]1월'!$F$6:$CP$99,16,),)/1000 -> 82.439169 | V13: =+U13-T13 -> 7.9260679 | W13: =+IFERROR(HLOOKUP($B13,'[3]1월'!$F$6:$CC$57,16,),)/1000 -> 87.333868 | X13: =+U13-W13 -> -4.894699 | Y13: =+[4]김해!$Q$85 -> 100999.6 | Z13: =+[4]김해!$R$85 -> 99339.807 | AA13: =+[5]김해!$Q$85 -> 94585.859 | AB13: =+[4]김해!$Q$89 -> 76745.601 | AC13: =+[4]김해!$R$89 -> 80683.799 | AD13: =+[5]김해!$Q$89 -> 73642.29 | AE13: =+Y13-AB13 -> 24253.999 | AF13: =+Z13-AC13 -> 18656.008 | AG13: =+AA13-AD13 -> 20943.57
B14: 정관 | G14: =+I14 -> 정관 | I14: 정관 | J14: =+IFERROR(HLOOKUP($B14,'[1]1월'!$D$6:$BN$259,2,),)/1000 -> 18 | K14: =+IFERROR(HLOOKUP($B14,'[2]1월'!$F$6:$CP$99,2,),)/1000 -> 21.5175 | L14: =+K14-J14 -> 3.5175 | M14: =+IFERROR(HLOOKUP($B14,'[3]1월'!$F$6:$CC$57,2,),)/1000 -> 18.264 | N14: =+K14-M14 -> 3.2535 | O14: =+IFERROR(HLOOKUP($B14,'[1]1월'!$D$6:$BN$259,3,),)/1000 -> 1872 | P14: =+IFERROR(HLOOKUP($B14,'[2]1월'!$F$6:$CP$99,3,),)/1000 -> 2218.1056 | Q14: =+P14-O14 -> 346.10565 | R14: =+IFERROR(HLOOKUP($B14,'[3]1월'!$F$6:$CC$57,3,),)/1000 -> 1770.7951 | S14: =+P14-R14 -> 447.31055 | T14: =+IFERROR(HLOOKUP($B14,'[1]1월'!$D$6:$BN$259,16,),)/1000 -> 244.37138 | U14: =+IFERROR(HLOOKUP($B14,'[2]1월'!$F$6:$CP$99,16,),)/1000 -> 256.96584 | V14: =+U14-T14 -> 12.594457 | W14: =+IFERROR(HLOOKUP($B14,'[3]1월'!$F$6:$CC$57,16,),)/1000 -> 235.72105 | X14: =+U14-W14 -> 21.24479 | Y14: =+[4]정관!$Q$85 -> 104000 | Z14: =+[4]정관!$R$85 -> 103083.8 | AA14: =+[5]정관!$Q$85 -> 96955.492 | AB14: =+[4]정관!$Q$89 -> 78930.42 | AC14: =+[4]정관!$R$89 -> 81962.525 | AD14: =+[5]정관!$Q$89 -> 73083.967 | AE14: =+Y14-AB14 -> 25069.58 | AF14: =+Z14-AC14 -> 21121.274 | AG14: =+AA14-AD14 -> 23871.525
B15: 양산 | G15: =+I15 -> 양산 | I15: 양산 | J15: =+IFERROR(HLOOKUP($B15,'[1]1월'!$D$6:$BN$259,2,),)/1000 -> 11 | K15: =+IFERROR(HLOOKUP($B15,'[2]1월'!$F$6:$CP$99,2,),)/1000 -> 13.864 | L15: =+K15-J15 -> 2.864 | M15: =+IFERROR(HLOOKUP($B15,'[3]1월'!$F$6:$CC$57,2,),)/1000 -> 12.092 | N15: =+K15-M15 -> 1.772 | O15: =+IFERROR(HLOOKUP($B15,'[1]1월'!$D$6:$BN$259,3,),)/1000 -> 1059.0887 | P15: =+IFERROR(HLOOKUP($B15,'[2]1월'!$F$6:$CP$99,3,),)/1000 -> 1311.9159 | Q15: =+P15-O15 -> 252.82724 | R15: =+IFERROR(HLOOKUP($B15,'[3]1월'!$F$6:$CC$57,3,),)/1000 -> 1104.9134 | S15: =+P15-R15 -> 207.0025 | T15: =+IFERROR(HLOOKUP($B15,'[1]1월'!$D$6:$BN$259,16,),)/1000 -> 120.73507 | U15: =+IFERROR(HLOOKUP($B15,'[2]1월'!$F$6:$CP$99,16,),)/1000 -> 152.26055 | V15: =+U15-T15 -> 31.525481 | W15: =+IFERROR(HLOOKUP($B15,'[3]1월'!$F$6:$CC$57,16,),)/1000 -> 138.27595 | X15: =+U15-W15 -> 13.984595 | Y15: =+[4]양산!$Q$85 -> 96280.788 | Z15: =+[4]양산!$R$85 -> 94627.517 | AA15: =+[5]양산!$Q$85 -> 91386.531 | AB15: =+[4]양산!$Q$89 -> 71791.379 | AC15: =+[4]양산!$R$89 -> 73539.584 | AD15: =+[5]양산!$Q$89 -> 67798.421 | AE15: =+Y15-AB15 -> 24489.409 | AF15: =+Z15-AC15 -> 21087.933 | AG15: =+AA15-AD15 -> 23588.11
B16: 창원 | G16: =+I16 -> 창원 | I16: 창원 | J16: =+IFERROR(HLOOKUP($B16,'[1]1월'!$D$6:$BN$259,2,),)/1000 -> 14 | K16: =+IFERROR(HLOOKUP($B16,'[2]1월'!$F$6:$CP$99,2,),)/1000 -> 17.315 | L16: =+K16-J16 -> 3.315 | M16: =+IFERROR(HLOOKUP($B16,'[3]1월'!$F$6:$CC$57,2,),)/1000 -> 18.165 | N16: =+K16-M16 -> -0.85 | O16: =+IFERROR(HLOOKUP($B16,'[1]1월'!$D$6:$BN$259,3,),)/1000 -> 1394.204 | P16: =+IFERROR(HLOOKUP($B16,'[2]1월'!$F$6:$CP$99,3,),)/1000 -> 1843.6711 | Q16: =+P16-O16 -> 449.4671 | R16: =+IFERROR(HLOOKUP($B16,'[3]1월'!$F$6:$CC$57,3,),)/1000 -> 1684.7087 | S16: =+P16-R16 -> 158.9624 | T16: =+IFERROR(HLOOKUP($B16,'[1]1월'!$D$6:$BN$259,16,),)/1000 -> 182.43936 | U16: =+IFERROR(HLOOKUP($B16,'[2]1월'!$F$6:$CP$99,16,),)/1000 -> 299.90023 | V16: =+U16-T16 -> 117.46087 | W16: =+IFERROR(HLOOKUP($B16,'[3]1월'!$F$6:$CC$57,16,),)/1000 -> 292.02561 | X16: =+U16-W16 -> 7.874615 | Y16: =+[4]창원!$Q$85 -> 99586 | Z16: =+[4]창원!$R$85 -> 106478.26 | AA16: =+[5]창원!$Q$85 -> 92744.767 | AB16: =+[4]창원!$Q$89 -> 72320.546 | AC16: =+[4]창원!$R$89 -> 77287.77 | AD16: =+[5]창원!$Q$89 -> 66159.287 | AE16: =+Y16-AB16 -> 27265.454 | AF16: =+Z16-AC16 -> 29190.491 | AG16: =+AA16-AD16 -> 26585.48
B17: 대구 | G17: =+I17 -> 대구 | I17: 대구 | J17: =+IFERROR(HLOOKUP($B17,'[1]1월'!$D$6:$BN$259,2,),)/1000 -> 13.5 | K17: =+IFERROR(HLOOKUP($B17,'[2]1월'!$F$6:$CP$99,2,),)/1000 -> 14.7545 | L17: =+K17-J17 -> 1.2545 | M17: =+IFERROR(HLOOKUP($B17,'[3]1월'!$F$6:$CC$57,2,),)/1000 -> 19.5995 | N17: =+K17-M17 -> -4.845 | O17: =+IFERROR(HLOOKUP($B17,'[1]1월'!$D$6:$BN$259,3,),)/1000 -> 1320.3 | P17: =+IFERROR(HLOOKUP($B17,'[2]1월'!$F$6:$CP$99,3,),)/1000 -> 1474.5359 | Q17: =+P17-O17 -> 154.2359 | R17: =+IFERROR(HLOOKUP($B17,'[3]1월'!$F$6:$CC$57,3,),)/1000 -> 1726.7423 | S17: =+P17-R17 -> -252.20645 | T17: =+IFERROR(HLOOKUP($B17,'[1]1월'!$D$6:$BN$259,16,),)/1000 -> 168.2638 | U17: =+IFERROR(HLOOKUP($B17,'[2]1월'!$F$6:$CP$99,16,),)/1000 -> 205.45768 | V17: =+U17-T17 -> 37.193881 | W17: =+IFERROR(HLOOKUP($B17,'[3]1월'!$F$6:$CC$57,16,),)/1000 -> 251.62929 | X17: =+U17-W17 -> -46.171605 | Y17: =+[4]대구!$Q$85 -> 97800 | Z17: =+[4]대구!$R$85 -> 99938.046 | AA17: =+[5]대구!$Q$85 -> 88101.347 | AB17: =+[4]대구!$Q$89 -> 71441.174 | AC17: =+[4]대구!$R$89 -> 74479.86 | AD17: =+[5]대구!$Q$89 -> 65599.88 | AE17: =+Y17-AB17 -> 26358.826 | AF17: =+Z17-AC17 -> 25458.186 | AG17: =+AA17-AD17 -> 22501.467
B18: 울산 | G18: =+I18 -> 울산 | I18: 울산 | J18: =+IFERROR(HLOOKUP($B18,'[1]1월'!$D$6:$BN$259,2,),)/1000 -> 5 | K18: =+IFERROR(HLOOKUP($B18,'[2]1월'!$F$6:$CP$99,2,),)/1000 -> 5.383 | L18: =+K18-J18 -> 0.383 | M18: =+IFERROR(HLOOKUP($B18,'[3]1월'!$F$6:$CC$57,2,),)/1000 -> 8.1305 | N18: =+K18-M18 -> -2.7475 | O18: =+IFERROR(HLOOKUP($B18,'[1]1월'!$D$6:$BN$259,3,),)/1000 -> 490.01366 | P18: =+IFERROR(HLOOKUP($B18,'[2]1월'!$F$6:$CP$99,3,),)/1000 -> 560.6076 | Q18: =+P18-O18 -> 70.59394 | R18: =+IFERROR(HLOOKUP($B18,'[3]1월'!$F$6:$CC$57,3,),)/1000 -> 780.75985 | S18: =+P18-R18 -> -220.15225 | T18: =+IFERROR(HLOOKUP($B18,'[1]1월'!$D$6:$BN$259,16,),)/1000 -> -50.284219 | U18: =+IFERROR(HLOOKUP($B18,'[2]1월'!$F$6:$CP$99,16,),)/1000 -> -2.687835 | V18: =+U18-T18 -> 47.596384 | W18: =+IFERROR(HLOOKUP($B18,'[3]1월'!$F$6:$CC$57,16,),)/1000 -> 38.844698 | X18: =+U18-W18 -> -41.532533 | Y18: =+[4]울산!$Q$85 -> 98002.732 | Z18: =+[4]울산!$R$85 -> 104144.08 | AA18: =+[5]울산!$Q$85 -> 96053.017 | AB18: =+[4]울산!$Q$89 -> 79706.615 | AC18: =+[4]울산!$R$89 -> 82948.249 | AD18: =+[5]울산!$Q$89 -> 74906.545 | AE18: =+Y18-AB18 -> 18296.117 | AF18: =+Z18-AC18 -> 21195.834 | AG18: =+AA18-AD18 -> 21146.472
B19: 아산 | G19: =+I19 -> 아산 | I19: 아산 | J19: =+IFERROR(HLOOKUP($B19,'[1]1월'!$D$6:$BN$259,2,),)/1000 -> 15.5 | K19: =+IFERROR(HLOOKUP($B19,'[2]1월'!$F$6:$CP$99,2,),)/1000 -> 22.999 | L19: =+K19-J19 -> 7.499 | M19: =+IFERROR(HLOOKUP($B19,'[3]1월'!$F$6:$CC$57,2,),)/1000 -> 20.146 | N19: =+K19-M19 -> 2.853 | O19: =+IFERROR(HLOOKUP($B19,'[1]1월'!$D$6:$BN$259,3,),)/1000 -> 1565.4994 | P19: =+IFERROR(HLOOKUP($B19,'[2]1월'!$F$6:$CP$99,3,),)/1000 -> 2225.2769 | Q19: =+P19-O19 -> 659.7775 | R19: =+IFERROR(HLOOKUP($B19,'[3]1월'!$F$6:$CC$57,3,),)/1000 -> 1851.2001 | S19: =+P19-R19 -> 374.0768 | T19: =+IFERROR(HLOOKUP($B19,'[1]1월'!$D$6:$BN$259,16,),)/1000 -> 135.48481 | U19: =+IFERROR(HLOOKUP($B19,'[2]1월'!$F$6:$CP$99,16,),)/1000 -> 76.583958 | V19: =+U19-T19 -> -58.900847 | W19: =+IFERROR(HLOOKUP($B19,'[3]1월'!$F$6:$CC$57,16,),)/1000 -> 241.78052 | X19: =+U19-W19 -> -165.19657 | Y19: =+[4]아산!$Q$85 -> 100999.96 | Z19: =+[4]아산!$R$85 -> 96755.376 | AA19: =+[5]아산!$Q$85 -> 91745.374 | AB19: =+[4]아산!$Q$89 -> 77854.206 | AC19: =+[4]아산!$R$89 -> 82780.119 | AD19: =+[5]아산!$Q$89 -> 67815.424 | AE19: =+Y19-AB19 -> 23145.755 | AF19: =+Z19-AC19 -> 13975.257 | AG19: =+AA19-AD19 -> 23929.95
B20: 전주 | G20: =+I20 -> 전주 | I20: 전주 | J20: =+IFERROR(HLOOKUP($B20,'[1]1월'!$D$6:$BN$259,2,),)/1000 -> 10 | K20: =+IFERROR(HLOOKUP($B20,'[2]1월'!$F$6:$CP$99,2,),)/1000 -> 6.567 | L20: =+K20-J20 -> -3.433 | M20: =+IFERROR(HLOOKUP($B20,'[3]1월'!$F$6:$CC$57,2,),)/1000 -> 8.263 | N20: =+K20-M20 -> -1.696 | O20: =+IFERROR(HLOOKUP($B20,'[1]1월'!$D$6:$BN$259,3,),)/1000 -> 1006.5891 | P20: =+IFERROR(HLOOKUP($B20,'[2]1월'!$F$6:$CP$99,3,),)/1000 -> 648.20874 | Q20: =+P20-O20 -> -358.38036 | R20: =+IFERROR(HLOOKUP($B20,'[3]1월'!$F$6:$CC$57,3,),)/1000 -> 717.62855 | S20: =+P20-R20 -> -69.419814 | T20: =+IFERROR(HLOOKUP($B20,'[1]1월'!$D$6:$BN$259,16,),)/1000 -> 109.5688 | U20: =+IFERROR(HLOOKUP($B20,'[2]1월'!$F$6:$CP$99,16,),)/1000 -> 24.564714 | V20: =+U20-T20 -> -85.004085 | W20: =+IFERROR(HLOOKUP($B20,'[3]1월'!$F$6:$CC$57,16,),)/1000 -> 14.677472 | X20: =+U20-W20 -> 9.887242 | Y20: =+[4]전주!$Q$85 -> 100658.91 | Z20: =+[4]전주!$R$85 -> 98706.98 | AA20: =+[5]전주!$Q$85 -> 86834.354 | AB20: =+[4]전주!$Q$89 -> 74727.497 | AC20: =+[4]전주!$R$89 -> 74181.954 | AD20: =+[5]전주!$Q$89 -> 65096.895 | AE20: =+Y20-AB20 -> 25931.412 | AF20: =+Z20-AC20 -> 24525.026 | AG20: =+AA20-AD20 -> 21737.459
B21: 군산 | G21: =+I21 -> 군산 | I21: 군산 | J21: =+IFERROR(HLOOKUP($B21,'[1]1월'!$D$6:$BN$259,2,),)/1000 -> 4 | K21: =+IFERROR(HLOOKUP($B21,'[2]1월'!$F$6:$CP$99,2,),)/1000 -> 7.363 | L21: =+K21-J21 -> 3.363 | M21: =+IFERROR(HLOOKUP($B21,'[3]1월'!$F$6:$CC$57,2,),)/1000 -> 6.52 | N21: =+K21-M21 -> 0.843 | O21: =+IFERROR(HLOOKUP($B21,'[1]1월'!$D$6:$BN$259,3,),)/1000 -> 434.23396 | P21: =+IFERROR(HLOOKUP($B21,'[2]1월'!$F$6:$CP$99,3,),)/1000 -> 752.76158 | Q21: =+P21-O21 -> 318.52762 | R21: =+IFERROR(HLOOKUP($B21,'[3]1월'!$F$6:$CC$57,3,),)/1000 -> 582.53435 | S21: =+P21-R21 -> 170.22723 | T21: =+IFERROR(HLOOKUP($B21,'[1]1월'!$D$6:$BN$259,16,),)/1000 -> 58.09579 | U21: =+IFERROR(HLOOKUP($B21,'[2]1월'!$F$6:$CP$99,16,),)/1000 -> 157.32964 | V21: =+U21-T21 -> 99.233847 | W21: =+IFERROR(HLOOKUP($B21,'[3]1월'!$F$6:$CC$57,16,),)/1000 -> 86.060698 | X21: =+U21-W21 -> 71.268939 | Y21: =+[4]군산!$Q$85 -> 108558.49 | Z21: =+[4]군산!$R$85 -> 102235.72 | AA21: =+[5]군산!$Q$85 -> 89327.018 | AB21: =+[4]군산!$Q$89 -> 70400.342 | AC21: =+[4]군산!$R$89 -> 69601.844 | AD21: =+[5]군산!$Q$89 -> 62541.228 | AE21: =+Y21-AB21 -> 38158.15 | AF21: =+Z21-AC21 -> 32633.872 | AG21: =+AA21-AD21 -> 26785.79
B22: 원주 | G22: =+I22 -> 원주 | I22: 원주 | J22: =+IFERROR(HLOOKUP($B22,'[1]1월'!$D$6:$BN$259,2,),)/1000 -> 4 | K22: =+IFERROR(HLOOKUP($B22,'[2]1월'!$F$6:$CP$99,2,),)/1000 -> 3.533 | L22: =+K22-J22 -> -0.467 | M22: =+IFERROR(HLOOKUP($B22,'[3]1월'!$F$6:$CC$57,2,),)/1000 -> 1.813 | N22: =+K22-M22 -> 1.72 | O22: =+IFERROR(HLOOKUP($B22,'[1]1월'!$D$6:$BN$259,3,),)/1000 -> 431.6 | P22: =+IFERROR(HLOOKUP($B22,'[2]1월'!$F$6:$CP$99,3,),)/1000 -> 412.2751 | Q22: =+P22-O22 -> -19.3249 | R22: =+IFERROR(HLOOKUP($B22,'[3]1월'!$F$6:$CC$57,3,),)/1000 -> 154.2127 | S22: =+P22-R22 -> 258.0624 | T22: =+IFERROR(HLOOKUP($B22,'[1]1월'!$D$6:$BN$259,16,),)/1000 -> 34.357 | U22: =+IFERROR(HLOOKUP($B22,'[2]1월'!$F$6:$CP$99,16,),)/1000 -> 53.424534 | V22: =+U22-T22 -> 19.067534 | W22: =+IFERROR(HLOOKUP($B22,'[3]1월'!$F$6:$CC$57,16,),)/1000 -> -48.466116 | X22: =+U22-W22 -> 101.89065 | Y22: =+[4]원주!$Q$85 -> 107900 | Z22: =+[4]원주!$R$85 -> 116692.64 | AA22: =+[5]원주!$Q$85 -> 85059.404 | AB22: =+[4]원주!$Q$89 -> 75438.971 | AC22: =+[4]원주!$R$89 -> 76321.153 | AD22: =+[5]원주!$Q$89 -> 65788.766 | AE22: =+Y22-AB22 -> 32461.029 | AF22: =+Z22-AC22 -> 40371.487 | AG22: =+AA22-AD22 -> 19270.638
B23: 제주 | G23: =+I23 -> 제주 | I23: 제주 | J23: =+IFERROR(HLOOKUP($B23,'[1]1월'!$D$6:$BN$259,2,),)/1000 -> 4 | K23: =+IFERROR(HLOOKUP($B23,'[2]1월'!$F$6:$CP$99,2,),)/1000 -> 3.2615 | L23: =+K23-J23 -> -0.7385 | M23: =+IFERROR(HLOOKUP($B23,'[3]1월'!$F$6:$CC$57,2,),)/1000 -> 6.328 | N23: =+K23-M23 -> -3.0665 | O23: =+IFERROR(HLOOKUP($B23,'[1]1월'!$D$6:$BN$259,3,),)/1000 -> 506.8 | P23: =+IFERROR(HLOOKUP($B23,'[2]1월'!$F$6:$CP$99,3,),)/1000 -> 419.7493 | Q23: =+P23-O23 -> -87.050701 | R23: =+IFERROR(HLOOKUP($B23,'[3]1월'!$F$6:$CC$57,3,),)/1000 -> 738.13421 | S23: =+P23-R23 -> -318.38492 | T23: =+IFERROR(HLOOKUP($B23,'[1]1월'!$D$6:$BN$259,16,),)/1000 -> 42.978795 | U23: =+IFERROR(HLOOKUP($B23,'[2]1월'!$F$6:$CP$99,16,),)/1000 -> 35.375497 | V23: =+U23-T23 -> -7.6032979 | W23: =+IFERROR(HLOOKUP($B23,'[3]1월'!$F$6:$CC$57,16,),)/1000 -> 175.67346 | X23: =+U23-W23 -> -140.29796 | Y23: =+[4]제주!$Q$85 -> 126700 | Z23: =+[4]제주!$R$85 -> 128698.24 | AA23: =+[5]제주!$Q$85 -> 116650.12 | AB23: =+[4]제주!$Q$89 -> 89935.469 | AC23: =+[4]제주!$R$89 -> 90773.836 | AD23: =+[5]제주!$Q$89 -> 75659.131 | AE23: =+Y23-AB23 -> 36764.531 | AF23: =+Z23-AC23 -> 37924.401 | AG23: =+AA23-AD23 -> 40990.992
G24: =+I24 -> 수도권 | I24: 수도권 | J24: =SUM(J7:J10) -> 93 | K24: =SUM(K7:K10) -> 102.264 | L24: =+K24-J24 -> 9.264 | M24: =SUM(M7:M10) -> 93.376 | N24: =+K24-M24 -> 8.888 | O24: =SUM(O7:O10) -> 8982.3396 | P24: =SUM(P7:P10) -> 9926.1808 | Q24: =+P24-O24 -> 943.84119 | R24: =SUM(R7:R10) -> 8282.4478 | S24: =+P24-R24 -> 1643.733 | T24: =SUM(T7:T10) -> 581.00836 | U24: =SUM(U7:U10) -> 486.07577 | V24: =+U24-T24 -> -94.932592 | W24: =SUM(W7:W10) -> 407.54562 | X24: =+U24-W24 -> 78.530142 | Y24: =+[4]수도권!$Q$85 -> 96584.296 | Z24: =+[4]수도권!$R$85 -> 97064.272 | AA24: =+[5]수도권!$Q$85 -> 88709.415 | AB24: =+[4]수도권!$Q$89 -> 79517.081 | AC24: =+[4]수도권!$R$89 -> 82325.824 | AD24: =+[5]수도권!$Q$89 -> 73361.249 | AE24: =+Y24-AB24 -> 17067.215 | AF24: =+Z24-AC24 -> 14738.448 | AG24: =+AA24-AD24 -> 15348.166
G25: =+I25 -> 영남권 | I25: 영남권 | J25: =SUM(J11:J18) -> 110.5 | K25: =SUM(K11:K18) -> 132.898 | L25: =+K25-J25 -> 22.398 | M25: =SUM(M11:M18) -> 132.135 | N25: =+K25-M25 -> 0.763 | O25: =SUM(O11:O18) -> 11247.532 | P25: =SUM(P11:P18) -> 13491.194 | Q25: =+P25-O25 -> 2243.6616 | R25: =SUM(R11:R18) -> 12461.698 | S25: =+P25-R25 -> 1029.4956 | T25: =SUM(T11:T18) -> 1299.246 | U25: =SUM(U11:U18) -> 1491.2352 | V25: =+U25-T25 -> 191.98916 | W25: =SUM(W11:W18) -> 1664.1377 | X25: =+U25-W25 -> -172.90249 | Y25: =+[4]영남권!$Q$85 -> 101787.62 | Z25: =+[4]영남권!$R$85 -> 101515.92 | AA25: =+[5]영남권!$Q$85 -> 94314.373 | AB25: =+[4]영남권!$Q$89 -> 75914.682 | AC25: =+[4]영남권!$R$89 -> 79377.391 | AD25: =+[5]영남권!$Q$89 -> 70465.975 | AE25: =+Y25-AB25 -> 25872.937 | AF25: =+Z25-AC25 -> 22138.533 | AG25: =+AA25-AD25 -> 23848.398
G26: =+I26 -> 중부권 | I26: 중부권 | J26: =SUM(J19:J23) -> 37.5 | K26: =SUM(K19:K23) -> 43.7235 | L26: =+K26-J26 -> 6.2235 | M26: =SUM(M19:M23) -> 43.07 | N26: =+K26-M26 -> 0.6535 | O26: =SUM(O19:O23) -> 3944.7225 | P26: =SUM(P19:P23) -> 4458.2716 | Q26: =+P26-O26 -> 513.54915 | R26: =SUM(R19:R23) -> 4043.7099 | S26: =+P26-R26 -> 414.5617 | T26: =SUM(T19:T23) -> 380.48519 | U26: =SUM(U19:U23) -> 347.27834 | V26: =+U26-T26 -> -33.206849 | W26: =SUM(W19:W23) -> 469.72604 | X26: =+U26-W26 -> -122.4477 | Y26: =+[4]중부권!$Q$85 -> 105192.6 | Z26: =+[4]중부권!$R$85 -> 101965.11 | AA26: =+[5]중부권!$Q$85 -> 94006.133 | AB26: =+[4]중부권!$Q$89 -> 77256.381 | AC26: =+[4]중부권!$R$89 -> 79343.893 | AD26: =+[5]중부권!$Q$89 -> 67597.806 | AE26: =+Y26-AB26 -> 27936.218 | AF26: =+Z26-AC26 -> 22621.219 | AG26: =+AA26-AD26 -> 26408.326
G27: =+K27/J27 -> 1.1572012 | H27: 레미콘 계 | J27: =SUM(J24:J26) -> 241 | K27: =SUM(K24:K26) -> 278.8855 | L27: =+K27-J27 -> 37.8855 | M27: =SUM(M24:M26) -> 268.581 | N27: =+K27-M27 -> 10.3045 | O27: =SUM(O24:O26) -> 24174.594 | P27: =SUM(P24:P26) -> 27875.646 | Q27: =+P27-O27 -> 3701.052 | R27: =SUM(R24:R26) -> 24787.856 | S27: =+P27-R27 -> 3087.7903 | T27: =SUM(T24:T26) -> 2260.7396 | U27: =SUM(U24:U26) -> 2324.5893 | V27: =+U27-T27 -> 63.849721 | W27: =SUM(W24:W26) -> 2541.4093 | X27: =+U27-W27 -> -216.82004 | Y27: =+[4]합계!$Q$85 -> 100309.52 | Z27: =+[4]합계!$R$85 -> 99953.913 | AA27: =+[5]합계!$Q$85 -> 92313.001 | AB27: =+[4]합계!$Q$89 -> 77513.59 | AC27: =+[4]합계!$R$89 -> 80453.28 | AD27: =+[5]합계!$Q$89 -> 71029.87 | AE27: =+Y27-AB27 -> 22795.928 | AF27: =+Z27-AC27 -> 19500.633 | AG27: =+AA27-AD27 -> 21283.131
B28: 건자재 | E28: 건자재영업 | G28: 건자재 | H28: 건자재 | J28: =+IFERROR(HLOOKUP($B28,'[1]1월'!$D$6:$BN$259,2,),) -> 6900 | K28: =+IFERROR(HLOOKUP($E28,'[2]1월'!$F$6:$CP$99,2,),) -> 6425.093 | L28: =+K28-J28 -> -474.907 | M28: =+IFERROR(HLOOKUP($E28,'[3]1월'!$F$6:$CC$57,2,),) -> 6946.787 | N28: =+K28-M28 -> -521.694 | O28: =+IFERROR(HLOOKUP($B28,'[1]1월'!$D$6:$BN$259,3,),)/1000 -> 8447.9432 | P28: =+IFERROR(HLOOKUP($E28,'[2]1월'!$F$6:$CP$99,3,),)/1000 -> 7407.9572 | Q28: =+P28-O28 -> -1039.986 | R28: =+IFERROR(HLOOKUP($E28,'[3]1월'!$F$6:$CC$57,3,),)/1000 -> 8813.6343 | S28: =+P28-R28 -> -1405.6771 | T28: =+IFERROR(HLOOKUP($B28,'[1]1월'!$D$6:$BN$259,16,),)/1000 -> 94.750483 | U28: =+IFERROR(HLOOKUP($E28,'[2]1월'!$F$6:$CP$99,16,),)/1000 -> 75.267211 | V28: =+U28-T28 -> -19.483272 | W28: =+IFERROR(HLOOKUP($E28,'[3]1월'!$F$6:$CC$57,16,),)/1000 -> 74.398934 | X28: =+U28-W28 -> 0.868277 | Y28: ■ 비고
B29: 부산모래장 | F29: 부산골재 | G29: =+I29 -> 부산모래장 | H29: 골재 | I29: 부산모래장 | J29: =+IFERROR(HLOOKUP($B29,'[1]1월'!$D$6:$BN$259,2,),)/1000 -> 24.586871 | K29: =+IFERROR(HLOOKUP($F29,'[2]1월'!$F$6:$CP$99,2,),)/1000 -> 27.205 | L29: =+K29-J29 -> 2.6181293 | M29: =+IFERROR(HLOOKUP($F29,'[3]1월'!$F$6:$CC$57,2,),)/1000 -> 32.145 | N29: =+K29-M29 -> -4.94 | O29: =+IFERROR(HLOOKUP($B29,'[1]1월'!$D$6:$BN$259,3,),)/1000 -> 697.84314 | P29: =+IFERROR(HLOOKUP($F29,'[2]1월'!$F$6:$CP$99,3,),)/1000 -> 780.046 | Q29: =+P29-O29 -> 82.202857 | R29: =+IFERROR(HLOOKUP($F29,'[3]1월'!$F$6:$CC$57,3,),)/1000 -> 905.482 | S29: =+P29-R29 -> -125.436 | T29: =+IFERROR(HLOOKUP($B29,'[1]1월'!$D$6:$BN$259,21,),)/1000 -> 16.821421 | U29: =+IFERROR(HLOOKUP($F29,'[2]1월'!$F$6:$CP$99,21,),)/1000 -> 57.434467 | V29: =+U29-T29 -> 40.613047 | W29: =+IFERROR(HLOOKUP($F29,'[3]1월'!$F$6:$CC$57,16,),)/1000 -> 13.998209 | X29: =+U29-W29 -> 43.436258
B30: 서부산크라샤 | F30: 서부산골재 | G30: =+I30 -> 서부산CR | I30: 서부산CR | J30: =+IFERROR(HLOOKUP($B30,'[1]1월'!$D$6:$BN$259,2,),)/1000 -> 12.3718 | K30: =+IFERROR(HLOOKUP($F30,'[2]1월'!$F$6:$CP$99,2,),)/1000 -> 27.872 | L30: =+K30-J30 -> 15.5002 | M30: =+IFERROR(HLOOKUP($F30,'[3]1월'!$F$6:$CC$57,2,),)/1000 -> 33.74 | N30: =+K30-M30 -> -5.868 | O30: =+IFERROR(HLOOKUP($B30,'[1]1월'!$D$6:$BN$259,3,),)/1000 -> 192.913 | P30: =+IFERROR(HLOOKUP($F30,'[2]1월'!$F$6:$CP$99,3,),)/1000 -> 373.312 | Q30: =+P30-O30 -> 180.399 | R30: =+IFERROR(HLOOKUP($F30,'[3]1월'!$F$6:$CC$57,3,),)/1000 -> 393.346 | S30: =+P30-R30 -> -20.034 | T30: =+IFERROR(HLOOKUP($B30,'[1]1월'!$D$6:$BN$259,21,),)/1000 -> 65.72153 | U30: =+IFERROR(HLOOKUP($F30,'[2]1월'!$F$6:$CP$99,21,),)/1000 -> 54.476102 | V30: =+U30-T30 -> -11.245429 | W30: =+IFERROR(HLOOKUP($F30,'[3]1월'!$F$6:$CC$57,16,),)/1000 -> 13.770077 | X30: =+U30-W30 -> 40.706025
B31: 부산크라샤 | F31: 부산크라샤 | G31: =+I31 -> 부산CR | I31: 부산CR | J31: =+IFERROR(HLOOKUP($B31,'[1]1월'!$D$6:$BN$259,2,),)/1000 -> 39.6703 | K31: =+IFERROR(HLOOKUP($F31,'[2]1월'!$F$6:$CP$99,2,),)/1000 -> 29.44 | L31: =+K31-J31 -> -10.2303 | M31: =+IFERROR(HLOOKUP($F31,'[3]1월'!$F$6:$CC$57,2,),)/1000 -> 0 | N31: =+K31-M31 -> 29.44 | O31: =+IFERROR(HLOOKUP($B31,'[1]1월'!$D$6:$BN$259,3,),)/1000 -> 709.40685 | P31: =+IFERROR(HLOOKUP($F31,'[2]1월'!$F$6:$CP$99,3,),)/1000 -> 566.162 | Q31: =+P31-O31 -> -143.24485 | R31: =+IFERROR(HLOOKUP($F31,'[3]1월'!$F$6:$CC$57,3,),)/1000 -> 0 | S31: =+P31-R31 -> 566.162 | T31: =+IFERROR(HLOOKUP($B31,'[1]1월'!$D$6:$BN$259,21,),)/1000 -> -55.517927 | U31: =+IFERROR(HLOOKUP($F31,'[2]1월'!$F$6:$CP$99,21,),)/1000 -> 72.163163 | V31: =+U31-T31 -> 127.68109 | W31: =+IFERROR(HLOOKUP($F31,'[3]1월'!$F$6:$CC$57,16,),)/1000 -> -9.33373 | X31: =+U31-W31 -> 81.496893
H32: 골재 계 | J32: =SUM(J29:J31) -> 76.628971 | K32: =SUM(K29:K31) -> 84.517 | L32: =+K32-J32 -> 7.8880294 | M32: =SUM(M29:M31) -> 65.885 | N32: =+K32-M32 -> 18.632 | O32: =SUM(O29:O31) -> 1600.163 | P32: =SUM(P29:P31) -> 1719.52 | Q32: =+P32-O32 -> 119.357 | R32: =SUM(R29:R31) -> 1298.828 | S32: =+P32-R32 -> 420.692 | T32: =SUM(T29:T31) -> 27.025024 | U32: =SUM(U29:U31) -> 184.07373 | V32: =+U32-T32 -> 157.04871 | W32: =SUM(W29:W31) -> 18.434556 | X32: =+U32-W32 -> 165.63918
B33: 포항임대 | C33: 속초임대 | D33: 강릉임대 | E33: 레미콘임대 계 | G33: =+I33 -> 레미콘임대 | H33: 기타 | I33: 레미콘임대 | L33: =+K33-J33 -> 0 | N33: =+K33-M33 -> 0 | O33: =(IFERROR(HLOOKUP($B33,'[1]1월'!$D$6:$BN$259,3,),)++IFERROR(HLOOKUP($C33,'[1]1월'!$D$6:$BN$259,3,),)+IFERROR(HLOOKUP($D33,'[1]1월'!$D$6:$BN$259,3,),))/1000 -> 90.84 | P33: =+IFERROR(HLOOKUP($E33,'[2]1월'!$F$6:$CP$99,3,),)/1000 -> 90.84 | Q33: =+P33-O33 -> 0 | R33: =+IFERROR(HLOOKUP($E33,'[3]1월'!$F$6:$CC$57,3,),)/1000 -> 78.34 | S33: =+P33-R33 -> 12.5 | T33: =(IFERROR(HLOOKUP($B33,'[1]1월'!$D$6:$BN$259,21,),)++IFERROR(HLOOKUP($C33,'[1]1월'!$D$6:$BN$259,21,),)+IFERROR(HLOOKUP($D33,'[1]1월'!$D$6:$BN$259,21,),))/1000 -> 72.165959 | U33: =+IFERROR(HLOOKUP($E33,'[2]1월'!$F$6:$CP$99,16,),)/1000 -> 71.79658 | V33: =+U33-T33 -> -0.369379 | W33: =+IFERROR(HLOOKUP($E33,'[3]1월'!$F$6:$CC$57,16,),)/1000 -> 59.685201 | X33: =+U33-W33 -> 12.111379
B34: 부동산임대 | C34: 주유소임대 | E34: 임대 계 | G34: =+I34 -> 임대 | I34: 임대 | L34: =+K34-J34 -> 0 | M34: 0 | N34: =+K34-M34 -> 0 | O34: =(+IFERROR(HLOOKUP($B34,'[1]1월'!$D$6:$BN$259,3,),)+IFERROR(HLOOKUP($C34,'[1]1월'!$D$6:$BN$259,3,),))/1000 -> 72.2975 | P34: =+IFERROR(HLOOKUP($E34,'[2]1월'!$F$6:$CP$99,3,),)/1000 -> 71.933111 | Q34: =+P34-O34 -> -0.36438933 | R34: =+IFERROR(HLOOKUP($E34,'[3]1월'!$F$6:$CC$57,3,),)/1000 -> 94.115918 | S34: =+P34-R34 -> -22.182807 | T34: =(+IFERROR(HLOOKUP($B34,'[1]1월'!$D$6:$BN$259,21,),)+IFERROR(HLOOKUP($C34,'[1]1월'!$D$6:$BN$259,21,),))/1000 -> 62.030473 | U34: =+IFERROR(HLOOKUP($E34,'[2]1월'!$F$6:$CP$99,16,),)/1000 -> 61.824294 | V34: =+U34-T34 -> -0.20617933 | W34: =+IFERROR(HLOOKUP($E34,'[3]1월'!$F$6:$CC$57,16,),)/1000 -> 39.911628 | X34: =+U34-W34 -> 21.912666
B35: 공 통 비 | G35: =+I35 -> 공통비 | I35: 공통비 | L35: =+K35-J35 -> 0 | N35: =+K35-M35 -> 0 | Q35: =+P35-O35 -> 0 | S35: =+P35-R35 -> 0 | T35: =-'[1]1월'!$Z$22/1000 -> -1461.295 | U35: =+-'[2]1월'!$Z$22/1000 -> -1549.2991 | V35: =+U35-T35 -> -88.004163 | W35: =+-'[3]1월'!$Z$22/1000 -> -1236.2774 | X35: =+U35-W35 -> -313.02176
G36: =+I36 -> OPC 소급분 | I36: OPC 소급분 | N36: =+K36-M36 -> 0 | Q36: =+P36-O36 -> 0 | S36: =+P36-R36 -> 0 | T36: =+'[1]1월'!$AS$26/1000 -> 0 | U36: =-'[2]1월'!$BD$26/1000 -> 0 | V36: =+U36-T36 -> 0 | W36: =-'[3]1월'!$BD$26/1000 -> 0 | X36: =+U36-W36 -> 0
G37: =+I37 -> 대손 | I37: 대손 | N37: =+K37-M37 -> 0 | Q37: =+P37-O37 -> 0 | S37: =+P37-R37 -> 0 | U37: =-'[2]1월'!$BE$26/1000 -> 0 | V37: =+U37-T37 -> 0 | W37: =-'[3]1월'!$BE$26/1000 -> 0 | X37: =+U37-W37 -> 0
G38: =+I38 -> 미운영 공장 | I38: 미운영 공장 | M38: =SUM(M54:M57) -> 0 | N38: =+K38-M38 -> 0 | Q38: =+P38-O38 -> 0 | S38: =+P38-R38 -> 0 | T38: =SUM('[1]1월'!$AM$26:$AQ$26)/1000 -> -35.767484 | U38: =+'[2]1월'!$BF$26/1000 -> -36.069287 | V38: =+U38-T38 -> -0.30180256 | W38: =+'[3]1월'!$BF$26/1000 -> -8.200843 | X38: =+U38-W38 -> -27.868444
B39: 기타 계 | G39: =+I39 -> 기타 | I39: 기타 | L39: =+K39-J39 -> 0 | N39: =+K39-M39 -> 0 | O39: =IFERROR(HLOOKUP($B39,'[1]1월'!$D$6:$BN$259,3,),)/1000 -> 1.77 | P39: =+('[2]1월'!$F$8-SUM('[2]1월'!$Z$8,'[2]1월'!$AH$8,'[2]1월'!$AN$8,'[2]1월'!$AO$8,'[2]1월'!$BA$8,'[2]1월'!$BD$8,'[2]1월'!$BE$8,'[2]1월'!$BF$8))/1000 -> 1.7024 | Q39: =+P39-O39 -> -0.0676 | R39: =+('[3]1월'!$F$8-SUM('[3]1월'!$Z$8,'[3]1월'!$AH$8,'[3]1월'!$AN$8,'[3]1월'!$AO$8,'[3]1월'!$BA$8,'[3]1월'!$BD$8,'[3]1월'!$BE$8,'[3]1월'!$BF$8))/1000 -> 1.6661 | S39: =+P39-R39 -> 0.0363 | T39: =+('[1]1월'!$E$26-'[1]1월'!$Z$26-'[1]1월'!$AA$26-'[1]1월'!$AE$26-'[1]1월'!$AL$26-'[1]1월'!$AM$26-'[1]1월'!$AN$26-'[1]1월'!$AO$26-'[1]1월'!$AP$26-'[1]1월'!$AQ$26-'[1]1월'!$AS$26)/1000 -> -15.985408 | U39: =+('[2]1월'!$F$26-SUM('[2]1월'!$Z$26,'[2]1월'!$AH$26,'[2]1월'!$AN$26,'[2]1월'!$AO$26,'[2]1월'!$BA$26,'[2]1월'!$BD$26,'[2]1월'!$BE$26,'[2]1월'!$BF$26))/1000 -> -17.114136 | V39: =+U39-T39 -> -1.128728 | W39: =+('[3]1월'!$F$26-SUM('[3]1월'!$Z$26,'[3]1월'!$AH$26,'[3]1월'!$AN$26,'[3]1월'!$AO$26,'[3]1월'!$BA$26,'[3]1월'!$BD$26,'[3]1월'!$BE$26,'[3]1월'!$BF$26))/1000 -> -17.003696 | X39: =+U39-W39 -> -0.11044
N40: =+K40-M40 -> 0 | Q40: =+P40-O40 -> 0 | S40: =+P40-R40 -> 0 | V40: =+U40-T40 -> 0
H41: 기타 계 | J41: =SUM(J33:J40) -> 0 | K41: =SUM(K33:K40) -> 0 | L41: =+K41-J41 -> 0 | M41: =SUM(M33:M40) -> 0 | N41: =+K41-M41 -> 0 | O41: =SUM(O33:O40) -> 164.9075 | P41: =SUM(P33:P40) -> 164.47551 | Q41: =+P41-O41 -> -0.43198933 | R41: =SUM(R33:R40) -> 174.12202 | S41: =+P41-R41 -> -9.646507 | T41: =SUM(T33:T40) -> -1378.8514 | U41: =SUM(U33:U40) -> -1468.8617 | V41: =+U41-T41 -> -90.010251 | W41: =SUM(W33:W40) -> -1161.8851 | X41: =+U41-W41 -> -306.97659
G43: =+P43/O43 -> 1.0808428 | H43: 합계 | O43: =+O27+O32+O28+O41 -> 34387.608 | P43: =+P27+P32+P28+P41 -> 37167.599 | Q43: =+P43-O43 -> 2779.991 | R43: =+R27+R32+R28+R41 -> 35074.44 | S43: =+P43-R43 -> 2093.1587 | T43: =+T27+T32+T28+T41 -> 1003.6636 | U43: =+U27+U32+U28+U41 -> 1115.0685 | V43: =+U43-T43 -> 111.40491 | W43: =+W27+W32+W28+W41 -> 1472.3577 | X43: =+U43-W43 -> -357.28919
...

Sheet 사업장별(누계)
H3: □ 사업장별 손익실적(2024-01)
AG4: [단위 : 천㎥, 톤, 백만원]
H5: 구분 | J5: 물량 | O5: 매출 | T5: 영업이익(공통비 배부전) | Y5: 판매단가 | AB5: 변동비 | AE5: 공헌이익
J6: 계획 | K6: 실적 | L6: 차이 | M6: 전년 | N6: 차이 | O6: 계획 | P6: 실적 | Q6: 차이 | R6: 전년 | S6: 차이 | T6: 계획 | U6: 실적 | V6: 차이 | W6: 전년 | X6: 차이 | Y6: 계획 | Z6: 실적 | AA6: 전년 | AB6: 계획 | AC6: 실적 | AD6: 전년 | AE6: 계획 | AF6: 실적 | AG6: 전년
B7: 안양 | H7: 레미콘 | I7: 안양 | J7: =+IFERROR(HLOOKUP($B7,'[1]1월'!$D$6:$BN$259,2,),)/1000 -> 37 | K7: =+IFERROR(HLOOKUP($B7,'[2]1월'!$F$6:$CP$99,2,),)/1000 -> 45.761 | L7: =+K7-J7 -> 8.761 | M7: =+IFERROR(HLOOKUP($B7,'[3]1월'!$F$6:$CC$57,2,),)/1000 -> 39.266 | N7: =+K7-M7 -> 6.495 | O7: =+IFERROR(HLOOKUP($B7,'[1]1월'!$D$6:$BN$259,3,),)/1000 -> 3581.7519 | P7: =+IFERROR(HLOOKUP($B7,'[2]1월'!$F$6:$CP$99,3,),)/1000 -> 4371.1989 | Q7: =+P7-O7 -> 789.44705 | R7: =+IFERROR(HLOOKUP($B7,'[3]1월'!$F$6:$CC$57,3,),)/1000 -> 3529.8298 | S7: =+P7-R7 -> 841.3691 | T7: =+IFERROR(HLOOKUP($B7,'[1]1월'!$D$6:$BN$259,16,),)/1000 -> 326.89293 | U7: =+IFERROR(HLOOKUP($B7,'[2]1월'!$F$6:$CP$99,16,),)/1000 -> 337.22639 | V7: =+U7-T7 -> 10.333459 | W7: =+IFERROR(HLOOKUP($B7,'[3]1월'!$F$6:$CC$57,16,),)/1000 -> 393.29113 | X7: =+U7-W7 -> -56.06474 | Y7: =+[4]안양!$Q$85 -> 96804.104 | Z7: =+[4]안양!$R$85 -> 95522.364 | AA7: =+[5]안양!$Q$85 -> 89895.324 | AB7: =+[4]안양!$Q$89 -> 79892.321 | AC7: =+[4]안양!$R$89 -> 81107.602 | AD7: =+[5]안양!$Q$89 -> 72443.519 | AE7: =+Y7-AB7 -> 16911.783 | AF7: =+Z7-AC7 -> 14414.762 | AG7: =+AA7-AD7 -> 17451.805
B8: 인천 | H8: 직영 | I8: 인천 | J8: =+IFERROR(HLOOKUP($B8,'[1]1월'!$D$6:$BN$259,2,),)/1000 -> 28 | K8: =+IFERROR(HLOOKUP($B8,'[2]1월'!$F$6:$CP$99,2,),)/1000 -> 28.34 | L8: =+K8-J8 -> 0.34 | M8: =+IFERROR(HLOOKUP($B8,'[3]1월'!$F$6:$CC$57,2,),)/1000 -> 24.957 | N8: =+K8-M8 -> 3.383 | O8: =+IFERROR(HLOOKUP($B8,'[1]1월'!$D$6:$BN$259,3,),)/1000 -> 2739.7515 | P8: =+IFERROR(HLOOKUP($B8,'[2]1월'!$F$6:$CP$99,3,),)/1000 -> 2766.8113 | Q8: =+P8-O8 -> 27.059798 | R8: =+IFERROR(HLOOKUP($B8,'[3]1월'!$F$6:$CC$57,3,),)/1000 -> 2220.1667 | S8: =+P8-R8 -> 546.64461 | T8: =+IFERROR(HLOOKUP($B8,'[1]1월'!$D$6:$BN$259,16,),)/1000 -> 125.23471 | U8: =+IFERROR(HLOOKUP($B8,'[2]1월'!$F$6:$CP$99,16,),)/1000 -> 102.92462 | V8: =+U8-T8 -> -22.31009 | W8: =+IFERROR(HLOOKUP($B8,'[3]1월'!$F$6:$CC$57,16,),)/1000 -> 29.293796 | X8: =+U8-W8 -> 73.630826 | Y8: =+[4]인천!$Q$85 -> 97848.269 | Z8: =+[4]인천!$R$85 -> 97629.193 | AA8: =+[5]인천!$Q$85 -> 88932.118 | AB8: =+[4]인천!$Q$89 -> 81867.136 | AC8: =+[4]인천!$R$89 -> 84063.445 | AD8: =+[5]인천!$Q$89 -> 74896.804 | AE8: =+Y8-AB8 -> 15981.133 | AF8: =+Z8-AC8 -> 13565.748 | AG8: =+AA8-AD8 -> 14035.314
B9: 파주 | I9: 파주 | J9: =+IFERROR(HLOOKUP($B9,'[1]1월'!$D$6:$BN$259,2,),)/1000 -> 20 | K9: =+IFERROR(HLOOKUP($B9,'[2]1월'!$F$6:$CP$99,2,),)/1000 -> 22.882 | L9: =+K9-J9 -> 2.882 | M9: =+IFERROR(HLOOKUP($B9,'[3]1월'!$F$6:$CC$57,2,),)/1000 -> 20.905 | N9: =+K9-M9 -> 1.977 | O9: =+IFERROR(HLOOKUP($B9,'[1]1월'!$D$6:$BN$259,3,),)/1000 -> 1918.6197 | P9: =+IFERROR(HLOOKUP($B9,'[2]1월'!$F$6:$CP$99,3,),)/1000 -> 2301.3269 | Q9: =+P9-O9 -> 382.70724 | R9: =+IFERROR(HLOOKUP($B9,'[3]1월'!$F$6:$CC$57,3,),)/1000 -> 1836.6317 | S9: =+P9-R9 -> 464.69519 | T9: =+IFERROR(HLOOKUP($B9,'[1]1월'!$D$6:$BN$259,16,),)/1000 -> 141.9663 | U9: =+IFERROR(HLOOKUP($B9,'[2]1월'!$F$6:$CP$99,16,),)/1000 -> 116.27631 | V9: =+U9-T9 -> -25.689992 | W9: =+IFERROR(HLOOKUP($B9,'[3]1월'!$F$6:$CC$57,16,),)/1000 -> 0.643766 | X9: =+U9-W9 -> 115.63255 | Y9: =+[4]파주!$Q$85 -> 95930.984 | Z9: =+[4]파주!$R$85 -> 100573.68 | AA9: =+[5]파주!$Q$85 -> 87902.852 | AB9: =+[4]파주!$Q$89 -> 77860.175 | AC9: =+[4]파주!$R$89 -> 84086.773 | AD9: =+[5]파주!$Q$89 -> 76114 | AE9: =+Y9-AB9 -> 18070.809 | AF9: =+Z9-AC9 -> 16486.906 | AG9: =+AA9-AD9 -> 11788.851
B10: 김포 | I10: 김포 | J10: =+IFERROR(HLOOKUP($B10,'[1]1월'!$D$6:$BN$259,2,),)/1000 -> 8 | K10: =+IFERROR(HLOOKUP($B10,'[2]1월'!$F$6:$CP$99,2,),)/1000 -> 5.281 | L10: =+K10-J10 -> -2.719 | M10: =+IFERROR(HLOOKUP($B10,'[3]1월'!$F$6:$CC$57,2,),)/1000 -> 8.248 | N10: =+K10-M10 -> -2.967 | O10: =+IFERROR(HLOOKUP($B10,'[1]1월'!$D$6:$BN$259,3,),)/1000 -> 742.2165 | P10: =+IFERROR(HLOOKUP($B10,'[2]1월'!$F$6:$CP$99,3,),)/1000 -> 486.8436 | Q10: =+P10-O10 -> -255.3729 | R10: =+IFERROR(HLOOKUP($B10,'[3]1월'!$F$6:$CC$57,3,),)/1000 -> 695.81949 | S10: =+P10-R10 -> -208.97589 | T10: =+IFERROR(HLOOKUP($B10,'[1]1월'!$D$6:$BN$259,16,),)/1000 -> -13.085594 | U10: =+IFERROR(HLOOKUP($B10,'[2]1월'!$F$6:$CP$99,16,),)/1000 -> -70.351562 | V10: =+U10-T10 -> -57.265968 | W10: =+IFERROR(HLOOKUP($B10,'[3]1월'!$F$6:$CC$57,16,),)/1000 -> -15.683073 | X10: =+U10-W10 -> -54.668489 | Y10: =+[4]김포!$Q$85 -> 92777.062 | Z10: =+[4]김포!$R$85 -> 92187.767 | AA10: =+[5]김포!$Q$85 -> 84362.208 | AB10: =+[4]김포!$Q$89 -> 73698.667 | AC10: =+[4]김포!$R$89 -> 75942.492 | AD10: =+[5]김포!$Q$89 -> 66383.614 | AE10: =+Y10-AB10 -> 19078.396 | AF10: =+Z10-AC10 -> 16245.275 | AG10: =+AA10-AD10 -> 17978.594
B11: 부산 | I11: 부산 | J11: =+IFERROR(HLOOKUP($B11,'[1]1월'!$D$6:$BN$259,2,),)/1000 -> 18 | K11: =+IFERROR(HLOOKUP($B11,'[2]1월'!$F$6:$CP$99,2,),)/1000 -> 23.815 | L11: =+K11-J11 -> 5.815 | M11: =+IFERROR(HLOOKUP($B11,'[3]1월'!$F$6:$CC$57,2,),)/1000 -> 24.118 | N11: =+K11-M11 -> -0.303 | O11: =+IFERROR(HLOOKUP($B11,'[1]1월'!$D$6:$BN$259,3,),)/1000 -> 1936.7942 | P11: =+IFERROR(HLOOKUP($B11,'[2]1월'!$F$6:$CP$99,3,),)/1000 -> 2518.1609 | Q11: =+P11-O11 -> 581.36664 | R11: =+IFERROR(HLOOKUP($B11,'[3]1월'!$F$6:$CC$57,3,),)/1000 -> 2452.0565 | S11: =+P11-R11 -> 66.104366 | T11: =+IFERROR(HLOOKUP($B11,'[1]1월'!$D$6:$BN$259,16,),)/1000 -> 245.36511 | U11: =+IFERROR(HLOOKUP($B11,'[2]1월'!$F$6:$CP$99,16,),)/1000 -> 298.81115 | V11: =+U11-T11 -> 53.44604 | W11: =+IFERROR(HLOOKUP($B11,'[3]1월'!$F$6:$CC$57,16,),)/1000 -> 433.03577 | X11: =+U11-W11 -> -134.22462 | Y11: =+[4]부산!$Q$85 -> 107599.68 | Z11: =+[4]부산!$R$85 -> 105738.44 | AA11: =+[5]부산!$Q$85 -> 101668.21 | AB11: =+[4]부산!$Q$89 -> 78358.379 | AC11: =+[4]부산!$R$89 -> 82993.734 | AD11: =+[5]부산!$Q$89 -> 73283.728 | AE11: =+Y11-AB11 -> 29241.301 | AF11: =+Z11-AC11 -> 22744.702 | AG11: =+AA11-AD11 -> 28384.483
B12: 서부산 | I12: 서부산 | J12: =+IFERROR(HLOOKUP($B12,'[1]1월'!$D$6:$BN$259,2,),)/1000 -> 21 | K12: =+IFERROR(HLOOKUP($B12,'[2]1월'!$F$6:$CP$99,2,),)/1000 -> 23.91 | L12: =+K12-J12 -> 2.91 | M12: =+IFERROR(HLOOKUP($B12,'[3]1월'!$F$6:$CC$57,2,),)/1000 -> 20.168 | N12: =+K12-M12 -> 3.742 | O12: =+IFERROR(HLOOKUP($B12,'[1]1월'!$D$6:$BN$259,3,),)/1000 -> 2165.1353 | P12: =+IFERROR(HLOOKUP($B12,'[2]1월'!$F$6:$CP$99,3,),)/1000 -> 2338.4863 | Q12: =+P12-O12 -> 173.35098 | R12: =+IFERROR(HLOOKUP($B12,'[3]1월'!$F$6:$CC$57,3,),)/1000 -> 1845.0339 | S12: =+P12-R12 -> 493.4524 | T12: =+IFERROR(HLOOKUP($B12,'[1]1월'!$D$6:$BN$259,16,),)/1000 -> 313.84242 | U12: =+IFERROR(HLOOKUP($B12,'[2]1월'!$F$6:$CP$99,16,),)/1000 -> 198.0884 | V12: =+U12-T12 -> -115.75402 | W12: =+IFERROR(HLOOKUP($B12,'[3]1월'!$F$6:$CC$57,16,),)/1000 -> 187.27144 | X12: =+U12-W12 -> 10.816962 | Y12: =+[4]서부산!$Q$85 -> 103101.68 | Z12: =+[4]서부산!$R$85 -> 97803.693 | AA12: =+[5]서부산!$Q$85 -> 91483.236 | AB12: =+[4]서부산!$Q$89 -> 77368.389 | AC12: =+[4]서부산!$R$89 -> 79885.068 | AD12: =+[5]서부산!$Q$89 -> 71161.531 | AE12: =+Y12-AB12 -> 25733.292 | AF12: =+Z12-AC12 -> 17918.625 | AG12: =+AA12-AD12 -> 20321.705
B13: 김해 | I13: 김해 | J13: =+IFERROR(HLOOKUP($B13,'[1]1월'!$D$6:$BN$259,2,),)/1000 -> 10 | K13: =+IFERROR(HLOOKUP($B13,'[2]1월'!$F$6:$CP$99,2,),)/1000 -> 12.339 | L13: =+K13-J13 -> 2.339 | M13: =+IFERROR(HLOOKUP($B13,'[3]1월'!$F$6:$CC$57,2,),)/1000 -> 11.598 | N13: =+K13-M13 -> 0.741 | O13: =+IFERROR(HLOOKUP($B13,'[1]1월'!$D$6:$BN$259,3,),)/1000 -> 1009.996 | P13: =+IFERROR(HLOOKUP($B13,'[2]1월'!$F$6:$CP$99,3,),)/1000 -> 1225.7102 | Q13: =+P13-O13 -> 215.7142 | R13: =+IFERROR(HLOOKUP($B13,'[3]1월'!$F$6:$CC$57,3,),)/1000 -> 1096.6881 | S13: =+P13-R13 -> 129.0221 | T13: =+IFERROR(HLOOKUP($B13,'[1]1월'!$D$6:$BN$259,16,),)/1000 -> 74.513101 | U13: =+IFERROR(HLOOKUP($B13,'[2]1월'!$F$6:$CP$99,16,),)/1000 -> 82.439169 | V13: =+U13-T13 -> 7.9260679 | W13: =+IFERROR(HLOOKUP($B13,'[3]1월'!$F$6:$CC$57,16,),)/1000 -> 87.333868 | X13: =+U13-W13 -> -4.894699 | Y13: =+[4]김해!$Q$85 -> 100999.6 | Z13: =+[4]김해!$R$85 -> 99339.807 | AA13: =+[5]김해!$Q$85 -> 94585.859 | AB13: =+[4]김해!$Q$89 -> 76745.601 | AC13: =+[4]김해!$R$89 -> 80683.799 | AD13: =+[5]김해!$Q$89 -> 73642.29 | AE13: =+Y13-AB13 -> 24253.999 | AF13: =+Z13-AC13 -> 18656.008 | AG13: =+AA13-AD13 -> 20943.57
B14: 정관 | I14: 정관 | J14: =+IFERROR(HLOOKUP($B14,'[1]1월'!$D$6:$BN$259,2,),)/1000 -> 18 | K14: =+IFERROR(HLOOKUP($B14,'[2]1월'!$F$6:$CP$99,2,),)/1000 -> 21.5175 | L14: =+K14-J14 -> 3.5175 | M14: =+IFERROR(HLOOKUP($B14,'[3]1월'!$F$6:$CC$57,2,),)/1000 -> 18.264 | N14: =+K14-M14 -> 3.2535 | O14: =+IFERROR(HLOOKUP($B14,'[1]1월'!$D$6:$BN$259,3,),)/1000 -> 1872 | P14: =+IFERROR(HLOOKUP($B14,'[2]1월'!$F$6:$CP$99,3,),)/1000 -> 2218.1056 | Q14: =+P14-O14 -> 346.10565 | R14: =+IFERROR(HLOOKUP($B14,'[3]1월'!$F$6:$CC$57,3,),)/1000 -> 1770.7951 | S14: =+P14-R14 -> 447.31055 | T14: =+IFERROR(HLOOKUP($B14,'[1]1월'!$D$6:$BN$259,16,),)/1000 -> 244.37138 | U14: =+IFERROR(HLOOKUP($B14,'[2]1월'!$F$6:$CP$99,16,),)/1000 -> 256.96584 | V14: =+U14-T14 -> 12.594457 | W14: =+IFERROR(HLOOKUP($B14,'[3]1월'!$F$6:$CC$57,16,),)/1000 -> 235.72105 | X14: =+U14-W14 -> 21.24479 | Y14: =+[4]정관!$Q$85 -> 104000 | Z14: =+[4]정관!$R$85 -> 103083.8 | AA14: =+[5]정관!$Q$85 -> 96955.492 | AB14: =+[4]정관!$Q$89 -> 78930.42 | AC14: =+[4]정관!$R$89 -> 81962.525 | AD14: =+[5]정관!$Q$89 -> 73083.967 | AE14: =+Y14-AB14 -> 25069.58 | AF14: =+Z14-AC14 -> 21121.274 | AG14: =+AA14-AD14 -> 23871.525
B15: 양산 | I15: 양산 | J15: =+IFERROR(HLOOKUP($B15,'[1]1월'!$D$6:$BN$259,2,),)/1000 -> 11 | K15: =+IFERROR(HLOOKUP($B15,'[2]1월'!$F$6:$CP$99,2,),)/1000 -> 13.864 | L15: =+K15-J15 -> 2.864 | M15: =+IFERROR(HLOOKUP($B15,'[3]1월'!$F$6:$CC$57,2,),)/1000 -> 12.092 | N15: =+K15-M15 -> 1.772 | O15: =+IFERROR(HLOOKUP($B15,'[1]1월'!$D$6:$BN$259,3,),)/1000 -> 1059.0887 | P15: =+IFERROR(HLOOKUP($B15,'[2]1월'!$F$6:$CP$99,3,),)/1000 -> 1311.9159 | Q15: =+P15-O15 -> 252.82724 | R15: =+IFERROR(HLOOKUP($B15,'[3]1월'!$F$6:$CC$57,3,),)/1000 -> 1104.9134 | S15: =+P15-R15 -> 207.0025 | T15: =+IFERROR(HLOOKUP($B15,'[1]1월'!$D$6:$BN$259,16,),)/1000 -> 120.73507 | U15: =+IFERROR(HLOOKUP($B15,'[2]1월'!$F$6:$CP$99,16,),)/1000 -> 152.26055 | V15: =+U15-T15 -> 31.525481 | W15: =+IFERROR(HLOOKUP($B15,'[3]1월'!$F$6:$CC$57,16,),)/1000 -> 138.27595 | X15: =+U15-W15 -> 13.984595 | Y15: =+[4]양산!$Q$85 -> 96280.788 | Z15: =+[4]양산!$R$85 -> 94627.517 | AA15: =+[5]양산!$Q$85 -> 91386.531 | AB15: =+[4]양산!$Q$89 -> 71791.379 | AC15: =+[4]양산!$R$89 -> 73539.584 | AD15: =+[5]양산!$Q$89 -> 67798.421 | AE15: =+Y15-AB15 -> 24489.409 | AF15: =+Z15-AC15 -> 21087.933 | AG15: =+AA15-AD15 -> 23588.11
B16: 창원 | I16: 창원 | J16: =+IFERROR(HLOOKUP($B16,'[1]1월'!$D$6:$BN$259,2,),)/1000 -> 14 | K16: =+IFERROR(HLOOKUP($B16,'[2]1월'!$F$6:$CP$99,2,),)/1000 -> 17.315 | L16: =+K16-J16 -> 3.315 | M16: =+IFERROR(HLOOKUP($B16,'[3]1월'!$F$6:$CC$57,2,),)/1000 -> 18.165 | N16: =+K16-M16 -> -0.85 | O16: =+IFERROR(HLOOKUP($B16,'[1]1월'!$D$6:$BN$259,3,),)/1000 -> 1394.204 | P16: =+IFERROR(HLOOKUP($B16,'[2]1월'!$F$6:$CP$99,3,),)/1000 -> 1843.6711 | Q16: =+P16-O16 -> 449.4671 | R16: =+IFERROR(HLOOKUP($B16,'[3]1월'!$F$6:$CC$57,3,),)/1000 -> 1684.7087 | S16: =+P16-R16 -> 158.9624 | T16: =+IFERROR(HLOOKUP($B16,'[1]1월'!$D$6:$BN$259,16,),)/1000 -> 182.43936 | U16: =+IFERROR(HLOOKUP($B16,'[2]1월'!$F$6:$CP$99,16,),)/1000 -> 299.90023 | V16: =+U16-T16 -> 117.46087 | W16: =+IFERROR(HLOOKUP($B16,'[3]1월'!$F$6:$CC$57,16,),)/1000 -> 292.02561 | X16: =+U16-W16 -> 7.874615 | Y16: =+[4]창원!$Q$85 -> 99586 | Z16: =+[4]창원!$R$85 -> 106478.26 | AA16: =+[5]창원!$Q$85 -> 92744.767 | AB16: =+[4]창원!$Q$89 -> 72320.546 | AC16: =+[4]창원!$R$89 -> 77287.77 | AD16: =+[5]창원!$Q$89 -> 66159.287 | AE16: =+Y16-AB16 -> 27265.454 | AF16: =+Z16-AC16 -> 29190.491 | AG16: =+AA16-AD16 -> 26585.48
