Workbook

Sheet 표지
A6: 2024년 11월 마감 손익
A24: 건재사업본부

Sheet 손익총괄
C3: □ 건재사업본부 손익실적(2024-11) | Z3: □ 건재부문 실적(11월)
X4: [단위 : 천㎥, 톤, 원/㎥, 원/톤, 백만원] | AK4: (단위 : 천㎥, 천톤, 억원)
C5: 구분 | E5: 11월 | J5: 11월 누계 | P5: 11월 주요지표 | Z5: 구분 | AB5: =+E5 -> 11월 | AG5: =+J5 -> 11월 누계
A6: 2024년 11월 마감 손익 | E6: 계획 | F6: 실적 | G6: 계획대비 | H6: 전년 | I6: 전년대비 | J6: 계획 | K6: 실적 | L6: 계획대비 | M6: 전년 | N6: 전년대비 | AB6: =+E6 -> 계획 | AC6: =+F6 -> 실적 | AD6: =+G6 -> 계획대비 | AE6: =+H6 -> 전년 | AF6: =+I6 -> 전년대비 | AG6: =+J6 -> 계획 | AH6: =+K6 -> 실적 | AI6: =+L6 -> 계획대비 | ... AK6: =+N6 -> 전년대비
A7: =+F7/E7 -> 0.87708906 | B7: =+K7/J7 -> 0.97288614 | C7: 물량 | D7: 레미콘 | E7: =+'[1]11월'!$Z$7/1000 -> 320 | F7: =+'[2]11월'!$Z$7/1000 -> 280.6685 | G7: =+F7-E7 -> -39.3315 | H7: =+'[3]11월'!$Z$7/1000 -> 359.19918 | I7: =+F7-H7 -> -78.53068 | J7: =+[4]손익총괄!J7+E7 -> 3192.5 | K7: =+[4]손익총괄!K7+F7 -> 3105.939 | L7: =+K7-J7 -> -86.561 | M7: =+[4]손익총괄!M7+H7 -> 3559.7182 | N7: =+K7-M7 -> -453.77918 | Q7: □ 레미콘 | Z7: 물량 | AA7: =+D7 -> 레미콘 | AB7: =+E7 -> 320 | AC7: =+F7 -> 280.6685 | AD7: =+AC7-AB7 -> -39.3315 | AE7: =+H7 -> 359.19918 | AF7: =+AC7-AE7 -> -78.53068 | AG7: =+J7 -> 3192.5 | AH7: =+K7 -> 3105.939 | AI7: =+AH7-AG7 -> -86.561 | AJ7: =+M7 -> 3559.7182 | AK7: =+AH7-AJ7 -> -453.77918
D8: 철강재 | E8: =+'[1]11월'!$AA$7 -> 9200 | F8: =+'[2]11월'!$AO$7 -> 10221.802 | G8: =+F8-E8 -> 1021.802 | H8: =+'[3]11월'!$AO$7 -> 10109.273 | I8: =+F8-H8 -> 112.529 | J8: =+[4]손익총괄!J8+E8 -> 81400 | K8: =+[4]손익총괄!K8+F8 -> 97161.154 | L8: =+K8-J8 -> 15761.154 | M8: =+[4]손익총괄!M8+H8 -> 88735.037 | N8: =+K8-M8 -> 8426.117 | Q8: 구분 | S8: 계획 | T8: 실적 | U8: 계획대비 | V8: 전년 | W8: 전년대비 | AA8: =+D8 -> 철강재 | AB8: =+E8/1000 -> 9.2 | AC8: =+F8/1000 -> 10.221802 | AD8: =+AC8-AB8 -> 1.021802 | AE8: =+H8/1000 -> 10.109273 | AF8: =+AC8-AE8 -> 0.112529 | AG8: =+J8/1000 -> 81.4 | AH8: =+K8/1000 -> 97.161154 | AI8: =+AH8-AG8 -> 15.761154 | AJ8: =+M8/1000 -> 88.735037 | AK8: =+AH8-AJ8 -> 8.426117
D9: 골재 | E9: =+'[1]11월'!$AE$7/1000 -> 124.63455 | F9: =+'[2]11월'!$AN$7/1000 -> 66.126 | G9: =+F9-E9 -> -58.508547 | H9: =+'[3]11월'!$AN$7/1000 -> 105.474 | I9: =+F9-H9 -> -39.348 | J9: =+[4]손익총괄!J9+E9 -> 1105.0942 | K9: =+[4]손익총괄!K9+F9 -> 780.431 | L9: =+K9-J9 -> -324.66321 | M9: =+[4]손익총괄!M9+H9 -> 777.867 | N9: =+K9-M9 -> 2.564 | Q9: 물량 | R9: 수도권 | S9: =+[5]수도권!$T$5/1000 -> 121.5 | T9: =+[5]수도권!$U$5/1000 -> 107.646 | U9: =+T9-S9 -> -13.854 | V9: =+[6]수도권!$T$5/1000 -> 139.27168 | W9: =+T9-V9 -> -31.62568 | AA9: =+D9 -> 골재 | AB9: =+E9 -> 124.63455 | AC9: =+F9 -> 66.126 | AD9: =+AC9-AB9 -> -58.508547 | AE9: =+H9 -> 105.474 | AF9: =+AC9-AE9 -> -39.348 | AG9: =+J9 -> 1105.0942 | AH9: =+K9 -> 780.431 | AI9: =+AH9-AG9 -> -324.66321 | AJ9: =+M9 -> 777.867 | AK9: =+AH9-AJ9 -> 2.564
C10: 매출 | D10: 레미콘 | E10: =+'[1]11월'!$Z$8/1000 -> 32971.103 | F10: =+'[2]11월'!$Z$8/1000 -> 28069.669 | G10: =+F10-E10 -> -4901.4338 | H10: =+'[3]11월'!$Z$8/1000 -> 34627.748 | I10: =+F10-H10 -> -6558.0792 | J10: =+[4]손익총괄!J10+E10 -> 325751.35 | K10: =+[4]손익총괄!K10+F10 -> 312392.53 | L10: =+K10-J10 -> -13358.821 | M10: =+[4]손익총괄!M10+H10 -> 343943.94 | N10: =+K10-M10 -> -31551.413 | R10: 영남권 | S10: =+[5]영남권!$T$5/1000 -> 139.5 | T10: =+[5]영남권!$U$5/1000 -> 121.551 | U10: =+T10-S10 -> -17.949 | V10: =+[6]영남권!$T$5/1000 -> 155.159 | W10: =+T10-V10 -> -33.608 | Z10: 매출액 | AA10: =+D10 -> 레미콘 | AB10: =+E10/100 -> 329.71103 | AC10: =+F10/100 -> 280.69669 | AD10: =+AC10-AB10 -> -49.014338 | AE10: =+H10/100 -> 346.27748 | AF10: =+AC10-AE10 -> -65.580792 | AG10: =+J10/100 -> 3257.5135 | AH10: =+K10/100 -> 3123.9253 | AI10: =+AH10-AG10 -> -133.58821 | AJ10: =+M10/100 -> 3439.4394 | AK10: =+AH10-AJ10 -> -315.51413
D11: 건자재 | E11: =+'[1]11월'!$AA$8/1000 -> 11242.202 | F11: =+'[2]11월'!$AO$8/1000 -> 9942.869 | G11: =+F11-E11 -> -1299.3331 | H11: =+'[3]11월'!$AO$8/1000 -> 12404.88 | I11: =+F11-H11 -> -2462.0112 | J11: =+[4]손익총괄!J11+E11 -> 99529.162 | K11: =+[4]손익총괄!K11+F11 -> 96553.945 | L11: =+K11-J11 -> -2975.2168 | M11: =+[4]손익총괄!M11+H11 -> 108745.62 | N11: =+K11-M11 -> -12191.679 | R11: 중부권 | S11: =+[5]중부권!$T$5/1000 -> 59 | T11: =+[5]중부권!$U$5/1000 -> 51.4715 | U11: =+T11-S11 -> -7.5285 | V11: =+[6]중부권!$T$5/1000 -> 64.7685 | W11: =+T11-V11 -> -13.297 | AA11: =+D11 -> 건자재 | AB11: =+E11/100 -> 112.42202 | AC11: =+F11/100 -> 99.42869 | AD11: =+AC11-AB11 -> -12.993331 | AE11: =+H11/100 -> 124.0488 | AF11: =+AC11-AE11 -> -24.620112 | AG11: =+J11/100 -> 995.29162 | AH11: =+K11/100 -> 965.53945 | AI11: =+AH11-AG11 -> -29.752168 | AJ11: =+M11/100 -> 1087.4562 | AK11: =+AH11-AJ11 -> -121.91679
D12: 골재 | E12: =+'[1]11월'!$AE$8/1000 -> 2273.0709 | F12: =+'[2]11월'!$AN$8/1000 -> 1414.0255 | G12: =+F12-E12 -> -859.04544 | H12: =+'[3]11월'!$AN$8/1000 -> 2014.7305 | I12: =+F12-H12 -> -600.705 | J12: =+[4]손익총괄!J12+E12 -> 20875.566 | K12: =+[4]손익총괄!K12+F12 -> 15789.63 | L12: =+K12-J12 -> -5085.9362 | M12: =+[4]손익총괄!M12+H12 -> 14872.953 | N12: =+K12-M12 -> 916.67618 | Q12: 계 | S12: =SUM(S9:S11) -> 320 | T12: =SUM(T9:T11) -> 280.6685 | U12: =+T12-S12 -> -39.3315 | V12: =SUM(V9:V11) -> 359.19918 | W12: =+T12-V12 -> -78.53068 | AA12: =+D12 -> 골재 | AB12: =+E12/100 -> 22.730709 | AC12: =+F12/100 -> 14.140255 | AD12: =+AC12-AB12 -> -8.5904544 | AE12: =+H12/100 -> 20.147305 | AF12: =+AC12-AE12 -> -6.00705 | AG12: =+J12/100 -> 208.75566 | AH12: =+K12/100 -> 157.8963 | AI12: =+AH12-AG12 -> -50.859362 | AJ12: =+M12/100 -> 148.72953 | AK12: =+AH12-AJ12 -> 9.1667618
D13: 기타 | E13: =+'[1]11월'!$E$8/1000-E10-E11-E12 -> 164.9075 | F13: =+'[2]11월'!$F$8/1000-F10-F11-F12 -> 165.32457 | G13: =+F13-E13 -> 0.41706767 | H13: =+'[3]11월'!$F$8/1000-H10-H11-H12 -> 186.35542 | I13: =+F13-H13 -> -21.030851 | J13: =+[4]손익총괄!J13+E13 -> 1814.5825 | K13: =+[4]손익총괄!K13+F13 -> 1821.6955 | L13: =+K13-J13 -> 7.1130263 | M13: =+[4]손익총괄!M13+H13 -> 2141.8557 | N13: =+K13-M13 -> -320.16012 | Q13: 판매단가 | R13: 수도권 | S13: =+[5]수도권!$T$61 -> 102195.91 | T13: =+[5]수도권!$U$61 -> 97363.141 | U13: =+T13-S13 -> -4832.77 | V13: =+[6]수도권!$Q$85 -> 94344.989 | W13: =+T13-V13 -> 3018.1523 | AA13: =+D13 -> 기타 | AB13: =+E13/100 -> 1.649075 | AC13: =+F13/100 -> 1.6532457 | AD13: =+AC13-AB13 -> 0.0041706767 | AE13: =+H13/100 -> 1.8635542 | AF13: =+AC13-AE13 -> -0.21030851 | AG13: =+J13/100 -> 18.145825 | AH13: =+K13/100 -> 18.216955 | AI13: =+AH13-AG13 -> 0.071130263 | AJ13: =+M13/100 -> 21.418557 | AK13: =+AH13-AJ13 -> -3.2016012
A14: =+F14/E14 -> 0.84867736 | B14: =+K14/J14 -> 0.95220031 | C14: 계 | E14: =SUM(E10:E13) -> 46651.284 | F14: =SUM(F10:F13) -> 39591.888 | G14: =+F14-E14 -> -7059.3953 | H14: =SUM(H10:H13) -> 49233.714 | I14: =+F14-H14 -> -9641.8262 | J14: =SUM(J10:J13) -> 447970.66 | K14: =SUM(K10:K13) -> 426557.8 | L14: =+K14-J14 -> -21412.861 | M14: =SUM(M10:M13) -> 469704.38 | N14: =+K14-M14 -> -43146.576 | R14: 영남권 | S14: =+[5]영남권!$T$61 -> 102613.81 | T14: =+[5]영남권!$U$61 -> 100718.16 | U14: =+T14-S14 -> -1895.651 | V14: =+[6]영남권!$Q$85 -> 97198.734 | W14: =+T14-V14 -> 3519.425 | AA14: 계 | AB14: =SUM(AB10:AB13) -> 466.51284 | AC14: =SUM(AC10:AC13) -> 395.91888 | AD14: =+AC14-AB14 -> -70.593953 | AE14: =SUM(AE10:AE13) -> 492.33714 | AF14: =+AC14-AE14 -> -96.418262 | AG14: =SUM(AG10:AG13) -> 4479.7066 | AH14: =SUM(AH10:AH13) -> 4265.578 | AI14: =+AH14-AG14 -> -214.12861 | AJ14: =SUM(AJ10:AJ13) -> 4697.0438 | AK14: =+AH14-AJ14 -> -431.46576
C15: 매출원가 | D15: 레미콘 | E15: =+('[1]11월'!$Z$10+'[1]11월'!$Z$19)/1000 -> 27072.089 | F15: =+('[2]11월'!$Z$10+'[2]11월'!$Z$19)/1000 -> 25171.805 | G15: =+F15-E15 -> -1900.2838 | H15: =+('[3]11월'!$Z$10+'[3]11월'!$Z$19)/1000 -> 30176.667 | I15: =+F15-H15 -> -5004.8622 | J15: =+[4]손익총괄!J15+E15 -> 271161.95 | K15: =+[4]손익총괄!K15+F15 -> 272340.29 | L15: =+K15-J15 -> 1178.3387 | M15: =+[4]손익총괄!M15+H15 -> 284970.04 | N15: =+K15-M15 -> -12629.75 | R15: 중부권 | S15: =+[5]중부권!$T$61 -> 105757.17 | T15: =+[5]중부권!$U$61 -> 103847.09 | U15: =+T15-S15 -> -1910.0887 | V15: =+[6]중부권!$Q$85 -> 98678.013 | W15: =+T15-V15 -> 5169.0731 | Z15: 영업이익 | AA15: =+D30 -> 레미콘 | AB15: =+E30/100 -> 52.63218 | AC15: =+F30/100 -> 21.959234 | AD15: =+AC15-AB15 -> -30.672946 | AE15: =+H30/100 -> 37.428734 | AF15: =+AC15-AE15 -> -15.4695 | AG15: =+J30/100 -> 473.29443 | AH15: =+K30/100 -> 324.6906 | AI15: =+AH15-AG15 -> -148.60383 | AJ15: =+M30/100 -> 515.43263 | AK15: =+AH15-AJ15 -> -190.74202
D16: 건자재 | E16: =+('[1]11월'!$AA$10+'[1]11월'!$AA$19)/1000 -> 10954.963 | F16: =+('[2]11월'!$AO$10+'[2]11월'!$AO$19)/1000 -> 9692.7755 | G16: =+F16-E16 -> -1262.1872 | H16: =+('[3]11월'!$AO$10+'[3]11월'!$AO$19)/1000 -> 12188.791 | I16: =+F16-H16 -> -2496.0153 | J16: =+[4]손익총괄!J16+E16 -> 96983.428 | K16: =+[4]손익총괄!K16+F16 -> 94392.929 | L16: =+K16-J16 -> -2590.4993 | M16: =+[4]손익총괄!M16+H16 -> 106558.77 | N16: =+K16-M16 -> -12165.841 | Q16: 계 | S16: =+[5]합계!$T$61 -> 103034.7 | T16: =+[5]합계!$U$61 -> 100000.5 | U16: =+T16-S16 -> -3034.1988 | V16: =+[6]합계!$Q$85 -> 96359.434 | W16: =+T16-V16 -> 3641.0641 | AA16: =+D31 -> % | AB16: =+E31 -> 0.15963124 | AC16: =+F31 -> 0.078231182 | AD16: =+AC16-AB16 -> -0.081400056 | AE16: =+H31 -> 0.10808885 | AF16: =+AC16-AE16 -> -0.029857665 | AG16: =+J31 -> 0.14529316 | AH16: =+K31 -> 0.10393674 | AI16: =+AH16-AG16 -> -0.041356424 | AJ16: =+M31 -> 0.14985949 | AK16: =+AH16-AJ16 -> -0.045922749
D17: 골재 | E17: =+('[1]11월'!$AE$10+'[1]11월'!$AE$19)/1000 -> 1978.6362 | F17: =+('[2]11월'!$AN$10+'[2]11월'!$AN$19)/1000 -> 1633.277 | G17: =+F17-E17 -> -345.35923 | H17: =+('[3]11월'!$AN$10+'[3]11월'!$AN$19)/1000 -> 1876.9573 | I17: =+F17-H17 -> -243.68036 | J17: =+[4]손익총괄!J17+E17 -> 18486.773 | K17: =+[4]손익총괄!K17+F17 -> 15409.91 | L17: =+K17-J17 -> -3076.8633 | M17: =+[4]손익총괄!M17+H17 -> 13679.935 | N17: =+K17-M17 -> 1729.9745 | Q17: 공헌이익 | R17: 수도권 | S17: =+[5]수도권!$Q$90 -> 22997.9 | T17: =+[5]수도권!$R$90 -> 14160.07 | U17: =+T17-S17 -> -8837.8297 | V17: =+[6]수도권!$Q$90 -> 13522.243 | W17: =+T17-V17 -> 637.82733 | AA17: =+D32 -> 건자재 | AB17: =+E32/100 -> 1.6573533 | AC17: =+F32/100 -> 1.1835665 | AD17: =+AC17-AB17 -> -0.4737868 | AE17: =+H32/100 -> 0.98190129 | AF17: =+AC17-AE17 -> 0.2016652 | AG17: =+J32/100 -> 11.613904 | AH17: =+K32/100 -> 6.0186035 | AI17: =+AH17-AG17 -> -5.5953008 | AJ17: =+M32/100 -> 8.6828041 | AK17: =+AH17-AJ17 -> -2.6642006
D18: 기타 | E18: =+('[1]11월'!$E$10+'[1]11월'!$E$19)/1000-E15-E16-E17 -> 65.289347 | F18: =+('[2]11월'!$F$10+'[2]11월'!$F$19)/1000-F15-F16-F17 -> -208.79434 | G18: =+F18-E18 -> -274.08369 | H18: =+('[3]11월'!$F$10+'[3]11월'!$F$19)/1000-H15-H16-H17 -> 28.582473 | I18: =+F18-H18 -> -237.37681 | J18: =+[4]손익총괄!J18+E18 -> -669.93587 | K18: =+[4]손익총괄!K18+F18 -> -538.6119 | L18: =+K18-J18 -> 131.32397 | M18: =+[4]손익총괄!M18+H18 -> 585.33795 | N18: =+K18-M18 -> -1123.9498 | R18: 영남권 | S18: =+[5]영남권!$Q$90 -> 26459.648 | T18: =+[5]영남권!$R$90 -> 21227.896 | U18: =+T18-S18 -> -5231.7527 | V18: =+[6]영남권!$Q$90 -> 21637.6 | W18: =+T18-V18 -> -409.70391 | AA18: =+D33 -> 골재 | AB18: =+E33/100 -> 2.5925 | AC18: =+F33/100 -> -2.9010889 | AD18: =+AC18-AB18 -> -5.4935889 | AE18: =+H33/100 -> 1.2797343 | AF18: =+AC18-AE18 -> -4.1808232 | AG18: =+J33/100 -> 18.063168 | AH18: =+K33/100 -> -2.9410414 | AI18: =+AH18-AG18 -> -21.004209 | AJ18: =+M33/100 -> 8.9153957 | AK18: =+AH18-AJ18 -> -11.856437
C19: 계 | E19: =SUM(E15:E18) -> 40070.977 | F19: =SUM(F15:F18) -> 36289.063 | G19: =+F19-E19 -> -3781.914 | H19: =SUM(H15:H18) -> 44270.998 | I19: =+F19-H19 -> -7981.9348 | J19: =SUM(J15:J18) -> 385962.21 | K19: =SUM(K15:K18) -> 381604.51 | L19: =+K19-J19 -> -4357.7 | M19: =SUM(M15:M18) -> 405794.08 | N19: =+K19-M19 -> -24189.566 | R19: 중부권 | S19: =+[5]중부권!$Q$90 -> 28568.039 | T19: =+[5]중부권!$R$90 -> 23600.464 | U19: =+T19-S19 -> -4967.5746 | V19: =+[6]중부권!$Q$90 -> 23589.717 | W19: =+T19-V19 -> 10.747284 | AA19: 공통비 | AB19: =+'사업장별(당월)'!T35/100 -> -11.739158 | AC19: =+'사업장별(당월)'!U35/100 -> -12.654311 | AD19: =+AC19-AB19 -> -0.91515309 | AE19: =+'사업장별(당월)'!W35/100 -> -12.023067 | AF19: =+AC19-AE19 -> -0.63124355 | AG19: =+'사업장별(누계)'!T35/100 -> -149.71779 | AH19: =+'사업장별(누계)'!U35/100 -> -153.53848 | AI19: =+AH19-AG19 -> -3.8206959 | AJ19: =+'사업장별(누계)'!W35/100 -> -129.29509 | AK19: =+AH19-AJ19 -> -24.243393
C20: 매출이익 | D20: 레미콘 | E20: =+E10-E15 -> 5899.0141 | F20: =+F10-F15 -> 2897.8641 | G20: =+F20-E20 -> -3001.15 | H20: =+H10-H15 -> 4451.081 | I20: =+F20-H20 -> -1553.2169 | J20: =+J10-J15 -> 54589.402 | K20: =+K10-K15 -> 40052.242 | L20: =+K20-J20 -> -14537.159 | M20: =+M10-M15 -> 58973.906 | N20: =+K20-M20 -> -18921.663 | Q20: 계 | S20: =+[5]합계!$Q$90 -> 25534 | T20: =+[5]합계!$R$90 -> 18957.932 | U20: =+T20-S20 -> -6576.0679 | V20: =+[6]합계!$Q$90 -> 18847.795 | W20: =+T20-V20 -> 110.13731 | AA20: =+'사업장별(누계)'!I34 -> 임대 | AB20: =+('사업장별(당월)'!T33+'사업장별(당월)'!T34)/100 -> 1.3425598 | AC20: =+('사업장별(당월)'!U33+'사업장별(당월)'!U34)/100 -> 1.2605507 | AD20: =+AC20-AB20 -> -0.082009123 | AE20: =+('사업장별(당월)'!W33+'사업장별(당월)'!W34)/100 -> 1.2851645 | AF20: =+AC20-AE20 -> -0.02461376 | AG20: =+('사업장별(누계)'!T33+'사업장별(누계)'!T34)/100 -> 14.630188 | AH20: =+('사업장별(누계)'!U33+'사업장별(누계)'!U34)/100 -> 14.211182 | AI20: =+AH20-AG20 -> -0.41900594 | AJ20: =+('사업장별(누계)'!W33+'사업장별(누계)'!W34)/100 -> 13.19195 | AK20: =+AH20-AJ20 -> 1.0192321
D21: 건자재 | E21: =+E11-E16 -> 287.23939 | F21: =+F11-F16 -> 250.09354 | G21: =+F21-E21 -> -37.145849 | H21: =+H11-H16 -> 216.0894 | I21: =+F21-H21 -> 34.004143 | J21: =+J11-J16 -> 2545.7337 | K21: =+K11-K16 -> 2161.0162 | L21: =+K21-J21 -> -384.71744 | M21: =+M11-M16 -> 2186.8542 | N21: =+K21-M21 -> -25.837998 | Q21: □ 건자재 | AA21: =+'사업장별(누계)'!I37 -> 대손 | AB21: =+'사업장별(당월)'!T37/100 -> 0 | AC21: =+'사업장별(당월)'!U37/100 -> 0 | AD21: =+AC21-AB21 -> 0 | AE21: =+'사업장별(당월)'!W37/100 -> 0 | AF21: =+AC21-AE21 -> 0 | AG21: =+'사업장별(누계)'!T37/100 -> 0 | AH21: =+'사업장별(누계)'!U37/100 -> -5.7385933 | AI21: =+AH21-AG21 -> -5.7385933 | AJ21: =+'사업장별(누계)'!W37/100 -> -19.74222 | AK21: =+AH21-AJ21 -> 14.003626
D22: 골재 | E22: =+E12-E17 -> 294.43475 | F22: =+F12-F17 -> -219.25146 | G22: =+F22-E22 -> -513.68621 | H22: =+H12-H17 -> 137.77318 | I22: =+F22-H22 -> -357.02464 | J22: =+J12-J17 -> 2388.7927 | K22: =+K12-K17 -> 379.71973 | L22: =+K22-J22 -> -2009.073 | M22: =+M12-M17 -> 1193.0181 | N22: =+K22-M22 -> -813.29833 | Q22: 구분 | S22: 계획 | T22: 실적 | U22: 계획대비 | V22: 전년 | W22: 전년대비 | AA22: =+D34 -> 기타 | AB22: =+AB26-AB19-AB20-AB21 -> -1.1499503 | AC22: =+AC26-AC19-AC20-AC21 -> 1.9206589 | AD22: =+AC22-AB22 -> 3.0706092 | AE22: =+AE26-AE19-AE20-AE21 -> -0.26000684 | AF22: =+AC22-AE22 -> 2.1806657 | AG22: =+AG26-AG19-AG20-AG21 -> 2.7465483 | AH22: =+AH26-AH19-AH20-AH21 -> 3.537348 | AI22: =+AH22-AG22 -> 0.79079963 | AJ22: =+AJ26-AJ19-AJ20-AJ21 -> -3.7740458 | AK22: =+AH22-AJ22 -> 7.3113938
D23: 기타 | E23: =+E13-E18 -> 99.618153 | F23: =+F13-F18 -> 374.11891 | G23: =+F23-E23 -> 274.50076 | H23: =+H13-H18 -> 157.77295 | I23: =+F23-H23 -> 216.34596 | J23: =+J13-J18 -> 2484.5184 | K23: =+K13-K18 -> 2360.3074 | L23: =+K23-J23 -> -124.21094 | M23: =+M13-M18 -> 1556.5177 | N23: =+K23-M23 -> 803.78973 | Q23: 철강재 판매단가 | S23: =+'[7]11월'!$F$10 -> 976086.96 | T23: =+'[7]11월'!$G$10 -> 798803.69 | U23: =+T23-S23 -> -177283.27 | V23: =+'[8]11월'!$G$10 -> 985246.58 | W23: =+T23-V23 -> -186442.89 | AA23: 계 | AB23: =SUM(AB15,AB17:AB22) -> 45.335485 | AC23: =SUM(AC15,AC17:AC22) -> 10.76861 | AD23: =+AC23-AB23 -> -34.566874 | AE23: =SUM(AE15,AE17:AE22) -> 28.69246 | AF23: =+AC23-AE23 -> -17.92385 | AG23: =SUM(AG15,AG17:AG22) -> 370.63045 | AH23: =SUM(AH15,AH17:AH22) -> 186.23962 | AI23: =+AH23-AG23 -> -184.39084 | AJ23: =SUM(AJ15,AJ17:AJ22) -> 393.41142 | AK23: =+AH23-AJ23 -> -207.1718
C24: 계 | E24: =SUM(E20:E23) -> 6580.3064 | F24: =SUM(F20:F23) -> 3302.8251 | G24: =+F24-E24 -> -3277.4813 | H24: =SUM(H20:H23) -> 4962.7166 | I24: =+F24-H24 -> -1659.8915 | J24: =SUM(J20:J23) -> 62008.447 | K24: =SUM(K20:K23) -> 44953.286 | L24: =+K24-J24 -> -17055.161 | M24: =SUM(M20:M23) -> 63910.296 | N24: =+K24-M24 -> -18957.01 | Q24: 철강재 마진률 | S24: =+'[7]11월'!$F$15 -> 0.023224944 | T24: =+'[7]11월'!$G$15 -> 0.023726716 | U24: =+T24-S24 -> 0.00050177217 | V24: =+'[8]11월'!$G$15 -> 0.016194919 | W24: =+T24-V24 -> 0.0075317977 | AA24: =+D36 -> % | AB24: =+E36 -> 0.097179501 | AC24: =+F36 -> 0.027199032 | AD24: =+G36 -> -0.06998047 | AE24: =+H36 -> 0.058278073 | AF24: =+I36 -> -0.031079041 | AG24: =+J36 -> 0.08273543 | AH24: =+K36 -> 0.043661051 | ... AK24: =+N36 -> -0.040096189
C25: 판관비 | D25: 레미콘 | E25: =+('[1]11월'!$Z$13+'[1]11월'!$Z$20)/1000 -> 635.79616 | F25: =+('[2]11월'!$Z$13+'[2]11월'!$Z$20)/1000 -> 701.94071 | G25: =+F25-E25 -> 66.144548 | H25: =+('[3]11월'!$Z$13+'[3]11월'!$Z$20)/1000 -> 708.20763 | I25: =+F25-H25 -> -6.266917 | J25: =+[4]손익총괄!J25+E25 -> 7259.9586 | K25: =+[4]손익총괄!K25+F25 -> 7583.1822 | L25: =+K25-J25 -> 323.22366 | M25: =+[4]손익총괄!M25+H25 -> 7430.6432 | N25: =+K25-M25 -> 152.539 | Q25: □ 골재
D26: 건자재 | E26: =+('[1]11월'!$AA$13+'[1]11월'!$AA$20)/1000 -> 121.50406 | F26: =+('[2]11월'!$AO$13+'[2]11월'!$AO$20)/1000 -> 131.73689 | G26: =+F26-E26 -> 10.232831 | H26: =+('[3]11월'!$AO$13+'[3]11월'!$AO$20)/1000 -> 117.89927 | I26: =+F26-H26 -> 13.837623 | J26: =+[4]손익총괄!J26+E26 -> 1384.3432 | K26: =+[4]손익총괄!K26+F26 -> 1559.1559 | L26: =+K26-J26 -> 174.81264 | M26: =+[4]손익총괄!M26+H26 -> 1318.5738 | N26: =+K26-M26 -> 240.58207 | Q26: 구분 | S26: 계획 | T26: 실적 | U26: 계획대비 | V26: 전년 | W26: 전년대비 | AB26: =+'사업장별(당월)'!T41/100 -> -11.546548 | AC26: =+'사업장별(당월)'!U41/100 -> -9.4731013 | AD26: =+AC26-AB26 -> 2.073447 | AE26: =+'사업장별(당월)'!W41/100 -> -10.99791 | AF26: =+AE26-AD26 -> -13.071357 | AG26: =+'사업장별(누계)'!T41/100 -> -132.34105 | AH26: =+'사업장별(누계)'!U41/100 -> -141.52855 | AJ26: =+'사업장별(누계)'!W41/100 -> -139.6194
D27: 골재 | E27: =+('[1]11월'!$AE$13+'[1]11월'!$AE$20+'[1]11월'!$AE$22)/1000 -> 35.18475 | F27: =+('[2]11월'!$AN$13+'[2]11월'!$AN$20+'[2]11월'!$AN$22)/1000 -> 70.857428 | G27: =+F27-E27 -> 35.672678 | H27: =+('[3]11월'!$AN$13+'[3]11월'!$AN$20+'[3]11월'!$AN$22)/1000 -> 9.79975 | I27: =+F27-H27 -> 61.057678 | J27: =+[4]손익총괄!J27+E27 -> 582.47594 | K27: =+[4]손익총괄!K27+F27 -> 673.82387 | L27: =+K27-J27 -> 91.347939 | M27: =+[4]손익총괄!M27+H27 -> 301.4785 | N27: =+K27-M27 -> 372.34538 | Q27: 판매량 | R27: 자가 | S27: =(+'[9]서부산크라샤(당월)'!$N$66+'[9]부산모래장(당월)'!$Q$48+'[9]부산크라샤(당월)'!$N$66)/1000 -> 63.834547 | T27: =(+'[9]서부산크라샤(당월)'!$O$66+'[9]부산모래장(당월)'!$R$48+'[9]부산크라샤(당월)'!$O$66)/1000 -> 36.922 | U27: =+T27-S27 -> -26.912547 | V27: =('[10]부산골재(당월)'!$R$48+'[10]서부산골재(당월)'!$O$66+'[10]부산크라샤(당월)'!$O$66)/1000 -> 67.377 | W27: =+T27-V27 -> -30.455
D28: 기타 | E28: =+('[1]11월'!$E$13+'[1]11월'!$E$20)/1000-E25-E26-E27+('[1]11월'!$E$22/1000) -> 1254.273 | F28: =+('[2]11월'!$F$13+'[2]11월'!$F$20)/1000-F25-F26-F27+'[2]11월'!$F$22/1000 -> 1321.429 | G28: =+F28-E28 -> 67.156056 | H28: =+('[3]11월'!$F$13+'[3]11월'!$F$20)/1000-H25-H26-H27+'[3]11월'!$F$22/1000 -> 1257.5639 | I28: =+F28-H28 -> 63.865122 | J28: =+[4]손익총괄!J28+E28 -> 15718.623 | K28: =+[4]손익총괄!K28+F28 -> 16513.162 | L28: =+K28-J28 -> 794.53861 | M28: =+[4]손익총괄!M28+H28 -> 15518.458 | N28: =+K28-M28 -> 994.70384 | R28: 외판 | S28: =(+'[9]서부산크라샤(당월)'!$N$59+'[9]부산모래장(당월)'!$Q$47+'[9]부산크라샤(당월)'!$N$59)/1000 -> 60.8 | T28: =(+'[9]서부산크라샤(당월)'!$O$59+'[9]부산모래장(당월)'!$R$47+'[9]부산크라샤(당월)'!$O$59)/1000 -> 29.204 | U28: =+T28-S28 -> -31.596 | V28: =+('[10]부산골재(당월)'!$R$47+'[10]서부산골재(당월)'!$O$59+'[10]부산크라샤(당월)'!$O$59)/1000 -> 38.097 | W28: =+T28-V28 -> -8.893
C29: 계 | E29: =SUM(E25:E28) -> 2046.758 | F29: =SUM(F25:F28) -> 2225.9641 | G29: =+F29-E29 -> 179.20611 | H29: =SUM(H25:H28) -> 2093.4706 | I29: =+F29-H29 -> 132.49351 | J29: =SUM(J25:J28) -> 24945.401 | K29: =SUM(K25:K28) -> 26329.324 | L29: =+K29-J29 -> 1383.9228 | M29: =SUM(M25:M28) -> 24569.154 | N29: =+K29-M29 -> 1760.1703 | Q29: 합 계 | S29: =SUM(S27:S28) -> 124.63455 | T29: =SUM(T27:T28) -> 66.126 | U29: =+T29-S29 -> -58.508547 | V29: =SUM(V27:V28) -> 105.474 | W29: =+T29-V29 -> -39.348
C30: 영업이익 | D30: 레미콘 | E30: =+E20-E25 -> 5263.218 | F30: =+F20-F25 -> 2195.9234 | G30: =+F30-E30 -> -3067.2946 | H30: =+H20-H25 -> 3742.8734 | I30: =+F30-H30 -> -1546.95 | J30: =+J20-J25 -> 47329.443 | K30: =+K20-K25 -> 32469.06 | L30: =+K30-J30 -> -14860.383 | M30: =+M20-M25 -> 51543.263 | N30: =+K30-M30 -> -19074.202 | Q30: □ 기타내역(영업이익)
D31: % | E31: =+E30/E10 -> 0.15963124 | F31: =+F30/F10 -> 0.078231182 | G31: =+F31-E31 -> -0.081400056 | H31: =+H30/H10 -> 0.10808885 | I31: =+F31-H31 -> -0.029857665 | J31: =+J30/J10 -> 0.14529316 | K31: =+K30/K10 -> 0.10393674 | L31: =+K31-J31 -> -0.041356424 | M31: =+M30/M10 -> 0.14985949 | N31: =+K31-M31 -> -0.045922749 | Q31: 구분 | S31: 계획 | T31: 실적 | U31: 계획대비 | V31: 전년 | W31: 전년대비
D32: 건자재 | E32: =+E21-E26 -> 165.73533 | F32: =+F21-F26 -> 118.35665 | G32: =+F32-E32 -> -47.37868 | H32: =+H21-H26 -> 98.190129 | I32: =+F32-H32 -> 20.16652 | J32: =+J21-J26 -> 1161.3904 | K32: =+K21-K26 -> 601.86035 | L32: =+K32-J32 -> -559.53008 | M32: =+M21-M26 -> 868.28041 | N32: =+K32-M32 -> -266.42006 | Q32: 레미콘임대 | S32: =+'사업장별(당월)'!T33 -> 72.210526 | T32: =+'사업장별(당월)'!U33 -> 67.392238 | U32: =+T32-S32 -> -4.818288 | V32: =+'사업장별(당월)'!W33 -> 71.822105 | W32: =+T32-V32 -> -4.429867
D33: 골재 | E33: =+E22-E27 -> 259.25 | F33: =+F22-F27 -> -290.10889 | G33: =+F33-E33 -> -549.35889 | H33: =+H22-H27 -> 127.97343 | I33: =+F33-H33 -> -418.08232 | J33: =+J22-J27 -> 1806.3168 | K33: =+K22-K27 -> -294.10414 | L33: =+K33-J33 -> -2100.4209 | M33: =+M22-M27 -> 891.53957 | N33: =+K33-M33 -> -1185.6437 | Q33: 임대 | S33: =+'사업장별(당월)'!T34 -> 62.045457 | T33: =+'사업장별(당월)'!U34 -> 58.662833 | U33: =+T33-S33 -> -3.3826243 | V33: =+'사업장별(당월)'!W34 -> 56.694342 | W33: =+T33-V33 -> 1.968491
D34: 기타 | E34: =+E23-E28 -> -1154.6548 | F34: =+F23-F28 -> -947.31013 | G34: =+F34-E34 -> 207.3447 | H34: =+H23-H28 -> -1099.791 | I34: =+F34-H34 -> 152.48084 | J34: =+J23-J28 -> -13234.105 | K34: =+K23-K28 -> -14152.855 | L34: =+K34-J34 -> -918.74955 | M34: =+M23-M28 -> -13961.94 | N34: =+K34-M34 -> -190.91411 | Q34: 공통비 | S34: =+'사업장별(당월)'!T35 -> -1173.9158 | T34: =+'사업장별(당월)'!U35 -> -1265.4311 | U34: =+T34-S34 -> -91.515309 | V34: =+'사업장별(당월)'!W35 -> -1202.3067 | W34: =+T34-V34 -> -63.124355
C35: 계 | E35: =SUM(E30,E32:E34) -> 4533.5485 | F35: =SUM(F30,F32:F34) -> 1076.861 | G35: =+F35-E35 -> -3456.6874 | H35: =SUM(H30,H32:H34) -> 2869.246 | I35: =+F35-H35 -> -1792.385 | J35: =SUM(J30,J32:J34) -> 37063.045 | K35: =SUM(K30,K32:K34) -> 18623.962 | L35: =+K35-J35 -> -18439.084 | M35: =SUM(M30,M32:M34) -> 39341.142 | N35: =+K35-M35 -> -20717.18 | Q35: 기타 | S35: =+S36-S32-S33-S34 -> -114.99503 | T35: =+T36-T32-T33-T34 -> 192.06589 | U35: =+T35-S35 -> 307.06092 | V35: =+V36-V32-V33-V34 -> -26.000684 | W35: =+T35-V35 -> 218.06657
D36: % | E36: =+E35/E14 -> 0.097179501 | F36: =+F35/F14 -> 0.027199032 | G36: =+F36-E36 -> -0.06998047 | H36: =+H35/H14 -> 0.058278073 | I36: =+F36-H36 -> -0.031079041 | J36: =+J35/J14 -> 0.08273543 | K36: =+K35/K14 -> 0.043661051 | L36: =+K36-J36 -> -0.03907438 | M36: =+M35/M14 -> 0.08375724 | N36: =+K36-M36 -> -0.040096189 | Q36: 합계 | S36: =+'사업장별(당월)'!T41 -> -1154.6548 | T36: =+'사업장별(당월)'!U41 -> -947.31013 | U36: =+T36-S36 -> 207.3447 | V36: =+'사업장별(당월)'!W41 -> -1099.791 | W36: =+T36-V36 -> 152.48084
E38: =+'[1]11월'!$E$26/1000 -> 4533.5485 | F38: =+'[2]11월'!$F$26/1000 -> 1076.861 | H38: =+'[3]11월'!$F$26/1000 -> 2869.246 | J38: =+[4]손익총괄!J38+E38 -> 37063.045 | K38: =+[4]손익총괄!K38+F38 -> 18623.962 | M38: =+[4]손익총괄!M38+H38 -> 39341.142
E39: =+E35=E38 -> TRUE | F39: =+F35=F38 -> TRUE | H39: =+H35=H38 -> TRUE | J39: =+J35=J38 -> TRUE | K39: =+K35=K38 -> TRUE | M39: =+M35=M38 -> TRUE
E40: =+E35-E38 -> 0 | F40: =+F35-F38 -> 1.8189894e-12 | H40: =+H35-H38 -> 0 | J40: =+J35-J38 -> 0 | K40: =+K35-K38 -> 0 | M40: =+M35-M38 -> 0

Sheet 사업장별(당월)
H3: □ 사업장별 손익실적(2024-11)
AG4: [단위 : 천㎥, 톤, 백만원]
H5: 구분 | J5: 물량 | O5: 매출 | T5: 영업이익(공통비 배부전) | Y5: 판매단가 | AB5: 변동비 | AE5: 공헌이익
A6: 2024년 11월 마감 손익 | J6: 계획 | K6: 실적 | L6: 차이 | M6: 전년 | N6: 차이 | O6: 계획 | P6: 실적 | Q6: 차이 | R6: 전년 | S6: 차이 | T6: 계획 | U6: 실적 | V6: 차이 | W6: 전년 | X6: 차이 | Y6: 계획 | Z6: 실적 | AA6: 전년 | AB6: 계획 | AC6: 실적 | AD6: 전년 | AE6: 계획 | AF6: 실적 | AG6: 전년
B7: 안양 | G7: =+I7 -> 안양 | H7: 레미콘 | I7: 안양 | J7: =+IFERROR(HLOOKUP($B7,'[1]11월'!$D$6:$BN$259,2,),)/1000 -> 45 | K7: =+IFERROR(HLOOKUP($B7,'[2]11월'!$F$6:$CP$99,2,),)/1000 -> 38.566 | L7: =+K7-J7 -> -6.434 | M7: =+IFERROR(HLOOKUP($B7,'[3]11월'!$F$6:$CC$57,2,),)/1000 -> 52.411 | N7: =+K7-M7 -> -13.845 | O7: =+IFERROR(HLOOKUP($B7,'[1]11월'!$D$6:$BN$259,3,),)/1000 -> 4576.7897 | P7: =+IFERROR(HLOOKUP($B7,'[2]11월'!$F$6:$CP$99,3,),)/1000 -> 3786.5243 | Q7: =+P7-O7 -> -790.26544 | R7: =+IFERROR(HLOOKUP($B7,'[3]11월'!$F$6:$CC$57,3,),)/1000 -> 4739.0451 | S7: =+P7-R7 -> -952.52079 | T7: =+IFERROR(HLOOKUP($B7,'[1]11월'!$D$6:$BN$259,16,),)/1000 -> 669.44377 | U7: =+IFERROR(HLOOKUP($B7,'[2]11월'!$F$6:$CP$99,16,),)/1000 -> 302.27516 | V7: =+U7-T7 -> -367.16861 | W7: =+IFERROR(HLOOKUP($B7,'[3]11월'!$F$6:$CC$57,16,),)/1000 -> 289.11731 | X7: =+U7-W7 -> 13.157852 | Y7: =+[5]안양!$Q$85 -> 101706.44 | Z7: =+[5]안양!$R$85 -> 98187.636 | AA7: =+[6]안양!$Q$85 -> 90390.319 | AB7: =+[5]안양!$Q$89 -> 80285.824 | AC7: =+[5]안양!$R$89 -> 83030.588 | AD7: =+[6]안양!$Q$89 -> 79011.361 | AE7: =+Y7-AB7 -> 21420.613 | AF7: =+Z7-AC7 -> 15157.048 | AG7: =+AA7-AD7 -> 11378.958
B8: 인천 | G8: =+I8 -> 인천 | H8: 직영 | I8: 인천 | J8: =+IFERROR(HLOOKUP($B8,'[1]11월'!$D$6:$BN$259,2,),)/1000 -> 36 | K8: =+IFERROR(HLOOKUP($B8,'[2]11월'!$F$6:$CP$99,2,),)/1000 -> 29.507 | L8: =+K8-J8 -> -6.493 | M8: =+IFERROR(HLOOKUP($B8,'[3]11월'!$F$6:$CC$57,2,),)/1000 -> 38.282 | N8: =+K8-M8 -> -8.775 | O8: =+IFERROR(HLOOKUP($B8,'[1]11월'!$D$6:$BN$259,3,),)/1000 -> 3840.6235 | P8: =+IFERROR(HLOOKUP($B8,'[2]11월'!$F$6:$CP$99,3,),)/1000 -> 2907.4014 | Q8: =+P8-O8 -> -933.22206 | R8: =+IFERROR(HLOOKUP($B8,'[3]11월'!$F$6:$CC$57,3,),)/1000 -> 3653.7019 | S8: =+P8-R8 -> -746.30043 | T8: =+IFERROR(HLOOKUP($B8,'[1]11월'!$D$6:$BN$259,16,),)/1000 -> 631.27755 | U8: =+IFERROR(HLOOKUP($B8,'[2]11월'!$F$6:$CP$99,16,),)/1000 -> 72.336657 | V8: =+U8-T8 -> -558.94089 | W8: =+IFERROR(HLOOKUP($B8,'[3]11월'!$F$6:$CC$57,16,),)/1000 -> 197.3863 | X8: =+U8-W8 -> -125.04964 | Y8: =+[5]인천!$Q$85 -> 106683.99 | Z8: =+[5]인천!$R$85 -> 98532.601 | AA8: =+[6]인천!$Q$85 -> 95427.937 | AB8: =+[5]인천!$Q$89 -> 81462.254 | AC8: =+[5]인천!$R$89 -> 85841.298 | AD8: =+[6]인천!$Q$89 -> 82915.993 | AE8: =+Y8-AB8 -> 25221.732 | AF8: =+Z8-AC8 -> 12691.303 | AG8: =+AA8-AD8 -> 12511.943
B9: 파주 | G9: =+I9 -> 파주 | I9: 파주 | J9: =+IFERROR(HLOOKUP($B9,'[1]11월'!$D$6:$BN$259,2,),)/1000 -> 23 | K9: =+IFERROR(HLOOKUP($B9,'[2]11월'!$F$6:$CP$99,2,),)/1000 -> 22.349 | L9: =+K9-J9 -> -0.651 | M9: =+IFERROR(HLOOKUP($B9,'[3]11월'!$F$6:$CC$57,2,),)/1000 -> 32.522 | N9: =+K9-M9 -> -10.173 | O9: =+IFERROR(HLOOKUP($B9,'[1]11월'!$D$6:$BN$259,3,),)/1000 -> 2308.8135 | P9: =+IFERROR(HLOOKUP($B9,'[2]11월'!$F$6:$CP$99,3,),)/1000 -> 2134.5209 | Q9: =+P9-O9 -> -174.29254 | R9: =+IFERROR(HLOOKUP($B9,'[3]11월'!$F$6:$CC$57,3,),)/1000 -> 3216.1735 | S9: =+P9-R9 -> -1081.6525 | T9: =+IFERROR(HLOOKUP($B9,'[1]11월'!$D$6:$BN$259,16,),)/1000 -> 291.23696 | U9: =+IFERROR(HLOOKUP($B9,'[2]11월'!$F$6:$CP$99,16,),)/1000 -> 79.622709 | V9: =+U9-T9 -> -211.61425 | W9: =+IFERROR(HLOOKUP($B9,'[3]11월'!$F$6:$CC$57,16,),)/1000 -> 229.24384 | X9: =+U9-W9 -> -149.62113 | Y9: =+[5]파주!$Q$85 -> 100383.19 | Z9: =+[5]파주!$R$85 -> 95512.912 | AA9: =+[6]파주!$Q$85 -> 98825.228 | AB9: =+[5]파주!$Q$89 -> 78647.244 | AC9: =+[5]파주!$R$89 -> 81942.563 | AD9: =+[6]파주!$Q$89 -> 84723.197 | AE9: =+Y9-AB9 -> 21735.95 | AF9: =+Z9-AC9 -> 13570.349 | AG9: =+AA9-AD9 -> 14102.031
B10: 김포 | G10: =+I10 -> 김포 | I10: 김포 | J10: =+IFERROR(HLOOKUP($B10,'[1]11월'!$D$6:$BN$259,2,),)/1000 -> 17.5 | K10: =+IFERROR(HLOOKUP($B10,'[2]11월'!$F$6:$CP$99,2,),)/1000 -> 17.224 | L10: =+K10-J10 -> -0.276 | M10: =+IFERROR(HLOOKUP($B10,'[3]11월'!$F$6:$CC$57,2,),)/1000 -> 16.05668 | N10: =+K10-M10 -> 1.16732 | O10: =+IFERROR(HLOOKUP($B10,'[1]11월'!$D$6:$BN$259,3,),)/1000 -> 1690.5765 | P10: =+IFERROR(HLOOKUP($B10,'[2]11월'!$F$6:$CP$99,3,),)/1000 -> 1650.7338 | Q10: =+P10-O10 -> -39.8427 | R10: =+IFERROR(HLOOKUP($B10,'[3]11월'!$F$6:$CC$57,3,),)/1000 -> 1538.7716 | S10: =+P10-R10 -> 111.96222 | T10: =+IFERROR(HLOOKUP($B10,'[1]11월'!$D$6:$BN$259,16,),)/1000 -> 264.05161 | U10: =+IFERROR(HLOOKUP($B10,'[2]11월'!$F$6:$CP$99,16,),)/1000 -> 98.878248 | V10: =+U10-T10 -> -165.17336 | W10: =+IFERROR(HLOOKUP($B10,'[3]11월'!$F$6:$CC$57,16,),)/1000 -> 184.97632 | X10: =+U10-W10 -> -86.098076 | Y10: =+[5]김포!$Q$85 -> 96604.371 | Z10: =+[5]김포!$R$85 -> 95901.216 | AA10: =+[6]김포!$Q$85 -> 95784.706 | AB10: =+[5]김포!$Q$89 -> 72466.77 | AC10: =+[5]김포!$R$89 -> 80686.638 | AD10: =+[6]김포!$Q$89 -> 73858.942 | AE10: =+Y10-AB10 -> 24137.601 | AF10: =+Z10-AC10 -> 15214.577 | AG10: =+AA10-AD10 -> 21925.764
B11: 부산 | G11: =+I11 -> 부산 | I11: 부산 | J11: =+IFERROR(HLOOKUP($B11,'[1]11월'!$D$6:$BN$259,2,),)/1000 -> 24 | K11: =+IFERROR(HLOOKUP($B11,'[2]11월'!$F$6:$CP$99,2,),)/1000 -> 19.12 | L11: =+K11-J11 -> -4.88 | M11: =+IFERROR(HLOOKUP($B11,'[3]11월'!$F$6:$CC$57,2,),)/1000 -> 24.2875 | N11: =+K11-M11 -> -5.1675 | O11: =+IFERROR(HLOOKUP($B11,'[1]11월'!$D$6:$BN$259,3,),)/1000 -> 2582.3961 | P11: =+IFERROR(HLOOKUP($B11,'[2]11월'!$F$6:$CP$99,3,),)/1000 -> 2100.75 | Q11: =+P11-O11 -> -481.64606 | R11: =+IFERROR(HLOOKUP($B11,'[3]11월'!$F$6:$CC$57,3,),)/1000 -> 2488.4756 | S11: =+P11-R11 -> -387.7256 | T11: =+IFERROR(HLOOKUP($B11,'[1]11월'!$D$6:$BN$259,16,),)/1000 -> 440.56963 | U11: =+IFERROR(HLOOKUP($B11,'[2]11월'!$F$6:$CP$99,16,),)/1000 -> 175.17909 | V11: =+U11-T11 -> -265.39054 | W11: =+IFERROR(HLOOKUP($B11,'[3]11월'!$F$6:$CC$57,16,),)/1000 -> 295.99216 | X11: =+U11-W11 -> -120.81307 | Y11: =+[5]부산!$Q$85 -> 107599.84 | Z11: =+[5]부산!$R$85 -> 109871.86 | AA11: =+[6]부산!$Q$85 -> 102459.11 | AB11: =+[5]부산!$Q$89 -> 78841.491 | AC11: =+[5]부산!$R$89 -> 86400.778 | AD11: =+[6]부산!$Q$89 -> 79670.334 | AE11: =+Y11-AB11 -> 28758.345 | AF11: =+Z11-AC11 -> 23471.085 | AG11: =+AA11-AD11 -> 22788.775
B12: 서부산 | G12: =+I12 -> 서부산 | I12: 서부산 | J12: =+IFERROR(HLOOKUP($B12,'[1]11월'!$D$6:$BN$259,2,),)/1000 -> 26 | K12: =+IFERROR(HLOOKUP($B12,'[2]11월'!$F$6:$CP$99,2,),)/1000 -> 19.932 | L12: =+K12-J12 -> -6.068 | M12: =+IFERROR(HLOOKUP($B12,'[3]11월'!$F$6:$CC$57,2,),)/1000 -> 29.358 | N12: =+K12-M12 -> -9.426 | O12: =+IFERROR(HLOOKUP($B12,'[1]11월'!$D$6:$BN$259,3,),)/1000 -> 2719.0035 | P12: =+IFERROR(HLOOKUP($B12,'[2]11월'!$F$6:$CP$99,3,),)/1000 -> 1883.6583 | Q12: =+P12-O12 -> -835.34523 | R12: =+IFERROR(HLOOKUP($B12,'[3]11월'!$F$6:$CC$57,3,),)/1000 -> 2851.8056 | S12: =+P12-R12 -> -968.14732 | T12: =+IFERROR(HLOOKUP($B12,'[1]11월'!$D$6:$BN$259,16,),)/1000 -> 511.79381 | U12: =+IFERROR(HLOOKUP($B12,'[2]11월'!$F$6:$CP$99,16,),)/1000 -> 124.8758 | V12: =+U12-T12 -> -386.91801 | W12: =+IFERROR(HLOOKUP($B12,'[3]11월'!$F$6:$CC$57,16,),)/1000 -> 436.14119 | X12: =+U12-W12 -> -311.26539 | Y12: =+[5]서부산!$Q$85 -> 104577.06 | Z12: =+[5]서부산!$R$85 -> 94504.229 | AA12: =+[6]서부산!$Q$85 -> 97138.961 | AB12: =+[5]서부산!$Q$89 -> 76327.595 | AC12: =+[5]서부산!$R$89 -> 77003.708 | AD12: =+[6]서부산!$Q$89 -> 74683.793 | AE12: =+Y12-AB12 -> 28249.464 | AF12: =+Z12-AC12 -> 17500.521 | AG12: =+AA12-AD12 -> 22455.167
B13: 김해 | G13: =+I13 -> 김해 | I13: 김해 | J13: =+IFERROR(HLOOKUP($B13,'[1]11월'!$D$6:$BN$259,2,),)/1000 -> 14 | K13: =+IFERROR(HLOOKUP($B13,'[2]11월'!$F$6:$CP$99,2,),)/1000 -> 12.286 | L13: =+K13-J13 -> -1.714 | M13: =+IFERROR(HLOOKUP($B13,'[3]11월'!$F$6:$CC$57,2,),)/1000 -> 16.069 | N13: =+K13-M13 -> -3.783 | O13: =+IFERROR(HLOOKUP($B13,'[1]11월'!$D$6:$BN$259,3,),)/1000 -> 1414.0056 | P13: =+IFERROR(HLOOKUP($B13,'[2]11월'!$F$6:$CP$99,3,),)/1000 -> 1181.5016 | Q13: =+P13-O13 -> -232.504 | R13: =+IFERROR(HLOOKUP($B13,'[3]11월'!$F$6:$CC$57,3,),)/1000 -> 1581.8795 | S13: =+P13-R13 -> -400.37789 | T13: =+IFERROR(HLOOKUP($B13,'[1]11월'!$D$6:$BN$259,16,),)/1000 -> 199.30405 | U13: =+IFERROR(HLOOKUP($B13,'[2]11월'!$F$6:$CP$99,16,),)/1000 -> 84.464322 | V13: =+U13-T13 -> -114.83973 | W13: =+IFERROR(HLOOKUP($B13,'[3]11월'!$F$6:$CC$57,16,),)/1000 -> 188.29218 | X13: =+U13-W13 -> -103.82786 | Y13: =+[5]김해!$Q$85 -> 101000.4 | Z13: =+[5]김해!$R$85 -> 96166.498 | AA13: =+[6]김해!$Q$85 -> 98442.933 | AB13: =+[5]김해!$Q$89 -> 77024.582 | AC13: =+[5]김해!$R$89 -> 77299.138 | AD13: =+[6]김해!$Q$89 -> 78010.996 | AE13: =+Y13-AB13 -> 23975.818 | AF13: =+Z13-AC13 -> 18867.36 | AG13: =+AA13-AD13 -> 20431.937
B14: 정관 | G14: =+I14 -> 정관 | I14: 정관 | J14: =+IFERROR(HLOOKUP($B14,'[1]11월'!$D$6:$BN$259,2,),)/1000 -> 19 | K14: =+IFERROR(HLOOKUP($B14,'[2]11월'!$F$6:$CP$99,2,),)/1000 -> 18.063 | L14: =+K14-J14 -> -0.937 | M14: =+IFERROR(HLOOKUP($B14,'[3]11월'!$F$6:$CC$57,2,),)/1000 -> 22.187 | N14: =+K14-M14 -> -4.124 | O14: =+IFERROR(HLOOKUP($B14,'[1]11월'!$D$6:$BN$259,3,),)/1000 -> 1976 | P14: =+IFERROR(HLOOKUP($B14,'[2]11월'!$F$6:$CP$99,3,),)/1000 -> 1827.7784 | Q14: =+P14-O14 -> -148.22159 | R14: =+IFERROR(HLOOKUP($B14,'[3]11월'!$F$6:$CC$57,3,),)/1000 -> 2237.4768 | S14: =+P14-R14 -> -409.69839 | T14: =+IFERROR(HLOOKUP($B14,'[1]11월'!$D$6:$BN$259,16,),)/1000 -> 288.71255 | U14: =+IFERROR(HLOOKUP($B14,'[2]11월'!$F$6:$CP$99,16,),)/1000 -> 141.17147 | V14: =+U14-T14 -> -147.54108 | W14: =+IFERROR(HLOOKUP($B14,'[3]11월'!$F$6:$CC$57,16,),)/1000 -> 345.89393 | X14: =+U14-W14 -> -204.72246 | Y14: =+[5]정관!$Q$85 -> 104000 | Z14: =+[5]정관!$R$85 -> 101189.08 | AA14: =+[6]정관!$Q$85 -> 100846.3 | AB14: =+[5]정관!$Q$89 -> 79201.727 | AC14: =+[5]정관!$R$89 -> 82675.659 | AD14: =+[6]정관!$Q$89 -> 76983.404 | AE14: =+Y14-AB14 -> 24798.273 | AF14: =+Z14-AC14 -> 18513.424 | AG14: =+AA14-AD14 -> 23862.893
B15: 양산 | G15: =+I15 -> 양산 | I15: 양산 | J15: =+IFERROR(HLOOKUP($B15,'[1]11월'!$D$6:$BN$259,2,),)/1000 -> 12 | K15: =+IFERROR(HLOOKUP($B15,'[2]11월'!$F$6:$CP$99,2,),)/1000 -> 10.32 | L15: =+K15-J15 -> -1.68 | M15: =+IFERROR(HLOOKUP($B15,'[3]11월'!$F$6:$CC$57,2,),)/1000 -> 13.651 | N15: =+K15-M15 -> -3.331 | O15: =+IFERROR(HLOOKUP($B15,'[1]11월'!$D$6:$BN$259,3,),)/1000 -> 1166.5218 | P15: =+IFERROR(HLOOKUP($B15,'[2]11월'!$F$6:$CP$99,3,),)/1000 -> 1034.8856 | Q15: =+P15-O15 -> -131.63623 | R15: =+IFERROR(HLOOKUP($B15,'[3]11월'!$F$6:$CC$57,3,),)/1000 -> 1229.7334 | S15: =+P15-R15 -> -194.8478 | T15: =+IFERROR(HLOOKUP($B15,'[1]11월'!$D$6:$BN$259,16,),)/1000 -> 172.32307 | U15: =+IFERROR(HLOOKUP($B15,'[2]11월'!$F$6:$CP$99,16,),)/1000 -> 98.711031 | V15: =+U15-T15 -> -73.612036 | W15: =+IFERROR(HLOOKUP($B15,'[3]11월'!$F$6:$CC$57,16,),)/1000 -> 75.512559 | X15: =+U15-W15 -> 23.198472 | Y15: =+[5]양산!$Q$85 -> 97210.153 | Z15: =+[5]양산!$R$85 -> 100279.61 | AA15: =+[6]양산!$Q$85 -> 90083.759 | AB15: =+[5]양산!$Q$89 -> 71708.561 | AC15: =+[5]양산!$R$89 -> 76706.995 | AD15: =+[6]양산!$Q$89 -> 73954.29 | AE15: =+Y15-AB15 -> 25501.592 | AF15: =+Z15-AC15 -> 23572.618 | AG15: =+AA15-AD15 -> 16129.47
B16: 창원 | G16: =+I16 -> 창원 | I16: 창원 | J16: =+IFERROR(HLOOKUP($B16,'[1]11월'!$D$6:$BN$259,2,),)/1000 -> 16 | K16: =+IFERROR(HLOOKUP($B16,'[2]11월'!$F$6:$CP$99,2,),)/1000 -> 13.393 | L16: =+K16-J16 -> -2.607 | M16: =+IFERROR(HLOOKUP($B16,'[3]11월'!$F$6:$CC$57,2,),)/1000 -> 24.905 | N16: =+K16-M16 -> -11.512 | O16: =+IFERROR(HLOOKUP($B16,'[1]11월'!$D$6:$BN$259,3,),)/1000 -> 1628.6015 | P16: =+IFERROR(HLOOKUP($B16,'[2]11월'!$F$6:$CP$99,3,),)/1000 -> 1320.8885 | Q16: =+P16-O16 -> -307.713 | R16: =+IFERROR(HLOOKUP($B16,'[3]11월'!$F$6:$CC$57,3,),)/1000 -> 2379.7132 | S16: =+P16-R16 -> -1058.8247 | T16: =+IFERROR(HLOOKUP($B16,'[1]11월'!$D$6:$BN$259,16,),)/1000 -> 283.85298 | U16: =+IFERROR(HLOOKUP($B16,'[2]11월'!$F$6:$CP$99,16,),)/1000 -> 134.08562 | V16: =+U16-T16 -> -149.76736 | W16: =+IFERROR(HLOOKUP($B16,'[3]11월'!$F$6:$CC$57,16,),)/1000 -> 375.28587 | X16: =+U16-W16 -> -241.20025 | Y16: =+[5]창원!$Q$85 -> 101787.59 | Z16: =+[5]창원!$R$85 -> 98625.289 | AA16: =+[6]창원!$Q$85 -> 95551.624 | AB16: =+[5]창원!$Q$89 -> 72750.016 | AC16: =+[5]창원!$R$89 -> 75355.289 | AD16: =+[6]창원!$Q$89 -> 72769.45 | AE16: =+Y16-AB16 -> 29037.577 | AF16: =+Z16-AC16 -> 23270 | AG16: =+AA16-AD16 -> 22782.174
B17: 대구 | G17: =+I17 -> 대구 | I17: 대구 | J17: =+IFERROR(HLOOKUP($B17,'[1]11월'!$D$6:$BN$259,2,),)/1000 -> 16.5 | K17: =+IFERROR(HLOOKUP($B17,'[2]11월'!$F$6:$CP$99,2,),)/1000 -> 15.449 | L17: =+K17-J17 -> -1.051 | M17: =+IFERROR(HLOOKUP($B17,'[3]11월'!$F$6:$CC$57,2,),)/1000 -> 19.431 | N17: =+K17-M17 -> -3.982 | O17: =+IFERROR(HLOOKUP($B17,'[1]11월'!$D$6:$BN$259,3,),)/1000 -> 1613.04 | P17: =+IFERROR(HLOOKUP($B17,'[2]11월'!$F$6:$CP$99,3,),)/1000 -> 1485.4652 | Q17: =+P17-O17 -> -127.57475 | R17: =+IFERROR(HLOOKUP($B17,'[3]11월'!$F$6:$CC$57,3,),)/1000 -> 1786.2266 | S17: =+P17-R17 -> -300.76135 | T17: =+IFERROR(HLOOKUP($B17,'[1]11월'!$D$6:$BN$259,16,),)/1000 -> 284.59643 | U17: =+IFERROR(HLOOKUP($B17,'[2]11월'!$F$6:$CP$99,16,),)/1000 -> 166.75688 | V17: =+U17-T17 -> -117.83955 | W17: =+IFERROR(HLOOKUP($B17,'[3]11월'!$F$6:$CC$57,16,),)/1000 -> 222.08831 | X17: =+U17-W17 -> -55.331428 | Y17: =+[5]대구!$Q$85 -> 97760 | Z17: =+[5]대구!$R$85 -> 96152.842 | AA17: =+[6]대구!$Q$85 -> 91926.643 | AB17: =+[5]대구!$Q$89 -> 71060.782 | AC17: =+[5]대구!$R$89 -> 74152.653 | AD17: =+[6]대구!$Q$89 -> 71502.714 | AE17: =+Y17-AB17 -> 26699.218 | AF17: =+Z17-AC17 -> 22000.188 | AG17: =+AA17-AD17 -> 20423.929
B18: 울산 | G18: =+I18 -> 울산 | I18: 울산 | J18: =+IFERROR(HLOOKUP($B18,'[1]11월'!$D$6:$BN$259,2,),)/1000 -> 12 | K18: =+IFERROR(HLOOKUP($B18,'[2]11월'!$F$6:$CP$99,2,),)/1000 -> 12.988 | L18: =+K18-J18 -> 0.988 | M18: =+IFERROR(HLOOKUP($B18,'[3]11월'!$F$6:$CC$57,2,),)/1000 -> 5.2705 | N18: =+K18-M18 -> 7.7175 | O18: =+IFERROR(HLOOKUP($B18,'[1]11월'!$D$6:$BN$259,3,),)/1000 -> 1215.058 | P18: =+IFERROR(HLOOKUP($B18,'[2]11월'!$F$6:$CP$99,3,),)/1000 -> 1407.4653 | Q18: =+P18-O18 -> 192.4073 | R18: =+IFERROR(HLOOKUP($B18,'[3]11월'!$F$6:$CC$57,3,),)/1000 -> 526.1009 | S18: =+P18-R18 -> 881.3644 | T18: =+IFERROR(HLOOKUP($B18,'[1]11월'!$D$6:$BN$259,16,),)/1000 -> 120.14689 | U18: =+IFERROR(HLOOKUP($B18,'[2]11월'!$F$6:$CP$99,16,),)/1000 -> 169.85775 | V18: =+U18-T18 -> 49.710856 | W18: =+IFERROR(HLOOKUP($B18,'[3]11월'!$F$6:$CC$57,16,),)/1000 -> -18.246208 | X18: =+U18-W18 -> 188.10396 | Y18: =+[5]울산!$Q$85 -> 101254.83 | Z18: =+[5]울산!$R$85 -> 108366.59 | AA18: =+[6]울산!$Q$85 -> 99801.715 | AB18: =+[5]울산!$Q$89 -> 80550.789 | AC18: =+[5]울산!$R$89 -> 83931.342 | AD18: =+[6]울산!$Q$89 -> 80390.959 | AE18: =+Y18-AB18 -> 20704.045 | AF18: =+Z18-AC18 -> 24435.25 | AG18: =+AA18-AD18 -> 19410.755
B19: 아산 | G19: =+I19 -> 아산 | I19: 아산 | J19: =+IFERROR(HLOOKUP($B19,'[1]11월'!$D$6:$BN$259,2,),)/1000 -> 28 | K19: =+IFERROR(HLOOKUP($B19,'[2]11월'!$F$6:$CP$99,2,),)/1000 -> 27.751 | L19: =+K19-J19 -> -0.249 | M19: =+IFERROR(HLOOKUP($B19,'[3]11월'!$F$6:$CC$57,2,),)/1000 -> 30.918 | N19: =+K19-M19 -> -3.167 | O19: =+IFERROR(HLOOKUP($B19,'[1]11월'!$D$6:$BN$259,3,),)/1000 -> 2828.015 | P19: =+IFERROR(HLOOKUP($B19,'[2]11월'!$F$6:$CP$99,3,),)/1000 -> 2807.1351 | Q19: =+P19-O19 -> -20.879863 | R19: =+IFERROR(HLOOKUP($B19,'[3]11월'!$F$6:$CC$57,3,),)/1000 -> 2979.6452 | S19: =+P19-R19 -> -172.51006 | T19: =+IFERROR(HLOOKUP($B19,'[1]11월'!$D$6:$BN$259,16,),)/1000 -> 446.17527 | U19: =+IFERROR(HLOOKUP($B19,'[2]11월'!$F$6:$CP$99,16,),)/1000 -> 245.55114 | V19: =+U19-T19 -> -200.62413 | W19: =+IFERROR(HLOOKUP($B19,'[3]11월'!$F$6:$CC$57,16,),)/1000 -> 374.96461 | X19: =+U19-W19 -> -129.41347 | Y19: =+[5]아산!$Q$85 -> 101000.54 | Z19: =+[5]아산!$R$85 -> 100993.94 | AA19: =+[6]아산!$Q$85 -> 96250.587 | AB19: =+[5]아산!$Q$89 -> 77568.064 | AC19: =+[5]아산!$R$89 -> 82819.722 | AD19: =+[6]아산!$Q$89 -> 77247.813 | AE19: =+Y19-AB19 -> 23432.471 | AF19: =+Z19-AC19 -> 18174.222 | AG19: =+AA19-AD19 -> 19002.774
B20: 전주 | G20: =+I20 -> 전주 | I20: 전주 | J20: =+IFERROR(HLOOKUP($B20,'[1]11월'!$D$6:$BN$259,2,),)/1000 -> 12 | K20: =+IFERROR(HLOOKUP($B20,'[2]11월'!$F$6:$CP$99,2,),)/1000 -> 9.1185 | L20: =+K20-J20 -> -2.8815 | M20: =+IFERROR(HLOOKUP($B20,'[3]11월'!$F$6:$CC$57,2,),)/1000 -> 11.306 | N20: =+K20-M20 -> -2.1875 | O20: =+IFERROR(HLOOKUP($B20,'[1]11월'!$D$6:$BN$259,3,),)/1000 -> 1221.5593 | P20: =+IFERROR(HLOOKUP($B20,'[2]11월'!$F$6:$CP$99,3,),)/1000 -> 903.67658 | Q20: =+P20-O20 -> -317.88268 | R20: =+IFERROR(HLOOKUP($B20,'[3]11월'!$F$6:$CC$57,3,),)/1000 -> 968.3004 | S20: =+P20-R20 -> -64.623818 | T20: =+IFERROR(HLOOKUP($B20,'[1]11월'!$D$6:$BN$259,16,),)/1000 -> 204.11101 | U20: =+IFERROR(HLOOKUP($B20,'[2]11월'!$F$6:$CP$99,16,),)/1000 -> 64.246477 | V20: =+U20-T20 -> -139.86453 | W20: =+IFERROR(HLOOKUP($B20,'[3]11월'!$F$6:$CC$57,16,),)/1000 -> 56.852236 | X20: =+U20-W20 -> 7.394241 | Y20: =+[5]전주!$Q$85 -> 101796.6 | Z20: =+[5]전주!$R$85 -> 99117.984 | AA20: =+[6]전주!$Q$85 -> 85633.894 | AB20: =+[5]전주!$Q$89 -> 73495.475 | AC20: =+[5]전주!$R$89 -> 76865.183 | AD20: =+[6]전주!$Q$89 -> 68516.279 | AE20: =+Y20-AB20 -> 28301.13 | AF20: =+Z20-AC20 -> 22252.801 | AG20: =+AA20-AD20 -> 17117.615
B21: 군산 | G21: =+I21 -> 군산 | I21: 군산 | J21: =+IFERROR(HLOOKUP($B21,'[1]11월'!$D$6:$BN$259,2,),)/1000 -> 7 | K21: =+IFERROR(HLOOKUP($B21,'[2]11월'!$F$6:$CP$99,2,),)/1000 -> 7.147 | L21: =+K21-J21 -> 0.147 | M21: =+IFERROR(HLOOKUP($B21,'[3]11월'!$F$6:$CC$57,2,),)/1000 -> 10.1825 | N21: =+K21-M21 -> -3.0355 | O21: =+IFERROR(HLOOKUP($B21,'[1]11월'!$D$6:$BN$259,3,),)/1000 -> 762.99903 | P21: =+IFERROR(HLOOKUP($B21,'[2]11월'!$F$6:$CP$99,3,),)/1000 -> 764.9177 | Q21: =+P21-O21 -> 1.918671 | R21: =+IFERROR(HLOOKUP($B21,'[3]11월'!$F$6:$CC$57,3,),)/1000 -> 1059.8706 | S21: =+P21-R21 -> -294.95294 | T21: =+IFERROR(HLOOKUP($B21,'[1]11월'!$D$6:$BN$259,16,),)/1000 -> 193.41126 | U21: =+IFERROR(HLOOKUP($B21,'[2]11월'!$F$6:$CP$99,16,),)/1000 -> 153.19348 | V21: =+U21-T21 -> -40.217787 | W21: =+IFERROR(HLOOKUP($B21,'[3]11월'!$F$6:$CC$57,16,),)/1000 -> 286.27942 | X21: =+U21-W21 -> -133.08594 | Y21: =+[5]군산!$Q$85 -> 108999.86 | Z21: =+[5]군산!$R$85 -> 107026.4 | AA21: =+[6]군산!$Q$85 -> 104087.47 | AB21: =+[5]군산!$Q$89 -> 70884.733 | AC21: =+[5]군산!$R$89 -> 73409.949 | AD21: =+[6]군산!$Q$89 -> 68690.171 | AE21: =+Y21-AB21 -> 38115.129 | AF21: =+Z21-AC21 -> 33616.454 | AG21: =+AA21-AD21 -> 35397.297
B22: 원주 | G22: =+I22 -> 원주 | I22: 원주 | J22: =+IFERROR(HLOOKUP($B22,'[1]11월'!$D$6:$BN$259,2,),)/1000 -> 5 | K22: =+IFERROR(HLOOKUP($B22,'[2]11월'!$F$6:$CP$99,2,),)/1000 -> 4.554 | L22: =+K22-J22 -> -0.446 | M22: =+IFERROR(HLOOKUP($B22,'[3]11월'!$F$6:$CC$57,2,),)/1000 -> 5.9845 | N22: =+K22-M22 -> -1.4305 | O22: =+IFERROR(HLOOKUP($B22,'[1]11월'!$D$6:$BN$259,3,),)/1000 -> 539.5 | P22: =+IFERROR(HLOOKUP($B22,'[2]11월'!$F$6:$CP$99,3,),)/1000 -> 521.4149 | Q22: =+P22-O22 -> -18.0851 | R22: =+IFERROR(HLOOKUP($B22,'[3]11월'!$F$6:$CC$57,3,),)/1000 -> 615.8714 | S22: =+P22-R22 -> -94.4565 | T22: =+IFERROR(HLOOKUP($B22,'[1]11월'!$D$6:$BN$259,16,),)/1000 -> 96.951877 | U22: =+IFERROR(HLOOKUP($B22,'[2]11월'!$F$6:$CP$99,16,),)/1000 -> 96.375569 | V22: =+U22-T22 -> -0.57630801 | W22: =+IFERROR(HLOOKUP($B22,'[3]11월'!$F$6:$CC$57,16,),)/1000 -> 84.897067 | X22: =+U22-W22 -> 11.478502 | Y22: =+[5]원주!$Q$85 -> 107900 | Z22: =+[5]원주!$R$85 -> 114496.03 | AA22: =+[6]원주!$Q$85 -> 103024.56 | AB22: =+[5]원주!$Q$89 -> 73124.293 | AC22: =+[5]원주!$R$89 -> 74946.434 | AD22: =+[6]원주!$Q$89 -> 74178.192 | AE22: =+Y22-AB22 -> 34775.707 | AF22: =+Z22-AC22 -> 39549.592 | AG22: =+AA22-AD22 -> 28846.372
B23: 제주 | G23: =+I23 -> 제주 | I23: 제주 | J23: =+IFERROR(HLOOKUP($B23,'[1]11월'!$D$6:$BN$259,2,),)/1000 -> 7 | K23: =+IFERROR(HLOOKUP($B23,'[2]11월'!$F$6:$CP$99,2,),)/1000 -> 2.901 | L23: =+K23-J23 -> -4.099 | M23: =+IFERROR(HLOOKUP($B23,'[3]11월'!$F$6:$CC$57,2,),)/1000 -> 6.3775 | N23: =+K23-M23 -> -3.4765 | O23: =+IFERROR(HLOOKUP($B23,'[1]11월'!$D$6:$BN$259,3,),)/1000 -> 887.6 | P23: =+IFERROR(HLOOKUP($B23,'[2]11월'!$F$6:$CP$99,3,),)/1000 -> 350.95144 | Q23: =+P23-O23 -> -536.64856 | R23: =+IFERROR(HLOOKUP($B23,'[3]11월'!$F$6:$CC$57,3,),)/1000 -> 774.95708 | S23: =+P23-R23 -> -424.00565 | T23: =+IFERROR(HLOOKUP($B23,'[1]11월'!$D$6:$BN$259,16,),)/1000 -> 165.25927 | U23: =+IFERROR(HLOOKUP($B23,'[2]11월'!$F$6:$CP$99,16,),)/1000 -> -11.658004 | V23: =+U23-T23 -> -176.91727 | W23: =+IFERROR(HLOOKUP($B23,'[3]11월'!$F$6:$CC$57,16,),)/1000 -> 118.1963 | X23: =+U23-W23 -> -129.85431 | Y23: =+[5]제주!$Q$85 -> 126800 | Z23: =+[5]제주!$R$85 -> 120976.02 | AA23: =+[6]제주!$Q$85 -> 121552.08 | AB23: =+[5]제주!$Q$89 -> 91213.272 | AC23: =+[5]제주!$R$89 -> 91677.915 | AD23: =+[6]제주!$Q$89 -> 87747.614 | AE23: =+Y23-AB23 -> 35586.728 | AF23: =+Z23-AC23 -> 29298.106 | AG23: =+AA23-AD23 -> 33804.464
G24: =+I24 -> 수도권 | I24: 수도권 | J24: =SUM(J7:J10) -> 121.5 | K24: =SUM(K7:K10) -> 107.646 | L24: =+K24-J24 -> -13.854 | M24: =SUM(M7:M10) -> 139.27168 | N24: =+K24-M24 -> -31.62568 | O24: =SUM(O7:O10) -> 12416.803 | P24: =SUM(P7:P10) -> 10479.18 | Q24: =+P24-O24 -> -1937.6227 | R24: =SUM(R7:R10) -> 13147.692 | S24: =+P24-R24 -> -2668.5115 | T24: =SUM(T7:T10) -> 1856.0099 | U24: =SUM(U7:U10) -> 553.11277 | V24: =+U24-T24 -> -1302.8971 | W24: =SUM(W7:W10) -> 900.72377 | X24: =+U24-W24 -> -347.611 | Y24: =+[5]수도권!$Q$85 -> 102195.91 | Z24: =+[5]수도권!$R$85 -> 97363.141 | AA24: =+[6]수도권!$Q$85 -> 94344.989 | AB24: =+[5]수도권!$Q$89 -> 79198.011 | AC24: =+[5]수도권!$R$89 -> 83203.071 | AD24: =+[6]수도권!$Q$89 -> 80822.746 | AE24: =+Y24-AB24 -> 22997.9 | AF24: =+Z24-AC24 -> 14160.07 | AG24: =+AA24-AD24 -> 13522.243
G25: =+I25 -> 영남권 | I25: 영남권 | J25: =SUM(J11:J18) -> 139.5 | K25: =SUM(K11:K18) -> 121.551 | L25: =+K25-J25 -> -17.949 | M25: =SUM(M11:M18) -> 155.159 | N25: =+K25-M25 -> -33.608 | O25: =SUM(O11:O18) -> 14314.627 | P25: =SUM(P11:P18) -> 12242.393 | Q25: =+P25-O25 -> -2072.2336 | R25: =SUM(R11:R18) -> 15081.412 | S25: =+P25-R25 -> -2839.0187 | T25: =SUM(T11:T18) -> 2301.2994 | U25: =SUM(U11:U18) -> 1095.102 | V25: =+U25-T25 -> -1206.1974 | W25: =SUM(W11:W18) -> 1920.96 | X25: =+U25-W25 -> -825.85803 | Y25: =+[5]영남권!$Q$85 -> 102613.81 | Z25: =+[5]영남권!$R$85 -> 100718.16 | AA25: =+[6]영남권!$Q$85 -> 97198.734 | AB25: =+[5]영남권!$Q$89 -> 76154.162 | AC25: =+[5]영남권!$R$89 -> 79490.263 | AD25: =+[6]영남권!$Q$89 -> 75561.134 | AE25: =+Y25-AB25 -> 26459.648 | AF25: =+Z25-AC25 -> 21227.896 | AG25: =+AA25-AD25 -> 21637.6
G26: =+I26 -> 중부권 | I26: 중부권 | J26: =SUM(J19:J23) -> 59 | K26: =SUM(K19:K23) -> 51.4715 | L26: =+K26-J26 -> -7.5285 | M26: =SUM(M19:M23) -> 64.7685 | N26: =+K26-M26 -> -13.297 | O26: =SUM(O19:O23) -> 6239.6733 | P26: =SUM(P19:P23) -> 5348.0958 | Q26: =+P26-O26 -> -891.57753 | R26: =SUM(R19:R23) -> 6398.6447 | S26: =+P26-R26 -> -1050.549 | T26: =SUM(T19:T23) -> 1105.9087 | U26: =SUM(U19:U23) -> 547.70866 | V26: =+U26-T26 -> -558.20003 | W26: =SUM(W19:W23) -> 921.18964 | X26: =+U26-W26 -> -373.48098 | Y26: =+[5]중부권!$Q$85 -> 105757.17 | Z26: =+[5]중부권!$R$85 -> 103847.09 | AA26: =+[6]중부권!$Q$85 -> 98678.013 | AB26: =+[5]중부권!$Q$89 -> 77189.135 | AC26: =+[5]중부권!$R$89 -> 80246.621 | AD26: =+[6]중부권!$Q$89 -> 75088.296 | AE26: =+Y26-AB26 -> 28568.039 | AF26: =+Z26-AC26 -> 23600.464 | AG26: =+AA26-AD26 -> 23589.717
G27: =+K27/J27 -> 0.87708906 | H27: 레미콘 계 | J27: =SUM(J24:J26) -> 320 | K27: =SUM(K24:K26) -> 280.6685 | L27: =+K27-J27 -> -39.3315 | M27: =SUM(M24:M26) -> 359.19918 | N27: =+K27-M27 -> -78.53068 | O27: =SUM(O24:O26) -> 32971.103 | P27: =SUM(P24:P26) -> 28069.669 | Q27: =+P27-O27 -> -4901.4338 | R27: =SUM(R24:R26) -> 34627.748 | S27: =+P27-R27 -> -6558.0792 | T27: =SUM(T24:T26) -> 5263.218 | U27: =SUM(U24:U26) -> 2195.9234 | V27: =+U27-T27 -> -3067.2946 | W27: =SUM(W24:W26) -> 3742.8734 | X27: =+U27-W27 -> -1546.95 | Y27: =+[5]합계!$Q$85 -> 103034.7 | Z27: =+[5]합계!$R$85 -> 100000.5 | AA27: =+[6]합계!$Q$85 -> 96359.434 | AB27: =+[5]합계!$Q$89 -> 77500.697 | AC27: =+[5]합계!$R$89 -> 81042.566 | AD27: =+[6]합계!$Q$89 -> 77511.639 | AE27: =+Y27-AB27 -> 25534 | AF27: =+Z27-AC27 -> 18957.932 | AG27: =+AA27-AD27 -> 18847.795
B28: 건자재 | E28: 건자재영업 | G28: 건자재 | H28: 건자재 | J28: =+IFERROR(HLOOKUP($B28,'[1]11월'!$D$6:$BN$259,2,),) -> 9200 | K28: =+IFERROR(HLOOKUP($E28,'[2]11월'!$F$6:$CP$99,2,),) -> 10221.802 | L28: =+K28-J28 -> 1021.802 | M28: =+IFERROR(HLOOKUP($E28,'[3]11월'!$F$6:$CC$57,2,),) -> 10109.273 | N28: =+K28-M28 -> 112.529 | O28: =+IFERROR(HLOOKUP($B28,'[1]11월'!$D$6:$BN$259,3,),)/1000 -> 11242.202 | P28: =+IFERROR(HLOOKUP($E28,'[2]11월'!$F$6:$CP$99,3,),)/1000 -> 9942.869 | Q28: =+P28-O28 -> -1299.3331 | R28: =+IFERROR(HLOOKUP($E28,'[3]11월'!$F$6:$CC$57,3,),)/1000 -> 12404.88 | S28: =+P28-R28 -> -2462.0112 | T28: =+IFERROR(HLOOKUP($B28,'[1]11월'!$D$6:$BN$259,16,),)/1000 -> 165.73533 | U28: =+IFERROR(HLOOKUP($E28,'[2]11월'!$F$6:$CP$99,16,),)/1000 -> 118.35665 | V28: =+U28-T28 -> -47.37868 | W28: =+IFERROR(HLOOKUP($E28,'[3]11월'!$F$6:$CC$57,16,),)/1000 -> 98.190129 | X28: =+U28-W28 -> 20.16652 | Y28: ■ 비고
B29: 부산모래장 | C29: 부산골재 | G29: =+I29 -> 부산모래장 | H29: 골재 | I29: 부산모래장 | J29: =+IFERROR(HLOOKUP($B29,'[1]11월'!$D$6:$BN$259,2,),)/1000 -> 29.768648 | K29: =+IFERROR(HLOOKUP($C29,'[2]11월'!$F$6:$CP$99,2,),)/1000 -> 25.492 | L29: =+K29-J29 -> -4.2766484 | M29: =+IFERROR(HLOOKUP($C29,'[3]11월'!$F$6:$CC$57,2,),)/1000 -> 31.346 | N29: =+K29-M29 -> -5.854 | O29: =+IFERROR(HLOOKUP($B29,'[1]11월'!$D$6:$BN$259,3,),)/1000 -> 846.36177 | P29: =+IFERROR(HLOOKUP($C29,'[2]11월'!$F$6:$CP$99,3,),)/1000 -> 701.3415 | Q29: =+P29-O29 -> -145.02027 | R29: =+IFERROR(HLOOKUP($C29,'[3]11월'!$F$6:$CC$57,3,),)/1000 -> 893.3245 | S29: =+P29-R29 -> -191.983 | T29: =+IFERROR(HLOOKUP($B29,'[1]11월'!$D$6:$BN$259,21,),)/1000 -> 68.431451 | U29: =+IFERROR(HLOOKUP($C29,'[2]11월'!$F$6:$CP$99,21,),)/1000 -> 1.8739536 | V29: =+U29-T29 -> -66.557497 | W29: =+IFERROR(HLOOKUP($C29,'[3]11월'!$F$6:$CC$57,16,),)/1000 -> 56.281423 | X29: =+U29-W29 -> -54.407469 | Y29: - 1군단가 소급분 : 233백만원
B30: 서부산크라샤 | C30: 서부산골재 | G30: =+I30 -> 서부산CR | I30: 서부산CR | J30: =+IFERROR(HLOOKUP($B30,'[1]11월'!$D$6:$BN$259,2,),)/1000 -> 51.375563 | K30: =+IFERROR(HLOOKUP($C30,'[2]11월'!$F$6:$CP$99,2,),)/1000 -> 1.202 | L30: =+K30-J30 -> -50.173563 | M30: =+IFERROR(HLOOKUP($C30,'[3]11월'!$F$6:$CC$57,2,),)/1000 -> 37.866 | N30: =+K30-M30 -> -36.664 | O30: =+IFERROR(HLOOKUP($B30,'[1]11월'!$D$6:$BN$259,3,),)/1000 -> 637.61412 | P30: =+IFERROR(HLOOKUP($C30,'[2]11월'!$F$6:$CP$99,3,),)/1000 -> 14.424 | Q30: =+P30-O30 -> -623.19012 | R30: =+IFERROR(HLOOKUP($C30,'[3]11월'!$F$6:$CC$57,3,),)/1000 -> 482.524 | S30: =+P30-R30 -> -468.1 | T30: =+IFERROR(HLOOKUP($B30,'[1]11월'!$D$6:$BN$259,21,),)/1000 -> 118.26266 | U30: =+IFERROR(HLOOKUP($C30,'[2]11월'!$F$6:$CP$99,21,),)/1000 -> -70.358755 | V30: =+U30-T30 -> -188.62142 | W30: =+IFERROR(HLOOKUP($C30,'[3]11월'!$F$6:$CC$57,16,),)/1000 -> 86.54813 | X30: =+U30-W30 -> -156.90688 | Y30: (두산건설 117백만원, 롯데건설 113백만원, 계룡건설산업 1.7백만원, 동아건설산업 0.6백만원)
B31: 부산크라샤 | C31: 부산크라샤 | G31: =+I31 -> 부산CR | I31: 부산CR | J31: =+IFERROR(HLOOKUP($B31,'[1]11월'!$D$6:$BN$259,2,),)/1000 -> 43.490335 | K31: =+IFERROR(HLOOKUP($C31,'[2]11월'!$F$6:$CP$99,2,),)/1000 -> 39.432 | L31: =+K31-J31 -> -4.0583354 | M31: =+IFERROR(HLOOKUP($C31,'[3]11월'!$F$6:$CC$57,2,),)/1000 -> 36.262 | N31: =+K31-M31 -> 3.17 | O31: =+IFERROR(HLOOKUP($B31,'[1]11월'!$D$6:$BN$259,3,),)/1000 -> 789.09505 | P31: =+IFERROR(HLOOKUP($C31,'[2]11월'!$F$6:$CP$99,3,),)/1000 -> 698.26 | Q31: =+P31-O31 -> -90.83505 | R31: =+IFERROR(HLOOKUP($C31,'[3]11월'!$F$6:$CC$57,3,),)/1000 -> 638.882 | S31: =+P31-R31 -> 59.378 | T31: =+IFERROR(HLOOKUP($B31,'[1]11월'!$D$6:$BN$259,21,),)/1000 -> 72.555884 | U31: =+IFERROR(HLOOKUP($C31,'[2]11월'!$F$6:$CP$99,21,),)/1000 -> -221.62408 | V31: =+U31-T31 -> -294.17997 | W31: =+IFERROR(HLOOKUP($C31,'[3]11월'!$F$6:$CC$57,16,),)/1000 -> -14.856121 | X31: =+U31-W31 -> -206.76796
H32: 골재 계 | J32: =SUM(J29:J31) -> 124.63455 | K32: =SUM(K29:K31) -> 66.126 | L32: =+K32-J32 -> -58.508547 | M32: =SUM(M29:M31) -> 105.474 | N32: =+K32-M32 -> -39.348 | O32: =SUM(O29:O31) -> 2273.0709 | P32: =SUM(P29:P31) -> 1414.0255 | Q32: =+P32-O32 -> -859.04544 | R32: =SUM(R29:R31) -> 2014.7305 | S32: =+P32-R32 -> -600.705 | T32: =SUM(T29:T31) -> 259.25 | U32: =SUM(U29:U31) -> -290.10889 | V32: =+U32-T32 -> -549.35889 | W32: =SUM(W29:W31) -> 127.97343 | X32: =+U32-W32 -> -418.08232 | Y32: ▶ 운반비 소급
B33: 포항임대 | C33: 속초임대 | D33: 강릉임대 | E33: 레미콘임대 계 | G33: =+I33 -> 레미콘임대 | H33: 기타 | I33: 레미콘임대 | L33: =+K33-J33 -> 0 | N33: =+K33-M33 -> 0 | O33: =(IFERROR(HLOOKUP($B33,'[1]11월'!$D$6:$BN$259,3,),)++IFERROR(HLOOKUP($C33,'[1]11월'!$D$6:$BN$259,3,),)+IFERROR(HLOOKUP($D33,'[1]11월'!$D$6:$BN$259,3,),))/1000 -> 90.84 | P33: =+IFERROR(HLOOKUP($E33,'[2]11월'!$F$6:$CP$99,3,),)/1000 -> 90.84 | Q33: =+P33-O33 -> 0 | R33: =+IFERROR(HLOOKUP($E33,'[3]11월'!$F$6:$CC$57,3,),)/1000 -> 90.84 | S33: =+P33-R33 -> 0 | T33: =(IFERROR(HLOOKUP($B33,'[1]11월'!$D$6:$BN$259,21,),)++IFERROR(HLOOKUP($C33,'[1]11월'!$D$6:$BN$259,21,),)+IFERROR(HLOOKUP($D33,'[1]11월'!$D$6:$BN$259,21,),))/1000 -> 72.210526 | U33: =+IFERROR(HLOOKUP($E33,'[2]11월'!$F$6:$CP$99,16,),)/1000 -> 67.392238 | V33: =+U33-T33 -> -4.818288 | W33: =+IFERROR(HLOOKUP($E33,'[3]11월'!$F$6:$CC$57,16,),)/1000 -> 71.822105 | X33: =+U33-W33 -> -4.429867 | Y33: - 인천 : 6,598만원
B34: 부동산임대 | C34: 주유소임대 | E34: 임대 계 | G34: =+I34 -> 임대 | I34: 임대 | L34: =+K34-J34 -> 0 | M34: 0 | N34: =+K34-M34 -> 0 | O34: =(+IFERROR(HLOOKUP($B34,'[1]11월'!$D$6:$BN$259,3,),)+IFERROR(HLOOKUP($C34,'[1]11월'!$D$6:$BN$259,3,),))/1000 -> 72.2975 | P34: =+IFERROR(HLOOKUP($E34,'[2]11월'!$F$6:$CP$99,3,),)/1000 -> 72.663968 | Q34: =+P34-O34 -> 0.36646767 | R34: =+IFERROR(HLOOKUP($E34,'[3]11월'!$F$6:$CC$57,3,),)/1000 -> 93.741319 | S34: =+P34-R34 -> -21.077351 | T34: =(+IFERROR(HLOOKUP($B34,'[1]11월'!$D$6:$BN$259,21,),)+IFERROR(HLOOKUP($C34,'[1]11월'!$D$6:$BN$259,21,),))/1000 -> 62.045457 | U34: =+IFERROR(HLOOKUP($E34,'[2]11월'!$F$6:$CP$99,16,),)/1000 -> 58.662833 | V34: =+U34-T34 -> -3.3826243 | W34: =+IFERROR(HLOOKUP($E34,'[3]11월'!$F$6:$CC$57,16,),)/1000 -> 56.694342 | X34: =+U34-W34 -> 1.968491 | Y34: - 김포 : 2,914만원
B35: 공 통 비 | G35: =+I35 -> 공통비 | I35: 공통비 | L35: =+K35-J35 -> 0 | N35: =+K35-M35 -> 0 | Q35: =+P35-O35 -> 0 | S35: =+P35-R35 -> 0 | T35: =-'[1]11월'!$Z$22/1000 -> -1173.9158 | U35: =+-'[2]11월'!$Z$22/1000 -> -1265.4311 | V35: =+U35-T35 -> -91.515309 | W35: =+-'[3]11월'!$Z$22/1000 -> -1202.3067 | X35: =+U35-W35 -> -63.124355
G36: =+I36 -> OPC 소급분 | I36: OPC 소급분 | N36: =+K36-M36 -> 0 | Q36: =+P36-O36 -> 0 | S36: =+P36-R36 -> 0 | T36: =+'[1]11월'!$AS$26/1000 -> 0 | U36: ='[2]11월'!$BD$26/1000 -> 241.78824 | V36: =+U36-T36 -> 241.78824 | W36: =-'[3]11월'!$BD$26/1000 -> 0 | X36: =+U36-W36 -> 241.78824
G37: =+I37 -> 대손 | I37: 대손 | N37: =+K37-M37 -> 0 | Q37: =+P37-O37 -> 0 | S37: =+P37-R37 -> 0 | U37: ='[2]11월'!$BE$26/1000 -> 0 | V37: =+U37-T37 -> 0 | W37: ='[3]11월'!$BE$26/1000 -> 0 | X37: =+U37-W37 -> 0
G38: =+I38 -> 미운영 공장 | I38: 미운영 공장 | M38: =SUM(M54:M59) -> 0 | N38: =+K38-M38 -> 0 | Q38: =+P38-O38 -> 0 | R38: =+IFERROR(HLOOKUP($I$38,'[3]11월'!$F$6:$BJ$50,3,),)/1000 -> 0 | S38: =+P38-R38 -> 0 | T38: =SUM('[1]11월'!$AM$26:$AQ$26)/1000 -> -35.713225 | U38: =+'[2]11월'!$BF$26/1000 -> -32.976668 | V38: =+U38-T38 -> 2.7365574 | W38: =+'[3]11월'!$BF$26/1000 -> -9.302589 | X38: =+U38-W38 -> -23.674079
B39: 기타 계 | G39: =+I39 -> 기타 | I39: 기타 | L39: =+K39-J39 -> 0 | N39: =+K39-M39 -> 0 | O39: =IFERROR(HLOOKUP($B39,'[1]11월'!$D$6:$BN$259,3,),)/1000 -> 1.77 | P39: =+('[2]11월'!$F$8-SUM('[2]11월'!$Z$8,'[2]11월'!$AH$8,'[2]11월'!$AN$8,'[2]11월'!$AO$8,'[2]11월'!$BA$8,'[2]11월'!$BD$8,'[2]11월'!$BE$8,'[2]11월'!$BF$8))/1000 -> 1.8206 | Q39: =+P39-O39 -> 0.0506 | R39: =+('[3]11월'!$F$8-SUM('[3]11월'!$Z$8,'[3]11월'!$AH$8,'[3]11월'!$AN$8,'[3]11월'!$AO$8,'[3]11월'!$BA$8,'[3]11월'!$BD$8,'[3]11월'!$BE$8,'[3]11월'!$BF$8))/1000 -> 1.7741 | S39: =+P39-R39 -> 0.0465 | T39: =+('[1]11월'!$E$26-'[1]11월'!$Z$26-'[1]11월'!$AA$26-'[1]11월'!$AE$26-'[1]11월'!$AL$26-'[1]11월'!$AM$26-'[1]11월'!$AN$26-'[1]11월'!$AO$26-'[1]11월'!$AP$26-'[1]11월'!$AQ$26-'[1]11월'!$AS$26)/1000 -> -79.281808 | U39: =+('[2]11월'!$F$26-SUM('[2]11월'!$Z$26,'[2]11월'!$AH$26,'[2]11월'!$AN$26,'[2]11월'!$AO$26,'[2]11월'!$BA$26,'[2]11월'!$BD$26,'[2]11월'!$BE$26,'[2]11월'!$BF$26))/1000 -> -16.745684 | V39: =+U39-T39 -> 62.536124 | W39: =+('[3]11월'!$F$26-SUM('[3]11월'!$Z$26,'[3]11월'!$AH$26,'[3]11월'!$AN$26,'[3]11월'!$AO$26,'[3]11월'!$BA$26,'[3]11월'!$BD$26,'[3]11월'!$BE$26,'[3]11월'!$BF$26))/1000 -> -16.698095 | X39: =+U39-W39 -> -0.047589
N40: =+K40-M40 -> 0 | Q40: =+P40-O40 -> 0 | S40: =+P40-R40 -> 0 | V40: =+U40-T40 -> 0
H41: 기타 계 | J41: =SUM(J33:J40) -> 0 | K41: =SUM(K33:K40) -> 0 | L41: =+K41-J41 -> 0 | M41: =SUM(M33:M40) -> 0 | N41: =+K41-M41 -> 0 | O41: =SUM(O33:O40) -> 164.9075 | P41: =SUM(P33:P40) -> 165.32457 | Q41: =+P41-O41 -> 0.41706767 | R41: =SUM(R33:R40) -> 186.35542 | S41: =+P41-R41 -> -21.030851 | T41: =SUM(T33:T40) -> -1154.6548 | U41: =SUM(U33:U40) -> -947.31013 | V41: =+U41-T41 -> 207.3447 | W41: =SUM(W33:W40) -> -1099.791 | X41: =+U41-W41 -> 152.48084
U42: 19 | V42: 12.4
...

Sheet 사업장별(누계)
H3: □ 사업장별 손익실적(2024-11누계)
AG4: [단위 : 천㎥, 톤, 백만원]
H5: 구분 | J5: 물량 | O5: 매출 | T5: 영업이익(공통비 배부전) | Y5: 판매단가 | AB5: 변동비 | AE5: 공헌이익
A6: 2024년 11월 마감 손익 | J6: 계획 | K6: 실적 | L6: 차이 | M6: 전년 | N6: 차이 | O6: 계획 | P6: 실적 | Q6: 차이 | R6: 전년 | S6: 차이 | T6: 계획 | U6: 실적 | V6: 차이 | W6: 전년 | X6: 차이 | Y6: 계획 | Z6: 실적 | AA6: 전년 | AB6: 계획 | AC6: 실적 | AD6: 전년 | AE6: 계획 | AF6: 실적 | AG6: 전년
B7: 안양 | F7: =+U7/T7 -> 0.59504132 | G7: =+K7/J7 -> 0.90008079 | H7: 레미콘 | I7: 안양 | J7: =+'사업장별(당월)'!J7+'[4]사업장별(누계)'!J7 -> 458 | K7: =+'사업장별(당월)'!K7+'[4]사업장별(누계)'!K7 -> 412.237 | L7: =+K7-J7 -> -45.763 | M7: =+'사업장별(당월)'!M7+'[4]사업장별(누계)'!M7 -> 503.729 | N7: =+K7-M7 -> -91.492 | O7: =+'사업장별(당월)'!O7+'[4]사업장별(누계)'!O7 -> 45972.704 | P7: =+'사업장별(당월)'!P7+'[4]사업장별(누계)'!P7 -> 40826.39 | Q7: =+P7-O7 -> -5146.3146 | R7: =+'사업장별(당월)'!R7+'[4]사업장별(누계)'!R7 -> 46803.178 | S7: =+P7-R7 -> -5976.788 | T7: =+'사업장별(당월)'!T7+'[4]사업장별(누계)'!T7 -> 6381.786 | U7: =+'사업장별(당월)'!U7+'[4]사업장별(누계)'!U7 -> 3797.4263 | V7: =+U7-T7 -> -2584.3596 | W7: =+'사업장별(당월)'!W7+'[4]사업장별(누계)'!W7 -> 6517.3077 | X7: =+U7-W7 -> -2719.8814 | Y7: =+[11]안양!$Q$85 -> 100377.08 | Z7: =+[11]안양!$R$85 -> 99032.751 | AA7: =+[12]안양!$Q$85 -> 92889.087 | AB7: =+[11]안양!$Q$89 -> 79110.734 | AC7: =+[11]안양!$R$89 -> 81711.511 | AD7: =+[12]안양!$Q$89 -> 73537.47 | AE7: =+Y7-AB7 -> 21266.35 | AF7: =+Z7-AC7 -> 17321.24 | AG7: =+AA7-AD7 -> 19351.617 | AI7: =+U7/T7-1 -> -0.40495868 | AJ7: =+U7/T7 -> 0.59504132 | AK7: =+Z7-Y7 -> -1344.3321 | AL7: =+AC7-AB7 -> 2600.7773 | AM7: =+AF7-AE7 -> -3945.1095
B8: 인천 | F8: =+U8/T8 -> 0.42385025 | G8: =+K8/J8 -> 0.86215698 | H8: 직영 | I8: 인천 | J8: =+'사업장별(당월)'!J8+'[4]사업장별(누계)'!J8 -> 344 | K8: =+'사업장별(당월)'!K8+'[4]사업장별(누계)'!K8 -> 296.582 | L8: =+K8-J8 -> -47.418 | M8: =+'사업장별(당월)'!M8+'[4]사업장별(누계)'!M8 -> 410.205 | N8: =+K8-M8 -> -113.623 | O8: =+'사업장별(당월)'!O8+'[4]사업장별(누계)'!O8 -> 35293.239 | P8: =+'사업장별(당월)'!P8+'[4]사업장별(누계)'!P8 -> 29518.041 | Q8: =+P8-O8 -> -5775.198 | R8: =+'사업장별(당월)'!R8+'[4]사업장별(누계)'!R8 -> 39438.592 | S8: =+P8-R8 -> -9920.5503 | T8: =+'사업장별(당월)'!T8+'[4]사업장별(누계)'!T8 -> 4092.7151 | U8: =+'사업장별(당월)'!U8+'[4]사업장별(누계)'!U8 -> 1734.6983 | V8: =+U8-T8 -> -2358.0167 | W8: =+'사업장별(당월)'!W8+'[4]사업장별(누계)'!W8 -> 4666.1956 | X8: =+U8-W8 -> -2931.4973 | Y8: =+[11]인천!$Q$85 -> 102596.63 | Z8: =+[11]인천!$R$85 -> 99531.02 | AA8: =+[12]인천!$Q$85 -> 96118.628 | AB8: =+[11]인천!$Q$89 -> 81209.33 | AC8: =+[11]인천!$R$89 -> 82712.025 | AD8: =+[12]인천!$Q$89 -> 76710.002 | AE8: =+Y8-AB8 -> 21387.296 | AF8: =+Z8-AC8 -> 16818.996 | AG8: =+AA8-AD8 -> 19408.626 | AI8: =+U8/T8-1 -> -0.57614975 | AK8: =+Z8-Y8 -> -3065.6052 | AL8: =+AC8-AB8 -> 1502.6948 | AM8: =+AF8-AE8 -> -4568.3001
B9: 파주 | F9: =+U9/T9 -> 0.49994163 | G9: =+K9/J9 -> 0.99272015 | I9: 파주 | J9: =+'사업장별(당월)'!J9+'[4]사업장별(누계)'!J9 -> 268 | K9: =+'사업장별(당월)'!K9+'[4]사업장별(누계)'!K9 -> 266.049 | L9: =+K9-J9 -> -1.951 | M9: =+'사업장별(당월)'!M9+'[4]사업장별(누계)'!M9 -> 295.711 | N9: =+K9-M9 -> -29.662 | O9: =+'사업장별(당월)'!O9+'[4]사업장별(누계)'!O9 -> 26497.579 | P9: =+'사업장별(당월)'!P9+'[4]사업장별(누계)'!P9 -> 25690.117 | Q9: =+P9-O9 -> -807.46195 | R9: =+'사업장별(당월)'!R9+'[4]사업장별(누계)'!R9 -> 27580.717 | S9: =+P9-R9 -> -1890.6006 | T9: =+'사업장별(당월)'!T9+'[4]사업장별(누계)'!T9 -> 3547.5969 | U9: =+'사업장별(당월)'!U9+'[4]사업장별(누계)'!U9 -> 1773.5914 | V9: =+U9-T9 -> -1774.0055 | W9: =+'사업장별(당월)'!W9+'[4]사업장별(누계)'!W9 -> 2875.4888 | X9: =+U9-W9 -> -1101.8975 | Y9: =+[11]파주!$Q$85 -> 98871.563 | Z9: =+[11]파주!$R$85 -> 96569.207 | AA9: =+[12]파주!$Q$85 -> 93243.275 | AB9: =+[11]파주!$Q$89 -> 76546.537 | AC9: =+[11]파주!$R$89 -> 80413.641 | AD9: =+[12]파주!$Q$89 -> 75251.334 | AE9: =+Y9-AB9 -> 22325.025 | AF9: =+Z9-AC9 -> 16155.566 | AG9: =+AA9-AD9 -> 17991.94 | AI9: =+U9/T9-1 -> -0.50005837 | AK9: =+Z9-Y9 -> -2302.3557 | AL9: =+AC9-AB9 -> 3867.1032 | AM9: =+AF9-AE9 -> -6169.4589
