Workbook

Sheet 표지
A6: 2024년 3월 마감 손익
A24: 건재사업본부

Sheet 손익총괄
C3: □ 건재사업본부 손익실적(2024-03) | Z3: □ 건재부문 실적(3월)
X4: [단위 : 천㎥, 톤, 원/㎥, 원/톤, 백만원] | AK4: (단위 : 천㎥, 천톤, 억원)
C5: 구분 | E5: 3월 | J5: 3월 누계 | P5: 3월 주요지표 | Z5: 구분 | AB5: =+E5 -> 3월 | AG5: =+J5 -> 3월 누계
E6: 계획 | F6: 실적 | G6: 계획대비 | H6: 전년 | I6: 전년대비 | J6: 계획 | K6: 실적 | L6: 계획대비 | M6: 전년 | N6: 전년대비 | AB6: =+E6 -> 계획 | AC6: =+F6 -> 실적 | AD6: =+G6 -> 계획대비 | AE6: =+H6 -> 전년 | AF6: =+I6 -> 전년대비 | AG6: =+J6 -> 계획 | AH6: =+K6 -> 실적 | AI6: =+L6 -> 계획대비 | ... AK6: =+N6 -> 전년대비
C7: 물량 | D7: 레미콘 | E7: =+'[1]3월'!$Z$7/1000 -> 286 | F7: =+'[2]3월'!$Z$7/1000 -> 298.4865 | G7: =+F7-E7 -> 12.4865 | H7: =+'[3]3월'!$Z$7/1000 -> 364.2905 | I7: =+F7-H7 -> -65.804 | J7: =+[4]손익총괄!J7+E7 -> 756 | K7: =+[4]손익총괄!K7+F7 -> 794.9285 | L7: =+K7-J7 -> 38.9285 | M7: =+[4]손익총괄!M7+H7 -> 956.873 | N7: =+K7-M7 -> -161.9445 | Q7: □ 레미콘 | Z7: 물량 | AA7: =+D7 -> 레미콘 | AB7: =+E7 -> 286 | AC7: =+F7 -> 298.4865 | AD7: =+AC7-AB7 -> 12.4865 | AE7: =+H7 -> 364.2905 | AF7: =+AC7-AE7 -> -65.804 | AG7: =+J7 -> 756 | AH7: =+K7 -> 794.9285 | AI7: =+AH7-AG7 -> 38.9285 | AJ7: =+M7 -> 956.873 | AK7: =+AH7-AJ7 -> -161.9445
D8: 철강재 | E8: =+'[1]3월'!$AA$7 -> 7300 | F8: =+'[2]3월'!$AO$7 -> 8665.068 | G8: =+F8-E8 -> 1365.068 | H8: =+'[3]3월'!$AO$7 -> 9838.578 | I8: =+F8-H8 -> -1173.51 | J8: =+[4]손익총괄!J8+E8 -> 20600 | K8: =+[4]손익총괄!K8+F8 -> 21735.563 | L8: =+K8-J8 -> 1135.563 | M8: =+[4]손익총괄!M8+H8 -> 25167.705 | N8: =+K8-M8 -> -3432.142 | Q8: 구분 | S8: 계획 | T8: 실적 | U8: 계획대비 | V8: 전년 | W8: 전년대비 | AA8: =+D8 -> 철강재 | AB8: =+E8/1000 -> 7.3 | AC8: =+F8/1000 -> 8.665068 | AD8: =+AC8-AB8 -> 1.365068 | AE8: =+H8/1000 -> 9.838578 | AF8: =+AC8-AE8 -> -1.17351 | AG8: =+J8/1000 -> 20.6 | AH8: =+K8/1000 -> 21.735563 | AI8: =+AH8-AG8 -> 1.135563 | AJ8: =+M8/1000 -> 25.167705 | AK8: =+AH8-AJ8 -> -3.432142
D9: 골재 | E9: =+'[1]3월'!$AE$7/1000 -> 56.647025 | F9: =+'[2]3월'!$AN$7/1000 -> 84.928 | G9: =+F9-E9 -> 28.280975 | H9: =+'[3]3월'!$AN$7/1000 -> 56.46 | I9: =+F9-H9 -> 28.468 | J9: =+[4]손익총괄!J9+E9 -> 200.13808 | K9: =+[4]손익총괄!K9+F9 -> 234.717 | L9: =+K9-J9 -> 34.578923 | M9: =+[4]손익총괄!M9+H9 -> 187.093 | N9: =+K9-M9 -> 47.624 | Q9: 물량 | R9: 수도권 | S9: =+[5]수도권!$T$5/1000 -> 108.5 | T9: =+[5]수도권!$U$5/1000 -> 110.047 | U9: =+T9-S9 -> 1.547 | V9: =+[6]수도권!$T$5/1000 -> 134.352 | W9: =+T9-V9 -> -24.305 | AA9: =+D9 -> 골재 | AB9: =+E9 -> 56.647025 | AC9: =+F9 -> 84.928 | AD9: =+AC9-AB9 -> 28.280975 | AE9: =+H9 -> 56.46 | AF9: =+AC9-AE9 -> 28.468 | AG9: =+J9 -> 200.13808 | AH9: =+K9 -> 234.717 | AI9: =+AH9-AG9 -> 34.578923 | AJ9: =+M9 -> 187.093 | AK9: =+AH9-AJ9 -> 47.624
C10: 매출 | D10: 레미콘 | E10: =+'[1]3월'!$Z$8/1000 -> 29068.74 | F10: =+'[2]3월'!$Z$8/1000 -> 30505.252 | G10: =+F10-E10 -> 1436.5118 | H10: =+'[3]3월'!$Z$8/1000 -> 34465.761 | I10: =+F10-H10 -> -3960.5087 | J10: =+[4]손익총괄!J10+E10 -> 76183.36 | K10: =+[4]손익총괄!K10+F10 -> 80602.44 | L10: =+K10-J10 -> 4419.0803 | M10: =+[4]손익총괄!M10+H10 -> 89505.517 | N10: =+K10-M10 -> -8903.0761 | R10: 영남권 | S10: =+[5]영남권!$T$5/1000 -> 125 | T10: =+[5]영남권!$U$5/1000 -> 134.5 | U10: =+T10-S10 -> 9.5 | V10: =+[6]영남권!$T$5/1000 -> 163.0325 | W10: =+T10-V10 -> -28.5325 | Z10: 매출액 | AA10: =+D10 -> 레미콘 | AB10: =+E10/100 -> 290.6874 | AC10: =+F10/100 -> 305.05252 | AD10: =+AC10-AB10 -> 14.365118 | AE10: =+H10/100 -> 344.65761 | AF10: =+AC10-AE10 -> -39.605087 | AG10: =+J10/100 -> 761.8336 | AH10: =+K10/100 -> 806.0244 | AI10: =+AH10-AG10 -> 44.190803 | AJ10: =+M10/100 -> 895.05517 | AK10: =+AH10-AJ10 -> -89.030761
D11: 건자재 | E11: =+'[1]3월'!$AA$8/1000 -> 8929.3158 | F11: =+'[2]3월'!$AO$8/1000 -> 8759.9178 | G11: =+F11-E11 -> -169.398 | H11: =+'[3]3월'!$AO$8/1000 -> 11359.969 | I11: =+F11-H11 -> -2600.0515 | J11: =+[4]손익총괄!J11+E11 -> 25207.457 | K11: =+[4]손익총괄!K11+F11 -> 22933.533 | L11: =+K11-J11 -> -2273.9239 | M11: =+[4]손익총괄!M11+H11 -> 29963.075 | N11: =+K11-M11 -> -7029.5416 | R11: 중부권 | S11: =+[5]중부권!$T$5/1000 -> 52.5 | T11: =+[5]중부권!$U$5/1000 -> 53.9395 | U11: =+T11-S11 -> 1.4395 | V11: =+[6]중부권!$T$5/1000 -> 66.906 | W11: =+T11-V11 -> -12.9665 | AA11: =+D11 -> 건자재 | AB11: =+E11/100 -> 89.293158 | AC11: =+F11/100 -> 87.599178 | AD11: =+AC11-AB11 -> -1.69398 | AE11: =+H11/100 -> 113.59969 | AF11: =+AC11-AE11 -> -26.000515 | AG11: =+J11/100 -> 252.07457 | AH11: =+K11/100 -> 229.33533 | AI11: =+AH11-AG11 -> -22.739239 | AJ11: =+M11/100 -> 299.63075 | AK11: =+AH11-AJ11 -> -70.295416
D12: 골재 | E12: =+'[1]3월'!$AE$8/1000 -> 1271.8175 | F12: =+'[2]3월'!$AN$8/1000 -> 1765.0027 | G12: =+F12-E12 -> 493.1852 | H12: =+'[3]3월'!$AN$8/1000 -> 1014.7881 | I12: =+F12-H12 -> 750.21457 | J12: =+[4]손익총괄!J12+E12 -> 4274.4968 | K12: =+[4]손익총괄!K12+F12 -> 4781.6092 | L12: =+K12-J12 -> 507.11237 | M12: =+[4]손익총괄!M12+H12 -> 3527.6313 | N12: =+K12-M12 -> 1253.9779 | Q12: 계 | S12: =SUM(S9:S11) -> 286 | T12: =SUM(T9:T11) -> 298.4865 | U12: =+T12-S12 -> 12.4865 | V12: =SUM(V9:V11) -> 364.2905 | W12: =+T12-V12 -> -65.804 | AA12: =+D12 -> 골재 | AB12: =+E12/100 -> 12.718175 | AC12: =+F12/100 -> 17.650027 | AD12: =+AC12-AB12 -> 4.931852 | AE12: =+H12/100 -> 10.147881 | AF12: =+AC12-AE12 -> 7.5021457 | AG12: =+J12/100 -> 42.744968 | AH12: =+K12/100 -> 47.816092 | AI12: =+AH12-AG12 -> 5.0711237 | AJ12: =+M12/100 -> 35.276313 | AK12: =+AH12-AJ12 -> 12.539779
D13: 기타 | E13: =+'[1]3월'!$E$8/1000-E10-E11-E12 -> 164.9075 | F13: =+'[2]3월'!$F$8/1000-F10-F11-F12 -> 164.55387 | G13: =+F13-E13 -> -0.35363233 | H13: =+'[3]3월'!$F$8/1000-H10-H11-H12 -> 197.66135 | I13: =+F13-H13 -> -33.10748 | J13: =+[4]손익총괄!J13+E13 -> 494.7225 | K13: =+[4]손익총괄!K13+F13 -> 493.55454 | L13: =+K13-J13 -> -1.167963 | M13: =+[4]손익총괄!M13+H13 -> 545.87154 | N13: =+K13-M13 -> -52.317005 | Q13: 판매단가 | R13: 수도권 | S13: =+[5]수도권!$T$61 -> 99587.16 | T13: =+[5]수도권!$U$61 -> 101292.86 | U13: =+T13-S13 -> 1705.7037 | V13: =+[6]수도권!$Q$85 -> 90214.452 | W13: =+T13-V13 -> 11078.412 | AA13: =+D13 -> 기타 | AB13: =+E13/100 -> 1.649075 | AC13: =+F13/100 -> 1.6455387 | AD13: =+AC13-AB13 -> -0.0035363233 | AE13: =+H13/100 -> 1.9766135 | AF13: =+AC13-AE13 -> -0.3310748 | AG13: =+J13/100 -> 4.947225 | AH13: =+K13/100 -> 4.9355454 | AI13: =+AH13-AG13 -> -0.01167963 | AJ13: =+M13/100 -> 5.4587154 | AK13: =+AH13-AJ13 -> -0.52317005
C14: 계 | E14: =SUM(E10:E13) -> 39434.781 | F14: =SUM(F10:F13) -> 41194.726 | G14: =+F14-E14 -> 1759.9454 | H14: =SUM(H10:H13) -> 47038.179 | I14: =+F14-H14 -> -5843.4531 | J14: =SUM(J10:J13) -> 106160.04 | K14: =SUM(K10:K13) -> 108811.14 | L14: =+K14-J14 -> 2651.1008 | M14: =SUM(M10:M13) -> 123542.09 | N14: =+K14-M14 -> -14730.957 | R14: 영남권 | S14: =+[5]영남권!$T$61 -> 101799.63 | T14: =+[5]영남권!$U$61 -> 101364.13 | U14: =+T14-S14 -> -435.5036 | V14: =+[6]영남권!$Q$85 -> 97096.926 | W14: =+T14-V14 -> 4267.1996 | AA14: 계 | AB14: =SUM(AB10:AB13) -> 394.34781 | AC14: =SUM(AC10:AC13) -> 411.94726 | AD14: =+AC14-AB14 -> 17.599454 | AE14: =SUM(AE10:AE13) -> 470.38179 | AF14: =+AC14-AE14 -> -58.434531 | AG14: =SUM(AG10:AG13) -> 1061.6004 | AH14: =SUM(AH10:AH13) -> 1088.1114 | AI14: =+AH14-AG14 -> 26.511008 | AJ14: =SUM(AJ10:AJ13) -> 1235.4209 | AK14: =+AH14-AJ14 -> -147.30957
C15: 매출원가 | D15: 레미콘 | E15: =+('[1]3월'!$Z$10+'[1]3월'!$Z$19)/1000 -> 24470.106 | F15: =+('[2]3월'!$Z$10+'[2]3월'!$Z$19)/1000 -> 26174.702 | G15: =+F15-E15 -> 1704.5966 | H15: =+('[3]3월'!$Z$10+'[3]3월'!$Z$19)/1000 -> 28231.322 | I15: =+F15-H15 -> -2056.6196 | J15: =+[4]손익총괄!J15+E15 -> 65799.017 | K15: =+[4]손익총괄!K15+F15 -> 70916.899 | L15: =+K15-J15 -> 5117.8815 | M15: =+[4]손익총괄!M15+H15 -> 75054.71 | N15: =+K15-M15 -> -4137.8115 | R15: 중부권 | S15: =+[5]중부권!$T$61 -> 105496.75 | T15: =+[5]중부권!$U$61 -> 106231.06 | U15: =+T15-S15 -> 734.31053 | V15: =+[6]중부권!$Q$85 -> 97398.18 | W15: =+T15-V15 -> 8832.8851 | Z15: 영업이익 | AA15: =+D30 -> 레미콘 | AB15: =+E30/100 -> 39.126893 | AC15: =+F30/100 -> 36.918986 | AD15: =+AC15-AB15 -> -2.2079074 | AE15: =+H30/100 -> 55.973249 | AF15: =+AC15-AE15 -> -19.054263 | AG15: =+J30/100 -> 83.75105 | AH15: =+K30/100 -> 77.133876 | AI15: =+AH15-AG15 -> -6.6171741 | AJ15: =+M30/100 -> 124.6607 | AK15: =+AH15-AJ15 -> -47.526825
D16: 건자재 | E16: =+('[1]3월'!$AA$10+'[1]3월'!$AA$19)/1000 -> 8700.4423 | F16: =+('[2]3월'!$AO$10+'[2]3월'!$AO$19)/1000 -> 8596.6222 | G16: =+F16-E16 -> -103.82006 | H16: =+('[3]3월'!$AO$10+'[3]3월'!$AO$19)/1000 -> 11153.676 | I16: =+F16-H16 -> -2557.0534 | J16: =+[4]손익총괄!J16+E16 -> 24562.006 | K16: =+[4]손익총괄!K16+F16 -> 22399.724 | L16: =+K16-J16 -> -2162.2812 | M16: =+[4]손익총괄!M16+H16 -> 29387.997 | N16: =+K16-M16 -> -6988.2722 | Q16: 계 | S16: =+[5]합계!$T$61 -> 101638.95 | T16: =+[5]합계!$U$61 -> 102216.11 | U16: =+T16-S16 -> 577.15967 | V16: =+[6]합계!$Q$85 -> 94616.766 | W16: =+T16-V16 -> 7599.3453 | AA16: =+D31 -> % | AB16: =+E31 -> 0.13460127 | AC16: =+F31 -> 0.12102501 | AD16: =+AC16-AB16 -> -0.013576254 | AE16: =+H31 -> 0.16240248 | AF16: =+AC16-AE16 -> -0.041377462 | AG16: =+J31 -> 0.10993352 | AH16: =+K31 -> 0.0956967 | AI16: =+AH16-AG16 -> -0.01423682 | AJ16: =+M31 -> 0.13927711 | AK16: =+AH16-AJ16 -> -0.043580414
D17: 골재 | E17: =+('[1]3월'!$AE$10+'[1]3월'!$AE$19)/1000 -> 1177.972 | F17: =+('[2]3월'!$AN$10+'[2]3월'!$AN$19)/1000 -> 1564.4598 | G17: =+F17-E17 -> 386.48782 | H17: =+('[3]3월'!$AN$10+'[3]3월'!$AN$19)/1000 -> 831.37837 | I17: =+F17-H17 -> 733.08143 | J17: =+[4]손익총괄!J17+E17 -> 3968.9273 | K17: =+[4]손익총괄!K17+F17 -> 4229.3105 | L17: =+K17-J17 -> 260.38318 | M17: =+[4]손익총괄!M17+H17 -> 3155.4331 | N17: =+K17-M17 -> 1073.8773 | Q17: 공헌이익 | R17: 수도권 | S17: =+[5]수도권!$Q$90 -> 21095.807 | T17: =+[5]수도권!$R$90 -> 19077.909 | U17: =+T17-S17 -> -2017.8977 | V17: =+[6]수도권!$Q$90 -> 16629.535 | W17: =+T17-V17 -> 2448.3737 | AA17: =+D32 -> 건자재 | AB17: =+E32/100 -> 0.94407923 | AC17: =+F32/100 -> 0.31655346 | AD17: =+AC17-AB17 -> -0.62752577 | AE17: =+H32/100 -> 0.54577897 | AF17: =+AC17-AE17 -> -0.22922551 | AG17: =+J32/100 -> 2.603396 | AH17: =+K32/100 -> 1.4876724 | AI17: =+AH17-AG17 -> -1.1157236 | AJ17: =+M32/100 -> 2.0620407 | AK17: =+AH17-AJ17 -> -0.57436838
D18: 기타 | E18: =+('[1]3월'!$E$10+'[1]3월'!$E$19)/1000-E15-E16-E17 -> 49.561638 | F18: =+('[2]3월'!$F$10+'[2]3월'!$F$19)/1000-F15-F16-F17 -> 14.536916 | G18: =+F18-E18 -> -35.024722 | H18: =+('[3]3월'!$F$10+'[3]3월'!$F$19)/1000-H15-H16-H17 -> -17.724033 | I18: =+F18-H18 -> 32.260949 | J18: =+[4]손익총괄!J18+E18 -> 107.32467 | K18: =+[4]손익총괄!K18+F18 -> 71.47703 | L18: =+K18-J18 -> -35.847643 | M18: =+[4]손익총괄!M18+H18 -> 31.449464 | N18: =+K18-M18 -> 40.027566 | R18: 영남권 | S18: =+[5]영남권!$Q$90 -> 26231.975 | T18: =+[5]영남권!$R$90 -> 22198.4 | U18: =+T18-S18 -> -4033.5755 | V18: =+[6]영남권!$Q$90 -> 26639.265 | W18: =+T18-V18 -> -4440.8647 | AA18: =+D33 -> 골재 | AB18: =+E33/100 -> -0.33719615 | AC18: =+F33/100 -> 1.558676 | AD18: =+AC18-AB18 -> 1.8958721 | AE18: =+H33/100 -> 1.6304315 | AF18: =+AC18-AE18 -> -0.071755507 | AG18: =+J33/100 -> 1.039859 | AH18: =+K33/100 -> 4.1912069 | AI18: =+AH18-AG18 -> 3.1513479 | AJ18: =+M33/100 -> 3.154824 | AK18: =+AH18-AJ18 -> 1.0363829
C19: 계 | E19: =SUM(E15:E18) -> 34398.082 | F19: =SUM(F15:F18) -> 36350.321 | G19: =+F19-E19 -> 1952.2396 | H19: =SUM(H15:H18) -> 40198.652 | I19: =+F19-H19 -> -3848.3306 | J19: =SUM(J15:J18) -> 94437.275 | K19: =SUM(K15:K18) -> 97617.411 | L19: =+K19-J19 -> 3180.1358 | M19: =SUM(M15:M18) -> 107629.59 | N19: =+K19-M19 -> -10012.179 | R19: 중부권 | S19: =+[5]중부권!$Q$90 -> 29745.744 | T19: =+[5]중부권!$R$90 -> 29414.592 | U19: =+T19-S19 -> -331.15156 | V19: =+[6]중부권!$Q$90 -> 29128.006 | W19: =+T19-V19 -> 286.58581 | AA19: =+D34 -> 기타 | AB19: =+E34/100 -> -10.783693 | AC19: =+F34/100 -> -30.027274 | AD19: =+AC19-AB19 -> -19.243581 | AE19: =+H34/100 -> -10.741647 | AF19: =+AC19-AE19 -> -19.285627 | AG19: =+J34/100 -> -34.279632 | AH19: =+K34/100 -> -51.302564 | AI19: =+AH19-AG19 -> -17.022932 | AJ19: =+M34/100 -> -29.674638 | AK19: =+AH19-AJ19 -> -21.627926
C20: 매출이익 | D20: 레미콘 | E20: =+E10-E15 -> 4598.6345 | F20: =+F10-F15 -> 4330.5497 | G20: =+F20-E20 -> -268.08478 | H20: =+H10-H15 -> 6234.4388 | I20: =+F20-H20 -> -1903.8891 | J20: =+J10-J15 -> 10384.343 | K20: =+K10-K15 -> 9685.5416 | L20: =+K20-J20 -> -698.80114 | M20: =+M10-M15 -> 14450.806 | N20: =+K20-M20 -> -4765.2646 | Q20: 계 | S20: =+[5]합계!$Q$90 -> 24928.474 | T20: =+[5]합계!$R$90 -> 22348.202 | U20: =+T20-S20 -> -2580.2714 | V20: =+[6]합계!$Q$90 -> 23396.958 | W20: =+T20-V20 -> -1048.7558 | AA20: 계 | AB20: =+AB15+AB17+AB18+AB19 -> 28.950084 | AC20: =+AC15+AC17+AC18+AC19 -> 8.7669411 | AD20: =+AC20-AB20 -> -20.183142 | AE20: =+AE15+AE17+AE18+AE19 -> 47.407813 | AF20: =+AC20-AE20 -> -38.640871 | AG20: =+AG15+AG17+AG18+AG19 -> 53.114672 | AH20: =+AH15+AH17+AH18+AH19 -> 31.510191 | AI20: =+AH20-AG20 -> -21.604482 | AJ20: =+AJ15+AJ17+AJ18+AJ19 -> 100.20293 | AK20: =+AH20-AJ20 -> -68.692736
D21: 건자재 | E21: =+E11-E16 -> 228.8735 | F21: =+F11-F16 -> 163.29556 | G21: =+F21-E21 -> -65.577945 | H21: =+H11-H16 -> 206.29365 | I21: =+F21-H21 -> -42.998097 | J21: =+J11-J16 -> 645.45115 | K21: =+K11-K16 -> 533.80844 | L21: =+K21-J21 -> -111.64271 | M21: =+M11-M16 -> 575.07791 | N21: =+K21-M21 -> -41.269471 | Q21: □ 건자재 | AA21: =+D36 -> % | AB21: =+E36 -> 0.073412564 | AC21: =+F36 -> 0.021281707 | AD21: =+G36 -> -0.052130856 | AE21: =+H36 -> 0.10078582 | AF21: =+I36 -> -0.079504108 | AG21: =+J36 -> 0.050032643 | AH21: =+K36 -> 0.028958608 | ... AK21: =+N36 -> -0.05214972
D22: 골재 | E22: =+E12-E17 -> 93.845488 | F22: =+F12-F17 -> 200.54287 | G22: =+F22-E22 -> 106.69738 | H22: =+H12-H17 -> 183.40973 | I22: =+F22-H22 -> 17.133138 | J22: =+J12-J17 -> 305.56952 | K22: =+K12-K17 -> 552.29871 | L22: =+K22-J22 -> 246.72919 | M22: =+M12-M17 -> 372.19818 | N22: =+K22-M22 -> 180.10053 | Q22: 구분 | S22: 계획 | T22: 실적 | U22: 계획대비 | V22: 전년 | W22: 전년대비
D23: 기타 | E23: =+E13-E18 -> 115.34586 | F23: =+F13-F18 -> 150.01695 | G23: =+F23-E23 -> 34.67109 | H23: =+H13-H18 -> 215.38538 | I23: =+F23-H23 -> -65.368429 | J23: =+J13-J18 -> 387.39783 | K23: =+K13-K18 -> 422.07751 | L23: =+K23-J23 -> 34.67968 | M23: =+M13-M18 -> 514.42208 | N23: =+K23-M23 -> -92.344571 | Q23: 철강재 판매단가 | S23: =+'[7]3월'!$F$10 -> 978767.12 | T23: =+'[7]3월'!$G$10 -> 873530.52 | U23: =+T23-S23 -> -105236.6 | V23: =+'[8]3월'!$G$10 -> 1030973.4 | W23: =+T23-V23 -> -157442.87
C24: 계 | E24: =SUM(E20:E23) -> 5036.6994 | F24: =SUM(F20:F23) -> 4844.4051 | G24: =+F24-E24 -> -192.29425 | H24: =SUM(H20:H23) -> 6839.5276 | I24: =+F24-H24 -> -1995.1225 | J24: =SUM(J20:J23) -> 11722.761 | K24: =SUM(K20:K23) -> 11193.726 | L24: =+K24-J24 -> -529.03498 | M24: =SUM(M20:M23) -> 15912.504 | N24: =+K24-M24 -> -4718.7781 | Q24: 철강재 마진률 | S24: =+'[7]3월'!$F$15 -> 0.023347096 | T24: =+'[7]3월'!$G$15 -> 0.018797 | U24: =+T24-S24 -> -0.0045500957 | V24: =+'[8]3월'!$G$15 -> 0.01771437 | W24: =+T24-V24 -> 0.0010826304
C25: 판관비 | D25: 레미콘 | E25: =+('[1]3월'!$Z$13+'[1]3월'!$Z$20)/1000 -> 685.94519 | F25: =+('[2]3월'!$Z$13+'[2]3월'!$Z$20)/1000 -> 638.65116 | G25: =+F25-E25 -> -47.294033 | H25: =+('[3]3월'!$Z$13+'[3]3월'!$Z$20)/1000 -> 637.11391 | I25: =+F25-H25 -> 1.537254 | J25: =+[4]손익총괄!J25+E25 -> 2009.2378 | K25: =+[4]손익총괄!K25+F25 -> 1972.154 | L25: =+K25-J25 -> -37.083734 | M25: =+[4]손익총괄!M25+H25 -> 1984.7361 | N25: =+K25-M25 -> -12.582083 | Q25: □ 골재
D26: 건자재 | E26: =+('[1]3월'!$AA$13+'[1]3월'!$AA$20)/1000 -> 134.46558 | F26: =+('[2]3월'!$AO$13+'[2]3월'!$AO$20)/1000 -> 131.64021 | G26: =+F26-E26 -> -2.825368 | H26: =+('[3]3월'!$AO$13+'[3]3월'!$AO$20)/1000 -> 151.71576 | I26: =+F26-H26 -> -20.075546 | J26: =+[4]손익총괄!J26+E26 -> 385.11155 | K26: =+[4]손익총괄!K26+F26 -> 385.04121 | L26: =+K26-J26 -> -0.070343 | M26: =+[4]손익총괄!M26+H26 -> 368.87384 | N26: =+K26-M26 -> 16.167367 | Q26: 구분 | S26: 계획 | T26: 실적 | U26: 계획대비 | V26: 전년 | W26: 전년대비
D27: 골재 | E27: =+('[1]3월'!$AE$13+'[1]3월'!$AE$20+'[1]3월'!$AE$22)/1000 -> 127.5651 | F27: =+('[2]3월'!$AN$13+'[2]3월'!$AN$20+'[2]3월'!$AN$22)/1000 -> 44.675271 | G27: =+F27-E27 -> -82.889832 | H27: =+('[3]3월'!$AN$13+'[3]3월'!$AN$20+'[3]3월'!$AN$22)/1000 -> 20.366582 | I27: =+F27-H27 -> 24.308689 | J27: =+[4]손익총괄!J27+E27 -> 201.58362 | K27: =+[4]손익총괄!K27+F27 -> 133.17802 | L27: =+K27-J27 -> -68.405607 | M27: =+[4]손익총괄!M27+H27 -> 56.715781 | N27: =+K27-M27 -> 76.462234 | Q27: 판매량 | R27: 자가 | S27: =(+'[9]서부산크라샤(당월)'!$N$66+'[9]부산모래장(당월)'!$Q$48+'[9]부산크라샤(당월)'!$N$66)/1000 -> 28.647025 | T27: =(+'[9]서부산크라샤(당월)'!$O$66+'[9]부산모래장(당월)'!$R$48+'[9]부산크라샤(당월)'!$O$66)/1000 -> 49.65 | U27: =+T27-S27 -> 21.002975 | V27: =('[10]부산골재(당월)'!$R$48+'[10]서부산골재(당월)'!$O$66+'[10]부산크라샤(당월)'!$O$66)/1000 -> 34.244 | W27: =+T27-V27 -> 15.406
D28: 기타 | E28: =+('[1]3월'!$E$13+'[1]3월'!$E$20)/1000-E25-E26-E27+('[1]3월'!$E$22/1000) -> 1193.7151 | F28: =+('[2]3월'!$F$13+'[2]3월'!$F$20)/1000-F25-F26-F27+'[2]3월'!$F$22/1000 -> 3152.7443 | G28: =+F28-E28 -> 1959.0292 | H28: =+('[3]3월'!$F$13+'[3]3월'!$F$20)/1000-H25-H26-H27+'[3]3월'!$F$22/1000 -> 1289.5501 | I28: =+F28-H28 -> 1863.1943 | J28: =+[4]손익총괄!J28+E28 -> 3815.3611 | K28: =+[4]손익총괄!K28+F28 -> 5552.3339 | L28: =+K28-J28 -> 1736.9729 | M28: =+[4]손익총괄!M28+H28 -> 3481.8859 | N28: =+K28-M28 -> 2070.448 | R28: 외판 | S28: =(+'[9]서부산크라샤(당월)'!$N$59+'[9]부산모래장(당월)'!$Q$47+'[9]부산크라샤(당월)'!$N$59)/1000 -> 28 | T28: =(+'[9]서부산크라샤(당월)'!$O$59+'[9]부산모래장(당월)'!$R$47+'[9]부산크라샤(당월)'!$O$59)/1000 -> 35.278 | U28: =+T28-S28 -> 7.278 | V28: =+('[10]부산골재(당월)'!$R$47+'[10]서부산골재(당월)'!$O$59+'[10]부산크라샤(당월)'!$O$59)/1000 -> 22.216 | W28: =+T28-V28 -> 13.062
C29: 계 | E29: =SUM(E25:E28) -> 2141.691 | F29: =SUM(F25:F28) -> 3967.711 | G29: =+F29-E29 -> 1826.02 | H29: =SUM(H25:H28) -> 2098.7463 | I29: =+F29-H29 -> 1868.9647 | J29: =SUM(J25:J28) -> 6411.294 | K29: =SUM(K25:K28) -> 8042.7072 | L29: =+K29-J29 -> 1631.4132 | M29: =SUM(M25:M28) -> 5892.2117 | N29: =+K29-M29 -> 2150.4955 | Q29: 합 계 | S29: =SUM(S27:S28) -> 56.647025 | T29: =SUM(T27:T28) -> 84.928 | U29: =+T29-S29 -> 28.280975 | V29: =SUM(V27:V28) -> 56.46 | W29: =+T29-V29 -> 28.468
C30: 영업이익 | D30: 레미콘 | E30: =+E20-E25 -> 3912.6893 | F30: =+F20-F25 -> 3691.8986 | G30: =+F30-E30 -> -220.79074 | H30: =+H20-H25 -> 5597.3249 | I30: =+F30-H30 -> -1905.4263 | J30: =+J20-J25 -> 8375.105 | K30: =+K20-K25 -> 7713.3876 | L30: =+K30-J30 -> -661.71741 | M30: =+M20-M25 -> 12466.07 | N30: =+K30-M30 -> -4752.6825 | Q30: □ 기타내역(영업이익)
D31: % | E31: =+E30/E10 -> 0.13460127 | F31: =+F30/F10 -> 0.12102501 | G31: =+F31-E31 -> -0.013576254 | H31: =+H30/H10 -> 0.16240248 | I31: =+F31-H31 -> -0.041377462 | J31: =+J30/J10 -> 0.10993352 | K31: =+K30/K10 -> 0.0956967 | L31: =+K31-J31 -> -0.01423682 | M31: =+M30/M10 -> 0.13927711 | N31: =+K31-M31 -> -0.043580414 | Q31: 구분 | S31: 계획 | T31: 실적 | U31: 계획대비 | V31: 전년 | W31: 전년대비
D32: 건자재 | E32: =+E21-E26 -> 94.407923 | F32: =+F21-F26 -> 31.655346 | G32: =+F32-E32 -> -62.752577 | H32: =+H21-H26 -> 54.577897 | I32: =+F32-H32 -> -22.922551 | J32: =+J21-J26 -> 260.3396 | K32: =+K21-K26 -> 148.76724 | L32: =+K32-J32 -> -111.57236 | M32: =+M21-M26 -> 206.20407 | N32: =+K32-M32 -> -57.436838 | Q32: 레미콘임대 | S32: =+'사업장별(당월)'!T33 -> 75.360275 | T32: =+'사업장별(당월)'!U33 -> 75.121657 | U32: =+T32-S32 -> -0.238618 | V32: =+'사업장별(당월)'!W33 -> 66.104033 | W32: =+T32-V32 -> 9.017624
D33: 골재 | E33: =+E22-E27 -> -33.719615 | F33: =+F22-F27 -> 155.8676 | G33: =+F33-E33 -> 189.58721 | H33: =+H22-H27 -> 163.04315 | I33: =+F33-H33 -> -7.1755507 | J33: =+J22-J27 -> 103.9859 | K33: =+K22-K27 -> 419.12069 | L33: =+K33-J33 -> 315.13479 | M33: =+M22-M27 -> 315.4824 | N33: =+K33-M33 -> 103.63829 | Q33: 임대 | S33: =+'사업장별(당월)'!T34 -> 74.623417 | T33: =+'사업장별(당월)'!U34 -> 74.495595 | U33: =+T33-S33 -> -0.12782233 | V33: =+'사업장별(당월)'!W34 -> 125.50124 | W33: =+T33-V33 -> -51.005645
D34: 기타 | E34: =+E23-E28 -> -1078.3693 | F34: =+F23-F28 -> -3002.7274 | G34: =+F34-E34 -> -1924.3581 | H34: =+H23-H28 -> -1074.1647 | I34: =+F34-H34 -> -1928.5627 | J34: =+J23-J28 -> -3427.9632 | K34: =+K23-K28 -> -5130.2564 | L34: =+K34-J34 -> -1702.2932 | M34: =+M23-M28 -> -2967.4638 | N34: =+K34-M34 -> -2162.7926 | Q34: 공통비 | S34: =+'사업장별(당월)'!T35 -> -1156.8522 | T34: =+'사업장별(당월)'!U35 -> -1237.7949 | U34: =+T34-S34 -> -80.942691 | V34: =+'사업장별(당월)'!W35 -> -986.92285 | W34: =+T34-V34 -> -250.87206
C35: 계 | E35: =SUM(E30,E32:E34) -> 2895.0084 | F35: =SUM(F30,F32:F34) -> 876.69411 | G35: =+F35-E35 -> -2018.3142 | H35: =SUM(H30,H32:H34) -> 4740.7813 | I35: =+F35-H35 -> -3864.0871 | J35: =SUM(J30,J32:J34) -> 5311.4672 | K35: =SUM(K30,K32:K34) -> 3151.0191 | L35: =+K35-J35 -> -2160.4482 | M35: =SUM(M30,M32:M34) -> 10020.293 | N35: =+K35-M35 -> -6869.2736 | Q35: 기타 | S35: =+S36-S32-S33-S34 -> -71.500726 | T35: =+T36-T32-T33-T34 -> -1914.5497 | U35: =+T35-S35 -> -1843.049 | V35: =+V36-V32-V33-V34 -> -278.8471 | W35: =+T35-V35 -> -1635.7026
D36: % | E36: =+E35/E14 -> 0.073412564 | F36: =+F35/F14 -> 0.021281707 | G36: =+F36-E36 -> -0.052130856 | H36: =+H35/H14 -> 0.10078582 | I36: =+F36-H36 -> -0.079504108 | J36: =+J35/J14 -> 0.050032643 | K36: =+K35/K14 -> 0.028958608 | L36: =+K36-J36 -> -0.021074035 | M36: =+M35/M14 -> 0.081108328 | N36: =+K36-M36 -> -0.05214972 | Q36: 합계 | S36: =+'사업장별(당월)'!T41 -> -1078.3693 | T36: =+'사업장별(당월)'!U41 -> -3002.7274 | U36: =+T36-S36 -> -1924.3581 | V36: =+'사업장별(당월)'!W41 -> -1074.1647 | W36: =+T36-V36 -> -1928.5627
E38: =+'[1]3월'!$E$26/1000 -> 2895.0084 | F38: =+'[2]3월'!$F$26/1000 -> 876.69411 | H38: =+'[3]3월'!$F$26/1000 -> 4740.7813 | J38: =+[4]손익총괄!J38+E38 -> 5311.4672 | K38: =+[4]손익총괄!K38+F38 -> 3151.0191 | M38: =+[4]손익총괄!M38+H38 -> 10020.293
E39: =+E35=E38 -> TRUE | F39: =+F35=F38 -> FALSE | H39: =+H35=H38 -> TRUE | J39: =+J35=J38 -> FALSE | K39: =+K35=K38 -> FALSE | M39: =+M35=M38 -> TRUE
E40: =+E35-E38 -> -4.0927262e-12 | F40: =+F35-F38 -> 1.1368684e-12 | H40: =+H35-H38 -> 0 | J40: =+J35-J38 -> 0 | K40: =+K35-K38 -> -8.1854523e-12 | M40: =+M35-M38 -> -2.5465852e-11

Sheet 사업장별(당월)
H3: □ 사업장별 손익실적(2024-03)
AG4: [단위 : 천㎥, 톤, 백만원]
H5: 구분 | J5: 물량 | O5: 매출 | T5: 영업이익(공통비 배부전) | Y5: 판매단가 | AB5: 변동비 | AE5: 공헌이익
J6: 계획 | K6: 실적 | L6: 차이 | M6: 전년 | N6: 차이 | O6: 계획 | P6: 실적 | Q6: 차이 | R6: 전년 | S6: 차이 | T6: 계획 | U6: 실적 | V6: 차이 | W6: 전년 | X6: 차이 | Y6: 계획 | Z6: 실적 | AA6: 전년 | AB6: 계획 | AC6: 실적 | AD6: 전년 | AE6: 계획 | AF6: 실적 | AG6: 전년
B7: 안양 | G7: =+I7 -> 안양 | H7: 레미콘 | I7: 안양 | J7: =+IFERROR(HLOOKUP($B7,'[1]3월'!$D$6:$BN$259,2,),)/1000 -> 41 | K7: =+IFERROR(HLOOKUP($B7,'[2]3월'!$F$6:$CP$99,2,),)/1000 -> 40.978 | L7: =+K7-J7 -> -0.022 | M7: =+IFERROR(HLOOKUP($B7,'[3]3월'!$F$6:$CC$57,2,),)/1000 -> 44.44 | N7: =+K7-M7 -> -3.462 | O7: =+IFERROR(HLOOKUP($B7,'[1]3월'!$D$6:$BN$259,3,),)/1000 -> 4131.023 | P7: =+IFERROR(HLOOKUP($B7,'[2]3월'!$F$6:$CP$99,3,),)/1000 -> 4078.3749 | Q7: =+P7-O7 -> -52.648036 | R7: =+IFERROR(HLOOKUP($B7,'[3]3월'!$F$6:$CC$57,3,),)/1000 -> 4017.1087 | S7: =+P7-R7 -> 61.266257 | T7: =+IFERROR(HLOOKUP($B7,'[1]3월'!$D$6:$BN$259,16,),)/1000 -> 542.32383 | U7: =+IFERROR(HLOOKUP($B7,'[2]3월'!$F$6:$CP$99,16,),)/1000 -> 402.62876 | V7: =+U7-T7 -> -139.69507 | W7: =+IFERROR(HLOOKUP($B7,'[3]3월'!$F$6:$CC$57,16,),)/1000 -> 373.48677 | X7: =+U7-W7 -> 29.141988 | Y7: =+[5]안양!$Q$85 -> 100756.66 | Z7: =+[5]안양!$R$85 -> 99525.963 | AA7: =+[6]안양!$Q$85 -> 90393.984 | AB7: =+[5]안양!$Q$89 -> 79758.17 | AC7: =+[5]안양!$R$89 -> 82835.122 | AD7: =+[6]안양!$Q$89 -> 76169.73 | AE7: =+Y7-AB7 -> 20998.487 | AF7: =+Z7-AC7 -> 16690.841 | AG7: =+AA7-AD7 -> 14224.254
B8: 인천 | G8: =+I8 -> 인천 | H8: 직영 | I8: 인천 | J8: =+IFERROR(HLOOKUP($B8,'[1]3월'!$D$6:$BN$259,2,),)/1000 -> 28 | K8: =+IFERROR(HLOOKUP($B8,'[2]3월'!$F$6:$CP$99,2,),)/1000 -> 31.816 | L8: =+K8-J8 -> 3.816 | M8: =+IFERROR(HLOOKUP($B8,'[3]3월'!$F$6:$CC$57,2,),)/1000 -> 42.674 | N8: =+K8-M8 -> -10.858 | O8: =+IFERROR(HLOOKUP($B8,'[1]3월'!$D$6:$BN$259,3,),)/1000 -> 2879.3244 | P8: =+IFERROR(HLOOKUP($B8,'[2]3월'!$F$6:$CP$99,3,),)/1000 -> 3319.8121 | Q8: =+P8-O8 -> 440.48765 | R8: =+IFERROR(HLOOKUP($B8,'[3]3월'!$F$6:$CC$57,3,),)/1000 -> 3907.1919 | S8: =+P8-R8 -> -587.37978 | T8: =+IFERROR(HLOOKUP($B8,'[1]3월'!$D$6:$BN$259,16,),)/1000 -> 268.98683 | U8: =+IFERROR(HLOOKUP($B8,'[2]3월'!$F$6:$CP$99,16,),)/1000 -> 383.64319 | V8: =+U8-T8 -> 114.65636 | W8: =+IFERROR(HLOOKUP($B8,'[3]3월'!$F$6:$CC$57,16,),)/1000 -> 403.17202 | X8: =+U8-W8 -> -19.528835 | Y8: =+[5]인천!$Q$85 -> 102833.02 | Z8: =+[5]인천!$R$85 -> 104344.11 | AA8: =+[6]인천!$Q$85 -> 91552.938 | AB8: =+[5]인천!$Q$89 -> 82089.822 | AC8: =+[5]인천!$R$89 -> 83563.84 | AD8: =+[6]인천!$Q$89 -> 75174.238 | AE8: =+Y8-AB8 -> 20743.195 | AF8: =+Z8-AC8 -> 20780.267 | AG8: =+AA8-AD8 -> 16378.7
B9: 파주 | G9: =+I9 -> 파주 | I9: 파주 | J9: =+IFERROR(HLOOKUP($B9,'[1]3월'!$D$6:$BN$259,2,),)/1000 -> 27 | K9: =+IFERROR(HLOOKUP($B9,'[2]3월'!$F$6:$CP$99,2,),)/1000 -> 24.852 | L9: =+K9-J9 -> -2.148 | M9: =+IFERROR(HLOOKUP($B9,'[3]3월'!$F$6:$CC$57,2,),)/1000 -> 25.552 | N9: =+K9-M9 -> -0.7 | O9: =+IFERROR(HLOOKUP($B9,'[1]3월'!$D$6:$BN$259,3,),)/1000 -> 2619.672 | P9: =+IFERROR(HLOOKUP($B9,'[2]3월'!$F$6:$CP$99,3,),)/1000 -> 2542.437 | Q9: =+P9-O9 -> -77.235012 | R9: =+IFERROR(HLOOKUP($B9,'[3]3월'!$F$6:$CC$57,3,),)/1000 -> 2311.8427 | S9: =+P9-R9 -> 230.59429 | T9: =+IFERROR(HLOOKUP($B9,'[1]3월'!$D$6:$BN$259,16,),)/1000 -> 318.60083 | U9: =+IFERROR(HLOOKUP($B9,'[2]3월'!$F$6:$CP$99,16,),)/1000 -> 246.07782 | V9: =+U9-T9 -> -72.523012 | W9: =+IFERROR(HLOOKUP($B9,'[3]3월'!$F$6:$CC$57,16,),)/1000 -> 194.96663 | X9: =+U9-W9 -> 51.111193 | Y9: =+[5]파주!$Q$85 -> 97024.888 | Z9: =+[5]파주!$R$85 -> 102308.19 | AA9: =+[6]파주!$Q$85 -> 90248.344 | AB9: =+[5]파주!$Q$89 -> 76459.395 | AC9: =+[5]파주!$R$89 -> 83204.708 | AD9: =+[6]파주!$Q$89 -> 73041.207 | AE9: =+Y9-AB9 -> 20565.493 | AF9: =+Z9-AC9 -> 19103.481 | AG9: =+AA9-AD9 -> 17207.137
B10: 김포 | G10: =+I10 -> 김포 | I10: 김포 | J10: =+IFERROR(HLOOKUP($B10,'[1]3월'!$D$6:$BN$259,2,),)/1000 -> 12.5 | K10: =+IFERROR(HLOOKUP($B10,'[2]3월'!$F$6:$CP$99,2,),)/1000 -> 12.401 | L10: =+K10-J10 -> -0.099 | M10: =+IFERROR(HLOOKUP($B10,'[3]3월'!$F$6:$CC$57,2,),)/1000 -> 21.686 | N10: =+K10-M10 -> -9.285 | O10: =+IFERROR(HLOOKUP($B10,'[1]3월'!$D$6:$BN$259,3,),)/1000 -> 1175.1875 | P10: =+IFERROR(HLOOKUP($B10,'[2]3월'!$F$6:$CP$99,3,),)/1000 -> 1206.2439 | Q10: =+P10-O10 -> 31.056436 | R10: =+IFERROR(HLOOKUP($B10,'[3]3월'!$F$6:$CC$57,3,),)/1000 -> 1891.9711 | S10: =+P10-R10 -> -685.72714 | T10: =+IFERROR(HLOOKUP($B10,'[1]3월'!$D$6:$BN$259,16,),)/1000 -> 118.97714 | U10: =+IFERROR(HLOOKUP($B10,'[2]3월'!$F$6:$CP$99,16,),)/1000 -> 115.38405 | V10: =+U10-T10 -> -3.5930852 | W10: =+IFERROR(HLOOKUP($B10,'[3]3월'!$F$6:$CC$57,16,),)/1000 -> 294.49631 | X10: =+U10-W10 -> -179.11226 | Y10: =+[5]김포!$Q$85 -> 94015 | Z10: =+[5]김포!$R$85 -> 97269.892 | AA10: =+[6]김포!$Q$85 -> 87095.13 | AB10: =+[5]김포!$Q$89 -> 70664.655 | AC10: =+[5]김포!$R$89 -> 74721.474 | AD10: =+[6]김포!$Q$89 -> 65547.122 | AE10: =+Y10-AB10 -> 23350.345 | AF10: =+Z10-AC10 -> 22548.418 | AG10: =+AA10-AD10 -> 21548.008
B11: 부산 | G11: =+I11 -> 부산 | I11: 부산 | J11: =+IFERROR(HLOOKUP($B11,'[1]3월'!$D$6:$BN$259,2,),)/1000 -> 19 | K11: =+IFERROR(HLOOKUP($B11,'[2]3월'!$F$6:$CP$99,2,),)/1000 -> 21.643 | L11: =+K11-J11 -> 2.643 | M11: =+IFERROR(HLOOKUP($B11,'[3]3월'!$F$6:$CC$57,2,),)/1000 -> 26.724 | N11: =+K11-M11 -> -5.081 | O11: =+IFERROR(HLOOKUP($B11,'[1]3월'!$D$6:$BN$259,3,),)/1000 -> 2044.4048 | P11: =+IFERROR(HLOOKUP($B11,'[2]3월'!$F$6:$CP$99,3,),)/1000 -> 2301.5966 | Q11: =+P11-O11 -> 257.19183 | R11: =+IFERROR(HLOOKUP($B11,'[3]3월'!$F$6:$CC$57,3,),)/1000 -> 2712.1276 | S11: =+P11-R11 -> -410.53096 | T11: =+IFERROR(HLOOKUP($B11,'[1]3월'!$D$6:$BN$259,16,),)/1000 -> 283.18565 | U11: =+IFERROR(HLOOKUP($B11,'[2]3월'!$F$6:$CP$99,16,),)/1000 -> 237.07459 | V11: =+U11-T11 -> -46.111062 | W11: =+IFERROR(HLOOKUP($B11,'[3]3월'!$F$6:$CC$57,16,),)/1000 -> 536.21261 | X11: =+U11-W11 -> -299.13802 | Y11: =+[5]부산!$Q$85 -> 107600.25 | Z11: =+[5]부산!$R$85 -> 106343.7 | AA11: =+[6]부산!$Q$85 -> 101486.59 | AB11: =+[5]부산!$Q$89 -> 78387.597 | AC11: =+[5]부산!$R$89 -> 84400.455 | AD11: =+[6]부산!$Q$89 -> 73440.195 | AE11: =+Y11-AB11 -> 29212.656 | AF11: =+Z11-AC11 -> 21943.243 | AG11: =+AA11-AD11 -> 28046.394
B12: 서부산 | G12: =+I12 -> 서부산 | I12: 서부산 | J12: =+IFERROR(HLOOKUP($B12,'[1]3월'!$D$6:$BN$259,2,),)/1000 -> 24 | K12: =+IFERROR(HLOOKUP($B12,'[2]3월'!$F$6:$CP$99,2,),)/1000 -> 23.104 | L12: =+K12-J12 -> -0.896 | M12: =+IFERROR(HLOOKUP($B12,'[3]3월'!$F$6:$CC$57,2,),)/1000 -> 24.087 | N12: =+K12-M12 -> -0.983 | O12: =+IFERROR(HLOOKUP($B12,'[1]3월'!$D$6:$BN$259,3,),)/1000 -> 2488.2567 | P12: =+IFERROR(HLOOKUP($B12,'[2]3월'!$F$6:$CP$99,3,),)/1000 -> 2353.7109 | Q12: =+P12-O12 -> -134.54578 | R12: =+IFERROR(HLOOKUP($B12,'[3]3월'!$F$6:$CC$57,3,),)/1000 -> 2411.6617 | S12: =+P12-R12 -> -57.9508 | T12: =+IFERROR(HLOOKUP($B12,'[1]3월'!$D$6:$BN$259,16,),)/1000 -> 420.79331 | U12: =+IFERROR(HLOOKUP($B12,'[2]3월'!$F$6:$CP$99,16,),)/1000 -> 346.17788 | V12: =+U12-T12 -> -74.61543 | W12: =+IFERROR(HLOOKUP($B12,'[3]3월'!$F$6:$CC$57,16,),)/1000 -> 565.70032 | X12: =+U12-W12 -> -219.52244 | Y12: =+[5]서부산!$Q$85 -> 103677.36 | Z12: =+[5]서부산!$R$85 -> 101874.61 | AA12: =+[6]서부산!$Q$85 -> 100122.96 | AB12: =+[5]서부산!$Q$89 -> 78686.696 | AC12: =+[5]서부산!$R$89 -> 78936.836 | AD12: =+[6]서부산!$Q$89 -> 69676.894 | AE12: =+Y12-AB12 -> 24990.665 | AF12: =+Z12-AC12 -> 22937.771 | AG12: =+AA12-AD12 -> 30446.065
B13: 김해 | G13: =+I13 -> 김해 | I13: 김해 | J13: =+IFERROR(HLOOKUP($B13,'[1]3월'!$D$6:$BN$259,2,),)/1000 -> 12 | K13: =+IFERROR(HLOOKUP($B13,'[2]3월'!$F$6:$CP$99,2,),)/1000 -> 14.128 | L13: =+K13-J13 -> 2.128 | M13: =+IFERROR(HLOOKUP($B13,'[3]3월'!$F$6:$CC$57,2,),)/1000 -> 15.829 | N13: =+K13-M13 -> -1.701 | O13: =+IFERROR(HLOOKUP($B13,'[1]3월'!$D$6:$BN$259,3,),)/1000 -> 1212.0024 | P13: =+IFERROR(HLOOKUP($B13,'[2]3월'!$F$6:$CP$99,3,),)/1000 -> 1362.6295 | Q13: =+P13-O13 -> 150.6271 | R13: =+IFERROR(HLOOKUP($B13,'[3]3월'!$F$6:$CC$57,3,),)/1000 -> 1540.5559 | S13: =+P13-R13 -> -177.9264 | T13: =+IFERROR(HLOOKUP($B13,'[1]3월'!$D$6:$BN$259,16,),)/1000 -> 142.69555 | U13: =+IFERROR(HLOOKUP($B13,'[2]3월'!$F$6:$CP$99,16,),)/1000 -> 100.67253 | V13: =+U13-T13 -> -42.023028 | W13: =+IFERROR(HLOOKUP($B13,'[3]3월'!$F$6:$CC$57,16,),)/1000 -> 243.72032 | X13: =+U13-W13 -> -143.04779 | Y13: =+[5]김해!$Q$85 -> 101000.2 | Z13: =+[5]김해!$R$85 -> 96687.289 | AA13: =+[6]김해!$Q$85 -> 97324.904 | AB13: =+[5]김해!$Q$89 -> 76392.309 | AC13: =+[5]김해!$R$89 -> 79530.474 | AD13: =+[6]김해!$Q$89 -> 73868.048 | AE13: =+Y13-AB13 -> 24607.891 | AF13: =+Z13-AC13 -> 17156.814 | AG13: =+AA13-AD13 -> 23456.856
B14: 정관 | G14: =+I14 -> 정관 | I14: 정관 | J14: =+IFERROR(HLOOKUP($B14,'[1]3월'!$D$6:$BN$259,2,),)/1000 -> 18 | K14: =+IFERROR(HLOOKUP($B14,'[2]3월'!$F$6:$CP$99,2,),)/1000 -> 20.677 | L14: =+K14-J14 -> 2.677 | M14: =+IFERROR(HLOOKUP($B14,'[3]3월'!$F$6:$CC$57,2,),)/1000 -> 23.173 | N14: =+K14-M14 -> -2.496 | O14: =+IFERROR(HLOOKUP($B14,'[1]3월'!$D$6:$BN$259,3,),)/1000 -> 1872 | P14: =+IFERROR(HLOOKUP($B14,'[2]3월'!$F$6:$CP$99,3,),)/1000 -> 2137.7737 | Q14: =+P14-O14 -> 265.7737 | R14: =+IFERROR(HLOOKUP($B14,'[3]3월'!$F$6:$CC$57,3,),)/1000 -> 2297.1177 | S14: =+P14-R14 -> -159.344 | T14: =+IFERROR(HLOOKUP($B14,'[1]3월'!$D$6:$BN$259,16,),)/1000 -> 245.91393 | U14: =+IFERROR(HLOOKUP($B14,'[2]3월'!$F$6:$CP$99,16,),)/1000 -> 246.30266 | V14: =+U14-T14 -> 0.38873081 | W14: =+IFERROR(HLOOKUP($B14,'[3]3월'!$F$6:$CC$57,16,),)/1000 -> 379.50504 | X14: =+U14-W14 -> -133.20238 | Y14: =+[5]정관!$Q$85 -> 104000 | Z14: =+[5]정관!$R$85 -> 103388.97 | AA14: =+[6]정관!$Q$85 -> 99129.06 | AB14: =+[5]정관!$Q$89 -> 77839.343 | AC14: =+[5]정관!$R$89 -> 82316.125 | AD14: =+[6]정관!$Q$89 -> 74933.675 | AE14: =+Y14-AB14 -> 26160.657 | AF14: =+Z14-AC14 -> 21072.843 | AG14: =+AA14-AD14 -> 24195.384
B15: 양산 | G15: =+I15 -> 양산 | I15: 양산 | J15: =+IFERROR(HLOOKUP($B15,'[1]3월'!$D$6:$BN$259,2,),)/1000 -> 11 | K15: =+IFERROR(HLOOKUP($B15,'[2]3월'!$F$6:$CP$99,2,),)/1000 -> 13.47 | L15: =+K15-J15 -> 2.47 | M15: =+IFERROR(HLOOKUP($B15,'[3]3월'!$F$6:$CC$57,2,),)/1000 -> 18.102 | N15: =+K15-M15 -> -4.632 | O15: =+IFERROR(HLOOKUP($B15,'[1]3월'!$D$6:$BN$259,3,),)/1000 -> 1063.8695 | P15: =+IFERROR(HLOOKUP($B15,'[2]3월'!$F$6:$CP$99,3,),)/1000 -> 1230.1273 | Q15: =+P15-O15 -> 166.25781 | R15: =+IFERROR(HLOOKUP($B15,'[3]3월'!$F$6:$CC$57,3,),)/1000 -> 1686.4854 | S15: =+P15-R15 -> -456.35812 | T15: =+IFERROR(HLOOKUP($B15,'[1]3월'!$D$6:$BN$259,16,),)/1000 -> 118.04824 | U15: =+IFERROR(HLOOKUP($B15,'[2]3월'!$F$6:$CP$99,16,),)/1000 -> 132.96661 | V15: =+U15-T15 -> 14.918371 | W15: =+IFERROR(HLOOKUP($B15,'[3]3월'!$F$6:$CC$57,16,),)/1000 -> 312.72786 | X15: =+U15-W15 -> -179.76125 | Y15: =+[5]양산!$Q$85 -> 96715.406 | Z15: =+[5]양산!$R$85 -> 91323.48 | AA15: =+[6]양산!$Q$85 -> 93165.694 | AB15: =+[5]양산!$Q$89 -> 71493.416 | AC15: =+[5]양산!$R$89 -> 71355.878 | AD15: =+[6]양산!$Q$89 -> 67449.587 | AE15: =+Y15-AB15 -> 25221.99 | AF15: =+Z15-AC15 -> 19967.603 | AG15: =+AA15-AD15 -> 25716.108
B16: 창원 | G16: =+I16 -> 창원 | I16: 창원 | J16: =+IFERROR(HLOOKUP($B16,'[1]3월'!$D$6:$BN$259,2,),)/1000 -> 18 | K16: =+IFERROR(HLOOKUP($B16,'[2]3월'!$F$6:$CP$99,2,),)/1000 -> 18.723 | L16: =+K16-J16 -> 0.723 | M16: =+IFERROR(HLOOKUP($B16,'[3]3월'!$F$6:$CC$57,2,),)/1000 -> 22.044 | N16: =+K16-M16 -> -3.321 | O16: =+IFERROR(HLOOKUP($B16,'[1]3월'!$D$6:$BN$259,3,),)/1000 -> 1793.4425 | P16: =+IFERROR(HLOOKUP($B16,'[2]3월'!$F$6:$CP$99,3,),)/1000 -> 1905.079 | Q16: =+P16-O16 -> 111.6365 | R16: =+IFERROR(HLOOKUP($B16,'[3]3월'!$F$6:$CC$57,3,),)/1000 -> 2043.2435 | S16: =+P16-R16 -> -138.1645 | T16: =+IFERROR(HLOOKUP($B16,'[1]3월'!$D$6:$BN$259,16,),)/1000 -> 296.12377 | U16: =+IFERROR(HLOOKUP($B16,'[2]3월'!$F$6:$CP$99,16,),)/1000 -> 321.83747 | V16: =+U16-T16 -> 25.713699 | W16: =+IFERROR(HLOOKUP($B16,'[3]3월'!$F$6:$CC$57,16,),)/1000 -> 425.86197 | X16: =+U16-W16 -> -104.0245 | Y16: =+[5]창원!$Q$85 -> 99635.694 | Z16: =+[5]창원!$R$85 -> 101750.73 | AA16: =+[6]창원!$Q$85 -> 92689.326 | AB16: =+[5]창원!$Q$89 -> 71886.301 | AC16: =+[5]창원!$R$89 -> 74990.256 | AD16: =+[6]창원!$Q$89 -> 66107.699 | AE16: =+Y16-AB16 -> 27749.393 | AF16: =+Z16-AC16 -> 26760.478 | AG16: =+AA16-AD16 -> 26581.627
B17: 대구 | G17: =+I17 -> 대구 | I17: 대구 | J17: =+IFERROR(HLOOKUP($B17,'[1]3월'!$D$6:$BN$259,2,),)/1000 -> 16 | K17: =+IFERROR(HLOOKUP($B17,'[2]3월'!$F$6:$CP$99,2,),)/1000 -> 15.572 | L17: =+K17-J17 -> -0.428 | M17: =+IFERROR(HLOOKUP($B17,'[3]3월'!$F$6:$CC$57,2,),)/1000 -> 21.7045 | N17: =+K17-M17 -> -6.1325 | O17: =+IFERROR(HLOOKUP($B17,'[1]3월'!$D$6:$BN$259,3,),)/1000 -> 1564.8 | P17: =+IFERROR(HLOOKUP($B17,'[2]3월'!$F$6:$CP$99,3,),)/1000 -> 1576.5958 | Q17: =+P17-O17 -> 11.795842 | R17: =+IFERROR(HLOOKUP($B17,'[3]3월'!$F$6:$CC$57,3,),)/1000 -> 2074.421 | S17: =+P17-R17 -> -497.82516 | T17: =+IFERROR(HLOOKUP($B17,'[1]3월'!$D$6:$BN$259,16,),)/1000 -> 253.15821 | U17: =+IFERROR(HLOOKUP($B17,'[2]3월'!$F$6:$CP$99,16,),)/1000 -> 198.15277 | V17: =+U17-T17 -> -55.00544 | W17: =+IFERROR(HLOOKUP($B17,'[3]3월'!$F$6:$CC$57,16,),)/1000 -> 445.24218 | X17: =+U17-W17 -> -247.08941 | Y17: =+[5]대구!$Q$85 -> 97800 | Z17: =+[5]대구!$R$85 -> 101245.56 | AA17: =+[6]대구!$Q$85 -> 95589.957 | AB17: =+[5]대구!$Q$89 -> 70142.003 | AC17: =+[5]대구!$R$89 -> 77193.44 | AD17: =+[6]대구!$Q$89 -> 66842.167 | AE17: =+Y17-AB17 -> 27657.997 | AF17: =+Z17-AC17 -> 24052.119 | AG17: =+AA17-AD17 -> 28747.79
B18: 울산 | G18: =+I18 -> 울산 | I18: 울산 | J18: =+IFERROR(HLOOKUP($B18,'[1]3월'!$D$6:$BN$259,2,),)/1000 -> 7 | K18: =+IFERROR(HLOOKUP($B18,'[2]3월'!$F$6:$CP$99,2,),)/1000 -> 7.183 | L18: =+K18-J18 -> 0.183 | M18: =+IFERROR(HLOOKUP($B18,'[3]3월'!$F$6:$CC$57,2,),)/1000 -> 11.369 | N18: =+K18-M18 -> -4.186 | O18: =+IFERROR(HLOOKUP($B18,'[1]3월'!$D$6:$BN$259,3,),)/1000 -> 686.1778 | P18: =+IFERROR(HLOOKUP($B18,'[2]3월'!$F$6:$CP$99,3,),)/1000 -> 760.20834 | Q18: =+P18-O18 -> 74.030542 | R18: =+IFERROR(HLOOKUP($B18,'[3]3월'!$F$6:$CC$57,3,),)/1000 -> 1063.213 | S18: =+P18-R18 -> -303.00466 | T18: =+IFERROR(HLOOKUP($B18,'[1]3월'!$D$6:$BN$259,16,),)/1000 -> -8.9297031 | U18: =+IFERROR(HLOOKUP($B18,'[2]3월'!$F$6:$CP$99,16,),)/1000 -> 30.862733 | V18: =+U18-T18 -> 39.792436 | W18: =+IFERROR(HLOOKUP($B18,'[3]3월'!$F$6:$CC$57,16,),)/1000 -> 122.99234 | X18: =+U18-W18 -> -92.129602 | Y18: =+[5]울산!$Q$85 -> 98025.4 | Z18: =+[5]울산!$R$85 -> 105834.38 | AA18: =+[6]울산!$Q$85 -> 93554.315 | AB18: =+[5]울산!$Q$89 -> 78234.678 | AC18: =+[5]울산!$R$89 -> 83954.888 | AD18: =+[6]울산!$Q$89 -> 71298.056 | AE18: =+Y18-AB18 -> 19790.722 | AF18: =+Z18-AC18 -> 21879.491 | AG18: =+AA18-AD18 -> 22256.259
B19: 아산 | G19: =+I19 -> 아산 | I19: 아산 | J19: =+IFERROR(HLOOKUP($B19,'[1]3월'!$D$6:$BN$259,2,),)/1000 -> 24 | K19: =+IFERROR(HLOOKUP($B19,'[2]3월'!$F$6:$CP$99,2,),)/1000 -> 27.772 | L19: =+K19-J19 -> 3.772 | M19: =+IFERROR(HLOOKUP($B19,'[3]3월'!$F$6:$CC$57,2,),)/1000 -> 30.829 | N19: =+K19-M19 -> -3.057 | O19: =+IFERROR(HLOOKUP($B19,'[1]3월'!$D$6:$BN$259,3,),)/1000 -> 2423.9894 | P19: =+IFERROR(HLOOKUP($B19,'[2]3월'!$F$6:$CP$99,3,),)/1000 -> 2853.2172 | Q19: =+P19-O19 -> 429.2278 | R19: =+IFERROR(HLOOKUP($B19,'[3]3월'!$F$6:$CC$57,3,),)/1000 -> 2876.1871 | S19: =+P19-R19 -> -22.96995 | T19: =+IFERROR(HLOOKUP($B19,'[1]3월'!$D$6:$BN$259,16,),)/1000 -> 374.64057 | U19: =+IFERROR(HLOOKUP($B19,'[2]3월'!$F$6:$CP$99,16,),)/1000 -> 386.52773 | V19: =+U19-T19 -> 11.887158 | W19: =+IFERROR(HLOOKUP($B19,'[3]3월'!$F$6:$CC$57,16,),)/1000 -> 532.67521 | X19: =+U19-W19 -> -146.14748 | Y19: =+[5]아산!$Q$85 -> 100999.56 | Z19: =+[5]아산!$R$85 -> 102685.24 | AA19: =+[6]아산!$Q$85 -> 93236.814 | AB19: =+[5]아산!$Q$89 -> 76007.141 | AC19: =+[5]아산!$R$89 -> 79375.617 | AD19: =+[6]아산!$Q$89 -> 67429.62 | AE19: =+Y19-AB19 -> 24992.417 | AF19: =+Z19-AC19 -> 23309.621 | AG19: =+AA19-AD19 -> 25807.194
B20: 전주 | G20: =+I20 -> 전주 | I20: 전주 | J20: =+IFERROR(HLOOKUP($B20,'[1]3월'!$D$6:$BN$259,2,),)/1000 -> 12 | K20: =+IFERROR(HLOOKUP($B20,'[2]3월'!$F$6:$CP$99,2,),)/1000 -> 7.133 | L20: =+K20-J20 -> -4.867 | M20: =+IFERROR(HLOOKUP($B20,'[3]3월'!$F$6:$CC$57,2,),)/1000 -> 11.945 | N20: =+K20-M20 -> -4.812 | O20: =+IFERROR(HLOOKUP($B20,'[1]3월'!$D$6:$BN$259,3,),)/1000 -> 1245.3259 | P20: =+IFERROR(HLOOKUP($B20,'[2]3월'!$F$6:$CP$99,3,),)/1000 -> 668.37119 | Q20: =+P20-O20 -> -576.9547 | R20: =+IFERROR(HLOOKUP($B20,'[3]3월'!$F$6:$CC$57,3,),)/1000 -> 1080.1422 | S20: =+P20-R20 -> -411.77102 | T20: =+IFERROR(HLOOKUP($B20,'[1]3월'!$D$6:$BN$259,16,),)/1000 -> 196.65841 | U20: =+IFERROR(HLOOKUP($B20,'[2]3월'!$F$6:$CP$99,16,),)/1000 -> 10.43893 | V20: =+U20-T20 -> -186.21948 | W20: =+IFERROR(HLOOKUP($B20,'[3]3월'!$F$6:$CC$57,16,),)/1000 -> 141.11615 | X20: =+U20-W20 -> -130.67722 | Y20: =+[5]전주!$Q$85 -> 103777.16 | Z20: =+[5]전주!$R$85 -> 93701.275 | AA20: =+[6]전주!$Q$85 -> 90426.305 | AB20: =+[5]전주!$Q$89 -> 74508.817 | AC20: =+[5]전주!$R$89 -> 71268.039 | AD20: =+[6]전주!$Q$89 -> 66717.705 | AE20: =+Y20-AB20 -> 29268.341 | AF20: =+Z20-AC20 -> 22433.236 | AG20: =+AA20-AD20 -> 23708.6
B21: 군산 | G21: =+I21 -> 군산 | I21: 군산 | J21: =+IFERROR(HLOOKUP($B21,'[1]3월'!$D$6:$BN$259,2,),)/1000 -> 7.5 | K21: =+IFERROR(HLOOKUP($B21,'[2]3월'!$F$6:$CP$99,2,),)/1000 -> 8.978 | L21: =+K21-J21 -> 1.478 | M21: =+IFERROR(HLOOKUP($B21,'[3]3월'!$F$6:$CC$57,2,),)/1000 -> 8.9965 | N21: =+K21-M21 -> -0.0185 | O21: =+IFERROR(HLOOKUP($B21,'[1]3월'!$D$6:$BN$259,3,),)/1000 -> 822.9643 | P21: =+IFERROR(HLOOKUP($B21,'[2]3월'!$F$6:$CP$99,3,),)/1000 -> 1017.8315 | Q21: =+P21-O21 -> 194.86725 | R21: =+IFERROR(HLOOKUP($B21,'[3]3월'!$F$6:$CC$57,3,),)/1000 -> 873.91435 | S21: =+P21-R21 -> 143.9172 | T21: =+IFERROR(HLOOKUP($B21,'[1]3월'!$D$6:$BN$259,16,),)/1000 -> 222.08148 | U21: =+IFERROR(HLOOKUP($B21,'[2]3월'!$F$6:$CP$99,16,),)/1000 -> 313.98711 | V21: =+U21-T21 -> 91.905631 | W21: =+IFERROR(HLOOKUP($B21,'[3]3월'!$F$6:$CC$57,16,),)/1000 -> 220.37512 | X21: =+U21-W21 -> 93.611987 | Y21: =+[5]군산!$Q$85 -> 109728.57 | Z21: =+[5]군산!$R$85 -> 113442.55 | AA21: =+[6]군산!$Q$85 -> 97056.908 | AB21: =+[5]군산!$Q$89 -> 69726.729 | AC21: =+[5]군산!$R$89 -> 70413.769 | AD21: =+[6]군산!$Q$89 -> 64107.545 | AE21: =+Y21-AB21 -> 40001.844 | AF21: =+Z21-AC21 -> 43028.785 | AG21: =+AA21-AD21 -> 32949.362
B22: 원주 | G22: =+I22 -> 원주 | I22: 원주 | J22: =+IFERROR(HLOOKUP($B22,'[1]3월'!$D$6:$BN$259,2,),)/1000 -> 5 | K22: =+IFERROR(HLOOKUP($B22,'[2]3월'!$F$6:$CP$99,2,),)/1000 -> 6.2085 | L22: =+K22-J22 -> 1.2085 | M22: =+IFERROR(HLOOKUP($B22,'[3]3월'!$F$6:$CC$57,2,),)/1000 -> 7.0215 | N22: =+K22-M22 -> -0.813 | O22: =+IFERROR(HLOOKUP($B22,'[1]3월'!$D$6:$BN$259,3,),)/1000 -> 539.5 | P22: =+IFERROR(HLOOKUP($B22,'[2]3월'!$F$6:$CP$99,3,),)/1000 -> 692.2704 | Q22: =+P22-O22 -> 152.7704 | R22: =+IFERROR(HLOOKUP($B22,'[3]3월'!$F$6:$CC$57,3,),)/1000 -> 709.56992 | S22: =+P22-R22 -> -17.299518 | T22: =+IFERROR(HLOOKUP($B22,'[1]3월'!$D$6:$BN$259,16,),)/1000 -> 77.071971 | U22: =+IFERROR(HLOOKUP($B22,'[2]3월'!$F$6:$CP$99,16,),)/1000 -> 145.91854 | V22: =+U22-T22 -> 68.846574 | W22: =+IFERROR(HLOOKUP($B22,'[3]3월'!$F$6:$CC$57,16,),)/1000 -> 170.60459 | X22: =+U22-W22 -> -24.686041 | Y22: =+[5]원주!$Q$85 -> 107900 | Z22: =+[5]원주!$R$85 -> 111513.97 | AA22: =+[6]원주!$Q$85 -> 101026.22 | AB22: =+[5]원주!$Q$89 -> 75191.705 | AC22: =+[5]원주!$R$89 -> 73875.972 | AD22: =+[6]원주!$Q$89 -> 64707.623 | AE22: =+Y22-AB22 -> 32708.295 | AF22: =+Z22-AC22 -> 37637.994 | AG22: =+AA22-AD22 -> 36318.6
B23: 제주 | G23: =+I23 -> 제주 | I23: 제주 | J23: =+IFERROR(HLOOKUP($B23,'[1]3월'!$D$6:$BN$259,2,),)/1000 -> 4 | K23: =+IFERROR(HLOOKUP($B23,'[2]3월'!$F$6:$CP$99,2,),)/1000 -> 3.848 | L23: =+K23-J23 -> -0.152 | M23: =+IFERROR(HLOOKUP($B23,'[3]3월'!$F$6:$CC$57,2,),)/1000 -> 8.114 | N23: =+K23-M23 -> -4.266 | O23: =+IFERROR(HLOOKUP($B23,'[1]3월'!$D$6:$BN$259,3,),)/1000 -> 506.8 | P23: =+IFERROR(HLOOKUP($B23,'[2]3월'!$F$6:$CP$99,3,),)/1000 -> 498.9725 | Q23: =+P23-O23 -> -7.8275 | R23: =+IFERROR(HLOOKUP($B23,'[3]3월'!$F$6:$CC$57,3,),)/1000 -> 969.00694 | S23: =+P23-R23 -> -470.03444 | T23: =+IFERROR(HLOOKUP($B23,'[1]3월'!$D$6:$BN$259,16,),)/1000 -> 42.35929 | U23: =+IFERROR(HLOOKUP($B23,'[2]3월'!$F$6:$CP$99,16,),)/1000 -> 73.24519 | V23: =+U23-T23 -> 30.8859 | W23: =+IFERROR(HLOOKUP($B23,'[3]3월'!$F$6:$CC$57,16,),)/1000 -> 234.46947 | X23: =+U23-W23 -> -161.22428 | Y23: =+[5]제주!$Q$85 -> 126700 | Z23: =+[5]제주!$R$85 -> 129670.61 | AA23: =+[6]제주!$Q$85 -> 119468.4 | AB23: =+[5]제주!$Q$89 -> 89935.469 | AC23: =+[5]제주!$R$89 -> 88327.903 | AD23: =+[6]제주!$Q$89 -> 81150.68 | AE23: =+Y23-AB23 -> 36764.531 | AF23: =+Z23-AC23 -> 41342.705 | AG23: =+AA23-AD23 -> 38317.723
G24: =+I24 -> 수도권 | I24: 수도권 | J24: =SUM(J7:J10) -> 108.5 | K24: =SUM(K7:K10) -> 110.047 | L24: =+K24-J24 -> 1.547 | M24: =SUM(M7:M10) -> 134.352 | N24: =+K24-M24 -> -24.305 | O24: =SUM(O7:O10) -> 10805.207 | P24: =SUM(P7:P10) -> 11146.868 | Q24: =+P24-O24 -> 341.66104 | R24: =SUM(R7:R10) -> 12128.114 | S24: =+P24-R24 -> -981.24638 | T24: =SUM(T7:T10) -> 1248.8886 | U24: =SUM(U7:U10) -> 1147.7338 | V24: =+U24-T24 -> -101.1548 | W24: =SUM(W7:W10) -> 1266.1217 | X24: =+U24-W24 -> -118.38791 | Y24: =+[5]수도권!$Q$85 -> 99587.16 | Z24: =+[5]수도권!$R$85 -> 101292.86 | AA24: =+[6]수도권!$Q$85 -> 90214.452 | AB24: =+[5]수도권!$Q$89 -> 78491.353 | AC24: =+[5]수도권!$R$89 -> 82214.955 | AD24: =+[6]수도권!$Q$89 -> 73584.916 | AE24: =+Y24-AB24 -> 21095.807 | AF24: =+Z24-AC24 -> 19077.909 | AG24: =+AA24-AD24 -> 16629.535
G25: =+I25 -> 영남권 | I25: 영남권 | J25: =SUM(J11:J18) -> 125 | K25: =SUM(K11:K18) -> 134.5 | L25: =+K25-J25 -> 9.5 | M25: =SUM(M11:M18) -> 163.0325 | N25: =+K25-M25 -> -28.5325 | O25: =SUM(O11:O18) -> 12724.954 | P25: =SUM(P11:P18) -> 13627.721 | Q25: =+P25-O25 -> 902.76754 | R25: =SUM(R11:R18) -> 15828.826 | S25: =+P25-R25 -> -2201.1046 | T25: =SUM(T11:T18) -> 1750.989 | U25: =SUM(U11:U18) -> 1614.0472 | V25: =+U25-T25 -> -136.94172 | W25: =SUM(W11:W18) -> 3031.9626 | X25: =+U25-W25 -> -1417.9154 | Y25: =+[5]영남권!$Q$85 -> 101799.63 | Z25: =+[5]영남권!$R$85 -> 101364.13 | AA25: =+[6]영남권!$Q$85 -> 97096.926 | AB25: =+[5]영남권!$Q$89 -> 75567.654 | AC25: =+[5]영남권!$R$89 -> 79165.726 | AD25: =+[6]영남권!$Q$89 -> 70457.662 | AE25: =+Y25-AB25 -> 26231.975 | AF25: =+Z25-AC25 -> 22198.4 | AG25: =+AA25-AD25 -> 26639.265
G26: =+I26 -> 중부권 | I26: 중부권 | J26: =SUM(J19:J23) -> 52.5 | K26: =SUM(K19:K23) -> 53.9395 | L26: =+K26-J26 -> 1.4395 | M26: =SUM(M19:M23) -> 66.906 | N26: =+K26-M26 -> -12.9665 | O26: =SUM(O19:O23) -> 5538.5796 | P26: =SUM(P19:P23) -> 5730.6628 | Q26: =+P26-O26 -> 192.08325 | R26: =SUM(R19:R23) -> 6508.8206 | S26: =+P26-R26 -> -778.15772 | T26: =SUM(T19:T23) -> 912.81172 | U26: =SUM(U19:U23) -> 930.1175 | V26: =+U26-T26 -> 17.305781 | W26: =SUM(W19:W23) -> 1299.2405 | X26: =+U26-W26 -> -369.12303 | Y26: =+[5]중부권!$Q$85 -> 105496.75 | Z26: =+[5]중부권!$R$85 -> 106231.06 | AA26: =+[6]중부권!$Q$85 -> 97398.18 | AB26: =+[5]중부권!$Q$89 -> 75751.011 | AC26: =+[5]중부권!$R$89 -> 76816.473 | AD26: =+[6]중부권!$Q$89 -> 68270.173 | AE26: =+Y26-AB26 -> 29745.744 | AF26: =+Z26-AC26 -> 29414.592 | AG26: =+AA26-AD26 -> 29128.006
G27: =+K27/J27 -> 1.0436591 | H27: 레미콘 계 | J27: =SUM(J24:J26) -> 286 | K27: =SUM(K24:K26) -> 298.4865 | L27: =+K27-J27 -> 12.4865 | M27: =SUM(M24:M26) -> 364.2905 | N27: =+K27-M27 -> -65.804 | O27: =SUM(O24:O26) -> 29068.74 | P27: =SUM(P24:P26) -> 30505.252 | Q27: =+P27-O27 -> 1436.5118 | R27: =SUM(R24:R26) -> 34465.761 | S27: =+P27-R27 -> -3960.5087 | T27: =SUM(T24:T26) -> 3912.6893 | U27: =SUM(U24:U26) -> 3691.8986 | V27: =+U27-T27 -> -220.79074 | W27: =SUM(W24:W26) -> 5597.3249 | X27: =+U27-W27 -> -1905.4263 | Y27: =+[5]합계!$Q$85 -> 101638.95 | Z27: =+[5]합계!$R$85 -> 102216.11 | AA27: =+[6]합계!$Q$85 -> 94616.766 | AB27: =+[5]합계!$Q$89 -> 76710.478 | AC27: =+[5]합계!$R$89 -> 79867.909 | AD27: =+[6]합계!$Q$89 -> 71219.808 | AE27: =+Y27-AB27 -> 24928.474 | AF27: =+Z27-AC27 -> 22348.202 | AG27: =+AA27-AD27 -> 23396.958
B28: 건자재 | E28: 건자재영업 | G28: 건자재 | H28: 건자재 | J28: =+IFERROR(HLOOKUP($B28,'[1]3월'!$D$6:$BN$259,2,),) -> 7300 | K28: =+IFERROR(HLOOKUP($E28,'[2]3월'!$F$6:$CP$99,2,),) -> 8665.068 | L28: =+K28-J28 -> 1365.068 | M28: =+IFERROR(HLOOKUP($E28,'[3]3월'!$F$6:$CC$57,2,),) -> 9838.578 | N28: =+K28-M28 -> -1173.51 | O28: =+IFERROR(HLOOKUP($B28,'[1]3월'!$D$6:$BN$259,3,),)/1000 -> 8929.3158 | P28: =+IFERROR(HLOOKUP($E28,'[2]3월'!$F$6:$CP$99,3,),)/1000 -> 8759.9178 | Q28: =+P28-O28 -> -169.398 | R28: =+IFERROR(HLOOKUP($E28,'[3]3월'!$F$6:$CC$57,3,),)/1000 -> 11359.969 | S28: =+P28-R28 -> -2600.0515 | T28: =+IFERROR(HLOOKUP($B28,'[1]3월'!$D$6:$BN$259,16,),)/1000 -> 94.407923 | U28: =+IFERROR(HLOOKUP($E28,'[2]3월'!$F$6:$CP$99,16,),)/1000 -> 31.655346 | V28: =+U28-T28 -> -62.752577 | W28: =+IFERROR(HLOOKUP($E28,'[3]3월'!$F$6:$CC$57,16,),)/1000 -> 54.577897 | X28: =+U28-W28 -> -22.922551 | Y28: ■ 비고
B29: 부산모래장 | F29: 부산골재 | G29: =+I29 -> 부산모래장 | H29: 골재 | I29: 부산모래장 | J29: =+IFERROR(HLOOKUP($B29,'[1]3월'!$D$6:$BN$259,2,),)/1000 -> 14.876697 | K29: =+IFERROR(HLOOKUP($F29,'[2]3월'!$F$6:$CP$99,2,),)/1000 -> 20.278 | L29: =+K29-J29 -> 5.4013026 | M29: =+IFERROR(HLOOKUP($F29,'[3]3월'!$F$6:$CC$57,2,),)/1000 -> 16.092 | N29: =+K29-M29 -> 4.186 | O29: =+IFERROR(HLOOKUP($B29,'[1]3월'!$D$6:$BN$259,3,),)/1000 -> 522.36153 | P29: =+IFERROR(HLOOKUP($F29,'[2]3월'!$F$6:$CP$99,3,),)/1000 -> 667.14967 | Q29: =+P29-O29 -> 144.78814 | R29: =+IFERROR(HLOOKUP($F29,'[3]3월'!$F$6:$CC$57,3,),)/1000 -> 541.5721 | S29: =+P29-R29 -> 125.57757 | T29: =+IFERROR(HLOOKUP($B29,'[1]3월'!$D$6:$BN$259,21,),)/1000 -> 24.013512 | U29: =+IFERROR(HLOOKUP($F29,'[2]3월'!$F$6:$CP$99,21,),)/1000 -> 62.624016 | V29: =+U29-T29 -> 38.610504 | W29: =+IFERROR(HLOOKUP($F29,'[3]3월'!$F$6:$CC$57,16,),)/1000 -> 58.332984 | X29: =+U29-W29 -> 4.2910316 | Y29: - 대손 19억 : 개별 10억(선원건설 7.9억, 송학건설 1억, 계원토건 1.2억) + 집합 9억
B30: 서부산크라샤 | F30: 서부산골재 | G30: =+I30 -> 서부산CR | I30: 서부산CR | J30: =+IFERROR(HLOOKUP($B30,'[1]3월'!$D$6:$BN$259,2,),)/1000 -> 0 | K30: =+IFERROR(HLOOKUP($F30,'[2]3월'!$F$6:$CP$99,2,),)/1000 -> 21.556 | L30: =+K30-J30 -> 21.556 | M30: =+IFERROR(HLOOKUP($F30,'[3]3월'!$F$6:$CC$57,2,),)/1000 -> 40.368 | N30: =+K30-M30 -> -18.812 | O30: =+IFERROR(HLOOKUP($B30,'[1]3월'!$D$6:$BN$259,3,),)/1000 -> 0 | P30: =+IFERROR(HLOOKUP($F30,'[2]3월'!$F$6:$CP$99,3,),)/1000 -> 310.084 | Q30: =+P30-O30 -> 310.084 | R30: =+IFERROR(HLOOKUP($F30,'[3]3월'!$F$6:$CC$57,3,),)/1000 -> 473.216 | S30: =+P30-R30 -> -163.132 | T30: =+IFERROR(HLOOKUP($B30,'[1]3월'!$D$6:$BN$259,21,),)/1000 -> -92.380353 | U30: =+IFERROR(HLOOKUP($F30,'[2]3월'!$F$6:$CP$99,21,),)/1000 -> 45.27456 | V30: =+U30-T30 -> 137.65491 | W30: =+IFERROR(HLOOKUP($F30,'[3]3월'!$F$6:$CC$57,16,),)/1000 -> 116.4274 | X30: =+U30-W30 -> -71.152837
B31: 부산크라샤 | F31: 부산크라샤 | G31: =+I31 -> 부산CR | I31: 부산CR | J31: =+IFERROR(HLOOKUP($B31,'[1]3월'!$D$6:$BN$259,2,),)/1000 -> 41.770328 | K31: =+IFERROR(HLOOKUP($F31,'[2]3월'!$F$6:$CP$99,2,),)/1000 -> 43.094 | L31: =+K31-J31 -> 1.3236722 | M31: =+IFERROR(HLOOKUP($F31,'[3]3월'!$F$6:$CC$57,2,),)/1000 -> 0 | N31: =+K31-M31 -> 43.094 | O31: =+IFERROR(HLOOKUP($B31,'[1]3월'!$D$6:$BN$259,3,),)/1000 -> 749.45594 | P31: =+IFERROR(HLOOKUP($F31,'[2]3월'!$F$6:$CP$99,3,),)/1000 -> 787.769 | Q31: =+P31-O31 -> 38.313058 | R31: =+IFERROR(HLOOKUP($F31,'[3]3월'!$F$6:$CC$57,3,),)/1000 -> 0 | S31: =+P31-R31 -> 787.769 | T31: =+IFERROR(HLOOKUP($B31,'[1]3월'!$D$6:$BN$259,21,),)/1000 -> 34.647226 | U31: =+IFERROR(HLOOKUP($F31,'[2]3월'!$F$6:$CP$99,21,),)/1000 -> 47.96902 | V31: =+U31-T31 -> 13.321795 | W31: =+IFERROR(HLOOKUP($F31,'[3]3월'!$F$6:$CC$57,16,),)/1000 -> -11.717235 | X31: =+U31-W31 -> 59.686255
H32: 골재 계 | J32: =SUM(J29:J31) -> 56.647025 | K32: =SUM(K29:K31) -> 84.928 | L32: =+K32-J32 -> 28.280975 | M32: =SUM(M29:M31) -> 56.46 | N32: =+K32-M32 -> 28.468 | O32: =SUM(O29:O31) -> 1271.8175 | P32: =SUM(P29:P31) -> 1765.0027 | Q32: =+P32-O32 -> 493.1852 | R32: =SUM(R29:R31) -> 1014.7881 | S32: =+P32-R32 -> 750.21457 | T32: =SUM(T29:T31) -> -33.719615 | U32: =SUM(U29:U31) -> 155.8676 | V32: =+U32-T32 -> 189.58721 | W32: =SUM(W29:W31) -> 163.04315 | X32: =+U32-W32 -> -7.1755507
B33: 포항임대 | C33: 속초임대 | D33: 강릉임대 | E33: 레미콘임대 계 | G33: =+I33 -> 레미콘임대 | H33: 기타 | I33: 레미콘임대 | L33: =+K33-J33 -> 0 | N33: =+K33-M33 -> 0 | O33: =(IFERROR(HLOOKUP($B33,'[1]3월'!$D$6:$BN$259,3,),)++IFERROR(HLOOKUP($C33,'[1]3월'!$D$6:$BN$259,3,),)+IFERROR(HLOOKUP($D33,'[1]3월'!$D$6:$BN$259,3,),))/1000 -> 90.84 | P33: =+IFERROR(HLOOKUP($E33,'[2]3월'!$F$6:$CP$99,3,),)/1000 -> 90.84 | Q33: =+P33-O33 -> 0 | R33: =+IFERROR(HLOOKUP($E33,'[3]3월'!$F$6:$CC$57,3,),)/1000 -> 78.34 | S33: =+P33-R33 -> 12.5 | T33: =(IFERROR(HLOOKUP($B33,'[1]3월'!$D$6:$BN$259,21,),)++IFERROR(HLOOKUP($C33,'[1]3월'!$D$6:$BN$259,21,),)+IFERROR(HLOOKUP($D33,'[1]3월'!$D$6:$BN$259,21,),))/1000 -> 75.360275 | U33: =+IFERROR(HLOOKUP($E33,'[2]3월'!$F$6:$CP$99,16,),)/1000 -> 75.121657 | V33: =+U33-T33 -> -0.238618 | W33: =+IFERROR(HLOOKUP($E33,'[3]3월'!$F$6:$CC$57,16,),)/1000 -> 66.104033 | X33: =+U33-W33 -> 9.017624
B34: 부동산임대 | C34: 주유소임대 | E34: 임대 계 | G34: =+I34 -> 임대 | I34: 임대 | L34: =+K34-J34 -> 0 | M34: 0 | N34: =+K34-M34 -> 0 | O34: =(+IFERROR(HLOOKUP($B34,'[1]3월'!$D$6:$BN$259,3,),)+IFERROR(HLOOKUP($C34,'[1]3월'!$D$6:$BN$259,3,),))/1000 -> 72.2975 | P34: =+IFERROR(HLOOKUP($E34,'[2]3월'!$F$6:$CP$99,3,),)/1000 -> 72.011468 | Q34: =+P34-O34 -> -0.28603233 | R34: =+IFERROR(HLOOKUP($E34,'[3]3월'!$F$6:$CC$57,3,),)/1000 -> 117.52245 | S34: =+P34-R34 -> -45.51098 | T34: =(+IFERROR(HLOOKUP($B34,'[1]3월'!$D$6:$BN$259,21,),)+IFERROR(HLOOKUP($C34,'[1]3월'!$D$6:$BN$259,21,),))/1000 -> 74.623417 | U34: =+IFERROR(HLOOKUP($E34,'[2]3월'!$F$6:$CP$99,16,),)/1000 -> 74.495595 | V34: =+U34-T34 -> -0.12782233 | W34: =+IFERROR(HLOOKUP($E34,'[3]3월'!$F$6:$CC$57,16,),)/1000 -> 125.50124 | X34: =+U34-W34 -> -51.005645
B35: 공 통 비 | G35: =+I35 -> 공통비 | I35: 공통비 | L35: =+K35-J35 -> 0 | N35: =+K35-M35 -> 0 | Q35: =+P35-O35 -> 0 | S35: =+P35-R35 -> 0 | T35: =-'[1]3월'!$Z$22/1000 -> -1156.8522 | U35: =+-'[2]3월'!$Z$22/1000 -> -1237.7949 | V35: =+U35-T35 -> -80.942691 | W35: =+-'[3]3월'!$Z$22/1000 -> -986.92285 | X35: =+U35-W35 -> -250.87206
G36: =+I36 -> OPC 소급분 | I36: OPC 소급분 | N36: =+K36-M36 -> 0 | Q36: =+P36-O36 -> 0 | S36: =+P36-R36 -> 0 | T36: =+'[1]3월'!$AS$26/1000 -> 0 | U36: =-'[2]3월'!$BD$26/1000 -> 0 | V36: =+U36-T36 -> 0 | W36: =-'[3]3월'!$BD$26/1000 -> 0 | X36: =+U36-W36 -> 0
G37: =+I37 -> 대손 | I37: 대손 | N37: =+K37-M37 -> 0 | Q37: =+P37-O37 -> 0 | S37: =+P37-R37 -> 0 | U37: ='[2]3월'!$BE$26/1000 -> -1906.5691 | V37: =+U37-T37 -> -1906.5691 | W37: ='[3]3월'!$BE$26/1000 -> -278.3528 | X37: =+U37-W37 -> -1628.2163
G38: =+I38 -> 미운영 공장 | I38: 미운영 공장 | M38: =SUM(M54:M57) -> 0 | N38: =+K38-M38 -> 0 | Q38: =+P38-O38 -> 0 | S38: =+P38-R38 -> 0 | T38: =SUM('[1]3월'!$AM$26:$AQ$26)/1000 -> -3.4117974 | U38: =+'[2]3월'!$BF$26/1000 -> -1.614152 | V38: =+U38-T38 -> 1.7976454 | W38: =+'[3]3월'!$BF$26/1000 -> -21.326463 | X38: =+U38-W38 -> 19.712311
B39: 기타 계 | G39: =+I39 -> 기타 | I39: 기타 | L39: =+K39-J39 -> 0 | N39: =+K39-M39 -> 0 | O39: =IFERROR(HLOOKUP($B39,'[1]3월'!$D$6:$BN$259,3,),)/1000 -> 1.77 | P39: =+('[2]3월'!$F$8-SUM('[2]3월'!$Z$8,'[2]3월'!$AH$8,'[2]3월'!$AN$8,'[2]3월'!$AO$8,'[2]3월'!$BA$8,'[2]3월'!$BD$8,'[2]3월'!$BE$8,'[2]3월'!$BF$8))/1000 -> 1.7024 | Q39: =+P39-O39 -> -0.0676 | R39: =+('[3]3월'!$F$8-SUM('[3]3월'!$Z$8,'[3]3월'!$AH$8,'[3]3월'!$AN$8,'[3]3월'!$AO$8,'[3]3월'!$BA$8,'[3]3월'!$BD$8,'[3]3월'!$BE$8,'[3]3월'!$BF$8))/1000 -> 1.7989 | S39: =+P39-R39 -> -0.0965 | T39: =+('[1]3월'!$E$26-'[1]3월'!$Z$26-'[1]3월'!$AA$26-'[1]3월'!$AE$26-'[1]3월'!$AL$26-'[1]3월'!$AM$26-'[1]3월'!$AN$26-'[1]3월'!$AO$26-'[1]3월'!$AP$26-'[1]3월'!$AQ$26-'[1]3월'!$AS$26)/1000 -> -68.088929 | U39: =+('[2]3월'!$F$26-SUM('[2]3월'!$Z$26,'[2]3월'!$AH$26,'[2]3월'!$AN$26,'[2]3월'!$AO$26,'[2]3월'!$BA$26,'[2]3월'!$BD$26,'[2]3월'!$BE$26,'[2]3월'!$BF$26))/1000 -> -6.366509 | V39: =+U39-T39 -> 61.72242 | W39: =+('[3]3월'!$F$26-SUM('[3]3월'!$Z$26,'[3]3월'!$AH$26,'[3]3월'!$AN$26,'[3]3월'!$AO$26,'[3]3월'!$BA$26,'[3]3월'!$BD$26,'[3]3월'!$BE$26,'[3]3월'!$BF$26))/1000 -> 20.832166 | X39: =+U39-W39 -> -27.198675
N40: =+K40-M40 -> 0 | Q40: =+P40-O40 -> 0 | S40: =+P40-R40 -> 0 | V40: =+U40-T40 -> 0
H41: 기타 계 | J41: =SUM(J33:J40) -> 0 | K41: =SUM(K33:K40) -> 0 | L41: =+K41-J41 -> 0 | M41: =SUM(M33:M40) -> 0 | N41: =+K41-M41 -> 0 | O41: =SUM(O33:O40) -> 164.9075 | P41: =SUM(P33:P40) -> 164.55387 | Q41: =+P41-O41 -> -0.35363233 | R41: =SUM(R33:R40) -> 197.66135 | S41: =+P41-R41 -> -33.10748 | T41: =SUM(T33:T40) -> -1078.3693 | U41: =SUM(U33:U40) -> -3002.7274 | V41: =+U41-T41 -> -1924.3581 | W41: =SUM(W33:W40) -> -1074.1647 | X41: =+U41-W41 -> -1928.5627
U42: 19 | V42: 12.4
...

Sheet 사업장별(누계)
H3: □ 사업장별 손익실적(2024-03누계)
AG4: [단위 : 천㎥, 톤, 백만원]
H5: 구분 | J5: 물량 | O5: 매출 | T5: 영업이익(공통비 배부전) | Y5: 판매단가 | AB5: 변동비 | AE5: 공헌이익
J6: 계획 | K6: 실적 | L6: 차이 | M6: 전년 | N6: 차이 | O6: 계획 | P6: 실적 | Q6: 차이 | R6: 전년 | S6: 차이 | T6: 계획 | U6: 실적 | V6: 차이 | W6: 전년 | X6: 차이 | Y6: 계획 | Z6: 실적 | AA6: 전년 | AB6: 계획 | AC6: 실적 | AD6: 전년 | AE6: 계획 | AF6: 실적 | AG6: 전년
B7: 안양 | H7: 레미콘 | I7: 안양 | J7: =+'사업장별(당월)'!J7+'[4]사업장별(누계)'!J7 -> 114 | K7: =+'사업장별(당월)'!K7+'[4]사업장별(누계)'!K7 -> 124.451 | L7: =+K7-J7 -> 10.451 | M7: =+'사업장별(당월)'!M7+'[4]사업장별(누계)'!M7 -> 133.293 | N7: =+K7-M7 -> -8.842 | O7: =+'사업장별(당월)'!O7+'[4]사업장별(누계)'!O7 -> 11192.55 | P7: =+'사업장별(당월)'!P7+'[4]사업장별(누계)'!P7 -> 12223.782 | Q7: =+P7-O7 -> 1031.2314 | R7: =+'사업장별(당월)'!R7+'[4]사업장별(누계)'!R7 -> 12041.664 | S7: =+P7-R7 -> 182.1178 | T7: =+'사업장별(당월)'!T7+'[4]사업장별(누계)'!T7 -> 1164.9034 | U7: =+'사업장별(당월)'!U7+'[4]사업장별(누계)'!U7 -> 1191.1608 | V7: =+U7-T7 -> 26.257403 | W7: =+'사업장별(당월)'!W7+'[4]사업장별(누계)'!W7 -> 1394.5362 | X7: =+U7-W7 -> -203.37537 | Y7: =+[11]안양!$Q$85 -> 98180.267 | Z7: =+[11]안양!$R$85 -> 98221.644 | AA7: =+[12]안양!$Q$85 -> 90319.023 | AB7: =+[11]안양!$Q$89 -> 79919.909 | AC7: =+[11]안양!$R$89 -> 81295.712 | AD7: =+[12]안양!$Q$89 -> 73635.95 | AE7: =+Y7-AB7 -> 18260.358 | AF7: =+Z7-AC7 -> 16925.932 | AG7: =+AA7-AD7 -> 16683.073
B8: 인천 | H8: 직영 | I8: 인천 | J8: =+'사업장별(당월)'!J8+'[4]사업장별(누계)'!J8 -> 80 | K8: =+'사업장별(당월)'!K8+'[4]사업장별(누계)'!K8 -> 83.656 | L8: =+K8-J8 -> 3.656 | M8: =+'사업장별(당월)'!M8+'[4]사업장별(누계)'!M8 -> 105.474 | N8: =+K8-M8 -> -21.818 | O8: =+'사업장별(당월)'!O8+'[4]사업장별(누계)'!O8 -> 7957.9825 | P8: =+'사업장별(당월)'!P8+'[4]사업장별(누계)'!P8 -> 8443.3819 | Q8: =+P8-O8 -> 485.39944 | R8: =+'사업장별(당월)'!R8+'[4]사업장별(누계)'!R8 -> 9553.493 | S8: =+P8-R8 -> -1110.1111 | T8: =+'사업장별(당월)'!T8+'[4]사업장별(누계)'!T8 -> 466.82253 | U8: =+'사업장별(당월)'!U8+'[4]사업장별(누계)'!U8 -> 624.52589 | V8: =+U8-T8 -> 157.70337 | W8: =+'사업장별(당월)'!W8+'[4]사업장별(누계)'!W8 -> 805.21398 | X8: =+U8-W8 -> -180.68808 | Y8: =+[11]인천!$Q$85 -> 99474.781 | Z8: =+[11]인천!$R$85 -> 100929.78 | AA8: =+[12]인천!$Q$85 -> 90569.089 | AB8: =+[11]인천!$Q$89 -> 82054.945 | AC8: =+[11]인천!$R$89 -> 83319.257 | AD8: =+[12]인천!$Q$89 -> 74511.012 | AE8: =+Y8-AB8 -> 17419.836 | AF8: =+Z8-AC8 -> 17610.527 | AG8: =+AA8-AD8 -> 16058.076
B9: 파주 | I9: 파주 | J9: =+'사업장별(당월)'!J9+'[4]사업장별(누계)'!J9 -> 68 | K9: =+'사업장별(당월)'!K9+'[4]사업장별(누계)'!K9 -> 66.204 | L9: =+K9-J9 -> -1.796 | M9: =+'사업장별(당월)'!M9+'[4]사업장별(누계)'!M9 -> 69.881 | N9: =+K9-M9 -> -3.677 | O9: =+'사업장별(당월)'!O9+'[4]사업장별(누계)'!O9 -> 6557.4779 | P9: =+'사업장별(당월)'!P9+'[4]사업장별(누계)'!P9 -> 6763.0588 | Q9: =+P9-O9 -> 205.58094 | R9: =+'사업장별(당월)'!R9+'[4]사업장별(누계)'!R9 -> 6213.3585 | S9: =+P9-R9 -> 549.70031 | T9: =+'사업장별(당월)'!T9+'[4]사업장별(누계)'!T9 -> 632.69682 | U9: =+'사업장별(당월)'!U9+'[4]사업장별(누계)'!U9 -> 487.94201 | V9: =+U9-T9 -> -144.75481 | W9: =+'사업장별(당월)'!W9+'[4]사업장별(누계)'!W9 -> 362.72157 | X9: =+U9-W9 -> 125.22044 | Y9: =+[11]파주!$Q$85 -> 96433.498 | Z9: =+[11]파주!$R$85 -> 102161.74 | AA9: =+[12]파주!$Q$85 -> 88883.921 | AB9: =+[11]파주!$Q$89 -> 77347.607 | AC9: =+[11]파주!$R$89 -> 83825.434 | AD9: =+[12]파주!$Q$89 -> 73697.261 | AE9: =+Y9-AB9 -> 19085.891 | AF9: =+Z9-AC9 -> 18336.304 | AG9: =+AA9-AD9 -> 15186.66
B10: 김포 | I10: 김포 | J10: =+'사업장별(당월)'!J10+'[4]사업장별(누계)'!J10 -> 30.5 | K10: =+'사업장별(당월)'!K10+'[4]사업장별(누계)'!K10 -> 23.559 | L10: =+K10-J10 -> -6.941 | M10: =+'사업장별(당월)'!M10+'[4]사업장별(누계)'!M10 -> 42.2155 | N10: =+K10-M10 -> -18.6565 | O10: =+'사업장별(당월)'!O10+'[4]사업장별(누계)'!O10 -> 2841.2685 | P10: =+'사업장별(당월)'!P10+'[4]사업장별(누계)'!P10 -> 2263.1289 | Q10: =+P10-O10 -> -578.13957 | R10: =+'사업장별(당월)'!R10+'[4]사업장별(누계)'!R10 -> 3636.2374 | S10: =+P10-R10 -> -1373.1084 | T10: =+'사업장별(당월)'!T10+'[4]사업장별(누계)'!T10 -> 132.60507 | U10: =+'사업장별(당월)'!U10+'[4]사업장별(누계)'!U10 -> -5.58851 | V10: =+U10-T10 -> -138.19358 | W10: =+'사업장별(당월)'!W10+'[4]사업장별(누계)'!W10 -> 366.43109 | X10: =+U10-W10 -> -372.0196 | Y10: =+[11]김포!$Q$85 -> 93156.344 | Z10: =+[11]김포!$R$85 -> 96062.181 | AA10: =+[12]김포!$Q$85 -> 86035.522 | AB10: =+[11]김포!$Q$89 -> 72248.072 | AC10: =+[11]김포!$R$89 -> 76381.196 | AD10: =+[12]김포!$Q$89 -> 65968.884 | AE10: =+Y10-AB10 -> 20908.272 | AF10: =+Z10-AC10 -> 19680.985 | AG10: =+AA10-AD10 -> 20066.638
B11: 부산 | I11: 부산 | J11: =+'사업장별(당월)'!J11+'[4]사업장별(누계)'!J11 -> 53 | K11: =+'사업장별(당월)'!K11+'[4]사업장별(누계)'!K11 -> 62.108 | L11: =+K11-J11 -> 9.108 | M11: =+'사업장별(당월)'!M11+'[4]사업장별(누계)'!M11 -> 76.332 | N11: =+K11-M11 -> -14.224 | O11: =+'사업장별(당월)'!O11+'[4]사업장별(누계)'!O11 -> 5702.8015 | P11: =+'사업장별(당월)'!P11+'[4]사업장별(누계)'!P11 -> 6695.4014 | Q11: =+P11-O11 -> 992.59993 | R11: =+'사업장별(당월)'!R11+'[4]사업장별(누계)'!R11 -> 7796.9946 | S11: =+P11-R11 -> -1101.5932 | T11: =+'사업장별(당월)'!T11+'[4]사업장별(누계)'!T11 -> 725.75291 | U11: =+'사업장별(당월)'!U11+'[4]사업장별(누계)'!U11 -> 737.33397 | V11: =+U11-T11 -> 11.581052 | W11: =+'사업장별(당월)'!W11+'[4]사업장별(누계)'!W11 -> 1517.0039 | X11: =+U11-W11 -> -779.66996 | Y11: =+[11]부산!$Q$85 -> 107600.03 | Z11: =+[11]부산!$R$85 -> 107802.56 | AA11: =+[12]부산!$Q$85 -> 102145.82 | AB11: =+[11]부산!$Q$89 -> 78500.603 | AC11: =+[11]부산!$R$89 -> 84406.225 | AD11: =+[12]부산!$Q$89 -> 73184.558 | AE11: =+Y11-AB11 -> 29099.425 | AF11: =+Z11-AC11 -> 23396.335 | AG11: =+AA11-AD11 -> 28961.26
B12: 서부산 | I12: 서부산 | J12: =+'사업장별(당월)'!J12+'[4]사업장별(누계)'!J12 -> 64 | K12: =+'사업장별(당월)'!K12+'[4]사업장별(누계)'!K12 -> 63.855 | L12: =+K12-J12 -> -0.145 | M12: =+'사업장별(당월)'!M12+'[4]사업장별(누계)'!M12 -> 69.297 | N12: =+K12-M12 -> -5.442 | O12: =+'사업장별(당월)'!O12+'[4]사업장별(누계)'!O12 -> 6629.7965 | P12: =+'사업장별(당월)'!P12+'[4]사업장별(누계)'!P12 -> 6421.5315 | Q12: =+P12-O12 -> -208.26496 | R12: =+'사업장별(당월)'!R12+'[4]사업장별(누계)'!R12 -> 6626.9685 | S12: =+P12-R12 -> -205.43698 | T12: =+'사업장별(당월)'!T12+'[4]사업장별(누계)'!T12 -> 1036.9188 | U12: =+'사업장별(당월)'!U12+'[4]사업장별(누계)'!U12 -> 663.07388 | V12: =+U12-T12 -> -373.8449 | W12: =+'사업장별(당월)'!W12+'[4]사업장별(누계)'!W12 -> 1141.9588 | X12: =+U12-W12 -> -478.88487 | Y12: =+[11]서부산!$Q$85 -> 103590.57 | Z12: =+[11]서부산!$R$85 -> 100564.27 | AA12: =+[12]서부산!$Q$85 -> 95631.391 | AB12: =+[11]서부산!$Q$89 -> 78032.761 | AC12: =+[11]서부산!$R$89 -> 80023.775 | AD12: =+[12]서부산!$Q$89 -> 70387.245 | AE12: =+Y12-AB12 -> 25557.809 | AF12: =+Z12-AC12 -> 20540.495 | AG12: =+AA12-AD12 -> 25244.146
