Workbook

Sheet 표지
A6: 2024년 5월 마감 손익
A24: 건재사업본부

Sheet 손익총괄
C3: □ 건재사업본부 손익실적(2024-05) | Z3: □ 건재부문 실적(5월)
X4: [단위 : 천㎥, 톤, 원/㎥, 원/톤, 백만원] | AK4: (단위 : 천㎥, 천톤, 억원)
C5: 구분 | E5: 5월 | J5: 5월 누계 | P5: 5월 주요지표 | Z5: 구분 | AB5: =+E5 -> 5월 | AG5: =+J5 -> 5월 누계
E6: 계획 | F6: 실적 | G6: 계획대비 | H6: 전년 | I6: 전년대비 | J6: 계획 | K6: 실적 | L6: 계획대비 | M6: 전년 | N6: 전년대비 | AB6: =+E6 -> 계획 | AC6: =+F6 -> 실적 | AD6: =+G6 -> 계획대비 | AE6: =+H6 -> 전년 | AF6: =+I6 -> 전년대비 | AG6: =+J6 -> 계획 | AH6: =+K6 -> 실적 | AI6: =+L6 -> 계획대비 | ... AK6: =+N6 -> 전년대비
A7: =+F7/E7 -> 1.1055064 | B7: =+K7/J7 -> 1.0686217 | C7: 물량 | D7: 레미콘 | E7: =+'[1]5월'!$Z$7/1000 -> 314 | F7: =+'[2]5월'!$Z$7/1000 -> 347.129 | G7: =+F7-E7 -> 33.129 | H7: =+'[3]5월'!$Z$7/1000 -> 364.4015 | I7: =+F7-H7 -> -17.2725 | J7: =+[4]손익총괄!J7+E7 -> 1378.5 | K7: =+[4]손익총괄!K7+F7 -> 1473.095 | L7: =+K7-J7 -> 94.595 | M7: =+[4]손익총괄!M7+H7 -> 1644.049 | N7: =+K7-M7 -> -170.954 | Q7: □ 레미콘 | Z7: 물량 | AA7: =+D7 -> 레미콘 | AB7: =+E7 -> 314 | AC7: =+F7 -> 347.129 | AD7: =+AC7-AB7 -> 33.129 | AE7: =+H7 -> 364.4015 | AF7: =+AC7-AE7 -> -17.2725 | AG7: =+J7 -> 1378.5 | AH7: =+K7 -> 1473.095 | AI7: =+AH7-AG7 -> 94.595 | AJ7: =+M7 -> 1644.049 | AK7: =+AH7-AJ7 -> -170.954
D8: 철강재 | E8: =+'[1]5월'!$AA$7 -> 7600 | F8: =+'[2]5월'!$AO$7 -> 9787.441 | G8: =+F8-E8 -> 2187.441 | H8: =+'[3]5월'!$AO$7 -> 7344.996 | I8: =+F8-H8 -> 2442.445 | J8: =+[4]손익총괄!J8+E8 -> 35500 | K8: =+[4]손익총괄!K8+F8 -> 40097.987 | L8: =+K8-J8 -> 4597.987 | M8: =+[4]손익총괄!M8+H8 -> 41870.298 | N8: =+K8-M8 -> -1772.311 | Q8: 구분 | S8: 계획 | T8: 실적 | U8: 계획대비 | V8: 전년 | W8: 전년대비 | AA8: =+D8 -> 철강재 | AB8: =+E8/1000 -> 7.6 | AC8: =+F8/1000 -> 9.787441 | AD8: =+AC8-AB8 -> 2.187441 | AE8: =+H8/1000 -> 7.344996 | AF8: =+AC8-AE8 -> 2.442445 | AG8: =+J8/1000 -> 35.5 | AH8: =+K8/1000 -> 40.097987 | AI8: =+AH8-AG8 -> 4.597987 | AJ8: =+M8/1000 -> 41.870298 | AK8: =+AH8-AJ8 -> -1.772311
D9: 골재 | E9: =+'[1]5월'!$AE$7/1000 -> 121.05541 | F9: =+'[2]5월'!$AN$7/1000 -> 99.315 | G9: =+F9-E9 -> -21.740415 | H9: =+'[3]5월'!$AN$7/1000 -> 67.558 | I9: =+F9-H9 -> 31.757 | J9: =+[4]손익총괄!J9+E9 -> 380.22378 | K9: =+[4]손익총괄!K9+F9 -> 420.375 | L9: =+K9-J9 -> 40.151225 | M9: =+[4]손익총괄!M9+H9 -> 312.89 | N9: =+K9-M9 -> 107.485 | Q9: 물량 | R9: 수도권 | S9: =+[5]수도권!$T$5/1000 -> 125.5 | T9: =+[5]수도권!$U$5/1000 -> 120.114 | U9: =+T9-S9 -> -5.386 | V9: =+[6]수도권!$T$5/1000 -> 151.045 | W9: =+T9-V9 -> -30.931 | AA9: =+D9 -> 골재 | AB9: =+E9 -> 121.05541 | AC9: =+F9 -> 99.315 | AD9: =+AC9-AB9 -> -21.740415 | AE9: =+H9 -> 67.558 | AF9: =+AC9-AE9 -> 31.757 | AG9: =+J9 -> 380.22378 | AH9: =+K9 -> 420.375 | AI9: =+AH9-AG9 -> 40.151225 | AJ9: =+M9 -> 312.89 | AK9: =+AH9-AJ9 -> 107.485
C10: 매출 | D10: 레미콘 | E10: =+'[1]5월'!$Z$8/1000 -> 32099.301 | F10: =+'[2]5월'!$Z$8/1000 -> 35125.944 | G10: =+F10-E10 -> 3026.6423 | H10: =+'[3]5월'!$Z$8/1000 -> 35821.723 | I10: =+F10-H10 -> -695.77882 | J10: =+[4]손익총괄!J10+E10 -> 139759.55 | K10: =+[4]손익총괄!K10+F10 -> 149461.82 | L10: =+K10-J10 -> 9702.2703 | M10: =+[4]손익총괄!M10+H10 -> 155858.27 | N10: =+K10-M10 -> -6396.4468 | R10: 영남권 | S10: =+[5]영남권!$T$5/1000 -> 132 | T10: =+[5]영남권!$U$5/1000 -> 158.134 | U10: =+T10-S10 -> 26.134 | V10: =+[6]영남권!$T$5/1000 -> 145.6445 | W10: =+T10-V10 -> 12.4895 | Z10: 매출액 | AA10: =+D10 -> 레미콘 | AB10: =+E10/100 -> 320.99301 | AC10: =+F10/100 -> 351.25944 | AD10: =+AC10-AB10 -> 30.266423 | AE10: =+H10/100 -> 358.21723 | AF10: =+AC10-AE10 -> -6.9577882 | AG10: =+J10/100 -> 1397.5955 | AH10: =+K10/100 -> 1494.6182 | AI10: =+AH10-AG10 -> 97.022703 | AJ10: =+M10/100 -> 1558.5827 | AK10: =+AH10-AJ10 -> -63.964468
D11: 건자재 | E11: =+'[1]5월'!$AA$8/1000 -> 9285.6884 | F11: =+'[2]5월'!$AO$8/1000 -> 9774.8209 | G11: =+F11-E11 -> 489.13246 | H11: =+'[3]5월'!$AO$8/1000 -> 9029.1236 | I11: =+F11-H11 -> 745.69729 | J11: =+[4]손익총괄!J11+E11 -> 43422.461 | K11: =+[4]손익총괄!K11+F11 -> 41530.393 | L11: =+K11-J11 -> -1892.0677 | M11: =+[4]손익총괄!M11+H11 -> 50400.813 | N11: =+K11-M11 -> -8870.4199 | R11: 중부권 | S11: =+[5]중부권!$T$5/1000 -> 56.5 | T11: =+[5]중부권!$U$5/1000 -> 68.881 | U11: =+T11-S11 -> 12.381 | V11: =+[6]중부권!$T$5/1000 -> 67.712 | W11: =+T11-V11 -> 1.169 | AA11: =+D11 -> 건자재 | AB11: =+E11/100 -> 92.856884 | AC11: =+F11/100 -> 97.748209 | AD11: =+AC11-AB11 -> 4.8913246 | AE11: =+H11/100 -> 90.291236 | AF11: =+AC11-AE11 -> 7.4569729 | AG11: =+J11/100 -> 434.22461 | AH11: =+K11/100 -> 415.30393 | AI11: =+AH11-AG11 -> -18.920677 | AJ11: =+M11/100 -> 504.00813 | AK11: =+AH11-AJ11 -> -88.704199
D12: 골재 | E12: =+'[1]5월'!$AE$8/1000 -> 2182.0862 | F12: =+'[2]5월'!$AN$8/1000 -> 1975.778 | G12: =+F12-E12 -> -206.30819 | H12: =+'[3]5월'!$AN$8/1000 -> 1320.446 | I12: =+F12-H12 -> 655.332 | J12: =+[4]손익총괄!J12+E12 -> 7746.3091 | K12: =+[4]손익총괄!K12+F12 -> 8504.2076 | L12: =+K12-J12 -> 757.89848 | M12: =+[4]손익총괄!M12+H12 -> 5965.7549 | N12: =+K12-M12 -> 2538.4527 | Q12: 계 | S12: =SUM(S9:S11) -> 314 | T12: =SUM(T9:T11) -> 347.129 | U12: =+T12-S12 -> 33.129 | V12: =SUM(V9:V11) -> 364.4015 | W12: =+T12-V12 -> -17.2725 | AA12: =+D12 -> 골재 | AB12: =+E12/100 -> 21.820862 | AC12: =+F12/100 -> 19.75778 | AD12: =+AC12-AB12 -> -2.0630819 | AE12: =+H12/100 -> 13.20446 | AF12: =+AC12-AE12 -> 6.55332 | AG12: =+J12/100 -> 77.463091 | AH12: =+K12/100 -> 85.042076 | AI12: =+AH12-AG12 -> 7.5789848 | AJ12: =+M12/100 -> 59.657549 | AK12: =+AH12-AJ12 -> 25.384527
D13: 기타 | E13: =+'[1]5월'!$E$8/1000-E10-E11-E12 -> 164.9075 | F13: =+'[2]5월'!$F$8/1000-F10-F11-F12 -> 166.22714 | G13: =+F13-E13 -> 1.3196357 | H13: =+'[3]5월'!$F$8/1000-H10-H11-H12 -> 330.12234 | I13: =+F13-H13 -> -163.8952 | J13: =+[4]손익총괄!J13+E13 -> 824.5375 | K13: =+[4]손익총괄!K13+F13 -> 825.58077 | L13: =+K13-J13 -> 1.0432663 | M13: =+[4]손익총괄!M13+H13 -> 1027.6547 | N13: =+K13-M13 -> -202.07393 | Q13: 판매단가 | R13: 수도권 | S13: =+[5]수도권!$T$61 -> 100452.98 | T13: =+[5]수도권!$U$61 -> 99353.382 | U13: =+T13-S13 -> -1099.6013 | V13: =+[6]수도권!$Q$85 -> 95385.129 | W13: =+T13-V13 -> 3968.2529 | AA13: =+D13 -> 기타 | AB13: =+E13/100 -> 1.649075 | AC13: =+F13/100 -> 1.6622714 | AD13: =+AC13-AB13 -> 0.013196357 | AE13: =+H13/100 -> 3.3012234 | AF13: =+AC13-AE13 -> -1.638952 | AG13: =+J13/100 -> 8.245375 | AH13: =+K13/100 -> 8.2558077 | AI13: =+AH13-AG13 -> 0.010432663 | AJ13: =+M13/100 -> 10.276547 | AK13: =+AH13-AJ13 -> -2.0207393
A14: =+F14/E14 -> 1.0757063 | B14: =+K14/J14 -> 1.0446885 | C14: 계 | E14: =SUM(E10:E13) -> 43731.984 | F14: =SUM(F10:F13) -> 47042.77 | G14: =+F14-E14 -> 3310.7862 | H14: =SUM(H10:H13) -> 46501.414 | I14: =+F14-H14 -> 541.35527 | J14: =SUM(J10:J13) -> 191752.86 | K14: =SUM(K10:K13) -> 200322.01 | L14: =+K14-J14 -> 8569.1443 | M14: =SUM(M10:M13) -> 213252.49 | N14: =+K14-M14 -> -12930.488 | R14: 영남권 | S14: =+[5]영남권!$T$61 -> 102187.09 | T14: =+[5]영남권!$U$61 -> 100729.73 | U14: =+T14-S14 -> -1457.3602 | V14: =+[6]영남권!$Q$85 -> 99395.409 | W14: =+T14-V14 -> 1334.324 | AA14: 계 | AB14: =SUM(AB10:AB13) -> 437.31984 | AC14: =SUM(AC10:AC13) -> 470.4277 | AD14: =+AC14-AB14 -> 33.107862 | AE14: =SUM(AE10:AE13) -> 465.01414 | AF14: =+AC14-AE14 -> 5.4135527 | AG14: =SUM(AG10:AG13) -> 1917.5286 | AH14: =SUM(AH10:AH13) -> 2003.2201 | AI14: =+AH14-AG14 -> 85.691443 | AJ14: =SUM(AJ10:AJ13) -> 2132.5249 | AK14: =+AH14-AJ14 -> -129.30488
C15: 매출원가 | D15: 레미콘 | E15: =+('[1]5월'!$Z$10+'[1]5월'!$Z$19)/1000 -> 26262.49 | F15: =+('[2]5월'!$Z$10+'[2]5월'!$Z$19)/1000 -> 29394.123 | G15: =+F15-E15 -> 3131.6329 | H15: =+('[3]5월'!$Z$10+'[3]5월'!$Z$19)/1000 -> 28329.41 | I15: =+F15-H15 -> 1064.7136 | J15: =+[4]손익총괄!J15+E15 -> 118019.71 | K15: =+[4]손익총괄!K15+F15 -> 128726.38 | L15: =+K15-J15 -> 10706.665 | M15: =+[4]손익총괄!M15+H15 -> 128663.02 | N15: =+K15-M15 -> 63.354879 | R15: 중부권 | S15: =+[5]중부권!$T$61 -> 106261.16 | T15: =+[5]중부권!$U$61 -> 105549.17 | U15: =+T15-S15 -> -711.9888 | V15: =+[6]중부권!$Q$85 -> 102538.02 | W15: =+T15-V15 -> 3011.1507 | Z15: 영업이익 | AA15: =+D30 -> 레미콘 | AB15: =+E30/100 -> 51.87057 | AC15: =+F30/100 -> 50.627821 | AD15: =+AC15-AB15 -> -1.2427489 | AE15: =+H30/100 -> 68.29182 | AF15: =+AC15-AE15 -> -17.663999 | AG15: =+J30/100 -> 184.29961 | AH15: =+K30/100 -> 174.11416 | AI15: =+AH15-AG15 -> -10.185452 | AJ15: =+M30/100 -> 238.68507 | AK15: =+AH15-AJ15 -> -64.570915
D16: 건자재 | E16: =+('[1]5월'!$AA$10+'[1]5월'!$AA$19)/1000 -> 9048.0626 | F16: =+('[2]5월'!$AO$10+'[2]5월'!$AO$19)/1000 -> 9519.8983 | G16: =+F16-E16 -> 471.83575 | H16: =+('[3]5월'!$AO$10+'[3]5월'!$AO$19)/1000 -> 8861.8125 | I16: =+F16-H16 -> 658.08581 | J16: =+[4]손익총괄!J16+E16 -> 42310.511 | K16: =+[4]손익총괄!K16+F16 -> 40578.709 | L16: =+K16-J16 -> -1731.802 | M16: =+[4]손익총괄!M16+H16 -> 49421.318 | N16: =+K16-M16 -> -8842.609 | Q16: 계 | S16: =+[5]합계!$T$61 -> 102227.07 | T16: =+[5]합계!$U$61 -> 101219.55 | U16: =+T16-S16 -> -1007.5208 | V16: =+[6]합계!$Q$85 -> 98307.132 | W16: =+T16-V16 -> 2912.4218 | AA16: =+D31 -> % | AB16: =+E31 -> 0.16159408 | AC16: =+F31 -> 0.14413227 | AD16: =+AC16-AB16 -> -0.017461805 | AE16: =+H31 -> 0.1906436 | AF16: =+AC16-AE16 -> -0.046511323 | AG16: =+J31 -> 0.13186906 | AH16: =+K31 -> 0.11649407 | AI16: =+AH16-AG16 -> -0.015374993 | AJ16: =+M31 -> 0.15314239 | AK16: =+AH16-AJ16 -> -0.036648318
D17: 골재 | E17: =+('[1]5월'!$AE$10+'[1]5월'!$AE$19)/1000 -> 1923.881 | F17: =+('[2]5월'!$AN$10+'[2]5월'!$AN$19)/1000 -> 1758.9883 | G17: =+F17-E17 -> -164.89275 | H17: =+('[3]5월'!$AN$10+'[3]5월'!$AN$19)/1000 -> 1144.3205 | I17: =+F17-H17 -> 614.66774 | J17: =+[4]손익총괄!J17+E17 -> 7047.2687 | K17: =+[4]손익총괄!K17+F17 -> 7535.7403 | L17: =+K17-J17 -> 488.47165 | M17: =+[4]손익총괄!M17+H17 -> 5245.7058 | N17: =+K17-M17 -> 2290.0345 | Q17: 공헌이익 | R17: 수도권 | S17: =+[5]수도권!$Q$90 -> 22934.524 | T17: =+[5]수도권!$R$90 -> 19119.781 | U17: =+T17-S17 -> -3814.7431 | V17: =+[6]수도권!$Q$90 -> 22765.68 | W17: =+T17-V17 -> -3645.8994 | AA17: =+D32 -> 건자재 | AB17: =+E32/100 -> 1.1354778 | AC17: =+F32/100 -> 1.2236803 | AD17: =+AC17-AB17 -> 0.088202437 | AE17: =+H32/100 -> 0.54266285 | AF17: =+AC17-AE17 -> 0.68101742 | AG17: =+J32/100 -> 4.8125683 | AH17: =+K32/100 -> 2.6495259 | AI17: =+AH17-AG17 -> -2.1630423 | AJ17: =+M32/100 -> 3.7686907 | AK17: =+AH17-AJ17 -> -1.1191647
D18: 기타 | E18: =+('[1]5월'!$E$10+'[1]5월'!$E$19)/1000-E15-E16-E17 -> 65.348898 | F18: =+('[2]5월'!$F$10+'[2]5월'!$F$19)/1000-F15-F16-F17 -> 31.483638 | G18: =+F18-E18 -> -33.86526 | H18: =+('[3]5월'!$F$10+'[3]5월'!$F$19)/1000-H15-H16-H17 -> 184.36645 | I18: =+F18-H18 -> -152.88281 | J18: =+[4]손익총괄!J18+E18 -> 237.96292 | K18: =+[4]손익총괄!K18+F18 -> 131.40672 | L18: =+K18-J18 -> -106.5562 | M18: =+[4]손익총괄!M18+H18 -> 240.47014 | N18: =+K18-M18 -> -109.06342 | R18: 영남권 | S18: =+[5]영남권!$Q$90 -> 26998.986 | T18: =+[5]영남권!$R$90 -> 22869.321 | U18: =+T18-S18 -> -4129.6647 | V18: =+[6]영남권!$Q$90 -> 28232.721 | W18: =+T18-V18 -> -5363.4004 | AA18: =+D33 -> 골재 | AB18: =+E33/100 -> 2.2242641 | AC18: =+F33/100 -> 1.7157908 | AD18: =+AC18-AB18 -> -0.50847329 | AE18: =+H33/100 -> 0.79444908 | AF18: =+AC18-AE18 -> 0.92134169 | AG18: =+J33/100 -> 3.3114998 | AH18: =+K33/100 -> 7.4457722 | AI18: =+AH18-AG18 -> 4.1342724 | AJ18: =+M33/100 -> 5.2880246 | AK18: =+AH18-AJ18 -> 2.1577476
C19: 계 | E19: =SUM(E15:E18) -> 37299.783 | F19: =SUM(F15:F18) -> 40704.493 | G19: =+F19-E19 -> 3404.7106 | H19: =SUM(H15:H18) -> 38519.909 | I19: =+F19-H19 -> 2184.5843 | J19: =SUM(J15:J18) -> 167615.46 | K19: =SUM(K15:K18) -> 176972.23 | L19: =+K19-J19 -> 9356.7784 | M19: =SUM(M15:M18) -> 183570.52 | N19: =+K19-M19 -> -6598.283 | R19: 중부권 | S19: =+[5]중부권!$Q$90 -> 30676.188 | T19: =+[5]중부권!$R$90 -> 31197.021 | U19: =+T19-S19 -> 520.83252 | V19: =+[6]중부권!$Q$90 -> 32814.61 | W19: =+T19-V19 -> -1617.5897 | AA19: =+D34 -> 기타 | AB19: =+E34/100 -> -11.441403 | AC19: =+F34/100 -> -11.39437 | AD19: =+AC19-AB19 -> 0.047033704 | AE19: =+H34/100 -> -9.4452053 | AF19: =+AC19-AE19 -> -1.9491642 | AG19: =+J34/100 -> -60.960159 | AH19: =+K34/100 -> -77.50259 | AI19: =+AH19-AG19 -> -16.542431 | AJ19: =+M34/100 -> -51.954273 | AK19: =+AH19-AJ19 -> -25.548317
C20: 매출이익 | D20: 레미콘 | E20: =+E10-E15 -> 5836.8112 | F20: =+F10-F15 -> 5731.8206 | G20: =+F20-E20 -> -104.99056 | H20: =+H10-H15 -> 7492.313 | I20: =+F20-H20 -> -1760.4924 | J20: =+J10-J15 -> 21739.839 | K20: =+K10-K15 -> 20735.445 | L20: =+K20-J20 -> -1004.3946 | M20: =+M10-M15 -> 27195.246 | N20: =+K20-M20 -> -6459.8017 | Q20: 계 | S20: =+[5]합계!$Q$90 -> 26036.158 | T20: =+[5]합계!$R$90 -> 23245.012 | U20: =+T20-S20 -> -2791.1458 | V20: =+[6]합계!$Q$90 -> 26804.056 | W20: =+T20-V20 -> -3559.0437 | AA20: 계 | AB20: =+AB15+AB17+AB18+AB19 -> 43.788909 | AC20: =+AC15+AC17+AC18+AC19 -> 42.172923 | AD20: =+AC20-AB20 -> -1.6159861 | AE20: =+AE15+AE17+AE18+AE19 -> 60.183726 | AF20: =+AC20-AE20 -> -18.010804 | AG20: =+AG15+AG17+AG18+AG19 -> 131.46352 | AH20: =+AH15+AH17+AH18+AH19 -> 106.70687 | AI20: =+AH20-AG20 -> -24.756653 | AJ20: =+AJ15+AJ17+AJ18+AJ19 -> 195.78752 | AK20: =+AH20-AJ20 -> -89.080649
D21: 건자재 | E21: =+E11-E16 -> 237.62584 | F21: =+F11-F16 -> 254.92255 | G21: =+F21-E21 -> 17.296711 | H21: =+H11-H16 -> 167.31107 | I21: =+F21-H21 -> 87.611485 | J21: =+J11-J16 -> 1111.9505 | K21: =+K11-K16 -> 951.6847 | L21: =+K21-J21 -> -160.26579 | M21: =+M11-M16 -> 979.4956 | N21: =+K21-M21 -> -27.810896 | Q21: □ 건자재 | AA21: =+D36 -> % | AB21: =+E36 -> 0.10013017 | AC21: =+F36 -> 0.089648043 | AD21: =+G36 -> -0.010482125 | AE21: =+H36 -> 0.12942343 | AF21: =+I36 -> -0.039775389 | AG21: =+J36 -> 0.068558831 | AH21: =+K36 -> 0.053267671 | ... AK21: =+N36 -> -0.038542517
D22: 골재 | E22: =+E12-E17 -> 258.20516 | F22: =+F12-F17 -> 216.78972 | G22: =+F22-E22 -> -41.41544 | H22: =+H12-H17 -> 176.12546 | I22: =+F22-H22 -> 40.664259 | J22: =+J12-J17 -> 699.04041 | K22: =+K12-K17 -> 968.46724 | L22: =+K22-J22 -> 269.42683 | M22: =+M12-M17 -> 720.04905 | N22: =+K22-M22 -> 248.41819 | Q22: 구분 | S22: 계획 | T22: 실적 | U22: 계획대비 | V22: 전년 | W22: 전년대비 | Z22: * 5월누계 기타차이 : 대손 16억
D23: 기타 | E23: =+E13-E18 -> 99.558602 | F23: =+F13-F18 -> 134.7435 | G23: =+F23-E23 -> 35.184896 | H23: =+H13-H18 -> 145.75589 | I23: =+F23-H23 -> -11.012393 | J23: =+J13-J18 -> 586.57458 | K23: =+K13-K18 -> 694.17405 | L23: =+K23-J23 -> 107.59947 | M23: =+M13-M18 -> 787.18456 | N23: =+K23-M23 -> -93.010509 | Q23: 철강재 판매단가 | S23: =+'[7]5월'!$F$10 -> 977631.58 | T23: =+'[7]5월'!$G$10 -> 811389.31 | U23: =+T23-S23 -> -166242.27 | V23: =+'[8]5월'!$G$10 -> 1064717.6 | W23: =+T23-V23 -> -253328.34
C24: 계 | E24: =SUM(E20:E23) -> 6432.2008 | F24: =SUM(F20:F23) -> 6338.2764 | G24: =+F24-E24 -> -93.924389 | H24: =SUM(H20:H23) -> 7981.5054 | I24: =+F24-H24 -> -1643.2291 | J24: =SUM(J20:J23) -> 24137.405 | K24: =SUM(K20:K23) -> 23349.771 | L24: =+K24-J24 -> -787.63406 | M24: =SUM(M20:M23) -> 29681.976 | N24: =+K24-M24 -> -6332.2049 | Q24: 철강재 마진률 | S24: =+'[7]5월'!$F$15 -> 0.023295424 | T24: =+'[7]5월'!$G$15 -> 0.025679336 | U24: =+T24-S24 -> 0.0023839116 | V24: =+'[8]5월'!$G$15 -> 0.018355556 | W24: =+T24-V24 -> 0.0073237795
C25: 판관비 | D25: 레미콘 | E25: =+('[1]5월'!$Z$13+'[1]5월'!$Z$20)/1000 -> 649.75416 | F25: =+('[2]5월'!$Z$13+'[2]5월'!$Z$20)/1000 -> 669.0385 | G25: =+F25-E25 -> 19.284335 | H25: =+('[3]5월'!$Z$13+'[3]5월'!$Z$20)/1000 -> 663.13104 | I25: =+F25-H25 -> 5.907457 | J25: =+[4]손익총괄!J25+E25 -> 3309.8781 | K25: =+[4]손익총괄!K25+F25 -> 3324.0288 | L25: =+K25-J25 -> 14.150682 | M25: =+[4]손익총괄!M25+H25 -> 3326.739 | N25: =+K25-M25 -> -2.710173 | Q25: □ 골재
D26: 건자재 | E26: =+('[1]5월'!$AA$13+'[1]5월'!$AA$20)/1000 -> 124.07806 | F26: =+('[2]5월'!$AO$13+'[2]5월'!$AO$20)/1000 -> 132.55453 | G26: =+F26-E26 -> 8.476467 | H26: =+('[3]5월'!$AO$13+'[3]5월'!$AO$20)/1000 -> 113.04478 | I26: =+F26-H26 -> 19.509743 | J26: =+[4]손익총괄!J26+E26 -> 630.69367 | K26: =+[4]손익총괄!K26+F26 -> 686.73211 | L26: =+K26-J26 -> 56.038436 | M26: =+[4]손익총괄!M26+H26 -> 602.62653 | N26: =+K26-M26 -> 84.105574 | Q26: 구분 | S26: 계획 | T26: 실적 | U26: 계획대비 | V26: 전년 | W26: 전년대비
D27: 골재 | E27: =+('[1]5월'!$AE$13+'[1]5월'!$AE$20+'[1]5월'!$AE$22)/1000 -> 35.77875 | F27: =+('[2]5월'!$AN$13+'[2]5월'!$AN$20+'[2]5월'!$AN$22)/1000 -> 45.210639 | G27: =+F27-E27 -> 9.4318889 | H27: =+('[3]5월'!$AN$13+'[3]5월'!$AN$20+'[3]5월'!$AN$22)/1000 -> 96.680549 | I27: =+F27-H27 -> -51.46991 | J27: =+[4]손익총괄!J27+E27 -> 367.89044 | K27: =+[4]손익총괄!K27+F27 -> 223.89003 | L27: =+K27-J27 -> -144.00041 | M27: =+[4]손익총괄!M27+H27 -> 191.24659 | N27: =+K27-M27 -> 32.643435 | Q27: 판매량 | R27: 자가 | S27: =(+'[9]서부산크라샤(당월)'!$N$66+'[9]부산모래장(당월)'!$Q$48+'[9]부산크라샤(당월)'!$N$66)/1000 -> 58.255415 | T27: =(+'[9]서부산크라샤(당월)'!$O$66+'[9]부산모래장(당월)'!$R$48+'[9]부산크라샤(당월)'!$O$66)/1000 -> 60.876 | U27: =+T27-S27 -> 2.6205851 | V27: =('[10]부산골재(당월)'!$R$48+'[10]서부산골재(당월)'!$O$66+'[10]부산크라샤(당월)'!$O$66)/1000 -> 41.968 | W27: =+T27-V27 -> 18.908
D28: 기타 | E28: =+('[1]5월'!$E$13+'[1]5월'!$E$20)/1000-E25-E26-E27+('[1]5월'!$E$22/1000) -> 1243.6989 | F28: =+('[2]5월'!$F$13+'[2]5월'!$F$20)/1000-F25-F26-F27+'[2]5월'!$F$22/1000 -> 1274.1805 | G28: =+F28-E28 -> 30.481525 | H28: =+('[3]5월'!$F$13+'[3]5월'!$F$20)/1000-H25-H26-H27+'[3]5월'!$F$22/1000 -> 1090.2764 | I28: =+F28-H28 -> 183.90403 | J28: =+[4]손익총괄!J28+E28 -> 6682.5905 | K28: =+[4]손익총괄!K28+F28 -> 8444.433 | L28: =+K28-J28 -> 1761.8425 | M28: =+[4]손익총괄!M28+H28 -> 5982.6119 | N28: =+K28-M28 -> 2461.8212 | R28: 외판 | S28: =(+'[9]서부산크라샤(당월)'!$N$59+'[9]부산모래장(당월)'!$Q$47+'[9]부산크라샤(당월)'!$N$59)/1000 -> 62.8 | T28: =(+'[9]서부산크라샤(당월)'!$O$59+'[9]부산모래장(당월)'!$R$47+'[9]부산크라샤(당월)'!$O$59)/1000 -> 38.439 | U28: =+T28-S28 -> -24.361 | V28: =+('[10]부산골재(당월)'!$R$47+'[10]서부산골재(당월)'!$O$59+'[10]부산크라샤(당월)'!$O$59)/1000 -> 25.59 | W28: =+T28-V28 -> 12.849
C29: 계 | E29: =SUM(E25:E28) -> 2053.3099 | F29: =SUM(F25:F28) -> 2120.9841 | G29: =+F29-E29 -> 67.674216 | H29: =SUM(H25:H28) -> 1963.1328 | I29: =+F29-H29 -> 157.85132 | J29: =SUM(J25:J28) -> 10991.053 | K29: =SUM(K25:K28) -> 12679.084 | L29: =+K29-J29 -> 1688.0312 | M29: =SUM(M25:M28) -> 10103.224 | N29: =+K29-M29 -> 2575.86 | Q29: 합 계 | S29: =SUM(S27:S28) -> 121.05541 | T29: =SUM(T27:T28) -> 99.315 | U29: =+T29-S29 -> -21.740415 | V29: =SUM(V27:V28) -> 67.558 | W29: =+T29-V29 -> 31.757
C30: 영업이익 | D30: 레미콘 | E30: =+E20-E25 -> 5187.057 | F30: =+F20-F25 -> 5062.7821 | G30: =+F30-E30 -> -124.27489 | H30: =+H20-H25 -> 6829.182 | I30: =+F30-H30 -> -1766.3999 | J30: =+J20-J25 -> 18429.961 | K30: =+K20-K25 -> 17411.416 | L30: =+K30-J30 -> -1018.5452 | M30: =+M20-M25 -> 23868.507 | N30: =+K30-M30 -> -6457.0915 | Q30: □ 기타내역(영업이익)
D31: % | E31: =+E30/E10 -> 0.16159408 | F31: =+F30/F10 -> 0.14413227 | G31: =+F31-E31 -> -0.017461805 | H31: =+H30/H10 -> 0.1906436 | I31: =+F31-H31 -> -0.046511323 | J31: =+J30/J10 -> 0.13186906 | K31: =+K30/K10 -> 0.11649407 | L31: =+K31-J31 -> -0.015374993 | M31: =+M30/M10 -> 0.15314239 | N31: =+K31-M31 -> -0.036648318 | Q31: 구분 | S31: 계획 | T31: 실적 | U31: 계획대비 | V31: 전년 | W31: 전년대비
D32: 건자재 | E32: =+E21-E26 -> 113.54778 | F32: =+F21-F26 -> 122.36803 | G32: =+F32-E32 -> 8.8202437 | H32: =+H21-H26 -> 54.266285 | I32: =+F32-H32 -> 68.101742 | J32: =+J21-J26 -> 481.25683 | K32: =+K21-K26 -> 264.95259 | L32: =+K32-J32 -> -216.30423 | M32: =+M21-M26 -> 376.86907 | N32: =+K32-M32 -> -111.91647 | Q32: 레미콘임대 | S32: =+'사업장별(당월)'!T33 -> 72.165959 | T32: =+'사업장별(당월)'!U33 -> 68.93061 | U32: =+T32-S32 -> -3.235349 | V32: =+'사업장별(당월)'!W33 -> 55.160753 | W32: =+T32-V32 -> 13.769857
D33: 골재 | E33: =+E22-E27 -> 222.42641 | F33: =+F22-F27 -> 171.57908 | G33: =+F33-E33 -> -50.847329 | H33: =+H22-H27 -> 79.444908 | I33: =+F33-H33 -> 92.134169 | J33: =+J22-J27 -> 331.14998 | K33: =+K22-K27 -> 744.57722 | L33: =+K33-J33 -> 413.42724 | M33: =+M22-M27 -> 528.80246 | N33: =+K33-M33 -> 215.77476 | Q33: 임대 | S33: =+'사업장별(당월)'!T34 -> 62.030473 | T33: =+'사업장별(당월)'!U34 -> 63.574319 | U33: =+T33-S33 -> 1.5438457 | V33: =+'사업장별(당월)'!W34 -> 50.653987 | W33: =+T33-V33 -> 12.920332
D34: 기타 | E34: =+E23-E28 -> -1144.1403 | F34: =+F23-F28 -> -1139.437 | G34: =+F34-E34 -> 4.7033704 | H34: =+H23-H28 -> -944.52053 | I34: =+F34-H34 -> -194.91642 | J34: =+J23-J28 -> -6096.0159 | K34: =+K23-K28 -> -7750.259 | L34: =+K34-J34 -> -1654.2431 | M34: =+M23-M28 -> -5195.4273 | N34: =+K34-M34 -> -2554.8317 | Q34: 공통비 | S34: =+'사업장별(당월)'!T35 -> -1163.2875 | T34: =+'사업장별(당월)'!U35 -> -1157.1102 | U34: =+T34-S34 -> 6.1773143 | V34: =+'사업장별(당월)'!W35 -> -1023.2378 | W34: =+T34-V34 -> -133.87232
C35: 계 | E35: =SUM(E30,E32:E34) -> 4378.8909 | F35: =SUM(F30,F32:F34) -> 4217.2923 | G35: =+F35-E35 -> -161.59861 | H35: =SUM(H30,H32:H34) -> 6018.3726 | I35: =+F35-H35 -> -1801.0804 | J35: =SUM(J30,J32:J34) -> 13146.352 | K35: =SUM(K30,K32:K34) -> 10670.687 | L35: =+K35-J35 -> -2475.6653 | M35: =SUM(M30,M32:M34) -> 19578.752 | N35: =+K35-M35 -> -8908.0649 | Q35: 기타 | S35: =+S36-S32-S33-S34 -> -115.04929 | T35: =+T36-T32-T33-T34 -> -114.83173 | U35: =+T35-S35 -> 0.21755944 | V35: =+V36-V32-V33-V34 -> -27.097441 | W35: =+T35-V35 -> -87.734292
D36: % | E36: =+E35/E14 -> 0.10013017 | F36: =+F35/F14 -> 0.089648043 | G36: =+F36-E36 -> -0.010482125 | H36: =+H35/H14 -> 0.12942343 | I36: =+F36-H36 -> -0.039775389 | J36: =+J35/J14 -> 0.068558831 | K36: =+K35/K14 -> 0.053267671 | L36: =+K36-J36 -> -0.01529116 | M36: =+M35/M14 -> 0.091810188 | N36: =+K36-M36 -> -0.038542517 | Q36: 합계 | S36: =+'사업장별(당월)'!T41 -> -1144.1403 | T36: =+'사업장별(당월)'!U41 -> -1139.437 | U36: =+T36-S36 -> 4.7033704 | V36: =+'사업장별(당월)'!W41 -> -944.52053 | W36: =+T36-V36 -> -194.91642
E38: =+'[1]5월'!$E$26/1000 -> 4378.8909 | F38: =+'[2]5월'!$F$26/1000 -> 4217.2923 | H38: =+'[3]5월'!$F$26/1000 -> 6018.3726 | J38: =+[4]손익총괄!J38+E38 -> 13146.352 | K38: =+[4]손익총괄!K38+F38 -> 10670.687 | M38: =+[4]손익총괄!M38+H38 -> 19578.752
E39: =+E35=E38 -> TRUE | F39: =+F35=F38 -> FALSE | H39: =+H35=H38 -> FALSE | J39: =+J35=J38 -> TRUE | K39: =+K35=K38 -> TRUE | M39: =+M35=M38 -> TRUE
E40: =+E35-E38 -> 0 | F40: =+F35-F38 -> 0 | H40: =+H35-H38 -> 0 | J40: =+J35-J38 -> 2.7284841e-11 | K40: =+K35-K38 -> 0 | M40: =+M35-M38 -> -2.910383e-11

Sheet 사업장별(당월)
H3: □ 사업장별 손익실적(2024-05)
AG4: [단위 : 천㎥, 톤, 백만원]
H5: 구분 | J5: 물량 | O5: 매출 | T5: 영업이익(공통비 배부전) | Y5: 판매단가 | AB5: 변동비 | AE5: 공헌이익
J6: 계획 | K6: 실적 | L6: 차이 | M6: 전년 | N6: 차이 | O6: 계획 | P6: 실적 | Q6: 차이 | R6: 전년 | S6: 차이 | T6: 계획 | U6: 실적 | V6: 차이 | W6: 전년 | X6: 차이 | Y6: 계획 | Z6: 실적 | AA6: 전년 | AB6: 계획 | AC6: 실적 | AD6: 전년 | AE6: 계획 | AF6: 실적 | AG6: 전년
B7: 안양 | G7: =+I7 -> 안양 | H7: 레미콘 | I7: 안양 | J7: =+IFERROR(HLOOKUP($B7,'[1]5월'!$D$6:$BN$259,2,),)/1000 -> 44 | K7: =+IFERROR(HLOOKUP($B7,'[2]5월'!$F$6:$CP$99,2,),)/1000 -> 40.606 | L7: =+K7-J7 -> -3.394 | M7: =+IFERROR(HLOOKUP($B7,'[3]5월'!$F$6:$CC$57,2,),)/1000 -> 50.291 | N7: =+K7-M7 -> -9.685 | O7: =+IFERROR(HLOOKUP($B7,'[1]5월'!$D$6:$BN$259,3,),)/1000 -> 4457.8481 | P7: =+IFERROR(HLOOKUP($B7,'[2]5월'!$F$6:$CP$99,3,),)/1000 -> 4123.2946 | Q7: =+P7-O7 -> -334.55346 | R7: =+IFERROR(HLOOKUP($B7,'[3]5월'!$F$6:$CC$57,3,),)/1000 -> 4775.6819 | S7: =+P7-R7 -> -652.38727 | T7: =+IFERROR(HLOOKUP($B7,'[1]5월'!$D$6:$BN$259,16,),)/1000 -> 706.36516 | U7: =+IFERROR(HLOOKUP($B7,'[2]5월'!$F$6:$CP$99,16,),)/1000 -> 470.16461 | V7: =+U7-T7 -> -236.20055 | W7: =+IFERROR(HLOOKUP($B7,'[3]5월'!$F$6:$CC$57,16,),)/1000 -> 909.26044 | X7: =+U7-W7 -> -439.09583 | Y7: =+[5]안양!$Q$85 -> 101314.73 | Z7: =+[5]안양!$R$85 -> 101543.97 | AA7: =+[6]안양!$Q$85 -> 94943.662 | AB7: =+[5]안양!$Q$89 -> 78575.329 | AC7: =+[5]안양!$R$89 -> 82761.713 | AD7: =+[6]안양!$Q$89 -> 70931.39 | AE7: =+Y7-AB7 -> 22739.401 | AF7: =+Z7-AC7 -> 18782.261 | AG7: =+AA7-AD7 -> 24012.272
B8: 인천 | G8: =+I8 -> 인천 | H8: 직영 | I8: 인천 | J8: =+IFERROR(HLOOKUP($B8,'[1]5월'!$D$6:$BN$259,2,),)/1000 -> 35 | K8: =+IFERROR(HLOOKUP($B8,'[2]5월'!$F$6:$CP$99,2,),)/1000 -> 30.156 | L8: =+K8-J8 -> -4.844 | M8: =+IFERROR(HLOOKUP($B8,'[3]5월'!$F$6:$CC$57,2,),)/1000 -> 47.894 | N8: =+K8-M8 -> -17.738 | O8: =+IFERROR(HLOOKUP($B8,'[1]5월'!$D$6:$BN$259,3,),)/1000 -> 3594.5188 | P8: =+IFERROR(HLOOKUP($B8,'[2]5월'!$F$6:$CP$99,3,),)/1000 -> 2946.528 | Q8: =+P8-O8 -> -647.99085 | R8: =+IFERROR(HLOOKUP($B8,'[3]5월'!$F$6:$CC$57,3,),)/1000 -> 4757.6874 | S8: =+P8-R8 -> -1811.1595 | T8: =+IFERROR(HLOOKUP($B8,'[1]5월'!$D$6:$BN$259,16,),)/1000 -> 473.62349 | U8: =+IFERROR(HLOOKUP($B8,'[2]5월'!$F$6:$CP$99,16,),)/1000 -> 266.18334 | V8: =+U8-T8 -> -207.44015 | W8: =+IFERROR(HLOOKUP($B8,'[3]5월'!$F$6:$CC$57,16,),)/1000 -> 833.79834 | X8: =+U8-W8 -> -567.615 | Y8: =+[5]인천!$Q$85 -> 102700.54 | Z8: =+[5]인천!$R$85 -> 97709.509 | AA8: =+[6]인천!$Q$85 -> 99337.86 | AB8: =+[5]인천!$Q$89 -> 81104.52 | AC8: =+[5]인천!$R$89 -> 79830.372 | AD8: =+[6]인천!$Q$89 -> 75890.571 | AE8: =+Y8-AB8 -> 21596.017 | AF8: =+Z8-AC8 -> 17879.137 | AG8: =+AA8-AD8 -> 23447.289
B9: 파주 | G9: =+I9 -> 파주 | I9: 파주 | J9: =+IFERROR(HLOOKUP($B9,'[1]5월'!$D$6:$BN$259,2,),)/1000 -> 28 | K9: =+IFERROR(HLOOKUP($B9,'[2]5월'!$F$6:$CP$99,2,),)/1000 -> 28.609 | L9: =+K9-J9 -> 0.609 | M9: =+IFERROR(HLOOKUP($B9,'[3]5월'!$F$6:$CC$57,2,),)/1000 -> 31.208 | N9: =+K9-M9 -> -2.599 | O9: =+IFERROR(HLOOKUP($B9,'[1]5월'!$D$6:$BN$259,3,),)/1000 -> 2776.661 | P9: =+IFERROR(HLOOKUP($B9,'[2]5월'!$F$6:$CP$99,3,),)/1000 -> 2747.819 | Q9: =+P9-O9 -> -28.84203 | R9: =+IFERROR(HLOOKUP($B9,'[3]5월'!$F$6:$CC$57,3,),)/1000 -> 2894.0347 | S9: =+P9-R9 -> -146.21571 | T9: =+IFERROR(HLOOKUP($B9,'[1]5월'!$D$6:$BN$259,16,),)/1000 -> 439.03037 | U9: =+IFERROR(HLOOKUP($B9,'[2]5월'!$F$6:$CP$99,16,),)/1000 -> 254.15168 | V9: =+U9-T9 -> -184.87869 | W9: =+IFERROR(HLOOKUP($B9,'[3]5월'!$F$6:$CC$57,16,),)/1000 -> 405.53871 | X9: =+U9-W9 -> -151.38704 | Y9: =+[5]파주!$Q$85 -> 99166.464 | Z9: =+[5]파주!$R$85 -> 95934.038 | AA9: =+[6]파주!$Q$85 -> 92740.386 | AB9: =+[5]파주!$Q$89 -> 75452.936 | AC9: =+[5]파주!$R$89 -> 79393.119 | AD9: =+[6]파주!$Q$89 -> 73021.06 | AE9: =+Y9-AB9 -> 23713.528 | AF9: =+Z9-AC9 -> 16540.919 | AG9: =+AA9-AD9 -> 19719.327
B10: 김포 | G10: =+I10 -> 김포 | I10: 김포 | J10: =+IFERROR(HLOOKUP($B10,'[1]5월'!$D$6:$BN$259,2,),)/1000 -> 18.5 | K10: =+IFERROR(HLOOKUP($B10,'[2]5월'!$F$6:$CP$99,2,),)/1000 -> 20.743 | L10: =+K10-J10 -> 2.243 | M10: =+IFERROR(HLOOKUP($B10,'[3]5월'!$F$6:$CC$57,2,),)/1000 -> 21.652 | N10: =+K10-M10 -> -0.909 | O10: =+IFERROR(HLOOKUP($B10,'[1]5월'!$D$6:$BN$259,3,),)/1000 -> 1777.8215 | P10: =+IFERROR(HLOOKUP($B10,'[2]5월'!$F$6:$CP$99,3,),)/1000 -> 2113.5216 | Q10: =+P10-O10 -> 335.70006 | R10: =+IFERROR(HLOOKUP($B10,'[3]5월'!$F$6:$CC$57,3,),)/1000 -> 1977.1352 | S10: =+P10-R10 -> 136.38632 | T10: =+IFERROR(HLOOKUP($B10,'[1]5월'!$D$6:$BN$259,16,),)/1000 -> 295.88326 | U10: =+IFERROR(HLOOKUP($B10,'[2]5월'!$F$6:$CP$99,16,),)/1000 -> 354.65027 | V10: =+U10-T10 -> 58.767014 | W10: =+IFERROR(HLOOKUP($B10,'[3]5월'!$F$6:$CC$57,16,),)/1000 -> 330.11272 | X10: =+U10-W10 -> 24.537553 | Y10: =+[5]김포!$Q$85 -> 96098.459 | Z10: =+[5]김포!$R$85 -> 102058.93 | AA10: =+[6]김포!$Q$85 -> 91314.208 | AB10: =+[5]김포!$Q$89 -> 71346.583 | AC10: =+[5]김포!$R$89 -> 76893.344 | AD10: =+[6]김포!$Q$89 -> 68746.767 | AE10: =+Y10-AB10 -> 24751.877 | AF10: =+Z10-AC10 -> 25165.586 | AG10: =+AA10-AD10 -> 22567.441
B11: 부산 | G11: =+I11 -> 부산 | I11: 부산 | J11: =+IFERROR(HLOOKUP($B11,'[1]5월'!$D$6:$BN$259,2,),)/1000 -> 20 | K11: =+IFERROR(HLOOKUP($B11,'[2]5월'!$F$6:$CP$99,2,),)/1000 -> 28.1265 | L11: =+K11-J11 -> 8.1265 | M11: =+IFERROR(HLOOKUP($B11,'[3]5월'!$F$6:$CC$57,2,),)/1000 -> 24.945 | N11: =+K11-M11 -> 3.1815 | O11: =+IFERROR(HLOOKUP($B11,'[1]5월'!$D$6:$BN$259,3,),)/1000 -> 2152.006 | P11: =+IFERROR(HLOOKUP($B11,'[2]5월'!$F$6:$CP$99,3,),)/1000 -> 2986.1182 | Q11: =+P11-O11 -> 834.11222 | R11: =+IFERROR(HLOOKUP($B11,'[3]5월'!$F$6:$CC$57,3,),)/1000 -> 2521.2974 | S11: =+P11-R11 -> 464.82081 | T11: =+IFERROR(HLOOKUP($B11,'[1]5월'!$D$6:$BN$259,16,),)/1000 -> 326.75212 | U11: =+IFERROR(HLOOKUP($B11,'[2]5월'!$F$6:$CP$99,16,),)/1000 -> 411.9241 | V11: =+U11-T11 -> 85.17198 | W11: =+IFERROR(HLOOKUP($B11,'[3]5월'!$F$6:$CC$57,16,),)/1000 -> 485.37885 | X11: =+U11-W11 -> -73.454745 | Y11: =+[5]부산!$Q$85 -> 107600.3 | Z11: =+[5]부산!$R$85 -> 106167.43 | AA11: =+[6]부산!$Q$85 -> 101074.26 | AB11: =+[5]부산!$Q$89 -> 78668.111 | AC11: =+[5]부산!$R$89 -> 82923.267 | AD11: =+[6]부산!$Q$89 -> 71905.299 | AE11: =+Y11-AB11 -> 28932.188 | AF11: =+Z11-AC11 -> 23244.162 | AG11: =+AA11-AD11 -> 29168.96
B12: 서부산 | G12: =+I12 -> 서부산 | I12: 서부산 | J12: =+IFERROR(HLOOKUP($B12,'[1]5월'!$D$6:$BN$259,2,),)/1000 -> 26 | K12: =+IFERROR(HLOOKUP($B12,'[2]5월'!$F$6:$CP$99,2,),)/1000 -> 23.976 | L12: =+K12-J12 -> -2.024 | M12: =+IFERROR(HLOOKUP($B12,'[3]5월'!$F$6:$CC$57,2,),)/1000 -> 20.256 | N12: =+K12-M12 -> 3.72 | O12: =+IFERROR(HLOOKUP($B12,'[1]5월'!$D$6:$BN$259,3,),)/1000 -> 2684.6368 | P12: =+IFERROR(HLOOKUP($B12,'[2]5월'!$F$6:$CP$99,3,),)/1000 -> 2459.604 | Q12: =+P12-O12 -> -225.03282 | R12: =+IFERROR(HLOOKUP($B12,'[3]5월'!$F$6:$CC$57,3,),)/1000 -> 2129.6679 | S12: =+P12-R12 -> 329.9361 | T12: =+IFERROR(HLOOKUP($B12,'[1]5월'!$D$6:$BN$259,16,),)/1000 -> 492.80378 | U12: =+IFERROR(HLOOKUP($B12,'[2]5월'!$F$6:$CP$99,16,),)/1000 -> 360.2204 | V12: =+U12-T12 -> -132.58337 | W12: =+IFERROR(HLOOKUP($B12,'[3]5월'!$F$6:$CC$57,16,),)/1000 -> 367.48528 | X12: =+U12-W12 -> -7.264873 | Y12: =+[5]서부산!$Q$85 -> 103255.26 | Z12: =+[5]서부산!$R$85 -> 102586.09 | AA12: =+[6]서부산!$Q$85 -> 105137.63 | AB12: =+[5]서부산!$Q$89 -> 76205.201 | AC12: =+[5]서부산!$R$89 -> 78582.596 | AD12: =+[6]서부산!$Q$89 -> 77181.322 | AE12: =+Y12-AB12 -> 27050.061 | AF12: =+Z12-AC12 -> 24003.49 | AG12: =+AA12-AD12 -> 27956.311
B13: 김해 | G13: =+I13 -> 김해 | I13: 김해 | J13: =+IFERROR(HLOOKUP($B13,'[1]5월'!$D$6:$BN$259,2,),)/1000 -> 12 | K13: =+IFERROR(HLOOKUP($B13,'[2]5월'!$F$6:$CP$99,2,),)/1000 -> 14.268 | L13: =+K13-J13 -> 2.268 | M13: =+IFERROR(HLOOKUP($B13,'[3]5월'!$F$6:$CC$57,2,),)/1000 -> 14.873 | N13: =+K13-M13 -> -0.605 | O13: =+IFERROR(HLOOKUP($B13,'[1]5월'!$D$6:$BN$259,3,),)/1000 -> 1212.0024 | P13: =+IFERROR(HLOOKUP($B13,'[2]5월'!$F$6:$CP$99,3,),)/1000 -> 1329.1365 | Q13: =+P13-O13 -> 117.1341 | R13: =+IFERROR(HLOOKUP($B13,'[3]5월'!$F$6:$CC$57,3,),)/1000 -> 1507.0138 | S13: =+P13-R13 -> -177.8773 | T13: =+IFERROR(HLOOKUP($B13,'[1]5월'!$D$6:$BN$259,16,),)/1000 -> 158.87076 | U13: =+IFERROR(HLOOKUP($B13,'[2]5월'!$F$6:$CP$99,16,),)/1000 -> 76.218467 | V13: =+U13-T13 -> -82.652292 | W13: =+IFERROR(HLOOKUP($B13,'[3]5월'!$F$6:$CC$57,16,),)/1000 -> 257.13255 | X13: =+U13-W13 -> -180.91408 | Y13: =+[5]김해!$Q$85 -> 101000.2 | Z13: =+[5]김해!$R$85 -> 93214.324 | AA13: =+[6]김해!$Q$85 -> 101325.48 | AB13: =+[5]김해!$Q$89 -> 76489.955 | AC13: =+[5]김해!$R$89 -> 77424.481 | AD13: =+[6]김해!$Q$89 -> 75129.032 | AE13: =+Y13-AB13 -> 24510.245 | AF13: =+Z13-AC13 -> 15789.844 | AG13: =+AA13-AD13 -> 26196.444
B14: 정관 | G14: =+I14 -> 정관 | I14: 정관 | J14: =+IFERROR(HLOOKUP($B14,'[1]5월'!$D$6:$BN$259,2,),)/1000 -> 18 | K14: =+IFERROR(HLOOKUP($B14,'[2]5월'!$F$6:$CP$99,2,),)/1000 -> 24.315 | L14: =+K14-J14 -> 6.315 | M14: =+IFERROR(HLOOKUP($B14,'[3]5월'!$F$6:$CC$57,2,),)/1000 -> 18.999 | N14: =+K14-M14 -> 5.316 | O14: =+IFERROR(HLOOKUP($B14,'[1]5월'!$D$6:$BN$259,3,),)/1000 -> 1872 | P14: =+IFERROR(HLOOKUP($B14,'[2]5월'!$F$6:$CP$99,3,),)/1000 -> 2465.0836 | Q14: =+P14-O14 -> 593.0836 | R14: =+IFERROR(HLOOKUP($B14,'[3]5월'!$F$6:$CC$57,3,),)/1000 -> 1919.6708 | S14: =+P14-R14 -> 545.4128 | T14: =+IFERROR(HLOOKUP($B14,'[1]5월'!$D$6:$BN$259,16,),)/1000 -> 267.50167 | U14: =+IFERROR(HLOOKUP($B14,'[2]5월'!$F$6:$CP$99,16,),)/1000 -> 313.18669 | V14: =+U14-T14 -> 45.685018 | W14: =+IFERROR(HLOOKUP($B14,'[3]5월'!$F$6:$CC$57,16,),)/1000 -> 303.63124 | X14: =+U14-W14 -> 9.55545 | Y14: =+[5]정관!$Q$85 -> 104000 | Z14: =+[5]정관!$R$85 -> 101381.19 | AA14: =+[6]정관!$Q$85 -> 101040.62 | AB14: =+[5]정관!$Q$89 -> 78533.163 | AC14: =+[5]정관!$R$89 -> 80646.065 | AD14: =+[6]정관!$Q$89 -> 75177.279 | AE14: =+Y14-AB14 -> 25466.837 | AF14: =+Z14-AC14 -> 20735.124 | AG14: =+AA14-AD14 -> 25863.344
B15: 양산 | G15: =+I15 -> 양산 | I15: 양산 | J15: =+IFERROR(HLOOKUP($B15,'[1]5월'!$D$6:$BN$259,2,),)/1000 -> 11.5 | K15: =+IFERROR(HLOOKUP($B15,'[2]5월'!$F$6:$CP$99,2,),)/1000 -> 14.568 | L15: =+K15-J15 -> 3.068 | M15: =+IFERROR(HLOOKUP($B15,'[3]5월'!$F$6:$CC$57,2,),)/1000 -> 14.522 | N15: =+K15-M15 -> 0.046 | O15: =+IFERROR(HLOOKUP($B15,'[1]5월'!$D$6:$BN$259,3,),)/1000 -> 1112.7961 | P15: =+IFERROR(HLOOKUP($B15,'[2]5월'!$F$6:$CP$99,3,),)/1000 -> 1362.5258 | Q15: =+P15-O15 -> 249.72969 | R15: =+IFERROR(HLOOKUP($B15,'[3]5월'!$F$6:$CC$57,3,),)/1000 -> 1391.9045 | S15: =+P15-R15 -> -29.37872 | T15: =+IFERROR(HLOOKUP($B15,'[1]5월'!$D$6:$BN$259,16,),)/1000 -> 162.37087 | U15: =+IFERROR(HLOOKUP($B15,'[2]5월'!$F$6:$CP$99,16,),)/1000 -> 152.34023 | V15: =+U15-T15 -> -10.030637 | W15: =+IFERROR(HLOOKUP($B15,'[3]5월'!$F$6:$CC$57,16,),)/1000 -> 269.39112 | X15: =+U15-W15 -> -117.05089 | Y15: =+[5]양산!$Q$85 -> 96764.877 | Z15: =+[5]양산!$R$85 -> 93528.678 | AA15: =+[6]양산!$Q$85 -> 95847.989 | AB15: =+[5]양산!$Q$89 -> 70825.613 | AC15: =+[5]양산!$R$89 -> 73905.509 | AD15: =+[6]양산!$Q$89 -> 68016.334 | AE15: =+Y15-AB15 -> 25939.264 | AF15: =+Z15-AC15 -> 19623.169 | AG15: =+AA15-AD15 -> 27831.656
B16: 창원 | G16: =+I16 -> 창원 | I16: 창원 | J16: =+IFERROR(HLOOKUP($B16,'[1]5월'!$D$6:$BN$259,2,),)/1000 -> 18 | K16: =+IFERROR(HLOOKUP($B16,'[2]5월'!$F$6:$CP$99,2,),)/1000 -> 20.1685 | L16: =+K16-J16 -> 2.1685 | M16: =+IFERROR(HLOOKUP($B16,'[3]5월'!$F$6:$CC$57,2,),)/1000 -> 19.665 | N16: =+K16-M16 -> 0.5035 | O16: =+IFERROR(HLOOKUP($B16,'[1]5월'!$D$6:$BN$259,3,),)/1000 -> 1829.284 | P16: =+IFERROR(HLOOKUP($B16,'[2]5월'!$F$6:$CP$99,3,),)/1000 -> 1990.1033 | Q16: =+P16-O16 -> 160.8193 | R16: =+IFERROR(HLOOKUP($B16,'[3]5월'!$F$6:$CC$57,3,),)/1000 -> 1950.5857 | S16: =+P16-R16 -> 39.5176 | T16: =+IFERROR(HLOOKUP($B16,'[1]5월'!$D$6:$BN$259,16,),)/1000 -> 336.50848 | U16: =+IFERROR(HLOOKUP($B16,'[2]5월'!$F$6:$CP$99,16,),)/1000 -> 309.32629 | V16: =+U16-T16 -> -27.182186 | W16: =+IFERROR(HLOOKUP($B16,'[3]5월'!$F$6:$CC$57,16,),)/1000 -> 470.38098 | X16: =+U16-W16 -> -161.05469 | Y16: =+[5]창원!$Q$85 -> 101626.89 | Z16: =+[5]창원!$R$85 -> 98673.838 | AA16: =+[6]창원!$Q$85 -> 99190.73 | AB16: =+[5]창원!$Q$89 -> 72259.836 | AC16: =+[5]창원!$R$89 -> 74167.145 | AD16: =+[6]창원!$Q$89 -> 65843.598 | AE16: =+Y16-AB16 -> 29367.053 | AF16: =+Z16-AC16 -> 24506.693 | AG16: =+AA16-AD16 -> 33347.132
B17: 대구 | G17: =+I17 -> 대구 | I17: 대구 | J17: =+IFERROR(HLOOKUP($B17,'[1]5월'!$D$6:$BN$259,2,),)/1000 -> 16.5 | K17: =+IFERROR(HLOOKUP($B17,'[2]5월'!$F$6:$CP$99,2,),)/1000 -> 20.795 | L17: =+K17-J17 -> 4.295 | M17: =+IFERROR(HLOOKUP($B17,'[3]5월'!$F$6:$CC$57,2,),)/1000 -> 22.4465 | N17: =+K17-M17 -> -1.6515 | O17: =+IFERROR(HLOOKUP($B17,'[1]5월'!$D$6:$BN$259,3,),)/1000 -> 1613.04 | P17: =+IFERROR(HLOOKUP($B17,'[2]5월'!$F$6:$CP$99,3,),)/1000 -> 2090.7307 | Q17: =+P17-O17 -> 477.6907 | R17: =+IFERROR(HLOOKUP($B17,'[3]5월'!$F$6:$CC$57,3,),)/1000 -> 2128.3753 | S17: =+P17-R17 -> -37.64455 | T17: =+IFERROR(HLOOKUP($B17,'[1]5월'!$D$6:$BN$259,16,),)/1000 -> 296.33176 | U17: =+IFERROR(HLOOKUP($B17,'[2]5월'!$F$6:$CP$99,16,),)/1000 -> 403.78828 | V17: =+U17-T17 -> 107.45652 | W17: =+IFERROR(HLOOKUP($B17,'[3]5월'!$F$6:$CC$57,16,),)/1000 -> 500.43847 | X17: =+U17-W17 -> -96.650187 | Y17: =+[5]대구!$Q$85 -> 97760 | Z17: =+[5]대구!$R$85 -> 100540.07 | AA17: =+[6]대구!$Q$85 -> 94819.916 | AB17: =+[5]대구!$Q$89 -> 69576.21 | AC17: =+[5]대구!$R$89 -> 73272.696 | AD17: =+[6]대구!$Q$89 -> 65452.775 | AE17: =+Y17-AB17 -> 28183.79 | AF17: =+Z17-AC17 -> 27267.372 | AG17: =+AA17-AD17 -> 29367.142
B18: 울산 | G18: =+I18 -> 울산 | I18: 울산 | J18: =+IFERROR(HLOOKUP($B18,'[1]5월'!$D$6:$BN$259,2,),)/1000 -> 10 | K18: =+IFERROR(HLOOKUP($B18,'[2]5월'!$F$6:$CP$99,2,),)/1000 -> 11.917 | L18: =+K18-J18 -> 1.917 | M18: =+IFERROR(HLOOKUP($B18,'[3]5월'!$F$6:$CC$57,2,),)/1000 -> 9.938 | N18: =+K18-M18 -> 1.979 | O18: =+IFERROR(HLOOKUP($B18,'[1]5월'!$D$6:$BN$259,3,),)/1000 -> 1012.931 | P18: =+IFERROR(HLOOKUP($B18,'[2]5월'!$F$6:$CP$99,3,),)/1000 -> 1241.1459 | Q18: =+P18-O18 -> 228.21485 | R18: =+IFERROR(HLOOKUP($B18,'[3]5월'!$F$6:$CC$57,3,),)/1000 -> 927.6298 | S18: =+P18-R18 -> 313.51605 | T18: =+IFERROR(HLOOKUP($B18,'[1]5월'!$D$6:$BN$259,16,),)/1000 -> 104.57265 | U18: =+IFERROR(HLOOKUP($B18,'[2]5월'!$F$6:$CP$99,16,),)/1000 -> 187.53756 | V18: =+U18-T18 -> 82.964905 | W18: =+IFERROR(HLOOKUP($B18,'[3]5월'!$F$6:$CC$57,16,),)/1000 -> 94.02573 | X18: =+U18-W18 -> 93.51183 | Y18: =+[5]울산!$Q$85 -> 101293.1 | Z18: =+[5]울산!$R$85 -> 104149.19 | AA18: =+[6]울산!$Q$85 -> 93352.209 | AB18: =+[5]울산!$Q$89 -> 77547.726 | AC18: =+[5]울산!$R$89 -> 78333.912 | AD18: =+[6]울산!$Q$89 -> 71376.176 | AE18: =+Y18-AB18 -> 23745.374 | AF18: =+Z18-AC18 -> 25815.274 | AG18: =+AA18-AD18 -> 21976.033
B19: 아산 | G19: =+I19 -> 아산 | I19: 아산 | J19: =+IFERROR(HLOOKUP($B19,'[1]5월'!$D$6:$BN$259,2,),)/1000 -> 24 | K19: =+IFERROR(HLOOKUP($B19,'[2]5월'!$F$6:$CP$99,2,),)/1000 -> 32.637 | L19: =+K19-J19 -> 8.637 | M19: =+IFERROR(HLOOKUP($B19,'[3]5월'!$F$6:$CC$57,2,),)/1000 -> 28.419 | N19: =+K19-M19 -> 4.218 | O19: =+IFERROR(HLOOKUP($B19,'[1]5월'!$D$6:$BN$259,3,),)/1000 -> 2424.0036 | P19: =+IFERROR(HLOOKUP($B19,'[2]5월'!$F$6:$CP$99,3,),)/1000 -> 3371.382 | Q19: =+P19-O19 -> 947.37838 | R19: =+IFERROR(HLOOKUP($B19,'[3]5월'!$F$6:$CC$57,3,),)/1000 -> 2791.0739 | S19: =+P19-R19 -> 580.30813 | T19: =+IFERROR(HLOOKUP($B19,'[1]5월'!$D$6:$BN$259,16,),)/1000 -> 390.82873 | U19: =+IFERROR(HLOOKUP($B19,'[2]5월'!$F$6:$CP$99,16,),)/1000 -> 681.32996 | V19: =+U19-T19 -> 290.50123 | W19: =+IFERROR(HLOOKUP($B19,'[3]5월'!$F$6:$CC$57,16,),)/1000 -> 618.01405 | X19: =+U19-W19 -> 63.315907 | Y19: =+[5]아산!$Q$85 -> 101000.15 | Z19: =+[5]아산!$R$85 -> 103299.38 | AA19: =+[6]아산!$Q$85 -> 98295.776 | AB19: =+[5]아산!$Q$89 -> 76007.141 | AC19: =+[5]아산!$R$89 -> 75203.707 | AD19: =+[6]아산!$Q$89 -> 69105.83 | AE19: =+Y19-AB19 -> 24993.009 | AF19: =+Z19-AC19 -> 28095.677 | AG19: =+AA19-AD19 -> 29189.946
B20: 전주 | G20: =+I20 -> 전주 | I20: 전주 | J20: =+IFERROR(HLOOKUP($B20,'[1]5월'!$D$6:$BN$259,2,),)/1000 -> 12 | K20: =+IFERROR(HLOOKUP($B20,'[2]5월'!$F$6:$CP$99,2,),)/1000 -> 14.1955 | L20: =+K20-J20 -> 2.1955 | M20: =+IFERROR(HLOOKUP($B20,'[3]5월'!$F$6:$CC$57,2,),)/1000 -> 11.7485 | N20: =+K20-M20 -> 2.447 | O20: =+IFERROR(HLOOKUP($B20,'[1]5월'!$D$6:$BN$259,3,),)/1000 -> 1246.4674 | P20: =+IFERROR(HLOOKUP($B20,'[2]5월'!$F$6:$CP$99,3,),)/1000 -> 1369.0424 | Q20: =+P20-O20 -> 122.57496 | R20: =+IFERROR(HLOOKUP($B20,'[3]5월'!$F$6:$CC$57,3,),)/1000 -> 1190.5726 | S20: =+P20-R20 -> 178.46976 | T20: =+IFERROR(HLOOKUP($B20,'[1]5월'!$D$6:$BN$259,16,),)/1000 -> 228.25969 | U20: =+IFERROR(HLOOKUP($B20,'[2]5월'!$F$6:$CP$99,16,),)/1000 -> 209.80582 | V20: =+U20-T20 -> -18.45387 | W20: =+IFERROR(HLOOKUP($B20,'[3]5월'!$F$6:$CC$57,16,),)/1000 -> 238.54564 | X20: =+U20-W20 -> -28.739819 | Y20: =+[5]전주!$Q$85 -> 103872.28 | Z20: =+[5]전주!$R$85 -> 96441.996 | AA20: =+[6]전주!$Q$85 -> 101338.26 | AB20: =+[5]전주!$Q$89 -> 72772.78 | AC20: =+[5]전주!$R$89 -> 70782.447 | AD20: =+[6]전주!$Q$89 -> 69906.24 | AE20: =+Y20-AB20 -> 31099.503 | AF20: =+Z20-AC20 -> 25659.549 | AG20: =+AA20-AD20 -> 31432.023
B21: 군산 | G21: =+I21 -> 군산 | I21: 군산 | J21: =+IFERROR(HLOOKUP($B21,'[1]5월'!$D$6:$BN$259,2,),)/1000 -> 7.5 | K21: =+IFERROR(HLOOKUP($B21,'[2]5월'!$F$6:$CP$99,2,),)/1000 -> 10.731 | L21: =+K21-J21 -> 3.231 | M21: =+IFERROR(HLOOKUP($B21,'[3]5월'!$F$6:$CC$57,2,),)/1000 -> 12.4205 | N21: =+K21-M21 -> -1.6895 | O21: =+IFERROR(HLOOKUP($B21,'[1]5월'!$D$6:$BN$259,3,),)/1000 -> 817.18473 | P21: =+IFERROR(HLOOKUP($B21,'[2]5월'!$F$6:$CP$99,3,),)/1000 -> 1218.0546 | Q21: =+P21-O21 -> 400.86987 | R21: =+IFERROR(HLOOKUP($B21,'[3]5월'!$F$6:$CC$57,3,),)/1000 -> 1246.3775 | S21: =+P21-R21 -> -28.3229 | T21: =+IFERROR(HLOOKUP($B21,'[1]5월'!$D$6:$BN$259,16,),)/1000 -> 214.3396 | U21: =+IFERROR(HLOOKUP($B21,'[2]5월'!$F$6:$CP$99,16,),)/1000 -> 349.47533 | V21: =+U21-T21 -> 135.13573 | W21: =+IFERROR(HLOOKUP($B21,'[3]5월'!$F$6:$CC$57,16,),)/1000 -> 380.93049 | X21: =+U21-W21 -> -31.455168 | Y21: =+[5]군산!$Q$85 -> 108957.96 | Z21: =+[5]군산!$R$85 -> 113508.02 | AA21: =+[6]군산!$Q$85 -> 100362.52 | AB21: =+[5]군산!$Q$89 -> 69303.186 | AC21: =+[5]군산!$R$89 -> 73381.874 | AD21: =+[6]군산!$Q$89 -> 61353.885 | AE21: =+Y21-AB21 -> 39654.779 | AF21: =+Z21-AC21 -> 40126.149 | AG21: =+AA21-AD21 -> 39008.638
B22: 원주 | G22: =+I22 -> 원주 | I22: 원주 | J22: =+IFERROR(HLOOKUP($B22,'[1]5월'!$D$6:$BN$259,2,),)/1000 -> 7 | K22: =+IFERROR(HLOOKUP($B22,'[2]5월'!$F$6:$CP$99,2,),)/1000 -> 7.601 | L22: =+K22-J22 -> 0.601 | M22: =+IFERROR(HLOOKUP($B22,'[3]5월'!$F$6:$CC$57,2,),)/1000 -> 6.1285 | N22: =+K22-M22 -> 1.4725 | O22: =+IFERROR(HLOOKUP($B22,'[1]5월'!$D$6:$BN$259,3,),)/1000 -> 755.3 | P22: =+IFERROR(HLOOKUP($B22,'[2]5월'!$F$6:$CP$99,3,),)/1000 -> 848.8332 | Q22: =+P22-O22 -> 93.5332 | R22: =+IFERROR(HLOOKUP($B22,'[3]5월'!$F$6:$CC$57,3,),)/1000 -> 639.6528 | S22: =+P22-R22 -> 209.1804 | T22: =+IFERROR(HLOOKUP($B22,'[1]5월'!$D$6:$BN$259,16,),)/1000 -> 165.56488 | U22: =+IFERROR(HLOOKUP($B22,'[2]5월'!$F$6:$CP$99,16,),)/1000 -> 211.34338 | V22: =+U22-T22 -> 45.778495 | W22: =+IFERROR(HLOOKUP($B22,'[3]5월'!$F$6:$CC$57,16,),)/1000 -> 133.62029 | X22: =+U22-W22 -> 77.723092 | Y22: =+[5]원주!$Q$85 -> 107900 | Z22: =+[5]원주!$R$85 -> 111673.89 | AA22: =+[6]원주!$Q$85 -> 104400.1 | AB22: =+[5]원주!$Q$89 -> 72409.2 | AC22: =+[5]원주!$R$89 -> 71854.954 | AD22: =+[6]원주!$Q$89 -> 68394.862 | AE22: =+Y22-AB22 -> 35490.8 | AF22: =+Z22-AC22 -> 39818.931 | AG22: =+AA22-AD22 -> 36005.236
B23: 제주 | G23: =+I23 -> 제주 | I23: 제주 | J23: =+IFERROR(HLOOKUP($B23,'[1]5월'!$D$6:$BN$259,2,),)/1000 -> 6 | K23: =+IFERROR(HLOOKUP($B23,'[2]5월'!$F$6:$CP$99,2,),)/1000 -> 3.7165 | L23: =+K23-J23 -> -2.2835 | M23: =+IFERROR(HLOOKUP($B23,'[3]5월'!$F$6:$CC$57,2,),)/1000 -> 8.9955 | N23: =+K23-M23 -> -5.279 | O23: =+IFERROR(HLOOKUP($B23,'[1]5월'!$D$6:$BN$259,3,),)/1000 -> 760.8 | P23: =+IFERROR(HLOOKUP($B23,'[2]5월'!$F$6:$CP$99,3,),)/1000 -> 463.02055 | Q23: =+P23-O23 -> -297.77945 | R23: =+IFERROR(HLOOKUP($B23,'[3]5월'!$F$6:$CC$57,3,),)/1000 -> 1073.3614 | S23: =+P23-R23 -> -610.34084 | T23: =+IFERROR(HLOOKUP($B23,'[1]5월'!$D$6:$BN$259,16,),)/1000 -> 127.44973 | U23: =+IFERROR(HLOOKUP($B23,'[2]5월'!$F$6:$CP$99,16,),)/1000 -> 51.135698 | V23: =+U23-T23 -> -76.314031 | W23: =+IFERROR(HLOOKUP($B23,'[3]5월'!$F$6:$CC$57,16,),)/1000 -> 231.49708 | X23: =+U23-W23 -> -180.36138 | Y23: =+[5]제주!$Q$85 -> 126800 | Z23: =+[5]제주!$R$85 -> 124585.11 | AA23: =+[6]제주!$Q$85 -> 119517.93 | AB23: =+[5]제주!$Q$89 -> 91078.011 | AC23: =+[5]제주!$R$89 -> 88417.978 | AD23: =+[6]제주!$Q$89 -> 83709.69 | AE23: =+Y23-AB23 -> 35721.989 | AF23: =+Z23-AC23 -> 36167.129 | AG23: =+AA23-AD23 -> 35808.245
G24: =+I24 -> 수도권 | I24: 수도권 | J24: =SUM(J7:J10) -> 125.5 | K24: =SUM(K7:K10) -> 120.114 | L24: =+K24-J24 -> -5.386 | M24: =SUM(M7:M10) -> 151.045 | N24: =+K24-M24 -> -30.931 | O24: =SUM(O7:O10) -> 12606.849 | P24: =SUM(P7:P10) -> 11931.163 | Q24: =+P24-O24 -> -675.68629 | R24: =SUM(R7:R10) -> 14404.539 | S24: =+P24-R24 -> -2473.3762 | T24: =SUM(T7:T10) -> 1914.9023 | U24: =SUM(U7:U10) -> 1345.1499 | V24: =+U24-T24 -> -569.75238 | W24: =SUM(W7:W10) -> 2478.7102 | X24: =+U24-W24 -> -1133.5603 | Y24: =+[5]수도권!$Q$85 -> 100452.98 | Z24: =+[5]수도권!$R$85 -> 99353.382 | AA24: =+[6]수도권!$Q$85 -> 95385.129 | AB24: =+[5]수도권!$Q$89 -> 77518.459 | AC24: =+[5]수도권!$R$89 -> 80233.601 | AD24: =+[6]수도권!$Q$89 -> 72619.449 | AE24: =+Y24-AB24 -> 22934.524 | AF24: =+Z24-AC24 -> 19119.781 | AG24: =+AA24-AD24 -> 22765.68
G25: =+I25 -> 영남권 | I25: 영남권 | J25: =SUM(J11:J18) -> 132 | K25: =SUM(K11:K18) -> 158.134 | L25: =+K25-J25 -> 26.134 | M25: =SUM(M11:M18) -> 145.6445 | N25: =+K25-M25 -> 12.4895 | O25: =SUM(O11:O18) -> 13488.696 | P25: =SUM(P11:P18) -> 15924.448 | Q25: =+P25-O25 -> 2435.7516 | R25: =SUM(R11:R18) -> 14476.145 | S25: =+P25-R25 -> 1448.3028 | T25: =SUM(T11:T18) -> 2145.7121 | U25: =SUM(U11:U18) -> 2214.542 | V25: =+U25-T25 -> 68.829936 | W25: =SUM(W11:W18) -> 2747.8642 | X25: =+U25-W25 -> -533.32219 | Y25: =+[5]영남권!$Q$85 -> 102187.09 | Z25: =+[5]영남권!$R$85 -> 100729.73 | AA25: =+[6]영남권!$Q$85 -> 99395.409 | AB25: =+[5]영남권!$Q$89 -> 75188.107 | AC25: =+[5]영남권!$R$89 -> 77860.412 | AD25: =+[6]영남권!$Q$89 -> 71162.688 | AE25: =+Y25-AB25 -> 26998.986 | AF25: =+Z25-AC25 -> 22869.321 | AG25: =+AA25-AD25 -> 28232.721
G26: =+I26 -> 중부권 | I26: 중부권 | J26: =SUM(J19:J23) -> 56.5 | K26: =SUM(K19:K23) -> 68.881 | L26: =+K26-J26 -> 12.381 | M26: =SUM(M19:M23) -> 67.712 | N26: =+K26-M26 -> 1.169 | O26: =SUM(O19:O23) -> 6003.7557 | P26: =SUM(P19:P23) -> 7270.3327 | Q26: =+P26-O26 -> 1266.577 | R26: =SUM(R19:R23) -> 6941.0381 | S26: =+P26-R26 -> 329.29455 | T26: =SUM(T19:T23) -> 1126.4426 | U26: =SUM(U19:U23) -> 1503.0902 | V26: =+U26-T26 -> 376.64755 | W26: =SUM(W19:W23) -> 1602.6076 | X26: =+U26-W26 -> -99.517372 | Y26: =+[5]중부권!$Q$85 -> 106261.16 | Z26: =+[5]중부권!$R$85 -> 105549.17 | AA26: =+[6]중부권!$Q$85 -> 102538.02 | AB26: =+[5]중부권!$Q$89 -> 75584.975 | AC26: =+[5]중부권!$R$89 -> 74352.154 | AD26: =+[6]중부권!$Q$89 -> 69723.413 | AE26: =+Y26-AB26 -> 30676.188 | AF26: =+Z26-AC26 -> 31197.021 | AG26: =+AA26-AD26 -> 32814.61
G27: =+K27/J27 -> 1.1055064 | H27: 레미콘 계 | J27: =SUM(J24:J26) -> 314 | K27: =SUM(K24:K26) -> 347.129 | L27: =+K27-J27 -> 33.129 | M27: =SUM(M24:M26) -> 364.4015 | N27: =+K27-M27 -> -17.2725 | O27: =SUM(O24:O26) -> 32099.301 | P27: =SUM(P24:P26) -> 35125.944 | Q27: =+P27-O27 -> 3026.6423 | R27: =SUM(R24:R26) -> 35821.723 | S27: =+P27-R27 -> -695.77882 | T27: =SUM(T24:T26) -> 5187.057 | U27: =SUM(U24:U26) -> 5062.7821 | V27: =+U27-T27 -> -124.27489 | W27: =SUM(W24:W26) -> 6829.182 | X27: =+U27-W27 -> -1766.3999 | Y27: =+[5]합계!$Q$85 -> 102227.07 | Z27: =+[5]합계!$R$85 -> 101219.55 | AA27: =+[6]합계!$Q$85 -> 98307.132 | AB27: =+[5]합계!$Q$89 -> 76190.917 | AC27: =+[5]합계!$R$89 -> 77974.542 | AD27: =+[6]합계!$Q$89 -> 71503.076 | AE27: =+Y27-AB27 -> 26036.158 | AF27: =+Z27-AC27 -> 23245.012 | AG27: =+AA27-AD27 -> 26804.056
B28: 건자재 | E28: 건자재영업 | G28: 건자재 | H28: 건자재 | J28: =+IFERROR(HLOOKUP($B28,'[1]5월'!$D$6:$BN$259,2,),) -> 7600 | K28: =+IFERROR(HLOOKUP($E28,'[2]5월'!$F$6:$CP$99,2,),) -> 9787.441 | L28: =+K28-J28 -> 2187.441 | M28: =+IFERROR(HLOOKUP($E28,'[3]5월'!$F$6:$CC$57,2,),) -> 7344.996 | N28: =+K28-M28 -> 2442.445 | O28: =+IFERROR(HLOOKUP($B28,'[1]5월'!$D$6:$BN$259,3,),)/1000 -> 9285.6884 | P28: =+IFERROR(HLOOKUP($E28,'[2]5월'!$F$6:$CP$99,3,),)/1000 -> 9774.8209 | Q28: =+P28-O28 -> 489.13246 | R28: =+IFERROR(HLOOKUP($E28,'[3]5월'!$F$6:$CC$57,3,),)/1000 -> 9029.1236 | S28: =+P28-R28 -> 745.69729 | T28: =+IFERROR(HLOOKUP($B28,'[1]5월'!$D$6:$BN$259,16,),)/1000 -> 113.54778 | U28: =+IFERROR(HLOOKUP($E28,'[2]5월'!$F$6:$CP$99,16,),)/1000 -> 122.36803 | V28: =+U28-T28 -> 8.8202437 | W28: =+IFERROR(HLOOKUP($E28,'[3]5월'!$F$6:$CC$57,16,),)/1000 -> 54.266285 | X28: =+U28-W28 -> 68.101742 | Y28: ■ 비고
B29: 부산모래장 | F29: 부산골재 | G29: =+I29 -> 부산모래장 | H29: 골재 | I29: 부산모래장 | J29: =+IFERROR(HLOOKUP($B29,'[1]5월'!$D$6:$BN$259,2,),)/1000 -> 28.019294 | K29: =+IFERROR(HLOOKUP($F29,'[2]5월'!$F$6:$CP$99,2,),)/1000 -> 25.913 | L29: =+K29-J29 -> -2.1062943 | M29: =+IFERROR(HLOOKUP($F29,'[3]5월'!$F$6:$CC$57,2,),)/1000 -> 31.026 | N29: =+K29-M29 -> -5.113 | O29: =+IFERROR(HLOOKUP($B29,'[1]5월'!$D$6:$BN$259,3,),)/1000 -> 795.68227 | P29: =+IFERROR(HLOOKUP($F29,'[2]5월'!$F$6:$CP$99,3,),)/1000 -> 748.562 | Q29: =+P29-O29 -> -47.120273 | R29: =+IFERROR(HLOOKUP($F29,'[3]5월'!$F$6:$CC$57,3,),)/1000 -> 895.312 | S29: =+P29-R29 -> -146.75 | T29: =+IFERROR(HLOOKUP($B29,'[1]5월'!$D$6:$BN$259,21,),)/1000 -> 59.719076 | U29: =+IFERROR(HLOOKUP($F29,'[2]5월'!$F$6:$CP$99,21,),)/1000 -> 42.923393 | V29: =+U29-T29 -> -16.795683 | W29: =+IFERROR(HLOOKUP($F29,'[3]5월'!$F$6:$CC$57,16,),)/1000 -> 46.37338 | X29: =+U29-W29 -> -3.449987
B30: 서부산크라샤 | F30: 서부산골재 | G30: =+I30 -> 서부산CR | I30: 서부산CR | J30: =+IFERROR(HLOOKUP($B30,'[1]5월'!$D$6:$BN$259,2,),)/1000 -> 51.226029 | K30: =+IFERROR(HLOOKUP($F30,'[2]5월'!$F$6:$CP$99,2,),)/1000 -> 26.574 | L30: =+K30-J30 -> -24.652029 | M30: =+IFERROR(HLOOKUP($F30,'[3]5월'!$F$6:$CC$57,2,),)/1000 -> 36.532 | N30: =+K30-M30 -> -9.958 | O30: =+IFERROR(HLOOKUP($B30,'[1]5월'!$D$6:$BN$259,3,),)/1000 -> 635.92591 | P30: =+IFERROR(HLOOKUP($F30,'[2]5월'!$F$6:$CP$99,3,),)/1000 -> 369.83 | Q30: =+P30-O30 -> -266.09591 | R30: =+IFERROR(HLOOKUP($F30,'[3]5월'!$F$6:$CC$57,3,),)/1000 -> 425.134 | S30: =+P30-R30 -> -55.304 | T30: =+IFERROR(HLOOKUP($B30,'[1]5월'!$D$6:$BN$259,21,),)/1000 -> 158.67488 | U30: =+IFERROR(HLOOKUP($F30,'[2]5월'!$F$6:$CP$99,21,),)/1000 -> 48.486048 | V30: =+U30-T30 -> -110.18883 | W30: =+IFERROR(HLOOKUP($F30,'[3]5월'!$F$6:$CC$57,16,),)/1000 -> 119.13245 | X30: =+U30-W30 -> -70.646404
B31: 부산크라샤 | F31: 부산크라샤 | G31: =+I31 -> 부산CR | I31: 부산CR | J31: =+IFERROR(HLOOKUP($B31,'[1]5월'!$D$6:$BN$259,2,),)/1000 -> 41.810091 | K31: =+IFERROR(HLOOKUP($F31,'[2]5월'!$F$6:$CP$99,2,),)/1000 -> 46.828 | L31: =+K31-J31 -> 5.0179086 | M31: =+IFERROR(HLOOKUP($F31,'[3]5월'!$F$6:$CC$57,2,),)/1000 -> 0 | N31: =+K31-M31 -> 46.828 | O31: =+IFERROR(HLOOKUP($B31,'[1]5월'!$D$6:$BN$259,3,),)/1000 -> 750.47801 | P31: =+IFERROR(HLOOKUP($F31,'[2]5월'!$F$6:$CP$99,3,),)/1000 -> 857.386 | Q31: =+P31-O31 -> 106.90799 | R31: =+IFERROR(HLOOKUP($F31,'[3]5월'!$F$6:$CC$57,3,),)/1000 -> 0 | S31: =+P31-R31 -> 857.386 | T31: =+IFERROR(HLOOKUP($B31,'[1]5월'!$D$6:$BN$259,21,),)/1000 -> 4.0324504 | U31: =+IFERROR(HLOOKUP($F31,'[2]5월'!$F$6:$CP$99,21,),)/1000 -> 80.169636 | V31: =+U31-T31 -> 76.137186 | W31: =+IFERROR(HLOOKUP($F31,'[3]5월'!$F$6:$CC$57,16,),)/1000 -> -86.060924 | X31: =+U31-W31 -> 166.23056
H32: 골재 계 | J32: =SUM(J29:J31) -> 121.05541 | K32: =SUM(K29:K31) -> 99.315 | L32: =+K32-J32 -> -21.740415 | M32: =SUM(M29:M31) -> 67.558 | N32: =+K32-M32 -> 31.757 | O32: =SUM(O29:O31) -> 2182.0862 | P32: =SUM(P29:P31) -> 1975.778 | Q32: =+P32-O32 -> -206.30819 | R32: =SUM(R29:R31) -> 1320.446 | S32: =+P32-R32 -> 655.332 | T32: =SUM(T29:T31) -> 222.42641 | U32: =SUM(U29:U31) -> 171.57908 | V32: =+U32-T32 -> -50.847329 | W32: =SUM(W29:W31) -> 79.444908 | X32: =+U32-W32 -> 92.134169
B33: 포항임대 | C33: 속초임대 | D33: 강릉임대 | E33: 레미콘임대 계 | G33: =+I33 -> 레미콘임대 | H33: 기타 | I33: 레미콘임대 | L33: =+K33-J33 -> 0 | N33: =+K33-M33 -> 0 | O33: =(IFERROR(HLOOKUP($B33,'[1]5월'!$D$6:$BN$259,3,),)++IFERROR(HLOOKUP($C33,'[1]5월'!$D$6:$BN$259,3,),)+IFERROR(HLOOKUP($D33,'[1]5월'!$D$6:$BN$259,3,),))/1000 -> 90.84 | P33: =+IFERROR(HLOOKUP($E33,'[2]5월'!$F$6:$CP$99,3,),)/1000 -> 90.84 | Q33: =+P33-O33 -> 0 | R33: =+IFERROR(HLOOKUP($E33,'[3]5월'!$F$6:$CC$57,3,),)/1000 -> 78.34 | S33: =+P33-R33 -> 12.5 | T33: =(IFERROR(HLOOKUP($B33,'[1]5월'!$D$6:$BN$259,21,),)++IFERROR(HLOOKUP($C33,'[1]5월'!$D$6:$BN$259,21,),)+IFERROR(HLOOKUP($D33,'[1]5월'!$D$6:$BN$259,21,),))/1000 -> 72.165959 | U33: =+IFERROR(HLOOKUP($E33,'[2]5월'!$F$6:$CP$99,16,),)/1000 -> 68.93061 | V33: =+U33-T33 -> -3.235349 | W33: =+IFERROR(HLOOKUP($E33,'[3]5월'!$F$6:$CC$57,16,),)/1000 -> 55.160753 | X33: =+U33-W33 -> 13.769857
B34: 부동산임대 | C34: 주유소임대 | E34: 임대 계 | G34: =+I34 -> 임대 | I34: 임대 | L34: =+K34-J34 -> 0 | M34: 0 | N34: =+K34-M34 -> 0 | O34: =(+IFERROR(HLOOKUP($B34,'[1]5월'!$D$6:$BN$259,3,),)+IFERROR(HLOOKUP($C34,'[1]5월'!$D$6:$BN$259,3,),))/1000 -> 72.2975 | P34: =+IFERROR(HLOOKUP($E34,'[2]5월'!$F$6:$CP$99,3,),)/1000 -> 73.683136 | Q34: =+P34-O34 -> 1.3856357 | R34: =+IFERROR(HLOOKUP($E34,'[3]5월'!$F$6:$CC$57,3,),)/1000 -> 95.394236 | S34: =+P34-R34 -> -21.7111 | T34: =(+IFERROR(HLOOKUP($B34,'[1]5월'!$D$6:$BN$259,21,),)+IFERROR(HLOOKUP($C34,'[1]5월'!$D$6:$BN$259,21,),))/1000 -> 62.030473 | U34: =+IFERROR(HLOOKUP($E34,'[2]5월'!$F$6:$CP$99,16,),)/1000 -> 63.574319 | V34: =+U34-T34 -> 1.5438457 | W34: =+IFERROR(HLOOKUP($E34,'[3]5월'!$F$6:$CC$57,16,),)/1000 -> 50.653987 | X34: =+U34-W34 -> 12.920332
B35: 공 통 비 | G35: =+I35 -> 공통비 | I35: 공통비 | L35: =+K35-J35 -> 0 | N35: =+K35-M35 -> 0 | Q35: =+P35-O35 -> 0 | S35: =+P35-R35 -> 0 | T35: =-'[1]5월'!$Z$22/1000 -> -1163.2875 | U35: =+-'[2]5월'!$Z$22/1000 -> -1157.1102 | V35: =+U35-T35 -> 6.1773143 | W35: =+-'[3]5월'!$Z$22/1000 -> -1023.2378 | X35: =+U35-W35 -> -133.87232
G36: =+I36 -> OPC 소급분 | I36: OPC 소급분 | N36: =+K36-M36 -> 0 | Q36: =+P36-O36 -> 0 | S36: =+P36-R36 -> 0 | T36: =+'[1]5월'!$AS$26/1000 -> 0 | U36: =-'[2]5월'!$BD$26/1000 -> 0 | V36: =+U36-T36 -> 0 | W36: =-'[3]5월'!$BD$26/1000 -> 0 | X36: =+U36-W36 -> 0
G37: =+I37 -> 대손 | I37: 대손 | N37: =+K37-M37 -> 0 | Q37: =+P37-O37 -> 0 | S37: =+P37-R37 -> 0 | U37: ='[2]5월'!$BE$26/1000 -> 0 | V37: =+U37-T37 -> 0 | W37: ='[3]5월'!$BE$26/1000 -> 0 | X37: =+U37-W37 -> 0
G38: =+I38 -> 미운영 공장 | I38: 미운영 공장 | M38: =SUM(M54:M57) -> 0 | N38: =+K38-M38 -> 0 | Q38: =+P38-O38 -> 0 | R38: =+IFERROR(HLOOKUP($I$38,'[3]5월'!$F$6:$BJ$50,3,),)/1000 -> 188.626 | S38: =+P38-R38 -> -188.626 | T38: =SUM('[1]5월'!$AM$26:$AQ$26)/1000 -> -35.767484 | U38: =+'[2]5월'!$BF$26/1000 -> -97.949849 | V38: =+U38-T38 -> -62.182365 | W38: =+'[3]5월'!$BF$26/1000 -> 24.20909 | X38: =+U38-W38 -> -122.15894
B39: 기타 계 | G39: =+I39 -> 기타 | I39: 기타 | L39: =+K39-J39 -> 0 | N39: =+K39-M39 -> 0 | O39: =IFERROR(HLOOKUP($B39,'[1]5월'!$D$6:$BN$259,3,),)/1000 -> 1.77 | P39: =+('[2]5월'!$F$8-SUM('[2]5월'!$Z$8,'[2]5월'!$AH$8,'[2]5월'!$AN$8,'[2]5월'!$AO$8,'[2]5월'!$BA$8,'[2]5월'!$BD$8,'[2]5월'!$BE$8,'[2]5월'!$BF$8))/1000 -> 1.704 | Q39: =+P39-O39 -> -0.066 | R39: =+('[3]5월'!$F$8-SUM('[3]5월'!$Z$8,'[3]5월'!$AH$8,'[3]5월'!$AN$8,'[3]5월'!$AO$8,'[3]5월'!$BA$8,'[3]5월'!$BD$8,'[3]5월'!$BE$8,'[3]5월'!$BF$8))/1000 -> -32.2379 | S39: =+P39-R39 -> 33.9419 | T39: =+('[1]5월'!$E$26-'[1]5월'!$Z$26-'[1]5월'!$AA$26-'[1]5월'!$AE$26-'[1]5월'!$AL$26-'[1]5월'!$AM$26-'[1]5월'!$AN$26-'[1]5월'!$AO$26-'[1]5월'!$AP$26-'[1]5월'!$AQ$26-'[1]5월'!$AS$26)/1000 -> -79.281808 | U39: =+('[2]5월'!$F$26-SUM('[2]5월'!$Z$26,'[2]5월'!$AH$26,'[2]5월'!$AN$26,'[2]5월'!$AO$26,'[2]5월'!$BA$26,'[2]5월'!$BD$26,'[2]5월'!$BE$26,'[2]5월'!$BF$26))/1000 -> -16.881884 | V39: =+U39-T39 -> 62.399924 | W39: =+('[3]5월'!$F$26-SUM('[3]5월'!$Z$26,'[3]5월'!$AH$26,'[3]5월'!$AN$26,'[3]5월'!$AO$26,'[3]5월'!$BA$26,'[3]5월'!$BD$26,'[3]5월'!$BE$26,'[3]5월'!$BF$26))/1000 -> -51.306531 | X39: =+U39-W39 -> 34.424647
N40: =+K40-M40 -> 0 | Q40: =+P40-O40 -> 0 | S40: =+P40-R40 -> 0 | V40: =+U40-T40 -> 0
H41: 기타 계 | J41: =SUM(J33:J40) -> 0 | K41: =SUM(K33:K40) -> 0 | L41: =+K41-J41 -> 0 | M41: =SUM(M33:M40) -> 0 | N41: =+K41-M41 -> 0 | O41: =SUM(O33:O40) -> 164.9075 | P41: =SUM(P33:P40) -> 166.22714 | Q41: =+P41-O41 -> 1.3196357 | R41: =SUM(R33:R40) -> 330.12234 | S41: =+P41-R41 -> -163.8952 | T41: =SUM(T33:T40) -> -1144.1403 | U41: =SUM(U33:U40) -> -1139.437 | V41: =+U41-T41 -> 4.7033704 | W41: =SUM(W33:W40) -> -944.52053 | X41: =+U41-W41 -> -194.91642
U42: 19 | V42: 12.4
...

Sheet 사업장별(누계)
H3: □ 사업장별 손익실적(2024-05누계)
AG4: [단위 : 천㎥, 톤, 백만원]
H5: 구분 | J5: 물량 | O5: 매출 | T5: 영업이익(공통비 배부전) | Y5: 판매단가 | AB5: 변동비 | AE5: 공헌이익
J6: 계획 | K6: 실적 | L6: 차이 | M6: 전년 | N6: 차이 | O6: 계획 | P6: 실적 | Q6: 차이 | R6: 전년 | S6: 차이 | T6: 계획 | U6: 실적 | V6: 차이 | W6: 전년 | X6: 차이 | Y6: 계획 | Z6: 실적 | AA6: 전년 | AB6: 계획 | AC6: 실적 | AD6: 전년 | AE6: 계획 | AF6: 실적 | AG6: 전년
B7: 안양 | F7: =+U7/T7 -> 0.88106239 | G7: =+K7/J7 -> 1.0460594 | H7: 레미콘 | I7: 안양 | J7: =+'사업장별(당월)'!J7+'[4]사업장별(누계)'!J7 -> 202 | K7: =+'사업장별(당월)'!K7+'[4]사업장별(누계)'!K7 -> 211.304 | L7: =+K7-J7 -> 9.304 | M7: =+'사업장별(당월)'!M7+'[4]사업장별(누계)'!M7 -> 224.425 | N7: =+K7-M7 -> -13.121 | O7: =+'사업장별(당월)'!O7+'[4]사업장별(누계)'!O7 -> 20088.774 | P7: =+'사업장별(당월)'!P7+'[4]사업장별(누계)'!P7 -> 20962.964 | Q7: =+P7-O7 -> 874.19012 | R7: =+'사업장별(당월)'!R7+'[4]사업장별(누계)'!R7 -> 20504.1 | S7: =+P7-R7 -> 458.8643 | T7: =+'사업장별(당월)'!T7+'[4]사업장별(누계)'!T7 -> 2554.9771 | U7: =+'사업장별(당월)'!U7+'[4]사업장별(누계)'!U7 -> 2251.0942 | V7: =+U7-T7 -> -303.88287 | W7: =+'사업장별(당월)'!W7+'[4]사업장별(누계)'!W7 -> 2773.1319 | X7: =+U7-W7 -> -522.03768 | Y7: =+[11]안양!$Q$85 -> 99449.376 | Z7: =+[11]안양!$R$85 -> 99203.365 | AA7: =+[12]안양!$Q$85 -> 91346.276 | AB7: =+[11]안양!$Q$89 -> 79340.078 | AC7: =+[11]안양!$R$89 -> 81339.683 | AD7: =+[12]안양!$Q$89 -> 72646.211 | AE7: =+Y7-AB7 -> 20109.298 | AF7: =+Z7-AC7 -> 17863.682 | AG7: =+AA7-AD7 -> 18700.064 | AI7: 22.510942
B8: 인천 | F8: =+U8/T8 -> 0.86955277 | G8: =+K8/J8 -> 0.95938 | H8: 직영 | I8: 인천 | J8: =+'사업장별(당월)'!J8+'[4]사업장별(누계)'!J8 -> 150 | K8: =+'사업장별(당월)'!K8+'[4]사업장별(누계)'!K8 -> 143.907 | L8: =+K8-J8 -> -6.093 | M8: =+'사업장별(당월)'!M8+'[4]사업장별(누계)'!M8 -> 192.295 | N8: =+K8-M8 -> -48.388 | O8: =+'사업장별(당월)'!O8+'[4]사업장별(누계)'!O8 -> 15138.052 | P8: =+'사업장별(당월)'!P8+'[4]사업장별(누계)'!P8 -> 14464.339 | Q8: =+P8-O8 -> -673.7127 | R8: =+'사업장별(당월)'!R8+'[4]사업장별(누계)'!R8 -> 17944.412 | S8: =+P8-R8 -> -3480.0726 | T8: =+'사업장별(당월)'!T8+'[4]사업장별(누계)'!T8 -> 1404.9972 | U8: =+'사업장별(당월)'!U8+'[4]사업장별(누계)'!U8 -> 1221.7192 | V8: =+U8-T8 -> -183.27799 | W8: =+'사업장별(당월)'!W8+'[4]사업장별(누계)'!W8 -> 2043.5013 | X8: =+U8-W8 -> -821.78213 | Y8: =+[11]인천!$Q$85 -> 100920.35 | Z8: =+[11]인천!$R$85 -> 100511.71 | AA8: =+[12]인천!$Q$85 -> 93314.806 | AB8: =+[11]인천!$Q$89 -> 81598.631 | AC8: =+[11]인천!$R$89 -> 82210.921 | AD8: =+[12]인천!$Q$89 -> 75063.123 | AE8: =+Y8-AB8 -> 19321.714 | AF8: =+Z8-AC8 -> 18300.792 | AG8: =+AA8-AD8 -> 18251.684 | AI8: 12.217192
B9: 파주 | F9: =+U9/T9 -> 0.66371001 | G9: =+K9/J9 -> 1.0031382 | I9: 파주 | J9: =+'사업장별(당월)'!J9+'[4]사업장별(누계)'!J9 -> 123 | K9: =+'사업장별(당월)'!K9+'[4]사업장별(누계)'!K9 -> 123.386 | L9: =+K9-J9 -> 0.386 | M9: =+'사업장별(당월)'!M9+'[4]사업장별(누계)'!M9 -> 122.939 | N9: =+K9-M9 -> 0.447 | O9: =+'사업장별(당월)'!O9+'[4]사업장별(누계)'!O9 -> 12024.145 | P9: =+'사업장별(당월)'!P9+'[4]사업장별(누계)'!P9 -> 12286.365 | Q9: =+P9-O9 -> 262.21966 | R9: =+'사업장별(당월)'!R9+'[4]사업장별(누계)'!R9 -> 11063.622 | S9: =+P9-R9 -> 1222.7428 | T9: =+'사업장별(당월)'!T9+'[4]사업장별(누계)'!T9 -> 1468.7438 | U9: =+'사업장별(당월)'!U9+'[4]사업장별(누계)'!U9 -> 974.81997 | V9: =+U9-T9 -> -493.92384 | W9: =+'사업장별(당월)'!W9+'[4]사업장별(누계)'!W9 -> 945.7502 | X9: =+U9-W9 -> 29.069775 | Y9: =+[11]파주!$Q$85 -> 97757.28 | Z9: =+[11]파주!$R$85 -> 99613.277 | AA9: =+[12]파주!$Q$85 -> 89960.426 | AB9: =+[11]파주!$Q$89 -> 76694.358 | AC9: =+[11]파주!$R$89 -> 82206.609 | AD9: =+[12]파주!$Q$89 -> 73151.924 | AE9: =+Y9-AB9 -> 21062.922 | AF9: =+Z9-AC9 -> 17406.667 | AG9: =+AA9-AD9 -> 16808.502 | AI9: 9.7481997
B10: 김포 | F10: =+U10/T10 -> 0.91705078 | G10: =+K10/J10 -> 0.9450458 | I10: 김포 | J10: =+'사업장별(당월)'!J10+'[4]사업장별(누계)'!J10 -> 65.5 | K10: =+'사업장별(당월)'!K10+'[4]사업장별(누계)'!K10 -> 61.9005 | L10: =+K10-J10 -> -3.5995 | M10: =+'사업장별(당월)'!M10+'[4]사업장별(누계)'!M10 -> 85.1005 | N10: =+K10-M10 -> -23.2 | O10: =+'사업장별(당월)'!O10+'[4]사업장별(누계)'!O10 -> 6199.3665 | P10: =+'사업장별(당월)'!P10+'[4]사업장별(누계)'!P10 -> 6138.8182 | Q10: =+P10-O10 -> -60.548297 | R10: =+'사업장별(당월)'!R10+'[4]사업장별(누계)'!R10 -> 7477.5849 | S10: =+P10-R10 -> -1338.7667 | T10: =+'사업장별(당월)'!T10+'[4]사업장별(누계)'!T10 -> 677.79726 | U10: =+'사업장별(당월)'!U10+'[4]사업장별(누계)'!U10 -> 621.5745 | V10: =+U10-T10 -> -56.222756 | W10: =+'사업장별(당월)'!W10+'[4]사업장별(누계)'!W10 -> 956.62001 | X10: =+U10-W10 -> -335.04551 | Y10: =+[11]김포!$Q$85 -> 94646.817 | Z10: =+[11]김포!$R$85 -> 99202.658 | AA10: =+[12]김포!$Q$85 -> 87815.031 | AB10: =+[11]김포!$Q$89 -> 71555.624 | AC10: =+[11]김포!$R$89 -> 76358.732 | AD10: =+[12]김포!$Q$89 -> 67102.292 | AE10: =+Y10-AB10 -> 23091.193 | AF10: =+Z10-AC10 -> 22843.926 | AG10: =+AA10-AD10 -> 20712.739 | AI10: 6.215745
B11: 부산 | F11: =+U11/T11 -> 1.0375313 | G11: =+K11/J11 -> 1.2165968 | I11: 부산 | J11: =+'사업장별(당월)'!J11+'[4]사업장별(누계)'!J11 -> 93 | K11: =+'사업장별(당월)'!K11+'[4]사업장별(누계)'!K11 -> 113.1435 | L11: =+K11-J11 -> 20.1435 | M11: =+'사업장별(당월)'!M11+'[4]사업장별(누계)'!M11 -> 125.8755 | N11: =+K11-M11 -> -12.732 | O11: =+'사업장별(당월)'!O11+'[4]사업장별(누계)'!O11 -> 10006.81 | P11: =+'사업장별(당월)'!P11+'[4]사업장별(누계)'!P11 -> 12068.068 | Q11: =+P11-O11 -> 2061.2579 | R11: =+'사업장별(당월)'!R11+'[4]사업장별(누계)'!R11 -> 12750.467 | S11: =+P11-R11 -> -682.39891 | T11: =+'사업장별(당월)'!T11+'[4]사업장별(누계)'!T11 -> 1351.1309 | U11: =+'사업장별(당월)'!U11+'[4]사업장별(누계)'!U11 -> 1401.8406 | V11: =+U11-T11 -> 50.709659 | W11: =+'사업장별(당월)'!W11+'[4]사업장별(누계)'!W11 -> 2392.4509 | X11: =+U11-W11 -> -990.61032 | Y11: =+[11]부산!$Q$85 -> 107600.11 | Z11: =+[11]부산!$R$85 -> 106661.61 | AA11: =+[12]부산!$Q$85 -> 101294.27 | AB11: =+[11]부산!$Q$89 -> 78742.472 | AC11: =+[11]부산!$R$89 -> 83541.955 | AD11: =+[12]부산!$Q$89 -> 72839.146 | AE11: =+Y11-AB11 -> 28857.633 | AF11: =+Z11-AC11 -> 23119.653 | AG11: =+AA11-AD11 -> 28455.121 | AI11: 14.018406
