Workbook

Sheet 표지
A6: 2024년 10월 마감 손익
A24: 건재사업본부

Sheet 손익총괄
C3: □ 건재사업본부 손익실적(2024-10) | Z3: □ 건재부문 실적(10월)
X4: [단위 : 천㎥, 톤, 원/㎥, 원/톤, 백만원] | AK4: (단위 : 천㎥, 천톤, 억원)
C5: 구분 | E5: 10월 | J5: 10월 누계 | P5: 10월 주요지표 | Z5: 구분 | AB5: =+E5 -> 10월 | AG5: =+J5 -> 10월 누계
E6: 계획 | F6: 실적 | G6: 계획대비 | H6: 전년 | I6: 전년대비 | J6: 계획 | K6: 실적 | L6: 계획대비 | M6: 전년 | N6: 전년대비 | AB6: =+E6 -> 계획 | AC6: =+F6 -> 실적 | AD6: =+G6 -> 계획대비 | AE6: =+H6 -> 전년 | AF6: =+I6 -> 전년대비 | AG6: =+J6 -> 계획 | AH6: =+K6 -> 실적 | AI6: =+L6 -> 계획대비 | ... AK6: =+N6 -> 전년대비
A7: =+F7/E7 -> 0.92385358 | B7: =+K7/J7 -> 0.98355805 | C7: 물량 | D7: 레미콘 | E7: =+'[1]10월'!$Z$7/1000 -> 321 | F7: =+'[2]10월'!$Z$7/1000 -> 296.557 | G7: =+F7-E7 -> -24.443 | H7: =+'[3]10월'!$Z$7/1000 -> 350.514 | I7: =+F7-H7 -> -53.957 | J7: =+[4]손익총괄!J7+E7 -> 2872.5 | K7: =+[4]손익총괄!K7+F7 -> 2825.2705 | L7: =+K7-J7 -> -47.2295 | M7: =+[4]손익총괄!M7+H7 -> 3200.519 | N7: =+K7-M7 -> -375.2485 | Q7: □ 레미콘 | Z7: 물량 | AA7: =+D7 -> 레미콘 | AB7: =+E7 -> 321 | AC7: =+F7 -> 296.557 | AD7: =+AC7-AB7 -> -24.443 | AE7: =+H7 -> 350.514 | AF7: =+AC7-AE7 -> -53.957 | AG7: =+J7 -> 2872.5 | AH7: =+K7 -> 2825.2705 | AI7: =+AH7-AG7 -> -47.2295 | AJ7: =+M7 -> 3200.519 | AK7: =+AH7-AJ7 -> -375.2485
D8: 철강재 | E8: =+'[1]10월'!$AA$7 -> 8900 | F8: =+'[2]10월'!$AO$7 -> 8972.008 | G8: =+F8-E8 -> 72.008 | H8: =+'[3]10월'!$AO$7 -> 9070.045 | I8: =+F8-H8 -> -98.037 | J8: =+[4]손익총괄!J8+E8 -> 72200 | K8: =+[4]손익총괄!K8+F8 -> 86939.352 | L8: =+K8-J8 -> 14739.352 | M8: =+[4]손익총괄!M8+H8 -> 78625.764 | N8: =+K8-M8 -> 8313.588 | Q8: 구분 | S8: 계획 | T8: 실적 | U8: 계획대비 | V8: 전년 | W8: 전년대비 | AA8: =+D8 -> 철강재 | AB8: =+E8/1000 -> 8.9 | AC8: =+F8/1000 -> 8.972008 | AD8: =+AC8-AB8 -> 0.072008 | AE8: =+H8/1000 -> 9.070045 | AF8: =+AC8-AE8 -> -0.098037 | AG8: =+J8/1000 -> 72.2 | AH8: =+K8/1000 -> 86.939352 | AI8: =+AH8-AG8 -> 14.739352 | AJ8: =+M8/1000 -> 78.625764 | AK8: =+AH8-AJ8 -> 8.313588
D9: 골재 | E9: =+'[1]10월'!$AE$7/1000 -> 124.17291 | F9: =+'[2]10월'!$AN$7/1000 -> 60.09 | G9: =+F9-E9 -> -64.082914 | H9: =+'[3]10월'!$AN$7/1000 -> 98.511 | I9: =+F9-H9 -> -38.421 | J9: =+[4]손익총괄!J9+E9 -> 980.45966 | K9: =+[4]손익총괄!K9+F9 -> 714.305 | L9: =+K9-J9 -> -266.15466 | M9: =+[4]손익총괄!M9+H9 -> 672.393 | N9: =+K9-M9 -> 41.912 | Q9: 물량 | R9: 수도권 | S9: =+[5]수도권!$T$5/1000 -> 121.5 | T9: =+[5]수도권!$U$5/1000 -> 103.91 | U9: =+T9-S9 -> -17.59 | V9: =+[6]수도권!$T$5/1000 -> 136.035 | W9: =+T9-V9 -> -32.125 | AA9: =+D9 -> 골재 | AB9: =+E9 -> 124.17291 | AC9: =+F9 -> 60.09 | AD9: =+AC9-AB9 -> -64.082914 | AE9: =+H9 -> 98.511 | AF9: =+AC9-AE9 -> -38.421 | AG9: =+J9 -> 980.45966 | AH9: =+K9 -> 714.305 | AI9: =+AH9-AG9 -> -266.15466 | AJ9: =+M9 -> 672.393 | AK9: =+AH9-AJ9 -> 41.912
C10: 매출 | D10: 레미콘 | E10: =+'[1]10월'!$Z$8/1000 -> 33004.954 | F10: =+'[2]10월'!$Z$8/1000 -> 28528.552 | G10: =+F10-E10 -> -4476.4023 | H10: =+'[3]10월'!$Z$8/1000 -> 34276.781 | I10: =+F10-H10 -> -5748.229 | J10: =+[4]손익총괄!J10+E10 -> 292780.25 | K10: =+[4]손익총괄!K10+F10 -> 284322.86 | L10: =+K10-J10 -> -8457.3869 | M10: =+[4]손익총괄!M10+H10 -> 309316.19 | N10: =+K10-M10 -> -24993.334 | R10: 영남권 | S10: =+[5]영남권!$T$5/1000 -> 138.5 | T10: =+[5]영남권!$U$5/1000 -> 130.221 | U10: =+T10-S10 -> -8.279 | V10: =+[6]영남권!$T$5/1000 -> 149.6455 | W10: =+T10-V10 -> -19.4245 | Z10: 매출액 | AA10: =+D10 -> 레미콘 | AB10: =+E10/100 -> 330.04954 | AC10: =+F10/100 -> 285.28552 | AD10: =+AC10-AB10 -> -44.764023 | AE10: =+H10/100 -> 342.76781 | AF10: =+AC10-AE10 -> -57.48229 | AG10: =+J10/100 -> 2927.8025 | AH10: =+K10/100 -> 2843.2286 | AI10: =+AH10-AG10 -> -84.573869 | AJ10: =+M10/100 -> 3093.1619 | AK10: =+AH10-AJ10 -> -249.93334
D11: 건자재 | E11: =+'[1]10월'!$AA$8/1000 -> 10873.417 | F11: =+'[2]10월'!$AO$8/1000 -> 8678.6853 | G11: =+F11-E11 -> -2194.7316 | H11: =+'[3]10월'!$AO$8/1000 -> 11314.06 | I11: =+F11-H11 -> -2635.3749 | J11: =+[4]손익총괄!J11+E11 -> 88286.96 | K11: =+[4]손익총괄!K11+F11 -> 86611.076 | L11: =+K11-J11 -> -1675.8837 | M11: =+[4]손익총괄!M11+H11 -> 96340.744 | N11: =+K11-M11 -> -9729.6676 | R11: 중부권 | S11: =+[5]중부권!$T$5/1000 -> 61 | T11: =+[5]중부권!$U$5/1000 -> 62.426 | U11: =+T11-S11 -> 1.426 | V11: =+[6]중부권!$T$5/1000 -> 64.8335 | W11: =+T11-V11 -> -2.4075 | AA11: =+D11 -> 건자재 | AB11: =+E11/100 -> 108.73417 | AC11: =+F11/100 -> 86.786853 | AD11: =+AC11-AB11 -> -21.947316 | AE11: =+H11/100 -> 113.1406 | AF11: =+AC11-AE11 -> -26.353749 | AG11: =+J11/100 -> 882.8696 | AH11: =+K11/100 -> 866.11076 | AI11: =+AH11-AG11 -> -16.758837 | AJ11: =+M11/100 -> 963.40744 | AK11: =+AH11-AJ11 -> -97.296676
D12: 골재 | E12: =+'[1]10월'!$AE$8/1000 -> 2259.7288 | F12: =+'[2]10월'!$AN$8/1000 -> 1245.8185 | G12: =+F12-E12 -> -1013.9103 | H12: =+'[3]10월'!$AN$8/1000 -> 1852.293 | I12: =+F12-H12 -> -606.4745 | J12: =+[4]손익총괄!J12+E12 -> 18602.495 | K12: =+[4]손익총괄!K12+F12 -> 14375.604 | L12: =+K12-J12 -> -4226.8908 | M12: =+[4]손익총괄!M12+H12 -> 12858.223 | N12: =+K12-M12 -> 1517.3812 | Q12: 계 | S12: =SUM(S9:S11) -> 321 | T12: =SUM(T9:T11) -> 296.557 | U12: =+T12-S12 -> -24.443 | V12: =SUM(V9:V11) -> 350.514 | W12: =+T12-V12 -> -53.957 | AA12: =+D12 -> 골재 | AB12: =+E12/100 -> 22.597288 | AC12: =+F12/100 -> 12.458185 | AD12: =+AC12-AB12 -> -10.139103 | AE12: =+H12/100 -> 18.52293 | AF12: =+AC12-AE12 -> -6.064745 | AG12: =+J12/100 -> 186.02495 | AH12: =+K12/100 -> 143.75604 | AI12: =+AH12-AG12 -> -42.268908 | AJ12: =+M12/100 -> 128.58223 | AK12: =+AH12-AJ12 -> 15.173812
D13: 기타 | E13: =+'[1]10월'!$E$8/1000-E10-E11-E12 -> 164.9075 | F13: =+'[2]10월'!$F$8/1000-F10-F11-F12 -> 166.49562 | G13: =+F13-E13 -> 1.5881207 | H13: =+'[3]10월'!$F$8/1000-H10-H11-H12 -> 185.79062 | I13: =+F13-H13 -> -19.294996 | J13: =+[4]손익총괄!J13+E13 -> 1649.675 | K13: =+[4]손익총괄!K13+F13 -> 1656.371 | L13: =+K13-J13 -> 6.6959587 | M13: =+[4]손익총괄!M13+H13 -> 1955.5002 | N13: =+K13-M13 -> -299.12927 | Q13: 판매단가 | R13: 수도권 | S13: =+[5]수도권!$T$61 -> 101656.47 | T13: =+[5]수도권!$U$61 -> 93480.666 | U13: =+T13-S13 -> -8175.8003 | V13: =+[6]수도권!$Q$85 -> 96457.33 | W13: =+T13-V13 -> -2976.6637 | AA13: =+D13 -> 기타 | AB13: =+E13/100 -> 1.649075 | AC13: =+F13/100 -> 1.6649562 | AD13: =+AC13-AB13 -> 0.015881207 | AE13: =+H13/100 -> 1.8579062 | AF13: =+AC13-AE13 -> -0.19294996 | AG13: =+J13/100 -> 16.49675 | AH13: =+K13/100 -> 16.56371 | AI13: =+AH13-AG13 -> 0.066959587 | AJ13: =+M13/100 -> 19.555002 | AK13: =+AH13-AJ13 -> -2.9912927
A14: =+F14/E14 -> 0.8340614 | B14: =+K14/J14 -> 0.96423431 | C14: 계 | E14: =SUM(E10:E13) -> 46303.007 | F14: =SUM(F10:F13) -> 38619.551 | G14: =+F14-E14 -> -7683.4561 | H14: =SUM(H10:H13) -> 47628.924 | I14: =+F14-H14 -> -9009.3734 | J14: =SUM(J10:J13) -> 401319.38 | K14: =SUM(K10:K13) -> 386965.91 | L14: =+K14-J14 -> -14353.465 | M14: =SUM(M10:M13) -> 420470.66 | N14: =+K14-M14 -> -33504.75 | R14: 영남권 | S14: =+[5]영남권!$T$61 -> 102592.96 | T14: =+[5]영남권!$U$61 -> 96016.649 | U14: =+T14-S14 -> -6576.3128 | V14: =+[6]영남권!$Q$85 -> 97820.439 | W14: =+T14-V14 -> -1803.7903 | AA14: 계 | AB14: =SUM(AB10:AB13) -> 463.03007 | AC14: =SUM(AC10:AC13) -> 386.19551 | AD14: =+AC14-AB14 -> -76.834561 | AE14: =SUM(AE10:AE13) -> 476.28924 | AF14: =+AC14-AE14 -> -90.093734 | AG14: =SUM(AG10:AG13) -> 4013.1938 | AH14: =SUM(AH10:AH13) -> 3869.6591 | AI14: =+AH14-AG14 -> -143.53465 | AJ14: =SUM(AJ10:AJ13) -> 4204.7066 | AK14: =+AH14-AJ14 -> -335.0475
C15: 매출원가 | D15: 레미콘 | E15: =+('[1]10월'!$Z$10+'[1]10월'!$Z$19)/1000 -> 27044.707 | F15: =+('[2]10월'!$Z$10+'[2]10월'!$Z$19)/1000 -> 25663.485 | G15: =+F15-E15 -> -1381.2219 | H15: =+('[3]10월'!$Z$10+'[3]10월'!$Z$19)/1000 -> 27775.362 | I15: =+F15-H15 -> -2111.8766 | J15: =+[4]손익총괄!J15+E15 -> 244089.86 | K15: =+[4]손익총괄!K15+F15 -> 247168.48 | L15: =+K15-J15 -> 3078.6225 | M15: =+[4]손익총괄!M15+H15 -> 254793.37 | N15: =+K15-M15 -> -7624.8876 | R15: 중부권 | S15: =+[5]중부권!$T$61 -> 105648.66 | T15: =+[5]중부권!$U$61 -> 101095.66 | U15: =+T15-S15 -> -4552.9995 | V15: =+[6]중부권!$Q$85 -> 100356.67 | W15: =+T15-V15 -> 738.9865 | Z15: 영업이익 | AA15: =+D30 -> 레미콘 | AB15: =+E30/100 -> 53.114516 | AC15: =+F30/100 -> 21.412714 | AD15: =+AC15-AB15 -> -31.701802 | AE15: =+H30/100 -> 58.413245 | AF15: =+AC15-AE15 -> -37.000531 | AG15: =+J30/100 -> 420.66225 | AH15: =+K30/100 -> 302.73137 | AI15: =+AH15-AG15 -> -117.93088 | AJ15: =+M30/100 -> 478.00389 | AK15: =+AH15-AJ15 -> -175.27252
D16: 건자재 | E16: =+('[1]10월'!$AA$10+'[1]10월'!$AA$19)/1000 -> 10595.362 | F16: =+('[2]10월'!$AO$10+'[2]10월'!$AO$19)/1000 -> 8468.1695 | G16: =+F16-E16 -> -2127.192 | H16: =+('[3]10월'!$AO$10+'[3]10월'!$AO$19)/1000 -> 11109.066 | I16: =+F16-H16 -> -2640.8964 | J16: =+[4]손익총괄!J16+E16 -> 86028.466 | K16: =+[4]손익총괄!K16+F16 -> 84700.154 | L16: =+K16-J16 -> -1328.3121 | M16: =+[4]손익총괄!M16+H16 -> 94369.979 | N16: =+K16-M16 -> -9669.8255 | Q16: 계 | S16: =+[5]합계!$T$61 -> 102819.17 | T16: =+[5]합계!$U$61 -> 96197.561 | U16: =+T16-S16 -> -6621.6093 | V16: =+[6]합계!$Q$85 -> 97761.738 | W16: =+T16-V16 -> -1564.1768 | AA16: =+D31 -> % | AB16: =+E31 -> 0.16092892 | AC16: =+F31 -> 0.075057138 | AD16: =+AC16-AB16 -> -0.085871783 | AE16: =+H31 -> 0.17041637 | AF16: =+AC16-AE16 -> -0.095359232 | AG16: =+J31 -> 0.14367849 | AH16: =+K31 -> 0.10647451 | AI16: =+AH16-AG16 -> -0.037203986 | AJ16: =+M31 -> 0.15453568 | AK16: =+AH16-AJ16 -> -0.048061174
D17: 골재 | E17: =+('[1]10월'!$AE$10+'[1]10월'!$AE$19)/1000 -> 1891.2157 | F17: =+('[2]10월'!$AN$10+'[2]10월'!$AN$19)/1000 -> 1321.95 | G17: =+F17-E17 -> -569.2657 | H17: =+('[3]10월'!$AN$10+'[3]10월'!$AN$19)/1000 -> 1700.4395 | I17: =+F17-H17 -> -378.4895 | J17: =+[4]손익총괄!J17+E17 -> 16508.137 | K17: =+[4]손익총괄!K17+F17 -> 13776.633 | L17: =+K17-J17 -> -2731.504 | M17: =+[4]손익총괄!M17+H17 -> 11802.978 | N17: =+K17-M17 -> 1973.6549 | Q17: 공헌이익 | R17: 수도권 | S17: =+[5]수도권!$Q$90 -> 23514.084 | T17: =+[5]수도권!$R$90 -> 12984.216 | U17: =+T17-S17 -> -10529.867 | V17: =+[6]수도권!$Q$90 -> 20930.542 | W17: =+T17-V17 -> -7946.3255 | AA17: =+D32 -> 건자재 | AB17: =+E32/100 -> 1.5578428 | AC17: =+F32/100 -> 0.44005329 | AD17: =+AC17-AB17 -> -1.1177895 | AE17: =+H32/100 -> 0.85321437 | AF17: =+AC17-AE17 -> -0.41316108 | AG17: =+J32/100 -> 9.956551 | AH17: =+K32/100 -> 4.835037 | AI17: =+AH17-AG17 -> -5.121514 | AJ17: =+M32/100 -> 7.7009028 | AK17: =+AH17-AJ17 -> -2.8658658
D18: 기타 | E18: =+('[1]10월'!$E$10+'[1]10월'!$E$19)/1000-E15-E16-E17 -> 65.348898 | F18: =+('[2]10월'!$F$10+'[2]10월'!$F$19)/1000-F15-F16-F17 -> -220.72587 | G18: =+F18-E18 -> -286.07477 | H18: =+('[3]10월'!$F$10+'[3]10월'!$F$19)/1000-H15-H16-H17 -> 28.523642 | I18: =+F18-H18 -> -249.24951 | J18: =+[4]손익총괄!J18+E18 -> -735.22521 | K18: =+[4]손익총괄!K18+F18 -> -329.81756 | L18: =+K18-J18 -> 405.40766 | M18: =+[4]손익총괄!M18+H18 -> 556.75548 | N18: =+K18-M18 -> -886.57303 | R18: 영남권 | S18: =+[5]영남권!$Q$90 -> 26796.447 | T18: =+[5]영남권!$R$90 -> 17824.891 | U18: =+T18-S18 -> -8971.5561 | V18: =+[6]영남권!$Q$90 -> 27529.225 | W18: =+T18-V18 -> -9704.3347 | AA18: =+D33 -> 골재 | AB18: =+E33/100 -> 3.3315138 | AC18: =+F33/100 -> -1.4995785 | AD18: =+AC18-AB18 -> -4.8310923 | AE18: =+H33/100 -> 1.4179206 | AF18: =+AC18-AE18 -> -2.9174991 | AG18: =+J33/100 -> 15.470668 | AH18: =+K33/100 -> -0.039952527 | AI18: =+AH18-AG18 -> -15.51062 | AJ18: =+M33/100 -> 7.6356614 | AK18: =+AH18-AJ18 -> -7.6756139
C19: 계 | E19: =SUM(E15:E18) -> 39596.633 | F19: =SUM(F15:F18) -> 35232.879 | G19: =+F19-E19 -> -4363.7543 | H19: =SUM(H15:H18) -> 40613.391 | I19: =+F19-H19 -> -5380.5121 | J19: =SUM(J15:J18) -> 345891.24 | K19: =SUM(K15:K18) -> 345315.45 | L19: =+K19-J19 -> -575.786 | M19: =SUM(M15:M18) -> 361523.08 | N19: =+K19-M19 -> -16207.631 | R19: 중부권 | S19: =+[5]중부권!$Q$90 -> 28848.732 | T19: =+[5]중부권!$R$90 -> 25702.179 | U19: =+T19-S19 -> -3146.5529 | V19: =+[6]중부권!$Q$90 -> 28182.868 | W19: =+T19-V19 -> -2480.6891 | AA19: 공통비 | AB19: =+'사업장별(당월)'!T35/100 -> -12.393305 | AC19: =+'사업장별(당월)'!U35/100 -> -11.965785 | AD19: =+AC19-AB19 -> 0.42751972 | AE19: =+'사업장별(당월)'!W35/100 -> -12.145176 | AF19: =+AC19-AE19 -> 0.17939122 | AG19: =+'사업장별(누계)'!T35/100 -> -137.97863 | AH19: =+'사업장별(누계)'!U35/100 -> -140.88417 | AI19: =+AH19-AG19 -> -2.9055428 | AJ19: =+'사업장별(누계)'!W35/100 -> -117.27202 | AK19: =+AH19-AJ19 -> -23.61215
C20: 매출이익 | D20: 레미콘 | E20: =+E10-E15 -> 5960.2468 | F20: =+F10-F15 -> 2865.0663 | G20: =+F20-E20 -> -3095.1804 | H20: =+H10-H15 -> 6501.4187 | I20: =+F20-H20 -> -3636.3524 | J20: =+J10-J15 -> 48690.388 | K20: =+K10-K15 -> 37154.378 | L20: =+K20-J20 -> -11536.009 | M20: =+M10-M15 -> 54522.825 | N20: =+K20-M20 -> -17368.446 | Q20: 계 | S20: =+[5]합계!$Q$90 -> 25944.055 | T20: =+[5]합계!$R$90 -> 17786.111 | U20: =+T20-S20 -> -8157.9443 | V20: =+[6]합계!$Q$90 -> 25091.997 | W20: =+T20-V20 -> -7305.8865 | AA20: =+'사업장별(누계)'!I34 -> 임대 | AB20: =+('사업장별(당월)'!T33+'사업장별(당월)'!T34)/100 -> 1.3419643 | AC20: =+('사업장별(당월)'!U33+'사업장별(당월)'!U34)/100 -> 1.3487362 | AD20: =+AC20-AB20 -> 0.0067719267 | AE20: =+('사업장별(당월)'!W33+'사업장별(당월)'!W34)/100 -> 1.2817785 | AF20: =+AC20-AE20 -> 0.0669578 | AG20: =+('사업장별(누계)'!T33+'사업장별(누계)'!T34)/100 -> 13.287629 | AH20: =+('사업장별(누계)'!U33+'사업장별(누계)'!U34)/100 -> 12.950632 | AI20: =+AH20-AG20 -> -0.33699681 | AJ20: =+('사업장별(누계)'!W33+'사업장별(누계)'!W34)/100 -> 11.906786 | AK20: =+AH20-AJ20 -> 1.0438458
D21: 건자재 | E21: =+E11-E16 -> 278.05534 | F21: =+F11-F16 -> 210.51578 | G21: =+F21-E21 -> -67.539562 | H21: =+H11-H16 -> 204.99426 | I21: =+F21-H21 -> 5.52152 | J21: =+J11-J16 -> 2258.4943 | K21: =+K11-K16 -> 1910.9227 | L21: =+K21-J21 -> -347.57159 | M21: =+M11-M16 -> 1970.7648 | N21: =+K21-M21 -> -59.842141 | Q21: □ 건자재 | AA21: =+'사업장별(누계)'!I37 -> 대손 | AB21: =+'사업장별(당월)'!T37/100 -> 0 | AC21: =+'사업장별(당월)'!U37/100 -> 0 | AD21: =+AC21-AB21 -> 0 | AE21: =+'사업장별(당월)'!W37/100 -> 0.49 | AF21: =+AC21-AE21 -> -0.49 | AG21: =+'사업장별(누계)'!T37/100 -> 0 | AH21: =+'사업장별(누계)'!U37/100 -> -5.7385933 | AI21: =+AH21-AG21 -> -5.7385933 | AJ21: =+'사업장별(누계)'!W37/100 -> -19.74222 | AK21: =+AH21-AJ21 -> 14.003626
D22: 골재 | E22: =+E12-E17 -> 368.51313 | F22: =+F12-F17 -> -76.13149 | G22: =+F22-E22 -> -444.64462 | H22: =+H12-H17 -> 151.85351 | I22: =+F22-H22 -> -227.985 | J22: =+J12-J17 -> 2094.358 | K22: =+K12-K17 -> 598.97119 | L22: =+K22-J22 -> -1495.3868 | M22: =+M12-M17 -> 1055.2449 | N22: =+K22-M22 -> -456.27369 | Q22: 구분 | S22: 계획 | T22: 실적 | U22: 계획대비 | V22: 전년 | W22: 전년대비 | AA22: =+D34 -> 기타 | AB22: =+AB26-AB19-AB20-AB21 -> -1.1504929 | AC22: =+AC26-AC19-AC20-AC21 -> 2.0062159 | AD22: =+AC22-AB22 -> 3.1567089 | AE22: =+AE26-AE19-AE20-AE21 -> -0.25065102 | AF22: =+AC22-AE22 -> 2.2568669 | AG22: =+AG26-AG19-AG20-AG21 -> 3.8964987 | AH22: =+AH26-AH19-AH20-AH21 -> 1.6166891 | AI22: =+AH22-AG22 -> -2.2798096 | AJ22: =+AJ26-AJ19-AJ20-AJ21 -> -3.514039 | AK22: =+AH22-AJ22 -> 5.1307281
D23: 기타 | E23: =+E13-E18 -> 99.558602 | F23: =+F13-F18 -> 387.22149 | G23: =+F23-E23 -> 287.66289 | H23: =+H13-H18 -> 157.26697 | I23: =+F23-H23 -> 229.95452 | J23: =+J13-J18 -> 2384.9002 | K23: =+K13-K18 -> 1986.1885 | L23: =+K23-J23 -> -398.7117 | M23: =+M13-M18 -> 1398.7448 | N23: =+K23-M23 -> 587.44376 | Q23: 철강재 판매단가 | S23: =+'[7]10월'!$F$10 -> 976966.29 | T23: =+'[7]10월'!$G$10 -> 818946.48 | U23: =+T23-S23 -> -158019.81 | V23: =+'[8]10월'!$G$10 -> 964243.14 | W23: =+T23-V23 -> -145296.67 | AA23: 계 | AB23: =SUM(AB15,AB17:AB22) -> 45.802039 | AC23: =SUM(AC15,AC17:AC22) -> 11.742356 | AD23: =+AC23-AB23 -> -34.059683 | AE23: =SUM(AE15,AE17:AE22) -> 50.060331 | AF23: =+AC23-AE23 -> -38.317975 | AG23: =SUM(AG15,AG17:AG22) -> 325.29497 | AH23: =SUM(AH15,AH17:AH22) -> 175.47101 | AI23: =+AH23-AG23 -> -149.82396 | AJ23: =SUM(AJ15,AJ17:AJ22) -> 364.71896 | AK23: =+AH23-AJ23 -> -189.24795
C24: 계 | E24: =SUM(E20:E23) -> 6706.3738 | F24: =SUM(F20:F23) -> 3386.6721 | G24: =+F24-E24 -> -3319.7017 | H24: =SUM(H20:H23) -> 7015.5335 | I24: =+F24-H24 -> -3628.8613 | J24: =SUM(J20:J23) -> 55428.14 | K24: =SUM(K20:K23) -> 41650.461 | L24: =+K24-J24 -> -13777.679 | M24: =SUM(M20:M23) -> 58947.579 | N24: =+K24-M24 -> -17297.119 | Q24: 철강재 마진률 | S24: =+'[7]10월'!$F$15 -> 0.023265095 | T24: =+'[7]10월'!$G$15 -> 0.023542138 | U24: =+T24-S24 -> 0.00027704297 | V24: =+'[8]10월'!$G$15 -> 0.015555832 | W24: =+T24-V24 -> 0.0079863057 | AA24: =+D36 -> % | AB24: =+E36 -> 0.098918067 | AC24: =+F36 -> 0.030405212 | AD24: =+G36 -> -0.068512855 | AE24: =+H36 -> 0.1051049 | AF24: =+I36 -> -0.074699684 | AG24: =+J36 -> 0.081056382 | AH24: =+K36 -> 0.04534534 | ... AK24: =+N36 -> -0.041395304
C25: 판관비 | D25: 레미콘 | E25: =+('[1]10월'!$Z$13+'[1]10월'!$Z$20)/1000 -> 648.79516 | F25: =+('[2]10월'!$Z$13+'[2]10월'!$Z$20)/1000 -> 723.79491 | G25: =+F25-E25 -> 74.999752 | H25: =+('[3]10월'!$Z$13+'[3]10월'!$Z$20)/1000 -> 660.09421 | I25: =+F25-H25 -> 63.7007 | J25: =+[4]손익총괄!J25+E25 -> 6624.1624 | K25: =+[4]손익총괄!K25+F25 -> 6881.2415 | L25: =+K25-J25 -> 257.07911 | M25: =+[4]손익총괄!M25+H25 -> 6722.4356 | N25: =+K25-M25 -> 158.80592 | Q25: □ 골재
D26: 건자재 | E26: =+('[1]10월'!$AA$13+'[1]10월'!$AA$20)/1000 -> 122.27106 | F26: =+('[2]10월'!$AO$13+'[2]10월'!$AO$20)/1000 -> 166.51045 | G26: =+F26-E26 -> 44.239387 | H26: =+('[3]10월'!$AO$13+'[3]10월'!$AO$20)/1000 -> 119.67282 | I26: =+F26-H26 -> 46.837628 | J26: =+[4]손익총괄!J26+E26 -> 1262.8392 | K26: =+[4]손익총괄!K26+F26 -> 1427.419 | L26: =+K26-J26 -> 164.57981 | M26: =+[4]손익총괄!M26+H26 -> 1200.6745 | N26: =+K26-M26 -> 226.74444 | Q26: 구분 | S26: 계획 | T26: 실적 | U26: 계획대비 | V26: 전년 | W26: 전년대비 | AB26: =+'사업장별(당월)'!T41/100 -> -12.201833 | AC26: =+'사업장별(당월)'!U41/100 -> -8.6108329 | AD26: =+AC26-AB26 -> 3.5910005 | AE26: =+'사업장별(당월)'!W41/100 -> -10.624049 | AF26: =+AE26-AD26 -> -14.215049 | AG26: =+'사업장별(누계)'!T41/100 -> -120.7945 | AH26: =+'사업장별(누계)'!U41/100 -> -132.05544 | AJ26: =+'사업장별(누계)'!W41/100 -> -128.62149
D27: 골재 | E27: =+('[1]10월'!$AE$13+'[1]10월'!$AE$20+'[1]10월'!$AE$22)/1000 -> 35.36175 | F27: =+('[2]10월'!$AN$13+'[2]10월'!$AN$20+'[2]10월'!$AN$22)/1000 -> 73.826361 | G27: =+F27-E27 -> 38.464611 | H27: =+('[3]10월'!$AN$13+'[3]10월'!$AN$20+'[3]10월'!$AN$22)/1000 -> 10.061455 | I27: =+F27-H27 -> 63.764906 | J27: =+[4]손익총괄!J27+E27 -> 547.29119 | K27: =+[4]손익총괄!K27+F27 -> 602.96645 | L27: =+K27-J27 -> 55.675261 | M27: =+[4]손익총괄!M27+H27 -> 291.67875 | N27: =+K27-M27 -> 311.2877 | Q27: 판매량 | R27: 자가 | S27: =(+'[9]서부산크라샤(당월)'!$N$66+'[9]부산모래장(당월)'!$Q$48+'[9]부산크라샤(당월)'!$N$66)/1000 -> 63.372914 | T27: =(+'[9]서부산크라샤(당월)'!$O$66+'[9]부산모래장(당월)'!$R$48+'[9]부산크라샤(당월)'!$O$66)/1000 -> 38.555 | U27: =+T27-S27 -> -24.817914 | V27: =('[10]부산골재(당월)'!$R$48+'[10]서부산골재(당월)'!$O$66+'[10]부산크라샤(당월)'!$O$66)/1000 -> 62.023 | W27: =+T27-V27 -> -23.468
D28: 기타 | E28: =+('[1]10월'!$E$13+'[1]10월'!$E$20)/1000-E25-E26-E27+('[1]10월'!$E$22/1000) -> 1319.7419 | F28: =+('[2]10월'!$F$13+'[2]10월'!$F$20)/1000-F25-F26-F27+'[2]10월'!$F$22/1000 -> 1248.3048 | G28: =+F28-E28 -> -71.437163 | H28: =+('[3]10월'!$F$13+'[3]10월'!$F$20)/1000-H25-H26-H27+'[3]10월'!$F$22/1000 -> 1219.6719 | I28: =+F28-H28 -> 28.632918 | J28: =+[4]손익총괄!J28+E28 -> 14464.35 | K28: =+[4]손익총괄!K28+F28 -> 15191.733 | L28: =+K28-J28 -> 727.38255 | M28: =+[4]손익총괄!M28+H28 -> 14260.894 | N28: =+K28-M28 -> 930.83872 | R28: 외판 | S28: =(+'[9]서부산크라샤(당월)'!$N$59+'[9]부산모래장(당월)'!$Q$47+'[9]부산크라샤(당월)'!$N$59)/1000 -> 60.8 | T28: =(+'[9]서부산크라샤(당월)'!$O$59+'[9]부산모래장(당월)'!$R$47+'[9]부산크라샤(당월)'!$O$59)/1000 -> 21.535 | U28: =+T28-S28 -> -39.265 | V28: =+('[10]부산골재(당월)'!$R$47+'[10]서부산골재(당월)'!$O$59+'[10]부산크라샤(당월)'!$O$59)/1000 -> 36.488 | W28: =+T28-V28 -> -14.953
C29: 계 | E29: =SUM(E25:E28) -> 2126.1699 | F29: =SUM(F25:F28) -> 2212.4365 | G29: =+F29-E29 -> 86.266587 | H29: =SUM(H25:H28) -> 2009.5003 | I29: =+F29-H29 -> 202.93615 | J29: =SUM(J25:J28) -> 22898.643 | K29: =SUM(K25:K28) -> 24103.36 | L29: =+K29-J29 -> 1204.7167 | M29: =SUM(M25:M28) -> 22475.683 | N29: =+K29-M29 -> 1627.6768 | Q29: 합 계 | S29: =SUM(S27:S28) -> 124.17291 | T29: =SUM(T27:T28) -> 60.09 | U29: =+T29-S29 -> -64.082914 | V29: =SUM(V27:V28) -> 98.511 | W29: =+T29-V29 -> -38.421
C30: 영업이익 | D30: 레미콘 | E30: =+E20-E25 -> 5311.4516 | F30: =+F20-F25 -> 2141.2714 | G30: =+F30-E30 -> -3170.1802 | H30: =+H20-H25 -> 5841.3245 | I30: =+F30-H30 -> -3700.0531 | J30: =+J20-J25 -> 42066.225 | K30: =+K20-K25 -> 30273.137 | L30: =+K30-J30 -> -11793.088 | M30: =+M20-M25 -> 47800.389 | N30: =+K30-M30 -> -17527.252 | Q30: □ 기타내역(영업이익)
D31: % | E31: =+E30/E10 -> 0.16092892 | F31: =+F30/F10 -> 0.075057138 | G31: =+F31-E31 -> -0.085871783 | H31: =+H30/H10 -> 0.17041637 | I31: =+F31-H31 -> -0.095359232 | J31: =+J30/J10 -> 0.14367849 | K31: =+K30/K10 -> 0.10647451 | L31: =+K31-J31 -> -0.037203986 | M31: =+M30/M10 -> 0.15453568 | N31: =+K31-M31 -> -0.048061174 | Q31: 구분 | S31: 계획 | T31: 실적 | U31: 계획대비 | V31: 전년 | W31: 전년대비
D32: 건자재 | E32: =+E21-E26 -> 155.78428 | F32: =+F21-F26 -> 44.005329 | G32: =+F32-E32 -> -111.77895 | H32: =+H21-H26 -> 85.321437 | I32: =+F32-H32 -> -41.316108 | J32: =+J21-J26 -> 995.6551 | K32: =+K21-K26 -> 483.5037 | L32: =+K32-J32 -> -512.1514 | M32: =+M21-M26 -> 770.09028 | N32: =+K32-M32 -> -286.58658 | Q32: 레미콘임대 | S32: =+'사업장별(당월)'!T33 -> 72.165959 | T32: =+'사업장별(당월)'!U33 -> 71.16796 | U32: =+T32-S32 -> -0.997999 | V32: =+'사업장별(당월)'!W33 -> 71.889904 | W32: =+T32-V32 -> -0.721944
D33: 골재 | E33: =+E22-E27 -> 333.15138 | F33: =+F22-F27 -> -149.95785 | G33: =+F33-E33 -> -483.10923 | H33: =+H22-H27 -> 141.79206 | I33: =+F33-H33 -> -291.74991 | J33: =+J22-J27 -> 1547.0668 | K33: =+K22-K27 -> -3.9952527 | L33: =+K33-J33 -> -1551.062 | M33: =+M22-M27 -> 763.56614 | N33: =+K33-M33 -> -767.56139 | Q33: 임대 | S33: =+'사업장별(당월)'!T34 -> 62.030473 | T33: =+'사업장별(당월)'!U34 -> 63.705665 | U33: =+T33-S33 -> 1.6751917 | V33: =+'사업장별(당월)'!W34 -> 56.287941 | W33: =+T33-V33 -> 7.417724
D34: 기타 | E34: =+E23-E28 -> -1220.1833 | F34: =+F23-F28 -> -861.08329 | G34: =+F34-E34 -> 359.10005 | H34: =+H23-H28 -> -1062.4049 | I34: =+F34-H34 -> 201.3216 | J34: =+J23-J28 -> -12079.45 | K34: =+K23-K28 -> -13205.544 | L34: =+K34-J34 -> -1126.0943 | M34: =+M23-M28 -> -12862.149 | N34: =+K34-M34 -> -343.39495 | Q34: 공통비 | S34: =+'사업장별(당월)'!T35 -> -1239.3305 | T34: =+'사업장별(당월)'!U35 -> -1196.5785 | U34: =+T34-S34 -> 42.751972 | V34: =+'사업장별(당월)'!W35 -> -1214.5176 | W34: =+T34-V34 -> 17.939122
C35: 계 | E35: =SUM(E30,E32:E34) -> 4580.2039 | F35: =SUM(F30,F32:F34) -> 1174.2356 | G35: =+F35-E35 -> -3405.9683 | H35: =SUM(H30,H32:H34) -> 5006.0331 | I35: =+F35-H35 -> -3831.7975 | J35: =SUM(J30,J32:J34) -> 32529.497 | K35: =SUM(K30,K32:K34) -> 17547.101 | L35: =+K35-J35 -> -14982.396 | M35: =SUM(M30,M32:M34) -> 36471.896 | N35: =+K35-M35 -> -18924.795 | Q35: 기타 | S35: =+S36-S32-S33-S34 -> -115.04929 | T35: =+T36-T32-T33-T34 -> 200.62159 | U35: =+T35-S35 -> 315.67089 | V35: =+V36-V32-V33-V34 -> 23.934898 | W35: =+T35-V35 -> 176.68669
D36: % | E36: =+E35/E14 -> 0.098918067 | F36: =+F35/F14 -> 0.030405212 | G36: =+F36-E36 -> -0.068512855 | H36: =+H35/H14 -> 0.1051049 | I36: =+F36-H36 -> -0.074699684 | J36: =+J35/J14 -> 0.081056382 | K36: =+K35/K14 -> 0.04534534 | L36: =+K36-J36 -> -0.035711043 | M36: =+M35/M14 -> 0.086740644 | N36: =+K36-M36 -> -0.041395304 | Q36: 합계 | S36: =+'사업장별(당월)'!T41 -> -1220.1833 | T36: =+'사업장별(당월)'!U41 -> -861.08329 | U36: =+T36-S36 -> 359.10005 | V36: =+'사업장별(당월)'!W41 -> -1062.4049 | W36: =+T36-V36 -> 201.3216
E38: =+'[1]10월'!$E$26/1000 -> 4580.2039 | F38: =+'[2]10월'!$F$26/1000 -> 1174.2356 | H38: =+'[3]10월'!$F$26/1000 -> 5006.0331 | J38: =+[4]손익총괄!J38+E38 -> 32529.497 | K38: =+[4]손익총괄!K38+F38 -> 17547.101 | M38: =+[4]손익총괄!M38+H38 -> 36471.896
E39: =+E35=E38 -> FALSE | F39: =+F35=F38 -> FALSE | H39: =+H35=H38 -> TRUE | J39: =+J35=J38 -> TRUE | K39: =+K35=K38 -> TRUE | M39: =+M35=M38 -> TRUE
E40: =+E35-E38 -> 0 | F40: =+F35-F38 -> -6.5938366e-12 | H40: =+H35-H38 -> 0 | J40: =+J35-J38 -> 0 | K40: =+K35-K38 -> 0 | M40: =+M35-M38 -> 0

Sheet 사업장별(당월)
H3: □ 사업장별 손익실적(2024-10)
AG4: [단위 : 천㎥, 톤, 백만원]
H5: 구분 | J5: 물량 | O5: 매출 | T5: 영업이익(공통비 배부전) | Y5: 판매단가 | AB5: 변동비 | AE5: 공헌이익
J6: 계획 | K6: 실적 | L6: 차이 | M6: 전년 | N6: 차이 | O6: 계획 | P6: 실적 | Q6: 차이 | R6: 전년 | S6: 차이 | T6: 계획 | U6: 실적 | V6: 차이 | W6: 전년 | X6: 차이 | Y6: 계획 | Z6: 실적 | AA6: 전년 | AB6: 계획 | AC6: 실적 | AD6: 전년 | AE6: 계획 | AF6: 실적 | AG6: 전년
B7: 안양 | G7: =+I7 -> 안양 | H7: 레미콘 | I7: 안양 | J7: =+IFERROR(HLOOKUP($B7,'[1]10월'!$D$6:$BN$259,2,),)/1000 -> 43 | K7: =+IFERROR(HLOOKUP($B7,'[2]10월'!$F$6:$CP$99,2,),)/1000 -> 39.055 | L7: =+K7-J7 -> -3.945 | M7: =+IFERROR(HLOOKUP($B7,'[3]10월'!$F$6:$CC$57,2,),)/1000 -> 51.43 | N7: =+K7-M7 -> -12.375 | O7: =+IFERROR(HLOOKUP($B7,'[1]10월'!$D$6:$BN$259,3,),)/1000 -> 4325.9572 | P7: =+IFERROR(HLOOKUP($B7,'[2]10월'!$F$6:$CP$99,3,),)/1000 -> 3682.4273 | Q7: =+P7-O7 -> -643.52989 | R7: =+IFERROR(HLOOKUP($B7,'[3]10월'!$F$6:$CC$57,3,),)/1000 -> 4899.0204 | S7: =+P7-R7 -> -1216.5931 | T7: =+IFERROR(HLOOKUP($B7,'[1]10월'!$D$6:$BN$259,16,),)/1000 -> 642.15369 | U7: =+IFERROR(HLOOKUP($B7,'[2]10월'!$F$6:$CP$99,16,),)/1000 -> 151.42127 | V7: =+U7-T7 -> -490.73241 | W7: =+IFERROR(HLOOKUP($B7,'[3]10월'!$F$6:$CC$57,16,),)/1000 -> 878.60642 | X7: =+U7-W7 -> -727.18514 | Y7: =+[5]안양!$Q$85 -> 100603.66 | Z7: =+[5]안양!$R$85 -> 94288.243 | AA7: =+[6]안양!$Q$85 -> 95250.157 | AB7: =+[5]안양!$Q$89 -> 78584.856 | AC7: =+[5]안양!$R$89 -> 82720.758 | AD7: =+[6]안양!$Q$89 -> 72593.908 | AE7: =+Y7-AB7 -> 22018.799 | AF7: =+Z7-AC7 -> 11567.484 | AG7: =+AA7-AD7 -> 22656.249
B8: 인천 | G8: =+I8 -> 인천 | H8: 직영 | I8: 인천 | J8: =+IFERROR(HLOOKUP($B8,'[1]10월'!$D$6:$BN$259,2,),)/1000 -> 35 | K8: =+IFERROR(HLOOKUP($B8,'[2]10월'!$F$6:$CP$99,2,),)/1000 -> 26.461 | L8: =+K8-J8 -> -8.539 | M8: =+IFERROR(HLOOKUP($B8,'[3]10월'!$F$6:$CC$57,2,),)/1000 -> 36.932 | N8: =+K8-M8 -> -10.471 | O8: =+IFERROR(HLOOKUP($B8,'[1]10월'!$D$6:$BN$259,3,),)/1000 -> 3730.1457 | P8: =+IFERROR(HLOOKUP($B8,'[2]10월'!$F$6:$CP$99,3,),)/1000 -> 2558.6091 | Q8: =+P8-O8 -> -1171.5366 | R8: =+IFERROR(HLOOKUP($B8,'[3]10월'!$F$6:$CC$57,3,),)/1000 -> 3681.7834 | S8: =+P8-R8 -> -1123.1743 | T8: =+IFERROR(HLOOKUP($B8,'[1]10월'!$D$6:$BN$259,16,),)/1000 -> 599.24958 | U8: =+IFERROR(HLOOKUP($B8,'[2]10월'!$F$6:$CP$99,16,),)/1000 -> 63.89366 | V8: =+U8-T8 -> -535.35592 | W8: =+IFERROR(HLOOKUP($B8,'[3]10월'!$F$6:$CC$57,16,),)/1000 -> 548.9803 | X8: =+U8-W8 -> -485.08664 | Y8: =+[5]인천!$Q$85 -> 106575.59 | Z8: =+[5]인천!$R$85 -> 96693.589 | AA8: =+[6]인천!$Q$85 -> 99633.28 | AB8: =+[5]인천!$Q$89 -> 81397.734 | AC8: =+[5]인천!$R$89 -> 82558.135 | AD8: =+[6]인천!$Q$89 -> 76946.229 | AE8: =+Y8-AB8 -> 25177.858 | AF8: =+Z8-AC8 -> 14135.455 | AG8: =+AA8-AD8 -> 22687.051
B9: 파주 | G9: =+I9 -> 파주 | I9: 파주 | J9: =+IFERROR(HLOOKUP($B9,'[1]10월'!$D$6:$BN$259,2,),)/1000 -> 24 | K9: =+IFERROR(HLOOKUP($B9,'[2]10월'!$F$6:$CP$99,2,),)/1000 -> 26.27 | L9: =+K9-J9 -> 2.27 | M9: =+IFERROR(HLOOKUP($B9,'[3]10월'!$F$6:$CC$57,2,),)/1000 -> 29.047 | N9: =+K9-M9 -> -2.777 | O9: =+IFERROR(HLOOKUP($B9,'[1]10월'!$D$6:$BN$259,3,),)/1000 -> 2408.3832 | P9: =+IFERROR(HLOOKUP($B9,'[2]10월'!$F$6:$CP$99,3,),)/1000 -> 2323.423 | Q9: =+P9-O9 -> -84.960194 | R9: =+IFERROR(HLOOKUP($B9,'[3]10월'!$F$6:$CC$57,3,),)/1000 -> 2795.7611 | S9: =+P9-R9 -> -472.33808 | T9: =+IFERROR(HLOOKUP($B9,'[1]10월'!$D$6:$BN$259,16,),)/1000 -> 344.80583 | U9: =+IFERROR(HLOOKUP($B9,'[2]10월'!$F$6:$CP$99,16,),)/1000 -> 73.448678 | V9: =+U9-T9 -> -271.35715 | W9: =+IFERROR(HLOOKUP($B9,'[3]10월'!$F$6:$CC$57,16,),)/1000 -> 210.81257 | X9: =+U9-W9 -> -137.36389 | Y9: =+[5]파주!$Q$85 -> 100349.3 | Z9: =+[5]파주!$R$85 -> 88417.962 | AA9: =+[6]파주!$Q$85 -> 96050.413 | AB9: =+[5]파주!$Q$89 -> 76932.186 | AC9: =+[5]파주!$R$89 -> 77319.908 | AD9: =+[6]파주!$Q$89 -> 81480.789 | AE9: =+Y9-AB9 -> 23417.115 | AF9: =+Z9-AC9 -> 11098.054 | AG9: =+AA9-AD9 -> 14569.624
B10: 김포 | G10: =+I10 -> 김포 | I10: 김포 | J10: =+IFERROR(HLOOKUP($B10,'[1]10월'!$D$6:$BN$259,2,),)/1000 -> 19.5 | K10: =+IFERROR(HLOOKUP($B10,'[2]10월'!$F$6:$CP$99,2,),)/1000 -> 12.124 | L10: =+K10-J10 -> -7.376 | M10: =+IFERROR(HLOOKUP($B10,'[3]10월'!$F$6:$CC$57,2,),)/1000 -> 18.626 | N10: =+K10-M10 -> -6.502 | O10: =+IFERROR(HLOOKUP($B10,'[1]10월'!$D$6:$BN$259,3,),)/1000 -> 1886.7745 | P10: =+IFERROR(HLOOKUP($B10,'[2]10월'!$F$6:$CP$99,3,),)/1000 -> 1149.0606 | Q10: =+P10-O10 -> -737.7139 | R10: =+IFERROR(HLOOKUP($B10,'[3]10월'!$F$6:$CC$57,3,),)/1000 -> 1753.7472 | S10: =+P10-R10 -> -604.68659 | T10: =+IFERROR(HLOOKUP($B10,'[1]10월'!$D$6:$BN$259,16,),)/1000 -> 304.33331 | U10: =+IFERROR(HLOOKUP($B10,'[2]10월'!$F$6:$CP$99,16,),)/1000 -> 74.662069 | V10: =+U10-T10 -> -229.67124 | W10: =+IFERROR(HLOOKUP($B10,'[3]10월'!$F$6:$CC$57,16,),)/1000 -> 258.73897 | X10: =+U10-W10 -> -184.0769 | Y10: =+[5]김포!$Q$85 -> 96757.667 | Z10: =+[5]김포!$R$85 -> 94775.701 | AA10: =+[6]김포!$Q$85 -> 94155.868 | AB10: =+[5]김포!$Q$89 -> 72813.205 | AC10: =+[5]김포!$R$89 -> 75594.089 | AD10: =+[6]김포!$Q$89 -> 71718.789 | AE10: =+Y10-AB10 -> 23944.461 | AF10: =+Z10-AC10 -> 19181.613 | AG10: =+AA10-AD10 -> 22437.079
B11: 부산 | G11: =+I11 -> 부산 | I11: 부산 | J11: =+IFERROR(HLOOKUP($B11,'[1]10월'!$D$6:$BN$259,2,),)/1000 -> 24 | K11: =+IFERROR(HLOOKUP($B11,'[2]10월'!$F$6:$CP$99,2,),)/1000 -> 16.752 | L11: =+K11-J11 -> -7.248 | M11: =+IFERROR(HLOOKUP($B11,'[3]10월'!$F$6:$CC$57,2,),)/1000 -> 22.457 | N11: =+K11-M11 -> -5.705 | O11: =+IFERROR(HLOOKUP($B11,'[1]10월'!$D$6:$BN$259,3,),)/1000 -> 2582.4034 | P11: =+IFERROR(HLOOKUP($B11,'[2]10월'!$F$6:$CP$99,3,),)/1000 -> 1728.9812 | Q11: =+P11-O11 -> -853.4222 | R11: =+IFERROR(HLOOKUP($B11,'[3]10월'!$F$6:$CC$57,3,),)/1000 -> 2382.3234 | S11: =+P11-R11 -> -653.34224 | T11: =+IFERROR(HLOOKUP($B11,'[1]10월'!$D$6:$BN$259,16,),)/1000 -> 419.18794 | U11: =+IFERROR(HLOOKUP($B11,'[2]10월'!$F$6:$CP$99,16,),)/1000 -> 57.651193 | V11: =+U11-T11 -> -361.53675 | W11: =+IFERROR(HLOOKUP($B11,'[3]10월'!$F$6:$CC$57,16,),)/1000 -> 409.39305 | X11: =+U11-W11 -> -351.74186 | Y11: =+[5]부산!$Q$85 -> 107600.14 | Z11: =+[5]부산!$R$85 -> 103210.43 | AA11: =+[6]부산!$Q$85 -> 106083.78 | AB11: =+[5]부산!$Q$89 -> 79537.282 | AC11: =+[5]부산!$R$89 -> 83827.02 | AD11: =+[6]부산!$Q$89 -> 75899.939 | AE11: =+Y11-AB11 -> 28062.858 | AF11: =+Z11-AC11 -> 19383.412 | AG11: =+AA11-AD11 -> 30183.839
B12: 서부산 | G12: =+I12 -> 서부산 | I12: 서부산 | J12: =+IFERROR(HLOOKUP($B12,'[1]10월'!$D$6:$BN$259,2,),)/1000 -> 26 | K12: =+IFERROR(HLOOKUP($B12,'[2]10월'!$F$6:$CP$99,2,),)/1000 -> 19.663 | L12: =+K12-J12 -> -6.337 | M12: =+IFERROR(HLOOKUP($B12,'[3]10월'!$F$6:$CC$57,2,),)/1000 -> 28.123 | N12: =+K12-M12 -> -8.46 | O12: =+IFERROR(HLOOKUP($B12,'[1]10월'!$D$6:$BN$259,3,),)/1000 -> 2719.0035 | P12: =+IFERROR(HLOOKUP($B12,'[2]10월'!$F$6:$CP$99,3,),)/1000 -> 1865.5519 | Q12: =+P12-O12 -> -853.4516 | R12: =+IFERROR(HLOOKUP($B12,'[3]10월'!$F$6:$CC$57,3,),)/1000 -> 2771.162 | S12: =+P12-R12 -> -905.61008 | T12: =+IFERROR(HLOOKUP($B12,'[1]10월'!$D$6:$BN$259,16,),)/1000 -> 490.26668 | U12: =+IFERROR(HLOOKUP($B12,'[2]10월'!$F$6:$CP$99,16,),)/1000 -> 132.60606 | V12: =+U12-T12 -> -357.66063 | W12: =+IFERROR(HLOOKUP($B12,'[3]10월'!$F$6:$CC$57,16,),)/1000 -> 646.7975 | X12: =+U12-W12 -> -514.19144 | Y12: =+[5]서부산!$Q$85 -> 104577.06 | Z12: =+[5]서부산!$R$85 -> 94876.261 | AA12: =+[6]서부산!$Q$85 -> 98537.212 | AB12: =+[5]서부산!$Q$89 -> 76327.595 | AC12: =+[5]서부산!$R$89 -> 77092.366 | AD12: =+[6]서부산!$Q$89 -> 68098.831 | AE12: =+Y12-AB12 -> 28249.464 | AF12: =+Z12-AC12 -> 17783.895 | AG12: =+AA12-AD12 -> 30438.38
B13: 김해 | G13: =+I13 -> 김해 | I13: 김해 | J13: =+IFERROR(HLOOKUP($B13,'[1]10월'!$D$6:$BN$259,2,),)/1000 -> 13 | K13: =+IFERROR(HLOOKUP($B13,'[2]10월'!$F$6:$CP$99,2,),)/1000 -> 13.655 | L13: =+K13-J13 -> 0.655 | M13: =+IFERROR(HLOOKUP($B13,'[3]10월'!$F$6:$CC$57,2,),)/1000 -> 15.318 | N13: =+K13-M13 -> -1.663 | O13: =+IFERROR(HLOOKUP($B13,'[1]10월'!$D$6:$BN$259,3,),)/1000 -> 1313 | P13: =+IFERROR(HLOOKUP($B13,'[2]10월'!$F$6:$CP$99,3,),)/1000 -> 1233.987 | Q13: =+P13-O13 -> -79.013 | R13: =+IFERROR(HLOOKUP($B13,'[3]10월'!$F$6:$CC$57,3,),)/1000 -> 1480.8425 | S13: =+P13-R13 -> -246.8555 | T13: =+IFERROR(HLOOKUP($B13,'[1]10월'!$D$6:$BN$259,16,),)/1000 -> 172.85459 | U13: =+IFERROR(HLOOKUP($B13,'[2]10월'!$F$6:$CP$99,16,),)/1000 -> 10.398047 | V13: =+U13-T13 -> -162.45654 | W13: =+IFERROR(HLOOKUP($B13,'[3]10월'!$F$6:$CC$57,16,),)/1000 -> 221.70567 | X13: =+U13-W13 -> -211.30762 | Y13: =+[5]김해!$Q$85 -> 101000 | Z13: =+[5]김해!$R$85 -> 90368.876 | AA13: =+[6]김해!$Q$85 -> 96671.524 | AB13: =+[5]김해!$Q$89 -> 77107.505 | AC13: =+[5]김해!$R$89 -> 78384.071 | AD13: =+[6]김해!$Q$89 -> 73341.192 | AE13: =+Y13-AB13 -> 23892.495 | AF13: =+Z13-AC13 -> 11984.804 | AG13: =+AA13-AD13 -> 23330.332
B14: 정관 | G14: =+I14 -> 정관 | I14: 정관 | J14: =+IFERROR(HLOOKUP($B14,'[1]10월'!$D$6:$BN$259,2,),)/1000 -> 18 | K14: =+IFERROR(HLOOKUP($B14,'[2]10월'!$F$6:$CP$99,2,),)/1000 -> 21.756 | L14: =+K14-J14 -> 3.756 | M14: =+IFERROR(HLOOKUP($B14,'[3]10월'!$F$6:$CC$57,2,),)/1000 -> 21.851 | N14: =+K14-M14 -> -0.095 | O14: =+IFERROR(HLOOKUP($B14,'[1]10월'!$D$6:$BN$259,3,),)/1000 -> 1872 | P14: =+IFERROR(HLOOKUP($B14,'[2]10월'!$F$6:$CP$99,3,),)/1000 -> 2122.0107 | Q14: =+P14-O14 -> 250.01072 | R14: =+IFERROR(HLOOKUP($B14,'[3]10월'!$F$6:$CC$57,3,),)/1000 -> 2160.2739 | S14: =+P14-R14 -> -38.263178 | T14: =+IFERROR(HLOOKUP($B14,'[1]10월'!$D$6:$BN$259,16,),)/1000 -> 269.83512 | U14: =+IFERROR(HLOOKUP($B14,'[2]10월'!$F$6:$CP$99,16,),)/1000 -> 142.76763 | V14: =+U14-T14 -> -127.06749 | W14: =+IFERROR(HLOOKUP($B14,'[3]10월'!$F$6:$CC$57,16,),)/1000 -> 384.15831 | X14: =+U14-W14 -> -241.39068 | Y14: =+[5]정관!$Q$85 -> 104000 | Z14: =+[5]정관!$R$85 -> 97536.805 | AA14: =+[6]정관!$Q$85 -> 98863.846 | AB14: =+[5]정관!$Q$89 -> 78304.336 | AC14: =+[5]정관!$R$89 -> 81346.355 | AD14: =+[6]정관!$Q$89 -> 72569.956 | AE14: =+Y14-AB14 -> 25695.664 | AF14: =+Z14-AC14 -> 16190.45 | AG14: =+AA14-AD14 -> 26293.89
B15: 양산 | G15: =+I15 -> 양산 | I15: 양산 | J15: =+IFERROR(HLOOKUP($B15,'[1]10월'!$D$6:$BN$259,2,),)/1000 -> 12 | K15: =+IFERROR(HLOOKUP($B15,'[2]10월'!$F$6:$CP$99,2,),)/1000 -> 13.908 | L15: =+K15-J15 -> 1.908 | M15: =+IFERROR(HLOOKUP($B15,'[3]10월'!$F$6:$CC$57,2,),)/1000 -> 11.729 | N15: =+K15-M15 -> 2.179 | O15: =+IFERROR(HLOOKUP($B15,'[1]10월'!$D$6:$BN$259,3,),)/1000 -> 1166.5218 | P15: =+IFERROR(HLOOKUP($B15,'[2]10월'!$F$6:$CP$99,3,),)/1000 -> 1309.0972 | Q15: =+P15-O15 -> 142.57537 | R15: =+IFERROR(HLOOKUP($B15,'[3]10월'!$F$6:$CC$57,3,),)/1000 -> 1101.1099 | S15: =+P15-R15 -> 207.98729 | T15: =+IFERROR(HLOOKUP($B15,'[1]10월'!$D$6:$BN$259,16,),)/1000 -> 183.28795 | U15: =+IFERROR(HLOOKUP($B15,'[2]10월'!$F$6:$CP$99,16,),)/1000 -> 152.35462 | V15: =+U15-T15 -> -30.933328 | W15: =+IFERROR(HLOOKUP($B15,'[3]10월'!$F$6:$CC$57,16,),)/1000 -> 156.70708 | X15: =+U15-W15 -> -4.352465 | Y15: =+[5]양산!$Q$85 -> 97210.153 | Z15: =+[5]양산!$R$85 -> 94125.482 | AA15: =+[6]양산!$Q$85 -> 93879.266 | AB15: =+[5]양산!$Q$89 -> 70800.643 | AC15: =+[5]양산!$R$89 -> 72678.271 | AD15: =+[6]양산!$Q$89 -> 68763.005 | AE15: =+Y15-AB15 -> 26409.51 | AF15: =+Z15-AC15 -> 21447.211 | AG15: =+AA15-AD15 -> 25116.261
B16: 창원 | G16: =+I16 -> 창원 | I16: 창원 | J16: =+IFERROR(HLOOKUP($B16,'[1]10월'!$D$6:$BN$259,2,),)/1000 -> 17 | K16: =+IFERROR(HLOOKUP($B16,'[2]10월'!$F$6:$CP$99,2,),)/1000 -> 14.58 | L16: =+K16-J16 -> -2.42 | M16: =+IFERROR(HLOOKUP($B16,'[3]10월'!$F$6:$CC$57,2,),)/1000 -> 20.989 | N16: =+K16-M16 -> -6.409 | O16: =+IFERROR(HLOOKUP($B16,'[1]10월'!$D$6:$BN$259,3,),)/1000 -> 1729.667 | P16: =+IFERROR(HLOOKUP($B16,'[2]10월'!$F$6:$CP$99,3,),)/1000 -> 1357.6853 | Q16: =+P16-O16 -> -371.9817 | R16: =+IFERROR(HLOOKUP($B16,'[3]10월'!$F$6:$CC$57,3,),)/1000 -> 2019.1504 | S16: =+P16-R16 -> -661.4651 | T16: =+IFERROR(HLOOKUP($B16,'[1]10월'!$D$6:$BN$259,16,),)/1000 -> 309.65579 | U16: =+IFERROR(HLOOKUP($B16,'[2]10월'!$F$6:$CP$99,16,),)/1000 -> 76.578861 | V16: =+U16-T16 -> -233.07693 | W16: =+IFERROR(HLOOKUP($B16,'[3]10월'!$F$6:$CC$57,16,),)/1000 -> 434.99491 | X16: =+U16-W16 -> -358.41605 | Y16: =+[5]창원!$Q$85 -> 101745.12 | Z16: =+[5]창원!$R$85 -> 93119.705 | AA16: =+[6]창원!$Q$85 -> 96200.41 | AB16: =+[5]창원!$Q$89 -> 72531.102 | AC16: =+[5]창원!$R$89 -> 74871.475 | AD16: =+[6]창원!$Q$89 -> 66786.157 | AE16: =+Y16-AB16 -> 29214.015 | AF16: =+Z16-AC16 -> 18248.23 | AG16: =+AA16-AD16 -> 29414.253
B17: 대구 | G17: =+I17 -> 대구 | I17: 대구 | J17: =+IFERROR(HLOOKUP($B17,'[1]10월'!$D$6:$BN$259,2,),)/1000 -> 16.5 | K17: =+IFERROR(HLOOKUP($B17,'[2]10월'!$F$6:$CP$99,2,),)/1000 -> 15.64 | L17: =+K17-J17 -> -0.86 | M17: =+IFERROR(HLOOKUP($B17,'[3]10월'!$F$6:$CC$57,2,),)/1000 -> 20.4465 | N17: =+K17-M17 -> -4.8065 | O17: =+IFERROR(HLOOKUP($B17,'[1]10월'!$D$6:$BN$259,3,),)/1000 -> 1613.04 | P17: =+IFERROR(HLOOKUP($B17,'[2]10월'!$F$6:$CP$99,3,),)/1000 -> 1465.4841 | Q17: =+P17-O17 -> -147.55595 | R17: =+IFERROR(HLOOKUP($B17,'[3]10월'!$F$6:$CC$57,3,),)/1000 -> 1901.5033 | S17: =+P17-R17 -> -436.01925 | T17: =+IFERROR(HLOOKUP($B17,'[1]10월'!$D$6:$BN$259,16,),)/1000 -> 288.58165 | U17: =+IFERROR(HLOOKUP($B17,'[2]10월'!$F$6:$CP$99,16,),)/1000 -> 100.63415 | V17: =+U17-T17 -> -187.94749 | W17: =+IFERROR(HLOOKUP($B17,'[3]10월'!$F$6:$CC$57,16,),)/1000 -> 408.14683 | X17: =+U17-W17 -> -307.51268 | Y17: =+[5]대구!$Q$85 -> 97760 | Z17: =+[5]대구!$R$85 -> 93698.609 | AA17: =+[6]대구!$Q$85 -> 93018.593 | AB17: =+[5]대구!$Q$89 -> 70182.877 | AC17: =+[5]대구!$R$89 -> 76355.669 | AD17: =+[6]대구!$Q$89 -> 65323.493 | AE17: =+Y17-AB17 -> 27577.123 | AF17: =+Z17-AC17 -> 17342.941 | AG17: =+AA17-AD17 -> 27695.1
B18: 울산 | G18: =+I18 -> 울산 | I18: 울산 | J18: =+IFERROR(HLOOKUP($B18,'[1]10월'!$D$6:$BN$259,2,),)/1000 -> 12 | K18: =+IFERROR(HLOOKUP($B18,'[2]10월'!$F$6:$CP$99,2,),)/1000 -> 14.267 | L18: =+K18-J18 -> 2.267 | M18: =+IFERROR(HLOOKUP($B18,'[3]10월'!$F$6:$CC$57,2,),)/1000 -> 8.732 | N18: =+K18-M18 -> 5.535 | O18: =+IFERROR(HLOOKUP($B18,'[1]10월'!$D$6:$BN$259,3,),)/1000 -> 1213.4895 | P18: =+IFERROR(HLOOKUP($B18,'[2]10월'!$F$6:$CP$99,3,),)/1000 -> 1420.6245 | Q18: =+P18-O18 -> 207.135 | R18: =+IFERROR(HLOOKUP($B18,'[3]10월'!$F$6:$CC$57,3,),)/1000 -> 821.1822 | S18: =+P18-R18 -> 599.4423 | T18: =+IFERROR(HLOOKUP($B18,'[1]10월'!$D$6:$BN$259,16,),)/1000 -> 130.01697 | U18: =+IFERROR(HLOOKUP($B18,'[2]10월'!$F$6:$CP$99,16,),)/1000 -> 157.77048 | V18: =+U18-T18 -> 27.753515 | W18: =+IFERROR(HLOOKUP($B18,'[3]10월'!$F$6:$CC$57,16,),)/1000 -> 46.27613 | X18: =+U18-W18 -> 111.49435 | Y18: =+[5]울산!$Q$85 -> 101124.12 | Z18: =+[5]울산!$R$85 -> 99574.157 | AA18: =+[6]울산!$Q$85 -> 93892.31 | AB18: =+[5]울산!$Q$89 -> 79322.963 | AC18: =+[5]울산!$R$89 -> 78942.319 | AD18: =+[6]울산!$Q$89 -> 74121.3 | AE18: =+Y18-AB18 -> 21801.162 | AF18: =+Z18-AC18 -> 20631.838 | AG18: =+AA18-AD18 -> 19771.01
B19: 아산 | G19: =+I19 -> 아산 | I19: 아산 | J19: =+IFERROR(HLOOKUP($B19,'[1]10월'!$D$6:$BN$259,2,),)/1000 -> 28 | K19: =+IFERROR(HLOOKUP($B19,'[2]10월'!$F$6:$CP$99,2,),)/1000 -> 35.1425 | L19: =+K19-J19 -> 7.1425 | M19: =+IFERROR(HLOOKUP($B19,'[3]10월'!$F$6:$CC$57,2,),)/1000 -> 30.139 | N19: =+K19-M19 -> 5.0035 | O19: =+IFERROR(HLOOKUP($B19,'[1]10월'!$D$6:$BN$259,3,),)/1000 -> 2828.015 | P19: =+IFERROR(HLOOKUP($B19,'[2]10월'!$F$6:$CP$99,3,),)/1000 -> 3417.0639 | Q19: =+P19-O19 -> 589.04891 | R19: =+IFERROR(HLOOKUP($B19,'[3]10월'!$F$6:$CC$57,3,),)/1000 -> 2877.9451 | S19: =+P19-R19 -> 539.11881 | T19: =+IFERROR(HLOOKUP($B19,'[1]10월'!$D$6:$BN$259,16,),)/1000 -> 443.55499 | U19: =+IFERROR(HLOOKUP($B19,'[2]10월'!$F$6:$CP$99,16,),)/1000 -> 518.14114 | V19: =+U19-T19 -> 74.586147 | W19: =+IFERROR(HLOOKUP($B19,'[3]10월'!$F$6:$CC$57,16,),)/1000 -> 452.27289 | X19: =+U19-W19 -> 65.868249 | Y19: =+[5]아산!$Q$85 -> 101000.54 | Z19: =+[5]아산!$R$85 -> 97210.458 | AA19: =+[6]아산!$Q$85 -> 95493.307 | AB19: =+[5]아산!$Q$89 -> 77532.35 | AC19: =+[5]아산!$R$89 -> 75321.505 | AD19: =+[6]아산!$Q$89 -> 73816.088 | AE19: =+Y19-AB19 -> 23468.186 | AF19: =+Z19-AC19 -> 21888.953 | AG19: =+AA19-AD19 -> 21677.219
B20: 전주 | G20: =+I20 -> 전주 | I20: 전주 | J20: =+IFERROR(HLOOKUP($B20,'[1]10월'!$D$6:$BN$259,2,),)/1000 -> 13 | K20: =+IFERROR(HLOOKUP($B20,'[2]10월'!$F$6:$CP$99,2,),)/1000 -> 9.6695 | L20: =+K20-J20 -> -3.3305 | M20: =+IFERROR(HLOOKUP($B20,'[3]10월'!$F$6:$CC$57,2,),)/1000 -> 12.4395 | N20: =+K20-M20 -> -2.77 | O20: =+IFERROR(HLOOKUP($B20,'[1]10월'!$D$6:$BN$259,3,),)/1000 -> 1320.0808 | P20: =+IFERROR(HLOOKUP($B20,'[2]10월'!$F$6:$CP$99,3,),)/1000 -> 921.15986 | Q20: =+P20-O20 -> -398.9209 | R20: =+IFERROR(HLOOKUP($B20,'[3]10월'!$F$6:$CC$57,3,),)/1000 -> 1210.6657 | S20: =+P20-R20 -> -289.50584 | T20: =+IFERROR(HLOOKUP($B20,'[1]10월'!$D$6:$BN$259,16,),)/1000 -> 228.75892 | U20: =+IFERROR(HLOOKUP($B20,'[2]10월'!$F$6:$CP$99,16,),)/1000 -> 51.295807 | V20: =+U20-T20 -> -177.46311 | W20: =+IFERROR(HLOOKUP($B20,'[3]10월'!$F$6:$CC$57,16,),)/1000 -> 248.53375 | X20: =+U20-W20 -> -197.23794 | Y20: =+[5]전주!$Q$85 -> 101544.67 | Z20: =+[5]전주!$R$85 -> 95264.477 | AA20: =+[6]전주!$Q$85 -> 97324.306 | AB20: =+[5]전주!$Q$89 -> 73140.013 | AC20: =+[5]전주!$R$89 -> 74505.129 | AD20: =+[6]전주!$Q$89 -> 66110.731 | AE20: =+Y20-AB20 -> 28404.661 | AF20: =+Z20-AC20 -> 20759.349 | AG20: =+AA20-AD20 -> 31213.575
B21: 군산 | G21: =+I21 -> 군산 | I21: 군산 | J21: =+IFERROR(HLOOKUP($B21,'[1]10월'!$D$6:$BN$259,2,),)/1000 -> 7 | K21: =+IFERROR(HLOOKUP($B21,'[2]10월'!$F$6:$CP$99,2,),)/1000 -> 9.023 | L21: =+K21-J21 -> 2.023 | M21: =+IFERROR(HLOOKUP($B21,'[3]10월'!$F$6:$CC$57,2,),)/1000 -> 8.6055 | N21: =+K21-M21 -> 0.4175 | O21: =+IFERROR(HLOOKUP($B21,'[1]10월'!$D$6:$BN$259,3,),)/1000 -> 761.47221 | P21: =+IFERROR(HLOOKUP($B21,'[2]10월'!$F$6:$CP$99,3,),)/1000 -> 1002.9886 | Q21: =+P21-O21 -> 241.51634 | R21: =+IFERROR(HLOOKUP($B21,'[3]10월'!$F$6:$CC$57,3,),)/1000 -> 903.96604 | S21: =+P21-R21 -> 99.022512 | T21: =+IFERROR(HLOOKUP($B21,'[1]10월'!$D$6:$BN$259,16,),)/1000 -> 200.39525 | U21: =+IFERROR(HLOOKUP($B21,'[2]10월'!$F$6:$CP$99,16,),)/1000 -> 268.54539 | V21: =+U21-T21 -> 68.150136 | W21: =+IFERROR(HLOOKUP($B21,'[3]10월'!$F$6:$CC$57,16,),)/1000 -> 252.05178 | X21: =+U21-W21 -> 16.493606 | Y21: =+[5]군산!$Q$85 -> 108781.74 | Z21: =+[5]군산!$R$85 -> 111159.1 | AA21: =+[6]군산!$Q$85 -> 105101.35 | AB21: =+[5]군산!$Q$89 -> 69630.38 | AC21: =+[5]군산!$R$89 -> 72170.12 | AD21: =+[6]군산!$Q$89 -> 67141.823 | AE21: =+Y21-AB21 -> 39151.364 | AF21: =+Z21-AC21 -> 38988.979 | AG21: =+AA21-AD21 -> 37959.531
B22: 원주 | G22: =+I22 -> 원주 | I22: 원주 | J22: =+IFERROR(HLOOKUP($B22,'[1]10월'!$D$6:$BN$259,2,),)/1000 -> 6 | K22: =+IFERROR(HLOOKUP($B22,'[2]10월'!$F$6:$CP$99,2,),)/1000 -> 5.544 | L22: =+K22-J22 -> -0.456 | M22: =+IFERROR(HLOOKUP($B22,'[3]10월'!$F$6:$CC$57,2,),)/1000 -> 6.439 | N22: =+K22-M22 -> -0.895 | O22: =+IFERROR(HLOOKUP($B22,'[1]10월'!$D$6:$BN$259,3,),)/1000 -> 647.4 | P22: =+IFERROR(HLOOKUP($B22,'[2]10월'!$F$6:$CP$99,3,),)/1000 -> 603.98328 | Q22: =+P22-O22 -> -43.416723 | R22: =+IFERROR(HLOOKUP($B22,'[3]10월'!$F$6:$CC$57,3,),)/1000 -> 663.01853 | S22: =+P22-R22 -> -59.035251 | T22: =+IFERROR(HLOOKUP($B22,'[1]10월'!$D$6:$BN$259,16,),)/1000 -> 123.06149 | U22: =+IFERROR(HLOOKUP($B22,'[2]10월'!$F$6:$CP$99,16,),)/1000 -> 104.30831 | V22: =+U22-T22 -> -18.753179 | W22: =+IFERROR(HLOOKUP($B22,'[3]10월'!$F$6:$CC$57,16,),)/1000 -> 129.33401 | X22: =+U22-W22 -> -25.025701 | Y22: =+[5]원주!$Q$85 -> 107900 | Z22: =+[5]원주!$R$85 -> 108943.59 | AA22: =+[6]원주!$Q$85 -> 102998.99 | AB22: =+[5]원주!$Q$89 -> 72860.633 | AC22: =+[5]원주!$R$89 -> 73906.808 | AD22: =+[6]원주!$Q$89 -> 70663.788 | AE22: =+Y22-AB22 -> 35039.367 | AF22: =+Z22-AC22 -> 35036.784 | AG22: =+AA22-AD22 -> 32335.199
B23: 제주 | G23: =+I23 -> 제주 | I23: 제주 | J23: =+IFERROR(HLOOKUP($B23,'[1]10월'!$D$6:$BN$259,2,),)/1000 -> 7 | K23: =+IFERROR(HLOOKUP($B23,'[2]10월'!$F$6:$CP$99,2,),)/1000 -> 3.047 | L23: =+K23-J23 -> -3.953 | M23: =+IFERROR(HLOOKUP($B23,'[3]10월'!$F$6:$CC$57,2,),)/1000 -> 7.2105 | N23: =+K23-M23 -> -4.1635 | O23: =+IFERROR(HLOOKUP($B23,'[1]10월'!$D$6:$BN$259,3,),)/1000 -> 887.6 | P23: =+IFERROR(HLOOKUP($B23,'[2]10월'!$F$6:$CP$99,3,),)/1000 -> 366.41407 | Q23: =+P23-O23 -> -521.18593 | R23: =+IFERROR(HLOOKUP($B23,'[3]10월'!$F$6:$CC$57,3,),)/1000 -> 853.32547 | S23: =+P23-R23 -> -486.9114 | T23: =+IFERROR(HLOOKUP($B23,'[1]10월'!$D$6:$BN$259,16,),)/1000 -> 161.45189 | U23: =+IFERROR(HLOOKUP($B23,'[2]10월'!$F$6:$CP$99,16,),)/1000 -> 4.79407 | V23: =+U23-T23 -> -156.65782 | W23: =+IFERROR(HLOOKUP($B23,'[3]10월'!$F$6:$CC$57,16,),)/1000 -> 153.81435 | X23: =+U23-W23 -> -149.02028 | Y23: =+[5]제주!$Q$85 -> 126800 | Z23: =+[5]제주!$R$85 -> 120254.04 | AA23: =+[6]제주!$Q$85 -> 118440.38 | AB23: =+[5]제주!$Q$89 -> 91213.272 | AC23: =+[5]제주!$R$89 -> 91133.112 | AD23: =+[6]제주!$Q$89 -> 83392.471 | AE23: =+Y23-AB23 -> 35586.728 | AF23: =+Z23-AC23 -> 29120.931 | AG23: =+AA23-AD23 -> 35047.91
G24: =+I24 -> 수도권 | I24: 수도권 | J24: =SUM(J7:J10) -> 121.5 | K24: =SUM(K7:K10) -> 103.91 | L24: =+K24-J24 -> -17.59 | M24: =SUM(M7:M10) -> 136.035 | N24: =+K24-M24 -> -32.125 | O24: =SUM(O7:O10) -> 12351.261 | P24: =SUM(P7:P10) -> 9713.52 | Q24: =+P24-O24 -> -2637.7406 | R24: =SUM(R7:R10) -> 13130.312 | S24: =+P24-R24 -> -3416.7921 | T24: =SUM(T7:T10) -> 1890.5424 | U24: =SUM(U7:U10) -> 363.42568 | V24: =+U24-T24 -> -1527.1167 | W24: =SUM(W7:W10) -> 1897.1383 | X24: =+U24-W24 -> -1533.7126 | Y24: =+[5]수도권!$Q$85 -> 101656.47 | Z24: =+[5]수도권!$R$85 -> 93480.666 | AA24: =+[6]수도권!$Q$85 -> 96457.33 | AB24: =+[5]수도권!$Q$89 -> 78142.383 | AC24: =+[5]수도권!$R$89 -> 80496.449 | AD24: =+[6]수도권!$Q$89 -> 75526.788 | AE24: =+Y24-AB24 -> 23514.084 | AF24: =+Z24-AC24 -> 12984.216 | AG24: =+AA24-AD24 -> 20930.542
G25: =+I25 -> 영남권 | I25: 영남권 | J25: =SUM(J11:J18) -> 138.5 | K25: =SUM(K11:K18) -> 130.221 | L25: =+K25-J25 -> -8.279 | M25: =SUM(M11:M18) -> 149.6455 | N25: =+K25-M25 -> -19.4245 | O25: =SUM(O11:O18) -> 14209.125 | P25: =SUM(P11:P18) -> 12503.422 | Q25: =+P25-O25 -> -1705.7034 | R25: =SUM(R11:R18) -> 14637.548 | S25: =+P25-R25 -> -2134.1258 | T25: =SUM(T11:T18) -> 2263.6867 | U25: =SUM(U11:U18) -> 830.76104 | V25: =+U25-T25 -> -1432.9256 | W25: =SUM(W11:W18) -> 2708.1795 | X25: =+U25-W25 -> -1877.4184 | Y25: =+[5]영남권!$Q$85 -> 102592.96 | Z25: =+[5]영남권!$R$85 -> 96016.649 | AA25: =+[6]영남권!$Q$85 -> 97820.439 | AB25: =+[5]영남권!$Q$89 -> 75796.515 | AC25: =+[5]영남권!$R$89 -> 78191.758 | AD25: =+[6]영남권!$Q$89 -> 70291.214 | AE25: =+Y25-AB25 -> 26796.447 | AF25: =+Z25-AC25 -> 17824.891 | AG25: =+AA25-AD25 -> 27529.225
G26: =+I26 -> 중부권 | I26: 중부권 | J26: =SUM(J19:J23) -> 61 | K26: =SUM(K19:K23) -> 62.426 | L26: =+K26-J26 -> 1.426 | M26: =SUM(M19:M23) -> 64.8335 | N26: =+K26-M26 -> -2.4075 | O26: =SUM(O19:O23) -> 6444.568 | P26: =SUM(P19:P23) -> 6311.6097 | Q26: =+P26-O26 -> -132.9583 | R26: =SUM(R19:R23) -> 6508.9208 | S26: =+P26-R26 -> -197.31117 | T26: =SUM(T19:T23) -> 1157.2225 | U26: =SUM(U19:U23) -> 947.08472 | V26: =+U26-T26 -> -210.13782 | W26: =SUM(W19:W23) -> 1236.0068 | X26: =+U26-W26 -> -288.92206 | Y26: =+[5]중부권!$Q$85 -> 105648.66 | Z26: =+[5]중부권!$R$85 -> 101095.66 | AA26: =+[6]중부권!$Q$85 -> 100356.67 | AB26: =+[5]중부권!$Q$89 -> 76799.923 | AC26: =+[5]중부권!$R$89 -> 75393.477 | AD26: =+[6]중부권!$Q$89 -> 72173.801 | AE26: =+Y26-AB26 -> 28848.732 | AF26: =+Z26-AC26 -> 25702.179 | AG26: =+AA26-AD26 -> 28182.868
G27: =+K27/J27 -> 0.92385358 | H27: 레미콘 계 | J27: =SUM(J24:J26) -> 321 | K27: =SUM(K24:K26) -> 296.557 | L27: =+K27-J27 -> -24.443 | M27: =SUM(M24:M26) -> 350.514 | N27: =+K27-M27 -> -53.957 | O27: =SUM(O24:O26) -> 33004.954 | P27: =SUM(P24:P26) -> 28528.552 | Q27: =+P27-O27 -> -4476.4023 | R27: =SUM(R24:R26) -> 34276.781 | S27: =+P27-R27 -> -5748.229 | T27: =SUM(T24:T26) -> 5311.4516 | U27: =SUM(U24:U26) -> 2141.2714 | V27: =+U27-T27 -> -3170.1802 | W27: =SUM(W24:W26) -> 5841.3245 | X27: =+U27-W27 -> -3700.0531 | Y27: =+[5]합계!$Q$85 -> 102819.17 | Z27: =+[5]합계!$R$85 -> 96197.561 | AA27: =+[6]합계!$Q$85 -> 97761.738 | AB27: =+[5]합계!$Q$89 -> 76875.116 | AC27: =+[5]합계!$R$89 -> 78411.451 | AD27: =+[6]합계!$Q$89 -> 72669.741 | AE27: =+Y27-AB27 -> 25944.055 | AF27: =+Z27-AC27 -> 17786.111 | AG27: =+AA27-AD27 -> 25091.997
B28: 건자재 | E28: 건자재영업 | G28: 건자재 | H28: 건자재 | J28: =+IFERROR(HLOOKUP($B28,'[1]10월'!$D$6:$BN$259,2,),) -> 8900 | K28: =+IFERROR(HLOOKUP($E28,'[2]10월'!$F$6:$CP$99,2,),) -> 8972.008 | L28: =+K28-J28 -> 72.008 | M28: =+IFERROR(HLOOKUP($E28,'[3]10월'!$F$6:$CC$57,2,),) -> 9070.045 | N28: =+K28-M28 -> -98.037 | O28: =+IFERROR(HLOOKUP($B28,'[1]10월'!$D$6:$BN$259,3,),)/1000 -> 10873.417 | P28: =+IFERROR(HLOOKUP($E28,'[2]10월'!$F$6:$CP$99,3,),)/1000 -> 8678.6853 | Q28: =+P28-O28 -> -2194.7316 | R28: =+IFERROR(HLOOKUP($E28,'[3]10월'!$F$6:$CC$57,3,),)/1000 -> 11314.06 | S28: =+P28-R28 -> -2635.3749 | T28: =+IFERROR(HLOOKUP($B28,'[1]10월'!$D$6:$BN$259,16,),)/1000 -> 155.78428 | U28: =+IFERROR(HLOOKUP($E28,'[2]10월'!$F$6:$CP$99,16,),)/1000 -> 44.005329 | V28: =+U28-T28 -> -111.77895 | W28: =+IFERROR(HLOOKUP($E28,'[3]10월'!$F$6:$CC$57,16,),)/1000 -> 85.321437 | X28: =+U28-W28 -> -41.316108 | Y28: ■ 비고
B29: 부산모래장 | C29: 부산골재 | G29: =+I29 -> 부산모래장 | H29: 골재 | I29: 부산모래장 | J29: =+IFERROR(HLOOKUP($B29,'[1]10월'!$D$6:$BN$259,2,),)/1000 -> 29.254222 | K29: =+IFERROR(HLOOKUP($C29,'[2]10월'!$F$6:$CP$99,2,),)/1000 -> 20.119 | L29: =+K29-J29 -> -9.1352225 | M29: =+IFERROR(HLOOKUP($C29,'[3]10월'!$F$6:$CC$57,2,),)/1000 -> 29.978 | N29: =+K29-M29 -> -9.859 | O29: =+IFERROR(HLOOKUP($B29,'[1]10월'!$D$6:$BN$259,3,),)/1000 -> 832.16381 | P29: =+IFERROR(HLOOKUP($C29,'[2]10월'!$F$6:$CP$99,3,),)/1000 -> 571.11 | Q29: =+P29-O29 -> -261.05381 | R29: =+IFERROR(HLOOKUP($C29,'[3]10월'!$F$6:$CC$57,3,),)/1000 -> 855.205 | S29: =+P29-R29 -> -284.095 | T29: =+IFERROR(HLOOKUP($B29,'[1]10월'!$D$6:$BN$259,21,),)/1000 -> 60.533391 | U29: =+IFERROR(HLOOKUP($C29,'[2]10월'!$F$6:$CP$99,21,),)/1000 -> 53.934357 | V29: =+U29-T29 -> -6.5990338 | W29: =+IFERROR(HLOOKUP($C29,'[3]10월'!$F$6:$CC$57,16,),)/1000 -> 31.332617 | X29: =+U29-W29 -> 22.60174 | Y29: ▶ 판매단가 소급
B30: 서부산크라샤 | C30: 서부산골재 | G30: =+I30 -> 서부산CR | I30: 서부산CR | J30: =+IFERROR(HLOOKUP($B30,'[1]10월'!$D$6:$BN$259,2,),)/1000 -> 51.352963 | K30: =+IFERROR(HLOOKUP($C30,'[2]10월'!$F$6:$CP$99,2,),)/1000 -> 1.36 | L30: =+K30-J30 -> -49.992963 | M30: =+IFERROR(HLOOKUP($C30,'[3]10월'!$F$6:$CC$57,2,),)/1000 -> 33.644 | N30: =+K30-M30 -> -32.284 | O30: =+IFERROR(HLOOKUP($B30,'[1]10월'!$D$6:$BN$259,3,),)/1000 -> 637.54945 | P30: =+IFERROR(HLOOKUP($C30,'[2]10월'!$F$6:$CP$99,3,),)/1000 -> 15.64 | Q30: =+P30-O30 -> -621.90945 | R30: =+IFERROR(HLOOKUP($C30,'[3]10월'!$F$6:$CC$57,3,),)/1000 -> 400.76 | S30: =+P30-R30 -> -385.12 | T30: =+IFERROR(HLOOKUP($B30,'[1]10월'!$D$6:$BN$259,21,),)/1000 -> 174.00076 | U30: =+IFERROR(HLOOKUP($C30,'[2]10월'!$F$6:$CP$99,21,),)/1000 -> -83.948514 | V30: =+U30-T30 -> -257.94928 | W30: =+IFERROR(HLOOKUP($C30,'[3]10월'!$F$6:$CC$57,16,),)/1000 -> 41.015432 | X30: =+U30-W30 -> -124.96395 | Y30: - GS : 952백만원
B31: 부산크라샤 | C31: 부산크라샤 | G31: =+I31 -> 부산CR | I31: 부산CR | J31: =+IFERROR(HLOOKUP($B31,'[1]10월'!$D$6:$BN$259,2,),)/1000 -> 43.565728 | K31: =+IFERROR(HLOOKUP($C31,'[2]10월'!$F$6:$CP$99,2,),)/1000 -> 38.611 | L31: =+K31-J31 -> -4.9547281 | M31: =+IFERROR(HLOOKUP($C31,'[3]10월'!$F$6:$CC$57,2,),)/1000 -> 34.889 | N31: =+K31-M31 -> 3.722 | O31: =+IFERROR(HLOOKUP($B31,'[1]10월'!$D$6:$BN$259,3,),)/1000 -> 790.01556 | P31: =+IFERROR(HLOOKUP($C31,'[2]10월'!$F$6:$CP$99,3,),)/1000 -> 659.0685 | Q31: =+P31-O31 -> -130.94706 | R31: =+IFERROR(HLOOKUP($C31,'[3]10월'!$F$6:$CC$57,3,),)/1000 -> 596.328 | S31: =+P31-R31 -> 62.7405 | T31: =+IFERROR(HLOOKUP($B31,'[1]10월'!$D$6:$BN$259,21,),)/1000 -> 98.617225 | U31: =+IFERROR(HLOOKUP($C31,'[2]10월'!$F$6:$CP$99,21,),)/1000 -> -119.94369 | V31: =+U31-T31 -> -218.56092 | W31: =+IFERROR(HLOOKUP($C31,'[3]10월'!$F$6:$CC$57,16,),)/1000 -> 69.444007 | X31: =+U31-W31 -> -189.3877 | Y31: - 디엘이앤씨 53백만원, 삼환기업 40백만원, 디엘건설 7백만원
H32: 골재 계 | J32: =SUM(J29:J31) -> 124.17291 | K32: =SUM(K29:K31) -> 60.09 | L32: =+K32-J32 -> -64.082914 | M32: =SUM(M29:M31) -> 98.511 | N32: =+K32-M32 -> -38.421 | O32: =SUM(O29:O31) -> 2259.7288 | P32: =SUM(P29:P31) -> 1245.8185 | Q32: =+P32-O32 -> -1013.9103 | R32: =SUM(R29:R31) -> 1852.293 | S32: =+P32-R32 -> -606.4745 | T32: =SUM(T29:T31) -> 333.15138 | U32: =SUM(U29:U31) -> -149.95785 | V32: =+U32-T32 -> -483.10923 | W32: =SUM(W29:W31) -> 141.79206 | X32: =+U32-W32 -> -291.74991
B33: 포항임대 | C33: 속초임대 | D33: 강릉임대 | E33: 레미콘임대 계 | G33: =+I33 -> 레미콘임대 | H33: 기타 | I33: 레미콘임대 | L33: =+K33-J33 -> 0 | N33: =+K33-M33 -> 0 | O33: =(IFERROR(HLOOKUP($B33,'[1]10월'!$D$6:$BN$259,3,),)++IFERROR(HLOOKUP($C33,'[1]10월'!$D$6:$BN$259,3,),)+IFERROR(HLOOKUP($D33,'[1]10월'!$D$6:$BN$259,3,),))/1000 -> 90.84 | P33: =+IFERROR(HLOOKUP($E33,'[2]10월'!$F$6:$CP$99,3,),)/1000 -> 90.84 | Q33: =+P33-O33 -> 0 | R33: =+IFERROR(HLOOKUP($E33,'[3]10월'!$F$6:$CC$57,3,),)/1000 -> 90.84 | S33: =+P33-R33 -> 0 | T33: =(IFERROR(HLOOKUP($B33,'[1]10월'!$D$6:$BN$259,21,),)++IFERROR(HLOOKUP($C33,'[1]10월'!$D$6:$BN$259,21,),)+IFERROR(HLOOKUP($D33,'[1]10월'!$D$6:$BN$259,21,),))/1000 -> 72.165959 | U33: =+IFERROR(HLOOKUP($E33,'[2]10월'!$F$6:$CP$99,16,),)/1000 -> 71.16796 | V33: =+U33-T33 -> -0.997999 | W33: =+IFERROR(HLOOKUP($E33,'[3]10월'!$F$6:$CC$57,16,),)/1000 -> 71.889904 | X33: =+U33-W33 -> -0.721944 | Y33: ▶ 운반비 소급
B34: 부동산임대 | C34: 주유소임대 | E34: 임대 계 | G34: =+I34 -> 임대 | I34: 임대 | L34: =+K34-J34 -> 0 | M34: 0 | N34: =+K34-M34 -> 0 | O34: =(+IFERROR(HLOOKUP($B34,'[1]10월'!$D$6:$BN$259,3,),)+IFERROR(HLOOKUP($C34,'[1]10월'!$D$6:$BN$259,3,),))/1000 -> 72.2975 | P34: =+IFERROR(HLOOKUP($E34,'[2]10월'!$F$6:$CP$99,3,),)/1000 -> 73.837421 | Q34: =+P34-O34 -> 1.5399207 | R34: =+IFERROR(HLOOKUP($E34,'[3]10월'!$F$6:$CC$57,3,),)/1000 -> 93.176517 | S34: =+P34-R34 -> -19.339096 | T34: =(+IFERROR(HLOOKUP($B34,'[1]10월'!$D$6:$BN$259,21,),)+IFERROR(HLOOKUP($C34,'[1]10월'!$D$6:$BN$259,21,),))/1000 -> 62.030473 | U34: =+IFERROR(HLOOKUP($E34,'[2]10월'!$F$6:$CP$99,16,),)/1000 -> 63.705665 | V34: =+U34-T34 -> 1.6751917 | W34: =+IFERROR(HLOOKUP($E34,'[3]10월'!$F$6:$CC$57,16,),)/1000 -> 56.287941 | X34: =+U34-W34 -> 7.417724 | Y34: - 안양 : 4,350만원
B35: 공 통 비 | G35: =+I35 -> 공통비 | I35: 공통비 | L35: =+K35-J35 -> 0 | N35: =+K35-M35 -> 0 | Q35: =+P35-O35 -> 0 | S35: =+P35-R35 -> 0 | T35: =-'[1]10월'!$Z$22/1000 -> -1239.3305 | U35: =+-'[2]10월'!$Z$22/1000 -> -1196.5785 | V35: =+U35-T35 -> 42.751972 | W35: =+-'[3]10월'!$Z$22/1000 -> -1214.5176 | X35: =+U35-W35 -> 17.939122
G36: =+I36 -> OPC 소급분 | I36: OPC 소급분 | N36: =+K36-M36 -> 0 | Q36: =+P36-O36 -> 0 | S36: =+P36-R36 -> 0 | T36: =+'[1]10월'!$AS$26/1000 -> 0 | U36: ='[2]10월'!$BD$26/1000 -> 250 | V36: =+U36-T36 -> 250 | W36: =-'[3]10월'!$BD$26/1000 -> 0 | X36: =+U36-W36 -> 250
G37: =+I37 -> 대손 | I37: 대손 | N37: =+K37-M37 -> 0 | Q37: =+P37-O37 -> 0 | S37: =+P37-R37 -> 0 | U37: ='[2]10월'!$BE$26/1000 -> 0 | V37: =+U37-T37 -> 0 | W37: ='[3]10월'!$BE$26/1000 -> 49 | X37: =+U37-W37 -> -49
G38: =+I38 -> 미운영 공장 | I38: 미운영 공장 | M38: =SUM(M54:M57) -> 0 | N38: =+K38-M38 -> 0 | Q38: =+P38-O38 -> 0 | R38: =+IFERROR(HLOOKUP($I$38,'[3]10월'!$F$6:$BJ$50,3,),)/1000 -> 0 | S38: =+P38-R38 -> 0 | T38: =SUM('[1]10월'!$AM$26:$AQ$26)/1000 -> -35.767484 | U38: =+'[2]10월'!$BF$26/1000 -> -32.623866 | V38: =+U38-T38 -> 3.1436184 | W38: =+'[3]10월'!$BF$26/1000 -> -9.41434 | X38: =+U38-W38 -> -23.209526
B39: 기타 계 | G39: =+I39 -> 기타 | I39: 기타 | L39: =+K39-J39 -> 0 | N39: =+K39-M39 -> 0 | O39: =IFERROR(HLOOKUP($B39,'[1]10월'!$D$6:$BN$259,3,),)/1000 -> 1.77 | P39: =+('[2]10월'!$F$8-SUM('[2]10월'!$Z$8,'[2]10월'!$AH$8,'[2]10월'!$AN$8,'[2]10월'!$AO$8,'[2]10월'!$BA$8,'[2]10월'!$BD$8,'[2]10월'!$BE$8,'[2]10월'!$BF$8))/1000 -> 1.8182 | Q39: =+P39-O39 -> 0.0482 | R39: =+('[3]10월'!$F$8-SUM('[3]10월'!$Z$8,'[3]10월'!$AH$8,'[3]10월'!$AN$8,'[3]10월'!$AO$8,'[3]10월'!$BA$8,'[3]10월'!$BD$8,'[3]10월'!$BE$8,'[3]10월'!$BF$8))/1000 -> 1.7741 | S39: =+P39-R39 -> 0.0441 | T39: =+('[1]10월'!$E$26-'[1]10월'!$Z$26-'[1]10월'!$AA$26-'[1]10월'!$AE$26-'[1]10월'!$AL$26-'[1]10월'!$AM$26-'[1]10월'!$AN$26-'[1]10월'!$AO$26-'[1]10월'!$AP$26-'[1]10월'!$AQ$26-'[1]10월'!$AS$26)/1000 -> -79.281808 | U39: =+('[2]10월'!$F$26-SUM('[2]10월'!$Z$26,'[2]10월'!$AH$26,'[2]10월'!$AN$26,'[2]10월'!$AO$26,'[2]10월'!$BA$26,'[2]10월'!$BD$26,'[2]10월'!$BE$26,'[2]10월'!$BF$26))/1000 -> -16.754541 | V39: =+U39-T39 -> 62.527267 | W39: =+('[3]10월'!$F$26-SUM('[3]10월'!$Z$26,'[3]10월'!$AH$26,'[3]10월'!$AN$26,'[3]10월'!$AO$26,'[3]10월'!$BA$26,'[3]10월'!$BD$26,'[3]10월'!$BE$26,'[3]10월'!$BF$26))/1000 -> -15.650762 | X39: =+U39-W39 -> -1.103779
N40: =+K40-M40 -> 0 | Q40: =+P40-O40 -> 0 | S40: =+P40-R40 -> 0 | V40: =+U40-T40 -> 0
H41: 기타 계 | J41: =SUM(J33:J40) -> 0 | K41: =SUM(K33:K40) -> 0 | L41: =+K41-J41 -> 0 | M41: =SUM(M33:M40) -> 0 | N41: =+K41-M41 -> 0 | O41: =SUM(O33:O40) -> 164.9075 | P41: =SUM(P33:P40) -> 166.49562 | Q41: =+P41-O41 -> 1.5881207 | R41: =SUM(R33:R40) -> 185.79062 | S41: =+P41-R41 -> -19.294996 | T41: =SUM(T33:T40) -> -1220.1833 | U41: =SUM(U33:U40) -> -861.08329 | V41: =+U41-T41 -> 359.10005 | W41: =SUM(W33:W40) -> -1062.4049 | X41: =+U41-W41 -> 201.3216
U42: 19 | V42: 12.4
...

Sheet 사업장별(누계)
H3: □ 사업장별 손익실적(2024-10누계)
AG4: [단위 : 천㎥, 톤, 백만원]
H5: 구분 | J5: 물량 | O5: 매출 | T5: 영업이익(공통비 배부전) | Y5: 판매단가 | AB5: 변동비 | AE5: 공헌이익
J6: 계획 | K6: 실적 | L6: 차이 | M6: 전년 | N6: 차이 | O6: 계획 | P6: 실적 | Q6: 차이 | R6: 전년 | S6: 차이 | T6: 계획 | U6: 실적 | V6: 차이 | W6: 전년 | X6: 차이 | Y6: 계획 | Z6: 실적 | AA6: 전년 | AB6: 계획 | AC6: 실적 | AD6: 전년 | AE6: 계획 | AF6: 실적 | AG6: 전년
B7: 안양 | F7: =+U7/T7 -> 0.61185956 | G7: =+K7/J7 -> 0.9047724 | H7: 레미콘 | I7: 안양 | J7: =+'사업장별(당월)'!J7+'[4]사업장별(누계)'!J7 -> 413 | K7: =+'사업장별(당월)'!K7+'[4]사업장별(누계)'!K7 -> 373.671 | L7: =+K7-J7 -> -39.329 | M7: =+'사업장별(당월)'!M7+'[4]사업장별(누계)'!M7 -> 451.318 | N7: =+K7-M7 -> -77.647 | O7: =+'사업장별(당월)'!O7+'[4]사업장별(누계)'!O7 -> 41395.914 | P7: =+'사업장별(당월)'!P7+'[4]사업장별(누계)'!P7 -> 37039.865 | Q7: =+P7-O7 -> -4356.0492 | R7: =+'사업장별(당월)'!R7+'[4]사업장별(누계)'!R7 -> 42064.133 | S7: =+P7-R7 -> -5024.2672 | T7: =+'사업장별(당월)'!T7+'[4]사업장별(누계)'!T7 -> 5712.3422 | U7: =+'사업장별(당월)'!U7+'[4]사업장별(누계)'!U7 -> 3495.1512 | V7: =+U7-T7 -> -2217.191 | W7: =+'사업장별(당월)'!W7+'[4]사업장별(누계)'!W7 -> 6228.1904 | X7: =+U7-W7 -> -2733.0392 | Y7: =+[11]안양!$Q$85 -> 100232.24 | Z7: =+[11]안양!$R$85 -> 99119.962 | AA7: =+[12]안양!$Q$85 -> 93178.954 | AB7: =+[11]안양!$Q$89 -> 78982.697 | AC7: =+[11]안양!$R$89 -> 81575.399 | AD7: =+[12]안양!$Q$89 -> 72902.644 | AE7: =+Y7-AB7 -> 21249.541 | AF7: =+Z7-AC7 -> 17544.563 | AG7: =+AA7-AD7 -> 20276.309 | AI7: =+U7/T7-1 -> -0.38814044 | AJ7: =+U7/T7 -> 0.61185956 | AK7: =+Z7-Y7 -> -1112.2764 | AL7: =+AC7-AB7 -> 2592.7024 | AM7: =+AF7-AE7 -> -3704.9788
B8: 인천 | F8: =+U8/T8 -> 0.48025182 | G8: =+K8/J8 -> 0.86712662 | H8: 직영 | I8: 인천 | J8: =+'사업장별(당월)'!J8+'[4]사업장별(누계)'!J8 -> 308 | K8: =+'사업장별(당월)'!K8+'[4]사업장별(누계)'!K8 -> 267.075 | L8: =+K8-J8 -> -40.925 | M8: =+'사업장별(당월)'!M8+'[4]사업장별(누계)'!M8 -> 371.923 | N8: =+K8-M8 -> -104.848 | O8: =+'사업장별(당월)'!O8+'[4]사업장별(누계)'!O8 -> 31452.616 | P8: =+'사업장별(당월)'!P8+'[4]사업장별(누계)'!P8 -> 26610.64 | Q8: =+P8-O8 -> -4841.9759 | R8: =+'사업장별(당월)'!R8+'[4]사업장별(누계)'!R8 -> 35784.89 | S8: =+P8-R8 -> -9174.2499 | T8: =+'사업장별(당월)'!T8+'[4]사업장별(누계)'!T8 -> 3461.4375 | U8: =+'사업장별(당월)'!U8+'[4]사업장별(누계)'!U8 -> 1662.3617 | V8: =+U8-T8 -> -1799.0758 | W8: =+'사업장별(당월)'!W8+'[4]사업장별(누계)'!W8 -> 4468.8093 | X8: =+U8-W8 -> -2806.4477 | Y8: =+[11]인천!$Q$85 -> 102118.88 | Z8: =+[11]인천!$R$85 -> 99641.374 | AA8: =+[12]인천!$Q$85 -> 96189.949 | AB8: =+[11]인천!$Q$89 -> 81179.767 | AC8: =+[11]인천!$R$89 -> 82366.897 | AD8: =+[12]인천!$Q$89 -> 76069.849 | AE8: =+Y8-AB8 -> 20939.115 | AF8: =+Z8-AC8 -> 17274.477 | AG8: =+AA8-AD8 -> 20120.1 | AI8: =+U8/T8-1 -> -0.51974818 | AK8: =+Z8-Y8 -> -2477.508 | AL8: =+AC8-AB8 -> 1187.1297 | AM8: =+AF8-AE8 -> -3664.6377
B9: 파주 | F9: =+U9/T9 -> 0.52020314 | G9: =+K9/J9 -> 0.99469388 | I9: 파주 | J9: =+'사업장별(당월)'!J9+'[4]사업장별(누계)'!J9 -> 245 | K9: =+'사업장별(당월)'!K9+'[4]사업장별(누계)'!K9 -> 243.7 | L9: =+K9-J9 -> -1.3 | M9: =+'사업장별(당월)'!M9+'[4]사업장별(누계)'!M9 -> 263.189 | N9: =+K9-M9 -> -19.489 | O9: =+'사업장별(당월)'!O9+'[4]사업장별(누계)'!O9 -> 24188.765 | P9: =+'사업장별(당월)'!P9+'[4]사업장별(누계)'!P9 -> 23555.596 | Q9: =+P9-O9 -> -633.16941 | R9: =+'사업장별(당월)'!R9+'[4]사업장별(누계)'!R9 -> 24364.544 | S9: =+P9-R9 -> -808.94806 | T9: =+'사업장별(당월)'!T9+'[4]사업장별(누계)'!T9 -> 3256.3599 | U9: =+'사업장별(당월)'!U9+'[4]사업장별(누계)'!U9 -> 1693.9687 | V9: =+U9-T9 -> -1562.3913 | W9: =+'사업장별(당월)'!W9+'[4]사업장별(누계)'!W9 -> 2646.245 | X9: =+U9-W9 -> -952.27632 | Y9: =+[11]파주!$Q$85 -> 98729.654 | Z9: =+[11]파주!$R$85 -> 96666.953 | AA9: =+[12]파주!$Q$85 -> 92543.77 | AB9: =+[11]파주!$Q$89 -> 76349.328 | AC9: =+[11]파주!$R$89 -> 80272.138 | AD9: =+[12]파주!$Q$89 -> 74064.364 | AE9: =+Y9-AB9 -> 22380.326 | AF9: =+Z9-AC9 -> 16394.815 | AG9: =+AA9-AD9 -> 18479.405 | AI9: =+U9/T9-1 -> -0.47979686 | AK9: =+Z9-Y9 -> -2062.7009 | AL9: =+AC9-AB9 -> 3922.8099 | AM9: =+AF9-AE9 -> -5985.5108
