Workbook

Sheet 표지
A6: 2024년 2월 마감 손익
A24: 건재사업본부

Sheet 손익총괄
C3: □ 건재사업본부 손익실적(2024-02) | Z3: □ 건재부문 실적(2월)
X4: [단위 : 천㎥, 톤, 원/㎥, 원/톤, 백만원] | AK4: (단위 : 천㎥, 천톤, 억원)
C5: 구분 | E5: 2월 | J5: 2월 누계 | P5: 2월 주요지표 | Z5: 구분 | AB5: =+E5 -> 2월 | AG5: =+J5 -> 2월 누계
E6: 계획 | F6: 실적 | G6: 계획대비 | H6: 전년 | I6: 전년대비 | J6: 계획 | K6: 실적 | L6: 계획대비 | M6: 전년 | N6: 전년대비 | AB6: =+E6 -> 계획 | AC6: =+F6 -> 실적 | AD6: =+G6 -> 계획대비 | AE6: =+H6 -> 전년 | AF6: =+I6 -> 전년대비 | AG6: =+J6 -> 계획 | AH6: =+K6 -> 실적 | AI6: =+L6 -> 계획대비 | ... AK6: =+N6 -> 전년대비
C7: 물량 | D7: 레미콘 | E7: =+'[1]2월'!$Z$7/1000 -> 229 | F7: =+'[2]2월'!$Z$7/1000 -> 217.5565 | G7: =+F7-E7 -> -11.4435 | H7: =+'[3]2월'!$Z$7/1000 -> 324.0015 | I7: =+F7-H7 -> -106.445 | J7: =+[4]손익총괄!J7+E7 -> 470 | K7: =+[4]손익총괄!K7+F7 -> 496.442 | L7: =+K7-J7 -> 26.442 | M7: =+[4]손익총괄!M7+H7 -> 592.5825 | N7: =+K7-M7 -> -96.1405 | Q7: □ 레미콘 | Z7: 물량 | AA7: =+D7 -> 레미콘 | AB7: =+E7 -> 229 | AC7: =+F7 -> 217.5565 | AD7: =+AC7-AB7 -> -11.4435 | AE7: =+H7 -> 324.0015 | AF7: =+AC7-AE7 -> -106.445 | AG7: =+J7 -> 470 | AH7: =+K7 -> 496.442 | AI7: =+AH7-AG7 -> 26.442 | AJ7: =+M7 -> 592.5825 | AK7: =+AH7-AJ7 -> -96.1405
D8: 철강재 | E8: =+'[1]2월'!$AA$7 -> 6400 | F8: =+'[2]2월'!$AO$7 -> 6645.402 | G8: =+F8-E8 -> 245.402 | H8: =+'[3]2월'!$AO$7 -> 8382.34 | I8: =+F8-H8 -> -1736.938 | J8: =+[4]손익총괄!J8+E8 -> 13300 | K8: =+[4]손익총괄!K8+F8 -> 13070.495 | L8: =+K8-J8 -> -229.505 | M8: =+[4]손익총괄!M8+H8 -> 15329.127 | N8: =+K8-M8 -> -2258.632 | Q8: 구분 | S8: 계획 | T8: 실적 | U8: 계획대비 | V8: 전년 | W8: 전년대비 | AA8: =+D8 -> 철강재 | AB8: =+E8/1000 -> 6.4 | AC8: =+F8/1000 -> 6.645402 | AD8: =+AC8-AB8 -> 0.245402 | AE8: =+H8/1000 -> 8.38234 | AF8: =+AC8-AE8 -> -1.736938 | AG8: =+J8/1000 -> 13.3 | AH8: =+K8/1000 -> 13.070495 | AI8: =+AH8-AG8 -> -0.229505 | AJ8: =+M8/1000 -> 15.329127 | AK8: =+AH8-AJ8 -> -2.258632
D9: 골재 | E9: =+'[1]2월'!$AE$7/1000 -> 66.862081 | F9: =+'[2]2월'!$AN$7/1000 -> 65.272 | G9: =+F9-E9 -> -1.5900812 | H9: =+'[3]2월'!$AN$7/1000 -> 64.748 | I9: =+F9-H9 -> 0.524 | J9: =+[4]손익총괄!J9+E9 -> 143.49105 | K9: =+[4]손익총괄!K9+F9 -> 149.789 | L9: =+K9-J9 -> 6.2979482 | M9: =+[4]손익총괄!M9+H9 -> 130.633 | N9: =+K9-M9 -> 19.156 | Q9: 물량 | R9: 수도권 | S9: =+[5]수도권!$T$5/1000 -> 91 | T9: =+[5]수도권!$U$5/1000 -> 85.559 | U9: =+T9-S9 -> -5.441 | V9: =+[6]수도권!$T$5/1000 -> 123.1355 | W9: =+T9-V9 -> -37.5765 | AA9: =+D9 -> 골재 | AB9: =+E9 -> 66.862081 | AC9: =+F9 -> 65.272 | AD9: =+AC9-AB9 -> -1.5900812 | AE9: =+H9 -> 64.748 | AF9: =+AC9-AE9 -> 0.524 | AG9: =+J9 -> 143.49105 | AH9: =+K9 -> 149.789 | AI9: =+AH9-AG9 -> 6.2979482 | AJ9: =+M9 -> 130.633 | AK9: =+AH9-AJ9 -> 19.156
C10: 매출 | D10: 레미콘 | E10: =+'[1]2월'!$Z$8/1000 -> 22940.026 | F10: =+'[2]2월'!$Z$8/1000 -> 22221.543 | G10: =+F10-E10 -> -718.48349 | H10: =+'[3]2월'!$Z$8/1000 -> 30251.9 | I10: =+F10-H10 -> -8030.3577 | J10: =+[4]손익총괄!J10+E10 -> 47114.62 | K10: =+[4]손익총괄!K10+F10 -> 50097.188 | L10: =+K10-J10 -> 2982.5685 | M10: =+[4]손익총괄!M10+H10 -> 55039.756 | N10: =+K10-M10 -> -4942.5674 | R10: 영남권 | S10: =+[5]영남권!$T$5/1000 -> 102.5 | T10: =+[5]영남권!$U$5/1000 -> 100.9045 | U10: =+T10-S10 -> -1.5955 | V10: =+[6]영남권!$T$5/1000 -> 148.3495 | W10: =+T10-V10 -> -47.445 | Z10: 매출액 | AA10: =+D10 -> 레미콘 | AB10: =+E10/100 -> 229.40026 | AC10: =+F10/100 -> 222.21543 | AD10: =+AC10-AB10 -> -7.1848349 | AE10: =+H10/100 -> 302.519 | AF10: =+AC10-AE10 -> -80.303577 | AG10: =+J10/100 -> 471.1462 | AH10: =+K10/100 -> 500.97188 | AI10: =+AH10-AG10 -> 29.825685 | AJ10: =+M10/100 -> 550.39756 | AK10: =+AH10-AJ10 -> -49.425674
D11: 건자재 | E11: =+'[1]2월'!$AA$8/1000 -> 7830.1979 | F11: =+'[2]2월'!$AO$8/1000 -> 6765.658 | G11: =+F11-E11 -> -1064.5399 | H11: =+'[3]2월'!$AO$8/1000 -> 9789.471 | I11: =+F11-H11 -> -3023.813 | J11: =+[4]손익총괄!J11+E11 -> 16278.141 | K11: =+[4]손익총괄!K11+F11 -> 14173.615 | L11: =+K11-J11 -> -2104.5259 | M11: =+[4]손익총괄!M11+H11 -> 18603.105 | N11: =+K11-M11 -> -4429.4902 | R11: 중부권 | S11: =+[5]중부권!$T$5/1000 -> 35.5 | T11: =+[5]중부권!$U$5/1000 -> 31.093 | U11: =+T11-S11 -> -4.407 | V11: =+[6]중부권!$T$5/1000 -> 52.5165 | W11: =+T11-V11 -> -21.4235 | AA11: =+D11 -> 건자재 | AB11: =+E11/100 -> 78.301979 | AC11: =+F11/100 -> 67.65658 | AD11: =+AC11-AB11 -> -10.645399 | AE11: =+H11/100 -> 97.89471 | AF11: =+AC11-AE11 -> -30.23813 | AG11: =+J11/100 -> 162.78141 | AH11: =+K11/100 -> 141.73615 | AI11: =+AH11-AG11 -> -21.045259 | AJ11: =+M11/100 -> 186.03105 | AK11: =+AH11-AJ11 -> -44.294902
D12: 골재 | E12: =+'[1]2월'!$AE$8/1000 -> 1402.5163 | F12: =+'[2]2월'!$AN$8/1000 -> 1297.0865 | G12: =+F12-E12 -> -105.42984 | H12: =+'[3]2월'!$AN$8/1000 -> 1214.0152 | I12: =+F12-H12 -> 83.0713 | J12: =+[4]손익총괄!J12+E12 -> 3002.6793 | K12: =+[4]손익총괄!K12+F12 -> 3016.6065 | L12: =+K12-J12 -> 13.927166 | M12: =+[4]손익총괄!M12+H12 -> 2512.8432 | N12: =+K12-M12 -> 503.7633 | Q12: 계 | S12: =SUM(S9:S11) -> 229 | T12: =SUM(T9:T11) -> 217.5565 | U12: =+T12-S12 -> -11.4435 | V12: =SUM(V9:V11) -> 324.0015 | W12: =+T12-V12 -> -106.445 | AA12: =+D12 -> 골재 | AB12: =+E12/100 -> 14.025163 | AC12: =+F12/100 -> 12.970865 | AD12: =+AC12-AB12 -> -1.0542984 | AE12: =+H12/100 -> 12.140152 | AF12: =+AC12-AE12 -> 0.830713 | AG12: =+J12/100 -> 30.026793 | AH12: =+K12/100 -> 30.166065 | AI12: =+AH12-AG12 -> 0.13927166 | AJ12: =+M12/100 -> 25.128432 | AK12: =+AH12-AJ12 -> 5.037633
D13: 기타 | E13: =+'[1]2월'!$E$8/1000-E10-E11-E12 -> 164.9075 | F13: =+'[2]2월'!$F$8/1000-F10-F11-F12 -> 164.52516 | G13: =+F13-E13 -> -0.38234133 | H13: =+'[3]2월'!$F$8/1000-H10-H11-H12 -> 174.08818 | I13: =+F13-H13 -> -9.563018 | J13: =+[4]손익총괄!J13+E13 -> 329.815 | K13: =+[4]손익총괄!K13+F13 -> 329.00067 | L13: =+K13-J13 -> -0.81433067 | M13: =+[4]손익총괄!M13+H13 -> 348.2102 | N13: =+K13-M13 -> -19.209525 | Q13: 판매단가 | R13: 수도권 | S13: =+[5]수도권!$T$61 -> 96282.779 | T13: =+[5]수도권!$U$61 -> 100756.04 | U13: =+T13-S13 -> 4473.2566 | V13: =+[6]수도권!$Q$85 -> 89627.453 | W13: =+T13-V13 -> 11128.583 | AA13: =+D13 -> 기타 | AB13: =+E13/100 -> 1.649075 | AC13: =+F13/100 -> 1.6452516 | AD13: =+AC13-AB13 -> -0.0038234133 | AE13: =+H13/100 -> 1.7408818 | AF13: =+AC13-AE13 -> -0.09563018 | AG13: =+J13/100 -> 3.29815 | AH13: =+K13/100 -> 3.2900067 | AI13: =+AH13-AG13 -> -0.0081433067 | AJ13: =+M13/100 -> 3.482102 | AK13: =+AH13-AJ13 -> -0.19209525
C14: 계 | E14: =SUM(E10:E13) -> 32337.648 | F14: =SUM(F10:F13) -> 30448.812 | G14: =+F14-E14 -> -1888.8356 | H14: =SUM(H10:H13) -> 41429.475 | I14: =+F14-H14 -> -10980.662 | J14: =SUM(J10:J13) -> 66725.255 | K14: =SUM(K10:K13) -> 67616.411 | L14: =+K14-J14 -> 891.15542 | M14: =SUM(M10:M13) -> 76503.915 | N14: =+K14-M14 -> -8887.5038 | R14: 영남권 | S14: =+[5]영남권!$T$61 -> 101871.1 | T14: =+[5]영남권!$U$61 -> 102784.62 | U14: =+T14-S14 -> 913.52053 | V14: =+[6]영남권!$Q$85 -> 95374.233 | W14: =+T14-V14 -> 7410.3878 | AA14: 계 | AB14: =SUM(AB10:AB13) -> 323.37648 | AC14: =SUM(AC10:AC13) -> 304.48812 | AD14: =+AC14-AB14 -> -18.888356 | AE14: =SUM(AE10:AE13) -> 414.29475 | AF14: =+AC14-AE14 -> -109.80662 | AG14: =SUM(AG10:AG13) -> 667.25255 | AH14: =SUM(AH10:AH13) -> 676.16411 | AI14: =+AH14-AG14 -> 8.9115542 | AJ14: =SUM(AJ10:AJ13) -> 765.03915 | AK14: =+AH14-AJ14 -> -88.875038
C15: 매출원가 | D15: 레미콘 | E15: =+('[1]2월'!$Z$10+'[1]2월'!$Z$19)/1000 -> 20068.734 | F15: =+('[2]2월'!$Z$10+'[2]2월'!$Z$19)/1000 -> 19862.664 | G15: =+F15-E15 -> -206.06911 | H15: =+('[3]2월'!$Z$10+'[3]2월'!$Z$19)/1000 -> 25302.279 | I15: =+F15-H15 -> -5439.6149 | J15: =+[4]손익총괄!J15+E15 -> 41328.912 | K15: =+[4]손익총괄!K15+F15 -> 44742.197 | L15: =+K15-J15 -> 3413.2849 | M15: =+[4]손익총괄!M15+H15 -> 46823.389 | N15: =+K15-M15 -> -2081.1919 | R15: 중부권 | S15: =+[5]중부권!$T$61 -> 105253.67 | T15: =+[5]중부권!$U$61 -> 103875.43 | U15: =+T15-S15 -> -1378.2459 | V15: =+[6]중부권!$Q$85 -> 96860.392 | W15: =+T15-V15 -> 7015.0352 | Z15: 영업이익 | AA15: =+D30 -> 레미콘 | AB15: =+E30/100 -> 22.016761 | AC15: =+F30/100 -> 16.968997 | AD15: =+AC15-AB15 -> -5.0477639 | AE15: =+H30/100 -> 43.273358 | AF15: =+AC15-AE15 -> -26.304361 | AG15: =+J30/100 -> 44.624157 | AH15: =+K30/100 -> 40.21489 | AI15: =+AH15-AG15 -> -4.4092667 | AJ15: =+M30/100 -> 68.687452 | AK15: =+AH15-AJ15 -> -28.472562
D16: 건자재 | E16: =+('[1]2월'!$AA$10+'[1]2월'!$AA$19)/1000 -> 7629.6164 | F16: =+('[2]2월'!$AO$10+'[2]2월'!$AO$19)/1000 -> 6592.5773 | G16: =+F16-E16 -> -1037.0391 | H16: =+('[3]2월'!$AO$10+'[3]2월'!$AO$19)/1000 -> 9590.4664 | I16: =+F16-H16 -> -2997.8891 | J16: =+[4]손익총괄!J16+E16 -> 15861.563 | K16: =+[4]손익총괄!K16+F16 -> 13803.102 | L16: =+K16-J16 -> -2058.4611 | M16: =+[4]손익총괄!M16+H16 -> 18234.321 | N16: =+K16-M16 -> -4431.2188 | Q16: 계 | S16: =+[5]합계!$T$61 -> 100174.79 | T16: =+[5]합계!$U$61 -> 102142.73 | U16: =+T16-S16 -> 1967.9433 | V16: =+[6]합계!$Q$85 -> 93402.766 | W16: =+T16-V16 -> 8739.9632 | AA16: =+D31 -> % | AB16: =+E31 -> 0.095975309 | AC16: =+F31 -> 0.076362822 | AD16: =+AC16-AB16 -> -0.019612487 | AE16: =+H31 -> 0.14304344 | AF16: =+AC16-AE16 -> -0.066680616 | AG16: =+J31 -> 0.094714033 | AH16: =+K31 -> 0.080273746 | AI16: =+AH16-AG16 -> -0.014440287 | AJ16: =+M31 -> 0.12479607 | AK16: =+AH16-AJ16 -> -0.044522322
D17: 골재 | E17: =+('[1]2월'!$AE$10+'[1]2월'!$AE$19)/1000 -> 1253.5392 | F17: =+('[2]2월'!$AN$10+'[2]2월'!$AN$19)/1000 -> 1171.576 | G17: =+F17-E17 -> -81.963256 | H17: =+('[3]2월'!$AN$10+'[3]2월'!$AN$19)/1000 -> 1061.868 | I17: =+F17-H17 -> 109.70796 | J17: =+[4]손익총괄!J17+E17 -> 2790.9553 | K17: =+[4]손익총괄!K17+F17 -> 2664.8507 | L17: =+K17-J17 -> -126.10464 | M17: =+[4]손익총괄!M17+H17 -> 2324.0547 | N17: =+K17-M17 -> 340.79591 | Q17: 공헌이익 | R17: 수도권 | S17: =+[5]수도권!$Q$90 -> 16864.446 | T17: =+[5]수도권!$R$90 -> 19293.33 | U17: =+T17-S17 -> 2428.8842 | V17: =+[6]수도권!$Q$90 -> 17555.491 | W17: =+T17-V17 -> 1737.8391 | AA17: =+D32 -> 건자재 | AB17: =+E32/100 -> 0.71181193 | AC17: =+F32/100 -> 0.41844679 | AD17: =+AC17-AB17 -> -0.29336514 | AE17: =+H32/100 -> 0.77227243 | AF17: =+AC17-AE17 -> -0.35382564 | AG17: =+J32/100 -> 1.6593168 | AH17: =+K32/100 -> 1.1711189 | AI17: =+AH17-AG17 -> -0.48819786 | AJ17: =+M32/100 -> 1.5162618 | AK17: =+AH17-AJ17 -> -0.34514287
D18: 기타 | E18: =+('[1]2월'!$E$10+'[1]2월'!$E$19)/1000-E15-E16-E17 -> 28.821967 | F18: =+('[2]2월'!$F$10+'[2]2월'!$F$19)/1000-F15-F16-F17 -> 28.428296 | G18: =+F18-E18 -> -0.393671 | H18: =+('[3]2월'!$F$10+'[3]2월'!$F$19)/1000-H15-H16-H17 -> 24.822708 | I18: =+F18-H18 -> 3.605588 | J18: =+[4]손익총괄!J18+E18 -> 57.763035 | K18: =+[4]손익총괄!K18+F18 -> 56.940114 | L18: =+K18-J18 -> -0.822921 | M18: =+[4]손익총괄!M18+H18 -> 49.173497 | N18: =+K18-M18 -> 7.766617 | R18: 영남권 | S18: =+[5]영남권!$Q$90 -> 25870.777 | T18: =+[5]영남권!$R$90 -> 22654.141 | U18: =+T18-S18 -> -3216.6358 | V18: =+[6]영남권!$Q$90 -> 25212.578 | W18: =+T18-V18 -> -2558.4361 | AA18: =+D33 -> 골재 | AB18: =+E33/100 -> 1.1068049 | AC18: =+F33/100 -> 0.79179365 | AD18: =+AC18-AB18 -> -0.31501126 | AE18: =+H33/100 -> 1.340047 | AF18: =+AC18-AE18 -> -0.54825334 | AG18: =+J33/100 -> 1.3770551 | AH18: =+K33/100 -> 2.632531 | AI18: =+AH18-AG18 -> 1.2554758 | AJ18: =+M33/100 -> 1.5243926 | AK18: =+AH18-AJ18 -> 1.1081384
C19: 계 | E19: =SUM(E15:E18) -> 28980.711 | F19: =SUM(F15:F18) -> 27655.246 | G19: =+F19-E19 -> -1325.4651 | H19: =SUM(H15:H18) -> 35979.436 | I19: =+F19-H19 -> -8324.1905 | J19: =SUM(J15:J18) -> 60039.193 | K19: =SUM(K15:K18) -> 61267.09 | L19: =+K19-J19 -> 1227.8961 | M19: =SUM(M15:M18) -> 67430.938 | N19: =+K19-M19 -> -6163.8482 | R19: 중부권 | S19: =+[5]중부권!$Q$90 -> 27902.674 | T19: =+[5]중부권!$R$90 -> 26459.748 | U19: =+T19-S19 -> -1442.926 | V19: =+[6]중부권!$Q$90 -> 26932.075 | W19: =+T19-V19 -> -472.32715 | AA19: =+D34 -> 기타 | AB19: =+E34/100 -> -9.7074254 | AC19: =+F34/100 -> -6.5866734 | AD19: =+AC19-AB19 -> 3.120752 | AE19: =+H34/100 -> -7.3141407 | AF19: =+AC19-AE19 -> 0.72746734 | AG19: =+J34/100 -> -23.49594 | AH19: =+K34/100 -> -21.27529 | AI19: =+AH19-AG19 -> 2.2206495 | AJ19: =+M34/100 -> -18.932992 | AK19: =+AH19-AJ19 -> -2.3422986
C20: 매출이익 | D20: 레미콘 | E20: =+E10-E15 -> 2871.2926 | F20: =+F10-F15 -> 2358.8782 | G20: =+F20-E20 -> -512.41438 | H20: =+H10-H15 -> 4949.621 | I20: =+F20-H20 -> -2590.7428 | J20: =+J10-J15 -> 5785.7083 | K20: =+K10-K15 -> 5354.9919 | L20: =+K20-J20 -> -430.71637 | M20: =+M10-M15 -> 8216.3674 | N20: =+K20-M20 -> -2861.3755 | Q20: 계 | S20: =+[5]합계!$Q$90 -> 22606.83 | T20: =+[5]합계!$R$90 -> 21876.256 | U20: =+T20-S20 -> -730.57426 | V20: =+[6]합계!$Q$90 -> 22546.82 | W20: =+T20-V20 -> -670.56402 | AA20: 계 | AB20: =+AB15+AB17+AB18+AB19 -> 14.127952 | AC20: =+AC15+AC17+AC18+AC19 -> 11.592564 | AD20: =+AC20-AB20 -> -2.5353882 | AE20: =+AE15+AE17+AE18+AE19 -> 38.071537 | AF20: =+AC20-AE20 -> -26.478973 | AG20: =+AG15+AG17+AG18+AG19 -> 24.164589 | AH20: =+AH15+AH17+AH18+AH19 -> 22.74325 | AI20: =+AH20-AG20 -> -1.4213392 | AJ20: =+AJ15+AJ17+AJ18+AJ19 -> 52.795114 | AK20: =+AH20-AJ20 -> -30.051865
D21: 건자재 | E21: =+E11-E16 -> 200.58148 | F21: =+F11-F16 -> 173.08068 | G21: =+F21-E21 -> -27.500805 | H21: =+H11-H16 -> 199.00458 | I21: =+F21-H21 -> -25.923903 | J21: =+J11-J16 -> 416.57765 | K21: =+K11-K16 -> 370.51289 | L21: =+K21-J21 -> -46.064761 | M21: =+M11-M16 -> 368.78426 | N21: =+K21-M21 -> 1.728626 | Q21: □ 건자재 | AA21: =+D36 -> % | AB21: =+E36 -> 0.043688868 | AC21: =+F36 -> 0.038072303 | AD21: =+G36 -> -0.005616565 | AE21: =+H36 -> 0.09189481 | AF21: =+I36 -> -0.053822506 | AG21: =+J36 -> 0.036215056 | AH21: =+K36 -> 0.033635695 | ... AK21: =+N36 -> -0.035373995
D22: 골재 | E22: =+E12-E17 -> 148.97712 | F22: =+F12-F17 -> 125.51054 | G22: =+F22-E22 -> -23.466583 | H22: =+H12-H17 -> 152.1472 | I22: =+F22-H22 -> -26.636657 | J22: =+J12-J17 -> 211.72403 | K22: =+K12-K17 -> 351.75584 | L22: =+K22-J22 -> 140.03181 | M22: =+M12-M17 -> 188.78845 | N22: =+K22-M22 -> 162.96739 | Q22: 구분 | S22: 계획 | T22: 실적 | U22: 계획대비 | V22: 전년 | W22: 전년대비
D23: 기타 | E23: =+E13-E18 -> 136.08553 | F23: =+F13-F18 -> 136.09686 | G23: =+F23-E23 -> 0.011329667 | H23: =+H13-H18 -> 149.26547 | I23: =+F23-H23 -> -13.168606 | J23: =+J13-J18 -> 272.05197 | K23: =+K13-K18 -> 272.06056 | L23: =+K23-J23 -> 0.0085903333 | M23: =+M13-M18 -> 299.0367 | N23: =+K23-M23 -> -26.976142 | Q23: 철강재 판매단가 | S23: =+'[7]2월'!$F$10 -> 978125 | T23: =+'[7]2월'!$G$10 -> 886130.89 | U23: =+T23-S23 -> -91994.114 | V23: =+'[8]2월'!$G$10 -> 1027487 | W23: =+T23-V23 -> -141356.09
C24: 계 | E24: =SUM(E20:E23) -> 3356.9367 | F24: =SUM(F20:F23) -> 2793.5663 | G24: =+F24-E24 -> -563.37044 | H24: =SUM(H20:H23) -> 5450.0383 | I24: =+F24-H24 -> -2656.472 | J24: =SUM(J20:J23) -> 6686.0619 | K24: =SUM(K20:K23) -> 6349.3212 | L24: =+K24-J24 -> -336.74073 | M24: =SUM(M20:M23) -> 9072.9768 | N24: =+K24-M24 -> -2723.6556 | Q24: 철강재 마진률 | S24: =+'[7]2월'!$F$15 -> 0.023317891 | T24: =+'[7]2월'!$G$15 -> 0.027130154 | U24: =+T24-S24 -> 0.0038122631 | V24: =+'[8]2월'!$G$15 -> 0.019650368 | W24: =+T24-V24 -> 0.0074797864
C25: 판관비 | D25: 레미콘 | E25: =+('[1]2월'!$Z$13+'[1]2월'!$Z$20)/1000 -> 669.61647 | F25: =+('[2]2월'!$Z$13+'[2]2월'!$Z$20)/1000 -> 661.97847 | G25: =+F25-E25 -> -7.637996 | H25: =+('[3]2월'!$Z$13+'[3]2월'!$Z$20)/1000 -> 622.28521 | I25: =+F25-H25 -> 39.693266 | J25: =+[4]손익총괄!J25+E25 -> 1323.2926 | K25: =+[4]손익총괄!K25+F25 -> 1333.5029 | L25: =+K25-J25 -> 10.210299 | M25: =+[4]손익총괄!M25+H25 -> 1347.6222 | N25: =+K25-M25 -> -14.119337 | Q25: □ 골재
D26: 건자재 | E26: =+('[1]2월'!$AA$13+'[1]2월'!$AA$20)/1000 -> 129.40029 | F26: =+('[2]2월'!$AO$13+'[2]2월'!$AO$20)/1000 -> 131.236 | G26: =+F26-E26 -> 1.835709 | H26: =+('[3]2월'!$AO$13+'[3]2월'!$AO$20)/1000 -> 121.77734 | I26: =+F26-H26 -> 9.458661 | J26: =+[4]손익총괄!J26+E26 -> 250.64597 | K26: =+[4]손익총괄!K26+F26 -> 253.401 | L26: =+K26-J26 -> 2.755025 | M26: =+[4]손익총괄!M26+H26 -> 217.15808 | N26: =+K26-M26 -> 36.242913 | Q26: 구분 | S26: 계획 | T26: 실적 | U26: 계획대비 | V26: 전년 | W26: 전년대비
D27: 골재 | E27: =+('[1]2월'!$AE$13+'[1]2월'!$AE$20+'[1]2월'!$AE$22)/1000 -> 38.29663 | F27: =+('[2]2월'!$AN$13+'[2]2월'!$AN$20+'[2]2월'!$AN$22)/1000 -> 46.331173 | G27: =+F27-E27 -> 8.0345427 | H27: =+('[3]2월'!$AN$13+'[3]2월'!$AN$20+'[3]2월'!$AN$22)/1000 -> 18.142496 | I27: =+F27-H27 -> 28.188677 | J27: =+[4]손익총괄!J27+E27 -> 74.01852 | K27: =+[4]손익총괄!K27+F27 -> 88.502744 | L27: =+K27-J27 -> 14.484224 | M27: =+[4]손익총괄!M27+H27 -> 36.349199 | N27: =+K27-M27 -> 52.153545 | Q27: 판매량 | R27: 자가 | S27: =(+'[9]서부산크라샤(당월)'!$N$66+'[9]부산모래장(당월)'!$Q$48+'[9]부산크라샤(당월)'!$N$66)/1000 -> 39.362081 | T27: =(+'[9]서부산크라샤(당월)'!$O$66+'[9]부산모래장(당월)'!$R$48+'[9]부산크라샤(당월)'!$O$66)/1000 -> 41.722 | U27: =+T27-S27 -> 2.3599188 | V27: =('[10]부산골재(당월)'!$R$48+'[10]서부산골재(당월)'!$O$66+'[10]부산크라샤(당월)'!$O$66)/1000 -> 44.26 | W27: =+T27-V27 -> -2.538
D28: 기타 | E28: =+('[1]2월'!$E$13+'[1]2월'!$E$20)/1000-E25-E26-E27+('[1]2월'!$E$22/1000) -> 1106.8281 | F28: =+('[2]2월'!$F$13+'[2]2월'!$F$20)/1000-F25-F26-F27+'[2]2월'!$F$22/1000 -> 794.7642 | G28: =+F28-E28 -> -312.06387 | H28: =+('[3]2월'!$F$13+'[3]2월'!$F$20)/1000-H25-H26-H27+'[3]2월'!$F$22/1000 -> 880.67954 | I28: =+F28-H28 -> -85.91534 | J28: =+[4]손익총괄!J28+E28 -> 2621.6459 | K28: =+[4]손익총괄!K28+F28 -> 2399.5896 | L28: =+K28-J28 -> -222.05636 | M28: =+[4]손익총괄!M28+H28 -> 2192.3359 | N28: =+K28-M28 -> 207.25372 | R28: 외판 | S28: =(+'[9]서부산크라샤(당월)'!$N$59+'[9]부산모래장(당월)'!$Q$47+'[9]부산크라샤(당월)'!$N$59)/1000 -> 27.5 | T28: =(+'[9]서부산크라샤(당월)'!$O$59+'[9]부산모래장(당월)'!$R$47+'[9]부산크라샤(당월)'!$O$59)/1000 -> 23.55 | U28: =+T28-S28 -> -3.95 | V28: =+('[10]부산골재(당월)'!$R$47+'[10]서부산골재(당월)'!$O$59+'[10]부산크라샤(당월)'!$O$59)/1000 -> 20.488 | W28: =+T28-V28 -> 3.062
C29: 계 | E29: =SUM(E25:E28) -> 1944.1415 | F29: =SUM(F25:F28) -> 1634.3098 | G29: =+F29-E29 -> -309.83162 | H29: =SUM(H25:H28) -> 1642.8846 | I29: =+F29-H29 -> -8.574736 | J29: =SUM(J25:J28) -> 4269.603 | K29: =SUM(K25:K28) -> 4074.9962 | L29: =+K29-J29 -> -194.60681 | M29: =SUM(M25:M28) -> 3793.4654 | N29: =+K29-M29 -> 281.53084 | Q29: 합 계 | S29: =SUM(S27:S28) -> 66.862081 | T29: =SUM(T27:T28) -> 65.272 | U29: =+T29-S29 -> -1.5900812 | V29: =SUM(V27:V28) -> 64.748 | W29: =+T29-V29 -> 0.524
C30: 영업이익 | D30: 레미콘 | E30: =+E20-E25 -> 2201.6761 | F30: =+F20-F25 -> 1696.8997 | G30: =+F30-E30 -> -504.77639 | H30: =+H20-H25 -> 4327.3358 | I30: =+F30-H30 -> -2630.4361 | J30: =+J20-J25 -> 4462.4157 | K30: =+K20-K25 -> 4021.489 | L30: =+K30-J30 -> -440.92667 | M30: =+M20-M25 -> 6868.7452 | N30: =+K30-M30 -> -2847.2562 | Q30: □ 기타내역(영업이익)
D31: % | E31: =+E30/E10 -> 0.095975309 | F31: =+F30/F10 -> 0.076362822 | G31: =+F31-E31 -> -0.019612487 | H31: =+H30/H10 -> 0.14304344 | I31: =+F31-H31 -> -0.066680616 | J31: =+J30/J10 -> 0.094714033 | K31: =+K30/K10 -> 0.080273746 | L31: =+K31-J31 -> -0.014440287 | M31: =+M30/M10 -> 0.12479607 | N31: =+K31-M31 -> -0.044522322 | Q31: 구분 | S31: 계획 | T31: 실적 | U31: 계획대비 | V31: 전년 | W31: 전년대비
D32: 건자재 | E32: =+E21-E26 -> 71.181193 | F32: =+F21-F26 -> 41.844679 | G32: =+F32-E32 -> -29.336514 | H32: =+H21-H26 -> 77.227243 | I32: =+F32-H32 -> -35.382564 | J32: =+J21-J26 -> 165.93168 | K32: =+K21-K26 -> 117.11189 | L32: =+K32-J32 -> -48.819786 | M32: =+M21-M26 -> 151.62618 | N32: =+K32-M32 -> -34.514287 | Q32: 레미콘임대 | S32: =+'사업장별(당월)'!T33 -> 72.255091 | T32: =+'사업장별(당월)'!U33 -> 71.965353 | U32: =+T32-S32 -> -0.289738 | V32: =+'사업장별(당월)'!W33 -> 63.166801 | W32: =+T32-V32 -> 8.798552
D33: 골재 | E33: =+E22-E27 -> 110.68049 | F33: =+F22-F27 -> 79.179365 | G33: =+F33-E33 -> -31.501126 | H33: =+H22-H27 -> 134.0047 | I33: =+F33-H33 -> -54.825334 | J33: =+J22-J27 -> 137.70551 | K33: =+K22-K27 -> 263.2531 | L33: =+K33-J33 -> 125.54758 | M33: =+M22-M27 -> 152.43926 | N33: =+K33-M33 -> 110.81384 | Q33: 임대 | S33: =+'사업장별(당월)'!T34 -> 62.060442 | T33: =+'사업장별(당월)'!U34 -> 61.893705 | U33: =+T33-S33 -> -0.16673733 | V33: =+'사업장별(당월)'!W34 -> 24.163334 | W33: =+T33-V33 -> 37.730371
D34: 기타 | E34: =+E23-E28 -> -970.74254 | F34: =+F23-F28 -> -658.66734 | G34: =+F34-E34 -> 312.0752 | H34: =+H23-H28 -> -731.41407 | I34: =+F34-H34 -> 72.746734 | J34: =+J23-J28 -> -2349.594 | K34: =+K23-K28 -> -2127.529 | L34: =+K34-J34 -> 222.06495 | M34: =+M23-M28 -> -1893.2992 | N34: =+K34-M34 -> -234.22986 | Q34: 공통비 | S34: =+'사업장별(당월)'!T35 -> -1053.4137 | T34: =+'사업장별(당월)'!U35 -> -1053.317 | U34: =+T34-S34 -> 0.096726425 | V34: =+'사업장별(당월)'!W35 -> -788.78672 | W34: =+T34-V34 -> -264.53025
C35: 계 | E35: =SUM(E30,E32:E34) -> 1412.7952 | F35: =SUM(F30,F32:F34) -> 1159.2564 | G35: =+F35-E35 -> -253.53882 | H35: =SUM(H30,H32:H34) -> 3807.1537 | I35: =+F35-H35 -> -2647.8973 | J35: =SUM(J30,J32:J34) -> 2416.4589 | K35: =SUM(K30,K32:K34) -> 2274.325 | L35: =+K35-J35 -> -142.13392 | M35: =SUM(M30,M32:M34) -> 5279.5114 | N35: =+K35-M35 -> -3005.1865 | Q35: 기타 | S35: =+S36-S32-S33-S34 -> -51.644375 | T35: =+T36-T32-T33-T34 -> 260.79058 | U35: =+T35-S35 -> 312.43495 | V35: =+V36-V32-V33-V34 -> -29.95748 | W35: =+T35-V35 -> 290.74806
D36: % | E36: =+E35/E14 -> 0.043688868 | F36: =+F35/F14 -> 0.038072303 | G36: =+F36-E36 -> -0.005616565 | H36: =+H35/H14 -> 0.09189481 | I36: =+F36-H36 -> -0.053822506 | J36: =+J35/J14 -> 0.036215056 | K36: =+K35/K14 -> 0.033635695 | L36: =+K36-J36 -> -0.0025793614 | M36: =+M35/M14 -> 0.06900969 | N36: =+K36-M36 -> -0.035373995 | Q36: 합계 | S36: =+'사업장별(당월)'!T41 -> -970.74254 | T36: =+'사업장별(당월)'!U41 -> -658.66734 | U36: =+T36-S36 -> 312.0752 | V36: =+'사업장별(당월)'!W41 -> -731.41407 | W36: =+T36-V36 -> 72.746734
E38: =+'[1]2월'!$E$26/1000 -> 1412.7952 | F38: =+'[2]2월'!$F$26/1000 -> 1159.2564 | H38: =+'[3]2월'!$F$26/1000 -> 3807.1537 | J38: =+[4]손익총괄!J38+E38 -> 2416.4589 | K38: =+[4]손익총괄!K38+F38 -> 2274.325 | M38: =+[4]손익총괄!M38+H38 -> 5279.5114
E39: =+E35=E38 -> TRUE | F39: =+F35=F38 -> TRUE | H39: =+H35=H38 -> TRUE | J39: =+J35=J38 -> TRUE | K39: =+K35=K38 -> TRUE | M39: =+M35=M38 -> FALSE
E40: =+E35-E38 -> 0 | F40: =+F35-F38 -> 0 | H40: =+H35-H38 -> -4.0927262e-12 | J40: =+J35-J38 -> -5.4569682e-12 | K40: =+K35-K38 -> 0 | M40: =+M35-M38 -> -8.1854523e-12

Sheet 사업장별(당월)
H3: □ 사업장별 손익실적(2024-02)
AG4: [단위 : 천㎥, 톤, 백만원]
H5: 구분 | J5: 물량 | O5: 매출 | T5: 영업이익(공통비 배부전) | Y5: 판매단가 | AB5: 변동비 | AE5: 공헌이익
J6: 계획 | K6: 실적 | L6: 차이 | M6: 전년 | N6: 차이 | O6: 계획 | P6: 실적 | Q6: 차이 | R6: 전년 | S6: 차이 | T6: 계획 | U6: 실적 | V6: 차이 | W6: 전년 | X6: 차이 | Y6: 계획 | Z6: 실적 | AA6: 전년 | AB6: 계획 | AC6: 실적 | AD6: 전년 | AE6: 계획 | AF6: 실적 | AG6: 전년
B7: 안양 | G7: =+I7 -> 안양 | H7: 레미콘 | I7: 안양 | J7: =+IFERROR(HLOOKUP($B7,'[1]2월'!$D$6:$BN$259,2,),)/1000 -> 36 | K7: =+IFERROR(HLOOKUP($B7,'[2]2월'!$F$6:$CP$99,2,),)/1000 -> 37.712 | L7: =+K7-J7 -> 1.712 | M7: =+IFERROR(HLOOKUP($B7,'[3]2월'!$F$6:$CC$57,2,),)/1000 -> 49.587 | N7: =+K7-M7 -> -11.875 | O7: =+IFERROR(HLOOKUP($B7,'[1]2월'!$D$6:$BN$259,3,),)/1000 -> 3479.7757 | P7: =+IFERROR(HLOOKUP($B7,'[2]2월'!$F$6:$CP$99,3,),)/1000 -> 3774.208 | Q7: =+P7-O7 -> 294.43235 | R7: =+IFERROR(HLOOKUP($B7,'[3]2월'!$F$6:$CC$57,3,),)/1000 -> 4494.7256 | S7: =+P7-R7 -> -720.51756 | T7: =+IFERROR(HLOOKUP($B7,'[1]2월'!$D$6:$BN$259,16,),)/1000 -> 295.68664 | U7: =+IFERROR(HLOOKUP($B7,'[2]2월'!$F$6:$CP$99,16,),)/1000 -> 451.30565 | V7: =+U7-T7 -> 155.61901 | W7: =+IFERROR(HLOOKUP($B7,'[3]2월'!$F$6:$CC$57,16,),)/1000 -> 627.75827 | X7: =+U7-W7 -> -176.45262 | Y7: =+[5]안양!$Q$85 -> 96660.435 | Z7: =+[5]안양!$R$85 -> 100079.76 | AA7: =+[6]안양!$Q$85 -> 90588.461 | AB7: =+[5]안양!$Q$89 -> 80132.466 | AC7: =+[5]안양!$R$89 -> 79851.287 | AD7: =+[6]안양!$Q$89 -> 72304.625 | AE7: =+Y7-AB7 -> 16527.969 | AF7: =+Z7-AC7 -> 20228.476 | AG7: =+AA7-AD7 -> 18283.836
B8: 인천 | G8: =+I8 -> 인천 | H8: 직영 | I8: 인천 | J8: =+IFERROR(HLOOKUP($B8,'[1]2월'!$D$6:$BN$259,2,),)/1000 -> 24 | K8: =+IFERROR(HLOOKUP($B8,'[2]2월'!$F$6:$CP$99,2,),)/1000 -> 23.5 | L8: =+K8-J8 -> -0.5 | M8: =+IFERROR(HLOOKUP($B8,'[3]2월'!$F$6:$CC$57,2,),)/1000 -> 37.843 | N8: =+K8-M8 -> -14.343 | O8: =+IFERROR(HLOOKUP($B8,'[1]2월'!$D$6:$BN$259,3,),)/1000 -> 2338.9065 | P8: =+IFERROR(HLOOKUP($B8,'[2]2월'!$F$6:$CP$99,3,),)/1000 -> 2356.7585 | Q8: =+P8-O8 -> 17.851991 | R8: =+IFERROR(HLOOKUP($B8,'[3]2월'!$F$6:$CC$57,3,),)/1000 -> 3426.1344 | S8: =+P8-R8 -> -1069.3759 | T8: =+IFERROR(HLOOKUP($B8,'[1]2월'!$D$6:$BN$259,16,),)/1000 -> 72.600987 | U8: =+IFERROR(HLOOKUP($B8,'[2]2월'!$F$6:$CP$99,16,),)/1000 -> 137.95808 | V8: =+U8-T8 -> 65.357095 | W8: =+IFERROR(HLOOKUP($B8,'[3]2월'!$F$6:$CC$57,16,),)/1000 -> 372.74816 | X8: =+U8-W8 -> -234.79007 | Y8: =+[5]인천!$Q$85 -> 97454.439 | Z8: =+[5]인천!$R$85 -> 100287.6 | AA8: =+[6]인천!$Q$85 -> 90535.486 | AB8: =+[5]인천!$Q$89 -> 82233.367 | AC8: =+[5]인천!$R$89 -> 82090.723 | AD8: =+[6]인천!$Q$89 -> 73510.159 | AE8: =+Y8-AB8 -> 15221.072 | AF8: =+Z8-AC8 -> 18196.874 | AG8: =+AA8-AD8 -> 17025.328
B9: 파주 | G9: =+I9 -> 파주 | I9: 파주 | J9: =+IFERROR(HLOOKUP($B9,'[1]2월'!$D$6:$BN$259,2,),)/1000 -> 21 | K9: =+IFERROR(HLOOKUP($B9,'[2]2월'!$F$6:$CP$99,2,),)/1000 -> 18.47 | L9: =+K9-J9 -> -2.53 | M9: =+IFERROR(HLOOKUP($B9,'[3]2월'!$F$6:$CC$57,2,),)/1000 -> 23.424 | N9: =+K9-M9 -> -4.954 | O9: =+IFERROR(HLOOKUP($B9,'[1]2월'!$D$6:$BN$259,3,),)/1000 -> 2019.1862 | P9: =+IFERROR(HLOOKUP($B9,'[2]2월'!$F$6:$CP$99,3,),)/1000 -> 1919.2949 | Q9: =+P9-O9 -> -99.891291 | R9: =+IFERROR(HLOOKUP($B9,'[3]2월'!$F$6:$CC$57,3,),)/1000 -> 2064.8841 | S9: =+P9-R9 -> -145.58917 | T9: =+IFERROR(HLOOKUP($B9,'[1]2월'!$D$6:$BN$259,16,),)/1000 -> 172.12968 | U9: =+IFERROR(HLOOKUP($B9,'[2]2월'!$F$6:$CP$99,16,),)/1000 -> 125.58788 | V9: =+U9-T9 -> -46.541804 | W9: =+IFERROR(HLOOKUP($B9,'[3]2월'!$F$6:$CC$57,16,),)/1000 -> 167.11117 | X9: =+U9-W9 -> -41.523294 | Y9: =+[5]파주!$Q$85 -> 96151.724 | Z9: =+[5]파주!$R$85 -> 103935.69 | AA9: =+[6]파주!$Q$85 -> 88311.602 | AB9: =+[5]파주!$Q$89 -> 78001.433 | AC9: =+[5]파주!$R$89 -> 84337.303 | AD9: =+[6]파주!$Q$89 -> 72216.393 | AE9: =+Y9-AB9 -> 18150.291 | AF9: =+Z9-AC9 -> 19598.387 | AG9: =+AA9-AD9 -> 16095.209
B10: 김포 | G10: =+I10 -> 김포 | I10: 김포 | J10: =+IFERROR(HLOOKUP($B10,'[1]2월'!$D$6:$BN$259,2,),)/1000 -> 10 | K10: =+IFERROR(HLOOKUP($B10,'[2]2월'!$F$6:$CP$99,2,),)/1000 -> 5.877 | L10: =+K10-J10 -> -4.123 | M10: =+IFERROR(HLOOKUP($B10,'[3]2월'!$F$6:$CC$57,2,),)/1000 -> 12.2815 | N10: =+K10-M10 -> -6.4045 | O10: =+IFERROR(HLOOKUP($B10,'[1]2월'!$D$6:$BN$259,3,),)/1000 -> 923.8645 | P10: =+IFERROR(HLOOKUP($B10,'[2]2월'!$F$6:$CP$99,3,),)/1000 -> 570.04139 | Q10: =+P10-O10 -> -353.82311 | R10: =+IFERROR(HLOOKUP($B10,'[3]2월'!$F$6:$CC$57,3,),)/1000 -> 1048.4468 | S10: =+P10-R10 -> -478.40541 | T10: =+IFERROR(HLOOKUP($B10,'[1]2월'!$D$6:$BN$259,16,),)/1000 -> 26.713526 | U10: =+IFERROR(HLOOKUP($B10,'[2]2월'!$F$6:$CP$99,16,),)/1000 -> -50.621 | V10: =+U10-T10 -> -77.334526 | W10: =+IFERROR(HLOOKUP($B10,'[3]2월'!$F$6:$CC$57,16,),)/1000 -> 87.617854 | X10: =+U10-W10 -> -138.23885 | Y10: =+[5]김포!$Q$85 -> 92386.45 | Z10: =+[5]김포!$R$85 -> 96995.302 | AA10: =+[6]김포!$Q$85 -> 85334.467 | AB10: =+[5]김포!$Q$89 -> 73066.867 | AC10: =+[5]김포!$R$89 -> 80274.495 | AD10: =+[6]김포!$Q$89 -> 66417.447 | AE10: =+Y10-AB10 -> 19319.583 | AF10: =+Z10-AC10 -> 16720.807 | AG10: =+AA10-AD10 -> 18917.02
B11: 부산 | G11: =+I11 -> 부산 | I11: 부산 | J11: =+IFERROR(HLOOKUP($B11,'[1]2월'!$D$6:$BN$259,2,),)/1000 -> 16 | K11: =+IFERROR(HLOOKUP($B11,'[2]2월'!$F$6:$CP$99,2,),)/1000 -> 16.65 | L11: =+K11-J11 -> 0.65 | M11: =+IFERROR(HLOOKUP($B11,'[3]2월'!$F$6:$CC$57,2,),)/1000 -> 25.49 | N11: =+K11-M11 -> -8.84 | O11: =+IFERROR(HLOOKUP($B11,'[1]2월'!$D$6:$BN$259,3,),)/1000 -> 1721.6024 | P11: =+IFERROR(HLOOKUP($B11,'[2]2월'!$F$6:$CP$99,3,),)/1000 -> 1875.6439 | Q11: =+P11-O11 -> 154.04147 | R11: =+IFERROR(HLOOKUP($B11,'[3]2월'!$F$6:$CC$57,3,),)/1000 -> 2632.8105 | S11: =+P11-R11 -> -757.1666 | T11: =+IFERROR(HLOOKUP($B11,'[1]2월'!$D$6:$BN$259,16,),)/1000 -> 197.20215 | U11: =+IFERROR(HLOOKUP($B11,'[2]2월'!$F$6:$CP$99,16,),)/1000 -> 201.44822 | V11: =+U11-T11 -> 4.2460741 | W11: =+IFERROR(HLOOKUP($B11,'[3]2월'!$F$6:$CC$57,16,),)/1000 -> 547.75555 | X11: =+U11-W11 -> -346.30732 | Y11: =+[5]부산!$Q$85 -> 107600.15 | Z11: =+[5]부산!$R$85 -> 112651.29 | AA11: =+[6]부산!$Q$85 -> 103288.86 | AB11: =+[5]부산!$Q$89 -> 78794.799 | AC11: =+[5]부산!$R$89 -> 86432.204 | AD11: =+[6]부산!$Q$89 -> 72821.468 | AE11: =+Y11-AB11 -> 28805.353 | AF11: =+Z11-AC11 -> 26219.081 | AG11: =+AA11-AD11 -> 30467.394
B12: 서부산 | G12: =+I12 -> 서부산 | I12: 서부산 | J12: =+IFERROR(HLOOKUP($B12,'[1]2월'!$D$6:$BN$259,2,),)/1000 -> 19 | K12: =+IFERROR(HLOOKUP($B12,'[2]2월'!$F$6:$CP$99,2,),)/1000 -> 16.841 | L12: =+K12-J12 -> -2.159 | M12: =+IFERROR(HLOOKUP($B12,'[3]2월'!$F$6:$CC$57,2,),)/1000 -> 25.042 | N12: =+K12-M12 -> -8.201 | O12: =+IFERROR(HLOOKUP($B12,'[1]2월'!$D$6:$BN$259,3,),)/1000 -> 1976.4045 | P12: =+IFERROR(HLOOKUP($B12,'[2]2월'!$F$6:$CP$99,3,),)/1000 -> 1729.3343 | Q12: =+P12-O12 -> -247.07016 | R12: =+IFERROR(HLOOKUP($B12,'[3]2월'!$F$6:$CC$57,3,),)/1000 -> 2370.2729 | S12: =+P12-R12 -> -640.93858 | T12: =+IFERROR(HLOOKUP($B12,'[1]2월'!$D$6:$BN$259,16,),)/1000 -> 302.28306 | U12: =+IFERROR(HLOOKUP($B12,'[2]2월'!$F$6:$CP$99,16,),)/1000 -> 118.8076 | V12: =+U12-T12 -> -183.47546 | W12: =+IFERROR(HLOOKUP($B12,'[3]2월'!$F$6:$CC$57,16,),)/1000 -> 388.98699 | X12: =+U12-W12 -> -270.17939 | Y12: =+[5]서부산!$Q$85 -> 104021.29 | Z12: =+[5]서부산!$R$85 -> 102685.96 | AA12: =+[6]서부산!$Q$85 -> 94651.901 | AB12: =+[5]서부산!$Q$89 -> 77941.043 | AC12: =+[5]서부산!$R$89 -> 81711.867 | AD12: =+[6]서부산!$Q$89 -> 70446.738 | AE12: =+Y12-AB12 -> 26080.246 | AF12: =+Z12-AC12 -> 20974.097 | AG12: =+AA12-AD12 -> 24205.163
B13: 김해 | G13: =+I13 -> 김해 | I13: 김해 | J13: =+IFERROR(HLOOKUP($B13,'[1]2월'!$D$6:$BN$259,2,),)/1000 -> 11 | K13: =+IFERROR(HLOOKUP($B13,'[2]2월'!$F$6:$CP$99,2,),)/1000 -> 8.639 | L13: =+K13-J13 -> -2.361 | M13: =+IFERROR(HLOOKUP($B13,'[3]2월'!$F$6:$CC$57,2,),)/1000 -> 11.597 | N13: =+K13-M13 -> -2.958 | O13: =+IFERROR(HLOOKUP($B13,'[1]2월'!$D$6:$BN$259,3,),)/1000 -> 1110.9956 | P13: =+IFERROR(HLOOKUP($B13,'[2]2월'!$F$6:$CP$99,3,),)/1000 -> 890.1857 | Q13: =+P13-O13 -> -220.8099 | R13: =+IFERROR(HLOOKUP($B13,'[3]2월'!$F$6:$CC$57,3,),)/1000 -> 1082.2339 | S13: =+P13-R13 -> -192.0482 | T13: =+IFERROR(HLOOKUP($B13,'[1]2월'!$D$6:$BN$259,16,),)/1000 -> 119.9037 | U13: =+IFERROR(HLOOKUP($B13,'[2]2월'!$F$6:$CP$99,16,),)/1000 -> 16.811886 | V13: =+U13-T13 -> -103.09182 | W13: =+IFERROR(HLOOKUP($B13,'[3]2월'!$F$6:$CC$57,16,),)/1000 -> 115.159 | X13: =+U13-W13 -> -98.347116 | Y13: =+[5]김해!$Q$85 -> 100999.6 | Z13: =+[5]김해!$R$85 -> 103042.68 | AA13: =+[6]김해!$Q$85 -> 93320.16 | AB13: =+[5]김해!$Q$89 -> 76819.315 | AC13: =+[5]김해!$R$89 -> 83785.984 | AD13: =+[6]김해!$Q$89 -> 71654.56 | AE13: =+Y13-AB13 -> 24180.285 | AF13: =+Z13-AC13 -> 19256.695 | AG13: =+AA13-AD13 -> 21665.6
B14: 정관 | G14: =+I14 -> 정관 | I14: 정관 | J14: =+IFERROR(HLOOKUP($B14,'[1]2월'!$D$6:$BN$259,2,),)/1000 -> 16 | K14: =+IFERROR(HLOOKUP($B14,'[2]2월'!$F$6:$CP$99,2,),)/1000 -> 14.978 | L14: =+K14-J14 -> -1.022 | M14: =+IFERROR(HLOOKUP($B14,'[3]2월'!$F$6:$CC$57,2,),)/1000 -> 20.163 | N14: =+K14-M14 -> -5.185 | O14: =+IFERROR(HLOOKUP($B14,'[1]2월'!$D$6:$BN$259,3,),)/1000 -> 1664 | P14: =+IFERROR(HLOOKUP($B14,'[2]2월'!$F$6:$CP$99,3,),)/1000 -> 1493.4374 | Q14: =+P14-O14 -> -170.5626 | R14: =+IFERROR(HLOOKUP($B14,'[3]2월'!$F$6:$CC$57,3,),)/1000 -> 2028.1229 | S14: =+P14-R14 -> -534.68552 | T14: =+IFERROR(HLOOKUP($B14,'[1]2월'!$D$6:$BN$259,16,),)/1000 -> 206.81848 | U14: =+IFERROR(HLOOKUP($B14,'[2]2월'!$F$6:$CP$99,16,),)/1000 -> 34.868347 | V14: =+U14-T14 -> -171.95013 | W14: =+IFERROR(HLOOKUP($B14,'[3]2월'!$F$6:$CC$57,16,),)/1000 -> 387.1501 | X14: =+U14-W14 -> -352.28176 | Y14: =+[5]정관!$Q$85 -> 104000 | Z14: =+[5]정관!$R$85 -> 99708.733 | AA14: =+[6]정관!$Q$85 -> 100586.37 | AB14: =+[5]정관!$Q$89 -> 78994.788 | AC14: =+[5]정관!$R$89 -> 84310.743 | AD14: =+[6]정관!$Q$89 -> 72135.331 | AE14: =+Y14-AB14 -> 25005.212 | AF14: =+Z14-AC14 -> 15397.99 | AG14: =+AA14-AD14 -> 28451.036
B15: 양산 | G15: =+I15 -> 양산 | I15: 양산 | J15: =+IFERROR(HLOOKUP($B15,'[1]2월'!$D$6:$BN$259,2,),)/1000 -> 9 | K15: =+IFERROR(HLOOKUP($B15,'[2]2월'!$F$6:$CP$99,2,),)/1000 -> 9.558 | L15: =+K15-J15 -> 0.558 | M15: =+IFERROR(HLOOKUP($B15,'[3]2월'!$F$6:$CC$57,2,),)/1000 -> 12.89 | N15: =+K15-M15 -> -3.332 | O15: =+IFERROR(HLOOKUP($B15,'[1]2월'!$D$6:$BN$259,3,),)/1000 -> 864.5978 | P15: =+IFERROR(HLOOKUP($B15,'[2]2월'!$F$6:$CP$99,3,),)/1000 -> 924.58643 | Q15: =+P15-O15 -> 59.98863 | R15: =+IFERROR(HLOOKUP($B15,'[3]2월'!$F$6:$CC$57,3,),)/1000 -> 1213.8579 | S15: =+P15-R15 -> -289.2715 | T15: =+IFERROR(HLOOKUP($B15,'[1]2월'!$D$6:$BN$259,16,),)/1000 -> 91.002495 | U15: =+IFERROR(HLOOKUP($B15,'[2]2월'!$F$6:$CP$99,16,),)/1000 -> 98.534238 | V15: =+U15-T15 -> 7.5317432 | W15: =+IFERROR(HLOOKUP($B15,'[3]2월'!$F$6:$CC$57,16,),)/1000 -> 188.53671 | X15: =+U15-W15 -> -90.002469 | Y15: =+[5]양산!$Q$85 -> 96066.422 | Z15: =+[5]양산!$R$85 -> 96734.299 | AA15: =+[6]양산!$Q$85 -> 94170.515 | AB15: =+[5]양산!$Q$89 -> 71412.953 | AC15: =+[5]양산!$R$89 -> 71459.126 | AD15: =+[6]양산!$Q$89 -> 68415.923 | AE15: =+Y15-AB15 -> 24653.469 | AF15: =+Z15-AC15 -> 25275.173 | AG15: =+AA15-AD15 -> 25754.591
B16: 창원 | G16: =+I16 -> 창원 | I16: 창원 | J16: =+IFERROR(HLOOKUP($B16,'[1]2월'!$D$6:$BN$259,2,),)/1000 -> 14 | K16: =+IFERROR(HLOOKUP($B16,'[2]2월'!$F$6:$CP$99,2,),)/1000 -> 15.453 | L16: =+K16-J16 -> 1.453 | M16: =+IFERROR(HLOOKUP($B16,'[3]2월'!$F$6:$CC$57,2,),)/1000 -> 20.134 | N16: =+K16-M16 -> -4.681 | O16: =+IFERROR(HLOOKUP($B16,'[1]2월'!$D$6:$BN$259,3,),)/1000 -> 1394.204 | P16: =+IFERROR(HLOOKUP($B16,'[2]2월'!$F$6:$CP$99,3,),)/1000 -> 1538.5332 | Q16: =+P16-O16 -> 144.3292 | R16: =+IFERROR(HLOOKUP($B16,'[3]2월'!$F$6:$CC$57,3,),)/1000 -> 1861.4379 | S16: =+P16-R16 -> -322.9047 | T16: =+IFERROR(HLOOKUP($B16,'[1]2월'!$D$6:$BN$259,16,),)/1000 -> 199.86228 | U16: =+IFERROR(HLOOKUP($B16,'[2]2월'!$F$6:$CP$99,16,),)/1000 -> 220.45765 | V16: =+U16-T16 -> 20.59537 | W16: =+IFERROR(HLOOKUP($B16,'[3]2월'!$F$6:$CC$57,16,),)/1000 -> 343.55849 | X16: =+U16-W16 -> -123.10084 | Y16: =+[5]창원!$Q$85 -> 99586 | Z16: =+[5]창원!$R$85 -> 99562.104 | AA16: =+[6]창원!$Q$85 -> 92452.463 | AB16: =+[5]창원!$Q$89 -> 72424.549 | AC16: =+[5]창원!$R$89 -> 73759.236 | AD16: =+[6]창원!$Q$89 -> 66726.913 | AE16: =+Y16-AB16 -> 27161.451 | AF16: =+Z16-AC16 -> 25802.869 | AG16: =+AA16-AD16 -> 25725.55
B17: 대구 | G17: =+I17 -> 대구 | I17: 대구 | J17: =+IFERROR(HLOOKUP($B17,'[1]2월'!$D$6:$BN$259,2,),)/1000 -> 13.5 | K17: =+IFERROR(HLOOKUP($B17,'[2]2월'!$F$6:$CP$99,2,),)/1000 -> 13.997 | L17: =+K17-J17 -> 0.497 | M17: =+IFERROR(HLOOKUP($B17,'[3]2월'!$F$6:$CC$57,2,),)/1000 -> 22.5935 | N17: =+K17-M17 -> -8.5965 | O17: =+IFERROR(HLOOKUP($B17,'[1]2월'!$D$6:$BN$259,3,),)/1000 -> 1320.3 | P17: =+IFERROR(HLOOKUP($B17,'[2]2월'!$F$6:$CP$99,3,),)/1000 -> 1431.9897 | Q17: =+P17-O17 -> 111.6897 | R17: =+IFERROR(HLOOKUP($B17,'[3]2월'!$F$6:$CC$57,3,),)/1000 -> 1982.2 | S17: =+P17-R17 -> -550.2103 | T17: =+IFERROR(HLOOKUP($B17,'[1]2월'!$D$6:$BN$259,16,),)/1000 -> 188.98876 | U17: =+IFERROR(HLOOKUP($B17,'[2]2월'!$F$6:$CP$99,16,),)/1000 -> 216.44189 | V17: =+U17-T17 -> 27.453125 | W17: =+IFERROR(HLOOKUP($B17,'[3]2월'!$F$6:$CC$57,16,),)/1000 -> 321.07979 | X17: =+U17-W17 -> -104.63791 | Y17: =+[5]대구!$Q$85 -> 97800 | Z17: =+[5]대구!$R$85 -> 102306.9 | AA17: =+[6]대구!$Q$85 -> 87723.065 | AB17: =+[5]대구!$Q$89 -> 71441.174 | AC17: =+[5]대구!$R$89 -> 74620.402 | AD17: =+[6]대구!$Q$89 -> 66045.345 | AE17: =+Y17-AB17 -> 26358.826 | AF17: =+Z17-AC17 -> 27686.499 | AG17: =+AA17-AD17 -> 21677.72
B18: 울산 | G18: =+I18 -> 울산 | I18: 울산 | J18: =+IFERROR(HLOOKUP($B18,'[1]2월'!$D$6:$BN$259,2,),)/1000 -> 4 | K18: =+IFERROR(HLOOKUP($B18,'[2]2월'!$F$6:$CP$99,2,),)/1000 -> 4.7885 | L18: =+K18-J18 -> 0.7885 | M18: =+IFERROR(HLOOKUP($B18,'[3]2월'!$F$6:$CC$57,2,),)/1000 -> 10.44 | N18: =+K18-M18 -> -5.6515 | O18: =+IFERROR(HLOOKUP($B18,'[1]2월'!$D$6:$BN$259,3,),)/1000 -> 389.6835 | P18: =+IFERROR(HLOOKUP($B18,'[2]2월'!$F$6:$CP$99,3,),)/1000 -> 487.72015 | Q18: =+P18-O18 -> 98.03665 | R18: =+IFERROR(HLOOKUP($B18,'[3]2월'!$F$6:$CC$57,3,),)/1000 -> 977.4416 | S18: =+P18-R18 -> -489.72145 | T18: =+IFERROR(HLOOKUP($B18,'[1]2월'!$D$6:$BN$259,16,),)/1000 -> -58.251056 | U18: =+IFERROR(HLOOKUP($B18,'[2]2월'!$F$6:$CP$99,16,),)/1000 -> -66.050997 | V18: =+U18-T18 -> -7.7999413 | W18: =+IFERROR(HLOOKUP($B18,'[3]2월'!$F$6:$CC$57,16,),)/1000 -> 64.285417 | X18: =+U18-W18 -> -130.33641 | Y18: =+[5]울산!$Q$85 -> 97420.875 | Z18: =+[5]울산!$R$85 -> 101852.39 | AA18: =+[6]울산!$Q$85 -> 93653.585 | AB18: =+[5]울산!$Q$89 -> 79597.84 | AC18: =+[5]울산!$R$89 -> 86917.518 | AD18: =+[6]울산!$Q$89 -> 75146.941 | AE18: =+Y18-AB18 -> 17823.035 | AF18: =+Z18-AC18 -> 14934.868 | AG18: =+AA18-AD18 -> 18506.643
B19: 아산 | G19: =+I19 -> 아산 | I19: 아산 | J19: =+IFERROR(HLOOKUP($B19,'[1]2월'!$D$6:$BN$259,2,),)/1000 -> 14.5 | K19: =+IFERROR(HLOOKUP($B19,'[2]2월'!$F$6:$CP$99,2,),)/1000 -> 17.471 | L19: =+K19-J19 -> 2.971 | M19: =+IFERROR(HLOOKUP($B19,'[3]2월'!$F$6:$CC$57,2,),)/1000 -> 27.673 | N19: =+K19-M19 -> -10.202 | O19: =+IFERROR(HLOOKUP($B19,'[1]2월'!$D$6:$BN$259,3,),)/1000 -> 1464.4955 | P19: =+IFERROR(HLOOKUP($B19,'[2]2월'!$F$6:$CP$99,3,),)/1000 -> 1754.0612 | Q19: =+P19-O19 -> 289.56566 | R19: =+IFERROR(HLOOKUP($B19,'[3]2월'!$F$6:$CC$57,3,),)/1000 -> 2590.9238 | S19: =+P19-R19 -> -836.86264 | T19: =+IFERROR(HLOOKUP($B19,'[1]2월'!$D$6:$BN$259,16,),)/1000 -> 117.38233 | U19: =+IFERROR(HLOOKUP($B19,'[2]2월'!$F$6:$CP$99,16,),)/1000 -> 117.15924 | V19: =+U19-T19 -> -0.22308744 | W19: =+IFERROR(HLOOKUP($B19,'[3]2월'!$F$6:$CC$57,16,),)/1000 -> 365.5448 | X19: =+U19-W19 -> -248.38556 | Y19: =+[5]아산!$Q$85 -> 100999.69 | Z19: =+[5]아산!$R$85 -> 100398.44 | AA19: =+[6]아산!$Q$85 -> 93800.445 | AB19: =+[5]아산!$Q$89 -> 78008.057 | AC19: =+[5]아산!$R$89 -> 79376.802 | AD19: =+[6]아산!$Q$89 -> 69416.617 | AE19: =+Y19-AB19 -> 22991.632 | AF19: =+Z19-AC19 -> 21021.639 | AG19: =+AA19-AD19 -> 24383.828
B20: 전주 | G20: =+I20 -> 전주 | I20: 전주 | J20: =+IFERROR(HLOOKUP($B20,'[1]2월'!$D$6:$BN$259,2,),)/1000 -> 10 | K20: =+IFERROR(HLOOKUP($B20,'[2]2월'!$F$6:$CP$99,2,),)/1000 -> 2.263 | L20: =+K20-J20 -> -7.737 | M20: =+IFERROR(HLOOKUP($B20,'[3]2월'!$F$6:$CC$57,2,),)/1000 -> 8.0365 | N20: =+K20-M20 -> -5.7735 | O20: =+IFERROR(HLOOKUP($B20,'[1]2월'!$D$6:$BN$259,3,),)/1000 -> 1008.3758 | P20: =+IFERROR(HLOOKUP($B20,'[2]2월'!$F$6:$CP$99,3,),)/1000 -> 226.082 | Q20: =+P20-O20 -> -782.29381 | R20: =+IFERROR(HLOOKUP($B20,'[3]2월'!$F$6:$CC$57,3,),)/1000 -> 706.97394 | S20: =+P20-R20 -> -480.89194 | T20: =+IFERROR(HLOOKUP($B20,'[1]2월'!$D$6:$BN$259,16,),)/1000 -> 117.02374 | U20: =+IFERROR(HLOOKUP($B20,'[2]2월'!$F$6:$CP$99,16,),)/1000 -> -81.422136 | V20: =+U20-T20 -> -198.44587 | W20: =+IFERROR(HLOOKUP($B20,'[3]2월'!$F$6:$CC$57,16,),)/1000 -> 10.831823 | X20: =+U20-W20 -> -92.253959 | Y20: =+[5]전주!$Q$85 -> 100837.58 | Z20: =+[5]전주!$R$85 -> 99903.668 | AA20: =+[6]전주!$Q$85 -> 87971.814 | AB20: =+[5]전주!$Q$89 -> 74732.531 | AC20: =+[5]전주!$R$89 -> 73666.573 | AD20: =+[6]전주!$Q$89 -> 67286.453 | AE20: =+Y20-AB20 -> 26105.05 | AF20: =+Z20-AC20 -> 26237.095 | AG20: =+AA20-AD20 -> 20685.362
B21: 군산 | G21: =+I21 -> 군산 | I21: 군산 | J21: =+IFERROR(HLOOKUP($B21,'[1]2월'!$D$6:$BN$259,2,),)/1000 -> 4 | K21: =+IFERROR(HLOOKUP($B21,'[2]2월'!$F$6:$CP$99,2,),)/1000 -> 5.554 | L21: =+K21-J21 -> 1.554 | M21: =+IFERROR(HLOOKUP($B21,'[3]2월'!$F$6:$CC$57,2,),)/1000 -> 6.604 | N21: =+K21-M21 -> -1.05 | O21: =+IFERROR(HLOOKUP($B21,'[1]2월'!$D$6:$BN$259,3,),)/1000 -> 433.13408 | P21: =+IFERROR(HLOOKUP($B21,'[2]2월'!$F$6:$CP$99,3,),)/1000 -> 576.85868 | Q21: =+P21-O21 -> 143.7246 | R21: =+IFERROR(HLOOKUP($B21,'[3]2월'!$F$6:$CC$57,3,),)/1000 -> 605.03161 | S21: =+P21-R21 -> -28.172933 | T21: =+IFERROR(HLOOKUP($B21,'[1]2월'!$D$6:$BN$259,16,),)/1000 -> 75.802069 | U21: =+IFERROR(HLOOKUP($B21,'[2]2월'!$F$6:$CP$99,16,),)/1000 -> 104.45301 | V21: =+U21-T21 -> 28.650938 | W21: =+IFERROR(HLOOKUP($B21,'[3]2월'!$F$6:$CC$57,16,),)/1000 -> 113.88141 | X21: =+U21-W21 -> -9.428404 | Y21: =+[5]군산!$Q$85 -> 108283.52 | Z21: =+[5]군산!$R$85 -> 103863.64 | AA21: =+[6]군산!$Q$85 -> 91615.932 | AB21: =+[5]군산!$Q$89 -> 70400.342 | AC21: =+[5]군산!$R$89 -> 70822.396 | AD21: =+[6]군산!$Q$89 -> 63463.673 | AE21: =+Y21-AB21 -> 37883.177 | AF21: =+Z21-AC21 -> 33041.248 | AG21: =+AA21-AD21 -> 28152.258
B22: 원주 | G22: =+I22 -> 원주 | I22: 원주 | J22: =+IFERROR(HLOOKUP($B22,'[1]2월'!$D$6:$BN$259,2,),)/1000 -> 3 | K22: =+IFERROR(HLOOKUP($B22,'[2]2월'!$F$6:$CP$99,2,),)/1000 -> 3.4065 | L22: =+K22-J22 -> 0.4065 | M22: =+IFERROR(HLOOKUP($B22,'[3]2월'!$F$6:$CC$57,2,),)/1000 -> 2.892 | N22: =+K22-M22 -> 0.5145 | O22: =+IFERROR(HLOOKUP($B22,'[1]2월'!$D$6:$BN$259,3,),)/1000 -> 323.7 | P22: =+IFERROR(HLOOKUP($B22,'[2]2월'!$F$6:$CP$99,3,),)/1000 -> 364.3647 | Q22: =+P22-O22 -> 40.6647 | R22: =+IFERROR(HLOOKUP($B22,'[3]2월'!$F$6:$CC$57,3,),)/1000 -> 301.5011 | S22: =+P22-R22 -> 62.8636 | T22: =+IFERROR(HLOOKUP($B22,'[1]2월'!$D$6:$BN$259,16,),)/1000 -> 20.26208 | U22: =+IFERROR(HLOOKUP($B22,'[2]2월'!$F$6:$CP$99,16,),)/1000 -> 36.292712 | V22: =+U22-T22 -> 16.030632 | W22: =+IFERROR(HLOOKUP($B22,'[3]2월'!$F$6:$CC$57,16,),)/1000 -> 36.145729 | X22: =+U22-W22 -> 0.146983 | Y22: =+[5]원주!$Q$85 -> 107900 | Z22: =+[5]원주!$R$85 -> 106985.05 | AA22: =+[6]원주!$Q$85 -> 104253.49 | AB22: =+[5]원주!$Q$89 -> 75391.687 | AC22: =+[5]원주!$R$89 -> 72527.647 | AD22: =+[6]원주!$Q$89 -> 66869.222 | AE22: =+Y22-AB22 -> 32508.313 | AF22: =+Z22-AC22 -> 34457.401 | AG22: =+AA22-AD22 -> 37384.27
B23: 제주 | G23: =+I23 -> 제주 | I23: 제주 | J23: =+IFERROR(HLOOKUP($B23,'[1]2월'!$D$6:$BN$259,2,),)/1000 -> 4 | K23: =+IFERROR(HLOOKUP($B23,'[2]2월'!$F$6:$CP$99,2,),)/1000 -> 2.3985 | L23: =+K23-J23 -> -1.6015 | M23: =+IFERROR(HLOOKUP($B23,'[3]2월'!$F$6:$CC$57,2,),)/1000 -> 7.311 | N23: =+K23-M23 -> -4.9125 | O23: =+IFERROR(HLOOKUP($B23,'[1]2월'!$D$6:$BN$259,3,),)/1000 -> 506.8 | P23: =+IFERROR(HLOOKUP($B23,'[2]2월'!$F$6:$CP$99,3,),)/1000 -> 308.44243 | Q23: =+P23-O23 -> -198.35757 | R23: =+IFERROR(HLOOKUP($B23,'[3]2월'!$F$6:$CC$57,3,),)/1000 -> 864.90138 | S23: =+P23-R23 -> -556.45895 | T23: =+IFERROR(HLOOKUP($B23,'[1]2월'!$D$6:$BN$259,16,),)/1000 -> 56.265174 | U23: =+IFERROR(HLOOKUP($B23,'[2]2월'!$F$6:$CP$99,16,),)/1000 -> 14.867436 | V23: =+U23-T23 -> -41.397738 | W23: =+IFERROR(HLOOKUP($B23,'[3]2월'!$F$6:$CC$57,16,),)/1000 -> 189.18455 | X23: =+U23-W23 -> -174.31711 | Y23: =+[5]제주!$Q$85 -> 126700 | Z23: =+[5]제주!$R$85 -> 128598.05 | AA23: =+[6]제주!$Q$85 -> 118301.38 | AB23: =+[5]제주!$Q$89 -> 89935.469 | AC23: =+[5]제주!$R$89 -> 88785.068 | AD23: =+[6]제주!$Q$89 -> 81530.02 | AE23: =+Y23-AB23 -> 36764.531 | AF23: =+Z23-AC23 -> 39812.983 | AG23: =+AA23-AD23 -> 36771.359
G24: =+I24 -> 수도권 | I24: 수도권 | J24: =SUM(J7:J10) -> 91 | K24: =SUM(K7:K10) -> 85.559 | L24: =+K24-J24 -> -5.441 | M24: =SUM(M7:M10) -> 123.1355 | N24: =+K24-M24 -> -37.5765 | O24: =SUM(O7:O10) -> 8761.7329 | P24: =SUM(P7:P10) -> 8620.3028 | Q24: =+P24-O24 -> -141.43006 | R24: =SUM(R7:R10) -> 11034.191 | S24: =+P24-R24 -> -2413.888 | T24: =SUM(T7:T10) -> 567.13084 | U24: =SUM(U7:U10) -> 664.23061 | V24: =+U24-T24 -> 97.099776 | W24: =SUM(W7:W10) -> 1255.2355 | X24: =+U24-W24 -> -591.00484 | Y24: =+[5]수도권!$Q$85 -> 96282.779 | Z24: =+[5]수도권!$R$85 -> 100756.04 | AA24: =+[6]수도권!$Q$85 -> 89627.453 | AB24: =+[5]수도권!$Q$89 -> 79418.333 | AC24: =+[5]수도권!$R$89 -> 81462.706 | AD24: =+[6]수도권!$Q$89 -> 72071.962 | AE24: =+Y24-AB24 -> 16864.446 | AF24: =+Z24-AC24 -> 19293.33 | AG24: =+AA24-AD24 -> 17555.491
G25: =+I25 -> 영남권 | I25: 영남권 | J25: =SUM(J11:J18) -> 102.5 | K25: =SUM(K11:K18) -> 100.9045 | L25: =+K25-J25 -> -1.5955 | M25: =SUM(M11:M18) -> 148.3495 | N25: =+K25-M25 -> -47.445 | O25: =SUM(O11:O18) -> 10441.788 | P25: =SUM(P11:P18) -> 10371.431 | Q25: =+P25-O25 -> -70.357009 | R25: =SUM(R11:R18) -> 14148.378 | S25: =+P25-R25 -> -3776.9469 | T25: =SUM(T11:T18) -> 1247.8099 | U25: =SUM(U11:U18) -> 841.31884 | V25: =+U25-T25 -> -406.49103 | W25: =SUM(W11:W18) -> 2356.5121 | X25: =+U25-W25 -> -1515.1932 | Y25: =+[5]영남권!$Q$85 -> 101871.1 | Z25: =+[5]영남권!$R$85 -> 102784.62 | AA25: =+[6]영남권!$Q$85 -> 95374.233 | AB25: =+[5]영남권!$Q$89 -> 76000.323 | AC25: =+[5]영남권!$R$89 -> 80130.48 | AD25: =+[6]영남권!$Q$89 -> 70161.656 | AE25: =+Y25-AB25 -> 25870.777 | AF25: =+Z25-AC25 -> 22654.141 | AG25: =+AA25-AD25 -> 25212.578
G26: =+I26 -> 중부권 | I26: 중부권 | J26: =SUM(J19:J23) -> 35.5 | K26: =SUM(K19:K23) -> 31.093 | L26: =+K26-J26 -> -4.407 | M26: =SUM(M19:M23) -> 52.5165 | N26: =+K26-M26 -> -21.4235 | O26: =SUM(O19:O23) -> 3736.5054 | P26: =SUM(P19:P23) -> 3229.809 | Q26: =+P26-O26 -> -506.69642 | R26: =SUM(R19:R23) -> 5069.3318 | S26: =+P26-R26 -> -1839.5229 | T26: =SUM(T19:T23) -> 386.73539 | U26: =SUM(U19:U23) -> 191.35026 | V26: =+U26-T26 -> -195.38513 | W26: =SUM(W19:W23) -> 715.58831 | X26: =+U26-W26 -> -524.23805 | Y26: =+[5]중부권!$Q$85 -> 105253.67 | Z26: =+[5]중부권!$R$85 -> 103875.43 | AA26: =+[6]중부권!$Q$85 -> 96860.392 | AB26: =+[5]중부권!$Q$89 -> 77350.998 | AC26: =+[5]중부권!$R$89 -> 77415.679 | AD26: =+[6]중부권!$Q$89 -> 69928.316 | AE26: =+Y26-AB26 -> 27902.674 | AF26: =+Z26-AC26 -> 26459.748 | AG26: =+AA26-AD26 -> 26932.075
G27: =+K27/J27 -> 0.95002838 | H27: 레미콘 계 | J27: =SUM(J24:J26) -> 229 | K27: =SUM(K24:K26) -> 217.5565 | L27: =+K27-J27 -> -11.4435 | M27: =SUM(M24:M26) -> 324.0015 | N27: =+K27-M27 -> -106.445 | O27: =SUM(O24:O26) -> 22940.026 | P27: =SUM(P24:P26) -> 22221.543 | Q27: =+P27-O27 -> -718.48349 | R27: =SUM(R24:R26) -> 30251.9 | S27: =+P27-R27 -> -8030.3577 | T27: =SUM(T24:T26) -> 2201.6761 | U27: =SUM(U24:U26) -> 1696.8997 | V27: =+U27-T27 -> -504.77639 | W27: =SUM(W24:W26) -> 4327.3358 | X27: =+U27-W27 -> -2630.4361 | Y27: =+[5]합계!$Q$85 -> 100174.79 | Z27: =+[5]합계!$R$85 -> 102142.73 | AA27: =+[6]합계!$Q$85 -> 93402.766 | AB27: =+[5]합계!$Q$89 -> 77567.956 | AC27: =+[5]합계!$R$89 -> 80266.474 | AD27: =+[6]합계!$Q$89 -> 70855.946 | AE27: =+Y27-AB27 -> 22606.83 | AF27: =+Z27-AC27 -> 21876.256 | AG27: =+AA27-AD27 -> 22546.82
B28: 건자재 | E28: 건자재영업 | G28: 건자재 | H28: 건자재 | J28: =+IFERROR(HLOOKUP($B28,'[1]2월'!$D$6:$BN$259,2,),) -> 6400 | K28: =+IFERROR(HLOOKUP($E28,'[2]2월'!$F$6:$CP$99,2,),) -> 6645.402 | L28: =+K28-J28 -> 245.402 | M28: =+IFERROR(HLOOKUP($E28,'[3]2월'!$F$6:$CC$57,2,),) -> 8382.34 | N28: =+K28-M28 -> -1736.938 | O28: =+IFERROR(HLOOKUP($B28,'[1]2월'!$D$6:$BN$259,3,),)/1000 -> 7830.1979 | P28: =+IFERROR(HLOOKUP($E28,'[2]2월'!$F$6:$CP$99,3,),)/1000 -> 6765.658 | Q28: =+P28-O28 -> -1064.5399 | R28: =+IFERROR(HLOOKUP($E28,'[3]2월'!$F$6:$CC$57,3,),)/1000 -> 9789.471 | S28: =+P28-R28 -> -3023.813 | T28: =+IFERROR(HLOOKUP($B28,'[1]2월'!$D$6:$BN$259,16,),)/1000 -> 71.181193 | U28: =+IFERROR(HLOOKUP($E28,'[2]2월'!$F$6:$CP$99,16,),)/1000 -> 41.844679 | V28: =+U28-T28 -> -29.336514 | W28: =+IFERROR(HLOOKUP($E28,'[3]2월'!$F$6:$CC$57,16,),)/1000 -> 77.227243 | X28: =+U28-W28 -> -35.382564 | Y28: ■ 비고
B29: 부산모래장 | F29: 부산골재 | G29: =+I29 -> 부산모래장 | H29: 골재 | I29: 부산모래장 | J29: =+IFERROR(HLOOKUP($B29,'[1]2월'!$D$6:$BN$259,2,),)/1000 -> 18.067898 | K29: =+IFERROR(HLOOKUP($F29,'[2]2월'!$F$6:$CP$99,2,),)/1000 -> 18.623 | L29: =+K29-J29 -> 0.5551022 | M29: =+IFERROR(HLOOKUP($F29,'[3]2월'!$F$6:$CC$57,2,),)/1000 -> 25.752 | N29: =+K29-M29 -> -7.129 | O29: =+IFERROR(HLOOKUP($B29,'[1]2월'!$D$6:$BN$259,3,),)/1000 -> 557.43264 | P29: =+IFERROR(HLOOKUP($F29,'[2]2월'!$F$6:$CP$99,3,),)/1000 -> 535.572 | Q29: =+P29-O29 -> -21.860642 | R29: =+IFERROR(HLOOKUP($F29,'[3]2월'!$F$6:$CC$57,3,),)/1000 -> 753.9052 | S29: =+P29-R29 -> -218.3332 | T29: =+IFERROR(HLOOKUP($B29,'[1]2월'!$D$6:$BN$259,21,),)/1000 -> 34.128552 | U29: =+IFERROR(HLOOKUP($F29,'[2]2월'!$F$6:$CP$99,21,),)/1000 -> 33.694013 | V29: =+U29-T29 -> -0.43453928 | W29: =+IFERROR(HLOOKUP($F29,'[3]2월'!$F$6:$CC$57,16,),)/1000 -> 27.686922 | X29: =+U29-W29 -> 6.0070905
B30: 서부산크라샤 | F30: 서부산골재 | G30: =+I30 -> 서부산CR | I30: 서부산CR | J30: =+IFERROR(HLOOKUP($B30,'[1]2월'!$D$6:$BN$259,2,),)/1000 -> 11.1378 | K30: =+IFERROR(HLOOKUP($F30,'[2]2월'!$F$6:$CP$99,2,),)/1000 -> 23.046 | L30: =+K30-J30 -> 11.9082 | M30: =+IFERROR(HLOOKUP($F30,'[3]2월'!$F$6:$CC$57,2,),)/1000 -> 38.996 | N30: =+K30-M30 -> -15.95 | O30: =+IFERROR(HLOOKUP($B30,'[1]2월'!$D$6:$BN$259,3,),)/1000 -> 173.6068 | P30: =+IFERROR(HLOOKUP($F30,'[2]2월'!$F$6:$CP$99,3,),)/1000 -> 318.718 | Q30: =+P30-O30 -> 145.1112 | R30: =+IFERROR(HLOOKUP($F30,'[3]2월'!$F$6:$CC$57,3,),)/1000 -> 460.11 | S30: =+P30-R30 -> -141.392 | T30: =+IFERROR(HLOOKUP($B30,'[1]2월'!$D$6:$BN$259,21,),)/1000 -> 78.169969 | U30: =+IFERROR(HLOOKUP($F30,'[2]2월'!$F$6:$CP$99,21,),)/1000 -> 37.250623 | V30: =+U30-T30 -> -40.919346 | W30: =+IFERROR(HLOOKUP($F30,'[3]2월'!$F$6:$CC$57,16,),)/1000 -> 115.69047 | X30: =+U30-W30 -> -78.439847
B31: 부산크라샤 | F31: 부산크라샤 | G31: =+I31 -> 부산CR | I31: 부산CR | J31: =+IFERROR(HLOOKUP($B31,'[1]2월'!$D$6:$BN$259,2,),)/1000 -> 37.656383 | K31: =+IFERROR(HLOOKUP($F31,'[2]2월'!$F$6:$CP$99,2,),)/1000 -> 23.603 | L31: =+K31-J31 -> -14.053383 | M31: =+IFERROR(HLOOKUP($F31,'[3]2월'!$F$6:$CC$57,2,),)/1000 -> 0 | N31: =+K31-M31 -> 23.603 | O31: =+IFERROR(HLOOKUP($B31,'[1]2월'!$D$6:$BN$259,3,),)/1000 -> 671.4769 | P31: =+IFERROR(HLOOKUP($F31,'[2]2월'!$F$6:$CP$99,3,),)/1000 -> 442.7965 | Q31: =+P31-O31 -> -228.6804 | R31: =+IFERROR(HLOOKUP($F31,'[3]2월'!$F$6:$CC$57,3,),)/1000 -> 0 | S31: =+P31-R31 -> 442.7965 | T31: =+IFERROR(HLOOKUP($B31,'[1]2월'!$D$6:$BN$259,21,),)/1000 -> -1.6180294 | U31: =+IFERROR(HLOOKUP($F31,'[2]2월'!$F$6:$CP$99,21,),)/1000 -> 8.2347302 | V31: =+U31-T31 -> 9.8527597 | W31: =+IFERROR(HLOOKUP($F31,'[3]2월'!$F$6:$CC$57,16,),)/1000 -> -9.372693 | X31: =+U31-W31 -> 17.607423
H32: 골재 계 | J32: =SUM(J29:J31) -> 66.862081 | K32: =SUM(K29:K31) -> 65.272 | L32: =+K32-J32 -> -1.5900812 | M32: =SUM(M29:M31) -> 64.748 | N32: =+K32-M32 -> 0.524 | O32: =SUM(O29:O31) -> 1402.5163 | P32: =SUM(P29:P31) -> 1297.0865 | Q32: =+P32-O32 -> -105.42984 | R32: =SUM(R29:R31) -> 1214.0152 | S32: =+P32-R32 -> 83.0713 | T32: =SUM(T29:T31) -> 110.68049 | U32: =SUM(U29:U31) -> 79.179365 | V32: =+U32-T32 -> -31.501126 | W32: =SUM(W29:W31) -> 134.0047 | X32: =+U32-W32 -> -54.825334
B33: 포항임대 | C33: 속초임대 | D33: 강릉임대 | E33: 레미콘임대 계 | G33: =+I33 -> 레미콘임대 | H33: 기타 | I33: 레미콘임대 | L33: =+K33-J33 -> 0 | N33: =+K33-M33 -> 0 | O33: =(IFERROR(HLOOKUP($B33,'[1]2월'!$D$6:$BN$259,3,),)++IFERROR(HLOOKUP($C33,'[1]2월'!$D$6:$BN$259,3,),)+IFERROR(HLOOKUP($D33,'[1]2월'!$D$6:$BN$259,3,),))/1000 -> 90.84 | P33: =+IFERROR(HLOOKUP($E33,'[2]2월'!$F$6:$CP$99,3,),)/1000 -> 90.84 | Q33: =+P33-O33 -> 0 | R33: =+IFERROR(HLOOKUP($E33,'[3]2월'!$F$6:$CC$57,3,),)/1000 -> 78.34 | S33: =+P33-R33 -> 12.5 | T33: =(IFERROR(HLOOKUP($B33,'[1]2월'!$D$6:$BN$259,21,),)++IFERROR(HLOOKUP($C33,'[1]2월'!$D$6:$BN$259,21,),)+IFERROR(HLOOKUP($D33,'[1]2월'!$D$6:$BN$259,21,),))/1000 -> 72.255091 | U33: =+IFERROR(HLOOKUP($E33,'[2]2월'!$F$6:$CP$99,16,),)/1000 -> 71.965353 | V33: =+U33-T33 -> -0.289738 | W33: =+IFERROR(HLOOKUP($E33,'[3]2월'!$F$6:$CC$57,16,),)/1000 -> 63.166801 | X33: =+U33-W33 -> 8.798552
B34: 부동산임대 | C34: 주유소임대 | E34: 임대 계 | G34: =+I34 -> 임대 | I34: 임대 | L34: =+K34-J34 -> 0 | M34: 0 | N34: =+K34-M34 -> 0 | O34: =(+IFERROR(HLOOKUP($B34,'[1]2월'!$D$6:$BN$259,3,),)+IFERROR(HLOOKUP($C34,'[1]2월'!$D$6:$BN$259,3,),))/1000 -> 72.2975 | P34: =+IFERROR(HLOOKUP($E34,'[2]2월'!$F$6:$CP$99,3,),)/1000 -> 71.982759 | Q34: =+P34-O34 -> -0.31474133 | R34: =+IFERROR(HLOOKUP($E34,'[3]2월'!$F$6:$CC$57,3,),)/1000 -> 94.061277 | S34: =+P34-R34 -> -22.078518 | T34: =(+IFERROR(HLOOKUP($B34,'[1]2월'!$D$6:$BN$259,21,),)+IFERROR(HLOOKUP($C34,'[1]2월'!$D$6:$BN$259,21,),))/1000 -> 62.060442 | U34: =+IFERROR(HLOOKUP($E34,'[2]2월'!$F$6:$CP$99,16,),)/1000 -> 61.893705 | V34: =+U34-T34 -> -0.16673733 | W34: =+IFERROR(HLOOKUP($E34,'[3]2월'!$F$6:$CC$57,16,),)/1000 -> 24.163334 | X34: =+U34-W34 -> 37.730371
B35: 공 통 비 | G35: =+I35 -> 공통비 | I35: 공통비 | L35: =+K35-J35 -> 0 | N35: =+K35-M35 -> 0 | Q35: =+P35-O35 -> 0 | S35: =+P35-R35 -> 0 | T35: =-'[1]2월'!$Z$22/1000 -> -1053.4137 | U35: =+-'[2]2월'!$Z$22/1000 -> -1053.317 | V35: =+U35-T35 -> 0.096726425 | W35: =+-'[3]2월'!$Z$22/1000 -> -788.78672 | X35: =+U35-W35 -> -264.53025
G36: =+I36 -> OPC 소급분 | I36: OPC 소급분 | N36: =+K36-M36 -> 0 | Q36: =+P36-O36 -> 0 | S36: =+P36-R36 -> 0 | T36: =+'[1]2월'!$AS$26/1000 -> 0 | U36: =-'[2]2월'!$BD$26/1000 -> 0 | V36: =+U36-T36 -> 0 | W36: =-'[3]2월'!$BD$26/1000 -> 0 | X36: =+U36-W36 -> 0
G37: =+I37 -> 대손 | I37: 대손 | N37: =+K37-M37 -> 0 | Q37: =+P37-O37 -> 0 | S37: =+P37-R37 -> 0 | U37: ='[2]2월'!$BE$26/1000 -> 310.72653 | V37: =+U37-T37 -> 310.72653 | W37: =-'[3]2월'!$BE$26/1000 -> 0 | X37: =+U37-W37 -> 310.72653
G38: =+I38 -> 미운영 공장 | I38: 미운영 공장 | M38: =SUM(M54:M57) -> 0 | N38: =+K38-M38 -> 0 | Q38: =+P38-O38 -> 0 | S38: =+P38-R38 -> 0 | T38: =SUM('[1]2월'!$AM$26:$AQ$26)/1000 -> -35.658967 | U38: =+'[2]2월'!$BF$26/1000 -> -35.452237 | V38: =+U38-T38 -> 0.20673044 | W38: =+'[3]2월'!$BF$26/1000 -> -12.884253 | X38: =+U38-W38 -> -22.567984
B39: 기타 계 | G39: =+I39 -> 기타 | I39: 기타 | L39: =+K39-J39 -> 0 | N39: =+K39-M39 -> 0 | O39: =IFERROR(HLOOKUP($B39,'[1]2월'!$D$6:$BN$259,3,),)/1000 -> 1.77 | P39: =+('[2]2월'!$F$8-SUM('[2]2월'!$Z$8,'[2]2월'!$AH$8,'[2]2월'!$AN$8,'[2]2월'!$AO$8,'[2]2월'!$BA$8,'[2]2월'!$BD$8,'[2]2월'!$BE$8,'[2]2월'!$BF$8))/1000 -> 1.7024 | Q39: =+P39-O39 -> -0.0676 | R39: =+('[3]2월'!$F$8-SUM('[3]2월'!$Z$8,'[3]2월'!$AH$8,'[3]2월'!$AN$8,'[3]2월'!$AO$8,'[3]2월'!$BA$8,'[3]2월'!$BD$8,'[3]2월'!$BE$8,'[3]2월'!$BF$8))/1000 -> 1.6869 | S39: =+P39-R39 -> 0.0155 | T39: =+('[1]2월'!$E$26-'[1]2월'!$Z$26-'[1]2월'!$AA$26-'[1]2월'!$AE$26-'[1]2월'!$AL$26-'[1]2월'!$AM$26-'[1]2월'!$AN$26-'[1]2월'!$AO$26-'[1]2월'!$AP$26-'[1]2월'!$AQ$26-'[1]2월'!$AS$26)/1000 -> -15.985408 | U39: =+('[2]2월'!$F$26-SUM('[2]2월'!$Z$26,'[2]2월'!$AH$26,'[2]2월'!$AN$26,'[2]2월'!$AO$26,'[2]2월'!$BA$26,'[2]2월'!$BD$26,'[2]2월'!$BE$26,'[2]2월'!$BF$26))/1000 -> -14.483713 | V39: =+U39-T39 -> 1.501695 | W39: =+('[3]2월'!$F$26-SUM('[3]2월'!$Z$26,'[3]2월'!$AH$26,'[3]2월'!$AN$26,'[3]2월'!$AO$26,'[3]2월'!$BA$26,'[3]2월'!$BD$26,'[3]2월'!$BE$26,'[3]2월'!$BF$26))/1000 -> -17.073227 | X39: =+U39-W39 -> 2.589514
N40: =+K40-M40 -> 0 | Q40: =+P40-O40 -> 0 | S40: =+P40-R40 -> 0 | V40: =+U40-T40 -> 0
H41: 기타 계 | J41: =SUM(J33:J40) -> 0 | K41: =SUM(K33:K40) -> 0 | L41: =+K41-J41 -> 0 | M41: =SUM(M33:M40) -> 0 | N41: =+K41-M41 -> 0 | O41: =SUM(O33:O40) -> 164.9075 | P41: =SUM(P33:P40) -> 164.52516 | Q41: =+P41-O41 -> -0.38234133 | R41: =SUM(R33:R40) -> 174.08818 | S41: =+P41-R41 -> -9.563018 | T41: =SUM(T33:T40) -> -970.74254 | U41: =SUM(U33:U40) -> -658.66734 | V41: =+U41-T41 -> 312.0752 | W41: =SUM(W33:W40) -> -731.41407 | X41: =+U41-W41 -> 72.746734
G43: =+P43/O43 -> 0.9415902 | H43: 합계 | O43: =+O27+O32+O28+O41 -> 32337.648 | P43: =+P27+P32+P28+P41 -> 30448.812 | Q43: =+P43-O43 -> -1888.8356 | R43: =+R27+R32+R28+R41 -> 41429.475 | S43: =+P43-R43 -> -10980.662 | T43: =+T27+T32+T28+T41 -> 1412.7952 | U43: =+U27+U32+U28+U41 -> 1159.2564 | V43: =+U43-T43 -> -253.53882 | W43: =+W27+W32+W28+W41 -> 3807.1537 | X43: =+U43-W43 -> -2647.8973
...

Sheet 사업장별(누계)
H3: □ 사업장별 손익실적(2024-02누계)
AG4: [단위 : 천㎥, 톤, 백만원]
H5: 구분 | J5: 물량 | O5: 매출 | T5: 영업이익(공통비 배부전) | Y5: 판매단가 | AB5: 변동비 | AE5: 공헌이익
J6: 계획 | K6: 실적 | L6: 차이 | M6: 전년 | N6: 차이 | O6: 계획 | P6: 실적 | Q6: 차이 | R6: 전년 | S6: 차이 | T6: 계획 | U6: 실적 | V6: 차이 | W6: 전년 | X6: 차이 | Y6: 계획 | Z6: 실적 | AA6: 전년 | AB6: 계획 | AC6: 실적 | AD6: 전년 | AE6: 계획 | AF6: 실적 | AG6: 전년
B7: 안양 | H7: 레미콘 | I7: 안양 | J7: =+'사업장별(당월)'!J7+'[4]사업장별(누계)'!J7 -> 73 | K7: =+'사업장별(당월)'!K7+'[4]사업장별(누계)'!K7 -> 83.473 | L7: =+K7-J7 -> 10.473 | M7: =+'사업장별(당월)'!M7+'[4]사업장별(누계)'!M7 -> 88.853 | N7: =+K7-M7 -> -5.38 | O7: =+'사업장별(당월)'!O7+'[4]사업장별(누계)'!O7 -> 7061.5275 | P7: =+'사업장별(당월)'!P7+'[4]사업장별(누계)'!P7 -> 8145.4069 | Q7: =+P7-O7 -> 1083.8794 | R7: =+'사업장별(당월)'!R7+'[4]사업장별(누계)'!R7 -> 8024.5554 | S7: =+P7-R7 -> 120.85154 | T7: =+'사업장별(당월)'!T7+'[4]사업장별(누계)'!T7 -> 622.57957 | U7: =+'사업장별(당월)'!U7+'[4]사업장별(누계)'!U7 -> 788.53204 | V7: =+U7-T7 -> 165.95247 | W7: =+'사업장별(당월)'!W7+'[4]사업장별(누계)'!W7 -> 1021.0494 | X7: =+U7-W7 -> -232.51736 | Y7: =+[11]안양!$Q$85 -> 96733.253 | Z7: =+[11]안양!$R$85 -> 97581.336 | AA7: =+[12]안양!$Q$85 -> 90281.444 | AB7: =+[11]안양!$Q$89 -> 80010.749 | AC7: =+[11]안양!$R$89 -> 80540.048 | AD7: =+[12]안양!$Q$89 -> 72366.174 | AE7: =+Y7-AB7 -> 16722.505 | AF7: =+Z7-AC7 -> 17041.289 | AG7: =+AA7-AD7 -> 17915.27
B8: 인천 | H8: 직영 | I8: 인천 | J8: =+'사업장별(당월)'!J8+'[4]사업장별(누계)'!J8 -> 52 | K8: =+'사업장별(당월)'!K8+'[4]사업장별(누계)'!K8 -> 51.84 | L8: =+K8-J8 -> -0.16 | M8: =+'사업장별(당월)'!M8+'[4]사업장별(누계)'!M8 -> 62.8 | N8: =+K8-M8 -> -10.96 | O8: =+'사업장별(당월)'!O8+'[4]사업장별(누계)'!O8 -> 5078.6581 | P8: =+'사업장별(당월)'!P8+'[4]사업장별(누계)'!P8 -> 5123.5698 | Q8: =+P8-O8 -> 44.911789 | R8: =+'사업장별(당월)'!R8+'[4]사업장별(누계)'!R8 -> 5646.3011 | S8: =+P8-R8 -> -522.73127 | T8: =+'사업장별(당월)'!T8+'[4]사업장별(누계)'!T8 -> 197.8357 | U8: =+'사업장별(당월)'!U8+'[4]사업장별(누계)'!U8 -> 240.8827 | V8: =+U8-T8 -> 43.047005 | W8: =+'사업장별(당월)'!W8+'[4]사업장별(누계)'!W8 -> 402.04195 | X8: =+U8-W8 -> -161.15925 | Y8: =+[11]인천!$Q$85 -> 97666.501 | Z8: =+[11]인천!$R$85 -> 98834.295 | AA8: =+[12]인천!$Q$85 -> 89899.903 | AB8: =+[11]인천!$Q$89 -> 82036.166 | AC8: =+[11]인천!$R$89 -> 83169.154 | AD8: =+[12]인천!$Q$89 -> 74059.992 | AE8: =+Y8-AB8 -> 15630.335 | AF8: =+Z8-AC8 -> 15665.141 | AG8: =+AA8-AD8 -> 15839.911
B9: 파주 | I9: 파주 | J9: =+'사업장별(당월)'!J9+'[4]사업장별(누계)'!J9 -> 41 | K9: =+'사업장별(당월)'!K9+'[4]사업장별(누계)'!K9 -> 41.352 | L9: =+K9-J9 -> 0.352 | M9: =+'사업장별(당월)'!M9+'[4]사업장별(누계)'!M9 -> 44.329 | N9: =+K9-M9 -> -2.977 | O9: =+'사업장별(당월)'!O9+'[4]사업장별(누계)'!O9 -> 3937.8059 | P9: =+'사업장별(당월)'!P9+'[4]사업장별(누계)'!P9 -> 4220.6218 | Q9: =+P9-O9 -> 282.81595 | R9: =+'사업장별(당월)'!R9+'[4]사업장별(누계)'!R9 -> 3901.5158 | S9: =+P9-R9 -> 319.10602 | T9: =+'사업장별(당월)'!T9+'[4]사업장별(누계)'!T9 -> 314.09599 | U9: =+'사업장별(당월)'!U9+'[4]사업장별(누계)'!U9 -> 241.86419 | V9: =+U9-T9 -> -72.231796 | W9: =+'사업장별(당월)'!W9+'[4]사업장별(누계)'!W9 -> 167.75494 | X9: =+U9-W9 -> 74.109251 | Y9: =+[11]파주!$Q$85 -> 96044.046 | Z9: =+[11]파주!$R$85 -> 102073.71 | AA9: =+[12]파주!$Q$85 -> 88117.569 | AB9: =+[11]파주!$Q$89 -> 77932.527 | AC9: =+[11]파주!$R$89 -> 84198.573 | AD9: =+[12]파주!$Q$89 -> 74065.537 | AE9: =+Y9-AB9 -> 18111.519 | AF9: =+Z9-AC9 -> 17875.138 | AG9: =+AA9-AD9 -> 14052.032
B10: 김포 | I10: 김포 | J10: =+'사업장별(당월)'!J10+'[4]사업장별(누계)'!J10 -> 18 | K10: =+'사업장별(당월)'!K10+'[4]사업장별(누계)'!K10 -> 11.158 | L10: =+K10-J10 -> -6.842 | M10: =+'사업장별(당월)'!M10+'[4]사업장별(누계)'!M10 -> 20.5295 | N10: =+K10-M10 -> -9.3715 | O10: =+'사업장별(당월)'!O10+'[4]사업장별(누계)'!O10 -> 1666.081 | P10: =+'사업장별(당월)'!P10+'[4]사업장별(누계)'!P10 -> 1056.885 | Q10: =+P10-O10 -> -609.19601 | R10: =+'사업장별(당월)'!R10+'[4]사업장별(누계)'!R10 -> 1744.2663 | S10: =+P10-R10 -> -687.3813 | T10: =+'사업장별(당월)'!T10+'[4]사업장별(누계)'!T10 -> 13.627932 | U10: =+'사업장별(당월)'!U10+'[4]사업장별(누계)'!U10 -> -120.97256 | V10: =+U10-T10 -> -134.60049 | W10: =+'사업장별(당월)'!W10+'[4]사업장별(누계)'!W10 -> 71.934781 | X10: =+U10-W10 -> -192.90734 | Y10: =+[11]김포!$Q$85 -> 92560.056 | Z10: =+[11]김포!$R$85 -> 94719.931 | AA10: =+[12]김포!$Q$85 -> 84942.819 | AB10: =+[11]김포!$Q$89 -> 73347.667 | AC10: =+[11]김포!$R$89 -> 78222.841 | AD10: =+[12]김포!$Q$89 -> 66403.818 | AE10: =+Y10-AB10 -> 19212.389 | AF10: =+Z10-AC10 -> 16497.091 | AG10: =+AA10-AD10 -> 18539.001
B11: 부산 | I11: 부산 | J11: =+'사업장별(당월)'!J11+'[4]사업장별(누계)'!J11 -> 34 | K11: =+'사업장별(당월)'!K11+'[4]사업장별(누계)'!K11 -> 40.465 | L11: =+K11-J11 -> 6.465 | M11: =+'사업장별(당월)'!M11+'[4]사업장별(누계)'!M11 -> 49.608 | N11: =+K11-M11 -> -9.143 | O11: =+'사업장별(당월)'!O11+'[4]사업장별(누계)'!O11 -> 3658.3967 | P11: =+'사업장별(당월)'!P11+'[4]사업장별(누계)'!P11 -> 4393.8048 | Q11: =+P11-O11 -> 735.40811 | R11: =+'사업장별(당월)'!R11+'[4]사업장별(누계)'!R11 -> 5084.867 | S11: =+P11-R11 -> -691.06223 | T11: =+'사업장별(당월)'!T11+'[4]사업장별(누계)'!T11 -> 442.56726 | U11: =+'사업장별(당월)'!U11+'[4]사업장별(누계)'!U11 -> 500.25937 | V11: =+U11-T11 -> 57.692114 | W11: =+'사업장별(당월)'!W11+'[4]사업장별(누계)'!W11 -> 980.79131 | X11: =+U11-W11 -> -480.53194 | Y11: =+[11]부산!$Q$85 -> 107599.9 | Z11: =+[11]부산!$R$85 -> 108582.84 | AA11: =+[12]부산!$Q$85 -> 102500.95 | AB11: =+[11]부산!$Q$89 -> 78563.753 | AC11: =+[11]부산!$R$89 -> 84409.345 | AD11: =+[12]부산!$Q$89 -> 73050.537 | AE11: =+Y11-AB11 -> 29036.149 | AF11: =+Z11-AC11 -> 24173.498 | AG11: =+AA11-AD11 -> 29450.41
B12: 서부산 | I12: 서부산 | J12: =+'사업장별(당월)'!J12+'[4]사업장별(누계)'!J12 -> 40 | K12: =+'사업장별(당월)'!K12+'[4]사업장별(누계)'!K12 -> 40.751 | L12: =+K12-J12 -> 0.751 | M12: =+'사업장별(당월)'!M12+'[4]사업장별(누계)'!M12 -> 45.21 | N12: =+K12-M12 -> -4.459 | O12: =+'사업장별(당월)'!O12+'[4]사업장별(누계)'!O12 -> 4141.5398 | P12: =+'사업장별(당월)'!P12+'[4]사업장별(누계)'!P12 -> 4067.8206 | Q12: =+P12-O12 -> -73.71918 | R12: =+'사업장별(당월)'!R12+'[4]사업장별(누계)'!R12 -> 4215.3068 | S12: =+P12-R12 -> -147.48618 | T12: =+'사업장별(당월)'!T12+'[4]사업장별(누계)'!T12 -> 616.12547 | U12: =+'사업장별(당월)'!U12+'[4]사업장별(누계)'!U12 -> 316.896 | V12: =+U12-T12 -> -299.22947 | W12: =+'사업장별(당월)'!W12+'[4]사업장별(누계)'!W12 -> 576.25843 | X12: =+U12-W12 -> -259.36243 | Y12: =+[11]서부산!$Q$85 -> 103538.49 | Z12: =+[11]서부산!$R$85 -> 99821.369 | AA12: =+[12]서부산!$Q$85 -> 93238.372 | AB12: =+[11]서부산!$Q$89 -> 77640.4 | AC12: =+[11]서부산!$R$89 -> 80640.022 | AD12: =+[12]서부산!$Q$89 -> 70765.656 | AE12: =+Y12-AB12 -> 25898.095 | AF12: =+Z12-AC12 -> 19181.347 | AG12: =+AA12-AD12 -> 22472.716
