Workbook

Sheet 표지
A6: 2024년 9월 마감 손익
A24: 건재사업본부

Sheet 손익총괄
C3: □ 건재사업본부 손익실적(2024-09) | Z3: □ 건재부문 실적(9월)
X4: [단위 : 천㎥, 톤, 원/㎥, 원/톤, 백만원] | AK4: (단위 : 천㎥, 천톤, 억원)
C5: 구분 | E5: 9월 | J5: 9월 누계 | P5: 9월 주요지표 | Z5: 구분 | AB5: =+E5 -> 9월 | AG5: =+J5 -> 9월 누계
E6: 계획 | F6: 실적 | G6: 계획대비 | H6: 전년 | I6: 전년대비 | J6: 계획 | K6: 실적 | L6: 계획대비 | M6: 전년 | N6: 전년대비 | AB6: =+E6 -> 계획 | AC6: =+F6 -> 실적 | AD6: =+G6 -> 계획대비 | AE6: =+H6 -> 전년 | AF6: =+I6 -> 전년대비 | AG6: =+J6 -> 계획 | AH6: =+K6 -> 실적 | AI6: =+L6 -> 계획대비 | ... AK6: =+N6 -> 전년대비
A7: =+F7/E7 -> 0.81900971 | B7: =+K7/J7 -> 0.99106937 | C7: 물량 | D7: 레미콘 | E7: =+'[1]9월'!$Z$7/1000 -> 288.5 | F7: =+'[2]9월'!$Z$7/1000 -> 236.2843 | G7: =+F7-E7 -> -52.2157 | H7: =+'[3]9월'!$Z$7/1000 -> 315.1905 | I7: =+F7-H7 -> -78.9062 | J7: =+[4]손익총괄!J7+E7 -> 2551.5 | K7: =+[4]손익총괄!K7+F7 -> 2528.7135 | L7: =+K7-J7 -> -22.7865 | M7: =+[4]손익총괄!M7+H7 -> 2850.005 | N7: =+K7-M7 -> -321.2915 | Q7: □ 레미콘 | Z7: 물량 | AA7: =+D7 -> 레미콘 | AB7: =+E7 -> 288.5 | AC7: =+F7 -> 236.2843 | AD7: =+AC7-AB7 -> -52.2157 | AE7: =+H7 -> 315.1905 | AF7: =+AC7-AE7 -> -78.9062 | AG7: =+J7 -> 2551.5 | AH7: =+K7 -> 2528.7135 | AI7: =+AH7-AG7 -> -22.7865 | AJ7: =+M7 -> 2850.005 | AK7: =+AH7-AJ7 -> -321.2915
D8: 철강재 | E8: =+'[1]9월'!$AA$7 -> 6500 | F8: =+'[2]9월'!$AO$7 -> 7354.628 | G8: =+F8-E8 -> 854.628 | H8: =+'[3]9월'!$AO$7 -> 6990.503 | I8: =+F8-H8 -> 364.125 | J8: =+[4]손익총괄!J8+E8 -> 63300 | K8: =+[4]손익총괄!K8+F8 -> 77967.344 | L8: =+K8-J8 -> 14667.344 | M8: =+[4]손익총괄!M8+H8 -> 69555.719 | N8: =+K8-M8 -> 8411.625 | Q8: 구분 | S8: 계획 | T8: 실적 | U8: 계획대비 | V8: 전년 | W8: 전년대비 | AA8: =+D8 -> 철강재 | AB8: =+E8/1000 -> 6.5 | AC8: =+F8/1000 -> 7.354628 | AD8: =+AC8-AB8 -> 0.854628 | AE8: =+H8/1000 -> 6.990503 | AF8: =+AC8-AE8 -> 0.364125 | AG8: =+J8/1000 -> 63.3 | AH8: =+K8/1000 -> 77.967344 | AI8: =+AH8-AG8 -> 14.667344 | AJ8: =+M8/1000 -> 69.555719 | AK8: =+AH8-AJ8 -> 8.411625
D9: 골재 | E9: =+'[1]9월'!$AE$7/1000 -> 114.29774 | F9: =+'[2]9월'!$AN$7/1000 -> 46.951 | G9: =+F9-E9 -> -67.346735 | H9: =+'[3]9월'!$AN$7/1000 -> 81.909 | I9: =+F9-H9 -> -34.958 | J9: =+[4]손익총괄!J9+E9 -> 856.28675 | K9: =+[4]손익총괄!K9+F9 -> 654.215 | L9: =+K9-J9 -> -202.07175 | M9: =+[4]손익총괄!M9+H9 -> 573.882 | N9: =+K9-M9 -> 80.333 | Q9: 물량 | R9: 수도권 | S9: =+[5]수도권!$T$5/1000 -> 114.5 | T9: =+[5]수도권!$U$5/1000 -> 75.6348 | U9: =+T9-S9 -> -38.8652 | V9: =+[6]수도권!$T$5/1000 -> 129.8285 | W9: =+T9-V9 -> -54.1937 | AA9: =+D9 -> 골재 | AB9: =+E9 -> 114.29774 | AC9: =+F9 -> 46.951 | AD9: =+AC9-AB9 -> -67.346735 | AE9: =+H9 -> 81.909 | AF9: =+AC9-AE9 -> -34.958 | AG9: =+J9 -> 856.28675 | AH9: =+K9 -> 654.215 | AI9: =+AH9-AG9 -> -202.07175 | AJ9: =+M9 -> 573.882 | AK9: =+AH9-AJ9 -> 80.333
C10: 매출 | D10: 레미콘 | E10: =+'[1]9월'!$Z$8/1000 -> 29542.81 | F10: =+'[2]9월'!$Z$8/1000 -> 23619.373 | G10: =+F10-E10 -> -5923.4376 | H10: =+'[3]9월'!$Z$8/1000 -> 31031.49 | I10: =+F10-H10 -> -7412.1175 | J10: =+[4]손익총괄!J10+E10 -> 259775.29 | K10: =+[4]손익총괄!K10+F10 -> 255794.31 | L10: =+K10-J10 -> -3980.9846 | M10: =+[4]손익총괄!M10+H10 -> 275039.41 | N10: =+K10-M10 -> -19245.105 | R10: 영남권 | S10: =+[5]영남권!$T$5/1000 -> 120 | T10: =+[5]영남권!$U$5/1000 -> 111.844 | U10: =+T10-S10 -> -8.156 | V10: =+[6]영남권!$T$5/1000 -> 132.887 | W10: =+T10-V10 -> -21.043 | Z10: 매출액 | AA10: =+D10 -> 레미콘 | AB10: =+E10/100 -> 295.4281 | AC10: =+F10/100 -> 236.19373 | AD10: =+AC10-AB10 -> -59.234376 | AE10: =+H10/100 -> 310.3149 | AF10: =+AC10-AE10 -> -74.121175 | AG10: =+J10/100 -> 2597.7529 | AH10: =+K10/100 -> 2557.9431 | AI10: =+AH10-AG10 -> -39.809846 | AJ10: =+M10/100 -> 2750.3941 | AK10: =+AH10-AJ10 -> -192.45105
D11: 건자재 | E11: =+'[1]9월'!$AA$8/1000 -> 7946.92 | F11: =+'[2]9월'!$AO$8/1000 -> 7720.8259 | G11: =+F11-E11 -> -226.09414 | H11: =+'[3]9월'!$AO$8/1000 -> 9395.2205 | I11: =+F11-H11 -> -1674.3947 | J11: =+[4]손익총괄!J11+E11 -> 77413.543 | K11: =+[4]손익총괄!K11+F11 -> 77932.391 | L11: =+K11-J11 -> 518.8479 | M11: =+[4]손익총괄!M11+H11 -> 85026.684 | N11: =+K11-M11 -> -7094.2927 | R11: 중부권 | S11: =+[5]중부권!$T$5/1000 -> 54 | T11: =+[5]중부권!$U$5/1000 -> 48.8055 | U11: =+T11-S11 -> -5.1945 | V11: =+[6]중부권!$T$5/1000 -> 52.475 | W11: =+T11-V11 -> -3.6695 | AA11: =+D11 -> 건자재 | AB11: =+E11/100 -> 79.4692 | AC11: =+F11/100 -> 77.208259 | AD11: =+AC11-AB11 -> -2.2609414 | AE11: =+H11/100 -> 93.952205 | AF11: =+AC11-AE11 -> -16.743947 | AG11: =+J11/100 -> 774.13543 | AH11: =+K11/100 -> 779.32391 | AI11: =+AH11-AG11 -> 5.188479 | AJ11: =+M11/100 -> 850.26684 | AK11: =+AH11-AJ11 -> -70.942927
D12: 골재 | E12: =+'[1]9월'!$AE$8/1000 -> 2060.2702 | F12: =+'[2]9월'!$AN$8/1000 -> 885.7455 | G12: =+F12-E12 -> -1174.5247 | H12: =+'[3]9월'!$AN$8/1000 -> 1574.946 | I12: =+F12-H12 -> -689.2005 | J12: =+[4]손익총괄!J12+E12 -> 16342.766 | K12: =+[4]손익총괄!K12+F12 -> 13129.786 | L12: =+K12-J12 -> -3212.9805 | M12: =+[4]손익총괄!M12+H12 -> 11005.93 | N12: =+K12-M12 -> 2123.8557 | Q12: 계 | S12: =SUM(S9:S11) -> 288.5 | T12: =SUM(T9:T11) -> 236.2843 | U12: =+T12-S12 -> -52.2157 | V12: =SUM(V9:V11) -> 315.1905 | W12: =+T12-V12 -> -78.9062 | AA12: =+D12 -> 골재 | AB12: =+E12/100 -> 20.602702 | AC12: =+F12/100 -> 8.857455 | AD12: =+AC12-AB12 -> -11.745247 | AE12: =+H12/100 -> 15.74946 | AF12: =+AC12-AE12 -> -6.892005 | AG12: =+J12/100 -> 163.42766 | AH12: =+K12/100 -> 131.29786 | AI12: =+AH12-AG12 -> -32.129805 | AJ12: =+M12/100 -> 110.0593 | AK12: =+AH12-AJ12 -> 21.238557
D13: 기타 | E13: =+'[1]9월'!$E$8/1000-E10-E11-E12 -> 165.5075 | F13: =+'[2]9월'!$F$8/1000-F10-F11-F12 -> 165.97438 | G13: =+F13-E13 -> 0.46688067 | H13: =+'[3]9월'!$F$8/1000-H10-H11-H12 -> 185.37696 | I13: =+F13-H13 -> -19.402583 | J13: =+[4]손익총괄!J13+E13 -> 1484.7675 | K13: =+[4]손익총괄!K13+F13 -> 1489.8753 | L13: =+K13-J13 -> 5.107838 | M13: =+[4]손익총괄!M13+H13 -> 1769.7096 | N13: =+K13-M13 -> -279.83427 | Q13: 판매단가 | R13: 수도권 | S13: =+[5]수도권!$T$61 -> 100857.87 | T13: =+[5]수도권!$U$61 -> 97749.491 | U13: =+T13-S13 -> -3108.3753 | V13: =+[6]수도권!$Q$85 -> 96078.533 | W13: =+T13-V13 -> 1670.9581 | AA13: =+D13 -> 기타 | AB13: =+E13/100 -> 1.655075 | AC13: =+F13/100 -> 1.6597438 | AD13: =+AC13-AB13 -> 0.0046688067 | AE13: =+H13/100 -> 1.8537696 | AF13: =+AC13-AE13 -> -0.19402583 | AG13: =+J13/100 -> 14.847675 | AH13: =+K13/100 -> 14.898753 | AI13: =+AH13-AG13 -> 0.05107838 | AJ13: =+M13/100 -> 17.697096 | AK13: =+AH13-AJ13 -> -2.7983427
A14: =+F14/E14 -> 0.81559874 | B14: =+K14/J14 -> 0.98121211 | C14: 계 | E14: =SUM(E10:E13) -> 39715.508 | F14: =SUM(F10:F13) -> 32391.918 | G14: =+F14-E14 -> -7323.5895 | H14: =SUM(H10:H13) -> 42187.034 | I14: =+F14-H14 -> -9795.1153 | J14: =SUM(J10:J13) -> 355016.37 | K14: =SUM(K10:K13) -> 348346.36 | L14: =+K14-J14 -> -6670.0094 | M14: =SUM(M10:M13) -> 372841.74 | N14: =+K14-M14 -> -24495.376 | R14: 영남권 | S14: =+[5]영남권!$T$61 -> 102384.24 | T14: =+[5]영남권!$U$61 -> 99624.762 | U14: =+T14-S14 -> -2759.4818 | V14: =+[6]영남권!$Q$85 -> 99478.73 | W14: =+T14-V14 -> 146.03201 | AA14: 계 | AB14: =SUM(AB10:AB13) -> 397.15508 | AC14: =SUM(AC10:AC13) -> 323.91918 | AD14: =+AC14-AB14 -> -73.235895 | AE14: =SUM(AE10:AE13) -> 421.87034 | AF14: =+AC14-AE14 -> -97.951153 | AG14: =SUM(AG10:AG13) -> 3550.1637 | AH14: =SUM(AH10:AH13) -> 3483.4636 | AI14: =+AH14-AG14 -> -66.700094 | AJ14: =SUM(AJ10:AJ13) -> 3728.4174 | AK14: =+AH14-AJ14 -> -244.95376
C15: 매출원가 | D15: 레미콘 | E15: =+('[1]9월'!$Z$10+'[1]9월'!$Z$19)/1000 -> 24354.331 | F15: =+('[2]9월'!$Z$10+'[2]9월'!$Z$19)/1000 -> 21000.008 | G15: =+F15-E15 -> -3354.3223 | H15: =+('[3]9월'!$Z$10+'[3]9월'!$Z$19)/1000 -> 26312.29 | I15: =+F15-H15 -> -5312.2815 | J15: =+[4]손익총괄!J15+E15 -> 217045.15 | K15: =+[4]손익총괄!K15+F15 -> 221505 | L15: =+K15-J15 -> 4459.8443 | M15: =+[4]손익총괄!M15+H15 -> 227018.01 | N15: =+K15-M15 -> -5513.011 | R15: 중부권 | S15: =+[5]중부권!$T$61 -> 105712.51 | T15: =+[5]중부권!$U$61 -> 104305.46 | U15: =+T15-S15 -> -1407.0476 | V15: =+[6]중부권!$Q$85 -> 101710.77 | W15: =+T15-V15 -> 2594.6916 | Z15: 영업이익 | AA15: =+D30 -> 레미콘 | AB15: =+E30/100 -> 44.5541 | AC15: =+F30/100 -> 17.327354 | AD15: =+AC15-AB15 -> -27.226747 | AE15: =+H30/100 -> 38.397991 | AF15: =+AC15-AE15 -> -21.070637 | AG15: =+J30/100 -> 367.54774 | AH15: =+K30/100 -> 281.31865 | AI15: =+AH15-AG15 -> -86.229083 | AJ15: =+M30/100 -> 419.59065 | AK15: =+AH15-AJ15 -> -138.27199
D16: 건자재 | E16: =+('[1]9월'!$AA$10+'[1]9월'!$AA$19)/1000 -> 7743.493 | F16: =+('[2]9월'!$AO$10+'[2]9월'!$AO$19)/1000 -> 7575.1952 | G16: =+F16-E16 -> -168.29778 | H16: =+('[3]9월'!$AO$10+'[3]9월'!$AO$19)/1000 -> 9237.9614 | I16: =+F16-H16 -> -1662.7662 | J16: =+[4]손익총괄!J16+E16 -> 75433.104 | K16: =+[4]손익총괄!K16+F16 -> 76231.984 | L16: =+K16-J16 -> 798.87993 | M16: =+[4]손익총괄!M16+H16 -> 83260.913 | N16: =+K16-M16 -> -7028.9291 | Q16: 계 | S16: =+[5]합계!$T$61 -> 102401.42 | T16: =+[5]합계!$U$61 -> 99989.728 | U16: =+T16-S16 -> -2411.6936 | V16: =+[6]합계!$Q$85 -> 98458.403 | W16: =+T16-V16 -> 1531.3252 | AA16: =+D31 -> % | AB16: =+E31 -> 0.15081199 | AC16: =+F31 -> 0.073360771 | AD16: =+AC16-AB16 -> -0.07745122 | AE16: =+H31 -> 0.12373879 | AF16: =+AC16-AE16 -> -0.050378021 | AG16: =+J31 -> 0.14148679 | AH16: =+K31 -> 0.10997846 | AI16: =+AH16-AG16 -> -0.03150833 | AJ16: =+M31 -> 0.15255655 | AK16: =+AH16-AJ16 -> -0.042578087
D17: 골재 | E17: =+('[1]9월'!$AE$10+'[1]9월'!$AE$19)/1000 -> 1882.0209 | F17: =+('[2]9월'!$AN$10+'[2]9월'!$AN$19)/1000 -> 1111.2439 | G17: =+F17-E17 -> -770.77697 | H17: =+('[3]9월'!$AN$10+'[3]9월'!$AN$19)/1000 -> 1410.8989 | I17: =+F17-H17 -> -299.65496 | J17: =+[4]손익총괄!J17+E17 -> 14616.921 | K17: =+[4]손익총괄!K17+F17 -> 12454.683 | L17: =+K17-J17 -> -2162.2383 | M17: =+[4]손익총괄!M17+H17 -> 10102.539 | N17: =+K17-M17 -> 2352.1444 | Q17: 공헌이익 | R17: 수도권 | S17: =+[5]수도권!$Q$90 -> 22962.077 | T17: =+[5]수도권!$R$90 -> 18269.6 | U17: =+T17-S17 -> -4692.4774 | V17: =+[6]수도권!$Q$90 -> 21001.054 | W17: =+T17-V17 -> -2731.4542 | AA17: =+D32 -> 건자재 | AB17: =+E32/100 -> 0.60891698 | AC17: =+F32/100 -> -0.15579202 | AD17: =+AC17-AB17 -> -0.764709 | AE17: =+H32/100 -> -0.01565119 | AF17: =+AC17-AE17 -> -0.14014083 | AG17: =+J32/100 -> 8.3987082 | AH17: =+K32/100 -> 4.3949837 | AI17: =+AH17-AG17 -> -4.0037245 | AJ17: =+M32/100 -> 6.8476885 | AK17: =+AH17-AJ17 -> -2.4527048
D18: 기타 | E18: =+('[1]9월'!$E$10+'[1]9월'!$E$19)/1000-E15-E16-E17 -> 49.502087 | F18: =+('[2]9월'!$F$10+'[2]9월'!$F$19)/1000-F15-F16-F17 -> -238.70688 | G18: =+F18-E18 -> -288.20897 | H18: =+('[3]9월'!$F$10+'[3]9월'!$F$19)/1000-H15-H16-H17 -> 70.270941 | I18: =+F18-H18 -> -308.97783 | J18: =+[4]손익총괄!J18+E18 -> -800.57411 | K18: =+[4]손익총괄!K18+F18 -> -109.09169 | L18: =+K18-J18 -> 691.48242 | M18: =+[4]손익총괄!M18+H18 -> 528.23183 | N18: =+K18-M18 -> -637.32352 | R18: 영남권 | S18: =+[5]영남권!$Q$90 -> 27391.945 | T18: =+[5]영남권!$R$90 -> 22140.925 | U18: =+T18-S18 -> -5251.0201 | V18: =+[6]영남권!$Q$90 -> 22761.378 | W18: =+T18-V18 -> -620.45339 | AA18: =+D33 -> 골재 | AB18: =+E33/100 -> 1.3976456 | AC18: =+F33/100 -> -3.129805 | AD18: =+AC18-AB18 -> -4.5274506 | AE18: =+H33/100 -> 1.5089158 | AF18: =+AC18-AE18 -> -4.6387208 | AG18: =+J33/100 -> 12.139154 | AH18: =+K33/100 -> 1.459626 | AI18: =+AH18-AG18 -> -10.679528 | AJ18: =+M33/100 -> 6.2177408 | AK18: =+AH18-AJ18 -> -4.7581148
C19: 계 | E19: =SUM(E15:E18) -> 34029.347 | F19: =SUM(F15:F18) -> 29447.741 | G19: =+F19-E19 -> -4581.606 | H19: =SUM(H15:H18) -> 37031.421 | I19: =+F19-H19 -> -7583.6805 | J19: =SUM(J15:J18) -> 306294.6 | K19: =SUM(K15:K18) -> 310082.57 | L19: =+K19-J19 -> 3787.9683 | M19: =SUM(M15:M18) -> 320909.69 | N19: =+K19-M19 -> -10827.119 | R19: 중부권 | S19: =+[5]중부권!$Q$90 -> 29279.352 | T19: =+[5]중부권!$R$90 -> 29079.27 | U19: =+T19-S19 -> -200.08169 | V19: =+[6]중부권!$Q$90 -> 27401.312 | W19: =+T19-V19 -> 1677.9584 | AA19: 공통비 | AB19: =+'사업장별(당월)'!T35/100 -> -11.572821 | AC19: =+'사업장별(당월)'!U35/100 -> -13.686461 | AD19: =+AC19-AB19 -> -2.1136396 | AE19: =+'사업장별(당월)'!W35/100 -> -12.173342 | AF19: =+AC19-AE19 -> -1.5131189 | AG19: =+'사업장별(누계)'!T35/100 -> -125.58532 | AH19: =+'사업장별(누계)'!U35/100 -> -128.91839 | AI19: =+AH19-AG19 -> -3.3330625 | AJ19: =+'사업장별(누계)'!W35/100 -> -105.12685 | AK19: =+AH19-AJ19 -> -23.791541
C20: 매출이익 | D20: 레미콘 | E20: =+E10-E15 -> 5188.4795 | F20: =+F10-F15 -> 2619.3642 | G20: =+F20-E20 -> -2569.1153 | H20: =+H10-H15 -> 4719.2002 | I20: =+F20-H20 -> -2099.836 | J20: =+J10-J15 -> 42730.141 | K20: =+K10-K15 -> 34289.312 | L20: =+K20-J20 -> -8440.8289 | M20: =+M10-M15 -> 48021.406 | N20: =+K20-M20 -> -13732.094 | Q20: 계 | S20: =+[5]합계!$Q$90 -> 25987.093 | T20: =+[5]합계!$R$90 -> 22332.224 | U20: =+T20-S20 -> -3654.8687 | V20: =+[6]합계!$Q$90 -> 22815.466 | W20: =+T20-V20 -> -483.24211 | AA20: =+'사업장별(누계)'!I34 -> 임대 | AB20: =+('사업장별(당월)'!T33+'사업장별(당월)'!T34)/100 -> 1.5064324 | AC20: =+('사업장별(당월)'!U33+'사업장별(당월)'!U34)/100 -> 1.5179422 | AD20: =+AC20-AB20 -> 0.011509737 | AE20: =+('사업장별(당월)'!W33+'사업장별(당월)'!W34)/100 -> 1.2963562 | AF20: =+AC20-AE20 -> 0.22158598 | AG20: =+('사업장별(누계)'!T33+'사업장별(누계)'!T34)/100 -> 11.945664 | AH20: =+('사업장별(누계)'!U33+'사업장별(누계)'!U34)/100 -> 11.601896 | AI20: =+AH20-AG20 -> -0.34376874 | AJ20: =+('사업장별(누계)'!W33+'사업장별(누계)'!W34)/100 -> 10.625007 | AK20: =+AH20-AJ20 -> 0.97688802
D21: 건자재 | E21: =+E11-E16 -> 203.42698 | F21: =+F11-F16 -> 145.63062 | G21: =+F21-E21 -> -57.796361 | H21: =+H11-H16 -> 157.25911 | I21: =+F21-H21 -> -11.628488 | J21: =+J11-J16 -> 1980.4389 | K21: =+K11-K16 -> 1700.4069 | L21: =+K21-J21 -> -280.03203 | M21: =+M11-M16 -> 1765.7706 | N21: =+K21-M21 -> -65.363661 | Q21: □ 건자재 | AA21: =+'사업장별(누계)'!I37 -> 대손 | AB21: =+'사업장별(당월)'!T37/100 -> 0 | AC21: =+'사업장별(당월)'!U37/100 -> 4.0164838 | AD21: =+AC21-AB21 -> 4.0164838 | AE21: =+'사업장별(당월)'!W37/100 -> -7.7615284 | AF21: =+AC21-AE21 -> 11.778012 | AG21: =+'사업장별(누계)'!T37/100 -> 0 | AH21: =+'사업장별(누계)'!U37/100 -> -5.7385933 | AI21: =+AH21-AG21 -> -5.7385933 | AJ21: =+'사업장별(누계)'!W37/100 -> -20.23222 | AK21: =+AH21-AJ21 -> 14.493626
D22: 골재 | E22: =+E12-E17 -> 178.24931 | F22: =+F12-F17 -> -225.49843 | G22: =+F22-E22 -> -403.74775 | H22: =+H12-H17 -> 164.0471 | I22: =+F22-H22 -> -389.54554 | J22: =+J12-J17 -> 1725.8448 | K22: =+K12-K17 -> 675.10268 | L22: =+K22-J22 -> -1050.7422 | M22: =+M12-M17 -> 903.39137 | N22: =+K22-M22 -> -228.28869 | Q22: 구분 | S22: 계획 | T22: 실적 | U22: 계획대비 | V22: 전년 | W22: 전년대비 | AA22: =+D34 -> 기타 | AB22: =+AB26-AB19-AB20-AB21 -> -0.71446467 | AC22: =+AC26-AC19-AC20-AC21 -> 2.4069496 | AD22: =+AC22-AB22 -> 3.1214142 | AE22: =+AE26-AE19-AE20-AE21 -> -0.60571538 | AF22: =+AC22-AE22 -> 3.0126649 | AG22: =+AG26-AG19-AG20-AG21 -> 5.0469916 | AH22: =+AH26-AH19-AH20-AH21 -> -0.38952684 | AI22: =+AH22-AG22 -> -5.4365184 | AJ22: =+AJ26-AJ19-AJ20-AJ21 -> -3.2633879 | AK22: =+AH22-AJ22 -> 2.8738611
D23: 기타 | E23: =+E13-E18 -> 116.00541 | F23: =+F13-F18 -> 404.68127 | G23: =+F23-E23 -> 288.67585 | H23: =+H13-H18 -> 115.10602 | I23: =+F23-H23 -> 289.57524 | J23: =+J13-J18 -> 2285.3416 | K23: =+K13-K18 -> 1598.967 | L23: =+K23-J23 -> -686.37458 | M23: =+M13-M18 -> 1241.4778 | N23: =+K23-M23 -> 357.48925 | Q23: 철강재 판매단가 | S23: =+'[7]9월'!$F$10 -> 977692.31 | T23: =+'[7]9월'!$G$10 -> 879572.43 | U23: =+T23-S23 -> -98119.878 | V23: =+'[8]9월'!$G$10 -> 1007624.2 | W23: =+T23-V23 -> -128051.75 | AA23: 계 | AB23: =SUM(AB15,AB17:AB22) -> 35.77981 | AC23: =SUM(AC15,AC17:AC22) -> 8.2966716 | AD23: =+AC23-AB23 -> -27.483138 | AE23: =SUM(AE15,AE17:AE22) -> 20.647026 | AF23: =+AC23-AE23 -> -12.350354 | AG23: =SUM(AG15,AG17:AG22) -> 279.49293 | AH23: =SUM(AH15,AH17:AH22) -> 163.72865 | AI23: =+AH23-AG23 -> -115.76428 | AJ23: =SUM(AJ15,AJ17:AJ22) -> 314.65863 | AK23: =+AH23-AJ23 -> -150.92998
C24: 계 | E24: =SUM(E20:E23) -> 5686.1612 | F24: =SUM(F20:F23) -> 2944.1777 | G24: =+F24-E24 -> -2741.9835 | H24: =SUM(H20:H23) -> 5155.6125 | I24: =+F24-H24 -> -2211.4348 | J24: =SUM(J20:J23) -> 48721.766 | K24: =SUM(K20:K23) -> 38263.789 | L24: =+K24-J24 -> -10457.978 | M24: =SUM(M20:M23) -> 51932.046 | N24: =+K24-M24 -> -13668.257 | Q24: 철강재 마진률 | S24: =+'[7]9월'!$F$15 -> 0.02329819 | T24: =+'[7]9월'!$G$15 -> 0.017454463 | U24: =+T24-S24 -> -0.0058437274 | V24: =+'[8]9월'!$G$15 -> 0.014432643 | W24: =+T24-V24 -> 0.0030218199 | AA24: =+D36 -> % | AB24: =+E36 -> 0.090090273 | AC24: =+F36 -> 0.0256134 | AD24: =+G36 -> -0.064476873 | AE24: =+H36 -> 0.04894164 | AF24: =+I36 -> -0.02332824 | AG24: =+J36 -> 0.078726772 | AH24: =+K36 -> 0.047001683 | ... AK24: =+N36 -> -0.037393008
C25: 판관비 | D25: 레미콘 | E25: =+('[1]9월'!$Z$13+'[1]9월'!$Z$20)/1000 -> 733.06945 | F25: =+('[2]9월'!$Z$13+'[2]9월'!$Z$20)/1000 -> 886.62886 | G25: =+F25-E25 -> 153.5594 | H25: =+('[3]9월'!$Z$13+'[3]9월'!$Z$20)/1000 -> 879.40115 | I25: =+F25-H25 -> 7.227701 | J25: =+[4]손익총괄!J25+E25 -> 5975.3673 | K25: =+[4]손익총괄!K25+F25 -> 6157.4466 | L25: =+K25-J25 -> 182.07935 | M25: =+[4]손익총괄!M25+H25 -> 6062.3414 | N25: =+K25-M25 -> 95.105216 | Q25: □ 골재
D26: 건자재 | E26: =+('[1]9월'!$AA$13+'[1]9월'!$AA$20)/1000 -> 142.53528 | F26: =+('[2]9월'!$AO$13+'[2]9월'!$AO$20)/1000 -> 161.20982 | G26: =+F26-E26 -> 18.674539 | H26: =+('[3]9월'!$AO$13+'[3]9월'!$AO$20)/1000 -> 158.82422 | I26: =+F26-H26 -> 2.385595 | J26: =+[4]손익총괄!J26+E26 -> 1140.5681 | K26: =+[4]손익총괄!K26+F26 -> 1260.9085 | L26: =+K26-J26 -> 120.34042 | M26: =+[4]손익총괄!M26+H26 -> 1081.0017 | N26: =+K26-M26 -> 179.90681 | Q26: 구분 | S26: 계획 | T26: 실적 | U26: 계획대비 | V26: 전년 | W26: 전년대비 | AB26: =+'사업장별(당월)'!T41/100 -> -10.780853 | AC26: =+'사업장별(당월)'!U41/100 -> -5.7450853 | AD26: =+AC26-AB26 -> 5.0357682 | AE26: =+'사업장별(당월)'!W41/100 -> -19.24423 | AF26: =+AE26-AD26 -> -24.279998 | AG26: =+'사업장별(누계)'!T41/100 -> -108.59267 | AH26: =+'사업장별(누계)'!U41/100 -> -123.44461 | AJ26: =+'사업장별(누계)'!W41/100 -> -117.99745
D27: 골재 | E27: =+('[1]9월'!$AE$13+'[1]9월'!$AE$20+'[1]9월'!$AE$22)/1000 -> 38.48475 | F27: =+('[2]9월'!$AN$13+'[2]9월'!$AN$20+'[2]9월'!$AN$22)/1000 -> 87.482063 | G27: =+F27-E27 -> 48.997313 | H27: =+('[3]9월'!$AN$13+'[3]9월'!$AN$20+'[3]9월'!$AN$22)/1000 -> 13.155517 | I27: =+F27-H27 -> 74.326546 | J27: =+[4]손익총괄!J27+E27 -> 511.92944 | K27: =+[4]손익총괄!K27+F27 -> 529.14008 | L27: =+K27-J27 -> 17.21065 | M27: =+[4]손익총괄!M27+H27 -> 281.61729 | N27: =+K27-M27 -> 247.52279 | Q27: 판매량 | R27: 자가 | S27: =(+'[9]서부산크라샤(당월)'!$N$66+'[9]부산모래장(당월)'!$Q$48+'[9]부산크라샤(당월)'!$N$66)/1000 -> 52.497735 | T27: =(+'[9]서부산크라샤(당월)'!$O$66+'[9]부산모래장(당월)'!$R$48+'[9]부산크라샤(당월)'!$O$66)/1000 -> 32.178 | U27: =+T27-S27 -> -20.319735 | V27: =('[10]부산골재(당월)'!$R$48+'[10]서부산골재(당월)'!$O$66+'[10]부산크라샤(당월)'!$O$66)/1000 -> 51.902 | W27: =+T27-V27 -> -19.724
D28: 기타 | E28: =+('[1]9월'!$E$13+'[1]9월'!$E$20)/1000-E25-E26-E27+('[1]9월'!$E$22/1000) -> 1194.0908 | F28: =+('[2]9월'!$F$13+'[2]9월'!$F$20)/1000-F25-F26-F27+'[2]9월'!$F$22/1000 -> 979.18979 | G28: =+F28-E28 -> -214.90096 | H28: =+('[3]9월'!$F$13+'[3]9월'!$F$20)/1000-H25-H26-H27+'[3]9월'!$F$22/1000 -> 2039.529 | I28: =+F28-H28 -> -1060.3392 | J28: =+[4]손익총괄!J28+E28 -> 13144.608 | K28: =+[4]손익총괄!K28+F28 -> 13943.428 | L28: =+K28-J28 -> 798.81972 | M28: =+[4]손익총괄!M28+H28 -> 13041.222 | N28: =+K28-M28 -> 902.2058 | R28: 외판 | S28: =(+'[9]서부산크라샤(당월)'!$N$59+'[9]부산모래장(당월)'!$Q$47+'[9]부산크라샤(당월)'!$N$59)/1000 -> 61.8 | T28: =(+'[9]서부산크라샤(당월)'!$O$59+'[9]부산모래장(당월)'!$R$47+'[9]부산크라샤(당월)'!$O$59)/1000 -> 14.773 | U28: =+T28-S28 -> -47.027 | V28: =+('[10]부산골재(당월)'!$R$47+'[10]서부산골재(당월)'!$O$59+'[10]부산크라샤(당월)'!$O$59)/1000 -> 30.007 | W28: =+T28-V28 -> -15.234
C29: 계 | E29: =SUM(E25:E28) -> 2108.1802 | F29: =SUM(F25:F28) -> 2114.5105 | G29: =+F29-E29 -> 6.3302893 | H29: =SUM(H25:H28) -> 3090.9099 | I29: =+F29-H29 -> -976.39934 | J29: =SUM(J25:J28) -> 20772.473 | K29: =SUM(K25:K28) -> 21890.923 | L29: =+K29-J29 -> 1118.4501 | M29: =SUM(M25:M28) -> 20466.183 | N29: =+K29-M29 -> 1424.7406 | Q29: 합 계 | S29: =SUM(S27:S28) -> 114.29774 | T29: =SUM(T27:T28) -> 46.951 | U29: =+T29-S29 -> -67.346735 | V29: =SUM(V27:V28) -> 81.909 | W29: =+T29-V29 -> -34.958
C30: 영업이익 | D30: 레미콘 | E30: =+E20-E25 -> 4455.41 | F30: =+F20-F25 -> 1732.7354 | G30: =+F30-E30 -> -2722.6747 | H30: =+H20-H25 -> 3839.7991 | I30: =+F30-H30 -> -2107.0637 | J30: =+J20-J25 -> 36754.774 | K30: =+K20-K25 -> 28131.865 | L30: =+K30-J30 -> -8622.9083 | M30: =+M20-M25 -> 41959.065 | N30: =+K30-M30 -> -13827.199 | Q30: □ 기타내역(영업이익)
D31: % | E31: =+E30/E10 -> 0.15081199 | F31: =+F30/F10 -> 0.073360771 | G31: =+F31-E31 -> -0.07745122 | H31: =+H30/H10 -> 0.12373879 | I31: =+F31-H31 -> -0.050378021 | J31: =+J30/J10 -> 0.14148679 | K31: =+K30/K10 -> 0.10997846 | L31: =+K31-J31 -> -0.03150833 | M31: =+M30/M10 -> 0.15255655 | N31: =+K31-M31 -> -0.042578087 | Q31: 구분 | S31: 계획 | T31: 실적 | U31: 계획대비 | V31: 전년 | W31: 전년대비
D32: 건자재 | E32: =+E21-E26 -> 60.891698 | F32: =+F21-F26 -> -15.579202 | G32: =+F32-E32 -> -76.4709 | H32: =+H21-H26 -> -1.565119 | I32: =+F32-H32 -> -14.014083 | J32: =+J21-J26 -> 839.87082 | K32: =+K21-K26 -> 439.49837 | L32: =+K32-J32 -> -400.37245 | M32: =+M21-M26 -> 684.76885 | N32: =+K32-M32 -> -245.27048 | Q32: 레미콘임대 | S32: =+'사업장별(당월)'!T33 -> 75.404842 | T32: =+'사업장별(당월)'!U33 -> 76.004227 | U32: =+T32-S32 -> 0.599385 | V32: =+'사업장별(당월)'!W33 -> 30.418728 | W32: =+T32-V32 -> 45.585499
D33: 골재 | E33: =+E22-E27 -> 139.76456 | F33: =+F22-F27 -> -312.9805 | G33: =+F33-E33 -> -452.74506 | H33: =+H22-H27 -> 150.89158 | I33: =+F33-H33 -> -463.87208 | J33: =+J22-J27 -> 1213.9154 | K33: =+K22-K27 -> 145.9626 | L33: =+K33-J33 -> -1067.9528 | M33: =+M22-M27 -> 621.77408 | N33: =+K33-M33 -> -475.81148 | Q33: 임대 | S33: =+'사업장별(당월)'!T34 -> 75.238401 | T33: =+'사업장별(당월)'!U34 -> 75.78999 | U33: =+T33-S33 -> 0.55158867 | V33: =+'사업장별(당월)'!W34 -> 99.216891 | W33: =+T33-V33 -> -23.426901
D34: 기타 | E34: =+E23-E28 -> -1078.0853 | F34: =+F23-F28 -> -574.50853 | G34: =+F34-E34 -> 503.57682 | H34: =+H23-H28 -> -1924.423 | I34: =+F34-H34 -> 1349.9144 | J34: =+J23-J28 -> -10859.267 | K34: =+K23-K28 -> -12344.461 | L34: =+K34-J34 -> -1485.1943 | M34: =+M23-M28 -> -11799.745 | N34: =+K34-M34 -> -544.71655 | Q34: 공통비 | S34: =+'사업장별(당월)'!T35 -> -1157.2821 | T34: =+'사업장별(당월)'!U35 -> -1368.6461 | U34: =+T34-S34 -> -211.36396 | V34: =+'사업장별(당월)'!W35 -> -1217.3342 | W34: =+T34-V34 -> -151.31189
C35: 계 | E35: =SUM(E30,E32:E34) -> 3577.981 | F35: =SUM(F30,F32:F34) -> 829.66716 | G35: =+F35-E35 -> -2748.3138 | H35: =SUM(H30,H32:H34) -> 2064.7026 | I35: =+F35-H35 -> -1235.0354 | J35: =SUM(J30,J32:J34) -> 27949.293 | K35: =SUM(K30,K32:K34) -> 16372.865 | L35: =+K35-J35 -> -11576.428 | M35: =SUM(M30,M32:M34) -> 31465.863 | N35: =+K35-M35 -> -15092.998 | Q35: 기타 | S35: =+S36-S32-S33-S34 -> -71.446467 | T35: =+T36-T32-T33-T34 -> 642.34334 | U35: =+T35-S35 -> 713.78981 | V35: =+V36-V32-V33-V34 -> -836.72438 | W35: =+T35-V35 -> 1479.0677
D36: % | E36: =+E35/E14 -> 0.090090273 | F36: =+F35/F14 -> 0.0256134 | G36: =+F36-E36 -> -0.064476873 | H36: =+H35/H14 -> 0.04894164 | I36: =+F36-H36 -> -0.02332824 | J36: =+J35/J14 -> 0.078726772 | K36: =+K35/K14 -> 0.047001683 | L36: =+K36-J36 -> -0.03172509 | M36: =+M35/M14 -> 0.08439469 | N36: =+K36-M36 -> -0.037393008 | Q36: 합계 | S36: =+'사업장별(당월)'!T41 -> -1078.0853 | T36: =+'사업장별(당월)'!U41 -> -574.50853 | U36: =+T36-S36 -> 503.57682 | V36: =+'사업장별(당월)'!W41 -> -1924.423 | W36: =+T36-V36 -> 1349.9144
E38: =+'[1]9월'!$E$26/1000 -> 3577.981 | F38: =+'[2]9월'!$F$26/1000 -> 829.66716 | H38: =+'[3]9월'!$F$26/1000 -> 2064.7026 | J38: =+[4]손익총괄!J38+E38 -> 27949.293 | K38: =+[4]손익총괄!K38+F38 -> 16372.865 | M38: =+[4]손익총괄!M38+H38 -> 31465.863
E39: =+E35=E38 -> TRUE | F39: =+F35=F38 -> FALSE | H39: =+H35=H38 -> TRUE | J39: =+J35=J38 -> TRUE | K39: =+K35=K38 -> FALSE | M39: =+M35=M38 -> TRUE
E40: =+E35-E38 -> 0 | F40: =+F35-F38 -> 3.4106051e-12 | H40: =+H35-H38 -> 4.5474735e-12 | J40: =+J35-J38 -> 0 | K40: =+K35-K38 -> -3.6379788e-11 | M40: =+M35-M38 -> 0

Sheet 사업장별(당월)
H3: □ 사업장별 손익실적(2024-09)
AG4: [단위 : 천㎥, 톤, 백만원]
H5: 구분 | J5: 물량 | O5: 매출 | T5: 영업이익(공통비 배부전) | Y5: 판매단가 | AB5: 변동비 | AE5: 공헌이익
J6: 계획 | K6: 실적 | L6: 차이 | M6: 전년 | N6: 차이 | O6: 계획 | P6: 실적 | Q6: 차이 | R6: 전년 | S6: 차이 | T6: 계획 | U6: 실적 | V6: 차이 | W6: 전년 | X6: 차이 | Y6: 계획 | Z6: 실적 | AA6: 전년 | AB6: 계획 | AC6: 실적 | AD6: 전년 | AE6: 계획 | AF6: 실적 | AG6: 전년
B7: 안양 | G7: =+I7 -> 안양 | H7: 레미콘 | I7: 안양 | J7: =+IFERROR(HLOOKUP($B7,'[1]9월'!$D$6:$BN$259,2,),)/1000 -> 44 | K7: =+IFERROR(HLOOKUP($B7,'[2]9월'!$F$6:$CP$99,2,),)/1000 -> 28.4 | L7: =+K7-J7 -> -15.6 | M7: =+IFERROR(HLOOKUP($B7,'[3]9월'!$F$6:$CC$57,2,),)/1000 -> 48.184 | N7: =+K7-M7 -> -19.784 | O7: =+IFERROR(HLOOKUP($B7,'[1]9월'!$D$6:$BN$259,3,),)/1000 -> 4453.4734 | P7: =+IFERROR(HLOOKUP($B7,'[2]9월'!$F$6:$CP$99,3,),)/1000 -> 2850.3839 | Q7: =+P7-O7 -> -1603.0895 | R7: =+IFERROR(HLOOKUP($B7,'[3]9월'!$F$6:$CC$57,3,),)/1000 -> 4539.9433 | S7: =+P7-R7 -> -1689.5594 | T7: =+IFERROR(HLOOKUP($B7,'[1]9월'!$D$6:$BN$259,16,),)/1000 -> 678.99607 | U7: =+IFERROR(HLOOKUP($B7,'[2]9월'!$F$6:$CP$99,16,),)/1000 -> 202.0324 | V7: =+U7-T7 -> -476.96367 | W7: =+IFERROR(HLOOKUP($B7,'[3]9월'!$F$6:$CC$57,16,),)/1000 -> 655.9045 | X7: =+U7-W7 -> -453.8721 | Y7: =+[5]안양!$Q$85 -> 101215.3 | Z7: =+[5]안양!$R$85 -> 100365.63 | AA7: =+[6]안양!$Q$85 -> 94220.973 | AB7: =+[5]안양!$Q$89 -> 78752.533 | AC7: =+[5]안양!$R$89 -> 81650.507 | AD7: =+[6]안양!$Q$89 -> 74023.094 | AE7: =+Y7-AB7 -> 22462.771 | AF7: =+Z7-AC7 -> 18715.124 | AG7: =+AA7-AD7 -> 20197.879
B8: 인천 | G8: =+I8 -> 인천 | H8: 직영 | I8: 인천 | J8: =+IFERROR(HLOOKUP($B8,'[1]9월'!$D$6:$BN$259,2,),)/1000 -> 30 | K8: =+IFERROR(HLOOKUP($B8,'[2]9월'!$F$6:$CP$99,2,),)/1000 -> 18.327 | L8: =+K8-J8 -> -11.673 | M8: =+IFERROR(HLOOKUP($B8,'[3]9월'!$F$6:$CC$57,2,),)/1000 -> 34.957 | N8: =+K8-M8 -> -16.63 | O8: =+IFERROR(HLOOKUP($B8,'[1]9월'!$D$6:$BN$259,3,),)/1000 -> 3105.3788 | P8: =+IFERROR(HLOOKUP($B8,'[2]9월'!$F$6:$CP$99,3,),)/1000 -> 1795.8147 | Q8: =+P8-O8 -> -1309.5641 | R8: =+IFERROR(HLOOKUP($B8,'[3]9월'!$F$6:$CC$57,3,),)/1000 -> 3521.2229 | S8: =+P8-R8 -> -1725.4082 | T8: =+IFERROR(HLOOKUP($B8,'[1]9월'!$D$6:$BN$259,16,),)/1000 -> 369.08346 | U8: =+IFERROR(HLOOKUP($B8,'[2]9월'!$F$6:$CP$99,16,),)/1000 -> -68.39704 | V8: =+U8-T8 -> -437.4805 | W8: =+IFERROR(HLOOKUP($B8,'[3]9월'!$F$6:$CC$57,16,),)/1000 -> 373.48538 | X8: =+U8-W8 -> -441.88242 | Y8: =+[5]인천!$Q$85 -> 103512.63 | Z8: =+[5]인천!$R$85 -> 97987.379 | AA8: =+[6]인천!$Q$85 -> 100716.91 | AB8: =+[5]인천!$Q$89 -> 80746.878 | AC8: =+[5]인천!$R$89 -> 82653.877 | AD8: =+[6]인천!$Q$89 -> 79628.745 | AE8: =+Y8-AB8 -> 22765.75 | AF8: =+Z8-AC8 -> 15333.502 | AG8: =+AA8-AD8 -> 21088.161
B9: 파주 | G9: =+I9 -> 파주 | I9: 파주 | J9: =+IFERROR(HLOOKUP($B9,'[1]9월'!$D$6:$BN$259,2,),)/1000 -> 24 | K9: =+IFERROR(HLOOKUP($B9,'[2]9월'!$F$6:$CP$99,2,),)/1000 -> 19.1078 | L9: =+K9-J9 -> -4.8922 | M9: =+IFERROR(HLOOKUP($B9,'[3]9월'!$F$6:$CC$57,2,),)/1000 -> 29.377 | N9: =+K9-M9 -> -10.2692 | O9: =+IFERROR(HLOOKUP($B9,'[1]9월'!$D$6:$BN$259,3,),)/1000 -> 2390.1945 | P9: =+IFERROR(HLOOKUP($B9,'[2]9월'!$F$6:$CP$99,3,),)/1000 -> 1803.3963 | Q9: =+P9-O9 -> -586.79821 | R9: =+IFERROR(HLOOKUP($B9,'[3]9월'!$F$6:$CC$57,3,),)/1000 -> 2809.713 | S9: =+P9-R9 -> -1006.3167 | T9: =+IFERROR(HLOOKUP($B9,'[1]9월'!$D$6:$BN$259,16,),)/1000 -> 326.54742 | U9: =+IFERROR(HLOOKUP($B9,'[2]9월'!$F$6:$CP$99,16,),)/1000 -> 106.24983 | V9: =+U9-T9 -> -220.29759 | W9: =+IFERROR(HLOOKUP($B9,'[3]9월'!$F$6:$CC$57,16,),)/1000 -> 369.05487 | X9: =+U9-W9 -> -262.80504 | Y9: =+[5]파주!$Q$85 -> 99591.438 | Z9: =+[5]파주!$R$85 -> 94365.024 | AA9: =+[6]파주!$Q$85 -> 95605.396 | AB9: =+[5]파주!$Q$89 -> 76823.007 | AC9: =+[5]파주!$R$89 -> 75826.434 | AD9: =+[6]파주!$Q$89 -> 74000.888 | AE9: =+Y9-AB9 -> 22768.432 | AF9: =+Z9-AC9 -> 18538.59 | AG9: =+AA9-AD9 -> 21604.507
B10: 김포 | G10: =+I10 -> 김포 | I10: 김포 | J10: =+IFERROR(HLOOKUP($B10,'[1]9월'!$D$6:$BN$259,2,),)/1000 -> 16.5 | K10: =+IFERROR(HLOOKUP($B10,'[2]9월'!$F$6:$CP$99,2,),)/1000 -> 9.8 | L10: =+K10-J10 -> -6.7 | M10: =+IFERROR(HLOOKUP($B10,'[3]9월'!$F$6:$CC$57,2,),)/1000 -> 17.3105 | N10: =+K10-M10 -> -7.5105 | O10: =+IFERROR(HLOOKUP($B10,'[1]9월'!$D$6:$BN$259,3,),)/1000 -> 1599.179 | P10: =+IFERROR(HLOOKUP($B10,'[2]9월'!$F$6:$CP$99,3,),)/1000 -> 943.50309 | Q10: =+P10-O10 -> -655.67591 | R10: =+IFERROR(HLOOKUP($B10,'[3]9월'!$F$6:$CC$57,3,),)/1000 -> 1606.5766 | S10: =+P10-R10 -> -663.07355 | T10: =+IFERROR(HLOOKUP($B10,'[1]9월'!$D$6:$BN$259,16,),)/1000 -> 247.00641 | U10: =+IFERROR(HLOOKUP($B10,'[2]9월'!$F$6:$CP$99,16,),)/1000 -> 29.041857 | V10: =+U10-T10 -> -217.96455 | W10: =+IFERROR(HLOOKUP($B10,'[3]9월'!$F$6:$CC$57,16,),)/1000 -> 190.04047 | X10: =+U10-W10 -> -160.99861 | Y10: =+[5]김포!$Q$85 -> 96919.939 | Z10: =+[5]김포!$R$85 -> 96275.826 | AA10: =+[6]김포!$Q$85 -> 92784.692 | AB10: =+[5]김포!$Q$89 -> 71987.752 | AC10: =+[5]김포!$R$89 -> 74300.021 | AD10: =+[6]김포!$Q$89 -> 70716.173 | AE10: =+Y10-AB10 -> 24932.187 | AF10: =+Z10-AC10 -> 21975.804 | AG10: =+AA10-AD10 -> 22068.519
B11: 부산 | G11: =+I11 -> 부산 | I11: 부산 | J11: =+IFERROR(HLOOKUP($B11,'[1]9월'!$D$6:$BN$259,2,),)/1000 -> 21 | K11: =+IFERROR(HLOOKUP($B11,'[2]9월'!$F$6:$CP$99,2,),)/1000 -> 15.517 | L11: =+K11-J11 -> -5.483 | M11: =+IFERROR(HLOOKUP($B11,'[3]9월'!$F$6:$CC$57,2,),)/1000 -> 19.603 | N11: =+K11-M11 -> -4.086 | O11: =+IFERROR(HLOOKUP($B11,'[1]9월'!$D$6:$BN$259,3,),)/1000 -> 2259.6008 | P11: =+IFERROR(HLOOKUP($B11,'[2]9월'!$F$6:$CP$99,3,),)/1000 -> 1769.7428 | Q11: =+P11-O11 -> -489.85798 | R11: =+IFERROR(HLOOKUP($B11,'[3]9월'!$F$6:$CC$57,3,),)/1000 -> 2103.7886 | S11: =+P11-R11 -> -334.04577 | T11: =+IFERROR(HLOOKUP($B11,'[1]9월'!$D$6:$BN$259,16,),)/1000 -> 359.59565 | U11: =+IFERROR(HLOOKUP($B11,'[2]9월'!$F$6:$CP$99,16,),)/1000 -> 167.22155 | V11: =+U11-T11 -> -192.3741 | W11: =+IFERROR(HLOOKUP($B11,'[3]9월'!$F$6:$CC$57,16,),)/1000 -> 197.24959 | X11: =+U11-W11 -> -30.028036 | Y11: =+[5]부산!$Q$85 -> 107600.04 | Z11: =+[5]부산!$R$85 -> 114051.87 | AA11: =+[6]부산!$Q$85 -> 107319.73 | AB11: =+[5]부산!$Q$89 -> 77875.477 | AC11: =+[5]부산!$R$89 -> 84631.159 | AD11: =+[6]부산!$Q$89 -> 82938.801 | AE11: =+Y11-AB11 -> 29724.56 | AF11: =+Z11-AC11 -> 29420.706 | AG11: =+AA11-AD11 -> 24380.924
B12: 서부산 | G12: =+I12 -> 서부산 | I12: 서부산 | J12: =+IFERROR(HLOOKUP($B12,'[1]9월'!$D$6:$BN$259,2,),)/1000 -> 19 | K12: =+IFERROR(HLOOKUP($B12,'[2]9월'!$F$6:$CP$99,2,),)/1000 -> 13.004 | L12: =+K12-J12 -> -5.996 | M12: =+IFERROR(HLOOKUP($B12,'[3]9월'!$F$6:$CC$57,2,),)/1000 -> 23.901 | N12: =+K12-M12 -> -10.897 | O12: =+IFERROR(HLOOKUP($B12,'[1]9월'!$D$6:$BN$259,3,),)/1000 -> 1983.6418 | P12: =+IFERROR(HLOOKUP($B12,'[2]9월'!$F$6:$CP$99,3,),)/1000 -> 1314.9703 | Q12: =+P12-O12 -> -668.6715 | R12: =+IFERROR(HLOOKUP($B12,'[3]9월'!$F$6:$CC$57,3,),)/1000 -> 2410.5242 | S12: =+P12-R12 -> -1095.5539 | T12: =+IFERROR(HLOOKUP($B12,'[1]9월'!$D$6:$BN$259,16,),)/1000 -> 342.28746 | U12: =+IFERROR(HLOOKUP($B12,'[2]9월'!$F$6:$CP$99,16,),)/1000 -> 84.673494 | V12: =+U12-T12 -> -257.61397 | W12: =+IFERROR(HLOOKUP($B12,'[3]9월'!$F$6:$CC$57,16,),)/1000 -> 353.41775 | X12: =+U12-W12 -> -268.74425 | Y12: =+[5]서부산!$Q$85 -> 104402.2 | Z12: =+[5]서부산!$R$85 -> 101120.45 | AA12: =+[6]서부산!$Q$85 -> 100854.53 | AB12: =+[5]서부산!$Q$89 -> 76383.589 | AC12: =+[5]서부산!$R$89 -> 78001.326 | AD12: =+[6]서부산!$Q$89 -> 77345.656 | AE12: =+Y12-AB12 -> 28018.611 | AF12: =+Z12-AC12 -> 23119.122 | AG12: =+AA12-AD12 -> 23508.877
B13: 김해 | G13: =+I13 -> 김해 | I13: 김해 | J13: =+IFERROR(HLOOKUP($B13,'[1]9월'!$D$6:$BN$259,2,),)/1000 -> 12 | K13: =+IFERROR(HLOOKUP($B13,'[2]9월'!$F$6:$CP$99,2,),)/1000 -> 12.705 | L13: =+K13-J13 -> 0.705 | M13: =+IFERROR(HLOOKUP($B13,'[3]9월'!$F$6:$CC$57,2,),)/1000 -> 12.034 | N13: =+K13-M13 -> 0.671 | O13: =+IFERROR(HLOOKUP($B13,'[1]9월'!$D$6:$BN$259,3,),)/1000 -> 1211.9928 | P13: =+IFERROR(HLOOKUP($B13,'[2]9월'!$F$6:$CP$99,3,),)/1000 -> 1134.8287 | Q13: =+P13-O13 -> -77.1641 | R13: =+IFERROR(HLOOKUP($B13,'[3]9월'!$F$6:$CC$57,3,),)/1000 -> 1216.4462 | S13: =+P13-R13 -> -81.617498 | T13: =+IFERROR(HLOOKUP($B13,'[1]9월'!$D$6:$BN$259,16,),)/1000 -> 152.09575 | U13: =+IFERROR(HLOOKUP($B13,'[2]9월'!$F$6:$CP$99,16,),)/1000 -> -2.729523 | V13: =+U13-T13 -> -154.82527 | W13: =+IFERROR(HLOOKUP($B13,'[3]9월'!$F$6:$CC$57,16,),)/1000 -> 71.200624 | X13: =+U13-W13 -> -73.930147 | Y13: =+[5]김해!$Q$85 -> 100999.4 | Z13: =+[5]김해!$R$85 -> 89286.803 | AA13: =+[6]김해!$Q$85 -> 101199.28 | AB13: =+[5]김해!$Q$89 -> 76642.298 | AC13: =+[5]김해!$R$89 -> 75888.627 | AD13: =+[6]김해!$Q$89 -> 81202.894 | AE13: =+Y13-AB13 -> 24357.102 | AF13: =+Z13-AC13 -> 13398.176 | AG13: =+AA13-AD13 -> 19996.386
B14: 정관 | G14: =+I14 -> 정관 | I14: 정관 | J14: =+IFERROR(HLOOKUP($B14,'[1]9월'!$D$6:$BN$259,2,),)/1000 -> 16 | K14: =+IFERROR(HLOOKUP($B14,'[2]9월'!$F$6:$CP$99,2,),)/1000 -> 16.976 | L14: =+K14-J14 -> 0.976 | M14: =+IFERROR(HLOOKUP($B14,'[3]9월'!$F$6:$CC$57,2,),)/1000 -> 18.982 | N14: =+K14-M14 -> -2.006 | O14: =+IFERROR(HLOOKUP($B14,'[1]9월'!$D$6:$BN$259,3,),)/1000 -> 1664 | P14: =+IFERROR(HLOOKUP($B14,'[2]9월'!$F$6:$CP$99,3,),)/1000 -> 1722.9997 | Q14: =+P14-O14 -> 58.9997 | R14: =+IFERROR(HLOOKUP($B14,'[3]9월'!$F$6:$CC$57,3,),)/1000 -> 1927.8982 | S14: =+P14-R14 -> -204.89848 | T14: =+IFERROR(HLOOKUP($B14,'[1]9월'!$D$6:$BN$259,16,),)/1000 -> 221.82233 | U14: =+IFERROR(HLOOKUP($B14,'[2]9월'!$F$6:$CP$99,16,),)/1000 -> 103.5454 | V14: =+U14-T14 -> -118.27693 | W14: =+IFERROR(HLOOKUP($B14,'[3]9월'!$F$6:$CC$57,16,),)/1000 -> 219.38573 | X14: =+U14-W14 -> -115.84033 | Y14: =+[5]정관!$Q$85 -> 104000 | Z14: =+[5]정관!$R$85 -> 101496.21 | AA14: =+[6]정관!$Q$85 -> 101564.54 | AB14: =+[5]정관!$Q$89 -> 77926.101 | AC14: =+[5]정관!$R$89 -> 81278.39 | AD14: =+[6]정관!$Q$89 -> 78824.169 | AE14: =+Y14-AB14 -> 26073.899 | AF14: =+Z14-AC14 -> 20217.822 | AG14: =+AA14-AD14 -> 22740.376
B15: 양산 | G15: =+I15 -> 양산 | I15: 양산 | J15: =+IFERROR(HLOOKUP($B15,'[1]9월'!$D$6:$BN$259,2,),)/1000 -> 12 | K15: =+IFERROR(HLOOKUP($B15,'[2]9월'!$F$6:$CP$99,2,),)/1000 -> 12.518 | L15: =+K15-J15 -> 0.518 | M15: =+IFERROR(HLOOKUP($B15,'[3]9월'!$F$6:$CC$57,2,),)/1000 -> 13.622 | N15: =+K15-M15 -> -1.104 | O15: =+IFERROR(HLOOKUP($B15,'[1]9월'!$D$6:$BN$259,3,),)/1000 -> 1166.5218 | P15: =+IFERROR(HLOOKUP($B15,'[2]9월'!$F$6:$CP$99,3,),)/1000 -> 1127.9969 | Q15: =+P15-O15 -> -38.52493 | R15: =+IFERROR(HLOOKUP($B15,'[3]9월'!$F$6:$CC$57,3,),)/1000 -> 1240.3802 | S15: =+P15-R15 -> -112.38334 | T15: =+IFERROR(HLOOKUP($B15,'[1]9월'!$D$6:$BN$259,16,),)/1000 -> 189.63512 | U15: =+IFERROR(HLOOKUP($B15,'[2]9월'!$F$6:$CP$99,16,),)/1000 -> 69.602208 | V15: =+U15-T15 -> -120.03291 | W15: =+IFERROR(HLOOKUP($B15,'[3]9월'!$F$6:$CC$57,16,),)/1000 -> 82.581045 | X15: =+U15-W15 -> -12.978837 | Y15: =+[5]양산!$Q$85 -> 97210.153 | Z15: =+[5]양산!$R$85 -> 90109.994 | AA15: =+[6]양산!$Q$85 -> 91057.131 | AB15: =+[5]양산!$Q$89 -> 69380.456 | AC15: =+[5]양산!$R$89 -> 71969.385 | AD15: =+[6]양산!$Q$89 -> 72000.401 | AE15: =+Y15-AB15 -> 27829.697 | AF15: =+Z15-AC15 -> 18140.609 | AG15: =+AA15-AD15 -> 19056.73
B16: 창원 | G16: =+I16 -> 창원 | I16: 창원 | J16: =+IFERROR(HLOOKUP($B16,'[1]9월'!$D$6:$BN$259,2,),)/1000 -> 14 | K16: =+IFERROR(HLOOKUP($B16,'[2]9월'!$F$6:$CP$99,2,),)/1000 -> 14.953 | L16: =+K16-J16 -> 0.953 | M16: =+IFERROR(HLOOKUP($B16,'[3]9월'!$F$6:$CC$57,2,),)/1000 -> 20.125 | N16: =+K16-M16 -> -5.172 | O16: =+IFERROR(HLOOKUP($B16,'[1]9월'!$D$6:$BN$259,3,),)/1000 -> 1423.73 | P16: =+IFERROR(HLOOKUP($B16,'[2]9월'!$F$6:$CP$99,3,),)/1000 -> 1507.3454 | Q16: =+P16-O16 -> 83.6154 | R16: =+IFERROR(HLOOKUP($B16,'[3]9월'!$F$6:$CC$57,3,),)/1000 -> 1973.0212 | S16: =+P16-R16 -> -465.6758 | T16: =+IFERROR(HLOOKUP($B16,'[1]9월'!$D$6:$BN$259,16,),)/1000 -> 222.23827 | U16: =+IFERROR(HLOOKUP($B16,'[2]9월'!$F$6:$CP$99,16,),)/1000 -> 152.25467 | V16: =+U16-T16 -> -69.983603 | W16: =+IFERROR(HLOOKUP($B16,'[3]9월'!$F$6:$CC$57,16,),)/1000 -> 324.44847 | X16: =+U16-W16 -> -172.19381 | Y16: =+[5]창원!$Q$85 -> 101695 | Z16: =+[5]창원!$R$85 -> 100805.55 | AA16: =+[6]창원!$Q$85 -> 98038.32 | AB16: =+[5]창원!$Q$89 -> 72711.105 | AC16: =+[5]창원!$R$89 -> 74736.793 | AD16: =+[6]창원!$Q$89 -> 71948.623 | AE16: =+Y16-AB16 -> 28983.895 | AF16: =+Z16-AC16 -> 26068.757 | AG16: =+AA16-AD16 -> 26089.697
B17: 대구 | G17: =+I17 -> 대구 | I17: 대구 | J17: =+IFERROR(HLOOKUP($B17,'[1]9월'!$D$6:$BN$259,2,),)/1000 -> 16 | K17: =+IFERROR(HLOOKUP($B17,'[2]9월'!$F$6:$CP$99,2,),)/1000 -> 14.191 | L17: =+K17-J17 -> -1.809 | M17: =+IFERROR(HLOOKUP($B17,'[3]9월'!$F$6:$CC$57,2,),)/1000 -> 17.334 | N17: =+K17-M17 -> -3.143 | O17: =+IFERROR(HLOOKUP($B17,'[1]9월'!$D$6:$BN$259,3,),)/1000 -> 1564.16 | P17: =+IFERROR(HLOOKUP($B17,'[2]9월'!$F$6:$CP$99,3,),)/1000 -> 1379.9727 | Q17: =+P17-O17 -> -184.18725 | R17: =+IFERROR(HLOOKUP($B17,'[3]9월'!$F$6:$CC$57,3,),)/1000 -> 1626.8375 | S17: =+P17-R17 -> -246.86475 | T17: =+IFERROR(HLOOKUP($B17,'[1]9월'!$D$6:$BN$259,16,),)/1000 -> 287.14697 | U17: =+IFERROR(HLOOKUP($B17,'[2]9월'!$F$6:$CP$99,16,),)/1000 -> 137.65472 | V17: =+U17-T17 -> -149.49225 | W17: =+IFERROR(HLOOKUP($B17,'[3]9월'!$F$6:$CC$57,16,),)/1000 -> 218.38418 | X17: =+U17-W17 -> -80.729456 | Y17: =+[5]대구!$Q$85 -> 97760 | Z17: =+[5]대구!$R$85 -> 97242.812 | AA17: =+[6]대구!$Q$85 -> 93852.4 | AB17: =+[5]대구!$Q$89 -> 68963.293 | AC17: =+[5]대구!$R$89 -> 72709.872 | AD17: =+[6]대구!$Q$89 -> 70301.484 | AE17: =+Y17-AB17 -> 28796.707 | AF17: =+Z17-AC17 -> 24532.94 | AG17: =+AA17-AD17 -> 23550.916
B18: 울산 | G18: =+I18 -> 울산 | I18: 울산 | J18: =+IFERROR(HLOOKUP($B18,'[1]9월'!$D$6:$BN$259,2,),)/1000 -> 10 | K18: =+IFERROR(HLOOKUP($B18,'[2]9월'!$F$6:$CP$99,2,),)/1000 -> 11.98 | L18: =+K18-J18 -> 1.98 | M18: =+IFERROR(HLOOKUP($B18,'[3]9월'!$F$6:$CC$57,2,),)/1000 -> 7.286 | N18: =+K18-M18 -> 4.694 | O18: =+IFERROR(HLOOKUP($B18,'[1]9월'!$D$6:$BN$259,3,),)/1000 -> 1012.462 | P18: =+IFERROR(HLOOKUP($B18,'[2]9월'!$F$6:$CP$99,3,),)/1000 -> 1176.1866 | Q18: =+P18-O18 -> 163.72455 | R18: =+IFERROR(HLOOKUP($B18,'[3]9월'!$F$6:$CC$57,3,),)/1000 -> 718.7467 | S18: =+P18-R18 -> 457.43985 | T18: =+IFERROR(HLOOKUP($B18,'[1]9월'!$D$6:$BN$259,16,),)/1000 -> 88.588791 | U18: =+IFERROR(HLOOKUP($B18,'[2]9월'!$F$6:$CP$99,16,),)/1000 -> 78.459948 | V18: =+U18-T18 -> -10.128843 | W18: =+IFERROR(HLOOKUP($B18,'[3]9월'!$F$6:$CC$57,16,),)/1000 -> -25.275582 | X18: =+U18-W18 -> 103.73553 | Y18: =+[5]울산!$Q$85 -> 101246.2 | Z18: =+[5]울산!$R$85 -> 98179.178 | AA18: =+[6]울산!$Q$85 -> 98714.522 | AB18: =+[5]울산!$Q$89 -> 79194.379 | AC18: =+[5]울산!$R$89 -> 78607.479 | AD18: =+[6]울산!$Q$89 -> 82398.02 | AE18: =+Y18-AB18 -> 22051.821 | AF18: =+Z18-AC18 -> 19571.699 | AG18: =+AA18-AD18 -> 16316.502
B19: 아산 | G19: =+I19 -> 아산 | I19: 아산 | J19: =+IFERROR(HLOOKUP($B19,'[1]9월'!$D$6:$BN$259,2,),)/1000 -> 25 | K19: =+IFERROR(HLOOKUP($B19,'[2]9월'!$F$6:$CP$99,2,),)/1000 -> 23.352 | L19: =+K19-J19 -> -1.648 | M19: =+IFERROR(HLOOKUP($B19,'[3]9월'!$F$6:$CC$57,2,),)/1000 -> 24.188 | N19: =+K19-M19 -> -0.836 | O19: =+IFERROR(HLOOKUP($B19,'[1]9월'!$D$6:$BN$259,3,),)/1000 -> 2525.0035 | P19: =+IFERROR(HLOOKUP($B19,'[2]9월'!$F$6:$CP$99,3,),)/1000 -> 2315.0378 | Q19: =+P19-O19 -> -209.96574 | R19: =+IFERROR(HLOOKUP($B19,'[3]9월'!$F$6:$CC$57,3,),)/1000 -> 2300.5724 | S19: =+P19-R19 -> 14.46536 | T19: =+IFERROR(HLOOKUP($B19,'[1]9월'!$D$6:$BN$259,16,),)/1000 -> 384.78619 | U19: =+IFERROR(HLOOKUP($B19,'[2]9월'!$F$6:$CP$99,16,),)/1000 -> 256.65218 | V19: =+U19-T19 -> -128.13401 | W19: =+IFERROR(HLOOKUP($B19,'[3]9월'!$F$6:$CC$57,16,),)/1000 -> 301.86837 | X19: =+U19-W19 -> -45.216184 | Y19: =+[5]아산!$Q$85 -> 101000.14 | Z19: =+[5]아산!$R$85 -> 99026.219 | AA19: =+[6]아산!$Q$85 -> 95112.138 | AB19: =+[5]아산!$Q$89 -> 76991.453 | AC19: =+[5]아산!$R$89 -> 76440.336 | AD19: =+[6]아산!$Q$89 -> 74003.769 | AE19: =+Y19-AB19 -> 24008.687 | AF19: =+Z19-AC19 -> 22585.883 | AG19: =+AA19-AD19 -> 21108.369
B20: 전주 | G20: =+I20 -> 전주 | I20: 전주 | J20: =+IFERROR(HLOOKUP($B20,'[1]9월'!$D$6:$BN$259,2,),)/1000 -> 12 | K20: =+IFERROR(HLOOKUP($B20,'[2]9월'!$F$6:$CP$99,2,),)/1000 -> 10.103 | L20: =+K20-J20 -> -1.897 | M20: =+IFERROR(HLOOKUP($B20,'[3]9월'!$F$6:$CC$57,2,),)/1000 -> 9.8575 | N20: =+K20-M20 -> 0.2455 | O20: =+IFERROR(HLOOKUP($B20,'[1]9월'!$D$6:$BN$259,3,),)/1000 -> 1228.0728 | P20: =+IFERROR(HLOOKUP($B20,'[2]9월'!$F$6:$CP$99,3,),)/1000 -> 1007.1744 | Q20: =+P20-O20 -> -220.89836 | R20: =+IFERROR(HLOOKUP($B20,'[3]9월'!$F$6:$CC$57,3,),)/1000 -> 1033.3025 | S20: =+P20-R20 -> -26.128083 | T20: =+IFERROR(HLOOKUP($B20,'[1]9월'!$D$6:$BN$259,16,),)/1000 -> 209.31453 | U20: =+IFERROR(HLOOKUP($B20,'[2]9월'!$F$6:$CP$99,16,),)/1000 -> 98.002099 | V20: =+U20-T20 -> -111.31243 | W20: =+IFERROR(HLOOKUP($B20,'[3]9월'!$F$6:$CC$57,16,),)/1000 -> 153.73999 | X20: =+U20-W20 -> -55.737895 | Y20: =+[5]전주!$Q$85 -> 102339.4 | Z20: =+[5]전주!$R$85 -> 99690.626 | AA20: =+[6]전주!$Q$85 -> 104935.93 | AB20: =+[5]전주!$Q$89 -> 72820.536 | AC20: =+[5]전주!$R$89 -> 72859.165 | AD20: =+[6]전주!$Q$89 -> 73694.536 | AE20: =+Y20-AB20 -> 29518.86 | AF20: =+Z20-AC20 -> 26831.462 | AG20: =+AA20-AD20 -> 31241.397
B21: 군산 | G21: =+I21 -> 군산 | I21: 군산 | J21: =+IFERROR(HLOOKUP($B21,'[1]9월'!$D$6:$BN$259,2,),)/1000 -> 7 | K21: =+IFERROR(HLOOKUP($B21,'[2]9월'!$F$6:$CP$99,2,),)/1000 -> 7.883 | L21: =+K21-J21 -> 0.883 | M21: =+IFERROR(HLOOKUP($B21,'[3]9월'!$F$6:$CC$57,2,),)/1000 -> 7.779 | N21: =+K21-M21 -> 0.104 | O21: =+IFERROR(HLOOKUP($B21,'[1]9월'!$D$6:$BN$259,3,),)/1000 -> 762.99903 | P21: =+IFERROR(HLOOKUP($B21,'[2]9월'!$F$6:$CP$99,3,),)/1000 -> 917.5602 | Q21: =+P21-O21 -> 154.56117 | R21: =+IFERROR(HLOOKUP($B21,'[3]9월'!$F$6:$CC$57,3,),)/1000 -> 813.60725 | S21: =+P21-R21 -> 103.95295 | T21: =+IFERROR(HLOOKUP($B21,'[1]9월'!$D$6:$BN$259,16,),)/1000 -> 200.25549 | U21: =+IFERROR(HLOOKUP($B21,'[2]9월'!$F$6:$CP$99,16,),)/1000 -> 252.01421 | V21: =+U21-T21 -> 51.758728 | W21: =+IFERROR(HLOOKUP($B21,'[3]9월'!$F$6:$CC$57,16,),)/1000 -> 185.57947 | X21: =+U21-W21 -> 66.434748 | Y21: =+[5]군산!$Q$85 -> 108999.86 | Z21: =+[5]군산!$R$85 -> 116414.49 | AA21: =+[6]군산!$Q$85 -> 104590.21 | AB21: =+[5]군산!$Q$89 -> 69834.13 | AC21: =+[5]군산!$R$89 -> 72940.628 | AD21: =+[6]군산!$Q$89 -> 70455.437 | AE21: =+Y21-AB21 -> 39165.732 | AF21: =+Z21-AC21 -> 43473.867 | AG21: =+AA21-AD21 -> 34134.774
B22: 원주 | G22: =+I22 -> 원주 | I22: 원주 | J22: =+IFERROR(HLOOKUP($B22,'[1]9월'!$D$6:$BN$259,2,),)/1000 -> 4 | K22: =+IFERROR(HLOOKUP($B22,'[2]9월'!$F$6:$CP$99,2,),)/1000 -> 5.359 | L22: =+K22-J22 -> 1.359 | M22: =+IFERROR(HLOOKUP($B22,'[3]9월'!$F$6:$CC$57,2,),)/1000 -> 4.9845 | N22: =+K22-M22 -> 0.3745 | O22: =+IFERROR(HLOOKUP($B22,'[1]9월'!$D$6:$BN$259,3,),)/1000 -> 431.6 | P22: =+IFERROR(HLOOKUP($B22,'[2]9월'!$F$6:$CP$99,3,),)/1000 -> 606.961 | Q22: =+P22-O22 -> 175.361 | R22: =+IFERROR(HLOOKUP($B22,'[3]9월'!$F$6:$CC$57,3,),)/1000 -> 508.1092 | S22: =+P22-R22 -> 98.8518 | T22: =+IFERROR(HLOOKUP($B22,'[1]9월'!$D$6:$BN$259,16,),)/1000 -> 53.146043 | U22: =+IFERROR(HLOOKUP($B22,'[2]9월'!$F$6:$CP$99,16,),)/1000 -> 107.1387 | V22: =+U22-T22 -> 53.99266 | W22: =+IFERROR(HLOOKUP($B22,'[3]9월'!$F$6:$CC$57,16,),)/1000 -> 91.645691 | X22: =+U22-W22 -> 15.493012 | Y22: =+[5]원주!$Q$85 -> 107900 | Z22: =+[5]원주!$R$85 -> 113260.12 | AA22: =+[6]원주!$Q$85 -> 101937.85 | AB22: =+[5]원주!$Q$89 -> 72986.262 | AC22: =+[5]원주!$R$89 -> 73534.477 | AD22: =+[6]원주!$Q$89 -> 65834.361 | AE22: =+Y22-AB22 -> 34913.738 | AF22: =+Z22-AC22 -> 39725.647 | AG22: =+AA22-AD22 -> 36103.486
B23: 제주 | G23: =+I23 -> 제주 | I23: 제주 | J23: =+IFERROR(HLOOKUP($B23,'[1]9월'!$D$6:$BN$259,2,),)/1000 -> 6 | K23: =+IFERROR(HLOOKUP($B23,'[2]9월'!$F$6:$CP$99,2,),)/1000 -> 2.1085 | L23: =+K23-J23 -> -3.8915 | M23: =+IFERROR(HLOOKUP($B23,'[3]9월'!$F$6:$CC$57,2,),)/1000 -> 5.666 | N23: =+K23-M23 -> -3.5575 | O23: =+IFERROR(HLOOKUP($B23,'[1]9월'!$D$6:$BN$259,3,),)/1000 -> 760.8 | P23: =+IFERROR(HLOOKUP($B23,'[2]9월'!$F$6:$CP$99,3,),)/1000 -> 245.49822 | Q23: =+P23-O23 -> -515.30178 | R23: =+IFERROR(HLOOKUP($B23,'[3]9월'!$F$6:$CC$57,3,),)/1000 -> 680.80018 | S23: =+P23-R23 -> -435.30196 | T23: =+IFERROR(HLOOKUP($B23,'[1]9월'!$D$6:$BN$259,16,),)/1000 -> 122.86409 | U23: =+IFERROR(HLOOKUP($B23,'[2]9월'!$F$6:$CP$99,16,),)/1000 -> -40.681329 | V23: =+U23-T23 -> -163.54542 | W23: =+IFERROR(HLOOKUP($B23,'[3]9월'!$F$6:$CC$57,16,),)/1000 -> 77.088554 | X23: =+U23-W23 -> -117.76988 | Y23: =+[5]제주!$Q$85 -> 126800 | Z23: =+[5]제주!$R$85 -> 116432.64 | AA23: =+[6]제주!$Q$85 -> 120155.34 | AB23: =+[5]제주!$Q$89 -> 91328.928 | AC23: =+[5]제주!$R$89 -> 86083.475 | AD23: =+[6]제주!$Q$89 -> 89424.384 | AE23: =+Y23-AB23 -> 35471.072 | AF23: =+Z23-AC23 -> 30349.163 | AG23: =+AA23-AD23 -> 30730.959
G24: =+I24 -> 수도권 | I24: 수도권 | J24: =SUM(J7:J10) -> 114.5 | K24: =SUM(K7:K10) -> 75.6348 | L24: =+K24-J24 -> -38.8652 | M24: =SUM(M7:M10) -> 129.8285 | N24: =+K24-M24 -> -54.1937 | O24: =SUM(O7:O10) -> 11548.226 | P24: =SUM(P7:P10) -> 7393.098 | Q24: =+P24-O24 -> -4155.1277 | R24: =SUM(R7:R10) -> 12477.456 | S24: =+P24-R24 -> -5084.3579 | T24: =SUM(T7:T10) -> 1621.6334 | U24: =SUM(U7:U10) -> 268.92705 | V24: =+U24-T24 -> -1352.7063 | W24: =SUM(W7:W10) -> 1588.4852 | X24: =+U24-W24 -> -1319.5582 | Y24: =+[5]수도권!$Q$85 -> 100857.87 | Z24: =+[5]수도권!$R$85 -> 97749.491 | AA24: =+[6]수도권!$Q$85 -> 96078.533 | AB24: =+[5]수도권!$Q$89 -> 77895.789 | AC24: =+[5]수도권!$R$89 -> 79479.892 | AD24: =+[6]수도권!$Q$89 -> 75077.479 | AE24: =+Y24-AB24 -> 22962.077 | AF24: =+Z24-AC24 -> 18269.6 | AG24: =+AA24-AD24 -> 21001.054
G25: =+I25 -> 영남권 | I25: 영남권 | J25: =SUM(J11:J18) -> 120 | K25: =SUM(K11:K18) -> 111.844 | L25: =+K25-J25 -> -8.156 | M25: =SUM(M11:M18) -> 132.887 | N25: =+K25-M25 -> -21.043 | O25: =SUM(O11:O18) -> 12286.109 | P25: =SUM(P11:P18) -> 11134.043 | Q25: =+P25-O25 -> -1152.0661 | R25: =SUM(R11:R18) -> 13217.643 | S25: =+P25-R25 -> -2083.5997 | T25: =SUM(T11:T18) -> 1863.4103 | U25: =SUM(U11:U18) -> 790.68247 | V25: =+U25-T25 -> -1072.7279 | W25: =SUM(W11:W18) -> 1441.3918 | X25: =+U25-W25 -> -650.70933 | Y25: =+[5]영남권!$Q$85 -> 102384.24 | Z25: =+[5]영남권!$R$85 -> 99624.762 | AA25: =+[6]영남권!$Q$85 -> 99478.73 | AB25: =+[5]영남권!$Q$89 -> 74992.299 | AC25: =+[5]영남권!$R$89 -> 77483.837 | AD25: =+[6]영남권!$Q$89 -> 76717.351 | AE25: =+Y25-AB25 -> 27391.945 | AF25: =+Z25-AC25 -> 22140.925 | AG25: =+AA25-AD25 -> 22761.378
G26: =+I26 -> 중부권 | I26: 중부권 | J26: =SUM(J19:J23) -> 54 | K26: =SUM(K19:K23) -> 48.8055 | L26: =+K26-J26 -> -5.1945 | M26: =SUM(M19:M23) -> 52.475 | N26: =+K26-M26 -> -3.6695 | O26: =SUM(O19:O23) -> 5708.4753 | P26: =SUM(P19:P23) -> 5092.2316 | Q26: =+P26-O26 -> -616.24372 | R26: =SUM(R19:R23) -> 5336.3915 | S26: =+P26-R26 -> -244.15994 | T26: =SUM(T19:T23) -> 970.36634 | U26: =SUM(U19:U23) -> 673.12587 | V26: =+U26-T26 -> -297.24047 | W26: =SUM(W19:W23) -> 809.92207 | X26: =+U26-W26 -> -136.7962 | Y26: =+[5]중부권!$Q$85 -> 105712.51 | Z26: =+[5]중부권!$R$85 -> 104305.46 | AA26: =+[6]중부권!$Q$85 -> 101710.77 | AB26: =+[5]중부권!$Q$89 -> 76433.153 | AC26: =+[5]중부권!$R$89 -> 75226.187 | AD26: =+[6]중부권!$Q$89 -> 74309.454 | AE26: =+Y26-AB26 -> 29279.352 | AF26: =+Z26-AC26 -> 29079.27 | AG26: =+AA26-AD26 -> 27401.312
G27: =+K27/J27 -> 0.81900971 | H27: 레미콘 계 | J27: =SUM(J24:J26) -> 288.5 | K27: =SUM(K24:K26) -> 236.2843 | L27: =+K27-J27 -> -52.2157 | M27: =SUM(M24:M26) -> 315.1905 | N27: =+K27-M27 -> -78.9062 | O27: =SUM(O24:O26) -> 29542.81 | P27: =SUM(P24:P26) -> 23619.373 | Q27: =+P27-O27 -> -5923.4376 | R27: =SUM(R24:R26) -> 31031.49 | S27: =+P27-R27 -> -7412.1175 | T27: =SUM(T24:T26) -> 4455.41 | U27: =SUM(U24:U26) -> 1732.7354 | V27: =+U27-T27 -> -2722.6747 | W27: =SUM(W24:W26) -> 3839.7991 | X27: =+U27-W27 -> -2107.0637 | Y27: =+[5]합계!$Q$85 -> 102401.42 | Z27: =+[5]합계!$R$85 -> 99989.728 | AA27: =+[6]합계!$Q$85 -> 98458.403 | AB27: =+[5]합계!$Q$89 -> 76414.329 | AC27: =+[5]합계!$R$89 -> 77657.504 | AD27: =+[6]합계!$Q$89 -> 75642.937 | AE27: =+Y27-AB27 -> 25987.093 | AF27: =+Z27-AC27 -> 22332.224 | AG27: =+AA27-AD27 -> 22815.466
B28: 건자재 | E28: 건자재영업 | G28: 건자재 | H28: 건자재 | J28: =+IFERROR(HLOOKUP($B28,'[1]9월'!$D$6:$BN$259,2,),) -> 6500 | K28: =+IFERROR(HLOOKUP($E28,'[2]9월'!$F$6:$CP$99,2,),) -> 7354.628 | L28: =+K28-J28 -> 854.628 | M28: =+IFERROR(HLOOKUP($E28,'[3]9월'!$F$6:$CC$57,2,),) -> 6990.503 | N28: =+K28-M28 -> 364.125 | O28: =+IFERROR(HLOOKUP($B28,'[1]9월'!$D$6:$BN$259,3,),)/1000 -> 7946.92 | P28: =+IFERROR(HLOOKUP($E28,'[2]9월'!$F$6:$CP$99,3,),)/1000 -> 7720.8259 | Q28: =+P28-O28 -> -226.09414 | R28: =+IFERROR(HLOOKUP($E28,'[3]9월'!$F$6:$CC$57,3,),)/1000 -> 9395.2205 | S28: =+P28-R28 -> -1674.3947 | T28: =+IFERROR(HLOOKUP($B28,'[1]9월'!$D$6:$BN$259,16,),)/1000 -> 60.891698 | U28: =+IFERROR(HLOOKUP($E28,'[2]9월'!$F$6:$CP$99,16,),)/1000 -> -15.579202 | V28: =+U28-T28 -> -76.4709 | W28: =+IFERROR(HLOOKUP($E28,'[3]9월'!$F$6:$CC$57,16,),)/1000 -> -1.565119 | X28: =+U28-W28 -> -14.014083 | Y28: ■ 비고
B29: 부산모래장 | C29: 부산골재 | G29: =+I29 -> 부산모래장 | H29: 골재 | I29: 부산모래장 | J29: =+IFERROR(HLOOKUP($B29,'[1]9월'!$D$6:$BN$259,2,),)/1000 -> 26.511795 | K29: =+IFERROR(HLOOKUP($C29,'[2]9월'!$F$6:$CP$99,2,),)/1000 -> 9.143 | L29: =+K29-J29 -> -17.368795 | M29: =+IFERROR(HLOOKUP($C29,'[3]9월'!$F$6:$CC$57,2,),)/1000 -> 27.469 | N29: =+K29-M29 -> -18.326 | O29: =+IFERROR(HLOOKUP($B29,'[1]9월'!$D$6:$BN$259,3,),)/1000 -> 754.203 | P29: =+IFERROR(HLOOKUP($C29,'[2]9월'!$F$6:$CP$99,3,),)/1000 -> 251.0855 | Q29: =+P29-O29 -> -503.1175 | R29: =+IFERROR(HLOOKUP($C29,'[3]9월'!$F$6:$CC$57,3,),)/1000 -> 783.537 | S29: =+P29-R29 -> -532.4515 | T29: =+IFERROR(HLOOKUP($B29,'[1]9월'!$D$6:$BN$259,21,),)/1000 -> 54.760474 | U29: =+IFERROR(HLOOKUP($C29,'[2]9월'!$F$6:$CP$99,21,),)/1000 -> -3.6659722 | V29: =+U29-T29 -> -58.426446 | W29: =+IFERROR(HLOOKUP($C29,'[3]9월'!$F$6:$CC$57,16,),)/1000 -> 21.691171 | X29: =+U29-W29 -> -25.357143 | Y29: □ 대손 환입 : 4억
B30: 서부산크라샤 | C30: 서부산골재 | G30: =+I30 -> 서부산CR | I30: 서부산CR | J30: =+IFERROR(HLOOKUP($B30,'[1]9월'!$D$6:$BN$259,2,),)/1000 -> 46.66963 | K30: =+IFERROR(HLOOKUP($C30,'[2]9월'!$F$6:$CP$99,2,),)/1000 -> 1.05 | L30: =+K30-J30 -> -45.61963 | M30: =+IFERROR(HLOOKUP($C30,'[3]9월'!$F$6:$CC$57,2,),)/1000 -> 33.128 | N30: =+K30-M30 -> -32.078 | O30: =+IFERROR(HLOOKUP($B30,'[1]9월'!$D$6:$BN$259,3,),)/1000 -> 561.62812 | P30: =+IFERROR(HLOOKUP($C30,'[2]9월'!$F$6:$CP$99,3,),)/1000 -> 12.075 | Q30: =+P30-O30 -> -549.55312 | R30: =+IFERROR(HLOOKUP($C30,'[3]9월'!$F$6:$CC$57,3,),)/1000 -> 413.92 | S30: =+P30-R30 -> -401.845 | T30: =+IFERROR(HLOOKUP($B30,'[1]9월'!$D$6:$BN$259,21,),)/1000 -> 67.872078 | U30: =+IFERROR(HLOOKUP($C30,'[2]9월'!$F$6:$CP$99,21,),)/1000 -> -87.578777 | V30: =+U30-T30 -> -155.45085 | W30: =+IFERROR(HLOOKUP($C30,'[3]9월'!$F$6:$CC$57,16,),)/1000 -> 85.058036 | X30: =+U30-W30 -> -172.63681 | Y30: - 집합 대손 : 1.7억
B31: 부산크라샤 | C31: 부산크라샤 | G31: =+I31 -> 부산CR | I31: 부산CR | J31: =+IFERROR(HLOOKUP($B31,'[1]9월'!$D$6:$BN$259,2,),)/1000 -> 41.11631 | K31: =+IFERROR(HLOOKUP($C31,'[2]9월'!$F$6:$CP$99,2,),)/1000 -> 36.758 | L31: =+K31-J31 -> -4.3583098 | M31: =+IFERROR(HLOOKUP($C31,'[3]9월'!$F$6:$CC$57,2,),)/1000 -> 21.312 | N31: =+K31-M31 -> 15.446 | O31: =+IFERROR(HLOOKUP($B31,'[1]9월'!$D$6:$BN$259,3,),)/1000 -> 744.43911 | P31: =+IFERROR(HLOOKUP($C31,'[2]9월'!$F$6:$CP$99,3,),)/1000 -> 622.585 | Q31: =+P31-O31 -> -121.85411 | R31: =+IFERROR(HLOOKUP($C31,'[3]9월'!$F$6:$CC$57,3,),)/1000 -> 377.489 | S31: =+P31-R31 -> 245.096 | T31: =+IFERROR(HLOOKUP($B31,'[1]9월'!$D$6:$BN$259,21,),)/1000 -> 17.132013 | U31: =+IFERROR(HLOOKUP($C31,'[2]9월'!$F$6:$CP$99,21,),)/1000 -> -221.73575 | V31: =+U31-T31 -> -238.86776 | W31: =+IFERROR(HLOOKUP($C31,'[3]9월'!$F$6:$CC$57,16,),)/1000 -> 44.142378 | X31: =+U31-W31 -> -265.87813 | Y31: - 개별 대손 : 2.3억(신일 1.2억, 남양건설 1.1억)
H32: 골재 계 | J32: =SUM(J29:J31) -> 114.29774 | K32: =SUM(K29:K31) -> 46.951 | L32: =+K32-J32 -> -67.346735 | M32: =SUM(M29:M31) -> 81.909 | N32: =+K32-M32 -> -34.958 | O32: =SUM(O29:O31) -> 2060.2702 | P32: =SUM(P29:P31) -> 885.7455 | Q32: =+P32-O32 -> -1174.5247 | R32: =SUM(R29:R31) -> 1574.946 | S32: =+P32-R32 -> -689.2005 | T32: =SUM(T29:T31) -> 139.76456 | U32: =SUM(U29:U31) -> -312.9805 | V32: =+U32-T32 -> -452.74506 | W32: =SUM(W29:W31) -> 150.89159 | X32: =+U32-W32 -> -463.87208
B33: 포항임대 | C33: 속초임대 | D33: 강릉임대 | E33: 레미콘임대 계 | G33: =+I33 -> 레미콘임대 | H33: 기타 | I33: 레미콘임대 | L33: =+K33-J33 -> 0 | N33: =+K33-M33 -> 0 | O33: =(IFERROR(HLOOKUP($B33,'[1]9월'!$D$6:$BN$259,3,),)++IFERROR(HLOOKUP($C33,'[1]9월'!$D$6:$BN$259,3,),)+IFERROR(HLOOKUP($D33,'[1]9월'!$D$6:$BN$259,3,),))/1000 -> 90.84 | P33: =+IFERROR(HLOOKUP($E33,'[2]9월'!$F$6:$CP$99,3,),)/1000 -> 90.84 | Q33: =+P33-O33 -> 0 | R33: =+IFERROR(HLOOKUP($E33,'[3]9월'!$F$6:$CC$57,3,),)/1000 -> 90.84 | S33: =+P33-R33 -> 0 | T33: =(IFERROR(HLOOKUP($B33,'[1]9월'!$D$6:$BN$259,21,),)++IFERROR(HLOOKUP($C33,'[1]9월'!$D$6:$BN$259,21,),)+IFERROR(HLOOKUP($D33,'[1]9월'!$D$6:$BN$259,21,),))/1000 -> 75.404842 | U33: =+IFERROR(HLOOKUP($E33,'[2]9월'!$F$6:$CP$99,16,),)/1000 -> 76.004227 | V33: =+U33-T33 -> 0.599385 | W33: =+IFERROR(HLOOKUP($E33,'[3]9월'!$F$6:$CC$57,16,),)/1000 -> 30.418728 | X33: =+U33-W33 -> 45.585499
B34: 부동산임대 | C34: 주유소임대 | E34: 임대 계 | G34: =+I34 -> 임대 | I34: 임대 | L34: =+K34-J34 -> 0 | M34: 0 | N34: =+K34-M34 -> 0 | O34: =(+IFERROR(HLOOKUP($B34,'[1]9월'!$D$6:$BN$259,3,),)+IFERROR(HLOOKUP($C34,'[1]9월'!$D$6:$BN$259,3,),))/1000 -> 72.8975 | P34: =+IFERROR(HLOOKUP($E34,'[2]9월'!$F$6:$CP$99,3,),)/1000 -> 73.318181 | Q34: =+P34-O34 -> 0.42068067 | R34: =+IFERROR(HLOOKUP($E34,'[3]9월'!$F$6:$CC$57,3,),)/1000 -> 92.762864 | S34: =+P34-R34 -> -19.444683 | T34: =(+IFERROR(HLOOKUP($B34,'[1]9월'!$D$6:$BN$259,21,),)+IFERROR(HLOOKUP($C34,'[1]9월'!$D$6:$BN$259,21,),))/1000 -> 75.238401 | U34: =+IFERROR(HLOOKUP($E34,'[2]9월'!$F$6:$CP$99,16,),)/1000 -> 75.78999 | V34: =+U34-T34 -> 0.55158867 | W34: =+IFERROR(HLOOKUP($E34,'[3]9월'!$F$6:$CC$57,16,),)/1000 -> 99.216891 | X34: =+U34-W34 -> -23.426901
B35: 공 통 비 | G35: =+I35 -> 공통비 | I35: 공통비 | L35: =+K35-J35 -> 0 | N35: =+K35-M35 -> 0 | Q35: =+P35-O35 -> 0 | S35: =+P35-R35 -> 0 | T35: =-'[1]9월'!$Z$22/1000 -> -1157.2821 | U35: =+-'[2]9월'!$Z$22/1000 -> -1368.6461 | V35: =+U35-T35 -> -211.36396 | W35: =+-'[3]9월'!$Z$22/1000 -> -1217.3342 | X35: =+U35-W35 -> -151.31189
G36: =+I36 -> OPC 소급분 | I36: OPC 소급분 | N36: =+K36-M36 -> 0 | Q36: =+P36-O36 -> 0 | S36: =+P36-R36 -> 0 | T36: =+'[1]9월'!$AS$26/1000 -> 0 | U36: ='[2]9월'!$BD$26/1000 -> 250 | V36: =+U36-T36 -> 250 | W36: =-'[3]9월'!$BD$26/1000 -> 0 | X36: =+U36-W36 -> 250
G37: =+I37 -> 대손 | I37: 대손 | N37: =+K37-M37 -> 0 | Q37: =+P37-O37 -> 0 | S37: =+P37-R37 -> 0 | U37: ='[2]9월'!$BE$26/1000 -> 401.64838 | V37: =+U37-T37 -> 401.64838 | W37: ='[3]9월'!$BE$26/1000 -> -776.15284 | X37: =+U37-W37 -> 1177.8012
G38: =+I38 -> 미운영 공장 | I38: 미운영 공장 | M38: =SUM(M54:M57) -> 0 | N38: =+K38-M38 -> 0 | Q38: =+P38-O38 -> 0 | R38: =+IFERROR(HLOOKUP($I$38,'[3]9월'!$F$6:$BJ$50,3,),)/1000 -> 0 | S38: =+P38-R38 -> 0 | T38: =SUM('[1]9월'!$AM$26:$AQ$26)/1000 -> -3.3575384 | U38: =+'[2]9월'!$BF$26/1000 -> -3.050165 | V38: =+U38-T38 -> 0.30737344 | W38: =+'[3]9월'!$BF$26/1000 -> -43.327927 | X38: =+U38-W38 -> 40.277762
B39: 기타 계 | G39: =+I39 -> 기타 | I39: 기타 | L39: =+K39-J39 -> 0 | N39: =+K39-M39 -> 0 | O39: =IFERROR(HLOOKUP($B39,'[1]9월'!$D$6:$BN$259,3,),)/1000 -> 1.77 | P39: =+('[2]9월'!$F$8-SUM('[2]9월'!$Z$8,'[2]9월'!$AH$8,'[2]9월'!$AN$8,'[2]9월'!$AO$8,'[2]9월'!$BA$8,'[2]9월'!$BD$8,'[2]9월'!$BE$8,'[2]9월'!$BF$8))/1000 -> 1.8162 | Q39: =+P39-O39 -> 0.0462 | R39: =+('[3]9월'!$F$8-SUM('[3]9월'!$Z$8,'[3]9월'!$AH$8,'[3]9월'!$AN$8,'[3]9월'!$AO$8,'[3]9월'!$BA$8,'[3]9월'!$BD$8,'[3]9월'!$BE$8,'[3]9월'!$BF$8))/1000 -> 1.7741 | S39: =+P39-R39 -> 0.0421 | T39: =+('[1]9월'!$E$26-'[1]9월'!$Z$26-'[1]9월'!$AA$26-'[1]9월'!$AE$26-'[1]9월'!$AL$26-'[1]9월'!$AM$26-'[1]9월'!$AN$26-'[1]9월'!$AO$26-'[1]9월'!$AP$26-'[1]9월'!$AQ$26-'[1]9월'!$AS$26)/1000 -> -68.088929 | U39: =+('[2]9월'!$F$26-SUM('[2]9월'!$Z$26,'[2]9월'!$AH$26,'[2]9월'!$AN$26,'[2]9월'!$AO$26,'[2]9월'!$BA$26,'[2]9월'!$BD$26,'[2]9월'!$BE$26,'[2]9월'!$BF$26))/1000 -> -6.254879 | V39: =+U39-T39 -> 61.83405 | W39: =+('[3]9월'!$F$26-SUM('[3]9월'!$Z$26,'[3]9월'!$AH$26,'[3]9월'!$AN$26,'[3]9월'!$AO$26,'[3]9월'!$BA$26,'[3]9월'!$BD$26,'[3]9월'!$BE$26,'[3]9월'!$BF$26))/1000 -> -17.243611 | X39: =+U39-W39 -> 10.988732
N40: =+K40-M40 -> 0 | Q40: =+P40-O40 -> 0 | S40: =+P40-R40 -> 0 | V40: =+U40-T40 -> 0
H41: 기타 계 | J41: =SUM(J33:J40) -> 0 | K41: =SUM(K33:K40) -> 0 | L41: =+K41-J41 -> 0 | M41: =SUM(M33:M40) -> 0 | N41: =+K41-M41 -> 0 | O41: =SUM(O33:O40) -> 165.5075 | P41: =SUM(P33:P40) -> 165.97438 | Q41: =+P41-O41 -> 0.46688067 | R41: =SUM(R33:R40) -> 185.37696 | S41: =+P41-R41 -> -19.402583 | T41: =SUM(T33:T40) -> -1078.0853 | U41: =SUM(U33:U40) -> -574.50853 | V41: =+U41-T41 -> 503.57682 | W41: =SUM(W33:W40) -> -1924.423 | X41: =+U41-W41 -> 1349.9144
U42: 19 | V42: 12.4
...

Sheet 사업장별(누계)
H3: □ 사업장별 손익실적(2024-09누계)
AG4: [단위 : 천㎥, 톤, 백만원]
H5: 구분 | J5: 물량 | O5: 매출 | T5: 영업이익(공통비 배부전) | Y5: 판매단가 | AB5: 변동비 | AE5: 공헌이익
J6: 계획 | K6: 실적 | L6: 차이 | M6: 전년 | N6: 차이 | O6: 계획 | P6: 실적 | Q6: 차이 | R6: 전년 | S6: 차이 | T6: 계획 | U6: 실적 | V6: 차이 | W6: 전년 | X6: 차이 | Y6: 계획 | Z6: 실적 | AA6: 전년 | AB6: 계획 | AC6: 실적 | AD6: 전년 | AE6: 계획 | AF6: 실적 | AG6: 전년
B7: 안양 | F7: =+U7/T7 -> 0.65948828 | G7: =+K7/J7 -> 0.90436757 | H7: 레미콘 | I7: 안양 | J7: =+'사업장별(당월)'!J7+'[4]사업장별(누계)'!J7 -> 370 | K7: =+'사업장별(당월)'!K7+'[4]사업장별(누계)'!K7 -> 334.616 | L7: =+K7-J7 -> -35.384 | M7: =+'사업장별(당월)'!M7+'[4]사업장별(누계)'!M7 -> 399.888 | N7: =+K7-M7 -> -65.272 | O7: =+'사업장별(당월)'!O7+'[4]사업장별(누계)'!O7 -> 37069.957 | P7: =+'사업장별(당월)'!P7+'[4]사업장별(누계)'!P7 -> 33357.438 | Q7: =+P7-O7 -> -3712.5193 | R7: =+'사업장별(당월)'!R7+'[4]사업장별(누계)'!R7 -> 37165.112 | S7: =+P7-R7 -> -3807.6742 | T7: =+'사업장별(당월)'!T7+'[4]사업장별(누계)'!T7 -> 5070.1885 | U7: =+'사업장별(당월)'!U7+'[4]사업장별(누계)'!U7 -> 3343.7299 | V7: =+U7-T7 -> -1726.4586 | W7: =+'사업장별(당월)'!W7+'[4]사업장별(누계)'!W7 -> 5349.584 | X7: =+U7-W7 -> -2005.8541 | Y7: =+[11]안양!$Q$85 -> 100189.07 | Z7: =+[11]안양!$R$85 -> 99684.172 | AA7: =+[12]안양!$Q$85 -> 92912.317 | AB7: =+[11]안양!$Q$89 -> 79028.933 | AC7: =+[11]안양!$R$89 -> 81441.595 | AD7: =+[12]안양!$Q$89 -> 72942.375 | AE7: =+Y7-AB7 -> 21160.141 | AF7: =+Z7-AC7 -> 18242.577 | AG7: =+AA7-AD7 -> 19969.942 | AI7: =+U7/T7-1 -> -0.34051172 | AJ7: =+U7/T7 -> 0.65948828 | AK7: =+Z7-Y7 -> -504.90186 | AL7: =+AC7-AB7 -> 2412.6628 | AM7: =+AF7-AE7 -> -2917.5646
B8: 인천 | F8: =+U8/T8 -> 0.55847765 | G8: =+K8/J8 -> 0.88136996 | H8: 직영 | I8: 인천 | J8: =+'사업장별(당월)'!J8+'[4]사업장별(누계)'!J8 -> 273 | K8: =+'사업장별(당월)'!K8+'[4]사업장별(누계)'!K8 -> 240.614 | L8: =+K8-J8 -> -32.386 | M8: =+'사업장별(당월)'!M8+'[4]사업장별(누계)'!M8 -> 334.991 | N8: =+K8-M8 -> -94.377 | O8: =+'사업장별(당월)'!O8+'[4]사업장별(누계)'!O8 -> 27722.47 | P8: =+'사업장별(당월)'!P8+'[4]사업장별(누계)'!P8 -> 24052.031 | Q8: =+P8-O8 -> -3670.4393 | R8: =+'사업장별(당월)'!R8+'[4]사업장별(누계)'!R8 -> 32103.106 | S8: =+P8-R8 -> -8051.0756 | T8: =+'사업장별(당월)'!T8+'[4]사업장별(누계)'!T8 -> 2862.1879 | U8: =+'사업장별(당월)'!U8+'[4]사업장별(누계)'!U8 -> 1598.468 | V8: =+U8-T8 -> -1263.7199 | W8: =+'사업장별(당월)'!W8+'[4]사업장별(누계)'!W8 -> 3919.829 | X8: =+U8-W8 -> -2321.361 | Y8: =+[11]인천!$Q$85 -> 101547.51 | Z8: =+[11]인천!$R$85 -> 99965.701 | AA8: =+[12]인천!$Q$85 -> 95811.617 | AB8: =+[11]인천!$Q$89 -> 81151.823 | AC8: =+[11]인천!$R$89 -> 82345.503 | AD8: =+[12]인천!$Q$89 -> 75972.432 | AE8: =+Y8-AB8 -> 20395.686 | AF8: =+Z8-AC8 -> 17620.198 | AG8: =+AA8-AD8 -> 19839.185 | AI8: =+U8/T8-1 -> -0.44152235 | AK8: =+Z8-Y8 -> -1581.8078 | AL8: =+AC8-AB8 -> 1193.6806 | AM8: =+AF8-AE8 -> -2775.4884
B9: 파주 | F9: =+U9/T9 -> 0.55658247 | G9: =+K9/J9 -> 0.98384615 | I9: 파주 | J9: =+'사업장별(당월)'!J9+'[4]사업장별(누계)'!J9 -> 221 | K9: =+'사업장별(당월)'!K9+'[4]사업장별(누계)'!K9 -> 217.43 | L9: =+K9-J9 -> -3.57 | M9: =+'사업장별(당월)'!M9+'[4]사업장별(누계)'!M9 -> 234.142 | N9: =+K9-M9 -> -16.712 | O9: =+'사업장별(당월)'!O9+'[4]사업장별(누계)'!O9 -> 21780.382 | P9: =+'사업장별(당월)'!P9+'[4]사업장별(누계)'!P9 -> 21232.173 | Q9: =+P9-O9 -> -548.20922 | R9: =+'사업장별(당월)'!R9+'[4]사업장별(누계)'!R9 -> 21568.783 | S9: =+P9-R9 -> -336.60998 | T9: =+'사업장별(당월)'!T9+'[4]사업장별(누계)'!T9 -> 2911.5541 | U9: =+'사업장별(당월)'!U9+'[4]사업장별(누계)'!U9 -> 1620.52 | V9: =+U9-T9 -> -1291.0341 | W9: =+'사업장별(당월)'!W9+'[4]사업장별(누계)'!W9 -> 2435.4324 | X9: =+U9-W9 -> -814.91244 | Y9: =+[11]파주!$Q$85 -> 98553.765 | Z9: =+[11]파주!$R$85 -> 97669.562 | AA9: =+[12]파주!$Q$85 -> 92102.675 | AB9: =+[11]파주!$Q$89 -> 76286.031 | AC9: =+[11]파주!$R$89 -> 80630.911 | AD9: =+[12]파주!$Q$89 -> 73131.663 | AE9: =+Y9-AB9 -> 22267.734 | AF9: =+Z9-AC9 -> 17038.65 | AG9: =+AA9-AD9 -> 18971.012 | AI9: =+U9/T9-1 -> -0.44341753 | AK9: =+Z9-Y9 -> -884.20313 | AL9: =+AC9-AB9 -> 4344.88 | AM9: =+AF9-AE9 -> -5229.0832
