Workbook

Sheet 표지
A6: 2024년 7월 마감 손익
A24: 건재사업본부

Sheet 손익총괄
C3: □ 건재사업본부 손익실적(2024-07) | Z3: □ 건재부문 실적(7월)
X4: [단위 : 천㎥, 톤, 원/㎥, 원/톤, 백만원] | AK4: (단위 : 천㎥, 천톤, 억원)
C5: 구분 | E5: 7월 | J5: 7월 누계 | P5: 7월 주요지표 | Z5: 구분 | AB5: =+E5 -> 7월 | AG5: =+J5 -> 7월 누계
E6: 계획 | F6: 실적 | G6: 계획대비 | H6: 전년 | I6: 전년대비 | J6: 계획 | K6: 실적 | L6: 계획대비 | M6: 전년 | N6: 전년대비 | AB6: =+E6 -> 계획 | AC6: =+F6 -> 실적 | AD6: =+G6 -> 계획대비 | AE6: =+H6 -> 전년 | AF6: =+I6 -> 전년대비 | AG6: =+J6 -> 계획 | AH6: =+K6 -> 실적 | AI6: =+L6 -> 계획대비 | ... AK6: =+N6 -> 전년대비
A7: =+F7/E7 -> 0.87150255 | B7: =+K7/J7 -> 1.0295503 | C7: 물량 | D7: 레미콘 | E7: =+'[1]7월'!$Z$7/1000 -> 294.5 | F7: =+'[2]7월'!$Z$7/1000 -> 256.6575 | G7: =+F7-E7 -> -37.8425 | H7: =+'[3]7월'!$Z$7/1000 -> 268.759 | I7: =+F7-H7 -> -12.1015 | J7: =+[4]손익총괄!J7+E7 -> 1976.5 | K7: =+[4]손익총괄!K7+F7 -> 2034.9062 | L7: =+K7-J7 -> 58.4062 | M7: =+[4]손익총괄!M7+H7 -> 2262.89 | N7: =+K7-M7 -> -227.9838 | Q7: □ 레미콘 | Z7: 물량 | AA7: =+D7 -> 레미콘 | AB7: =+E7 -> 294.5 | AC7: =+F7 -> 256.6575 | AD7: =+AC7-AB7 -> -37.8425 | AE7: =+H7 -> 268.759 | AF7: =+AC7-AE7 -> -12.1015 | AG7: =+J7 -> 1976.5 | AH7: =+K7 -> 2034.9062 | AI7: =+AH7-AG7 -> 58.4062 | AJ7: =+M7 -> 2262.89 | AK7: =+AH7-AJ7 -> -227.9838
D8: 철강재 | E8: =+'[1]7월'!$AA$7 -> 7100 | F8: =+'[2]7월'!$AO$7 -> 12986.91 | G8: =+F8-E8 -> 5886.91 | H8: =+'[3]7월'!$AO$7 -> 6748.173 | I8: =+F8-H8 -> 6238.737 | J8: =+[4]손익총괄!J8+E8 -> 48700 | K8: =+[4]손익총괄!K8+F8 -> 61066.958 | L8: =+K8-J8 -> 12366.958 | M8: =+[4]손익총괄!M8+H8 -> 55688.971 | N8: =+K8-M8 -> 5377.987 | Q8: 구분 | S8: 계획 | T8: 실적 | U8: 계획대비 | V8: 전년 | W8: 전년대비 | AA8: =+D8 -> 철강재 | AB8: =+E8/1000 -> 7.1 | AC8: =+F8/1000 -> 12.98691 | AD8: =+AC8-AB8 -> 5.88691 | AE8: =+H8/1000 -> 6.748173 | AF8: =+AC8-AE8 -> 6.238737 | AG8: =+J8/1000 -> 48.7 | AH8: =+K8/1000 -> 61.066958 | AI8: =+AH8-AG8 -> 12.366958 | AJ8: =+M8/1000 -> 55.688971 | AK8: =+AH8-AJ8 -> 5.377987
D9: 골재 | E9: =+'[1]7월'!$AE$7/1000 -> 121.15976 | F9: =+'[2]7월'!$AN$7/1000 -> 60.962 | G9: =+F9-E9 -> -60.197765 | H9: =+'[3]7월'!$AN$7/1000 -> 47.578 | I9: =+F9-H9 -> 13.384 | J9: =+[4]손익총괄!J9+E9 -> 620.83174 | K9: =+[4]손익총괄!K9+F9 -> 557.661 | L9: =+K9-J9 -> -63.170738 | M9: =+[4]손익총괄!M9+H9 -> 425.041 | N9: =+K9-M9 -> 132.62 | Q9: 물량 | R9: 수도권 | S9: =+[5]수도권!$T$5/1000 -> 115.5 | T9: =+[5]수도권!$U$5/1000 -> 89.348 | U9: =+T9-S9 -> -26.152 | V9: =+[6]수도권!$T$5/1000 -> 115.353 | W9: =+T9-V9 -> -26.005 | AA9: =+D9 -> 골재 | AB9: =+E9 -> 121.15976 | AC9: =+F9 -> 60.962 | AD9: =+AC9-AB9 -> -60.197765 | AE9: =+H9 -> 47.578 | AF9: =+AC9-AE9 -> 13.384 | AG9: =+J9 -> 620.83174 | AH9: =+K9 -> 557.661 | AI9: =+AH9-AG9 -> -63.170738 | AJ9: =+M9 -> 425.041 | AK9: =+AH9-AJ9 -> 132.62
C10: 매출 | D10: 레미콘 | E10: =+'[1]7월'!$Z$8/1000 -> 30134.812 | F10: =+'[2]7월'!$Z$8/1000 -> 26139.233 | G10: =+F10-E10 -> -3995.5781 | H10: =+'[3]7월'!$Z$8/1000 -> 26649.615 | I10: =+F10-H10 -> -510.38118 | J10: =+[4]손익총괄!J10+E10 -> 200915.46 | K10: =+[4]손익총괄!K10+F10 -> 206378.1 | L10: =+K10-J10 -> 5462.6381 | M10: =+[4]손익총괄!M10+H10 -> 216914.6 | N10: =+K10-M10 -> -10536.505 | R10: 영남권 | S10: =+[5]영남권!$T$5/1000 -> 127 | T10: =+[5]영남권!$U$5/1000 -> 118.756 | U10: =+T10-S10 -> -8.244 | V10: =+[6]영남권!$T$5/1000 -> 111.9305 | W10: =+T10-V10 -> 6.8255 | Z10: 매출액 | AA10: =+D10 -> 레미콘 | AB10: =+E10/100 -> 301.34812 | AC10: =+F10/100 -> 261.39233 | AD10: =+AC10-AB10 -> -39.955781 | AE10: =+H10/100 -> 266.49615 | AF10: =+AC10-AE10 -> -5.1038118 | AG10: =+J10/100 -> 2009.1546 | AH10: =+K10/100 -> 2063.781 | AI10: =+AH10-AG10 -> 54.626381 | AJ10: =+M10/100 -> 2169.146 | AK10: =+AH10-AJ10 -> -105.36505
D11: 건자재 | E11: =+'[1]7월'!$AA$8/1000 -> 8684.4905 | F11: =+'[2]7월'!$AO$8/1000 -> 11314.649 | G11: =+F11-E11 -> 2630.1581 | H11: =+'[3]7월'!$AO$8/1000 -> 8183.4776 | I11: =+F11-H11 -> 3131.171 | J11: =+[4]손익총괄!J11+E11 -> 59550.777 | K11: =+[4]손익총괄!K11+F11 -> 60718.387 | L11: =+K11-J11 -> 1167.6099 | M11: =+[4]손익총괄!M11+H11 -> 67531.38 | N11: =+K11-M11 -> -6812.9935 | R11: 중부권 | S11: =+[5]중부권!$T$5/1000 -> 52 | T11: =+[5]중부권!$U$5/1000 -> 48.5535 | U11: =+T11-S11 -> -3.4465 | V11: =+[6]중부권!$T$5/1000 -> 41.4755 | W11: =+T11-V11 -> 7.078 | AA11: =+D11 -> 건자재 | AB11: =+E11/100 -> 86.844905 | AC11: =+F11/100 -> 113.14649 | AD11: =+AC11-AB11 -> 26.301581 | AE11: =+H11/100 -> 81.834776 | AF11: =+AC11-AE11 -> 31.31171 | AG11: =+J11/100 -> 595.50777 | AH11: =+K11/100 -> 607.18387 | AI11: =+AH11-AG11 -> 11.676099 | AJ11: =+M11/100 -> 675.3138 | AK11: =+AH11-AJ11 -> -68.129935
D12: 골재 | E12: =+'[1]7월'!$AE$8/1000 -> 2191.7858 | F12: =+'[2]7월'!$AN$8/1000 -> 1241.323 | G12: =+F12-E12 -> -950.46284 | H12: =+'[3]7월'!$AN$8/1000 -> 935.5555 | I12: =+F12-H12 -> 305.7675 | J12: =+[4]손익총괄!J12+E12 -> 12088.749 | K12: =+[4]손익총괄!K12+F12 -> 11222.53 | L12: =+K12-J12 -> -866.21942 | M12: =+[4]손익총괄!M12+H12 -> 8158.6194 | N12: =+K12-M12 -> 3063.9102 | Q12: 계 | S12: =SUM(S9:S11) -> 294.5 | T12: =SUM(T9:T11) -> 256.6575 | U12: =+T12-S12 -> -37.8425 | V12: =SUM(V9:V11) -> 268.759 | W12: =+T12-V12 -> -12.1015 | AA12: =+D12 -> 골재 | AB12: =+E12/100 -> 21.917858 | AC12: =+F12/100 -> 12.41323 | AD12: =+AC12-AB12 -> -9.5046284 | AE12: =+H12/100 -> 9.355555 | AF12: =+AC12-AE12 -> 3.057675 | AG12: =+J12/100 -> 120.88749 | AH12: =+K12/100 -> 112.2253 | AI12: =+AH12-AG12 -> -8.6621942 | AJ12: =+M12/100 -> 81.586194 | AK12: =+AH12-AJ12 -> 30.639102
D13: 기타 | E13: =+'[1]7월'!$E$8/1000-E10-E11-E12 -> 164.9075 | F13: =+'[2]7월'!$F$8/1000-F10-F11-F12 -> 165.44935 | G13: =+F13-E13 -> 0.54185267 | H13: =+'[3]7월'!$F$8/1000-H10-H11-H12 -> 187.52409 | I13: =+F13-H13 -> -22.074736 | J13: =+[4]손익총괄!J13+E13 -> 1154.3525 | K13: =+[4]손익총괄!K13+F13 -> 1157.2093 | L13: =+K13-J13 -> 2.8568307 | M13: =+[4]손익총괄!M13+H13 -> 1396.791 | N13: =+K13-M13 -> -239.58165 | Q13: 판매단가 | R13: 수도권 | S13: =+[5]수도권!$T$61 -> 100367.83 | T13: =+[5]수도권!$U$61 -> 98771.936 | U13: =+T13-S13 -> -1595.8908 | V13: =+[6]수도권!$Q$85 -> 95276.16 | W13: =+T13-V13 -> 3495.776 | AA13: =+D13 -> 기타 | AB13: =+E13/100 -> 1.649075 | AC13: =+F13/100 -> 1.6544935 | AD13: =+AC13-AB13 -> 0.0054185267 | AE13: =+H13/100 -> 1.8752409 | AF13: =+AC13-AE13 -> -0.22074736 | AG13: =+J13/100 -> 11.543525 | AH13: =+K13/100 -> 11.572093 | AI13: =+AH13-AG13 -> 0.028568307 | AJ13: =+M13/100 -> 13.96791 | AK13: =+AH13-AJ13 -> -2.3958165
A14: =+F14/E14 -> 0.94376964 | B14: =+K14/J14 -> 1.0210694 | C14: 계 | E14: =SUM(E10:E13) -> 41175.995 | F14: =SUM(F10:F13) -> 38860.654 | G14: =+F14-E14 -> -2315.341 | H14: =SUM(H10:H13) -> 35956.172 | I14: =+F14-H14 -> 2904.4826 | J14: =SUM(J10:J13) -> 273709.34 | K14: =SUM(K10:K13) -> 279476.22 | L14: =+K14-J14 -> 5766.8854 | M14: =SUM(M10:M13) -> 294001.39 | N14: =+K14-M14 -> -14525.17 | R14: 영남권 | S14: =+[5]영남권!$T$61 -> 102558.71 | T14: =+[5]영남권!$U$61 -> 102226.32 | U14: =+T14-S14 -> -332.38781 | V14: =+[6]영남권!$Q$85 -> 101161.29 | W14: =+T14-V14 -> 1065.0264 | AA14: 계 | AB14: =SUM(AB10:AB13) -> 411.75995 | AC14: =SUM(AC10:AC13) -> 388.60654 | AD14: =+AC14-AB14 -> -23.15341 | AE14: =SUM(AE10:AE13) -> 359.56172 | AF14: =+AC14-AE14 -> 29.044826 | AG14: =SUM(AG10:AG13) -> 2737.0934 | AH14: =SUM(AH10:AH13) -> 2794.7622 | AI14: =+AH14-AG14 -> 57.668854 | AJ14: =SUM(AJ10:AJ13) -> 2940.0139 | AK14: =+AH14-AJ14 -> -145.2517
C15: 매출원가 | D15: 레미콘 | E15: =+('[1]7월'!$Z$10+'[1]7월'!$Z$19)/1000 -> 24780.395 | F15: =+('[2]7월'!$Z$10+'[2]7월'!$Z$19)/1000 -> 22759.689 | G15: =+F15-E15 -> -2020.706 | H15: =+('[3]7월'!$Z$10+'[3]7월'!$Z$19)/1000 -> 21920.142 | I15: =+F15-H15 -> 839.54787 | J15: =+[4]손익총괄!J15+E15 -> 168554.97 | K15: =+[4]손익총괄!K15+F15 -> 178110.18 | L15: =+K15-J15 -> 9555.2079 | M15: =+[4]손익총괄!M15+H15 -> 178123.6 | N15: =+K15-M15 -> -13.421204 | R15: 중부권 | S15: =+[5]중부권!$T$61 -> 106103.3 | T15: =+[5]중부권!$U$61 -> 106628.96 | U15: =+T15-S15 -> 525.65909 | V15: =+[6]중부권!$Q$85 -> 104529.84 | W15: =+T15-V15 -> 2099.1218 | Z15: 영업이익 | AA15: =+D30 -> 레미콘 | AB15: =+E30/100 -> 47.064199 | AC15: =+F30/100 -> 27.249975 | AD15: =+AC15-AB15 -> -19.814224 | AE15: =+H30/100 -> 41.068087 | AF15: =+AC15-AE15 -> -13.818111 | AG15: =+J30/100 -> 277.53886 | AH15: =+K30/100 -> 236.4686 | AI15: =+AH15-AG15 -> -41.070261 | AJ15: =+M30/100 -> 342.75946 | AK15: =+AH15-AJ15 -> -106.29086
D16: 건자재 | E16: =+('[1]7월'!$AA$10+'[1]7월'!$AA$19)/1000 -> 8462.6954 | F16: =+('[2]7월'!$AO$10+'[2]7월'!$AO$19)/1000 -> 11193.013 | G16: =+F16-E16 -> 2730.3175 | H16: =+('[3]7월'!$AO$10+'[3]7월'!$AO$19)/1000 -> 7986.5306 | I16: =+F16-H16 -> 3206.4824 | J16: =+[4]손익총괄!J16+E16 -> 58027.237 | K16: =+[4]손익총괄!K16+F16 -> 59364.069 | L16: =+K16-J16 -> 1336.832 | M16: =+[4]손익총괄!M16+H16 -> 66145.747 | N16: =+K16-M16 -> -6781.6775 | Q16: 계 | S16: =+[5]합계!$T$61 -> 102325.34 | T16: =+[5]합계!$U$61 -> 101862.36 | U16: =+T16-S16 -> -462.98019 | V16: =+[6]합계!$Q$85 -> 99152.129 | W16: =+T16-V16 -> 2710.2274 | AA16: =+D31 -> % | AB16: =+E31 -> 0.15617884 | AC16: =+F31 -> 0.10424933 | AD16: =+AC16-AB16 -> -0.051929512 | AE16: =+H31 -> 0.15410387 | AF16: =+AC16-AE16 -> -0.049854539 | AG16: =+J31 -> 0.13813714 | AH16: =+K31 -> 0.11458028 | AI16: =+AH16-AG16 -> -0.023556857 | AJ16: =+M31 -> 0.15801585 | AK16: =+AH16-AJ16 -> -0.043435576
D17: 골재 | E17: =+('[1]7월'!$AE$10+'[1]7월'!$AE$19)/1000 -> 1953.7066 | F17: =+('[2]7월'!$AN$10+'[2]7월'!$AN$19)/1000 -> 1252.1428 | G17: =+F17-E17 -> -701.56378 | H17: =+('[3]7월'!$AN$10+'[3]7월'!$AN$19)/1000 -> 946.5424 | I17: =+F17-H17 -> 305.60038 | J17: =+[4]손익총괄!J17+E17 -> 10905.178 | K17: =+[4]손익총괄!K17+F17 -> 10244.78 | L17: =+K17-J17 -> -660.39777 | M17: =+[4]손익총괄!M17+H17 -> 7384.2663 | N17: =+K17-M17 -> 2860.5137 | Q17: 공헌이익 | R17: 수도권 | S17: =+[5]수도권!$Q$90 -> 22983.498 | T17: =+[5]수도권!$R$90 -> 17992.981 | U17: =+T17-S17 -> -4990.5171 | V17: =+[6]수도권!$Q$90 -> 22612.12 | W17: =+T17-V17 -> -4619.1391 | AA17: =+D32 -> 건자재 | AB17: =+E32/100 -> 1.0029102 | AC17: =+F32/100 -> -0.39569616 | AD17: =+AC17-AB17 -> -1.3986064 | AE17: =+H32/100 -> 0.87789723 | AF17: =+AC17-AE17 -> -1.2735934 | AG17: =+J32/100 -> 6.4701095 | AH17: =+K32/100 -> 3.7555282 | AI17: =+AH17-AG17 -> -2.7145813 | AJ17: =+M32/100 -> 5.8168383 | AK17: =+AH17-AJ17 -> -2.0613101
D18: 기타 | E18: =+('[1]7월'!$E$10+'[1]7월'!$E$19)/1000-E15-E16-E17 -> 65.348898 | F18: =+('[2]7월'!$F$10+'[2]7월'!$F$19)/1000-F15-F16-F17 -> 25.575635 | G18: =+F18-E18 -> -39.773263 | H18: =+('[3]7월'!$F$10+'[3]7월'!$F$19)/1000-H15-H16-H17 -> 30.774525 | I18: =+F18-H18 -> -5.19889 | J18: =+[4]손익총괄!J18+E18 -> -915.4251 | K18: =+[4]손익총괄!K18+F18 -> 351.13889 | L18: =+K18-J18 -> 1266.564 | M18: =+[4]손익총괄!M18+H18 -> 429.57843 | N18: =+K18-M18 -> -78.439542 | R18: 영남권 | S18: =+[5]영남권!$Q$90 -> 27653.409 | T18: =+[5]영남권!$R$90 -> 22717.772 | U18: =+T18-S18 -> -4935.6367 | V18: =+[6]영남권!$Q$90 -> 28245.721 | W18: =+T18-V18 -> -5527.9489 | AA18: =+D33 -> 골재 | AB18: =+E33/100 -> 2.0289453 | AC18: =+F33/100 -> -1.1055667 | AD18: =+AC18-AB18 -> -3.134512 | AE18: =+H33/100 -> -0.20329555 | AF18: =+AC18-AE18 -> -0.90227115 | AG18: =+J33/100 -> 7.453113 | AH18: =+K33/100 -> 6.0996158 | AI18: =+AH18-AG18 -> -1.3534971 | AJ18: =+M33/100 -> 5.1550173 | AK18: =+AH18-AJ18 -> 0.94459853
C19: 계 | E19: =SUM(E15:E18) -> 35262.146 | F19: =SUM(F15:F18) -> 35230.421 | G19: =+F19-E19 -> -31.725573 | H19: =SUM(H15:H18) -> 30883.989 | I19: =+F19-H19 -> 4346.4317 | J19: =SUM(J15:J18) -> 236571.96 | K19: =SUM(K15:K18) -> 248070.17 | L19: =+K19-J19 -> 11498.206 | M19: =SUM(M15:M18) -> 252083.19 | N19: =+K19-M19 -> -4013.0245 | R19: 중부권 | S19: =+[5]중부권!$Q$90 -> 29878.312 | T19: =+[5]중부권!$R$90 -> 30402.808 | U19: =+T19-S19 -> 524.49583 | V19: =+[6]중부권!$Q$90 -> 29238.395 | W19: =+T19-V19 -> 1164.4134 | AA19: 공통비 | AB19: =+'사업장별(당월)'!T35/100 -> -12.344134 | AC19: =+'사업장별(당월)'!U35/100 -> -13.384279 | AD19: =+AC19-AB19 -> -1.0401447 | AE19: =+'사업장별(당월)'!W35/100 -> -11.810521 | AF19: =+AC19-AE19 -> -1.5737576 | AG19: =+'사업장별(누계)'!T35/100 -> -102.26759 | AH19: =+'사업장별(누계)'!U35/100 -> -103.90772 | AI19: =+AH19-AG19 -> -1.6401299 | AJ19: =+'사업장별(누계)'!W35/100 -> -81.660362 | AK19: =+AH19-AJ19 -> -22.247355
C20: 매출이익 | D20: 레미콘 | E20: =+E10-E15 -> 5354.4161 | F20: =+F10-F15 -> 3379.544 | G20: =+F20-E20 -> -1974.8721 | H20: =+H10-H15 -> 4729.4731 | I20: =+F20-H20 -> -1349.929 | J20: =+J10-J15 -> 32360.487 | K20: =+K10-K15 -> 28267.918 | L20: =+K20-J20 -> -4092.5698 | M20: =+M10-M15 -> 38791.002 | N20: =+K20-M20 -> -10523.084 | Q20: 계 | S20: =+[5]합계!$Q$90 -> 26214.768 | T20: =+[5]합계!$R$90 -> 22535.083 | U20: =+T20-S20 -> -3679.6851 | V20: =+[6]합계!$Q$90 -> 25981.936 | W20: =+T20-V20 -> -3446.8535 | AA20: =+'사업장별(누계)'!I34 -> 임대 | AB20: =+('사업장별(당월)'!T33+'사업장별(당월)'!T34)/100 -> 1.3419643 | AC20: =+('사업장별(당월)'!U33+'사업장별(당월)'!U34)/100 -> 1.3519687 | AD20: =+AC20-AB20 -> 0.010004347 | AE20: =+('사업장별(당월)'!W33+'사업장별(당월)'!W34)/100 -> 1.2660979 | AF20: =+AC20-AE20 -> 0.08587079 | AG20: =+('사업장별(누계)'!T33+'사업장별(누계)'!T34)/100 -> 9.0972675 | AH20: =+('사업장별(누계)'!U33+'사업장별(누계)'!U34)/100 -> 8.7253339 | AI20: =+AH20-AG20 -> -0.37193362 | AJ20: =+('사업장별(누계)'!W33+'사업장별(누계)'!W34)/100 -> 8.0291196 | AK20: =+AH20-AJ20 -> 0.69621431
D21: 건자재 | E21: =+E11-E16 -> 221.79508 | F21: =+F11-F16 -> 121.6357 | G21: =+F21-E21 -> -100.15938 | H21: =+H11-H16 -> 196.94702 | I21: =+F21-H21 -> -75.311323 | J21: =+J11-J16 -> 1523.5397 | K21: =+K11-K16 -> 1354.3176 | L21: =+K21-J21 -> -169.22212 | M21: =+M11-M16 -> 1385.6335 | N21: =+K21-M21 -> -31.315925 | Q21: □ 건자재 | AA21: =+'사업장별(누계)'!I37 -> 대손 | AB21: =+'사업장별(당월)'!T37/100 -> 0 | AC21: =+'사업장별(당월)'!U37/100 -> 0 | AD21: =+AC21-AB21 -> 0 | AE21: =+'사업장별(당월)'!W37/100 -> 0 | AF21: =+AC21-AE21 -> 0 | AG21: =+'사업장별(누계)'!T37/100 -> 0 | AH21: =+'사업장별(누계)'!U37/100 -> -9.7550771 | AI21: =+AH21-AG21 -> -9.7550771 | AJ21: =+'사업장별(누계)'!W37/100 -> -12.470691 | AK21: =+AH21-AJ21 -> 2.7156142
D22: 골재 | E22: =+E12-E17 -> 238.07928 | F22: =+F12-F17 -> -10.819778 | G22: =+F22-E22 -> -248.89906 | H22: =+H12-H17 -> -10.986898 | I22: =+F22-H22 -> 0.16712001 | J22: =+J12-J17 -> 1183.5712 | K22: =+K12-K17 -> 977.74958 | L22: =+K22-J22 -> -205.82165 | M22: =+M12-M17 -> 774.35314 | N22: =+K22-M22 -> 203.39644 | Q22: 구분 | S22: 계획 | T22: 실적 | U22: 계획대비 | V22: 전년 | W22: 전년대비 | AA22: =+D34 -> 기타 | AB22: =+AB26-AB19-AB20-AB21 -> -1.1504929 | AC22: =+AC26-AC19-AC20-AC21 -> -0.51143327 | AD22: =+AC22-AB22 -> 0.63905965 | AE22: =+AE26-AE19-AE20-AE21 -> -0.26791872 | AF22: =+AC22-AE22 -> -0.24351455 | AG22: =+AG26-AG19-AG20-AG21 -> 6.9119492 | AH22: =+AH26-AH19-AH20-AH21 -> -4.7179522 | AI22: =+AH22-AG22 -> -11.629901 | AJ22: =+AJ26-AJ19-AJ20-AJ21 -> -2.428069 | AK22: =+AH22-AJ22 -> -2.2898831
D23: 기타 | E23: =+E13-E18 -> 99.558602 | F23: =+F13-F18 -> 139.87372 | G23: =+F23-E23 -> 40.315116 | H23: =+H13-H18 -> 156.74956 | I23: =+F23-H23 -> -16.875846 | J23: =+J13-J18 -> 2069.7776 | K23: =+K13-K18 -> 806.07044 | L23: =+K23-J23 -> -1263.7072 | M23: =+M13-M18 -> 967.21255 | N23: =+K23-M23 -> -161.14211 | Q23: 철강재 판매단가 | S23: =+'[7]7월'!$F$10 -> 975352.11 | T23: =+'[7]7월'!$G$10 -> 751049.21 | U23: =+T23-S23 -> -224302.9 | V23: =+'[8]7월'!$G$10 -> 1025254.3 | W23: =+T23-V23 -> -274205.1 | AA23: 계 | AB23: =SUM(AB15,AB17:AB22) -> 37.943392 | AC23: =SUM(AC15,AC17:AC22) -> 13.204969 | AD23: =+AC23-AB23 -> -24.738423 | AE23: =SUM(AE15,AE17:AE22) -> 30.930346 | AF23: =+AC23-AE23 -> -17.725377 | AG23: =SUM(AG15,AG17:AG22) -> 205.20371 | AH23: =SUM(AH15,AH17:AH22) -> 136.66833 | AI23: =+AH23-AG23 -> -68.535382 | AJ23: =SUM(AJ15,AJ17:AJ22) -> 265.20131 | AK23: =+AH23-AJ23 -> -128.53299
C24: 계 | E24: =SUM(E20:E23) -> 5913.8491 | F24: =SUM(F20:F23) -> 3630.2337 | G24: =+F24-E24 -> -2283.6154 | H24: =SUM(H20:H23) -> 5072.1827 | I24: =+F24-H24 -> -1441.9491 | J24: =SUM(J20:J23) -> 37137.376 | K24: =SUM(K20:K23) -> 31406.055 | L24: =+K24-J24 -> -5731.3207 | M24: =SUM(M20:M23) -> 41918.201 | N24: =+K24-M24 -> -10512.146 | Q24: 철강재 마진률 | S24: =+'[7]7월'!$F$15 -> 0.023191336 | T24: =+'[7]7월'!$G$15 -> 0.0082914273 | U24: =+T24-S24 -> -0.014899908 | V24: =+'[8]7월'!$G$15 -> 0.024765464 | W24: =+T24-V24 -> -0.016474037 | AA24: =+D36 -> % | AB24: =+E36 -> 0.092149302 | AC24: =+F36 -> 0.033980305 | AD24: =+G36 -> -0.058168996 | AE24: =+H36 -> 0.086022357 | AF24: =+I36 -> -0.052042051 | AG24: =+J36 -> 0.074971396 | AH24: =+K36 -> 0.048901594 | ... AK24: =+N36 -> -0.041302507
C25: 판관비 | D25: 레미콘 | E25: =+('[1]7월'!$Z$13+'[1]7월'!$Z$20)/1000 -> 647.99616 | F25: =+('[2]7월'!$Z$13+'[2]7월'!$Z$20)/1000 -> 654.54649 | G25: =+F25-E25 -> 6.550331 | H25: =+('[3]7월'!$Z$13+'[3]7월'!$Z$20)/1000 -> 622.6644 | I25: =+F25-H25 -> 31.882092 | J25: =+[4]손익총괄!J25+E25 -> 4606.6016 | K25: =+[4]손익총괄!K25+F25 -> 4621.0579 | L25: =+K25-J25 -> 14.456289 | M25: =+[4]손익총괄!M25+H25 -> 4515.0558 | N25: =+K25-M25 -> 106.00213 | Q25: □ 골재
D26: 건자재 | E26: =+('[1]7월'!$AA$13+'[1]7월'!$AA$20)/1000 -> 121.50406 | F26: =+('[2]7월'!$AO$13+'[2]7월'!$AO$20)/1000 -> 161.20531 | G26: =+F26-E26 -> 39.701253 | H26: =+('[3]7월'!$AO$13+'[3]7월'!$AO$20)/1000 -> 109.1573 | I26: =+F26-H26 -> 52.048016 | J26: =+[4]손익총괄!J26+E26 -> 876.52877 | K26: =+[4]손익총괄!K26+F26 -> 978.76478 | L26: =+K26-J26 -> 102.23601 | M26: =+[4]손익총괄!M26+H26 -> 803.94969 | N26: =+K26-M26 -> 174.81509 | Q26: 구분 | S26: 계획 | T26: 실적 | U26: 계획대비 | V26: 전년 | W26: 전년대비 | AB26: =+'사업장별(당월)'!T41/100 -> -12.152663 | AC26: =+'사업장별(당월)'!U41/100 -> -12.543743 | AD26: =+AC26-AB26 -> -0.39108073 | AE26: =+'사업장별(당월)'!W41/100 -> -10.812342 | AF26: =+AE26-AD26 -> -10.421261 | AG26: =+'사업장별(누계)'!T41/100 -> -86.258371 | AH26: =+'사업장별(누계)'!U41/100 -> -109.65541 | AJ26: =+'사업장별(누계)'!W41/100 -> -88.530003
D27: 골재 | E27: =+('[1]7월'!$AE$13+'[1]7월'!$AE$20+'[1]7월'!$AE$22)/1000 -> 35.18475 | F27: =+('[2]7월'!$AN$13+'[2]7월'!$AN$20+'[2]7월'!$AN$22)/1000 -> 99.736892 | G27: =+F27-E27 -> 64.552142 | H27: =+('[3]7월'!$AN$13+'[3]7월'!$AN$20+'[3]7월'!$AN$22)/1000 -> 9.342657 | I27: =+F27-H27 -> 90.394235 | J27: =+[4]손익총괄!J27+E27 -> 438.25994 | K27: =+[4]손익총괄!K27+F27 -> 367.788 | L27: =+K27-J27 -> -70.471934 | M27: =+[4]손익총괄!M27+H27 -> 258.85141 | N27: =+K27-M27 -> 108.93659 | Q27: 판매량 | R27: 자가 | S27: =(+'[9]서부산크라샤(당월)'!$N$66+'[9]부산모래장(당월)'!$Q$48+'[9]부산크라샤(당월)'!$N$66)/1000 -> 59.359765 | T27: =(+'[9]서부산크라샤(당월)'!$O$66+'[9]부산모래장(당월)'!$R$48+'[9]부산크라샤(당월)'!$O$66)/1000 -> 43.37 | U27: =+T27-S27 -> -15.989765 | V27: =('[10]부산골재(당월)'!$R$48+'[10]서부산골재(당월)'!$O$66+'[10]부산크라샤(당월)'!$O$66)/1000 -> 35.025 | W27: =+T27-V27 -> 8.345
D28: 기타 | E28: =+('[1]7월'!$E$13+'[1]7월'!$E$20)/1000-E25-E26-E27+('[1]7월'!$E$22/1000) -> 1314.8249 | F28: =+('[2]7월'!$F$13+'[2]7월'!$F$20)/1000-F25-F26-F27+'[2]7월'!$F$22/1000 -> 1394.2481 | G28: =+F28-E28 -> 79.423189 | H28: =+('[3]7월'!$F$13+'[3]7월'!$F$20)/1000-H25-H26-H27+'[3]7월'!$F$22/1000 -> 1237.9838 | I28: =+F28-H28 -> 156.26429 | J28: =+[4]손익총괄!J28+E28 -> 10695.615 | K28: =+[4]손익총괄!K28+F28 -> 11771.612 | L28: =+K28-J28 -> 1075.997 | M28: =+[4]손익총괄!M28+H28 -> 9820.2128 | N28: =+K28-M28 -> 1951.3989 | R28: 외판 | S28: =(+'[9]서부산크라샤(당월)'!$N$59+'[9]부산모래장(당월)'!$Q$47+'[9]부산크라샤(당월)'!$N$59)/1000 -> 61.8 | T28: =(+'[9]서부산크라샤(당월)'!$O$59+'[9]부산모래장(당월)'!$R$47+'[9]부산크라샤(당월)'!$O$59)/1000 -> 17.592 | U28: =+T28-S28 -> -44.208 | V28: =+('[10]부산골재(당월)'!$R$47+'[10]서부산골재(당월)'!$O$59+'[10]부산크라샤(당월)'!$O$59)/1000 -> 12.553 | W28: =+T28-V28 -> 5.039
C29: 계 | E29: =SUM(E25:E28) -> 2119.5098 | F29: =SUM(F25:F28) -> 2309.7367 | G29: =+F29-E29 -> 190.22692 | H29: =SUM(H25:H28) -> 1979.1481 | I29: =+F29-H29 -> 330.58863 | J29: =SUM(J25:J28) -> 16617.005 | K29: =SUM(K25:K28) -> 17739.222 | L29: =+K29-J29 -> 1122.2174 | M29: =SUM(M25:M28) -> 15398.07 | N29: =+K29-M29 -> 2341.1527 | Q29: 합 계 | S29: =SUM(S27:S28) -> 121.15976 | T29: =SUM(T27:T28) -> 60.962 | U29: =+T29-S29 -> -60.197765 | V29: =SUM(V27:V28) -> 47.578 | W29: =+T29-V29 -> 13.384
C30: 영업이익 | D30: 레미콘 | E30: =+E20-E25 -> 4706.4199 | F30: =+F20-F25 -> 2724.9975 | G30: =+F30-E30 -> -1981.4224 | H30: =+H20-H25 -> 4106.8087 | I30: =+F30-H30 -> -1381.8111 | J30: =+J20-J25 -> 27753.886 | K30: =+K20-K25 -> 23646.86 | L30: =+K30-J30 -> -4107.0261 | M30: =+M20-M25 -> 34275.946 | N30: =+K30-M30 -> -10629.086 | Q30: □ 기타내역(영업이익)
D31: % | E31: =+E30/E10 -> 0.15617884 | F31: =+F30/F10 -> 0.10424933 | G31: =+F31-E31 -> -0.051929512 | H31: =+H30/H10 -> 0.15410387 | I31: =+F31-H31 -> -0.049854539 | J31: =+J30/J10 -> 0.13813714 | K31: =+K30/K10 -> 0.11458028 | L31: =+K31-J31 -> -0.023556857 | M31: =+M30/M10 -> 0.15801585 | N31: =+K31-M31 -> -0.043435576 | Q31: 구분 | S31: 계획 | T31: 실적 | U31: 계획대비 | V31: 전년 | W31: 전년대비
D32: 건자재 | E32: =+E21-E26 -> 100.29102 | F32: =+F21-F26 -> -39.569616 | G32: =+F32-E32 -> -139.86064 | H32: =+H21-H26 -> 87.789723 | I32: =+F32-H32 -> -127.35934 | J32: =+J21-J26 -> 647.01095 | K32: =+K21-K26 -> 375.55282 | L32: =+K32-J32 -> -271.45813 | M32: =+M21-M26 -> 581.68383 | N32: =+K32-M32 -> -206.13101 | Q32: 레미콘임대 | S32: =+'사업장별(당월)'!T33 -> 72.165959 | T32: =+'사업장별(당월)'!U33 -> 72.53547 | U32: =+T32-S32 -> 0.369511 | V32: =+'사업장별(당월)'!W33 -> 69.372396 | W32: =+T32-V32 -> 3.163074
D33: 골재 | E33: =+E22-E27 -> 202.89453 | F33: =+F22-F27 -> -110.55667 | G33: =+F33-E33 -> -313.4512 | H33: =+H22-H27 -> -20.329555 | I33: =+F33-H33 -> -90.227115 | J33: =+J22-J27 -> 745.3113 | K33: =+K22-K27 -> 609.96158 | L33: =+K33-J33 -> -135.34971 | M33: =+M22-M27 -> 515.50173 | N33: =+K33-M33 -> 94.459853 | Q33: 임대 | S33: =+'사업장별(당월)'!T34 -> 62.030473 | T33: =+'사업장별(당월)'!U34 -> 62.661397 | U33: =+T33-S33 -> 0.63092367 | V33: =+'사업장별(당월)'!W34 -> 57.237392 | W33: =+T33-V33 -> 5.424005
D34: 기타 | E34: =+E23-E28 -> -1215.2663 | F34: =+F23-F28 -> -1254.3743 | G34: =+F34-E34 -> -39.108073 | H34: =+H23-H28 -> -1081.2342 | I34: =+F34-H34 -> -173.14014 | J34: =+J23-J28 -> -8625.8371 | K34: =+K23-K28 -> -10965.541 | L34: =+K34-J34 -> -2339.7042 | M34: =+M23-M28 -> -8853.0003 | N34: =+K34-M34 -> -2112.541 | Q34: 공통비 | S34: =+'사업장별(당월)'!T35 -> -1234.4134 | T34: =+'사업장별(당월)'!U35 -> -1338.4279 | U34: =+T34-S34 -> -104.01447 | V34: =+'사업장별(당월)'!W35 -> -1181.0521 | W34: =+T34-V34 -> -157.37576
C35: 계 | E35: =SUM(E30,E32:E34) -> 3794.3392 | F35: =SUM(F30,F32:F34) -> 1320.4969 | G35: =+F35-E35 -> -2473.8423 | H35: =SUM(H30,H32:H34) -> 3093.0346 | I35: =+F35-H35 -> -1772.5377 | J35: =SUM(J30,J32:J34) -> 20520.371 | K35: =SUM(K30,K32:K34) -> 13666.833 | L35: =+K35-J35 -> -6853.5382 | M35: =SUM(M30,M32:M34) -> 26520.131 | N35: =+K35-M35 -> -12853.299 | Q35: 기타 | S35: =+S36-S32-S33-S34 -> -115.04929 | T35: =+T36-T32-T33-T34 -> -51.143327 | U35: =+T35-S35 -> 63.905965 | V35: =+V36-V32-V33-V34 -> -26.791872 | W35: =+T35-V35 -> -24.351455
D36: % | E36: =+E35/E14 -> 0.092149302 | F36: =+F35/F14 -> 0.033980305 | G36: =+F36-E36 -> -0.058168996 | H36: =+H35/H14 -> 0.086022357 | I36: =+F36-H36 -> -0.052042051 | J36: =+J35/J14 -> 0.074971396 | K36: =+K35/K14 -> 0.048901594 | L36: =+K36-J36 -> -0.026069802 | M36: =+M35/M14 -> 0.090204101 | N36: =+K36-M36 -> -0.041302507 | Q36: 합계 | S36: =+'사업장별(당월)'!T41 -> -1215.2663 | T36: =+'사업장별(당월)'!U41 -> -1254.3743 | U36: =+T36-S36 -> -39.108073 | V36: =+'사업장별(당월)'!W41 -> -1081.2342 | W36: =+T36-V36 -> -173.14014
E38: =+'[1]7월'!$E$26/1000 -> 3794.3392 | F38: =+'[2]7월'!$F$26/1000 -> 1320.4969 | H38: =+'[3]7월'!$F$26/1000 -> 3093.0346 | J38: =+[4]손익총괄!J38+E38 -> 20520.371 | K38: =+[4]손익총괄!K38+F38 -> 13666.833 | M38: =+[4]손익총괄!M38+H38 -> 26520.131
E39: =+E35=E38 -> TRUE | F39: =+F35=F38 -> TRUE | H39: =+H35=H38 -> FALSE | J39: =+J35=J38 -> TRUE | K39: =+K35=K38 -> TRUE | M39: =+M35=M38 -> TRUE
E40: =+E35-E38 -> 0 | F40: =+F35-F38 -> 5.9117156e-12 | H40: =+H35-H38 -> 0 | J40: =+J35-J38 -> 0 | K40: =+K35-K38 -> -4.1836756e-11 | M40: =+M35-M38 -> 0

Sheet 사업장별(당월)
H3: □ 사업장별 손익실적(2024-07)
AG4: [단위 : 천㎥, 톤, 백만원]
H5: 구분 | J5: 물량 | O5: 매출 | T5: 영업이익(공통비 배부전) | Y5: 판매단가 | AB5: 변동비 | AE5: 공헌이익
J6: 계획 | K6: 실적 | L6: 차이 | M6: 전년 | N6: 차이 | O6: 계획 | P6: 실적 | Q6: 차이 | R6: 전년 | S6: 차이 | T6: 계획 | U6: 실적 | V6: 차이 | W6: 전년 | X6: 차이 | Y6: 계획 | Z6: 실적 | AA6: 전년 | AB6: 계획 | AC6: 실적 | AD6: 전년 | AE6: 계획 | AF6: 실적 | AG6: 전년
B7: 안양 | G7: =+I7 -> 안양 | H7: 레미콘 | I7: 안양 | J7: =+IFERROR(HLOOKUP($B7,'[1]7월'!$D$6:$BN$259,2,),)/1000 -> 39 | K7: =+IFERROR(HLOOKUP($B7,'[2]7월'!$F$6:$CP$99,2,),)/1000 -> 30.154 | L7: =+K7-J7 -> -8.846 | M7: =+IFERROR(HLOOKUP($B7,'[3]7월'!$F$6:$CC$57,2,),)/1000 -> 37.196 | N7: =+K7-M7 -> -7.042 | O7: =+IFERROR(HLOOKUP($B7,'[1]7월'!$D$6:$BN$259,3,),)/1000 -> 3945.98 | P7: =+IFERROR(HLOOKUP($B7,'[2]7월'!$F$6:$CP$99,3,),)/1000 -> 3033.8332 | Q7: =+P7-O7 -> -912.14673 | R7: =+IFERROR(HLOOKUP($B7,'[3]7월'!$F$6:$CC$57,3,),)/1000 -> 3521.6706 | S7: =+P7-R7 -> -487.83743 | T7: =+IFERROR(HLOOKUP($B7,'[1]7월'!$D$6:$BN$259,16,),)/1000 -> 584.85549 | U7: =+IFERROR(HLOOKUP($B7,'[2]7월'!$F$6:$CP$99,16,),)/1000 -> 258.59623 | V7: =+U7-T7 -> -326.25926 | W7: =+IFERROR(HLOOKUP($B7,'[3]7월'!$F$6:$CC$57,16,),)/1000 -> 515.2346 | X7: =+U7-W7 -> -256.63837 | Y7: =+[5]안양!$Q$85 -> 101178.97 | Z7: =+[5]안양!$R$85 -> 100611.3 | AA7: =+[6]안양!$Q$85 -> 94593.287 | AB7: =+[5]안양!$Q$89 -> 78552.065 | AC7: =+[5]안양!$R$89 -> 82629.791 | AD7: =+[6]안양!$Q$89 -> 73484.459 | AE7: =+Y7-AB7 -> 22626.908 | AF7: =+Z7-AC7 -> 17981.511 | AG7: =+AA7-AD7 -> 21108.829
B8: 인천 | G8: =+I8 -> 인천 | H8: 직영 | I8: 인천 | J8: =+IFERROR(HLOOKUP($B8,'[1]7월'!$D$6:$BN$259,2,),)/1000 -> 35 | K8: =+IFERROR(HLOOKUP($B8,'[2]7월'!$F$6:$CP$99,2,),)/1000 -> 25.908 | L8: =+K8-J8 -> -9.092 | M8: =+IFERROR(HLOOKUP($B8,'[3]7월'!$F$6:$CC$57,2,),)/1000 -> 36.185 | N8: =+K8-M8 -> -10.277 | O8: =+IFERROR(HLOOKUP($B8,'[1]7월'!$D$6:$BN$259,3,),)/1000 -> 3584.787 | P8: =+IFERROR(HLOOKUP($B8,'[2]7월'!$F$6:$CP$99,3,),)/1000 -> 2597.1843 | Q8: =+P8-O8 -> -987.6027 | R8: =+IFERROR(HLOOKUP($B8,'[3]7월'!$F$6:$CC$57,3,),)/1000 -> 3536.9139 | S8: =+P8-R8 -> -939.72961 | T8: =+IFERROR(HLOOKUP($B8,'[1]7월'!$D$6:$BN$259,16,),)/1000 -> 480.55943 | U8: =+IFERROR(HLOOKUP($B8,'[2]7월'!$F$6:$CP$99,16,),)/1000 -> 199.80018 | V8: =+U8-T8 -> -280.75925 | W8: =+IFERROR(HLOOKUP($B8,'[3]7월'!$F$6:$CC$57,16,),)/1000 -> 552.48013 | X8: =+U8-W8 -> -352.67995 | Y8: =+[5]인천!$Q$85 -> 102422.49 | Z8: =+[5]인천!$R$85 -> 100279.7 | AA8: =+[6]인천!$Q$85 -> 97701.903 | AB8: =+[5]인천!$Q$89 -> 80539.473 | AC8: =+[5]인천!$R$89 -> 81647.893 | AD8: =+[6]인천!$Q$89 -> 74386.721 | AE8: =+Y8-AB8 -> 21883.013 | AF8: =+Z8-AC8 -> 18631.808 | AG8: =+AA8-AD8 -> 23315.182
B9: 파주 | G9: =+I9 -> 파주 | I9: 파주 | J9: =+IFERROR(HLOOKUP($B9,'[1]7월'!$D$6:$BN$259,2,),)/1000 -> 23 | K9: =+IFERROR(HLOOKUP($B9,'[2]7월'!$F$6:$CP$99,2,),)/1000 -> 24.724 | L9: =+K9-J9 -> 1.724 | M9: =+IFERROR(HLOOKUP($B9,'[3]7월'!$F$6:$CC$57,2,),)/1000 -> 29.254 | N9: =+K9-M9 -> -4.53 | O9: =+IFERROR(HLOOKUP($B9,'[1]7월'!$D$6:$BN$259,3,),)/1000 -> 2282.1386 | P9: =+IFERROR(HLOOKUP($B9,'[2]7월'!$F$6:$CP$99,3,),)/1000 -> 2369.8819 | Q9: =+P9-O9 -> 87.74328 | R9: =+IFERROR(HLOOKUP($B9,'[3]7월'!$F$6:$CC$57,3,),)/1000 -> 2764.5207 | S9: =+P9-R9 -> -394.63884 | T9: =+IFERROR(HLOOKUP($B9,'[1]7월'!$D$6:$BN$259,16,),)/1000 -> 327.18299 | U9: =+IFERROR(HLOOKUP($B9,'[2]7월'!$F$6:$CP$99,16,),)/1000 -> 171.334 | V9: =+U9-T9 -> -155.84899 | W9: =+IFERROR(HLOOKUP($B9,'[3]7월'!$F$6:$CC$57,16,),)/1000 -> 447.91543 | X9: =+U9-W9 -> -276.58143 | Y9: =+[5]파주!$Q$85 -> 99223.418 | Z9: =+[5]파주!$R$85 -> 95898.5 | AA9: =+[6]파주!$Q$85 -> 94486.183 | AB9: =+[5]파주!$Q$89 -> 75352.008 | AC9: =+[5]파주!$R$89 -> 79787.149 | AD9: =+[6]파주!$Q$89 -> 72143.806 | AE9: =+Y9-AB9 -> 23871.41 | AF9: =+Z9-AC9 -> 16111.351 | AG9: =+AA9-AD9 -> 22342.377
B10: 김포 | G10: =+I10 -> 김포 | I10: 김포 | J10: =+IFERROR(HLOOKUP($B10,'[1]7월'!$D$6:$BN$259,2,),)/1000 -> 18.5 | K10: =+IFERROR(HLOOKUP($B10,'[2]7월'!$F$6:$CP$99,2,),)/1000 -> 8.562 | L10: =+K10-J10 -> -9.938 | M10: =+IFERROR(HLOOKUP($B10,'[3]7월'!$F$6:$CC$57,2,),)/1000 -> 12.718 | N10: =+K10-M10 -> -4.156 | O10: =+IFERROR(HLOOKUP($B10,'[1]7월'!$D$6:$BN$259,3,),)/1000 -> 1779.5785 | P10: =+IFERROR(HLOOKUP($B10,'[2]7월'!$F$6:$CP$99,3,),)/1000 -> 821.12558 | Q10: =+P10-O10 -> -958.45292 | R10: =+IFERROR(HLOOKUP($B10,'[3]7월'!$F$6:$CC$57,3,),)/1000 -> 1172.4611 | S10: =+P10-R10 -> -351.33553 | T10: =+IFERROR(HLOOKUP($B10,'[1]7월'!$D$6:$BN$259,16,),)/1000 -> 295.41139 | U10: =+IFERROR(HLOOKUP($B10,'[2]7월'!$F$6:$CP$99,16,),)/1000 -> 32.553125 | V10: =+U10-T10 -> -262.85826 | W10: =+IFERROR(HLOOKUP($B10,'[3]7월'!$F$6:$CC$57,16,),)/1000 -> 156.33311 | X10: =+U10-W10 -> -123.77998 | Y10: =+[5]김포!$Q$85 -> 96193.432 | Z10: =+[5]김포!$R$85 -> 95902.436 | AA10: =+[6]김포!$Q$85 -> 92182.424 | AB10: =+[5]김포!$Q$89 -> 71480.095 | AC10: =+[5]김포!$R$89 -> 74436.951 | AD10: =+[6]김포!$Q$89 -> 66553.84 | AE10: =+Y10-AB10 -> 24713.337 | AF10: =+Z10-AC10 -> 21465.485 | AG10: =+AA10-AD10 -> 25628.583
B11: 부산 | G11: =+I11 -> 부산 | I11: 부산 | J11: =+IFERROR(HLOOKUP($B11,'[1]7월'!$D$6:$BN$259,2,),)/1000 -> 22 | K11: =+IFERROR(HLOOKUP($B11,'[2]7월'!$F$6:$CP$99,2,),)/1000 -> 17.425 | L11: =+K11-J11 -> -4.575 | M11: =+IFERROR(HLOOKUP($B11,'[3]7월'!$F$6:$CC$57,2,),)/1000 -> 21.362 | N11: =+K11-M11 -> -3.937 | O11: =+IFERROR(HLOOKUP($B11,'[1]7월'!$D$6:$BN$259,3,),)/1000 -> 2367.1891 | P11: =+IFERROR(HLOOKUP($B11,'[2]7월'!$F$6:$CP$99,3,),)/1000 -> 1927.916 | Q11: =+P11-O11 -> -439.27306 | R11: =+IFERROR(HLOOKUP($B11,'[3]7월'!$F$6:$CC$57,3,),)/1000 -> 2269.5354 | S11: =+P11-R11 -> -341.6194 | T11: =+IFERROR(HLOOKUP($B11,'[1]7월'!$D$6:$BN$259,16,),)/1000 -> 395.44491 | U11: =+IFERROR(HLOOKUP($B11,'[2]7월'!$F$6:$CP$99,16,),)/1000 -> 190.61798 | V11: =+U11-T11 -> -204.82693 | W11: =+IFERROR(HLOOKUP($B11,'[3]7월'!$F$6:$CC$57,16,),)/1000 -> 422.11123 | X11: =+U11-W11 -> -231.49325 | Y11: =+[5]부산!$Q$85 -> 107599.5 | Z11: =+[5]부산!$R$85 -> 110640.8 | AA11: =+[6]부산!$Q$85 -> 106241.71 | AB11: =+[5]부산!$Q$89 -> 77709.296 | AC11: =+[5]부산!$R$89 -> 84480.701 | AD11: =+[6]부산!$Q$89 -> 74764.119 | AE11: =+Y11-AB11 -> 29890.207 | AF11: =+Z11-AC11 -> 26160.103 | AG11: =+AA11-AD11 -> 31477.591
B12: 서부산 | G12: =+I12 -> 서부산 | I12: 서부산 | J12: =+IFERROR(HLOOKUP($B12,'[1]7월'!$D$6:$BN$259,2,),)/1000 -> 26 | K12: =+IFERROR(HLOOKUP($B12,'[2]7월'!$F$6:$CP$99,2,),)/1000 -> 20.05 | L12: =+K12-J12 -> -5.95 | M12: =+IFERROR(HLOOKUP($B12,'[3]7월'!$F$6:$CC$57,2,),)/1000 -> 15.915 | N12: =+K12-M12 -> 4.135 | O12: =+IFERROR(HLOOKUP($B12,'[1]7월'!$D$6:$BN$259,3,),)/1000 -> 2701.4844 | P12: =+IFERROR(HLOOKUP($B12,'[2]7월'!$F$6:$CP$99,3,),)/1000 -> 2059.0346 | Q12: =+P12-O12 -> -642.4498 | R12: =+IFERROR(HLOOKUP($B12,'[3]7월'!$F$6:$CC$57,3,),)/1000 -> 1700.0394 | S12: =+P12-R12 -> 358.9952 | T12: =+IFERROR(HLOOKUP($B12,'[1]7월'!$D$6:$BN$259,16,),)/1000 -> 483.47274 | U12: =+IFERROR(HLOOKUP($B12,'[2]7월'!$F$6:$CP$99,16,),)/1000 -> 225.63006 | V12: =+U12-T12 -> -257.84268 | W12: =+IFERROR(HLOOKUP($B12,'[3]7월'!$F$6:$CC$57,16,),)/1000 -> 297.16164 | X12: =+U12-W12 -> -71.531576 | Y12: =+[5]서부산!$Q$85 -> 103903.25 | Z12: =+[5]서부산!$R$85 -> 102695.88 | AA12: =+[6]서부산!$Q$85 -> 106819.94 | AB12: =+[5]서부산!$Q$89 -> 76198.703 | AC12: =+[5]서부산!$R$89 -> 79119.203 | AD12: =+[6]서부산!$Q$89 -> 75936.262 | AE12: =+Y12-AB12 -> 27704.543 | AF12: =+Z12-AC12 -> 23576.674 | AG12: =+AA12-AD12 -> 30883.681
B13: 김해 | G13: =+I13 -> 김해 | I13: 김해 | J13: =+IFERROR(HLOOKUP($B13,'[1]7월'!$D$6:$BN$259,2,),)/1000 -> 11 | K13: =+IFERROR(HLOOKUP($B13,'[2]7월'!$F$6:$CP$99,2,),)/1000 -> 11.781 | L13: =+K13-J13 -> 0.781 | M13: =+IFERROR(HLOOKUP($B13,'[3]7월'!$F$6:$CC$57,2,),)/1000 -> 9.562 | N13: =+K13-M13 -> 2.219 | O13: =+IFERROR(HLOOKUP($B13,'[1]7월'!$D$6:$BN$259,3,),)/1000 -> 1111.0022 | P13: =+IFERROR(HLOOKUP($B13,'[2]7월'!$F$6:$CP$99,3,),)/1000 -> 1132.0667 | Q13: =+P13-O13 -> 21.0645 | R13: =+IFERROR(HLOOKUP($B13,'[3]7월'!$F$6:$CC$57,3,),)/1000 -> 951.4845 | S13: =+P13-R13 -> 180.5822 | T13: =+IFERROR(HLOOKUP($B13,'[1]7월'!$D$6:$BN$259,16,),)/1000 -> 134.25265 | U13: =+IFERROR(HLOOKUP($B13,'[2]7월'!$F$6:$CP$99,16,),)/1000 -> 38.555588 | V13: =+U13-T13 -> -95.697063 | W13: =+IFERROR(HLOOKUP($B13,'[3]7월'!$F$6:$CC$57,16,),)/1000 -> 99.327666 | X13: =+U13-W13 -> -60.772078 | Y13: =+[5]김해!$Q$85 -> 101000.2 | Z13: =+[5]김해!$R$85 -> 96092.581 | AA13: =+[6]김해!$Q$85 -> 99506.85 | AB13: =+[5]김해!$Q$89 -> 76177.61 | AC13: =+[5]김해!$R$89 -> 80907.956 | AD13: =+[6]김해!$Q$89 -> 75075.389 | AE13: =+Y13-AB13 -> 24822.59 | AF13: =+Z13-AC13 -> 15184.626 | AG13: =+AA13-AD13 -> 24431.461
B14: 정관 | G14: =+I14 -> 정관 | I14: 정관 | J14: =+IFERROR(HLOOKUP($B14,'[1]7월'!$D$6:$BN$259,2,),)/1000 -> 17 | K14: =+IFERROR(HLOOKUP($B14,'[2]7월'!$F$6:$CP$99,2,),)/1000 -> 17.288 | L14: =+K14-J14 -> 0.288 | M14: =+IFERROR(HLOOKUP($B14,'[3]7월'!$F$6:$CC$57,2,),)/1000 -> 15.233 | N14: =+K14-M14 -> 2.055 | O14: =+IFERROR(HLOOKUP($B14,'[1]7월'!$D$6:$BN$259,3,),)/1000 -> 1768 | P14: =+IFERROR(HLOOKUP($B14,'[2]7월'!$F$6:$CP$99,3,),)/1000 -> 1737.7844 | Q14: =+P14-O14 -> -30.2156 | R14: =+IFERROR(HLOOKUP($B14,'[3]7월'!$F$6:$CC$57,3,),)/1000 -> 1610.0879 | S14: =+P14-R14 -> 127.6965 | T14: =+IFERROR(HLOOKUP($B14,'[1]7월'!$D$6:$BN$259,16,),)/1000 -> 251.83451 | U14: =+IFERROR(HLOOKUP($B14,'[2]7월'!$F$6:$CP$99,16,),)/1000 -> 137.84952 | V14: =+U14-T14 -> -113.98499 | W14: =+IFERROR(HLOOKUP($B14,'[3]7월'!$F$6:$CC$57,16,),)/1000 -> 253.60877 | X14: =+U14-W14 -> -115.75926 | Y14: =+[5]정관!$Q$85 -> 104000 | Z14: =+[5]정관!$R$85 -> 100519.69 | AA14: =+[6]정관!$Q$85 -> 105697.36 | AB14: =+[5]정관!$Q$89 -> 77887.509 | AC14: =+[5]정관!$R$89 -> 81910.423 | AD14: =+[6]정관!$Q$89 -> 77276.297 | AE14: =+Y14-AB14 -> 26112.491 | AF14: =+Z14-AC14 -> 18609.267 | AG14: =+AA14-AD14 -> 28421.064
B15: 양산 | G15: =+I15 -> 양산 | I15: 양산 | J15: =+IFERROR(HLOOKUP($B15,'[1]7월'!$D$6:$BN$259,2,),)/1000 -> 9 | K15: =+IFERROR(HLOOKUP($B15,'[2]7월'!$F$6:$CP$99,2,),)/1000 -> 11.07 | L15: =+K15-J15 -> 2.07 | M15: =+IFERROR(HLOOKUP($B15,'[3]7월'!$F$6:$CC$57,2,),)/1000 -> 10.519 | N15: =+K15-M15 -> 0.551 | O15: =+IFERROR(HLOOKUP($B15,'[1]7월'!$D$6:$BN$259,3,),)/1000 -> 873.30597 | P15: =+IFERROR(HLOOKUP($B15,'[2]7월'!$F$6:$CP$99,3,),)/1000 -> 1022.5878 | Q15: =+P15-O15 -> 149.2818 | R15: =+IFERROR(HLOOKUP($B15,'[3]7월'!$F$6:$CC$57,3,),)/1000 -> 1013.719 | S15: =+P15-R15 -> 8.868773 | T15: =+IFERROR(HLOOKUP($B15,'[1]7월'!$D$6:$BN$259,16,),)/1000 -> 121.0902 | U15: =+IFERROR(HLOOKUP($B15,'[2]7월'!$F$6:$CP$99,16,),)/1000 -> 49.592748 | V15: =+U15-T15 -> -71.497453 | W15: =+IFERROR(HLOOKUP($B15,'[3]7월'!$F$6:$CC$57,16,),)/1000 -> 127.00296 | X15: =+U15-W15 -> -77.410213 | Y15: =+[5]양산!$Q$85 -> 97033.997 | Z15: =+[5]양산!$R$85 -> 92374.686 | AA15: =+[6]양산!$Q$85 -> 96370.282 | AB15: =+[5]양산!$Q$89 -> 68584.622 | AC15: =+[5]양산!$R$89 -> 75762.253 | AD15: =+[6]양산!$Q$89 -> 69998.176 | AE15: =+Y15-AB15 -> 28449.374 | AF15: =+Z15-AC15 -> 16612.433 | AG15: =+AA15-AD15 -> 26372.107
B16: 창원 | G16: =+I16 -> 창원 | I16: 창원 | J16: =+IFERROR(HLOOKUP($B16,'[1]7월'!$D$6:$BN$259,2,),)/1000 -> 16 | K16: =+IFERROR(HLOOKUP($B16,'[2]7월'!$F$6:$CP$99,2,),)/1000 -> 13.4055 | L16: =+K16-J16 -> -2.5945 | M16: =+IFERROR(HLOOKUP($B16,'[3]7월'!$F$6:$CC$57,2,),)/1000 -> 16.909 | N16: =+K16-M16 -> -3.5035 | O16: =+IFERROR(HLOOKUP($B16,'[1]7월'!$D$6:$BN$259,3,),)/1000 -> 1627.229 | P16: =+IFERROR(HLOOKUP($B16,'[2]7월'!$F$6:$CP$99,3,),)/1000 -> 1358.995 | Q16: =+P16-O16 -> -268.23395 | R16: =+IFERROR(HLOOKUP($B16,'[3]7월'!$F$6:$CC$57,3,),)/1000 -> 1624.3682 | S16: =+P16-R16 -> -265.37315 | T16: =+IFERROR(HLOOKUP($B16,'[1]7월'!$D$6:$BN$259,16,),)/1000 -> 282.65073 | U16: =+IFERROR(HLOOKUP($B16,'[2]7월'!$F$6:$CP$99,16,),)/1000 -> 173.4925 | V16: =+U16-T16 -> -109.15823 | W16: =+IFERROR(HLOOKUP($B16,'[3]7월'!$F$6:$CC$57,16,),)/1000 -> 301.92364 | X16: =+U16-W16 -> -128.43114 | Y16: =+[5]창원!$Q$85 -> 101701.81 | Z16: =+[5]창원!$R$85 -> 101375.93 | AA16: =+[6]창원!$Q$85 -> 96065.303 | AB16: =+[5]창원!$Q$89 -> 72423.237 | AC16: =+[5]창원!$R$89 -> 74138.455 | AD16: =+[6]창원!$Q$89 -> 67976.162 | AE16: =+Y16-AB16 -> 29278.575 | AF16: =+Z16-AC16 -> 27237.476 | AG16: =+AA16-AD16 -> 28089.141
B17: 대구 | G17: =+I17 -> 대구 | I17: 대구 | J17: =+IFERROR(HLOOKUP($B17,'[1]7월'!$D$6:$BN$259,2,),)/1000 -> 16 | K17: =+IFERROR(HLOOKUP($B17,'[2]7월'!$F$6:$CP$99,2,),)/1000 -> 12.691 | L17: =+K17-J17 -> -3.309 | M17: =+IFERROR(HLOOKUP($B17,'[3]7월'!$F$6:$CC$57,2,),)/1000 -> 16.467 | N17: =+K17-M17 -> -3.776 | O17: =+IFERROR(HLOOKUP($B17,'[1]7월'!$D$6:$BN$259,3,),)/1000 -> 1564.16 | P17: =+IFERROR(HLOOKUP($B17,'[2]7월'!$F$6:$CP$99,3,),)/1000 -> 1308.7025 | Q17: =+P17-O17 -> -255.45746 | R17: =+IFERROR(HLOOKUP($B17,'[3]7월'!$F$6:$CC$57,3,),)/1000 -> 1583.2716 | S17: =+P17-R17 -> -274.56906 | T17: =+IFERROR(HLOOKUP($B17,'[1]7월'!$D$6:$BN$259,16,),)/1000 -> 299.58492 | U17: =+IFERROR(HLOOKUP($B17,'[2]7월'!$F$6:$CP$99,16,),)/1000 -> 175.5937 | V17: =+U17-T17 -> -123.99122 | W17: =+IFERROR(HLOOKUP($B17,'[3]7월'!$F$6:$CC$57,16,),)/1000 -> 303.6879 | X17: =+U17-W17 -> -128.0942 | Y17: =+[5]대구!$Q$85 -> 97760 | Z17: =+[5]대구!$R$85 -> 103120.52 | AA17: =+[6]대구!$Q$85 -> 96148.151 | AB17: =+[5]대구!$Q$89 -> 68963.293 | AC17: =+[5]대구!$R$89 -> 75635.831 | AD17: =+[6]대구!$Q$89 -> 68492.831 | AE17: =+Y17-AB17 -> 28796.707 | AF17: =+Z17-AC17 -> 27484.69 | AG17: =+AA17-AD17 -> 27655.32
B18: 울산 | G18: =+I18 -> 울산 | I18: 울산 | J18: =+IFERROR(HLOOKUP($B18,'[1]7월'!$D$6:$BN$259,2,),)/1000 -> 10 | K18: =+IFERROR(HLOOKUP($B18,'[2]7월'!$F$6:$CP$99,2,),)/1000 -> 15.0455 | L18: =+K18-J18 -> 5.0455 | M18: =+IFERROR(HLOOKUP($B18,'[3]7월'!$F$6:$CC$57,2,),)/1000 -> 5.9635 | N18: =+K18-M18 -> 9.082 | O18: =+IFERROR(HLOOKUP($B18,'[1]7월'!$D$6:$BN$259,3,),)/1000 -> 1012.5851 | P18: =+IFERROR(HLOOKUP($B18,'[2]7월'!$F$6:$CP$99,3,),)/1000 -> 1592.9121 | Q18: =+P18-O18 -> 580.32696 | R18: =+IFERROR(HLOOKUP($B18,'[3]7월'!$F$6:$CC$57,3,),)/1000 -> 569.4604 | S18: =+P18-R18 -> 1023.4517 | T18: =+IFERROR(HLOOKUP($B18,'[1]7월'!$D$6:$BN$259,16,),)/1000 -> 99.238541 | U18: =+IFERROR(HLOOKUP($B18,'[2]7월'!$F$6:$CP$99,16,),)/1000 -> 240.50593 | V18: =+U18-T18 -> 141.26739 | W18: =+IFERROR(HLOOKUP($B18,'[3]7월'!$F$6:$CC$57,16,),)/1000 -> -0.837243 | X18: =+U18-W18 -> 241.34318 | Y18: =+[5]울산!$Q$85 -> 101258.51 | Z18: =+[5]울산!$R$85 -> 105872.99 | AA18: =+[6]울산!$Q$85 -> 95552.436 | AB18: =+[5]울산!$Q$89 -> 78071.462 | AC18: =+[5]울산!$R$89 -> 81253.354 | AD18: =+[6]울산!$Q$89 -> 75027.19 | AE18: =+Y18-AB18 -> 23187.052 | AF18: =+Z18-AC18 -> 24619.638 | AG18: =+AA18-AD18 -> 20525.247
B19: 아산 | G19: =+I19 -> 아산 | I19: 아산 | J19: =+IFERROR(HLOOKUP($B19,'[1]7월'!$D$6:$BN$259,2,),)/1000 -> 24 | K19: =+IFERROR(HLOOKUP($B19,'[2]7월'!$F$6:$CP$99,2,),)/1000 -> 24.195 | L19: =+K19-J19 -> 0.195 | M19: =+IFERROR(HLOOKUP($B19,'[3]7월'!$F$6:$CC$57,2,),)/1000 -> 20.317 | N19: =+K19-M19 -> 3.878 | O19: =+IFERROR(HLOOKUP($B19,'[1]7월'!$D$6:$BN$259,3,),)/1000 -> 2424.0036 | P19: =+IFERROR(HLOOKUP($B19,'[2]7월'!$F$6:$CP$99,3,),)/1000 -> 2473.766 | Q19: =+P19-O19 -> 49.762419 | R19: =+IFERROR(HLOOKUP($B19,'[3]7월'!$F$6:$CC$57,3,),)/1000 -> 2001.38 | S19: =+P19-R19 -> 472.38603 | T19: =+IFERROR(HLOOKUP($B19,'[1]7월'!$D$6:$BN$259,16,),)/1000 -> 373.79144 | U19: =+IFERROR(HLOOKUP($B19,'[2]7월'!$F$6:$CP$99,16,),)/1000 -> 395.11046 | V19: =+U19-T19 -> 21.319019 | W19: =+IFERROR(HLOOKUP($B19,'[3]7월'!$F$6:$CC$57,16,),)/1000 -> 231.05759 | X19: =+U19-W19 -> 164.05287 | Y19: =+[5]아산!$Q$85 -> 101000.15 | Z19: =+[5]아산!$R$85 -> 102242.86 | AA19: =+[6]아산!$Q$85 -> 98479.177 | AB19: =+[5]아산!$Q$89 -> 76608.278 | AC19: =+[5]아산!$R$89 -> 75710.543 | AD19: =+[6]아산!$Q$89 -> 76785.69 | AE19: =+Y19-AB19 -> 24391.872 | AF19: =+Z19-AC19 -> 26532.318 | AG19: =+AA19-AD19 -> 21693.487
B20: 전주 | G20: =+I20 -> 전주 | I20: 전주 | J20: =+IFERROR(HLOOKUP($B20,'[1]7월'!$D$6:$BN$259,2,),)/1000 -> 10 | K20: =+IFERROR(HLOOKUP($B20,'[2]7월'!$F$6:$CP$99,2,),)/1000 -> 8.0735 | L20: =+K20-J20 -> -1.9265 | M20: =+IFERROR(HLOOKUP($B20,'[3]7월'!$F$6:$CC$57,2,),)/1000 -> 6.746 | N20: =+K20-M20 -> 1.3275 | O20: =+IFERROR(HLOOKUP($B20,'[1]7월'!$D$6:$BN$259,3,),)/1000 -> 1030.0691 | P20: =+IFERROR(HLOOKUP($B20,'[2]7월'!$F$6:$CP$99,3,),)/1000 -> 767.062 | Q20: =+P20-O20 -> -263.00714 | R20: =+IFERROR(HLOOKUP($B20,'[3]7월'!$F$6:$CC$57,3,),)/1000 -> 742.7914 | S20: =+P20-R20 -> 24.270604 | T20: =+IFERROR(HLOOKUP($B20,'[1]7월'!$D$6:$BN$259,16,),)/1000 -> 166.47873 | U20: =+IFERROR(HLOOKUP($B20,'[2]7월'!$F$6:$CP$99,16,),)/1000 -> 44.821658 | V20: =+U20-T20 -> -121.65708 | W20: =+IFERROR(HLOOKUP($B20,'[3]7월'!$F$6:$CC$57,16,),)/1000 -> 111.56789 | X20: =+U20-W20 -> -66.746236 | Y20: =+[5]전주!$Q$85 -> 103006.91 | Z20: =+[5]전주!$R$85 -> 95009.847 | AA20: =+[6]전주!$Q$85 -> 110108.42 | AB20: =+[5]전주!$Q$89 -> 72610.173 | AC20: =+[5]전주!$R$89 -> 71872.966 | AD20: =+[6]전주!$Q$89 -> 73699.285 | AE20: =+Y20-AB20 -> 30396.741 | AF20: =+Z20-AC20 -> 23136.881 | AG20: =+AA20-AD20 -> 36409.135
B21: 군산 | G21: =+I21 -> 군산 | I21: 군산 | J21: =+IFERROR(HLOOKUP($B21,'[1]7월'!$D$6:$BN$259,2,),)/1000 -> 7 | K21: =+IFERROR(HLOOKUP($B21,'[2]7월'!$F$6:$CP$99,2,),)/1000 -> 7.211 | L21: =+K21-J21 -> 0.211 | M21: =+IFERROR(HLOOKUP($B21,'[3]7월'!$F$6:$CC$57,2,),)/1000 -> 5.1385 | N21: =+K21-M21 -> 2.0725 | O21: =+IFERROR(HLOOKUP($B21,'[1]7월'!$D$6:$BN$259,3,),)/1000 -> 762.99903 | P21: =+IFERROR(HLOOKUP($B21,'[2]7월'!$F$6:$CP$99,3,),)/1000 -> 865.03425 | Q21: =+P21-O21 -> 102.03522 | R21: =+IFERROR(HLOOKUP($B21,'[3]7월'!$F$6:$CC$57,3,),)/1000 -> 532.01538 | S21: =+P21-R21 -> 333.01887 | T21: =+IFERROR(HLOOKUP($B21,'[1]7월'!$D$6:$BN$259,16,),)/1000 -> 198.85369 | U21: =+IFERROR(HLOOKUP($B21,'[2]7월'!$F$6:$CP$99,16,),)/1000 -> 241.03226 | V21: =+U21-T21 -> 42.178571 | W21: =+IFERROR(HLOOKUP($B21,'[3]7월'!$F$6:$CC$57,16,),)/1000 -> 114.06306 | X21: =+U21-W21 -> 126.9692 | Y21: =+[5]군산!$Q$85 -> 108999.86 | Z21: =+[5]군산!$R$85 -> 119960.37 | AA21: =+[6]군산!$Q$85 -> 103400.06 | AB21: =+[5]군산!$Q$89 -> 69711.657 | AC21: =+[5]군산!$R$89 -> 75163.432 | AD21: =+[6]군산!$Q$89 -> 66178.643 | AE21: =+Y21-AB21 -> 39288.205 | AF21: =+Z21-AC21 -> 44796.941 | AG21: =+AA21-AD21 -> 37221.412
B22: 원주 | G22: =+I22 -> 원주 | I22: 원주 | J22: =+IFERROR(HLOOKUP($B22,'[1]7월'!$D$6:$BN$259,2,),)/1000 -> 5 | K22: =+IFERROR(HLOOKUP($B22,'[2]7월'!$F$6:$CP$99,2,),)/1000 -> 5.1725 | L22: =+K22-J22 -> 0.1725 | M22: =+IFERROR(HLOOKUP($B22,'[3]7월'!$F$6:$CC$57,2,),)/1000 -> 4.1045 | N22: =+K22-M22 -> 1.068 | O22: =+IFERROR(HLOOKUP($B22,'[1]7월'!$D$6:$BN$259,3,),)/1000 -> 539.5 | P22: =+IFERROR(HLOOKUP($B22,'[2]7월'!$F$6:$CP$99,3,),)/1000 -> 592.47664 | Q22: =+P22-O22 -> 52.976645 | R22: =+IFERROR(HLOOKUP($B22,'[3]7월'!$F$6:$CC$57,3,),)/1000 -> 421.2392 | S22: =+P22-R22 -> 171.23744 | T22: =+IFERROR(HLOOKUP($B22,'[1]7월'!$D$6:$BN$259,16,),)/1000 -> 88.943823 | U22: =+IFERROR(HLOOKUP($B22,'[2]7월'!$F$6:$CP$99,16,),)/1000 -> 120.92349 | V22: =+U22-T22 -> 31.979663 | W22: =+IFERROR(HLOOKUP($B22,'[3]7월'!$F$6:$CC$57,16,),)/1000 -> 76.169915 | X22: =+U22-W22 -> 44.753571 | Y22: =+[5]원주!$Q$85 -> 107900 | Z22: =+[5]원주!$R$85 -> 114543.58 | AA22: =+[6]원주!$Q$85 -> 102654.59 | AB22: =+[5]원주!$Q$89 -> 72909.893 | AC22: =+[5]원주!$R$89 -> 75019.456 | AD22: =+[6]원주!$Q$89 -> 66452.561 | AE22: =+Y22-AB22 -> 34990.107 | AF22: =+Z22-AC22 -> 39524.12 | AG22: =+AA22-AD22 -> 36202.025
B23: 제주 | G23: =+I23 -> 제주 | I23: 제주 | J23: =+IFERROR(HLOOKUP($B23,'[1]7월'!$D$6:$BN$259,2,),)/1000 -> 6 | K23: =+IFERROR(HLOOKUP($B23,'[2]7월'!$F$6:$CP$99,2,),)/1000 -> 3.9015 | L23: =+K23-J23 -> -2.0985 | M23: =+IFERROR(HLOOKUP($B23,'[3]7월'!$F$6:$CC$57,2,),)/1000 -> 5.1695 | N23: =+K23-M23 -> -1.268 | O23: =+IFERROR(HLOOKUP($B23,'[1]7월'!$D$6:$BN$259,3,),)/1000 -> 760.8 | P23: =+IFERROR(HLOOKUP($B23,'[2]7월'!$F$6:$CP$99,3,),)/1000 -> 478.87041 | Q23: =+P23-O23 -> -281.92959 | R23: =+IFERROR(HLOOKUP($B23,'[3]7월'!$F$6:$CC$57,3,),)/1000 -> 634.65588 | S23: =+P23-R23 -> -155.78547 | T23: =+IFERROR(HLOOKUP($B23,'[1]7월'!$D$6:$BN$259,16,),)/1000 -> 122.77373 | U23: =+IFERROR(HLOOKUP($B23,'[2]7월'!$F$6:$CP$99,16,),)/1000 -> 28.988095 | V23: =+U23-T23 -> -93.785634 | W23: =+IFERROR(HLOOKUP($B23,'[3]7월'!$F$6:$CC$57,16,),)/1000 -> 98.000358 | X23: =+U23-W23 -> -69.012263 | Y23: =+[5]제주!$Q$85 -> 126800 | Z23: =+[5]제주!$R$85 -> 122740.08 | AA23: =+[6]제주!$Q$85 -> 122769.3 | AB23: =+[5]제주!$Q$89 -> 91078.011 | AC23: =+[5]제주!$R$89 -> 92008.574 | AD23: =+[6]제주!$Q$89 -> 87515.062 | AE23: =+Y23-AB23 -> 35721.989 | AF23: =+Z23-AC23 -> 30731.502 | AG23: =+AA23-AD23 -> 35254.235
G24: =+I24 -> 수도권 | I24: 수도권 | J24: =SUM(J7:J10) -> 115.5 | K24: =SUM(K7:K10) -> 89.348 | L24: =+K24-J24 -> -26.152 | M24: =SUM(M7:M10) -> 115.353 | N24: =+K24-M24 -> -26.005 | O24: =SUM(O7:O10) -> 11592.484 | P24: =SUM(P7:P10) -> 8822.025 | Q24: =+P24-O24 -> -2770.4591 | R24: =SUM(R7:R10) -> 10995.566 | S24: =+P24-R24 -> -2173.5414 | T24: =SUM(T7:T10) -> 1688.0093 | U24: =SUM(U7:U10) -> 662.28354 | V24: =+U24-T24 -> -1025.7258 | W24: =SUM(W7:W10) -> 1671.9633 | X24: =+U24-W24 -> -1009.6797 | Y24: =+[5]수도권!$Q$85 -> 100367.83 | Z24: =+[5]수도권!$R$85 -> 98771.936 | AA24: =+[6]수도권!$Q$85 -> 95276.16 | AB24: =+[5]수도권!$Q$89 -> 77384.329 | AC24: =+[5]수도권!$R$89 -> 80778.956 | AD24: =+[6]수도권!$Q$89 -> 72664.041 | AE24: =+Y24-AB24 -> 22983.498 | AF24: =+Z24-AC24 -> 17992.981 | AG24: =+AA24-AD24 -> 22612.12
G25: =+I25 -> 영남권 | I25: 영남권 | J25: =SUM(J11:J18) -> 127 | K25: =SUM(K11:K18) -> 118.756 | L25: =+K25-J25 -> -8.244 | M25: =SUM(M11:M18) -> 111.9305 | N25: =+K25-M25 -> 6.8255 | O25: =SUM(O11:O18) -> 13024.956 | P25: =SUM(P11:P18) -> 12139.999 | Q25: =+P25-O25 -> -884.9566 | R25: =SUM(R11:R18) -> 11321.966 | S25: =+P25-R25 -> 818.03276 | T25: =SUM(T11:T18) -> 2067.5692 | U25: =SUM(U11:U18) -> 1231.838 | V25: =+U25-T25 -> -835.73119 | W25: =SUM(W11:W18) -> 1803.9866 | X25: =+U25-W25 -> -572.14855 | Y25: =+[5]영남권!$Q$85 -> 102558.71 | Z25: =+[5]영남권!$R$85 -> 102226.32 | AA25: =+[6]영남권!$Q$85 -> 101161.29 | AB25: =+[5]영남권!$Q$89 -> 74905.298 | AC25: =+[5]영남권!$R$89 -> 79508.547 | AD25: =+[6]영남권!$Q$89 -> 72915.572 | AE25: =+Y25-AB25 -> 27653.409 | AF25: =+Z25-AC25 -> 22717.772 | AG25: =+AA25-AD25 -> 28245.721
G26: =+I26 -> 중부권 | I26: 중부권 | J26: =SUM(J19:J23) -> 52 | K26: =SUM(K19:K23) -> 48.5535 | L26: =+K26-J26 -> -3.4465 | M26: =SUM(M19:M23) -> 41.4755 | N26: =+K26-M26 -> 7.078 | O26: =SUM(O19:O23) -> 5517.3718 | P26: =SUM(P19:P23) -> 5177.2093 | Q26: =+P26-O26 -> -340.16245 | R26: =SUM(R19:R23) -> 4332.0819 | S26: =+P26-R26 -> 845.12747 | T26: =SUM(T19:T23) -> 950.84142 | U26: =SUM(U19:U23) -> 830.87596 | V26: =+U26-T26 -> -119.96546 | W26: =SUM(W19:W23) -> 630.85882 | X26: =+U26-W26 -> 200.01714 | Y26: =+[5]중부권!$Q$85 -> 106103.3 | Z26: =+[5]중부권!$R$85 -> 106628.96 | AA26: =+[6]중부권!$Q$85 -> 104529.84 | AB26: =+[5]중부권!$Q$89 -> 76224.991 | AC26: =+[5]중부권!$R$89 -> 76226.154 | AD26: =+[6]중부권!$Q$89 -> 75291.446 | AE26: =+Y26-AB26 -> 29878.312 | AF26: =+Z26-AC26 -> 30402.808 | AG26: =+AA26-AD26 -> 29238.395
G27: =+K27/J27 -> 0.87150255 | H27: 레미콘 계 | J27: =SUM(J24:J26) -> 294.5 | K27: =SUM(K24:K26) -> 256.6575 | L27: =+K27-J27 -> -37.8425 | M27: =SUM(M24:M26) -> 268.759 | N27: =+K27-M27 -> -12.1015 | O27: =SUM(O24:O26) -> 30134.812 | P27: =SUM(P24:P26) -> 26139.233 | Q27: =+P27-O27 -> -3995.5781 | R27: =SUM(R24:R26) -> 26649.615 | S27: =+P27-R27 -> -510.38118 | T27: =SUM(T24:T26) -> 4706.4199 | U27: =SUM(U24:U26) -> 2724.9975 | V27: =+U27-T27 -> -1981.4224 | W27: =SUM(W24:W26) -> 4106.8087 | X27: =+U27-W27 -> -1381.8111 | Y27: =+[5]합계!$Q$85 -> 102325.34 | Z27: =+[5]합계!$R$85 -> 101862.36 | AA27: =+[6]합계!$Q$85 -> 99152.129 | AB27: =+[5]합계!$Q$89 -> 76110.569 | AC27: =+[5]합계!$R$89 -> 79327.273 | AD27: =+[6]합계!$Q$89 -> 73170.193 | AE27: =+Y27-AB27 -> 26214.768 | AF27: =+Z27-AC27 -> 22535.083 | AG27: =+AA27-AD27 -> 25981.936
B28: 건자재 | E28: 건자재영업 | G28: 건자재 | H28: 건자재 | J28: =+IFERROR(HLOOKUP($B28,'[1]7월'!$D$6:$BN$259,2,),) -> 7100 | K28: =+IFERROR(HLOOKUP($E28,'[2]7월'!$F$6:$CP$99,2,),) -> 12986.91 | L28: =+K28-J28 -> 5886.91 | M28: =+IFERROR(HLOOKUP($E28,'[3]7월'!$F$6:$CC$57,2,),) -> 6748.173 | N28: =+K28-M28 -> 6238.737 | O28: =+IFERROR(HLOOKUP($B28,'[1]7월'!$D$6:$BN$259,3,),)/1000 -> 8684.4905 | P28: =+IFERROR(HLOOKUP($E28,'[2]7월'!$F$6:$CP$99,3,),)/1000 -> 11314.649 | Q28: =+P28-O28 -> 2630.1581 | R28: =+IFERROR(HLOOKUP($E28,'[3]7월'!$F$6:$CC$57,3,),)/1000 -> 8183.4776 | S28: =+P28-R28 -> 3131.171 | T28: =+IFERROR(HLOOKUP($B28,'[1]7월'!$D$6:$BN$259,16,),)/1000 -> 100.29102 | U28: =+IFERROR(HLOOKUP($E28,'[2]7월'!$F$6:$CP$99,16,),)/1000 -> -39.569616 | V28: =+U28-T28 -> -139.86064 | W28: =+IFERROR(HLOOKUP($E28,'[3]7월'!$F$6:$CC$57,16,),)/1000 -> 87.789723 | X28: =+U28-W28 -> -127.35934 | Y28: ■ 비고
B29: 부산모래장 | C29: 부산골재 | G29: =+I29 -> 부산모래장 | H29: 골재 | I29: 부산모래장 | J29: =+IFERROR(HLOOKUP($B29,'[1]7월'!$D$6:$BN$259,2,),)/1000 -> 27.749091 | K29: =+IFERROR(HLOOKUP($C29,'[2]7월'!$F$6:$CP$99,2,),)/1000 -> 14.977 | L29: =+K29-J29 -> -12.772091 | M29: =+IFERROR(HLOOKUP($C29,'[3]7월'!$F$6:$CC$57,2,),)/1000 -> 20.186 | N29: =+K29-M29 -> -5.209 | O29: =+IFERROR(HLOOKUP($B29,'[1]7월'!$D$6:$BN$259,3,),)/1000 -> 789.50554 | P29: =+IFERROR(HLOOKUP($C29,'[2]7월'!$F$6:$CP$99,3,),)/1000 -> 424.8905 | Q29: =+P29-O29 -> -364.61504 | R29: =+IFERROR(HLOOKUP($C29,'[3]7월'!$F$6:$CC$57,3,),)/1000 -> 581.9085 | S29: =+P29-R29 -> -157.018 | T29: =+IFERROR(HLOOKUP($B29,'[1]7월'!$D$6:$BN$259,21,),)/1000 -> 50.103139 | U29: =+IFERROR(HLOOKUP($C29,'[2]7월'!$F$6:$CP$99,21,),)/1000 -> 64.377342 | V29: =+U29-T29 -> 14.274203 | W29: =+IFERROR(HLOOKUP($C29,'[3]7월'!$F$6:$CC$57,16,),)/1000 -> 21.515511 | X29: =+U29-W29 -> 42.861831
B30: 서부산크라샤 | C30: 서부산골재 | G30: =+I30 -> 서부산CR | I30: 서부산CR | J30: =+IFERROR(HLOOKUP($B30,'[1]7월'!$D$6:$BN$259,2,),)/1000 -> 50.611164 | K30: =+IFERROR(HLOOKUP($C30,'[2]7월'!$F$6:$CP$99,2,),)/1000 -> 10.47 | L30: =+K30-J30 -> -40.141164 | M30: =+IFERROR(HLOOKUP($C30,'[3]7월'!$F$6:$CC$57,2,),)/1000 -> 23.86 | N30: =+K30-M30 -> -13.39 | O30: =+IFERROR(HLOOKUP($B30,'[1]7월'!$D$6:$BN$259,3,),)/1000 -> 626.52373 | P30: =+IFERROR(HLOOKUP($C30,'[2]7월'!$F$6:$CP$99,3,),)/1000 -> 168.03 | Q30: =+P30-O30 -> -458.49373 | R30: =+IFERROR(HLOOKUP($C30,'[3]7월'!$F$6:$CC$57,3,),)/1000 -> 290.312 | S30: =+P30-R30 -> -122.282 | T30: =+IFERROR(HLOOKUP($B30,'[1]7월'!$D$6:$BN$259,21,),)/1000 -> 108.17456 | U30: =+IFERROR(HLOOKUP($C30,'[2]7월'!$F$6:$CP$99,21,),)/1000 -> -61.232674 | V30: =+U30-T30 -> -169.40723 | W30: =+IFERROR(HLOOKUP($C30,'[3]7월'!$F$6:$CC$57,16,),)/1000 -> 51.724768 | X30: =+U30-W30 -> -112.95744
B31: 부산크라샤 | C31: 부산크라샤 | G31: =+I31 -> 부산CR | I31: 부산CR | J31: =+IFERROR(HLOOKUP($B31,'[1]7월'!$D$6:$BN$259,2,),)/1000 -> 42.79951 | K31: =+IFERROR(HLOOKUP($C31,'[2]7월'!$F$6:$CP$99,2,),)/1000 -> 35.515 | L31: =+K31-J31 -> -7.2845097 | M31: =+IFERROR(HLOOKUP($C31,'[3]7월'!$F$6:$CC$57,2,),)/1000 -> 3.532 | N31: =+K31-M31 -> 31.983 | O31: =+IFERROR(HLOOKUP($B31,'[1]7월'!$D$6:$BN$259,3,),)/1000 -> 775.75657 | P31: =+IFERROR(HLOOKUP($C31,'[2]7월'!$F$6:$CP$99,3,),)/1000 -> 648.4025 | Q31: =+P31-O31 -> -127.35407 | R31: =+IFERROR(HLOOKUP($C31,'[3]7월'!$F$6:$CC$57,3,),)/1000 -> 63.335 | S31: =+P31-R31 -> 585.0675 | T31: =+IFERROR(HLOOKUP($B31,'[1]7월'!$D$6:$BN$259,21,),)/1000 -> 44.616837 | U31: =+IFERROR(HLOOKUP($C31,'[2]7월'!$F$6:$CP$99,21,),)/1000 -> -113.70134 | V31: =+U31-T31 -> -158.31818 | W31: =+IFERROR(HLOOKUP($C31,'[3]7월'!$F$6:$CC$57,16,),)/1000 -> -93.569834 | X31: =+U31-W31 -> -20.131504
H32: 골재 계 | J32: =SUM(J29:J31) -> 121.15976 | K32: =SUM(K29:K31) -> 60.962 | L32: =+K32-J32 -> -60.197765 | M32: =SUM(M29:M31) -> 47.578 | N32: =+K32-M32 -> 13.384 | O32: =SUM(O29:O31) -> 2191.7858 | P32: =SUM(P29:P31) -> 1241.323 | Q32: =+P32-O32 -> -950.46284 | R32: =SUM(R29:R31) -> 935.5555 | S32: =+P32-R32 -> 305.7675 | T32: =SUM(T29:T31) -> 202.89453 | U32: =SUM(U29:U31) -> -110.55667 | V32: =+U32-T32 -> -313.4512 | W32: =SUM(W29:W31) -> -20.329555 | X32: =+U32-W32 -> -90.227115
B33: 포항임대 | C33: 속초임대 | D33: 강릉임대 | E33: 레미콘임대 계 | G33: =+I33 -> 레미콘임대 | H33: 기타 | I33: 레미콘임대 | L33: =+K33-J33 -> 0 | N33: =+K33-M33 -> 0 | O33: =(IFERROR(HLOOKUP($B33,'[1]7월'!$D$6:$BN$259,3,),)++IFERROR(HLOOKUP($C33,'[1]7월'!$D$6:$BN$259,3,),)+IFERROR(HLOOKUP($D33,'[1]7월'!$D$6:$BN$259,3,),))/1000 -> 90.84 | P33: =+IFERROR(HLOOKUP($E33,'[2]7월'!$F$6:$CP$99,3,),)/1000 -> 90.84 | Q33: =+P33-O33 -> 0 | R33: =+IFERROR(HLOOKUP($E33,'[3]7월'!$F$6:$CC$57,3,),)/1000 -> 90.84 | S33: =+P33-R33 -> 0 | T33: =(IFERROR(HLOOKUP($B33,'[1]7월'!$D$6:$BN$259,21,),)++IFERROR(HLOOKUP($C33,'[1]7월'!$D$6:$BN$259,21,),)+IFERROR(HLOOKUP($D33,'[1]7월'!$D$6:$BN$259,21,),))/1000 -> 72.165959 | U33: =+IFERROR(HLOOKUP($E33,'[2]7월'!$F$6:$CP$99,16,),)/1000 -> 72.53547 | V33: =+U33-T33 -> 0.369511 | W33: =+IFERROR(HLOOKUP($E33,'[3]7월'!$F$6:$CC$57,16,),)/1000 -> 69.372396 | X33: =+U33-W33 -> 3.163074
B34: 부동산임대 | C34: 주유소임대 | E34: 임대 계 | G34: =+I34 -> 임대 | I34: 임대 | L34: =+K34-J34 -> 0 | M34: 0 | N34: =+K34-M34 -> 0 | O34: =(+IFERROR(HLOOKUP($B34,'[1]7월'!$D$6:$BN$259,3,),)+IFERROR(HLOOKUP($C34,'[1]7월'!$D$6:$BN$259,3,),))/1000 -> 72.2975 | P34: =+IFERROR(HLOOKUP($E34,'[2]7월'!$F$6:$CP$99,3,),)/1000 -> 72.793153 | Q34: =+P34-O34 -> 0.49565267 | R34: =+IFERROR(HLOOKUP($E34,'[3]7월'!$F$6:$CC$57,3,),)/1000 -> 94.921989 | S34: =+P34-R34 -> -22.128836 | T34: =(+IFERROR(HLOOKUP($B34,'[1]7월'!$D$6:$BN$259,21,),)+IFERROR(HLOOKUP($C34,'[1]7월'!$D$6:$BN$259,21,),))/1000 -> 62.030473 | U34: =+IFERROR(HLOOKUP($E34,'[2]7월'!$F$6:$CP$99,16,),)/1000 -> 62.661397 | V34: =+U34-T34 -> 0.63092367 | W34: =+IFERROR(HLOOKUP($E34,'[3]7월'!$F$6:$CC$57,16,),)/1000 -> 57.237392 | X34: =+U34-W34 -> 5.424005
B35: 공 통 비 | G35: =+I35 -> 공통비 | I35: 공통비 | L35: =+K35-J35 -> 0 | N35: =+K35-M35 -> 0 | Q35: =+P35-O35 -> 0 | S35: =+P35-R35 -> 0 | T35: =-'[1]7월'!$Z$22/1000 -> -1234.4134 | U35: =+-'[2]7월'!$Z$22/1000 -> -1338.4279 | V35: =+U35-T35 -> -104.01447 | W35: =+-'[3]7월'!$Z$22/1000 -> -1181.0521 | X35: =+U35-W35 -> -157.37576
G36: =+I36 -> OPC 소급분 | I36: OPC 소급분 | N36: =+K36-M36 -> 0 | Q36: =+P36-O36 -> 0 | S36: =+P36-R36 -> 0 | T36: =+'[1]7월'!$AS$26/1000 -> 0 | U36: =-'[2]7월'!$BD$26/1000 -> 0 | V36: =+U36-T36 -> 0 | W36: =-'[3]7월'!$BD$26/1000 -> 0 | X36: =+U36-W36 -> 0
G37: =+I37 -> 대손 | I37: 대손 | N37: =+K37-M37 -> 0 | Q37: =+P37-O37 -> 0 | S37: =+P37-R37 -> 0 | U37: ='[2]7월'!$BE$26/1000 -> 0 | V37: =+U37-T37 -> 0 | W37: ='[3]7월'!$BE$26/1000 -> 0 | X37: =+U37-W37 -> 0
G38: =+I38 -> 미운영 공장 | I38: 미운영 공장 | M38: =SUM(M54:M57) -> 0 | N38: =+K38-M38 -> 0 | Q38: =+P38-O38 -> 0 | R38: =+IFERROR(HLOOKUP($I$38,'[3]7월'!$F$6:$BJ$50,3,),)/1000 -> 0 | S38: =+P38-R38 -> 0 | T38: =SUM('[1]7월'!$AM$26:$AQ$26)/1000 -> -35.767484 | U38: =+'[2]7월'!$BF$26/1000 -> -34.386782 | V38: =+U38-T38 -> 1.3807024 | W38: =+'[3]7월'!$BF$26/1000 -> -10.510105 | X38: =+U38-W38 -> -23.876677
B39: 기타 계 | G39: =+I39 -> 기타 | I39: 기타 | L39: =+K39-J39 -> 0 | N39: =+K39-M39 -> 0 | O39: =IFERROR(HLOOKUP($B39,'[1]7월'!$D$6:$BN$259,3,),)/1000 -> 1.77 | P39: =+('[2]7월'!$F$8-SUM('[2]7월'!$Z$8,'[2]7월'!$AH$8,'[2]7월'!$AN$8,'[2]7월'!$AO$8,'[2]7월'!$BA$8,'[2]7월'!$BD$8,'[2]7월'!$BE$8,'[2]7월'!$BF$8))/1000 -> 1.8162 | Q39: =+P39-O39 -> 0.0462 | R39: =+('[3]7월'!$F$8-SUM('[3]7월'!$Z$8,'[3]7월'!$AH$8,'[3]7월'!$AN$8,'[3]7월'!$AO$8,'[3]7월'!$BA$8,'[3]7월'!$BD$8,'[3]7월'!$BE$8,'[3]7월'!$BF$8))/1000 -> 1.7621 | S39: =+P39-R39 -> 0.0541 | T39: =+('[1]7월'!$E$26-'[1]7월'!$Z$26-'[1]7월'!$AA$26-'[1]7월'!$AE$26-'[1]7월'!$AL$26-'[1]7월'!$AM$26-'[1]7월'!$AN$26-'[1]7월'!$AO$26-'[1]7월'!$AP$26-'[1]7월'!$AQ$26-'[1]7월'!$AS$26)/1000 -> -79.281808 | U39: =+('[2]7월'!$F$26-SUM('[2]7월'!$Z$26,'[2]7월'!$AH$26,'[2]7월'!$AN$26,'[2]7월'!$AO$26,'[2]7월'!$BA$26,'[2]7월'!$BD$26,'[2]7월'!$BE$26,'[2]7월'!$BF$26))/1000 -> -16.756545 | V39: =+U39-T39 -> 62.525263 | W39: =+('[3]7월'!$F$26-SUM('[3]7월'!$Z$26,'[3]7월'!$AH$26,'[3]7월'!$AN$26,'[3]7월'!$AO$26,'[3]7월'!$BA$26,'[3]7월'!$BD$26,'[3]7월'!$BE$26,'[3]7월'!$BF$26))/1000 -> -16.281767 | X39: =+U39-W39 -> -0.474778
N40: =+K40-M40 -> 0 | Q40: =+P40-O40 -> 0 | S40: =+P40-R40 -> 0 | V40: =+U40-T40 -> 0
H41: 기타 계 | J41: =SUM(J33:J40) -> 0 | K41: =SUM(K33:K40) -> 0 | L41: =+K41-J41 -> 0 | M41: =SUM(M33:M40) -> 0 | N41: =+K41-M41 -> 0 | O41: =SUM(O33:O40) -> 164.9075 | P41: =SUM(P33:P40) -> 165.44935 | Q41: =+P41-O41 -> 0.54185267 | R41: =SUM(R33:R40) -> 187.52409 | S41: =+P41-R41 -> -22.074736 | T41: =SUM(T33:T40) -> -1215.2663 | U41: =SUM(U33:U40) -> -1254.3743 | V41: =+U41-T41 -> -39.108073 | W41: =SUM(W33:W40) -> -1081.2342 | X41: =+U41-W41 -> -173.14014
U42: 19 | V42: 12.4
...

Sheet 사업장별(누계)
H3: □ 사업장별 손익실적(2024-07누계)
AG4: [단위 : 천㎥, 톤, 백만원]
H5: 구분 | J5: 물량 | O5: 매출 | T5: 영업이익(공통비 배부전) | Y5: 판매단가 | AB5: 변동비 | AE5: 공헌이익
J6: 계획 | K6: 실적 | L6: 차이 | M6: 전년 | N6: 차이 | O6: 계획 | P6: 실적 | Q6: 차이 | R6: 전년 | S6: 차이 | T6: 계획 | U6: 실적 | V6: 차이 | W6: 전년 | X6: 차이 | Y6: 계획 | Z6: 실적 | AA6: 전년 | AB6: 계획 | AC6: 실적 | AD6: 전년 | AE6: 계획 | AF6: 실적 | AG6: 전년
B7: 안양 | F7: =+U7/T7 -> 0.75585819 | G7: =+K7/J7 -> 0.97476056 | H7: 레미콘 | I7: 안양 | J7: =+'사업장별(당월)'!J7+'[4]사업장별(누계)'!J7 -> 284 | K7: =+'사업장별(당월)'!K7+'[4]사업장별(누계)'!K7 -> 276.832 | L7: =+K7-J7 -> -7.168 | M7: =+'사업장별(당월)'!M7+'[4]사업장별(누계)'!M7 -> 310.781 | N7: =+K7-M7 -> -33.949 | O7: =+'사업장별(당월)'!O7+'[4]사업장별(누계)'!O7 -> 28389.835 | P7: =+'사업장별(당월)'!P7+'[4]사업장별(누계)'!P7 -> 27548.945 | Q7: =+P7-O7 -> -840.89078 | R7: =+'사업장별(당월)'!R7+'[4]사업장별(누계)'!R7 -> 28717.155 | S7: =+P7-R7 -> -1168.21 | T7: =+'사업장별(당월)'!T7+'[4]사업장별(누계)'!T7 -> 3752.9225 | U7: =+'사업장별(당월)'!U7+'[4]사업장별(누계)'!U7 -> 2836.6772 | V7: =+U7-T7 -> -916.24528 | W7: =+'사업장별(당월)'!W7+'[4]사업장별(누계)'!W7 -> 4116.1655 | X7: =+U7-W7 -> -1279.4883 | Y7: =+[11]안양!$Q$85 -> 99964.209 | Z7: =+[11]안양!$R$85 -> 99509.44 | AA7: =+[12]안양!$Q$85 -> 92372.674 | AB7: =+[11]안양!$Q$89 -> 79129.066 | AC7: =+[11]안양!$R$89 -> 81474.35 | AD7: =+[12]안양!$Q$89 -> 72551.074 | AE7: =+Y7-AB7 -> 20835.143 | AF7: =+Z7-AC7 -> 18035.089 | AG7: =+AA7-AD7 -> 19821.6 | AI7: 22.510942
B8: 인천 | F8: =+U8/T8 -> 0.73434128 | G8: =+K8/J8 -> 0.92457674 | H8: 직영 | I8: 인천 | J8: =+'사업장별(당월)'!J8+'[4]사업장별(누계)'!J8 -> 215 | K8: =+'사업장별(당월)'!K8+'[4]사업장별(누계)'!K8 -> 198.784 | L8: =+K8-J8 -> -16.216 | M8: =+'사업장별(당월)'!M8+'[4]사업장별(누계)'!M8 -> 272.592 | N8: =+K8-M8 -> -73.808 | O8: =+'사업장별(당월)'!O8+'[4]사업장별(누계)'!O8 -> 21764.348 | P8: =+'사업장별(당월)'!P8+'[4]사업장별(누계)'!P8 -> 19919.822 | Q8: =+P8-O8 -> -1844.5264 | R8: =+'사업장별(당월)'!R8+'[4]사업장별(누계)'!R8 -> 25840.695 | S8: =+P8-R8 -> -5920.8737 | T8: =+'사업장별(당월)'!T8+'[4]사업장별(누계)'!T8 -> 2172.3489 | U8: =+'사업장별(당월)'!U8+'[4]사업장별(누계)'!U8 -> 1595.2455 | V8: =+U8-T8 -> -577.10342 | W8: =+'사업장별(당월)'!W8+'[4]사업장별(누계)'!W8 -> 3274.5166 | X8: =+U8-W8 -> -1679.2712 | Y8: =+[11]인천!$Q$85 -> 101229.53 | Z8: =+[11]인천!$R$85 -> 100212.69 | AA8: =+[12]인천!$Q$85 -> 94780.814 | AB8: =+[11]인천!$Q$89 -> 81283.386 | AC8: =+[11]인천!$R$89 -> 82061.112 | AD8: =+[12]인천!$Q$89 -> 75126.066 | AE8: =+Y8-AB8 -> 19946.141 | AF8: =+Z8-AC8 -> 18151.578 | AG8: =+AA8-AD8 -> 19654.747 | AI8: 12.217192
B9: 파주 | F9: =+U9/T9 -> 0.62391946 | G9: =+K9/J9 -> 1.0300816 | I9: 파주 | J9: =+'사업장별(당월)'!J9+'[4]사업장별(누계)'!J9 -> 174 | K9: =+'사업장별(당월)'!K9+'[4]사업장별(누계)'!K9 -> 179.2342 | L9: =+K9-J9 -> 5.2342 | M9: =+'사업장별(당월)'!M9+'[4]사업장별(누계)'!M9 -> 182.914 | N9: =+K9-M9 -> -3.6798 | O9: =+'사업장별(당월)'!O9+'[4]사업장별(누계)'!O9 -> 17099.407 | P9: =+'사업장별(당월)'!P9+'[4]사업장별(누계)'!P9 -> 17607.835 | Q9: =+P9-O9 -> 508.42796 | R9: =+'사업장별(당월)'!R9+'[4]사업장별(누계)'!R9 -> 16679.823 | S9: =+P9-R9 -> 928.01269 | T9: =+'사업장별(당월)'!T9+'[4]사업장별(누계)'!T9 -> 2247.6373 | U9: =+'사업장별(당월)'!U9+'[4]사업장별(누계)'!U9 -> 1402.3446 | V9: =+U9-T9 -> -845.29265 | W9: =+'사업장별(당월)'!W9+'[4]사업장별(누계)'!W9 -> 1866.7109 | X9: =+U9-W9 -> -464.36622 | Y9: =+[11]파주!$Q$85 -> 98272.456 | Z9: =+[11]파주!$R$85 -> 98269.313 | AA9: =+[12]파주!$Q$85 -> 91179.996 | AB9: =+[11]파주!$Q$89 -> 76335.988 | AC9: =+[11]파주!$R$89 -> 81410.232 | AD9: =+[12]파주!$Q$89 -> 72614.643 | AE9: =+Y9-AB9 -> 21936.468 | AF9: =+Z9-AC9 -> 16859.082 | AG9: =+AA9-AD9 -> 18565.354 | AI9: 9.7481997
B10: 김포 | F10: =+U10/T10 -> 0.61162954 | G10: =+K10/J10 -> 0.80273659 | I10: 김포 | J10: =+'사업장별(당월)'!J10+'[4]사업장별(누계)'!J10 -> 102.5 | K10: =+'사업장별(당월)'!K10+'[4]사업장별(누계)'!K10 -> 82.2805 | L10: =+K10-J10 -> -20.2195 | M10: =+'사업장별(당월)'!M10+'[4]사업장별(누계)'!M10 -> 118.0575 | N10: =+K10-M10 -> -35.777 | O10: =+'사업장별(당월)'!O10+'[4]사업장별(누계)'!O10 -> 9762.4155 | P10: =+'사업장별(당월)'!P10+'[4]사업장별(누계)'!P10 -> 8108.7848 | Q10: =+P10-O10 -> -1653.6307 | R10: =+'사업장별(당월)'!R10+'[4]사업장별(누계)'!R10 -> 10505.868 | S10: =+P10-R10 -> -2397.0829 | T10: =+'사업장별(당월)'!T10+'[4]사업장별(누계)'!T10 -> 1248.543 | U10: =+'사업장별(당월)'!U10+'[4]사업장별(누계)'!U10 -> 763.64576 | V10: =+U10-T10 -> -484.89721 | W10: =+'사업장별(당월)'!W10+'[4]사업장별(누계)'!W10 -> 1411.9746 | X10: =+U10-W10 -> -648.32885 | Y10: =+[11]김포!$Q$85 -> 95243.078 | Z10: =+[11]김포!$R$85 -> 98569.378 | AA10: =+[12]김포!$Q$85 -> 88941.757 | AB10: =+[11]김포!$Q$89 -> 71571.396 | AC10: =+[11]김포!$R$89 -> 75733.317 | AD10: =+[12]김포!$Q$89 -> 67151.104 | AE10: =+Y10-AB10 -> 23671.682 | AF10: =+Z10-AC10 -> 22836.061 | AG10: =+AA10-AD10 -> 21790.653 | AI10: 6.215745
