Workbook

Sheet 표지
A6: 2024년 4월 마감 손익
A24: 건재사업본부

Sheet 손익총괄
C3: □ 건재사업본부 손익실적(2024-04) | Z3: □ 건재부문 실적(4월)
X4: [단위 : 천㎥, 톤, 원/㎥, 원/톤, 백만원] | AK4: (단위 : 천㎥, 천톤, 억원)
C5: 구분 | E5: 4월 | J5: 4월 누계 | P5: 4월 주요지표 | Z5: 구분 | AB5: =+E5 -> 4월 | AG5: =+J5 -> 4월 누계
E6: 계획 | F6: 실적 | G6: 계획대비 | H6: 전년 | I6: 전년대비 | J6: 계획 | K6: 실적 | L6: 계획대비 | M6: 전년 | N6: 전년대비 | AB6: =+E6 -> 계획 | AC6: =+F6 -> 실적 | AD6: =+G6 -> 계획대비 | AE6: =+H6 -> 전년 | AF6: =+I6 -> 전년대비 | AG6: =+J6 -> 계획 | AH6: =+K6 -> 실적 | AI6: =+L6 -> 계획대비 | ... AK6: =+N6 -> 전년대비
C7: 물량 | D7: 레미콘 | E7: =+'[1]4월'!$Z$7/1000 -> 308.5 | F7: =+'[2]4월'!$Z$7/1000 -> 331.0375 | G7: =+F7-E7 -> 22.5375 | H7: =+'[3]4월'!$Z$7/1000 -> 322.7745 | I7: =+F7-H7 -> 8.263 | J7: =+[4]손익총괄!J7+E7 -> 1064.5 | K7: =+[4]손익총괄!K7+F7 -> 1125.966 | L7: =+K7-J7 -> 61.466 | M7: =+[4]손익총괄!M7+H7 -> 1279.6475 | N7: =+K7-M7 -> -153.6815 | Q7: □ 레미콘 | Z7: 물량 | AA7: =+D7 -> 레미콘 | AB7: =+E7 -> 308.5 | AC7: =+F7 -> 331.0375 | AD7: =+AC7-AB7 -> 22.5375 | AE7: =+H7 -> 322.7745 | AF7: =+AC7-AE7 -> 8.263 | AG7: =+J7 -> 1064.5 | AH7: =+K7 -> 1125.966 | AI7: =+AH7-AG7 -> 61.466 | AJ7: =+M7 -> 1279.6475 | AK7: =+AH7-AJ7 -> -153.6815
D8: 철강재 | E8: =+'[1]4월'!$AA$7 -> 7300 | F8: =+'[2]4월'!$AO$7 -> 8574.983 | G8: =+F8-E8 -> 1274.983 | H8: =+'[3]4월'!$AO$7 -> 9357.597 | I8: =+F8-H8 -> -782.614 | J8: =+[4]손익총괄!J8+E8 -> 27900 | K8: =+[4]손익총괄!K8+F8 -> 30310.546 | L8: =+K8-J8 -> 2410.546 | M8: =+[4]손익총괄!M8+H8 -> 34525.302 | N8: =+K8-M8 -> -4214.756 | Q8: 구분 | S8: 계획 | T8: 실적 | U8: 계획대비 | V8: 전년 | W8: 전년대비 | AA8: =+D8 -> 철강재 | AB8: =+E8/1000 -> 7.3 | AC8: =+F8/1000 -> 8.574983 | AD8: =+AC8-AB8 -> 1.274983 | AE8: =+H8/1000 -> 9.357597 | AF8: =+AC8-AE8 -> -0.782614 | AG8: =+J8/1000 -> 27.9 | AH8: =+K8/1000 -> 30.310546 | AI8: =+AH8-AG8 -> 2.410546 | AJ8: =+M8/1000 -> 34.525302 | AK8: =+AH8-AJ8 -> -4.214756
D9: 골재 | E9: =+'[1]4월'!$AE$7/1000 -> 59.030283 | F9: =+'[2]4월'!$AN$7/1000 -> 86.343 | G9: =+F9-E9 -> 27.312717 | H9: =+'[3]4월'!$AN$7/1000 -> 58.239 | I9: =+F9-H9 -> 28.104 | J9: =+[4]손익총괄!J9+E9 -> 259.16836 | K9: =+[4]손익총괄!K9+F9 -> 321.06 | L9: =+K9-J9 -> 61.89164 | M9: =+[4]손익총괄!M9+H9 -> 245.332 | N9: =+K9-M9 -> 75.728 | Q9: 물량 | R9: 수도권 | S9: =+[5]수도권!$T$5/1000 -> 122.5 | T9: =+[5]수도권!$U$5/1000 -> 122.5135 | U9: =+T9-S9 -> 0.0135 | V9: =+[6]수도권!$T$5/1000 -> 122.851 | W9: =+T9-V9 -> -0.3375 | AA9: =+D9 -> 골재 | AB9: =+E9 -> 59.030283 | AC9: =+F9 -> 86.343 | AD9: =+AC9-AB9 -> 27.312717 | AE9: =+H9 -> 58.239 | AF9: =+AC9-AE9 -> 28.104 | AG9: =+J9 -> 259.16836 | AH9: =+K9 -> 321.06 | AI9: =+AH9-AG9 -> 61.89164 | AJ9: =+M9 -> 245.332 | AK9: =+AH9-AJ9 -> 75.728
C10: 매출 | D10: 레미콘 | E10: =+'[1]4월'!$Z$8/1000 -> 31476.892 | F10: =+'[2]4월'!$Z$8/1000 -> 33733.44 | G10: =+F10-E10 -> 2256.5477 | H10: =+'[3]4월'!$Z$8/1000 -> 30531.031 | I10: =+F10-H10 -> 3202.4081 | J10: =+[4]손익총괄!J10+E10 -> 107660.25 | K10: =+[4]손익총괄!K10+F10 -> 114335.88 | L10: =+K10-J10 -> 6675.628 | M10: =+[4]손익총괄!M10+H10 -> 120036.55 | N10: =+K10-M10 -> -5700.668 | R10: 영남권 | S10: =+[5]영남권!$T$5/1000 -> 129.5 | T10: =+[5]영남권!$U$5/1000 -> 147.2215 | U10: =+T10-S10 -> 17.7215 | V10: =+[6]영남권!$T$5/1000 -> 140.756 | W10: =+T10-V10 -> 6.4655 | Z10: 매출액 | AA10: =+D10 -> 레미콘 | AB10: =+E10/100 -> 314.76892 | AC10: =+F10/100 -> 337.3344 | AD10: =+AC10-AB10 -> 22.565477 | AE10: =+H10/100 -> 305.31031 | AF10: =+AC10-AE10 -> 32.024081 | AG10: =+J10/100 -> 1076.6025 | AH10: =+K10/100 -> 1143.3588 | AI10: =+AH10-AG10 -> 66.75628 | AJ10: =+M10/100 -> 1200.3655 | AK10: =+AH10-AJ10 -> -57.00668
D11: 건자재 | E11: =+'[1]4월'!$AA$8/1000 -> 8929.3158 | F11: =+'[2]4월'!$AO$8/1000 -> 8822.0395 | G11: =+F11-E11 -> -107.2763 | H11: =+'[3]4월'!$AO$8/1000 -> 11408.615 | I11: =+F11-H11 -> -2586.5755 | J11: =+[4]손익총괄!J11+E11 -> 34136.773 | K11: =+[4]손익총괄!K11+F11 -> 31755.572 | L11: =+K11-J11 -> -2381.2002 | M11: =+[4]손익총괄!M11+H11 -> 41371.69 | N11: =+K11-M11 -> -9616.1171 | R11: 중부권 | S11: =+[5]중부권!$T$5/1000 -> 56.5 | T11: =+[5]중부권!$U$5/1000 -> 61.3025 | U11: =+T11-S11 -> 4.8025 | V11: =+[6]중부권!$T$5/1000 -> 59.1675 | W11: =+T11-V11 -> 2.135 | AA11: =+D11 -> 건자재 | AB11: =+E11/100 -> 89.293158 | AC11: =+F11/100 -> 88.220395 | AD11: =+AC11-AB11 -> -1.072763 | AE11: =+H11/100 -> 114.08615 | AF11: =+AC11-AE11 -> -25.865755 | AG11: =+J11/100 -> 341.36773 | AH11: =+K11/100 -> 317.55572 | AI11: =+AH11-AG11 -> -23.812002 | AJ11: =+M11/100 -> 413.7169 | AK11: =+AH11-AJ11 -> -96.161171
D12: 골재 | E12: =+'[1]4월'!$AE$8/1000 -> 1289.7261 | F12: =+'[2]4월'!$AN$8/1000 -> 1746.8204 | G12: =+F12-E12 -> 457.0943 | H12: =+'[3]4월'!$AN$8/1000 -> 1117.6776 | I12: =+F12-H12 -> 629.14281 | J12: =+[4]손익총괄!J12+E12 -> 5564.2229 | K12: =+[4]손익총괄!K12+F12 -> 6528.4296 | L12: =+K12-J12 -> 964.20667 | M12: =+[4]손익총괄!M12+H12 -> 4645.3089 | N12: =+K12-M12 -> 1883.1207 | Q12: 계 | S12: =SUM(S9:S11) -> 308.5 | T12: =SUM(T9:T11) -> 331.0375 | U12: =+T12-S12 -> 22.5375 | V12: =SUM(V9:V11) -> 322.7745 | W12: =+T12-V12 -> 8.263 | AA12: =+D12 -> 골재 | AB12: =+E12/100 -> 12.897261 | AC12: =+F12/100 -> 17.468204 | AD12: =+AC12-AB12 -> 4.570943 | AE12: =+H12/100 -> 11.176776 | AF12: =+AC12-AE12 -> 6.2914281 | AG12: =+J12/100 -> 55.642229 | AH12: =+K12/100 -> 65.284296 | AI12: =+AH12-AG12 -> 9.6420667 | AJ12: =+M12/100 -> 46.453089 | AK12: =+AH12-AJ12 -> 18.831207
D13: 기타 | E13: =+'[1]4월'!$E$8/1000-E10-E11-E12 -> 164.9075 | F13: =+'[2]4월'!$F$8/1000-F10-F11-F12 -> 165.79909 | G13: =+F13-E13 -> 0.89159367 | H13: =+'[3]4월'!$F$8/1000-H10-H11-H12 -> 151.66082 | I13: =+F13-H13 -> 14.138273 | J13: =+[4]손익총괄!J13+E13 -> 659.63 | K13: =+[4]손익총괄!K13+F13 -> 659.35363 | L13: =+K13-J13 -> -0.27636933 | M13: =+[4]손익총괄!M13+H13 -> 697.53236 | N13: =+K13-M13 -> -38.178732 | Q13: 판매단가 | R13: 수도권 | S13: =+[5]수도권!$T$61 -> 100360.89 | T13: =+[5]수도권!$U$61 -> 99830.046 | U13: =+T13-S13 -> -530.8434 | V13: =+[6]수도권!$Q$85 -> 90663.317 | W13: =+T13-V13 -> 9166.7287 | AA13: =+D13 -> 기타 | AB13: =+E13/100 -> 1.649075 | AC13: =+F13/100 -> 1.6579909 | AD13: =+AC13-AB13 -> 0.0089159367 | AE13: =+H13/100 -> 1.5166082 | AF13: =+AC13-AE13 -> 0.14138273 | AG13: =+J13/100 -> 6.5963 | AH13: =+K13/100 -> 6.5935363 | AI13: =+AH13-AG13 -> -0.0027636933 | AJ13: =+M13/100 -> 6.9753236 | AK13: =+AH13-AJ13 -> -0.38178732
C14: 계 | E14: =SUM(E10:E13) -> 41860.841 | F14: =SUM(F10:F13) -> 44468.099 | G14: =+F14-E14 -> 2607.2573 | H14: =SUM(H10:H13) -> 43208.985 | I14: =+F14-H14 -> 1259.1137 | J14: =SUM(J10:J13) -> 148020.88 | K14: =SUM(K10:K13) -> 153279.24 | L14: =+K14-J14 -> 5258.3581 | M14: =SUM(M10:M13) -> 166751.08 | N14: =+K14-M14 -> -13471.843 | R14: 영남권 | S14: =+[5]영남권!$T$61 -> 101814.88 | T14: =+[5]영남권!$U$61 -> 101618.83 | U14: =+T14-S14 -> -196.04242 | V14: =+[6]영남권!$Q$85 -> 95926.79 | W14: =+T14-V14 -> 5692.0451 | AA14: 계 | AB14: =SUM(AB10:AB13) -> 418.60841 | AC14: =SUM(AC10:AC13) -> 444.68099 | AD14: =+AC14-AB14 -> 26.072573 | AE14: =SUM(AE10:AE13) -> 432.08985 | AF14: =+AC14-AE14 -> 12.591137 | AG14: =SUM(AG10:AG13) -> 1480.2088 | AH14: =SUM(AH10:AH13) -> 1532.7924 | AI14: =+AH14-AG14 -> 52.583581 | AJ14: =SUM(AJ10:AJ13) -> 1667.5108 | AK14: =+AH14-AJ14 -> -134.71843
C15: 매출원가 | D15: 레미콘 | E15: =+('[1]4월'!$Z$10+'[1]4월'!$Z$19)/1000 -> 25958.207 | F15: =+('[2]4월'!$Z$10+'[2]4월'!$Z$19)/1000 -> 28415.357 | G15: =+F15-E15 -> 2457.1506 | H15: =+('[3]4월'!$Z$10+'[3]4월'!$Z$19)/1000 -> 25278.904 | I15: =+F15-H15 -> 3136.4528 | J15: =+[4]손익총괄!J15+E15 -> 91757.224 | K15: =+[4]손익총괄!K15+F15 -> 99332.256 | L15: =+K15-J15 -> 7575.032 | M15: =+[4]손익총괄!M15+H15 -> 100333.61 | N15: =+K15-M15 -> -1001.3587 | R15: 중부권 | S15: =+[5]중부권!$T$61 -> 106153.21 | T15: =+[5]중부권!$U$61 -> 106728.9 | U15: =+T15-S15 -> 575.69182 | V15: =+[6]중부권!$Q$85 -> 99528.287 | W15: =+T15-V15 -> 7200.6149 | Z15: 영업이익 | AA15: =+D30 -> 레미콘 | AB15: =+E30/100 -> 48.677991 | AC15: =+F30/100 -> 46.352462 | AD15: =+AC15-AB15 -> -2.3255294 | AE15: =+H30/100 -> 45.732553 | AF15: =+AC15-AE15 -> 0.61990848 | AG15: =+J30/100 -> 132.42904 | AH15: =+K30/100 -> 123.48634 | AI15: =+AH15-AG15 -> -8.9427035 | AJ15: =+M30/100 -> 170.39325 | AK15: =+AH15-AJ15 -> -46.906916
D16: 건자재 | E16: =+('[1]4월'!$AA$10+'[1]4월'!$AA$19)/1000 -> 8700.4423 | F16: =+('[2]4월'!$AO$10+'[2]4월'!$AO$19)/1000 -> 8659.0858 | G16: =+F16-E16 -> -41.356498 | H16: =+('[3]4월'!$AO$10+'[3]4월'!$AO$19)/1000 -> 11171.508 | I16: =+F16-H16 -> -2512.4226 | J16: =+[4]손익총괄!J16+E16 -> 33262.448 | K16: =+[4]손익총괄!K16+F16 -> 31058.81 | L16: =+K16-J16 -> -2203.6377 | M16: =+[4]손익총괄!M16+H16 -> 40559.505 | N16: =+K16-M16 -> -9500.6948 | Q16: 계 | S16: =+[5]합계!$T$61 -> 102032.06 | T16: =+[5]합계!$U$61 -> 101892.73 | U16: =+T16-S16 -> -139.33146 | V16: =+[6]합계!$Q$85 -> 94591.926 | W16: =+T16-V16 -> 7300.8073 | AA16: =+D31 -> % | AB16: =+E31 -> 0.15464675 | AC16: =+F31 -> 0.13740805 | AD16: =+AC16-AB16 -> -0.017238702 | AE16: =+H31 -> 0.1497904 | AF16: =+AC16-AE16 -> -0.012382346 | AG16: =+J31 -> 0.12300644 | AH16: =+K31 -> 0.10800314 | AI16: =+AH16-AG16 -> -0.015003301 | AJ16: =+M31 -> 0.14195114 | AK16: =+AH16-AJ16 -> -0.033948007
D17: 골재 | E17: =+('[1]4월'!$AE$10+'[1]4월'!$AE$19)/1000 -> 1154.4604 | F17: =+('[2]4월'!$AN$10+'[2]4월'!$AN$19)/1000 -> 1547.4416 | G17: =+F17-E17 -> 392.98121 | H17: =+('[3]4월'!$AN$10+'[3]4월'!$AN$19)/1000 -> 945.95219 | I17: =+F17-H17 -> 601.4894 | J17: =+[4]손익총괄!J17+E17 -> 5123.3877 | K17: =+[4]손익총괄!K17+F17 -> 5776.7521 | L17: =+K17-J17 -> 653.3644 | M17: =+[4]손익총괄!M17+H17 -> 4101.3853 | N17: =+K17-M17 -> 1675.3667 | Q17: 공헌이익 | R17: 수도권 | S17: =+[5]수도권!$Q$90 -> 22648.608 | T17: =+[5]수도권!$R$90 -> 19731.47 | U17: =+T17-S17 -> -2917.1378 | V17: =+[6]수도권!$Q$90 -> 18498.113 | W17: =+T17-V17 -> 1233.3569 | AA17: =+D32 -> 건자재 | AB17: =+E32/100 -> 1.0736944 | AC17: =+F32/100 -> -0.06182668 | AD17: =+AC17-AB17 -> -1.1355211 | AE17: =+H32/100 -> 1.1639871 | AF17: =+AC17-AE17 -> -1.2258137 | AG17: =+J32/100 -> 3.6770904 | AH17: =+K32/100 -> 1.4258457 | AI17: =+AH17-AG17 -> -2.2512447 | AJ17: =+M32/100 -> 3.2260278 | AK17: =+AH17-AJ17 -> -1.8001821
D18: 기타 | E18: =+('[1]4월'!$E$10+'[1]4월'!$E$19)/1000-E15-E16-E17 -> 65.289347 | F18: =+('[2]4월'!$F$10+'[2]4월'!$F$19)/1000-F15-F16-F17 -> 28.446048 | G18: =+F18-E18 -> -36.843299 | H18: =+('[3]4월'!$F$10+'[3]4월'!$F$19)/1000-H15-H16-H17 -> 24.65423 | I18: =+F18-H18 -> 3.791818 | J18: =+[4]손익총괄!J18+E18 -> 172.61402 | K18: =+[4]손익총괄!K18+F18 -> 99.923078 | L18: =+K18-J18 -> -72.690942 | M18: =+[4]손익총괄!M18+H18 -> 56.103694 | N18: =+K18-M18 -> 43.819384 | R18: 영남권 | S18: =+[5]영남권!$Q$90 -> 26393.369 | T18: =+[5]영남권!$R$90 -> 23376.451 | U18: =+T18-S18 -> -3016.9183 | V18: =+[6]영남권!$Q$90 -> 24977.735 | W18: =+T18-V18 -> -1601.2841 | AA18: =+D33 -> 골재 | AB18: =+E33/100 -> 0.047376714 | AC18: =+F33/100 -> 1.5387745 | AD18: =+AC18-AB18 -> 1.4913977 | AE18: =+H33/100 -> 1.3387515 | AF18: =+AC18-AE18 -> 0.20002296 | AG18: =+J33/100 -> 1.0872357 | AH18: =+K33/100 -> 5.7299814 | AI18: =+AH18-AG18 -> 4.6427457 | AJ18: =+M33/100 -> 4.4935755 | AK18: =+AH18-AJ18 -> 1.2364059
C19: 계 | E19: =SUM(E15:E18) -> 35878.399 | F19: =SUM(F15:F18) -> 38650.331 | G19: =+F19-E19 -> 2771.932 | H19: =SUM(H15:H18) -> 37421.019 | I19: =+F19-H19 -> 1229.3114 | J19: =SUM(J15:J18) -> 130315.67 | K19: =SUM(K15:K18) -> 136267.74 | L19: =+K19-J19 -> 5952.0678 | M19: =SUM(M15:M18) -> 145050.61 | N19: =+K19-M19 -> -8782.8674 | R19: 중부권 | S19: =+[5]중부권!$Q$90 -> 30392.701 | T19: =+[5]중부권!$R$90 -> 31984.708 | U19: =+T19-S19 -> 1592.007 | V19: =+[6]중부권!$Q$90 -> 30457.499 | W19: =+T19-V19 -> 1527.2095 | AA19: =+D34 -> 기타 | AB19: =+E34/100 -> -15.239123 | AC19: =+F34/100 -> -14.805656 | AD19: =+AC19-AB19 -> 0.43346748 | AE19: =+H34/100 -> -12.834429 | AF19: =+AC19-AE19 -> -1.9712268 | AG19: =+J34/100 -> -49.518756 | AH19: =+K34/100 -> -66.10822 | AI19: =+AH19-AG19 -> -16.589464 | AJ19: =+M34/100 -> -42.509068 | AK19: =+AH19-AJ19 -> -23.599153
C20: 매출이익 | D20: 레미콘 | E20: =+E10-E15 -> 5518.6853 | F20: =+F10-F15 -> 5318.0824 | G20: =+F20-E20 -> -200.60286 | H20: =+H10-H15 -> 5252.1271 | I20: =+F20-H20 -> 65.955301 | J20: =+J10-J15 -> 15903.028 | K20: =+K10-K15 -> 15003.624 | L20: =+K20-J20 -> -899.404 | M20: =+M10-M15 -> 19702.933 | N20: =+K20-M20 -> -4699.3093 | Q20: 계 | S20: =+[5]합계!$Q$90 -> 25638.844 | T20: =+[5]합계!$R$90 -> 23604.168 | U20: =+T20-S20 -> -2034.6765 | V20: =+[6]합계!$Q$90 -> 23526.666 | W20: =+T20-V20 -> 77.502164 | AA20: 계 | AB20: =+AB15+AB17+AB18+AB19 -> 34.559939 | AC20: =+AC15+AC17+AC18+AC19 -> 33.023754 | AD20: =+AC20-AB20 -> -1.5361853 | AE20: =+AE15+AE17+AE18+AE19 -> 35.400863 | AF20: =+AC20-AE20 -> -2.3771091 | AG20: =+AG15+AG17+AG18+AG19 -> 87.674611 | AH20: =+AH15+AH17+AH18+AH19 -> 64.533944 | AI20: =+AH20-AG20 -> -23.140667 | AJ20: =+AJ15+AJ17+AJ18+AJ19 -> 135.60379 | AK20: =+AH20-AJ20 -> -71.069845
D21: 건자재 | E21: =+E11-E16 -> 228.8735 | F21: =+F11-F16 -> 162.9537 | G21: =+F21-E21 -> -65.919799 | H21: =+H11-H16 -> 237.10661 | I21: =+F21-H21 -> -74.15291 | J21: =+J11-J16 -> 874.32465 | K21: =+K11-K16 -> 696.76215 | L21: =+K21-J21 -> -177.56251 | M21: =+M11-M16 -> 812.18453 | N21: =+K21-M21 -> -115.42238 | Q21: □ 건자재 | AA21: =+D36 -> % | AB21: =+E36 -> 0.082559112 | AC21: =+F36 -> 0.074263921 | AD21: =+G36 -> -0.0082951911 | AE21: =+H36 -> 0.081929401 | AF21: =+I36 -> -0.0076654804 | AG21: =+J36 -> 0.059231247 | AH21: =+K36 -> 0.042102209 | ... AK21: =+N36 -> -0.039218878
D22: 골재 | E22: =+E12-E17 -> 135.26573 | F22: =+F12-F17 -> 199.37882 | G22: =+F22-E22 -> 64.113084 | H22: =+H12-H17 -> 171.72541 | I22: =+F22-H22 -> 27.653407 | J22: =+J12-J17 -> 440.83526 | K22: =+K12-K17 -> 751.67753 | L22: =+K22-J22 -> 310.84227 | M22: =+M12-M17 -> 543.92359 | N22: =+K22-M22 -> 207.75393 | Q22: 구분 | S22: 계획 | T22: 실적 | U22: 계획대비 | V22: 전년 | W22: 전년대비 | Z22: * 4월누계 기타차이 : 대손 16억
D23: 기타 | E23: =+E13-E18 -> 99.618153 | F23: =+F13-F18 -> 137.35305 | G23: =+F23-E23 -> 37.734893 | H23: =+H13-H18 -> 127.00659 | I23: =+F23-H23 -> 10.346455 | J23: =+J13-J18 -> 487.01598 | K23: =+K13-K18 -> 559.43055 | L23: =+K23-J23 -> 72.414573 | M23: =+M13-M18 -> 641.42867 | N23: =+K23-M23 -> -81.998116 | Q23: 철강재 판매단가 | S23: =+'[7]4월'!$F$10 -> 978767.12 | T23: =+'[7]4월'!$G$10 -> 853042.91 | U23: =+T23-S23 -> -125724.22 | V23: =+'[8]4월'!$G$10 -> 1048311.1 | W23: =+T23-V23 -> -195268.22
C24: 계 | E24: =SUM(E20:E23) -> 5982.4427 | F24: =SUM(F20:F23) -> 5817.768 | G24: =+F24-E24 -> -164.67468 | H24: =SUM(H20:H23) -> 5787.9657 | I24: =+F24-H24 -> 29.802253 | J24: =SUM(J20:J23) -> 17705.204 | K24: =SUM(K20:K23) -> 17011.494 | L24: =+K24-J24 -> -693.70967 | M24: =SUM(M20:M23) -> 21700.47 | N24: =+K24-M24 -> -4688.9758 | Q24: 철강재 마진률 | S24: =+'[7]4월'!$F$15 -> 0.023347096 | T24: =+'[7]4월'!$G$15 -> 0.018146921 | U24: =+T24-S24 -> -0.0052001748 | V24: =+'[8]4월'!$G$15 -> 0.021217441 | W24: =+T24-V24 -> -0.0030705196
C25: 판관비 | D25: 레미콘 | E25: =+('[1]4월'!$Z$13+'[1]4월'!$Z$20)/1000 -> 650.88616 | F25: =+('[2]4월'!$Z$13+'[2]4월'!$Z$20)/1000 -> 682.83624 | G25: =+F25-E25 -> 31.950081 | H25: =+('[3]4월'!$Z$13+'[3]4월'!$Z$20)/1000 -> 678.87179 | I25: =+F25-H25 -> 3.964453 | J25: =+[4]손익총괄!J25+E25 -> 2660.1239 | K25: =+[4]손익총괄!K25+F25 -> 2654.9903 | L25: =+K25-J25 -> -5.133653 | M25: =+[4]손익총괄!M25+H25 -> 2663.6079 | N25: =+K25-M25 -> -8.61763 | Q25: □ 골재
D26: 건자재 | E26: =+('[1]4월'!$AA$13+'[1]4월'!$AA$20)/1000 -> 121.50406 | F26: =+('[2]4월'!$AO$13+'[2]4월'!$AO$20)/1000 -> 169.13637 | G26: =+F26-E26 -> 47.632312 | H26: =+('[3]4월'!$AO$13+'[3]4월'!$AO$20)/1000 -> 120.70791 | I26: =+F26-H26 -> 48.428464 | J26: =+[4]손익총괄!J26+E26 -> 506.61561 | K26: =+[4]손익총괄!K26+F26 -> 554.17758 | L26: =+K26-J26 -> 47.561969 | M26: =+[4]손익총괄!M26+H26 -> 489.58175 | N26: =+K26-M26 -> 64.595831 | Q26: 구분 | S26: 계획 | T26: 실적 | U26: 계획대비 | V26: 전년 | W26: 전년대비
D27: 골재 | E27: =+('[1]4월'!$AE$13+'[1]4월'!$AE$20+'[1]4월'!$AE$22)/1000 -> 130.52806 | F27: =+('[2]4월'!$AN$13+'[2]4월'!$AN$20+'[2]4월'!$AN$22)/1000 -> 45.501372 | G27: =+F27-E27 -> -85.02669 | H27: =+('[3]4월'!$AN$13+'[3]4월'!$AN$20+'[3]4월'!$AN$22)/1000 -> 37.850262 | I27: =+F27-H27 -> 7.6511105 | J27: =+[4]손익총괄!J27+E27 -> 332.11169 | K27: =+[4]손익총괄!K27+F27 -> 178.67939 | L27: =+K27-J27 -> -153.4323 | M27: =+[4]손익총괄!M27+H27 -> 94.566043 | N27: =+K27-M27 -> 84.113345 | Q27: 판매량 | R27: 자가 | S27: =(+'[9]서부산크라샤(당월)'!$N$66+'[9]부산모래장(당월)'!$Q$48+'[9]부산크라샤(당월)'!$N$66)/1000 -> 31.530283 | T27: =(+'[9]서부산크라샤(당월)'!$O$66+'[9]부산모래장(당월)'!$R$48+'[9]부산크라샤(당월)'!$O$66)/1000 -> 51.816 | U27: =+T27-S27 -> 20.285717 | V27: =('[10]부산골재(당월)'!$R$48+'[10]서부산골재(당월)'!$O$66+'[10]부산크라샤(당월)'!$O$66)/1000 -> 32.34 | W27: =+T27-V27 -> 19.476
D28: 기타 | E28: =+('[1]4월'!$E$13+'[1]4월'!$E$20)/1000-E25-E26-E27+('[1]4월'!$E$22/1000) -> 1623.5305 | F28: =+('[2]4월'!$F$13+'[2]4월'!$F$20)/1000-F25-F26-F27+'[2]4월'!$F$22/1000 -> 1617.9186 | G28: =+F28-E28 -> -5.6118551 | H28: =+('[3]4월'!$F$13+'[3]4월'!$F$20)/1000-H25-H26-H27+'[3]4월'!$F$22/1000 -> 1410.4495 | I28: =+F28-H28 -> 207.46914 | J28: =+[4]손익총괄!J28+E28 -> 5438.8916 | K28: =+[4]손익총괄!K28+F28 -> 7170.2526 | L28: =+K28-J28 -> 1731.361 | M28: =+[4]손익총괄!M28+H28 -> 4892.3354 | N28: =+K28-M28 -> 2277.9171 | R28: 외판 | S28: =(+'[9]서부산크라샤(당월)'!$N$59+'[9]부산모래장(당월)'!$Q$47+'[9]부산크라샤(당월)'!$N$59)/1000 -> 27.5 | T28: =(+'[9]서부산크라샤(당월)'!$O$59+'[9]부산모래장(당월)'!$R$47+'[9]부산크라샤(당월)'!$O$59)/1000 -> 34.527 | U28: =+T28-S28 -> 7.027 | V28: =+('[10]부산골재(당월)'!$R$47+'[10]서부산골재(당월)'!$O$59+'[10]부산크라샤(당월)'!$O$59)/1000 -> 25.899 | W28: =+T28-V28 -> 8.628
C29: 계 | E29: =SUM(E25:E28) -> 2526.4488 | F29: =SUM(F25:F28) -> 2515.3926 | G29: =+F29-E29 -> -11.056152 | H29: =SUM(H25:H28) -> 2247.8795 | I29: =+F29-H29 -> 267.51316 | J29: =SUM(J25:J28) -> 8937.7428 | K29: =SUM(K25:K28) -> 10558.1 | L29: =+K29-J29 -> 1620.357 | M29: =SUM(M25:M28) -> 8140.0912 | N29: =+K29-M29 -> 2418.0087 | Q29: 합 계 | S29: =SUM(S27:S28) -> 59.030283 | T29: =SUM(T27:T28) -> 86.343 | U29: =+T29-S29 -> 27.312717 | V29: =SUM(V27:V28) -> 58.239 | W29: =+T29-V29 -> 28.104
C30: 영업이익 | D30: 레미콘 | E30: =+E20-E25 -> 4867.7991 | F30: =+F20-F25 -> 4635.2462 | G30: =+F30-E30 -> -232.55294 | H30: =+H20-H25 -> 4573.2553 | I30: =+F30-H30 -> 61.990848 | J30: =+J20-J25 -> 13242.904 | K30: =+K20-K25 -> 12348.634 | L30: =+K30-J30 -> -894.27035 | M30: =+M20-M25 -> 17039.325 | N30: =+K30-M30 -> -4690.6916 | Q30: □ 기타내역(영업이익)
D31: % | E31: =+E30/E10 -> 0.15464675 | F31: =+F30/F10 -> 0.13740805 | G31: =+F31-E31 -> -0.017238702 | H31: =+H30/H10 -> 0.1497904 | I31: =+F31-H31 -> -0.012382346 | J31: =+J30/J10 -> 0.12300644 | K31: =+K30/K10 -> 0.10800314 | L31: =+K31-J31 -> -0.015003301 | M31: =+M30/M10 -> 0.14195114 | N31: =+K31-M31 -> -0.033948007 | Q31: 구분 | S31: 계획 | T31: 실적 | U31: 계획대비 | V31: 전년 | W31: 전년대비
D32: 건자재 | E32: =+E21-E26 -> 107.36944 | F32: =+F21-F26 -> -6.182668 | G32: =+F32-E32 -> -113.55211 | H32: =+H21-H26 -> 116.39871 | I32: =+F32-H32 -> -122.58137 | J32: =+J21-J26 -> 367.70904 | K32: =+K21-K26 -> 142.58457 | L32: =+K32-J32 -> -225.12447 | M32: =+M21-M26 -> 322.60278 | N32: =+K32-M32 -> -180.01821 | Q32: 레미콘임대 | S32: =+'사업장별(당월)'!T33 -> 72.210526 | T32: =+'사업장별(당월)'!U33 -> 71.958667 | U32: =+T32-S32 -> -0.251859 | V32: =+'사업장별(당월)'!W33 -> 63.066593 | W32: =+T32-V32 -> 8.892074
D33: 골재 | E33: =+E22-E27 -> 4.7376714 | F33: =+F22-F27 -> 153.87745 | G33: =+F33-E33 -> 149.13977 | H33: =+H22-H27 -> 133.87515 | I33: =+F33-H33 -> 20.002296 | J33: =+J22-J27 -> 108.72357 | K33: =+K22-K27 -> 572.99814 | L33: =+K33-J33 -> 464.27457 | M33: =+M22-M27 -> 449.35755 | N33: =+K33-M33 -> 123.64059 | Q33: 임대 | S33: =+'사업장별(당월)'!T34 -> 62.045457 | T33: =+'사업장별(당월)'!U34 -> 63.157758 | U33: =+T33-S33 -> 1.1123007 | V33: =+'사업장별(당월)'!W34 -> 34.773534 | W33: =+T33-V33 -> 28.384224
D34: 기타 | E34: =+E23-E28 -> -1523.9123 | F34: =+F23-F28 -> -1480.5656 | G34: =+F34-E34 -> 43.346748 | H34: =+H23-H28 -> -1283.4429 | I34: =+F34-H34 -> -197.12268 | J34: =+J23-J28 -> -4951.8756 | K34: =+K23-K28 -> -6610.822 | L34: =+K34-J34 -> -1658.9464 | M34: =+M23-M28 -> -4250.9068 | N34: =+K34-M34 -> -2359.9153 | Q34: 공통비 | S34: =+'사업장별(당월)'!T35 -> -1543.1733 | T34: =+'사업장별(당월)'!U35 -> -1567.4228 | U34: =+T34-S34 -> -24.249535 | V34: =+'사업장별(당월)'!W35 -> -1336.3393 | W34: =+T34-V34 -> -231.08351
C35: 계 | E35: =SUM(E30,E32:E34) -> 3455.9939 | F35: =SUM(F30,F32:F34) -> 3302.3754 | G35: =+F35-E35 -> -153.61853 | H35: =SUM(H30,H32:H34) -> 3540.0863 | I35: =+F35-H35 -> -237.71091 | J35: =SUM(J30,J32:J34) -> 8767.4611 | K35: =SUM(K30,K32:K34) -> 6453.3944 | L35: =+K35-J35 -> -2314.0667 | M35: =SUM(M30,M32:M34) -> 13560.379 | N35: =+K35-M35 -> -7106.9845 | Q35: 기타 | S35: =+S36-S32-S33-S34 -> -114.99503 | T35: =+T36-T32-T33-T34 -> -48.259192 | U35: =+T35-S35 -> 66.735841 | V35: =+V36-V32-V33-V34 -> -44.943727 | W35: =+T35-V35 -> -3.315465
D36: % | E36: =+E35/E14 -> 0.082559112 | F36: =+F35/F14 -> 0.074263921 | G36: =+F36-E36 -> -0.0082951911 | H36: =+H35/H14 -> 0.081929401 | I36: =+F36-H36 -> -0.0076654804 | J36: =+J35/J14 -> 0.059231247 | K36: =+K35/K14 -> 0.042102209 | L36: =+K36-J36 -> -0.017129038 | M36: =+M35/M14 -> 0.081321087 | N36: =+K36-M36 -> -0.039218878 | Q36: 합계 | S36: =+'사업장별(당월)'!T41 -> -1523.9123 | T36: =+'사업장별(당월)'!U41 -> -1480.5656 | U36: =+T36-S36 -> 43.346748 | V36: =+'사업장별(당월)'!W41 -> -1283.4429 | W36: =+T36-V36 -> -197.12268
E38: =+'[1]4월'!$E$26/1000 -> 3455.9939 | F38: =+'[2]4월'!$F$26/1000 -> 3302.3754 | H38: =+'[3]4월'!$F$26/1000 -> 3540.0863 | J38: =+[4]손익총괄!J38+E38 -> 8767.4611 | K38: =+[4]손익총괄!K38+F38 -> 6453.3944 | M38: =+[4]손익총괄!M38+H38 -> 13560.379
E39: =+E35=E38 -> TRUE | F39: =+F35=F38 -> TRUE | H39: =+H35=H38 -> FALSE | J39: =+J35=J38 -> FALSE | K39: =+K35=K38 -> TRUE | M39: =+M35=M38 -> TRUE
E40: =+E35-E38 -> 3.6379788e-12 | F40: =+F35-F38 -> 0 | H40: =+H35-H38 -> 0 | J40: =+J35-J38 -> 0 | K40: =+K35-K38 -> 0 | M40: =+M35-M38 -> -2.910383e-11

Sheet 사업장별(당월)
H3: □ 사업장별 손익실적(2024-04)
AG4: [단위 : 천㎥, 톤, 백만원]
H5: 구분 | J5: 물량 | O5: 매출 | T5: 영업이익(공통비 배부전) | Y5: 판매단가 | AB5: 변동비 | AE5: 공헌이익
J6: 계획 | K6: 실적 | L6: 차이 | M6: 전년 | N6: 차이 | O6: 계획 | P6: 실적 | Q6: 차이 | R6: 전년 | S6: 차이 | T6: 계획 | U6: 실적 | V6: 차이 | W6: 전년 | X6: 차이 | Y6: 계획 | Z6: 실적 | AA6: 전년 | AB6: 계획 | AC6: 실적 | AD6: 전년 | AE6: 계획 | AF6: 실적 | AG6: 전년
B7: 안양 | G7: =+I7 -> 안양 | H7: 레미콘 | I7: 안양 | J7: =+IFERROR(HLOOKUP($B7,'[1]4월'!$D$6:$BN$259,2,),)/1000 -> 44 | K7: =+IFERROR(HLOOKUP($B7,'[2]4월'!$F$6:$CP$99,2,),)/1000 -> 46.247 | L7: =+K7-J7 -> 2.247 | M7: =+IFERROR(HLOOKUP($B7,'[3]4월'!$F$6:$CC$57,2,),)/1000 -> 40.841 | N7: =+K7-M7 -> 5.406 | O7: =+IFERROR(HLOOKUP($B7,'[1]4월'!$D$6:$BN$259,3,),)/1000 -> 4438.3754 | P7: =+IFERROR(HLOOKUP($B7,'[2]4월'!$F$6:$CP$99,3,),)/1000 -> 4615.8876 | Q7: =+P7-O7 -> 177.51222 | R7: =+IFERROR(HLOOKUP($B7,'[3]4월'!$F$6:$CC$57,3,),)/1000 -> 3686.7538 | S7: =+P7-R7 -> 929.13377 | T7: =+IFERROR(HLOOKUP($B7,'[1]4월'!$D$6:$BN$259,16,),)/1000 -> 683.70851 | U7: =+IFERROR(HLOOKUP($B7,'[2]4월'!$F$6:$CP$99,16,),)/1000 -> 589.76879 | V7: =+U7-T7 -> -93.939723 | W7: =+IFERROR(HLOOKUP($B7,'[3]4월'!$F$6:$CC$57,16,),)/1000 -> 469.33526 | X7: =+U7-W7 -> 120.43353 | Y7: =+[5]안양!$Q$85 -> 100872.17 | Z7: =+[5]안양!$R$85 -> 99791.14 | AA7: =+[6]안양!$Q$85 -> 90270.899 | AB7: =+[5]안양!$Q$89 -> 78602.538 | AC7: =+[5]안양!$R$89 -> 80207.362 | AD7: =+[6]안양!$Q$89 -> 71529.872 | AE7: =+Y7-AB7 -> 22269.629 | AF7: =+Z7-AC7 -> 19583.777 | AG7: =+AA7-AD7 -> 18741.028
B8: 인천 | G8: =+I8 -> 인천 | H8: 직영 | I8: 인천 | J8: =+IFERROR(HLOOKUP($B8,'[1]4월'!$D$6:$BN$259,2,),)/1000 -> 35 | K8: =+IFERROR(HLOOKUP($B8,'[2]4월'!$F$6:$CP$99,2,),)/1000 -> 30.095 | L8: =+K8-J8 -> -4.905 | M8: =+IFERROR(HLOOKUP($B8,'[3]4월'!$F$6:$CC$57,2,),)/1000 -> 38.927 | N8: =+K8-M8 -> -8.832 | O8: =+IFERROR(HLOOKUP($B8,'[1]4월'!$D$6:$BN$259,3,),)/1000 -> 3585.5504 | P8: =+IFERROR(HLOOKUP($B8,'[2]4월'!$F$6:$CP$99,3,),)/1000 -> 3074.4291 | Q8: =+P8-O8 -> -511.12129 | R8: =+IFERROR(HLOOKUP($B8,'[3]4월'!$F$6:$CC$57,3,),)/1000 -> 3633.2312 | S8: =+P8-R8 -> -558.80208 | T8: =+IFERROR(HLOOKUP($B8,'[1]4월'!$D$6:$BN$259,16,),)/1000 -> 464.55119 | U8: =+IFERROR(HLOOKUP($B8,'[2]4월'!$F$6:$CP$99,16,),)/1000 -> 331.00999 | V8: =+U8-T8 -> -133.54121 | W8: =+IFERROR(HLOOKUP($B8,'[3]4월'!$F$6:$CC$57,16,),)/1000 -> 404.48903 | X8: =+U8-W8 -> -73.479041 | Y8: =+[5]인천!$Q$85 -> 102444.3 | Z8: =+[5]인천!$R$85 -> 102157.47 | AA8: =+[6]인천!$Q$85 -> 93334.478 | AB8: =+[5]인천!$Q$89 -> 81049.736 | AC8: =+[5]인천!$R$89 -> 81515.983 | AD8: =+[6]인천!$Q$89 -> 75539.025 | AE8: =+Y8-AB8 -> 21394.562 | AF8: =+Z8-AC8 -> 20641.489 | AG8: =+AA8-AD8 -> 17795.454
B9: 파주 | G9: =+I9 -> 파주 | I9: 파주 | J9: =+IFERROR(HLOOKUP($B9,'[1]4월'!$D$6:$BN$259,2,),)/1000 -> 27 | K9: =+IFERROR(HLOOKUP($B9,'[2]4월'!$F$6:$CP$99,2,),)/1000 -> 28.573 | L9: =+K9-J9 -> 1.573 | M9: =+IFERROR(HLOOKUP($B9,'[3]4월'!$F$6:$CC$57,2,),)/1000 -> 21.85 | N9: =+K9-M9 -> 6.723 | O9: =+IFERROR(HLOOKUP($B9,'[1]4월'!$D$6:$BN$259,3,),)/1000 -> 2690.0066 | P9: =+IFERROR(HLOOKUP($B9,'[2]4월'!$F$6:$CP$99,3,),)/1000 -> 2775.4874 | Q9: =+P9-O9 -> 85.48075 | R9: =+IFERROR(HLOOKUP($B9,'[3]4월'!$F$6:$CC$57,3,),)/1000 -> 1956.2292 | S9: =+P9-R9 -> 819.2582 | T9: =+IFERROR(HLOOKUP($B9,'[1]4월'!$D$6:$BN$259,16,),)/1000 -> 397.01663 | U9: =+IFERROR(HLOOKUP($B9,'[2]4월'!$F$6:$CP$99,16,),)/1000 -> 232.72628 | V9: =+U9-T9 -> -164.29034 | W9: =+IFERROR(HLOOKUP($B9,'[3]4월'!$F$6:$CC$57,16,),)/1000 -> 177.48992 | X9: =+U9-W9 -> 55.236366 | Y9: =+[5]파주!$Q$85 -> 99629.875 | Z9: =+[5]파주!$R$85 -> 97212.84 | AA9: =+[6]파주!$Q$85 -> 89411.337 | AB9: =+[5]파주!$Q$89 -> 76336.541 | AC9: =+[5]파주!$R$89 -> 81147.556 | AD9: =+[6]파주!$Q$89 -> 71640.462 | AE9: =+Y9-AB9 -> 23293.334 | AF9: =+Z9-AC9 -> 16065.284 | AG9: =+AA9-AD9 -> 17770.875
B10: 김포 | G10: =+I10 -> 김포 | I10: 김포 | J10: =+IFERROR(HLOOKUP($B10,'[1]4월'!$D$6:$BN$259,2,),)/1000 -> 16.5 | K10: =+IFERROR(HLOOKUP($B10,'[2]4월'!$F$6:$CP$99,2,),)/1000 -> 17.5985 | L10: =+K10-J10 -> 1.0985 | M10: =+IFERROR(HLOOKUP($B10,'[3]4월'!$F$6:$CC$57,2,),)/1000 -> 21.233 | N10: =+K10-M10 -> -3.6345 | O10: =+IFERROR(HLOOKUP($B10,'[1]4월'!$D$6:$BN$259,3,),)/1000 -> 1580.2765 | P10: =+IFERROR(HLOOKUP($B10,'[2]4월'!$F$6:$CP$99,3,),)/1000 -> 1762.1677 | Q10: =+P10-O10 -> 181.89122 | R10: =+IFERROR(HLOOKUP($B10,'[3]4월'!$F$6:$CC$57,3,),)/1000 -> 1864.2123 | S10: =+P10-R10 -> -102.04458 | T10: =+IFERROR(HLOOKUP($B10,'[1]4월'!$D$6:$BN$259,16,),)/1000 -> 249.30893 | U10: =+IFERROR(HLOOKUP($B10,'[2]4월'!$F$6:$CP$99,16,),)/1000 -> 272.51274 | V10: =+U10-T10 -> 23.203809 | W10: =+IFERROR(HLOOKUP($B10,'[3]4월'!$F$6:$CC$57,16,),)/1000 -> 260.0762 | X10: =+U10-W10 -> 12.436539 | Y10: =+[5]김포!$Q$85 -> 95774.333 | Z10: =+[5]김포!$R$85 -> 100131.7 | AA10: =+[6]김포!$Q$85 -> 87731.088 | AB10: =+[5]김포!$Q$89 -> 70510.023 | AC10: =+[5]김포!$R$89 -> 75716.071 | AD10: =+[6]김포!$Q$89 -> 67654.393 | AE10: =+Y10-AB10 -> 25264.311 | AF10: =+Z10-AC10 -> 24415.629 | AG10: =+AA10-AD10 -> 20076.695
B11: 부산 | G11: =+I11 -> 부산 | I11: 부산 | J11: =+IFERROR(HLOOKUP($B11,'[1]4월'!$D$6:$BN$259,2,),)/1000 -> 20 | K11: =+IFERROR(HLOOKUP($B11,'[2]4월'!$F$6:$CP$99,2,),)/1000 -> 22.909 | L11: =+K11-J11 -> 2.909 | M11: =+IFERROR(HLOOKUP($B11,'[3]4월'!$F$6:$CC$57,2,),)/1000 -> 24.5985 | N11: =+K11-M11 -> -1.6895 | O11: =+IFERROR(HLOOKUP($B11,'[1]4월'!$D$6:$BN$259,3,),)/1000 -> 2152.0023 | P11: =+IFERROR(HLOOKUP($B11,'[2]4월'!$F$6:$CP$99,3,),)/1000 -> 2386.548 | Q11: =+P11-O11 -> 234.54572 | R11: =+IFERROR(HLOOKUP($B11,'[3]4월'!$F$6:$CC$57,3,),)/1000 -> 2432.1745 | S11: =+P11-R11 -> -45.626522 | T11: =+IFERROR(HLOOKUP($B11,'[1]4월'!$D$6:$BN$259,16,),)/1000 -> 298.6259 | U11: =+IFERROR(HLOOKUP($B11,'[2]4월'!$F$6:$CP$99,16,),)/1000 -> 252.58252 | V11: =+U11-T11 -> -46.043374 | W11: =+IFERROR(HLOOKUP($B11,'[3]4월'!$F$6:$CC$57,16,),)/1000 -> 390.06814 | X11: =+U11-W11 -> -137.48562 | Y11: =+[5]부산!$Q$85 -> 107600.12 | Z11: =+[5]부산!$R$85 -> 104175.13 | AA11: =+[6]부산!$Q$85 -> 98874.913 | AB11: =+[5]부산!$Q$89 -> 79457.789 | AC11: =+[5]부산!$R$89 -> 81975.794 | AD11: =+[6]부산!$Q$89 -> 72722.724 | AE11: =+Y11-AB11 -> 28142.327 | AF11: =+Z11-AC11 -> 22199.335 | AG11: =+AA11-AD11 -> 26152.189
B12: 서부산 | G12: =+I12 -> 서부산 | I12: 서부산 | J12: =+IFERROR(HLOOKUP($B12,'[1]4월'!$D$6:$BN$259,2,),)/1000 -> 26 | K12: =+IFERROR(HLOOKUP($B12,'[2]4월'!$F$6:$CP$99,2,),)/1000 -> 25.12 | L12: =+K12-J12 -> -0.88 | M12: =+IFERROR(HLOOKUP($B12,'[3]4월'!$F$6:$CC$57,2,),)/1000 -> 19.461 | N12: =+K12-M12 -> 5.659 | O12: =+IFERROR(HLOOKUP($B12,'[1]4월'!$D$6:$BN$259,3,),)/1000 -> 2694.4035 | P12: =+IFERROR(HLOOKUP($B12,'[2]4월'!$F$6:$CP$99,3,),)/1000 -> 2565.4978 | Q12: =+P12-O12 -> -128.90574 | R12: =+IFERROR(HLOOKUP($B12,'[3]4월'!$F$6:$CC$57,3,),)/1000 -> 1977.2783 | S12: =+P12-R12 -> 588.2195 | T12: =+IFERROR(HLOOKUP($B12,'[1]4월'!$D$6:$BN$259,16,),)/1000 -> 469.94644 | U12: =+IFERROR(HLOOKUP($B12,'[2]4월'!$F$6:$CP$99,16,),)/1000 -> 358.97475 | V12: =+U12-T12 -> -110.97169 | W12: =+IFERROR(HLOOKUP($B12,'[3]4월'!$F$6:$CC$57,16,),)/1000 -> 304.20605 | X12: =+U12-W12 -> 54.768701 | Y12: =+[5]서부산!$Q$85 -> 103630.91 | Z12: =+[5]서부산!$R$85 -> 102129.69 | AA12: =+[6]서부산!$Q$85 -> 101602.09 | AB12: =+[5]서부산!$Q$89 -> 77500.939 | AC12: =+[5]서부산!$R$89 -> 78340.861 | AD12: =+[6]서부산!$Q$89 -> 75550.553 | AE12: =+Y12-AB12 -> 26129.967 | AF12: =+Z12-AC12 -> 23788.829 | AG12: =+AA12-AD12 -> 26051.539
B13: 김해 | G13: =+I13 -> 김해 | I13: 김해 | J13: =+IFERROR(HLOOKUP($B13,'[1]4월'!$D$6:$BN$259,2,),)/1000 -> 12 | K13: =+IFERROR(HLOOKUP($B13,'[2]4월'!$F$6:$CP$99,2,),)/1000 -> 17.236 | L13: =+K13-J13 -> 5.236 | M13: =+IFERROR(HLOOKUP($B13,'[3]4월'!$F$6:$CC$57,2,),)/1000 -> 14.88 | N13: =+K13-M13 -> 2.356 | O13: =+IFERROR(HLOOKUP($B13,'[1]4월'!$D$6:$BN$259,3,),)/1000 -> 1212.0024 | P13: =+IFERROR(HLOOKUP($B13,'[2]4월'!$F$6:$CP$99,3,),)/1000 -> 1721.9678 | Q13: =+P13-O13 -> 509.9654 | R13: =+IFERROR(HLOOKUP($B13,'[3]4월'!$F$6:$CC$57,3,),)/1000 -> 1389.396 | S13: =+P13-R13 -> 332.5718 | T13: =+IFERROR(HLOOKUP($B13,'[1]4월'!$D$6:$BN$259,16,),)/1000 -> 157.87535 | U13: =+IFERROR(HLOOKUP($B13,'[2]4월'!$F$6:$CP$99,16,),)/1000 -> 209.1524 | V13: =+U13-T13 -> 51.277043 | W13: =+IFERROR(HLOOKUP($B13,'[3]4월'!$F$6:$CC$57,16,),)/1000 -> 174.97551 | X13: =+U13-W13 -> 34.176888 | Y13: =+[5]김해!$Q$85 -> 101000.2 | Z13: =+[5]김해!$R$85 -> 99943.842 | AA13: =+[6]김해!$Q$85 -> 93382.343 | AB13: =+[5]김해!$Q$89 -> 76052.498 | AC13: =+[5]김해!$R$89 -> 79096.377 | AD13: =+[6]김해!$Q$89 -> 71780.878 | AE13: =+Y13-AB13 -> 24947.702 | AF13: =+Z13-AC13 -> 20847.465 | AG13: =+AA13-AD13 -> 21601.465
B14: 정관 | G14: =+I14 -> 정관 | I14: 정관 | J14: =+IFERROR(HLOOKUP($B14,'[1]4월'!$D$6:$BN$259,2,),)/1000 -> 18 | K14: =+IFERROR(HLOOKUP($B14,'[2]4월'!$F$6:$CP$99,2,),)/1000 -> 21.272 | L14: =+K14-J14 -> 3.272 | M14: =+IFERROR(HLOOKUP($B14,'[3]4월'!$F$6:$CC$57,2,),)/1000 -> 18.648 | N14: =+K14-M14 -> 2.624 | O14: =+IFERROR(HLOOKUP($B14,'[1]4월'!$D$6:$BN$259,3,),)/1000 -> 1872 | P14: =+IFERROR(HLOOKUP($B14,'[2]4월'!$F$6:$CP$99,3,),)/1000 -> 2214.5889 | Q14: =+P14-O14 -> 342.5889 | R14: =+IFERROR(HLOOKUP($B14,'[3]4월'!$F$6:$CC$57,3,),)/1000 -> 1832.643 | S14: =+P14-R14 -> 381.94588 | T14: =+IFERROR(HLOOKUP($B14,'[1]4월'!$D$6:$BN$259,16,),)/1000 -> 271.65616 | U14: =+IFERROR(HLOOKUP($B14,'[2]4월'!$F$6:$CP$99,16,),)/1000 -> 247.37615 | V14: =+U14-T14 -> -24.280008 | W14: =+IFERROR(HLOOKUP($B14,'[3]4월'!$F$6:$CC$57,16,),)/1000 -> 247.734 | X14: =+U14-W14 -> -0.357849 | Y14: =+[5]정관!$Q$85 -> 104000 | Z14: =+[5]정관!$R$85 -> 104108.17 | AA14: =+[6]정관!$Q$85 -> 98275.58 | AB14: =+[5]정관!$Q$89 -> 78162.091 | AC14: =+[5]정관!$R$89 -> 82781.134 | AD14: =+[6]정관!$Q$89 -> 74437.102 | AE14: =+Y14-AB14 -> 25837.909 | AF14: =+Z14-AC14 -> 21327.032 | AG14: =+AA14-AD14 -> 23838.478
B15: 양산 | G15: =+I15 -> 양산 | I15: 양산 | J15: =+IFERROR(HLOOKUP($B15,'[1]4월'!$D$6:$BN$259,2,),)/1000 -> 11 | K15: =+IFERROR(HLOOKUP($B15,'[2]4월'!$F$6:$CP$99,2,),)/1000 -> 12.804 | L15: =+K15-J15 -> 1.804 | M15: =+IFERROR(HLOOKUP($B15,'[3]4월'!$F$6:$CC$57,2,),)/1000 -> 14.434 | N15: =+K15-M15 -> -1.63 | O15: =+IFERROR(HLOOKUP($B15,'[1]4월'!$D$6:$BN$259,3,),)/1000 -> 1063.8695 | P15: =+IFERROR(HLOOKUP($B15,'[2]4월'!$F$6:$CP$99,3,),)/1000 -> 1198.3639 | Q15: =+P15-O15 -> 134.49447 | R15: =+IFERROR(HLOOKUP($B15,'[3]4월'!$F$6:$CC$57,3,),)/1000 -> 1350.3968 | S15: =+P15-R15 -> -152.0329 | T15: =+IFERROR(HLOOKUP($B15,'[1]4월'!$D$6:$BN$259,16,),)/1000 -> 155.33144 | U15: =+IFERROR(HLOOKUP($B15,'[2]4월'!$F$6:$CP$99,16,),)/1000 -> 114.7124 | V15: =+U15-T15 -> -40.619042 | W15: =+IFERROR(HLOOKUP($B15,'[3]4월'!$F$6:$CC$57,16,),)/1000 -> 245.54893 | X15: =+U15-W15 -> -130.83654 | Y15: =+[5]양산!$Q$85 -> 96715.406 | Z15: =+[5]양산!$R$85 -> 93592.935 | AA15: =+[6]양산!$Q$85 -> 93556.661 | AB15: =+[5]양산!$Q$89 -> 70432.272 | AC15: =+[5]양산!$R$89 -> 73554.02 | AD15: =+[6]양산!$Q$89 -> 66543.194 | AE15: =+Y15-AB15 -> 26283.134 | AF15: =+Z15-AC15 -> 20038.915 | AG15: =+AA15-AD15 -> 27013.467
B16: 창원 | G16: =+I16 -> 창원 | I16: 창원 | J16: =+IFERROR(HLOOKUP($B16,'[1]4월'!$D$6:$BN$259,2,),)/1000 -> 18 | K16: =+IFERROR(HLOOKUP($B16,'[2]4월'!$F$6:$CP$99,2,),)/1000 -> 19.1115 | L16: =+K16-J16 -> 1.1115 | M16: =+IFERROR(HLOOKUP($B16,'[3]4월'!$F$6:$CC$57,2,),)/1000 -> 22.036 | N16: =+K16-M16 -> -2.9245 | O16: =+IFERROR(HLOOKUP($B16,'[1]4월'!$D$6:$BN$259,3,),)/1000 -> 1793.0035 | P16: =+IFERROR(HLOOKUP($B16,'[2]4월'!$F$6:$CP$99,3,),)/1000 -> 1984.4876 | Q16: =+P16-O16 -> 191.48405 | R16: =+IFERROR(HLOOKUP($B16,'[3]4월'!$F$6:$CC$57,3,),)/1000 -> 2037.4773 | S16: =+P16-R16 -> -52.98975 | T16: =+IFERROR(HLOOKUP($B16,'[1]4월'!$D$6:$BN$259,16,),)/1000 -> 311.08833 | U16: =+IFERROR(HLOOKUP($B16,'[2]4월'!$F$6:$CP$99,16,),)/1000 -> 350.89098 | V16: =+U16-T16 -> 39.802646 | W16: =+IFERROR(HLOOKUP($B16,'[3]4월'!$F$6:$CC$57,16,),)/1000 -> 353.49433 | X16: =+U16-W16 -> -2.603346 | Y16: =+[5]창원!$Q$85 -> 99611.306 | Z16: =+[5]창원!$R$85 -> 103837.35 | AA16: =+[6]창원!$Q$85 -> 92461.304 | AB16: =+[5]창원!$Q$89 -> 71953.106 | AC16: =+[5]창원!$R$89 -> 74909.07 | AD16: =+[6]창원!$Q$89 -> 67635.834 | AE16: =+Y16-AB16 -> 27658.2 | AF16: =+Z16-AC16 -> 28928.282 | AG16: =+AA16-AD16 -> 24825.47
B17: 대구 | G17: =+I17 -> 대구 | I17: 대구 | J17: =+IFERROR(HLOOKUP($B17,'[1]4월'!$D$6:$BN$259,2,),)/1000 -> 16.5 | K17: =+IFERROR(HLOOKUP($B17,'[2]4월'!$F$6:$CP$99,2,),)/1000 -> 17.659 | L17: =+K17-J17 -> 1.159 | M17: =+IFERROR(HLOOKUP($B17,'[3]4월'!$F$6:$CC$57,2,),)/1000 -> 18.676 | N17: =+K17-M17 -> -1.017 | O17: =+IFERROR(HLOOKUP($B17,'[1]4월'!$D$6:$BN$259,3,),)/1000 -> 1613.7 | P17: =+IFERROR(HLOOKUP($B17,'[2]4월'!$F$6:$CP$99,3,),)/1000 -> 1760.5862 | Q17: =+P17-O17 -> 146.8862 | R17: =+IFERROR(HLOOKUP($B17,'[3]4월'!$F$6:$CC$57,3,),)/1000 -> 1734.6949 | S17: =+P17-R17 -> 25.89135 | T17: =+IFERROR(HLOOKUP($B17,'[1]4월'!$D$6:$BN$259,16,),)/1000 -> 287.40753 | U17: =+IFERROR(HLOOKUP($B17,'[2]4월'!$F$6:$CP$99,16,),)/1000 -> 287.68352 | V17: =+U17-T17 -> 0.27599061 | W17: =+IFERROR(HLOOKUP($B17,'[3]4월'!$F$6:$CC$57,16,),)/1000 -> 323.77131 | X17: =+U17-W17 -> -36.087791 | Y17: =+[5]대구!$Q$85 -> 97800 | Z17: =+[5]대구!$R$85 -> 99699.088 | AA17: =+[6]대구!$Q$85 -> 92883.639 | AB17: =+[5]대구!$Q$89 -> 69576.21 | AC17: =+[5]대구!$R$89 -> 73859.704 | AD17: =+[6]대구!$Q$89 -> 66659.106 | AE17: =+Y17-AB17 -> 28223.79 | AF17: =+Z17-AC17 -> 25839.384 | AG17: =+AA17-AD17 -> 26224.534
B18: 울산 | G18: =+I18 -> 울산 | I18: 울산 | J18: =+IFERROR(HLOOKUP($B18,'[1]4월'!$D$6:$BN$259,2,),)/1000 -> 8 | K18: =+IFERROR(HLOOKUP($B18,'[2]4월'!$F$6:$CP$99,2,),)/1000 -> 11.11 | L18: =+K18-J18 -> 3.11 | M18: =+IFERROR(HLOOKUP($B18,'[3]4월'!$F$6:$CC$57,2,),)/1000 -> 8.0225 | N18: =+K18-M18 -> 3.0875 | O18: =+IFERROR(HLOOKUP($B18,'[1]4월'!$D$6:$BN$259,3,),)/1000 -> 784.0454 | P18: =+IFERROR(HLOOKUP($B18,'[2]4월'!$F$6:$CP$99,3,),)/1000 -> 1127.6673 | Q18: =+P18-O18 -> 343.6219 | R18: =+IFERROR(HLOOKUP($B18,'[3]4월'!$F$6:$CC$57,3,),)/1000 -> 747.8462 | S18: =+P18-R18 -> 379.8211 | T18: =+IFERROR(HLOOKUP($B18,'[1]4월'!$D$6:$BN$259,16,),)/1000 -> 31.32769 | U18: =+IFERROR(HLOOKUP($B18,'[2]4월'!$F$6:$CP$99,16,),)/1000 -> 133.17269 | V18: =+U18-T18 -> 101.845 | W18: =+IFERROR(HLOOKUP($B18,'[3]4월'!$F$6:$CC$57,16,),)/1000 -> 40.734841 | X18: =+U18-W18 -> 92.437846 | Y18: =+[5]울산!$Q$85 -> 98005.675 | Z18: =+[5]울산!$R$85 -> 101500.21 | AA18: =+[6]울산!$Q$85 -> 93206.055 | AB18: =+[5]울산!$Q$89 -> 78179.89 | AC18: =+[5]울산!$R$89 -> 78272.849 | AD18: =+[6]울산!$Q$89 -> 71618.607 | AE18: =+Y18-AB18 -> 19825.785 | AF18: =+Z18-AC18 -> 23227.358 | AG18: =+AA18-AD18 -> 21587.448
B19: 아산 | G19: =+I19 -> 아산 | I19: 아산 | J19: =+IFERROR(HLOOKUP($B19,'[1]4월'!$D$6:$BN$259,2,),)/1000 -> 25 | K19: =+IFERROR(HLOOKUP($B19,'[2]4월'!$F$6:$CP$99,2,),)/1000 -> 30.069 | L19: =+K19-J19 -> 5.069 | M19: =+IFERROR(HLOOKUP($B19,'[3]4월'!$F$6:$CC$57,2,),)/1000 -> 26.625 | N19: =+K19-M19 -> 3.444 | O19: =+IFERROR(HLOOKUP($B19,'[1]4월'!$D$6:$BN$259,3,),)/1000 -> 2525.0038 | P19: =+IFERROR(HLOOKUP($B19,'[2]4월'!$F$6:$CP$99,3,),)/1000 -> 3153.8162 | Q19: =+P19-O19 -> 628.8124 | R19: =+IFERROR(HLOOKUP($B19,'[3]4월'!$F$6:$CC$57,3,),)/1000 -> 2530.0268 | S19: =+P19-R19 -> 623.7894 | T19: =+IFERROR(HLOOKUP($B19,'[1]4월'!$D$6:$BN$259,16,),)/1000 -> 411.17384 | U19: =+IFERROR(HLOOKUP($B19,'[2]4월'!$F$6:$CP$99,16,),)/1000 -> 538.83441 | V19: =+U19-T19 -> 127.66057 | W19: =+IFERROR(HLOOKUP($B19,'[3]4월'!$F$6:$CC$57,16,),)/1000 -> 543.39314 | X19: =+U19-W19 -> -4.558721 | Y19: =+[5]아산!$Q$85 -> 101000.15 | Z19: =+[5]아산!$R$85 -> 104707.69 | AA19: =+[6]아산!$Q$85 -> 95032.767 | AB19: =+[5]아산!$Q$89 -> 76085.87 | AC19: =+[5]아산!$R$89 -> 77280.259 | AD19: =+[6]아산!$Q$89 -> 66840.085 | AE19: =+Y19-AB19 -> 24914.282 | AF19: =+Z19-AC19 -> 27427.434 | AG19: =+AA19-AD19 -> 28192.681
B20: 전주 | G20: =+I20 -> 전주 | I20: 전주 | J20: =+IFERROR(HLOOKUP($B20,'[1]4월'!$D$6:$BN$259,2,),)/1000 -> 12 | K20: =+IFERROR(HLOOKUP($B20,'[2]4월'!$F$6:$CP$99,2,),)/1000 -> 9.772 | L20: =+K20-J20 -> -2.228 | M20: =+IFERROR(HLOOKUP($B20,'[3]4월'!$F$6:$CC$57,2,),)/1000 -> 12.6175 | N20: =+K20-M20 -> -2.8455 | O20: =+IFERROR(HLOOKUP($B20,'[1]4월'!$D$6:$BN$259,3,),)/1000 -> 1244.6852 | P20: =+IFERROR(HLOOKUP($B20,'[2]4월'!$F$6:$CP$99,3,),)/1000 -> 934.79442 | Q20: =+P20-O20 -> -309.89082 | R20: =+IFERROR(HLOOKUP($B20,'[3]4월'!$F$6:$CC$57,3,),)/1000 -> 1241.873 | S20: =+P20-R20 -> -307.07863 | T20: =+IFERROR(HLOOKUP($B20,'[1]4월'!$D$6:$BN$259,16,),)/1000 -> 207.03882 | U20: =+IFERROR(HLOOKUP($B20,'[2]4월'!$F$6:$CP$99,16,),)/1000 -> 98.974598 | V20: =+U20-T20 -> -108.06422 | W20: =+IFERROR(HLOOKUP($B20,'[3]4월'!$F$6:$CC$57,16,),)/1000 -> 227.09051 | X20: =+U20-W20 -> -128.11592 | Y20: =+[5]전주!$Q$85 -> 103723.77 | Z20: =+[5]전주!$R$85 -> 95671.078 | AA20: =+[6]전주!$Q$85 -> 98424.652 | AB20: =+[5]전주!$Q$89 -> 73824.767 | AC20: =+[5]전주!$R$89 -> 70537.059 | AD20: =+[6]전주!$Q$89 -> 68767.295 | AE20: =+Y20-AB20 -> 29899.003 | AF20: =+Z20-AC20 -> 25134.02 | AG20: =+AA20-AD20 -> 29657.357
B21: 군산 | G21: =+I21 -> 군산 | I21: 군산 | J21: =+IFERROR(HLOOKUP($B21,'[1]4월'!$D$6:$BN$259,2,),)/1000 -> 7.5 | K21: =+IFERROR(HLOOKUP($B21,'[2]4월'!$F$6:$CP$99,2,),)/1000 -> 10.98 | L21: =+K21-J21 -> 3.48 | M21: =+IFERROR(HLOOKUP($B21,'[3]4월'!$F$6:$CC$57,2,),)/1000 -> 8.262 | N21: =+K21-M21 -> 2.718 | O21: =+IFERROR(HLOOKUP($B21,'[1]4월'!$D$6:$BN$259,3,),)/1000 -> 820.36733 | P21: =+IFERROR(HLOOKUP($B21,'[2]4월'!$F$6:$CP$99,3,),)/1000 -> 1236.6071 | Q21: =+P21-O21 -> 416.23975 | R21: =+IFERROR(HLOOKUP($B21,'[3]4월'!$F$6:$CC$57,3,),)/1000 -> 809.2552 | S21: =+P21-R21 -> 427.35188 | T21: =+IFERROR(HLOOKUP($B21,'[1]4월'!$D$6:$BN$259,16,),)/1000 -> 225.71196 | U21: =+IFERROR(HLOOKUP($B21,'[2]4월'!$F$6:$CP$99,16,),)/1000 -> 393.17557 | V21: =+U21-T21 -> 167.46361 | W21: =+IFERROR(HLOOKUP($B21,'[3]4월'!$F$6:$CC$57,16,),)/1000 -> 170.62543 | X21: =+U21-W21 -> 222.55015 | Y21: =+[5]군산!$Q$85 -> 109382.31 | Z21: =+[5]군산!$R$85 -> 112623.6 | AA21: =+[6]군산!$Q$85 -> 97949.068 | AB21: =+[5]군산!$Q$89 -> 69401.039 | AC21: =+[5]군산!$R$89 -> 69227.207 | AD21: =+[6]군산!$Q$89 -> 65796.147 | AE21: =+Y21-AB21 -> 39981.273 | AF21: =+Z21-AC21 -> 43396.388 | AG21: =+AA21-AD21 -> 32152.921
B22: 원주 | G22: =+I22 -> 원주 | I22: 원주 | J22: =+IFERROR(HLOOKUP($B22,'[1]4월'!$D$6:$BN$259,2,),)/1000 -> 6 | K22: =+IFERROR(HLOOKUP($B22,'[2]4월'!$F$6:$CP$99,2,),)/1000 -> 6.9255 | L22: =+K22-J22 -> 0.9255 | M22: =+IFERROR(HLOOKUP($B22,'[3]4월'!$F$6:$CC$57,2,),)/1000 -> 3.9975 | N22: =+K22-M22 -> 2.928 | O22: =+IFERROR(HLOOKUP($B22,'[1]4월'!$D$6:$BN$259,3,),)/1000 -> 647.4 | P22: =+IFERROR(HLOOKUP($B22,'[2]4월'!$F$6:$CP$99,3,),)/1000 -> 765.70114 | Q22: =+P22-O22 -> 118.30115 | R22: =+IFERROR(HLOOKUP($B22,'[3]4월'!$F$6:$CC$57,3,),)/1000 -> 400.5802 | S22: =+P22-R22 -> 365.12095 | T22: =+IFERROR(HLOOKUP($B22,'[1]4월'!$D$6:$BN$259,16,),)/1000 -> 119.39039 | U22: =+IFERROR(HLOOKUP($B22,'[2]4월'!$F$6:$CP$99,16,),)/1000 -> 170.20888 | V22: =+U22-T22 -> 50.818489 | W22: =+IFERROR(HLOOKUP($B22,'[3]4월'!$F$6:$CC$57,16,),)/1000 -> 55.23525 | X22: =+U22-W22 -> 114.97363 | Y22: =+[5]원주!$Q$85 -> 107900 | Z22: =+[5]원주!$R$85 -> 110562.58 | AA22: =+[6]원주!$Q$85 -> 100207.68 | AB22: =+[5]원주!$Q$89 -> 72445.658 | AC22: =+[5]원주!$R$89 -> 72123.369 | AD22: =+[6]원주!$Q$89 -> 65419.534 | AE22: =+Y22-AB22 -> 35454.342 | AF22: =+Z22-AC22 -> 38439.211 | AG22: =+AA22-AD22 -> 34788.146
B23: 제주 | G23: =+I23 -> 제주 | I23: 제주 | J23: =+IFERROR(HLOOKUP($B23,'[1]4월'!$D$6:$BN$259,2,),)/1000 -> 6 | K23: =+IFERROR(HLOOKUP($B23,'[2]4월'!$F$6:$CP$99,2,),)/1000 -> 3.556 | L23: =+K23-J23 -> -2.444 | M23: =+IFERROR(HLOOKUP($B23,'[3]4월'!$F$6:$CC$57,2,),)/1000 -> 7.6655 | N23: =+K23-M23 -> -4.1095 | O23: =+IFERROR(HLOOKUP($B23,'[1]4월'!$D$6:$BN$259,3,),)/1000 -> 760.2 | P23: =+IFERROR(HLOOKUP($B23,'[2]4월'!$F$6:$CP$99,3,),)/1000 -> 454.84141 | Q23: =+P23-O23 -> -305.35859 | R23: =+IFERROR(HLOOKUP($B23,'[3]4월'!$F$6:$CC$57,3,),)/1000 -> 906.96266 | S23: =+P23-R23 -> -452.12124 | T23: =+IFERROR(HLOOKUP($B23,'[1]4월'!$D$6:$BN$259,16,),)/1000 -> 126.64 | U23: =+IFERROR(HLOOKUP($B23,'[2]4월'!$F$6:$CP$99,16,),)/1000 -> 53.489504 | V23: =+U23-T23 -> -73.150493 | W23: =+IFERROR(HLOOKUP($B23,'[3]4월'!$F$6:$CC$57,16,),)/1000 -> 184.98748 | X23: =+U23-W23 -> -131.49797 | Y23: =+[5]제주!$Q$85 -> 126700 | Z23: =+[5]제주!$R$85 -> 127908.16 | AA23: =+[6]제주!$Q$85 -> 118334.61 | AB23: =+[5]제주!$Q$89 -> 89540.511 | AC23: =+[5]제주!$R$89 -> 87547.524 | AD23: =+[6]제주!$Q$89 -> 82785.858 | AE23: =+Y23-AB23 -> 37159.489 | AF23: =+Z23-AC23 -> 40360.635 | AG23: =+AA23-AD23 -> 35548.749
G24: =+I24 -> 수도권 | I24: 수도권 | J24: =SUM(J7:J10) -> 122.5 | K24: =SUM(K7:K10) -> 122.5135 | L24: =+K24-J24 -> 0.0135 | M24: =SUM(M7:M10) -> 122.851 | N24: =+K24-M24 -> -0.3375 | O24: =SUM(O7:O10) -> 12294.209 | P24: =SUM(P7:P10) -> 12227.972 | Q24: =+P24-O24 -> -66.237096 | R24: =SUM(R7:R10) -> 11140.427 | S24: =+P24-R24 -> 1087.5453 | T24: =SUM(T7:T10) -> 1794.5853 | U24: =SUM(U7:U10) -> 1426.0178 | V24: =+U24-T24 -> -368.56747 | W24: =SUM(W7:W10) -> 1311.3904 | X24: =+U24-W24 -> 114.62739 | Y24: =+[5]수도권!$Q$85 -> 100360.89 | Z24: =+[5]수도권!$R$85 -> 99830.046 | AA24: =+[6]수도권!$Q$85 -> 90663.317 | AB24: =+[5]수도권!$Q$89 -> 77712.281 | AC24: =+[5]수도권!$R$89 -> 80098.575 | AD24: =+[6]수도권!$Q$89 -> 72165.204 | AE24: =+Y24-AB24 -> 22648.608 | AF24: =+Z24-AC24 -> 19731.47 | AG24: =+AA24-AD24 -> 18498.113
G25: =+I25 -> 영남권 | I25: 영남권 | J25: =SUM(J11:J18) -> 129.5 | K25: =SUM(K11:K18) -> 147.2215 | L25: =+K25-J25 -> 17.7215 | M25: =SUM(M11:M18) -> 140.756 | N25: =+K25-M25 -> 6.4655 | O25: =SUM(O11:O18) -> 13185.027 | P25: =SUM(P11:P18) -> 14959.708 | Q25: =+P25-O25 -> 1774.6809 | R25: =SUM(R11:R18) -> 13501.907 | S25: =+P25-R25 -> 1457.8005 | T25: =SUM(T11:T18) -> 1983.2588 | U25: =SUM(U11:U18) -> 1954.5454 | V25: =+U25-T25 -> -28.713438 | W25: =SUM(W11:W18) -> 2080.5331 | X25: =+U25-W25 -> -125.98771 | Y25: =+[5]영남권!$Q$85 -> 101814.88 | Z25: =+[5]영남권!$R$85 -> 101618.83 | AA25: =+[6]영남권!$Q$85 -> 95926.79 | AB25: =+[5]영남권!$Q$89 -> 75421.508 | AC25: =+[5]영남권!$R$89 -> 78242.384 | AD25: =+[6]영남권!$Q$89 -> 70949.055 | AE25: =+Y25-AB25 -> 26393.369 | AF25: =+Z25-AC25 -> 23376.451 | AG25: =+AA25-AD25 -> 24977.735
G26: =+I26 -> 중부권 | I26: 중부권 | J26: =SUM(J19:J23) -> 56.5 | K26: =SUM(K19:K23) -> 61.3025 | L26: =+K26-J26 -> 4.8025 | M26: =SUM(M19:M23) -> 59.1675 | N26: =+K26-M26 -> 2.135 | O26: =SUM(O19:O23) -> 5997.6564 | P26: =SUM(P19:P23) -> 6545.7603 | Q26: =+P26-O26 -> 548.10388 | R26: =SUM(R19:R23) -> 5888.6979 | S26: =+P26-R26 -> 657.06236 | T26: =SUM(T19:T23) -> 1089.955 | U26: =SUM(U19:U23) -> 1254.683 | V26: =+U26-T26 -> 164.72796 | W26: =SUM(W19:W23) -> 1181.3318 | X26: =+U26-W26 -> 73.351166 | Y26: =+[5]중부권!$Q$85 -> 106153.21 | Z26: =+[5]중부권!$R$85 -> 106728.9 | AA26: =+[6]중부권!$Q$85 -> 99528.287 | AB26: =+[5]중부권!$Q$89 -> 75760.509 | AC26: =+[5]중부권!$R$89 -> 74744.194 | AD26: =+[6]중부권!$Q$89 -> 69070.788 | AE26: =+Y26-AB26 -> 30392.701 | AF26: =+Z26-AC26 -> 31984.708 | AG26: =+AA26-AD26 -> 30457.499
G27: =+K27/J27 -> 1.0730551 | H27: 레미콘 계 | J27: =SUM(J24:J26) -> 308.5 | K27: =SUM(K24:K26) -> 331.0375 | L27: =+K27-J27 -> 22.5375 | M27: =SUM(M24:M26) -> 322.7745 | N27: =+K27-M27 -> 8.263 | O27: =SUM(O24:O26) -> 31476.892 | P27: =SUM(P24:P26) -> 33733.44 | Q27: =+P27-O27 -> 2256.5477 | R27: =SUM(R24:R26) -> 30531.031 | S27: =+P27-R27 -> 3202.4081 | T27: =SUM(T24:T26) -> 4867.7991 | U27: =SUM(U24:U26) -> 4635.2462 | V27: =+U27-T27 -> -232.55294 | W27: =SUM(W24:W26) -> 4573.2553 | X27: =+U27-W27 -> 61.990848 | Y27: =+[5]합계!$Q$85 -> 102032.06 | Z27: =+[5]합계!$R$85 -> 101892.73 | AA27: =+[6]합계!$Q$85 -> 94591.926 | AB27: =+[5]합계!$Q$89 -> 76393.22 | AC27: =+[5]합계!$R$89 -> 78288.565 | AD27: =+[6]합계!$Q$89 -> 71065.26 | AE27: =+Y27-AB27 -> 25638.844 | AF27: =+Z27-AC27 -> 23604.168 | AG27: =+AA27-AD27 -> 23526.666
B28: 건자재 | E28: 건자재영업 | G28: 건자재 | H28: 건자재 | J28: =+IFERROR(HLOOKUP($B28,'[1]4월'!$D$6:$BN$259,2,),) -> 7300 | K28: =+IFERROR(HLOOKUP($E28,'[2]4월'!$F$6:$CP$99,2,),) -> 8574.983 | L28: =+K28-J28 -> 1274.983 | M28: =+IFERROR(HLOOKUP($E28,'[3]4월'!$F$6:$CC$57,2,),) -> 9357.597 | N28: =+K28-M28 -> -782.614 | O28: =+IFERROR(HLOOKUP($B28,'[1]4월'!$D$6:$BN$259,3,),)/1000 -> 8929.3158 | P28: =+IFERROR(HLOOKUP($E28,'[2]4월'!$F$6:$CP$99,3,),)/1000 -> 8822.0395 | Q28: =+P28-O28 -> -107.2763 | R28: =+IFERROR(HLOOKUP($E28,'[3]4월'!$F$6:$CC$57,3,),)/1000 -> 11408.615 | S28: =+P28-R28 -> -2586.5755 | T28: =+IFERROR(HLOOKUP($B28,'[1]4월'!$D$6:$BN$259,16,),)/1000 -> 107.36944 | U28: =+IFERROR(HLOOKUP($E28,'[2]4월'!$F$6:$CP$99,16,),)/1000 -> -6.182668 | V28: =+U28-T28 -> -113.55211 | W28: =+IFERROR(HLOOKUP($E28,'[3]4월'!$F$6:$CC$57,16,),)/1000 -> 116.39871 | X28: =+U28-W28 -> -122.58137 | Y28: ■ 비고
B29: 부산모래장 | F29: 부산골재 | G29: =+I29 -> 부산모래장 | H29: 골재 | I29: 부산모래장 | J29: =+IFERROR(HLOOKUP($B29,'[1]4월'!$D$6:$BN$259,2,),)/1000 -> 17.196308 | K29: =+IFERROR(HLOOKUP($F29,'[2]4월'!$F$6:$CP$99,2,),)/1000 -> 20.579 | L29: =+K29-J29 -> 3.3826921 | M29: =+IFERROR(HLOOKUP($F29,'[3]4월'!$F$6:$CC$57,2,),)/1000 -> 22.427 | N29: =+K29-M29 -> -1.848 | O29: =+IFERROR(HLOOKUP($B29,'[1]4월'!$D$6:$BN$259,3,),)/1000 -> 539.08911 | P29: =+IFERROR(HLOOKUP($F29,'[2]4월'!$F$6:$CP$99,3,),)/1000 -> 653.70641 | Q29: =+P29-O29 -> 114.6173 | R29: =+IFERROR(HLOOKUP($F29,'[3]4월'!$F$6:$CC$57,3,),)/1000 -> 695.2956 | S29: =+P29-R29 -> -41.589192 | T29: =+IFERROR(HLOOKUP($B29,'[1]4월'!$D$6:$BN$259,21,),)/1000 -> 33.044389 | U29: =+IFERROR(HLOOKUP($F29,'[2]4월'!$F$6:$CP$99,21,),)/1000 -> 40.624192 | V29: =+U29-T29 -> 7.5798029 | W29: =+IFERROR(HLOOKUP($F29,'[3]4월'!$F$6:$CC$57,16,),)/1000 -> 69.539436 | X29: =+U29-W29 -> -28.915244
B30: 서부산크라샤 | F30: 서부산골재 | G30: =+I30 -> 서부산CR | I30: 서부산CR | J30: =+IFERROR(HLOOKUP($B30,'[1]4월'!$D$6:$BN$259,2,),)/1000 -> 0 | K30: =+IFERROR(HLOOKUP($F30,'[2]4월'!$F$6:$CP$99,2,),)/1000 -> 27.24 | L30: =+K30-J30 -> 27.24 | M30: =+IFERROR(HLOOKUP($F30,'[3]4월'!$F$6:$CC$57,2,),)/1000 -> 35.812 | N30: =+K30-M30 -> -8.572 | O30: =+IFERROR(HLOOKUP($B30,'[1]4월'!$D$6:$BN$259,3,),)/1000 -> 0 | P30: =+IFERROR(HLOOKUP($F30,'[2]4월'!$F$6:$CP$99,3,),)/1000 -> 382.248 | Q30: =+P30-O30 -> 382.248 | R30: =+IFERROR(HLOOKUP($F30,'[3]4월'!$F$6:$CC$57,3,),)/1000 -> 422.382 | S30: =+P30-R30 -> -40.134 | T30: =+IFERROR(HLOOKUP($B30,'[1]4월'!$D$6:$BN$259,21,),)/1000 -> -95.073313 | U30: =+IFERROR(HLOOKUP($F30,'[2]4월'!$F$6:$CP$99,21,),)/1000 -> 61.107316 | V30: =+U30-T30 -> 156.18063 | W30: =+IFERROR(HLOOKUP($F30,'[3]4월'!$F$6:$CC$57,16,),)/1000 -> 91.612904 | X30: =+U30-W30 -> -30.505588
B31: 부산크라샤 | F31: 부산크라샤 | G31: =+I31 -> 부산CR | I31: 부산CR | J31: =+IFERROR(HLOOKUP($B31,'[1]4월'!$D$6:$BN$259,2,),)/1000 -> 41.833975 | K31: =+IFERROR(HLOOKUP($F31,'[2]4월'!$F$6:$CP$99,2,),)/1000 -> 38.524 | L31: =+K31-J31 -> -3.3099753 | M31: =+IFERROR(HLOOKUP($F31,'[3]4월'!$F$6:$CC$57,2,),)/1000 -> 0 | N31: =+K31-M31 -> 38.524 | O31: =+IFERROR(HLOOKUP($B31,'[1]4월'!$D$6:$BN$259,3,),)/1000 -> 750.637 | P31: =+IFERROR(HLOOKUP($F31,'[2]4월'!$F$6:$CP$99,3,),)/1000 -> 710.866 | Q31: =+P31-O31 -> -39.770999 | R31: =+IFERROR(HLOOKUP($F31,'[3]4월'!$F$6:$CC$57,3,),)/1000 -> 0 | S31: =+P31-R31 -> 710.866 | T31: =+IFERROR(HLOOKUP($B31,'[1]4월'!$D$6:$BN$259,21,),)/1000 -> 66.766595 | U31: =+IFERROR(HLOOKUP($F31,'[2]4월'!$F$6:$CP$99,21,),)/1000 -> 52.145938 | V31: =+U31-T31 -> -14.620657 | W31: =+IFERROR(HLOOKUP($F31,'[3]4월'!$F$6:$CC$57,16,),)/1000 -> -27.277191 | X31: =+U31-W31 -> 79.423129
H32: 골재 계 | J32: =SUM(J29:J31) -> 59.030283 | K32: =SUM(K29:K31) -> 86.343 | L32: =+K32-J32 -> 27.312717 | M32: =SUM(M29:M31) -> 58.239 | N32: =+K32-M32 -> 28.104 | O32: =SUM(O29:O31) -> 1289.7261 | P32: =SUM(P29:P31) -> 1746.8204 | Q32: =+P32-O32 -> 457.0943 | R32: =SUM(R29:R31) -> 1117.6776 | S32: =+P32-R32 -> 629.14281 | T32: =SUM(T29:T31) -> 4.7376714 | U32: =SUM(U29:U31) -> 153.87745 | V32: =+U32-T32 -> 149.13977 | W32: =SUM(W29:W31) -> 133.87515 | X32: =+U32-W32 -> 20.002296
B33: 포항임대 | C33: 속초임대 | D33: 강릉임대 | E33: 레미콘임대 계 | G33: =+I33 -> 레미콘임대 | H33: 기타 | I33: 레미콘임대 | L33: =+K33-J33 -> 0 | N33: =+K33-M33 -> 0 | O33: =(IFERROR(HLOOKUP($B33,'[1]4월'!$D$6:$BN$259,3,),)++IFERROR(HLOOKUP($C33,'[1]4월'!$D$6:$BN$259,3,),)+IFERROR(HLOOKUP($D33,'[1]4월'!$D$6:$BN$259,3,),))/1000 -> 90.84 | P33: =+IFERROR(HLOOKUP($E33,'[2]4월'!$F$6:$CP$99,3,),)/1000 -> 90.84 | Q33: =+P33-O33 -> 0 | R33: =+IFERROR(HLOOKUP($E33,'[3]4월'!$F$6:$CC$57,3,),)/1000 -> 78.34 | S33: =+P33-R33 -> 12.5 | T33: =(IFERROR(HLOOKUP($B33,'[1]4월'!$D$6:$BN$259,21,),)++IFERROR(HLOOKUP($C33,'[1]4월'!$D$6:$BN$259,21,),)+IFERROR(HLOOKUP($D33,'[1]4월'!$D$6:$BN$259,21,),))/1000 -> 72.210526 | U33: =+IFERROR(HLOOKUP($E33,'[2]4월'!$F$6:$CP$99,16,),)/1000 -> 71.958667 | V33: =+U33-T33 -> -0.251859 | W33: =+IFERROR(HLOOKUP($E33,'[3]4월'!$F$6:$CC$57,16,),)/1000 -> 63.066593 | X33: =+U33-W33 -> 8.892074
B34: 부동산임대 | C34: 주유소임대 | E34: 임대 계 | G34: =+I34 -> 임대 | I34: 임대 | L34: =+K34-J34 -> 0 | M34: 0 | N34: =+K34-M34 -> 0 | O34: =(+IFERROR(HLOOKUP($B34,'[1]4월'!$D$6:$BN$259,3,),)+IFERROR(HLOOKUP($C34,'[1]4월'!$D$6:$BN$259,3,),))/1000 -> 72.2975 | P34: =+IFERROR(HLOOKUP($E34,'[2]4월'!$F$6:$CP$99,3,),)/1000 -> 73.256694 | Q34: =+P34-O34 -> 0.95919367 | R34: =+IFERROR(HLOOKUP($E34,'[3]4월'!$F$6:$CC$57,3,),)/1000 -> 71.577121 | S34: =+P34-R34 -> 1.679573 | T34: =(+IFERROR(HLOOKUP($B34,'[1]4월'!$D$6:$BN$259,21,),)+IFERROR(HLOOKUP($C34,'[1]4월'!$D$6:$BN$259,21,),))/1000 -> 62.045457 | U34: =+IFERROR(HLOOKUP($E34,'[2]4월'!$F$6:$CP$99,16,),)/1000 -> 63.157758 | V34: =+U34-T34 -> 1.1123007 | W34: =+IFERROR(HLOOKUP($E34,'[3]4월'!$F$6:$CC$57,16,),)/1000 -> 34.773534 | X34: =+U34-W34 -> 28.384224
B35: 공 통 비 | G35: =+I35 -> 공통비 | I35: 공통비 | L35: =+K35-J35 -> 0 | N35: =+K35-M35 -> 0 | Q35: =+P35-O35 -> 0 | S35: =+P35-R35 -> 0 | T35: =-'[1]4월'!$Z$22/1000 -> -1543.1733 | U35: =+-'[2]4월'!$Z$22/1000 -> -1567.4228 | V35: =+U35-T35 -> -24.249535 | W35: =+-'[3]4월'!$Z$22/1000 -> -1336.3393 | X35: =+U35-W35 -> -231.08351
G36: =+I36 -> OPC 소급분 | I36: OPC 소급분 | N36: =+K36-M36 -> 0 | Q36: =+P36-O36 -> 0 | S36: =+P36-R36 -> 0 | T36: =+'[1]4월'!$AS$26/1000 -> 0 | U36: =-'[2]4월'!$BD$26/1000 -> 0 | V36: =+U36-T36 -> 0 | W36: =-'[3]4월'!$BD$26/1000 -> 0 | X36: =+U36-W36 -> 0
G37: =+I37 -> 대손 | I37: 대손 | N37: =+K37-M37 -> 0 | Q37: =+P37-O37 -> 0 | S37: =+P37-R37 -> 0 | U37: ='[2]4월'!$BE$26/1000 -> 0 | V37: =+U37-T37 -> 0 | W37: ='[3]4월'!$BE$26/1000 -> 0 | X37: =+U37-W37 -> 0
G38: =+I38 -> 미운영 공장 | I38: 미운영 공장 | M38: =SUM(M54:M57) -> 0 | N38: =+K38-M38 -> 0 | Q38: =+P38-O38 -> 0 | S38: =+P38-R38 -> 0 | T38: =SUM('[1]4월'!$AM$26:$AQ$26)/1000 -> -35.713225 | U38: =+'[2]4월'!$BF$26/1000 -> -33.797813 | V38: =+U38-T38 -> 1.9154124 | W38: =+'[3]4월'!$BF$26/1000 -> -27.618783 | X38: =+U38-W38 -> -6.17903
B39: 기타 계 | G39: =+I39 -> 기타 | I39: 기타 | L39: =+K39-J39 -> 0 | N39: =+K39-M39 -> 0 | O39: =IFERROR(HLOOKUP($B39,'[1]4월'!$D$6:$BN$259,3,),)/1000 -> 1.77 | P39: =+('[2]4월'!$F$8-SUM('[2]4월'!$Z$8,'[2]4월'!$AH$8,'[2]4월'!$AN$8,'[2]4월'!$AO$8,'[2]4월'!$BA$8,'[2]4월'!$BD$8,'[2]4월'!$BE$8,'[2]4월'!$BF$8))/1000 -> 1.7024 | Q39: =+P39-O39 -> -0.0676 | R39: =+('[3]4월'!$F$8-SUM('[3]4월'!$Z$8,'[3]4월'!$AH$8,'[3]4월'!$AN$8,'[3]4월'!$AO$8,'[3]4월'!$BA$8,'[3]4월'!$BD$8,'[3]4월'!$BE$8,'[3]4월'!$BF$8))/1000 -> 1.7437 | S39: =+P39-R39 -> -0.0413 | T39: =+('[1]4월'!$E$26-'[1]4월'!$Z$26-'[1]4월'!$AA$26-'[1]4월'!$AE$26-'[1]4월'!$AL$26-'[1]4월'!$AM$26-'[1]4월'!$AN$26-'[1]4월'!$AO$26-'[1]4월'!$AP$26-'[1]4월'!$AQ$26-'[1]4월'!$AS$26)/1000 -> -79.281808 | U39: =+('[2]4월'!$F$26-SUM('[2]4월'!$Z$26,'[2]4월'!$AH$26,'[2]4월'!$AN$26,'[2]4월'!$AO$26,'[2]4월'!$BA$26,'[2]4월'!$BD$26,'[2]4월'!$BE$26,'[2]4월'!$BF$26))/1000 -> -14.461379 | V39: =+U39-T39 -> 64.820429 | W39: =+('[3]4월'!$F$26-SUM('[3]4월'!$Z$26,'[3]4월'!$AH$26,'[3]4월'!$AN$26,'[3]4월'!$AO$26,'[3]4월'!$BA$26,'[3]4월'!$BD$26,'[3]4월'!$BE$26,'[3]4월'!$BF$26))/1000 -> -17.324944 | X39: =+U39-W39 -> 2.863565
N40: =+K40-M40 -> 0 | Q40: =+P40-O40 -> 0 | S40: =+P40-R40 -> 0 | V40: =+U40-T40 -> 0
H41: 기타 계 | J41: =SUM(J33:J40) -> 0 | K41: =SUM(K33:K40) -> 0 | L41: =+K41-J41 -> 0 | M41: =SUM(M33:M40) -> 0 | N41: =+K41-M41 -> 0 | O41: =SUM(O33:O40) -> 164.9075 | P41: =SUM(P33:P40) -> 165.79909 | Q41: =+P41-O41 -> 0.89159367 | R41: =SUM(R33:R40) -> 151.66082 | S41: =+P41-R41 -> 14.138273 | T41: =SUM(T33:T40) -> -1523.9123 | U41: =SUM(U33:U40) -> -1480.5656 | V41: =+U41-T41 -> 43.346748 | W41: =SUM(W33:W40) -> -1283.4429 | X41: =+U41-W41 -> -197.12268
U42: 19 | V42: 12.4
...

Sheet 사업장별(누계)
H3: □ 사업장별 손익실적(2024-04누계)
AG4: [단위 : 천㎥, 톤, 백만원]
H5: 구분 | J5: 물량 | O5: 매출 | T5: 영업이익(공통비 배부전) | Y5: 판매단가 | AB5: 변동비 | AE5: 공헌이익
J6: 계획 | K6: 실적 | L6: 차이 | M6: 전년 | N6: 차이 | O6: 계획 | P6: 실적 | Q6: 차이 | R6: 전년 | S6: 차이 | T6: 계획 | U6: 실적 | V6: 차이 | W6: 전년 | X6: 차이 | Y6: 계획 | Z6: 실적 | AA6: 전년 | AB6: 계획 | AC6: 실적 | AD6: 전년 | AE6: 계획 | AF6: 실적 | AG6: 전년
B7: 안양 | H7: 레미콘 | I7: 안양 | J7: =+'사업장별(당월)'!J7+'[4]사업장별(누계)'!J7 -> 158 | K7: =+'사업장별(당월)'!K7+'[4]사업장별(누계)'!K7 -> 170.698 | L7: =+K7-J7 -> 12.698 | M7: =+'사업장별(당월)'!M7+'[4]사업장별(누계)'!M7 -> 174.134 | N7: =+K7-M7 -> -3.436 | O7: =+'사업장별(당월)'!O7+'[4]사업장별(누계)'!O7 -> 15630.926 | P7: =+'사업장별(당월)'!P7+'[4]사업장별(누계)'!P7 -> 16839.669 | Q7: =+P7-O7 -> 1208.7436 | R7: =+'사업장별(당월)'!R7+'[4]사업장별(누계)'!R7 -> 15728.418 | S7: =+P7-R7 -> 1111.2516 | T7: =+'사업장별(당월)'!T7+'[4]사업장별(누계)'!T7 -> 1848.6119 | U7: =+'사업장별(당월)'!U7+'[4]사업장별(누계)'!U7 -> 1780.9296 | V7: =+U7-T7 -> -67.68232 | W7: =+'사업장별(당월)'!W7+'[4]사업장별(누계)'!W7 -> 1863.8714 | X7: =+U7-W7 -> -82.941845 | Y7: =+[11]안양!$Q$85 -> 98929.91 | Z7: =+[11]안양!$R$85 -> 98646.302 | AA7: =+[12]안양!$Q$85 -> 90307.723 | AB7: =+[11]안양!$Q$89 -> 79553.046 | AC7: =+[11]안양!$R$89 -> 81001.251 | AD7: =+[12]안양!$Q$89 -> 73141.489 | AE7: =+Y7-AB7 -> 19376.864 | AF7: =+Z7-AC7 -> 17645.051 | AG7: =+AA7-AD7 -> 17166.234
B8: 인천 | H8: 직영 | I8: 인천 | J8: =+'사업장별(당월)'!J8+'[4]사업장별(누계)'!J8 -> 115 | K8: =+'사업장별(당월)'!K8+'[4]사업장별(누계)'!K8 -> 113.751 | L8: =+K8-J8 -> -1.249 | M8: =+'사업장별(당월)'!M8+'[4]사업장별(누계)'!M8 -> 144.401 | N8: =+K8-M8 -> -30.65 | O8: =+'사업장별(당월)'!O8+'[4]사업장별(누계)'!O8 -> 11543.533 | P8: =+'사업장별(당월)'!P8+'[4]사업장별(누계)'!P8 -> 11517.811 | Q8: =+P8-O8 -> -25.721848 | R8: =+'사업장별(당월)'!R8+'[4]사업장별(누계)'!R8 -> 13186.724 | S8: =+P8-R8 -> -1668.9131 | T8: =+'사업장별(당월)'!T8+'[4]사업장별(누계)'!T8 -> 931.37372 | U8: =+'사업장별(당월)'!U8+'[4]사업장별(누계)'!U8 -> 955.53588 | V8: =+U8-T8 -> 24.16216 | W8: =+'사업장별(당월)'!W8+'[4]사업장별(누계)'!W8 -> 1209.703 | X8: =+U8-W8 -> -254.16712 | Y8: =+[11]인천!$Q$85 -> 100378.55 | Z8: =+[11]인천!$R$85 -> 101254.59 | AA8: =+[12]인천!$Q$85 -> 91315.263 | AB8: =+[11]인천!$Q$89 -> 81749.012 | AC8: =+[11]인천!$R$89 -> 82842.102 | AD8: =+[12]인천!$Q$89 -> 74788.436 | AE8: =+Y8-AB8 -> 18629.535 | AF8: =+Z8-AC8 -> 18412.49 | AG8: =+AA8-AD8 -> 16526.827
B9: 파주 | I9: 파주 | J9: =+'사업장별(당월)'!J9+'[4]사업장별(누계)'!J9 -> 95 | K9: =+'사업장별(당월)'!K9+'[4]사업장별(누계)'!K9 -> 94.777 | L9: =+K9-J9 -> -0.223 | M9: =+'사업장별(당월)'!M9+'[4]사업장별(누계)'!M9 -> 91.731 | N9: =+K9-M9 -> 3.046 | O9: =+'사업장별(당월)'!O9+'[4]사업장별(누계)'!O9 -> 9247.4845 | P9: =+'사업장별(당월)'!P9+'[4]사업장별(누계)'!P9 -> 9538.5462 | Q9: =+P9-O9 -> 291.06169 | R9: =+'사업장별(당월)'!R9+'[4]사업장별(누계)'!R9 -> 8169.5877 | S9: =+P9-R9 -> 1368.9585 | T9: =+'사업장별(당월)'!T9+'[4]사업장별(누계)'!T9 -> 1029.7134 | U9: =+'사업장별(당월)'!U9+'[4]사업장별(누계)'!U9 -> 720.6683 | V9: =+U9-T9 -> -309.04515 | W9: =+'사업장별(당월)'!W9+'[4]사업장별(누계)'!W9 -> 540.21149 | X9: =+U9-W9 -> 180.45681 | Y9: =+[11]파주!$Q$85 -> 97341.942 | Z9: =+[11]파주!$R$85 -> 100686.07 | AA9: =+[12]파주!$Q$85 -> 89012.349 | AB9: =+[11]파주!$Q$89 -> 77060.251 | AC9: =+[11]파주!$R$89 -> 83027.045 | AD9: =+[12]파주!$Q$89 -> 73196.56 | AE9: =+Y9-AB9 -> 20281.691 | AF9: =+Z9-AC9 -> 17659.029 | AG9: =+AA9-AD9 -> 15815.789
B10: 김포 | I10: 김포 | J10: =+'사업장별(당월)'!J10+'[4]사업장별(누계)'!J10 -> 47 | K10: =+'사업장별(당월)'!K10+'[4]사업장별(누계)'!K10 -> 41.1575 | L10: =+K10-J10 -> -5.8425 | M10: =+'사업장별(당월)'!M10+'[4]사업장별(누계)'!M10 -> 63.4485 | N10: =+K10-M10 -> -22.291 | O10: =+'사업장별(당월)'!O10+'[4]사업장별(누계)'!O10 -> 4421.545 | P10: =+'사업장별(당월)'!P10+'[4]사업장별(누계)'!P10 -> 4025.2966 | Q10: =+P10-O10 -> -396.24836 | R10: =+'사업장별(당월)'!R10+'[4]사업장별(누계)'!R10 -> 5500.4497 | S10: =+P10-R10 -> -1475.153 | T10: =+'사업장별(당월)'!T10+'[4]사업장별(누계)'!T10 -> 381.914 | U10: =+'사업장별(당월)'!U10+'[4]사업장별(누계)'!U10 -> 266.92423 | V10: =+U10-T10 -> -114.98977 | W10: =+'사업장별(당월)'!W10+'[4]사업장별(누계)'!W10 -> 626.5073 | X10: =+U10-W10 -> -359.58306 | Y10: =+[11]김포!$Q$85 -> 94075.426 | Z10: =+[11]김포!$R$85 -> 97802.263 | AA10: =+[12]김포!$Q$85 -> 86602.407 | AB10: =+[11]김포!$Q$89 -> 71637.906 | AC10: =+[11]김포!$R$89 -> 76096.809 | AD10: =+[12]김포!$Q$89 -> 66532.407 | AE10: =+Y10-AB10 -> 22437.52 | AF10: =+Z10-AC10 -> 21705.454 | AG10: =+AA10-AD10 -> 20070
B11: 부산 | I11: 부산 | J11: =+'사업장별(당월)'!J11+'[4]사업장별(누계)'!J11 -> 73 | K11: =+'사업장별(당월)'!K11+'[4]사업장별(누계)'!K11 -> 85.017 | L11: =+K11-J11 -> 12.017 | M11: =+'사업장별(당월)'!M11+'[4]사업장별(누계)'!M11 -> 100.9305 | N11: =+K11-M11 -> -15.9135 | O11: =+'사업장별(당월)'!O11+'[4]사업장별(누계)'!O11 -> 7854.8038 | P11: =+'사업장별(당월)'!P11+'[4]사업장별(누계)'!P11 -> 9081.9494 | Q11: =+P11-O11 -> 1227.1457 | R11: =+'사업장별(당월)'!R11+'[4]사업장별(누계)'!R11 -> 10229.169 | S11: =+P11-R11 -> -1147.2197 | T11: =+'사업장별(당월)'!T11+'[4]사업장별(누계)'!T11 -> 1024.3788 | U11: =+'사업장별(당월)'!U11+'[4]사업장별(누계)'!U11 -> 989.91649 | V11: =+U11-T11 -> -34.462322 | W11: =+'사업장별(당월)'!W11+'[4]사업장별(누계)'!W11 -> 1907.0721 | X11: =+U11-W11 -> -917.15558 | Y11: =+[11]부산!$Q$85 -> 107600.05 | Z11: =+[11]부산!$R$85 -> 106825.1 | AA11: =+[12]부산!$Q$85 -> 101348.64 | AB11: =+[11]부산!$Q$89 -> 78762.845 | AC11: =+[11]부산!$R$89 -> 83745.24 | AD11: =+[12]부산!$Q$89 -> 73072.448 | AE11: =+Y11-AB11 -> 28837.206 | AF11: =+Z11-AC11 -> 23079.859 | AG11: =+AA11-AD11 -> 28276.194
B12: 서부산 | I12: 서부산 | J12: =+'사업장별(당월)'!J12+'[4]사업장별(누계)'!J12 -> 90 | K12: =+'사업장별(당월)'!K12+'[4]사업장별(누계)'!K12 -> 88.975 | L12: =+K12-J12 -> -1.025 | M12: =+'사업장별(당월)'!M12+'[4]사업장별(누계)'!M12 -> 88.758 | N12: =+K12-M12 -> 0.217 | O12: =+'사업장별(당월)'!O12+'[4]사업장별(누계)'!O12 -> 9324.2 | P12: =+'사업장별(당월)'!P12+'[4]사업장별(누계)'!P12 -> 8987.0293 | Q12: =+P12-O12 -> -337.1707 | R12: =+'사업장별(당월)'!R12+'[4]사업장별(누계)'!R12 -> 8604.2468 | S12: =+P12-R12 -> 382.78252 | T12: =+'사업장별(당월)'!T12+'[4]사업장별(누계)'!T12 -> 1506.8652 | U12: =+'사업장별(당월)'!U12+'[4]사업장별(누계)'!U12 -> 1022.0486 | V12: =+U12-T12 -> -484.81659 | W12: =+'사업장별(당월)'!W12+'[4]사업장별(누계)'!W12 -> 1446.1648 | X12: =+U12-W12 -> -424.11617 | Y12: =+[11]서부산!$Q$85 -> 103602.22 | Z12: =+[11]서부산!$R$85 -> 101006.23 | AA12: =+[12]서부산!$Q$85 -> 96940.521 | AB12: =+[11]서부산!$Q$89 -> 77879.123 | AC12: =+[11]서부산!$R$89 -> 79548.427 | AD12: =+[12]서부산!$Q$89 -> 71519.543 | AE12: =+Y12-AB12 -> 25723.099 | AF12: =+Z12-AC12 -> 21457.803 | AG12: =+AA12-AD12 -> 25420.978
