Workbook

Sheet 표지
A6: 2024년 6월 마감 손익
A24: 건재사업본부

Sheet 손익총괄
C3: □ 건재사업본부 손익실적(2024-06) | Z3: □ 건재부문 실적(6월)
X4: [단위 : 천㎥, 톤, 원/㎥, 원/톤, 백만원] | AK4: (단위 : 천㎥, 천톤, 억원)
C5: 구분 | E5: 6월 | J5: 6월 누계 | P5: 6월 주요지표 | Z5: 구분 | AB5: =+E5 -> 6월 | AG5: =+J5 -> 6월 누계
E6: 계획 | F6: 실적 | G6: 계획대비 | H6: 전년 | I6: 전년대비 | J6: 계획 | K6: 실적 | L6: 계획대비 | M6: 전년 | N6: 전년대비 | AB6: =+E6 -> 계획 | AC6: =+F6 -> 실적 | AD6: =+G6 -> 계획대비 | AE6: =+H6 -> 전년 | AF6: =+I6 -> 전년대비 | AG6: =+J6 -> 계획 | AH6: =+K6 -> 실적 | AI6: =+L6 -> 계획대비 | ... AK6: =+N6 -> 전년대비
A7: =+F7/E7 -> 1.0054488 | B7: =+K7/J7 -> 1.0572228 | C7: 물량 | D7: 레미콘 | E7: =+'[1]6월'!$Z$7/1000 -> 303.5 | F7: =+'[2]6월'!$Z$7/1000 -> 305.1537 | G7: =+F7-E7 -> 1.6537 | H7: =+'[3]6월'!$Z$7/1000 -> 350.082 | I7: =+F7-H7 -> -44.9283 | J7: =+[4]손익총괄!J7+E7 -> 1682 | K7: =+[4]손익총괄!K7+F7 -> 1778.2487 | L7: =+K7-J7 -> 96.2487 | M7: =+[4]손익총괄!M7+H7 -> 1994.131 | N7: =+K7-M7 -> -215.8823 | Q7: □ 레미콘 | Z7: 물량 | AA7: =+D7 -> 레미콘 | AB7: =+E7 -> 303.5 | AC7: =+F7 -> 305.1537 | AD7: =+AC7-AB7 -> 1.6537 | AE7: =+H7 -> 350.082 | AF7: =+AC7-AE7 -> -44.9283 | AG7: =+J7 -> 1682 | AH7: =+K7 -> 1778.2487 | AI7: =+AH7-AG7 -> 96.2487 | AJ7: =+M7 -> 1994.131 | AK7: =+AH7-AJ7 -> -215.8823
D8: 철강재 | E8: =+'[1]6월'!$AA$7 -> 6100 | F8: =+'[2]6월'!$AO$7 -> 7982.061 | G8: =+F8-E8 -> 1882.061 | H8: =+'[3]6월'!$AO$7 -> 7070.5 | I8: =+F8-H8 -> 911.561 | J8: =+[4]손익총괄!J8+E8 -> 41600 | K8: =+[4]손익총괄!K8+F8 -> 48080.048 | L8: =+K8-J8 -> 6480.048 | M8: =+[4]손익총괄!M8+H8 -> 48940.798 | N8: =+K8-M8 -> -860.75 | Q8: 구분 | S8: 계획 | T8: 실적 | U8: 계획대비 | V8: 전년 | W8: 전년대비 | AA8: =+D8 -> 철강재 | AB8: =+E8/1000 -> 6.1 | AC8: =+F8/1000 -> 7.982061 | AD8: =+AC8-AB8 -> 1.882061 | AE8: =+H8/1000 -> 7.0705 | AF8: =+AC8-AE8 -> 0.911561 | AG8: =+J8/1000 -> 41.6 | AH8: =+K8/1000 -> 48.080048 | AI8: =+AH8-AG8 -> 6.480048 | AJ8: =+M8/1000 -> 48.940798 | AK8: =+AH8-AJ8 -> -0.86075
D9: 골재 | E9: =+'[1]6월'!$AE$7/1000 -> 119.4482 | F9: =+'[2]6월'!$AN$7/1000 -> 76.324 | G9: =+F9-E9 -> -43.124199 | H9: =+'[3]6월'!$AN$7/1000 -> 64.573 | I9: =+F9-H9 -> 11.751 | J9: =+[4]손익총괄!J9+E9 -> 499.67197 | K9: =+[4]손익총괄!K9+F9 -> 496.699 | L9: =+K9-J9 -> -2.9729739 | M9: =+[4]손익총괄!M9+H9 -> 377.463 | N9: =+K9-M9 -> 119.236 | Q9: 물량 | R9: 수도권 | S9: =+[5]수도권!$T$5/1000 -> 119.5 | T9: =+[5]수도권!$U$5/1000 -> 107.2852 | U9: =+T9-S9 -> -12.2148 | V9: =+[6]수도권!$T$5/1000 -> 144.232 | W9: =+T9-V9 -> -36.9468 | AA9: =+D9 -> 골재 | AB9: =+E9 -> 119.4482 | AC9: =+F9 -> 76.324 | AD9: =+AC9-AB9 -> -43.124199 | AE9: =+H9 -> 64.573 | AF9: =+AC9-AE9 -> 11.751 | AG9: =+J9 -> 499.67197 | AH9: =+K9 -> 496.699 | AI9: =+AH9-AG9 -> -2.9729739 | AJ9: =+M9 -> 377.463 | AK9: =+AH9-AJ9 -> 119.236
C10: 매출 | D10: 레미콘 | E10: =+'[1]6월'!$Z$8/1000 -> 31021.092 | F10: =+'[2]6월'!$Z$8/1000 -> 30777.038 | G10: =+F10-E10 -> -244.05413 | H10: =+'[3]6월'!$Z$8/1000 -> 34406.715 | I10: =+F10-H10 -> -3629.6774 | J10: =+[4]손익총괄!J10+E10 -> 170780.65 | K10: =+[4]손익총괄!K10+F10 -> 180238.86 | L10: =+K10-J10 -> 9458.2162 | M10: =+[4]손익총괄!M10+H10 -> 190264.99 | N10: =+K10-M10 -> -10026.124 | R10: 영남권 | S10: =+[5]영남권!$T$5/1000 -> 128.5 | T10: =+[5]영남권!$U$5/1000 -> 137.792 | U10: =+T10-S10 -> 9.292 | V10: =+[6]영남권!$T$5/1000 -> 146.565 | W10: =+T10-V10 -> -8.773 | Z10: 매출액 | AA10: =+D10 -> 레미콘 | AB10: =+E10/100 -> 310.21092 | AC10: =+F10/100 -> 307.77038 | AD10: =+AC10-AB10 -> -2.4405413 | AE10: =+H10/100 -> 344.06715 | AF10: =+AC10-AE10 -> -36.296774 | AG10: =+J10/100 -> 1707.8065 | AH10: =+K10/100 -> 1802.3886 | AI10: =+AH10-AG10 -> 94.582162 | AJ10: =+M10/100 -> 1902.6499 | AK10: =+AH10-AJ10 -> -100.26124
D11: 건자재 | E11: =+'[1]6월'!$AA$8/1000 -> 7443.8253 | F11: =+'[2]6월'!$AO$8/1000 -> 7873.3448 | G11: =+F11-E11 -> 429.51951 | H11: =+'[3]6월'!$AO$8/1000 -> 8947.0894 | I11: =+F11-H11 -> -1073.7446 | J11: =+[4]손익총괄!J11+E11 -> 50866.286 | K11: =+[4]손익총괄!K11+F11 -> 49403.738 | L11: =+K11-J11 -> -1462.5482 | M11: =+[4]손익총괄!M11+H11 -> 59347.903 | N11: =+K11-M11 -> -9944.1645 | R11: 중부권 | S11: =+[5]중부권!$T$5/1000 -> 55.5 | T11: =+[5]중부권!$U$5/1000 -> 60.0765 | U11: =+T11-S11 -> 4.5765 | V11: =+[6]중부권!$T$5/1000 -> 59.285 | W11: =+T11-V11 -> 0.7915 | AA11: =+D11 -> 건자재 | AB11: =+E11/100 -> 74.438253 | AC11: =+F11/100 -> 78.733448 | AD11: =+AC11-AB11 -> 4.2951951 | AE11: =+H11/100 -> 89.470894 | AF11: =+AC11-AE11 -> -10.737446 | AG11: =+J11/100 -> 508.66286 | AH11: =+K11/100 -> 494.03738 | AI11: =+AH11-AG11 -> -14.625482 | AJ11: =+M11/100 -> 593.47903 | AK11: =+AH11-AJ11 -> -99.441645
D12: 골재 | E12: =+'[1]6월'!$AE$8/1000 -> 2150.6541 | F12: =+'[2]6월'!$AN$8/1000 -> 1476.999 | G12: =+F12-E12 -> -673.65505 | H12: =+'[3]6월'!$AN$8/1000 -> 1257.309 | I12: =+F12-H12 -> 219.69 | J12: =+[4]손익총괄!J12+E12 -> 9896.9632 | K12: =+[4]손익총괄!K12+F12 -> 9981.2066 | L12: =+K12-J12 -> 84.243423 | M12: =+[4]손익총괄!M12+H12 -> 7223.0639 | N12: =+K12-M12 -> 2758.1427 | Q12: 계 | S12: =SUM(S9:S11) -> 303.5 | T12: =SUM(T9:T11) -> 305.1537 | U12: =+T12-S12 -> 1.6537 | V12: =SUM(V9:V11) -> 350.082 | W12: =+T12-V12 -> -44.9283 | AA12: =+D12 -> 골재 | AB12: =+E12/100 -> 21.506541 | AC12: =+F12/100 -> 14.76999 | AD12: =+AC12-AB12 -> -6.7365505 | AE12: =+H12/100 -> 12.57309 | AF12: =+AC12-AE12 -> 2.1969 | AG12: =+J12/100 -> 98.969632 | AH12: =+K12/100 -> 99.812066 | AI12: =+AH12-AG12 -> 0.84243423 | AJ12: =+M12/100 -> 72.230639 | AK12: =+AH12-AJ12 -> 27.581427
D13: 기타 | E13: =+'[1]6월'!$E$8/1000-E10-E11-E12 -> 164.9075 | F13: =+'[2]6월'!$F$8/1000-F10-F11-F12 -> 166.17921 | G13: =+F13-E13 -> 1.2717117 | H13: =+'[3]6월'!$F$8/1000-H10-H11-H12 -> 181.61219 | I13: =+F13-H13 -> -15.432979 | J13: =+[4]손익총괄!J13+E13 -> 989.445 | K13: =+[4]손익총괄!K13+F13 -> 991.75998 | L13: =+K13-J13 -> 2.314978 | M13: =+[4]손익총괄!M13+H13 -> 1209.2669 | N13: =+K13-M13 -> -217.50691 | Q13: 판매단가 | R13: 수도권 | S13: =+[5]수도권!$T$61 -> 100194.01 | T13: =+[5]수도권!$U$61 -> 97972.586 | U13: =+T13-S13 -> -2221.4284 | V13: =+[6]수도권!$Q$85 -> 95370.959 | W13: =+T13-V13 -> 2601.6267 | AA13: =+D13 -> 기타 | AB13: =+E13/100 -> 1.649075 | AC13: =+F13/100 -> 1.6617921 | AD13: =+AC13-AB13 -> 0.012717117 | AE13: =+H13/100 -> 1.8161219 | AF13: =+AC13-AE13 -> -0.15432979 | AG13: =+J13/100 -> 9.89445 | AH13: =+K13/100 -> 9.9175998 | AI13: =+AH13-AG13 -> 0.02314978 | AJ13: =+M13/100 -> 12.092669 | AK13: =+AH13-AJ13 -> -2.1750691
A14: =+F14/E14 -> 0.98806002 | B14: =+K14/J14 -> 1.0347573 | C14: 계 | E14: =SUM(E10:E13) -> 40780.479 | F14: =SUM(F10:F13) -> 40293.561 | G14: =+F14-E14 -> -486.91796 | H14: =SUM(H10:H13) -> 44792.726 | I14: =+F14-H14 -> -4499.1651 | J14: =SUM(J10:J13) -> 232533.34 | K14: =SUM(K10:K13) -> 240615.57 | L14: =+K14-J14 -> 8082.2264 | M14: =SUM(M10:M13) -> 258045.22 | N14: =+K14-M14 -> -17429.653 | R14: 영남권 | S14: =+[5]영남권!$T$61 -> 102400.98 | T14: =+[5]영남권!$U$61 -> 100840.36 | U14: =+T14-S14 -> -1560.6247 | V14: =+[6]영남권!$Q$85 -> 99670.721 | W14: =+T14-V14 -> 1169.6357 | AA14: 계 | AB14: =SUM(AB10:AB13) -> 407.80479 | AC14: =SUM(AC10:AC13) -> 402.93561 | AD14: =+AC14-AB14 -> -4.8691796 | AE14: =SUM(AE10:AE13) -> 447.92726 | AF14: =+AC14-AE14 -> -44.991651 | AG14: =SUM(AG10:AG13) -> 2325.3334 | AH14: =SUM(AH10:AH13) -> 2406.1557 | AI14: =+AH14-AG14 -> 80.822264 | AJ14: =SUM(AJ10:AJ13) -> 2580.4522 | AK14: =+AH14-AJ14 -> -174.29653
C15: 매출원가 | D15: 레미콘 | E15: =+('[1]6월'!$Z$10+'[1]6월'!$Z$19)/1000 -> 25754.86 | F15: =+('[2]6월'!$Z$10+'[2]6월'!$Z$19)/1000 -> 26624.109 | G15: =+F15-E15 -> 869.24906 | H15: =+('[3]6월'!$Z$10+'[3]6월'!$Z$19)/1000 -> 27540.433 | I15: =+F15-H15 -> -916.32395 | J15: =+[4]손익총괄!J15+E15 -> 143774.57 | K15: =+[4]손익총괄!K15+F15 -> 155350.49 | L15: =+K15-J15 -> 11575.914 | M15: =+[4]손익총괄!M15+H15 -> 156203.46 | N15: =+K15-M15 -> -852.96908 | R15: 중부권 | S15: =+[5]중부권!$T$61 -> 106114.98 | T15: =+[5]중부권!$U$61 -> 106050.93 | U15: =+T15-S15 -> -64.051786 | V15: =+[6]중부권!$Q$85 -> 102035.99 | W15: =+T15-V15 -> 4014.9335 | Z15: 영업이익 | AA15: =+D30 -> 레미콘 | AB15: =+E30/100 -> 46.175047 | AC15: =+F30/100 -> 35.104462 | AD15: =+AC15-AB15 -> -11.070585 | AE15: =+H30/100 -> 63.0063 | AF15: =+AC15-AE15 -> -27.901837 | AG15: =+J30/100 -> 230.47466 | AH15: =+K30/100 -> 209.21862 | AI15: =+AH15-AG15 -> -21.256037 | AJ15: =+M30/100 -> 301.69137 | AK15: =+AH15-AJ15 -> -92.472752
D16: 건자재 | E16: =+('[1]6월'!$AA$10+'[1]6월'!$AA$19)/1000 -> 7254.0311 | F16: =+('[2]6월'!$AO$10+'[2]6월'!$AO$19)/1000 -> 7592.3476 | G16: =+F16-E16 -> 338.31646 | H16: =+('[3]6월'!$AO$10+'[3]6월'!$AO$19)/1000 -> 8737.8985 | I16: =+F16-H16 -> -1145.5509 | J16: =+[4]손익총괄!J16+E16 -> 49564.542 | K16: =+[4]손익총괄!K16+F16 -> 48171.056 | L16: =+K16-J16 -> -1393.4855 | M16: =+[4]손익총괄!M16+H16 -> 58159.216 | N16: =+K16-M16 -> -9988.1599 | Q16: 계 | S16: =+[5]합계!$T$61 -> 102211.18 | T16: =+[5]합계!$U$61 -> 100861.45 | U16: =+T16-S16 -> -1349.7221 | V16: =+[6]합계!$Q$85 -> 98290.639 | W16: =+T16-V16 -> 2570.8152 | AA16: =+D31 -> % | AB16: =+E31 -> 0.14885049 | AC16: =+F31 -> 0.11406056 | AD16: =+AC16-AB16 -> -0.034789927 | AE16: =+H31 -> 0.1831221 | AF16: =+AC16-AE16 -> -0.069061537 | AG16: =+J31 -> 0.13495362 | AH16: =+K31 -> 0.11607853 | AI16: =+AH16-AG16 -> -0.018875087 | AJ16: =+M31 -> 0.15856379 | AK16: =+AH16-AJ16 -> -0.04248526
D17: 골재 | E17: =+('[1]6월'!$AE$10+'[1]6월'!$AE$19)/1000 -> 1904.2025 | F17: =+('[2]6월'!$AN$10+'[2]6월'!$AN$19)/1000 -> 1456.8969 | G17: =+F17-E17 -> -447.30564 | H17: =+('[3]6월'!$AN$10+'[3]6월'!$AN$19)/1000 -> 1192.018 | I17: =+F17-H17 -> 264.87887 | J17: =+[4]손익총괄!J17+E17 -> 8951.4712 | K17: =+[4]손익총괄!K17+F17 -> 8992.6372 | L17: =+K17-J17 -> 41.166009 | M17: =+[4]손익총괄!M17+H17 -> 6437.7239 | N17: =+K17-M17 -> 2554.9134 | Q17: 공헌이익 | R17: 수도권 | S17: =+[5]수도권!$Q$90 -> 22851.48 | T17: =+[5]수도권!$R$90 -> 17945.084 | U17: =+T17-S17 -> -4906.3964 | V17: =+[6]수도권!$Q$90 -> 23158.157 | W17: =+T17-V17 -> -5213.0729 | AA17: =+D32 -> 건자재 | AB17: =+E32/100 -> 0.65463103 | AC17: =+F32/100 -> 1.5016984 | AD17: =+AC17-AB17 -> 0.84706737 | AE17: =+H32/100 -> 1.1702504 | AF17: =+AC17-AE17 -> 0.33144798 | AG17: =+J32/100 -> 5.4671993 | AH17: =+K32/100 -> 4.1512243 | AI17: =+AH17-AG17 -> -1.3159749 | AJ17: =+M32/100 -> 4.9389411 | AK17: =+AH17-AJ17 -> -0.78771672
D18: 기타 | E18: =+('[1]6월'!$E$10+'[1]6월'!$E$19)/1000-E15-E16-E17 -> -1218.7369 | F18: =+('[2]6월'!$F$10+'[2]6월'!$F$19)/1000-F15-F16-F17 -> 194.15654 | G18: =+F18-E18 -> 1412.8935 | H18: =+('[3]6월'!$F$10+'[3]6월'!$F$19)/1000-H15-H16-H17 -> 158.33377 | I18: =+F18-H18 -> 35.822771 | J18: =+[4]손익총괄!J18+E18 -> -980.774 | K18: =+[4]손익총괄!K18+F18 -> 325.56325 | L18: =+K18-J18 -> 1306.3372 | M18: =+[4]손익총괄!M18+H18 -> 398.80391 | N18: =+K18-M18 -> -73.240652 | R18: 영남권 | S18: =+[5]영남권!$Q$90 -> 27580.609 | T18: =+[5]영남권!$R$90 -> 22708.372 | U18: =+T18-S18 -> -4872.2362 | V18: =+[6]영남권!$Q$90 -> 28613.943 | W18: =+T18-V18 -> -5905.5707 | AA18: =+D33 -> 골재 | AB18: =+E33/100 -> 2.1126679 | AC18: =+F33/100 -> -0.24058962 | AD18: =+AC18-AB18 -> -2.3532575 | AE18: =+H33/100 -> 0.07028827 | AF18: =+AC18-AE18 -> -0.31087789 | AG18: =+J33/100 -> 5.4241676 | AH18: =+K33/100 -> 7.2051825 | AI18: =+AH18-AG18 -> 1.7810149 | AJ18: =+M33/100 -> 5.3583129 | AK18: =+AH18-AJ18 -> 1.8468697
C19: 계 | E19: =SUM(E15:E18) -> 33694.357 | F19: =SUM(F15:F18) -> 35867.51 | G19: =+F19-E19 -> 2173.1533 | H19: =SUM(H15:H18) -> 37628.683 | I19: =+F19-H19 -> -1761.1732 | J19: =SUM(J15:J18) -> 201309.81 | K19: =SUM(K15:K18) -> 212839.74 | L19: =+K19-J19 -> 11529.932 | M19: =SUM(M15:M18) -> 221199.2 | N19: =+K19-M19 -> -8359.4563 | R19: 중부권 | S19: =+[5]중부권!$Q$90 -> 30509.327 | T19: =+[5]중부권!$R$90 -> 30006.058 | U19: =+T19-S19 -> -503.26919 | V19: =+[6]중부권!$Q$90 -> 30764.15 | W19: =+T19-V19 -> -758.09183 | AA19: =+D34 -> 기타 | AB19: =+E34/100 -> -13.145549 | AC19: =+F34/100 -> -19.60908 | AD19: =+AC19-AB19 -> -6.4635306 | AE19: =+H34/100 -> -25.763388 | AF19: =+AC19-AE19 -> 6.1543083 | AG19: =+J34/100 -> -74.105708 | AH19: =+K34/100 -> -97.111669 | AI19: =+AH19-AG19 -> -23.005961 | AJ19: =+M34/100 -> -77.717661 | AK19: =+AH19-AJ19 -> -19.394009
C20: 매출이익 | D20: 레미콘 | E20: =+E10-E15 -> 5266.2321 | F20: =+F10-F15 -> 4152.9289 | G20: =+F20-E20 -> -1113.3032 | H20: =+H10-H15 -> 6866.2824 | I20: =+F20-H20 -> -2713.3535 | J20: =+J10-J15 -> 27006.071 | K20: =+K10-K15 -> 24888.374 | L20: =+K20-J20 -> -2117.6977 | M20: =+M10-M15 -> 34061.529 | N20: =+K20-M20 -> -9173.1552 | Q20: 계 | S20: =+[5]합계!$Q$90 -> 26254.128 | T20: =+[5]합계!$R$90 -> 22476.76 | U20: =+T20-S20 -> -3777.3673 | V20: =+[6]합계!$Q$90 -> 26722.744 | W20: =+T20-V20 -> -4245.9839 | AA20: 계 | AB20: =+AB15+AB17+AB18+AB19 -> 35.796797 | AC20: =+AC15+AC17+AC18+AC19 -> 16.756492 | AD20: =+AC20-AB20 -> -19.040305 | AE20: =+AE15+AE17+AE18+AE19 -> 38.48345 | AF20: =+AC20-AE20 -> -21.726959 | AG20: =+AG15+AG17+AG18+AG19 -> 167.26032 | AH20: =+AH15+AH17+AH18+AH19 -> 123.46336 | AI20: =+AH20-AG20 -> -43.796958 | AJ20: =+AJ15+AJ17+AJ18+AJ19 -> 234.27097 | AK20: =+AH20-AJ20 -> -110.80761
D21: 건자재 | E21: =+E11-E16 -> 189.79414 | F21: =+F11-F16 -> 280.9972 | G21: =+F21-E21 -> 91.203056 | H21: =+H11-H16 -> 209.19091 | I21: =+F21-H21 -> 71.806294 | J21: =+J11-J16 -> 1301.7446 | K21: =+K11-K16 -> 1232.6819 | L21: =+K21-J21 -> -69.062738 | M21: =+M11-M16 -> 1188.6865 | N21: =+K21-M21 -> 43.995398 | Q21: □ 건자재 | AA21: =+D36 -> % | AB21: =+E36 -> 0.087779247 | AC21: =+F36 -> 0.041586028 | AD21: =+G36 -> -0.046193218 | AE21: =+H36 -> 0.085914509 | AF21: =+I36 -> -0.04432848 | AG21: =+J36 -> 0.071929607 | AH21: =+K36 -> 0.051311459 | ... AK21: =+N36 -> -0.039475329
D22: 골재 | E22: =+E12-E17 -> 246.45154 | F22: =+F12-F17 -> 20.10212 | G22: =+F22-E22 -> -226.34942 | H22: =+H12-H17 -> 65.290989 | I22: =+F22-H22 -> -45.188869 | J22: =+J12-J17 -> 945.49195 | K22: =+K12-K17 -> 988.56936 | L22: =+K22-J22 -> 43.077414 | M22: =+M12-M17 -> 785.34004 | N22: =+K22-M22 -> 203.22932 | Q22: 구분 | S22: 계획 | T22: 실적 | U22: 계획대비 | V22: 전년 | W22: 전년대비 | Z22: * 6월누계 기타차이 : 대손 16억
D23: 기타 | E23: =+E13-E18 -> 1383.6444 | F23: =+F13-F18 -> -27.977325 | G23: =+F23-E23 -> -1411.6217 | H23: =+H13-H18 -> 23.278425 | I23: =+F23-H23 -> -51.25575 | J23: =+J13-J18 -> 1970.219 | K23: =+K13-K18 -> 666.19673 | L23: =+K23-J23 -> -1304.0223 | M23: =+M13-M18 -> 810.46299 | N23: =+K23-M23 -> -144.26626 | Q23: 철강재 판매단가 | S23: =+'[7]6월'!$F$10 -> 974590.16 | T23: =+'[7]6월'!$G$10 -> 785072.68 | U23: =+T23-S23 -> -189517.49 | V23: =+'[8]6월'!$G$10 -> 1043902.1 | W23: =+T23-V23 -> -258829.41
C24: 계 | E24: =SUM(E20:E23) -> 7086.1222 | F24: =SUM(F20:F23) -> 4426.0509 | G24: =+F24-E24 -> -2660.0713 | H24: =SUM(H20:H23) -> 7164.0427 | I24: =+F24-H24 -> -2737.9918 | J24: =SUM(J20:J23) -> 31223.527 | K24: =SUM(K20:K23) -> 27775.822 | L24: =+K24-J24 -> -3447.7053 | M24: =SUM(M20:M23) -> 36846.018 | N24: =+K24-M24 -> -9070.1967 | Q24: 철강재 마진률 | S24: =+'[7]6월'!$F$15 -> 0.023156434 | T24: =+'[7]6월'!$G$15 -> 0.037059976 | U24: =+T24-S24 -> 0.013903542 | V24: =+'[8]6월'!$G$15 -> 0.023814617 | W24: =+T24-V24 -> 0.013245359
C25: 판관비 | D25: 레미콘 | E25: =+('[1]6월'!$Z$13+'[1]6월'!$Z$20)/1000 -> 648.72737 | F25: =+('[2]6월'!$Z$13+'[2]6월'!$Z$20)/1000 -> 642.48265 | G25: =+F25-E25 -> -6.244724 | H25: =+('[3]6월'!$Z$13+'[3]6월'!$Z$20)/1000 -> 565.65244 | I25: =+F25-H25 -> 76.830213 | J25: =+[4]손익총괄!J25+E25 -> 3958.6055 | K25: =+[4]손익총괄!K25+F25 -> 3966.5114 | L25: =+K25-J25 -> 7.905958 | M25: =+[4]손익총괄!M25+H25 -> 3892.3914 | N25: =+K25-M25 -> 74.12004 | Q25: □ 골재
D26: 건자재 | E26: =+('[1]6월'!$AA$13+'[1]6월'!$AA$20)/1000 -> 124.33104 | F26: =+('[2]6월'!$AO$13+'[2]6월'!$AO$20)/1000 -> 130.82736 | G26: =+F26-E26 -> 6.496319 | H26: =+('[3]6월'!$AO$13+'[3]6월'!$AO$20)/1000 -> 92.165863 | I26: =+F26-H26 -> 38.661496 | J26: =+[4]손익총괄!J26+E26 -> 755.02471 | K26: =+[4]손익총괄!K26+F26 -> 817.55946 | L26: =+K26-J26 -> 62.534755 | M26: =+[4]손익총괄!M26+H26 -> 694.79239 | N26: =+K26-M26 -> 122.76707 | Q26: 구분 | S26: 계획 | T26: 실적 | U26: 계획대비 | V26: 전년 | W26: 전년대비
D27: 골재 | E27: =+('[1]6월'!$AE$13+'[1]6월'!$AE$20+'[1]6월'!$AE$22)/1000 -> 35.18475 | F27: =+('[2]6월'!$AN$13+'[2]6월'!$AN$20+'[2]6월'!$AN$22)/1000 -> 44.161082 | G27: =+F27-E27 -> 8.9763324 | H27: =+('[3]6월'!$AN$13+'[3]6월'!$AN$20+'[3]6월'!$AN$22)/1000 -> 58.262162 | I27: =+F27-H27 -> -14.10108 | J27: =+[4]손익총괄!J27+E27 -> 403.07519 | K27: =+[4]손익총괄!K27+F27 -> 268.05111 | L27: =+K27-J27 -> -135.02408 | M27: =+[4]손익총괄!M27+H27 -> 249.50875 | N27: =+K27-M27 -> 18.542355 | Q27: 판매량 | R27: 자가 | S27: =(+'[9]서부산크라샤(당월)'!$N$66+'[9]부산모래장(당월)'!$Q$48+'[9]부산크라샤(당월)'!$N$66)/1000 -> 56.648199 | T27: =(+'[9]서부산크라샤(당월)'!$O$66+'[9]부산모래장(당월)'!$R$48+'[9]부산크라샤(당월)'!$O$66)/1000 -> 47.014 | U27: =+T27-S27 -> -9.6341988 | V27: =('[10]부산골재(당월)'!$R$48+'[10]서부산골재(당월)'!$O$66+'[10]부산크라샤(당월)'!$O$66)/1000 -> 46.66 | W27: =+T27-V27 -> 0.354
D28: 기타 | E28: =+('[1]6월'!$E$13+'[1]6월'!$E$20)/1000-E25-E26-E27+('[1]6월'!$E$22/1000) -> 2698.1993 | F28: =+('[2]6월'!$F$13+'[2]6월'!$F$20)/1000-F25-F26-F27+'[2]6월'!$F$22/1000 -> 1932.9306 | G28: =+F28-E28 -> -765.26868 | H28: =+('[3]6월'!$F$13+'[3]6월'!$F$20)/1000-H25-H26-H27+'[3]6월'!$F$22/1000 -> 2599.6172 | I28: =+F28-H28 -> -666.68658 | J28: =+[4]손익총괄!J28+E28 -> 9380.7898 | K28: =+[4]손익총괄!K28+F28 -> 10377.364 | L28: =+K28-J28 -> 996.57386 | M28: =+[4]손익총괄!M28+H28 -> 8582.2291 | N28: =+K28-M28 -> 1795.1346 | R28: 외판 | S28: =(+'[9]서부산크라샤(당월)'!$N$59+'[9]부산모래장(당월)'!$Q$47+'[9]부산크라샤(당월)'!$N$59)/1000 -> 62.8 | T28: =(+'[9]서부산크라샤(당월)'!$O$59+'[9]부산모래장(당월)'!$R$47+'[9]부산크라샤(당월)'!$O$59)/1000 -> 29.31 | U28: =+T28-S28 -> -33.49 | V28: =+('[10]부산골재(당월)'!$R$47+'[10]서부산골재(당월)'!$O$59+'[10]부산크라샤(당월)'!$O$59)/1000 -> 17.913 | W28: =+T28-V28 -> 11.397
C29: 계 | E29: =SUM(E25:E28) -> 3506.4425 | F29: =SUM(F25:F28) -> 2750.4017 | G29: =+F29-E29 -> -756.04075 | H29: =SUM(H25:H28) -> 3315.6977 | I29: =+F29-H29 -> -565.29595 | J29: =SUM(J25:J28) -> 14497.495 | K29: =SUM(K25:K28) -> 15429.486 | L29: =+K29-J29 -> 931.9905 | M29: =SUM(M25:M28) -> 13418.922 | N29: =+K29-M29 -> 2010.5641 | Q29: 합 계 | S29: =SUM(S27:S28) -> 119.4482 | T29: =SUM(T27:T28) -> 76.324 | U29: =+T29-S29 -> -43.124199 | V29: =SUM(V27:V28) -> 64.573 | W29: =+T29-V29 -> 11.751
C30: 영업이익 | D30: 레미콘 | E30: =+E20-E25 -> 4617.5047 | F30: =+F20-F25 -> 3510.4462 | G30: =+F30-E30 -> -1107.0585 | H30: =+H20-H25 -> 6300.63 | I30: =+F30-H30 -> -2790.1837 | J30: =+J20-J25 -> 23047.466 | K30: =+K20-K25 -> 20921.862 | L30: =+K30-J30 -> -2125.6037 | M30: =+M20-M25 -> 30169.137 | N30: =+K30-M30 -> -9247.2752 | Q30: □ 기타내역(영업이익)
D31: % | E31: =+E30/E10 -> 0.14885049 | F31: =+F30/F10 -> 0.11406056 | G31: =+F31-E31 -> -0.034789927 | H31: =+H30/H10 -> 0.1831221 | I31: =+F31-H31 -> -0.069061537 | J31: =+J30/J10 -> 0.13495362 | K31: =+K30/K10 -> 0.11607853 | L31: =+K31-J31 -> -0.018875087 | M31: =+M30/M10 -> 0.15856379 | N31: =+K31-M31 -> -0.04248526 | Q31: 구분 | S31: 계획 | T31: 실적 | U31: 계획대비 | V31: 전년 | W31: 전년대비
D32: 건자재 | E32: =+E21-E26 -> 65.463103 | F32: =+F21-F26 -> 150.16984 | G32: =+F32-E32 -> 84.706737 | H32: =+H21-H26 -> 117.02504 | I32: =+F32-H32 -> 33.144798 | J32: =+J21-J26 -> 546.71993 | K32: =+K21-K26 -> 415.12243 | L32: =+K32-J32 -> -131.59749 | M32: =+M21-M26 -> 493.89411 | N32: =+K32-M32 -> -78.771672 | Q32: 레미콘임대 | S32: =+'사업장별(당월)'!T33 -> 13.943842 | T32: =+'사업장별(당월)'!U33 -> -23.482855 | U32: =+T32-S32 -> -37.426697 | V32: =+'사업장별(당월)'!W33 -> -3.942039 | W32: =+T32-V32 -> -19.540816
D33: 골재 | E33: =+E22-E27 -> 211.26679 | F33: =+F22-F27 -> -24.058962 | G33: =+F33-E33 -> -235.32575 | H33: =+H22-H27 -> 7.028827 | I33: =+F33-H33 -> -31.087789 | J33: =+J22-J27 -> 542.41676 | K33: =+K22-K27 -> 720.51825 | L33: =+K33-J33 -> 178.10149 | M33: =+M22-M27 -> 535.83129 | N33: =+K33-M33 -> 184.68697 | Q33: 임대 | S33: =+'사업장별(당월)'!T34 -> 74.638401 | T33: =+'사업장별(당월)'!U34 -> 76.100837 | U33: =+T33-S33 -> 1.4624357 | V33: =+'사업장별(당월)'!W34 -> 98.057103 | W33: =+T33-V33 -> -21.956266
D34: 기타 | E34: =+E23-E28 -> -1314.5549 | F34: =+F23-F28 -> -1960.908 | G34: =+F34-E34 -> -646.35306 | H34: =+H23-H28 -> -2576.3388 | I34: =+F34-H34 -> 615.43083 | J34: =+J23-J28 -> -7410.5708 | K34: =+K23-K28 -> -9711.1669 | L34: =+K34-J34 -> -2300.5961 | M34: =+M23-M28 -> -7771.7661 | N34: =+K34-M34 -> -1939.4009 | Q34: 공통비 | S34: =+'사업장별(당월)'!T35 -> -2614.3237 | T34: =+'사업장별(당월)'!U35 -> -2487.3998 | U34: =+T34-S34 -> 126.92383 | V34: =+'사업장별(당월)'!W35 -> -1613.42 | W34: =+T34-V34 -> -873.97987
C35: 계 | E35: =SUM(E30,E32:E34) -> 3579.6797 | F35: =SUM(F30,F32:F34) -> 1675.6492 | G35: =+F35-E35 -> -1904.0305 | H35: =SUM(H30,H32:H34) -> 3848.345 | I35: =+F35-H35 -> -2172.6959 | J35: =SUM(J30,J32:J34) -> 16726.032 | K35: =SUM(K30,K32:K34) -> 12346.336 | L35: =+K35-J35 -> -4379.6958 | M35: =SUM(M30,M32:M34) -> 23427.097 | N35: =+K35-M35 -> -11080.761 | Q35: 기타 | S35: =+S36-S32-S33-S34 -> 1211.1865 | T35: =+T36-T32-T33-T34 -> 473.8739 | U35: =+T35-S35 -> -737.31263 | V35: =+V36-V32-V33-V34 -> -1057.0339 | W35: =+T35-V35 -> 1530.9078
D36: % | E36: =+E35/E14 -> 0.087779247 | F36: =+F35/F14 -> 0.041586028 | G36: =+F36-E36 -> -0.046193218 | H36: =+H35/H14 -> 0.085914509 | I36: =+F36-H36 -> -0.04432848 | J36: =+J35/J14 -> 0.071929607 | K36: =+K35/K14 -> 0.051311459 | L36: =+K36-J36 -> -0.020618147 | M36: =+M35/M14 -> 0.090786788 | N36: =+K36-M36 -> -0.039475329 | Q36: 합계 | S36: =+'사업장별(당월)'!T41 -> -1314.5549 | T36: =+'사업장별(당월)'!U41 -> -1960.908 | U36: =+T36-S36 -> -646.35306 | V36: =+'사업장별(당월)'!W41 -> -2576.3388 | W36: =+T36-V36 -> 615.43083
E38: =+'[1]6월'!$E$26/1000 -> 3579.6797 | F38: =+'[2]6월'!$F$26/1000 -> 1675.6492 | H38: =+'[3]6월'!$F$26/1000 -> 3848.345 | J38: =+[4]손익총괄!J38+E38 -> 16726.032 | K38: =+[4]손익총괄!K38+F38 -> 12346.336 | M38: =+[4]손익총괄!M38+H38 -> 23427.097
E39: =+E35=E38 -> TRUE | F39: =+F35=F38 -> FALSE | H39: =+H35=H38 -> TRUE | J39: =+J35=J38 -> TRUE | K39: =+K35=K38 -> FALSE | M39: =+M35=M38 -> TRUE
E40: =+E35-E38 -> 0 | F40: =+F35-F38 -> -6.8212103e-12 | H40: =+H35-H38 -> 0 | J40: =+J35-J38 -> 0 | K40: =+K35-K38 -> -2.7284841e-11 | M40: =+M35-M38 -> 0

Sheet 사업장별(당월)
H3: □ 사업장별 손익실적(2024-06)
AG4: [단위 : 천㎥, 톤, 백만원]
H5: 구분 | J5: 물량 | O5: 매출 | T5: 영업이익(공통비 배부전) | Y5: 판매단가 | AB5: 변동비 | AE5: 공헌이익
J6: 계획 | K6: 실적 | L6: 차이 | M6: 전년 | N6: 차이 | O6: 계획 | P6: 실적 | Q6: 차이 | R6: 전년 | S6: 차이 | T6: 계획 | U6: 실적 | V6: 차이 | W6: 전년 | X6: 차이 | Y6: 계획 | Z6: 실적 | AA6: 전년 | AB6: 계획 | AC6: 실적 | AD6: 전년 | AE6: 계획 | AF6: 실적 | AG6: 전년
B7: 안양 | G7: =+I7 -> 안양 | H7: 레미콘 | I7: 안양 | J7: =+IFERROR(HLOOKUP($B7,'[1]6월'!$D$6:$BN$259,2,),)/1000 -> 43 | K7: =+IFERROR(HLOOKUP($B7,'[2]6월'!$F$6:$CP$99,2,),)/1000 -> 35.374 | L7: =+K7-J7 -> -7.626 | M7: =+IFERROR(HLOOKUP($B7,'[3]6월'!$F$6:$CC$57,2,),)/1000 -> 49.16 | N7: =+K7-M7 -> -13.786 | O7: =+IFERROR(HLOOKUP($B7,'[1]6월'!$D$6:$BN$259,3,),)/1000 -> 4355.0815 | P7: =+IFERROR(HLOOKUP($B7,'[2]6월'!$F$6:$CP$99,3,),)/1000 -> 3552.1473 | Q7: =+P7-O7 -> -802.93418 | R7: =+IFERROR(HLOOKUP($B7,'[3]6월'!$F$6:$CC$57,3,),)/1000 -> 4691.3842 | S7: =+P7-R7 -> -1139.2369 | T7: =+IFERROR(HLOOKUP($B7,'[1]6월'!$D$6:$BN$259,16,),)/1000 -> 613.08992 | U7: =+IFERROR(HLOOKUP($B7,'[2]6월'!$F$6:$CP$99,16,),)/1000 -> 326.98677 | V7: =+U7-T7 -> -286.10315 | W7: =+IFERROR(HLOOKUP($B7,'[3]6월'!$F$6:$CC$57,16,),)/1000 -> 827.79901 | X7: =+U7-W7 -> -500.81224 | Y7: =+[5]안양!$Q$85 -> 101280.96 | Z7: =+[5]안양!$R$85 -> 100399.7 | AA7: =+[6]안양!$Q$85 -> 95391.443 | AB7: =+[5]안양!$Q$89 -> 78661.124 | AC7: =+[5]안양!$R$89 -> 81293.291 | AD7: =+[6]안양!$Q$89 -> 71410 | AE7: =+Y7-AB7 -> 22619.84 | AF7: =+Z7-AC7 -> 19106.408 | AG7: =+AA7-AD7 -> 23981.443
B8: 인천 | G8: =+I8 -> 인천 | H8: 직영 | I8: 인천 | J8: =+IFERROR(HLOOKUP($B8,'[1]6월'!$D$6:$BN$259,2,),)/1000 -> 30 | K8: =+IFERROR(HLOOKUP($B8,'[2]6월'!$F$6:$CP$99,2,),)/1000 -> 28.969 | L8: =+K8-J8 -> -1.031 | M8: =+IFERROR(HLOOKUP($B8,'[3]6월'!$F$6:$CC$57,2,),)/1000 -> 44.112 | N8: =+K8-M8 -> -15.143 | O8: =+IFERROR(HLOOKUP($B8,'[1]6월'!$D$6:$BN$259,3,),)/1000 -> 3041.5095 | P8: =+IFERROR(HLOOKUP($B8,'[2]6월'!$F$6:$CP$99,3,),)/1000 -> 2858.2985 | Q8: =+P8-O8 -> -183.211 | R8: =+IFERROR(HLOOKUP($B8,'[3]6월'!$F$6:$CC$57,3,),)/1000 -> 4359.3699 | S8: =+P8-R8 -> -1501.0714 | T8: =+IFERROR(HLOOKUP($B8,'[1]6월'!$D$6:$BN$259,16,),)/1000 -> 286.79226 | U8: =+IFERROR(HLOOKUP($B8,'[2]6월'!$F$6:$CP$99,16,),)/1000 -> 173.72608 | V8: =+U8-T8 -> -113.06618 | W8: =+IFERROR(HLOOKUP($B8,'[3]6월'!$F$6:$CC$57,16,),)/1000 -> 678.53517 | X8: =+U8-W8 -> -504.80908 | Y8: =+[5]인천!$Q$85 -> 101383.65 | Z8: =+[5]인천!$R$85 -> 98667.488 | AA8: =+[6]인천!$Q$85 -> 98809.253 | AB8: =+[5]인천!$Q$89 -> 80575.059 | AC8: =+[5]인천!$R$89 -> 81685.367 | AD8: =+[6]인천!$Q$89 -> 76007.006 | AE8: =+Y8-AB8 -> 20808.589 | AF8: =+Z8-AC8 -> 16982.12 | AG8: =+AA8-AD8 -> 22802.247
B9: 파주 | G9: =+I9 -> 파주 | I9: 파주 | J9: =+IFERROR(HLOOKUP($B9,'[1]6월'!$D$6:$BN$259,2,),)/1000 -> 28 | K9: =+IFERROR(HLOOKUP($B9,'[2]6월'!$F$6:$CP$99,2,),)/1000 -> 31.1242 | L9: =+K9-J9 -> 3.1242 | M9: =+IFERROR(HLOOKUP($B9,'[3]6월'!$F$6:$CC$57,2,),)/1000 -> 30.721 | N9: =+K9-M9 -> 0.4032 | O9: =+IFERROR(HLOOKUP($B9,'[1]6월'!$D$6:$BN$259,3,),)/1000 -> 2793.1233 | P9: =+IFERROR(HLOOKUP($B9,'[2]6월'!$F$6:$CP$99,3,),)/1000 -> 2951.5883 | Q9: =+P9-O9 -> 158.46503 | R9: =+IFERROR(HLOOKUP($B9,'[3]6월'!$F$6:$CC$57,3,),)/1000 -> 2851.6796 | S9: =+P9-R9 -> 99.908735 | T9: =+IFERROR(HLOOKUP($B9,'[1]6월'!$D$6:$BN$259,16,),)/1000 -> 451.71048 | U9: =+IFERROR(HLOOKUP($B9,'[2]6월'!$F$6:$CP$99,16,),)/1000 -> 256.19066 | V9: =+U9-T9 -> -195.51982 | W9: =+IFERROR(HLOOKUP($B9,'[3]6월'!$F$6:$CC$57,16,),)/1000 -> 473.04522 | X9: =+U9-W9 -> -216.85456 | Y9: =+[5]파주!$Q$85 -> 99754.402 | Z9: =+[5]파주!$R$85 -> 94837.488 | AA9: =+[6]파주!$Q$85 -> 92792.513 | AB9: =+[5]파주!$Q$89 -> 75569.989 | AC9: =+[5]파주!$R$89 -> 79548.98 | AD9: =+[6]파주!$Q$89 -> 70955.27 | AE9: =+Y9-AB9 -> 24184.414 | AF9: =+Z9-AC9 -> 15288.508 | AG9: =+AA9-AD9 -> 21837.244
B10: 김포 | G10: =+I10 -> 김포 | I10: 김포 | J10: =+IFERROR(HLOOKUP($B10,'[1]6월'!$D$6:$BN$259,2,),)/1000 -> 18.5 | K10: =+IFERROR(HLOOKUP($B10,'[2]6월'!$F$6:$CP$99,2,),)/1000 -> 11.818 | L10: =+K10-J10 -> -6.682 | M10: =+IFERROR(HLOOKUP($B10,'[3]6월'!$F$6:$CC$57,2,),)/1000 -> 20.239 | N10: =+K10-M10 -> -8.421 | O10: =+IFERROR(HLOOKUP($B10,'[1]6월'!$D$6:$BN$259,3,),)/1000 -> 1783.4705 | P10: =+IFERROR(HLOOKUP($B10,'[2]6월'!$F$6:$CP$99,3,),)/1000 -> 1148.841 | Q10: =+P10-O10 -> -634.62948 | R10: =+IFERROR(HLOOKUP($B10,'[3]6월'!$F$6:$CC$57,3,),)/1000 -> 1855.8217 | S10: =+P10-R10 -> -706.98069 | T10: =+IFERROR(HLOOKUP($B10,'[1]6월'!$D$6:$BN$259,16,),)/1000 -> 275.33432 | U10: =+IFERROR(HLOOKUP($B10,'[2]6월'!$F$6:$CP$99,16,),)/1000 -> 109.51813 | V10: =+U10-T10 -> -165.81619 | W10: =+IFERROR(HLOOKUP($B10,'[3]6월'!$F$6:$CC$57,16,),)/1000 -> 299.02149 | X10: =+U10-W10 -> -189.50336 | Y10: =+[5]김포!$Q$85 -> 96403.811 | Z10: =+[5]김포!$R$85 -> 97204.532 | AA10: =+[6]김포!$Q$85 -> 91630.527 | AB10: =+[5]김포!$Q$89 -> 71718.54 | AC10: =+[5]김포!$R$89 -> 73416.58 | AD10: =+[6]김포!$Q$89 -> 67734.297 | AE10: =+Y10-AB10 -> 24685.271 | AF10: =+Z10-AC10 -> 23787.951 | AG10: =+AA10-AD10 -> 23896.23
B11: 부산 | G11: =+I11 -> 부산 | I11: 부산 | J11: =+IFERROR(HLOOKUP($B11,'[1]6월'!$D$6:$BN$259,2,),)/1000 -> 20 | K11: =+IFERROR(HLOOKUP($B11,'[2]6월'!$F$6:$CP$99,2,),)/1000 -> 18.738 | L11: =+K11-J11 -> -1.262 | M11: =+IFERROR(HLOOKUP($B11,'[3]6월'!$F$6:$CC$57,2,),)/1000 -> 23.084 | N11: =+K11-M11 -> -4.346 | O11: =+IFERROR(HLOOKUP($B11,'[1]6월'!$D$6:$BN$259,3,),)/1000 -> 2151.9989 | P11: =+IFERROR(HLOOKUP($B11,'[2]6월'!$F$6:$CP$99,3,),)/1000 -> 1988.3392 | Q11: =+P11-O11 -> -163.6598 | R11: =+IFERROR(HLOOKUP($B11,'[3]6월'!$F$6:$CC$57,3,),)/1000 -> 2384.3393 | S11: =+P11-R11 -> -396.00015 | T11: =+IFERROR(HLOOKUP($B11,'[1]6월'!$D$6:$BN$259,16,),)/1000 -> 274.00643 | U11: =+IFERROR(HLOOKUP($B11,'[2]6월'!$F$6:$CP$99,16,),)/1000 -> 118.63264 | V11: =+U11-T11 -> -155.37379 | W11: =+IFERROR(HLOOKUP($B11,'[3]6월'!$F$6:$CC$57,16,),)/1000 -> 463.92296 | X11: =+U11-W11 -> -345.29032 | Y11: =+[5]부산!$Q$85 -> 107599.95 | Z11: =+[5]부산!$R$85 -> 106112.67 | AA11: =+[6]부산!$Q$85 -> 103289.69 | AB11: =+[5]부산!$Q$89 -> 78125.792 | AC11: =+[5]부산!$R$89 -> 82775.926 | AD11: =+[6]부산!$Q$89 -> 71742.559 | AE11: =+Y11-AB11 -> 29474.155 | AF11: =+Z11-AC11 -> 23336.741 | AG11: =+AA11-AD11 -> 31547.135
B12: 서부산 | G12: =+I12 -> 서부산 | I12: 서부산 | J12: =+IFERROR(HLOOKUP($B12,'[1]6월'!$D$6:$BN$259,2,),)/1000 -> 25 | K12: =+IFERROR(HLOOKUP($B12,'[2]6월'!$F$6:$CP$99,2,),)/1000 -> 23.641 | L12: =+K12-J12 -> -1.359 | M12: =+IFERROR(HLOOKUP($B12,'[3]6월'!$F$6:$CC$57,2,),)/1000 -> 23.514 | N12: =+K12-M12 -> 0.127 | O12: =+IFERROR(HLOOKUP($B12,'[1]6월'!$D$6:$BN$259,3,),)/1000 -> 2608.1328 | P12: =+IFERROR(HLOOKUP($B12,'[2]6월'!$F$6:$CP$99,3,),)/1000 -> 2359.6325 | Q12: =+P12-O12 -> -248.50031 | R12: =+IFERROR(HLOOKUP($B12,'[3]6월'!$F$6:$CC$57,3,),)/1000 -> 2439.7256 | S12: =+P12-R12 -> -80.093109 | T12: =+IFERROR(HLOOKUP($B12,'[1]6월'!$D$6:$BN$259,16,),)/1000 -> 466.85724 | U12: =+IFERROR(HLOOKUP($B12,'[2]6월'!$F$6:$CP$99,16,),)/1000 -> 278.69374 | V12: =+U12-T12 -> -188.1635 | W12: =+IFERROR(HLOOKUP($B12,'[3]6월'!$F$6:$CC$57,16,),)/1000 -> 455.44939 | X12: =+U12-W12 -> -176.75565 | Y12: =+[5]서부산!$Q$85 -> 104325.31 | Z12: =+[5]서부산!$R$85 -> 99811.027 | AA12: =+[6]서부산!$Q$85 -> 103756.3 | AB12: =+[5]서부산!$Q$89 -> 76362.212 | AC12: =+[5]서부산!$R$89 -> 77851.89 | AD12: =+[6]서부산!$Q$89 -> 75475.255 | AE12: =+Y12-AB12 -> 27963.1 | AF12: =+Z12-AC12 -> 21959.137 | AG12: =+AA12-AD12 -> 28281.043
B13: 김해 | G13: =+I13 -> 김해 | I13: 김해 | J13: =+IFERROR(HLOOKUP($B13,'[1]6월'!$D$6:$BN$259,2,),)/1000 -> 12 | K13: =+IFERROR(HLOOKUP($B13,'[2]6월'!$F$6:$CP$99,2,),)/1000 -> 12.699 | L13: =+K13-J13 -> 0.699 | M13: =+IFERROR(HLOOKUP($B13,'[3]6월'!$F$6:$CC$57,2,),)/1000 -> 14.851 | N13: =+K13-M13 -> -2.152 | O13: =+IFERROR(HLOOKUP($B13,'[1]6월'!$D$6:$BN$259,3,),)/1000 -> 1212.0024 | P13: =+IFERROR(HLOOKUP($B13,'[2]6월'!$F$6:$CP$99,3,),)/1000 -> 1187.9416 | Q13: =+P13-O13 -> -24.0608 | R13: =+IFERROR(HLOOKUP($B13,'[3]6월'!$F$6:$CC$57,3,),)/1000 -> 1488.0979 | S13: =+P13-R13 -> -300.1563 | T13: =+IFERROR(HLOOKUP($B13,'[1]6월'!$D$6:$BN$259,16,),)/1000 -> 149.29424 | U13: =+IFERROR(HLOOKUP($B13,'[2]6월'!$F$6:$CP$99,16,),)/1000 -> 58.544437 | V13: =+U13-T13 -> -90.749803 | W13: =+IFERROR(HLOOKUP($B13,'[3]6월'!$F$6:$CC$57,16,),)/1000 -> 282.88673 | X13: =+U13-W13 -> -224.34229 | Y13: =+[5]김해!$Q$85 -> 101000.2 | Z13: =+[5]김해!$R$85 -> 93546.074 | AA13: =+[6]김해!$Q$85 -> 100201.87 | AB13: =+[5]김해!$Q$89 -> 76138.235 | AC13: =+[5]김해!$R$89 -> 77602.809 | AD13: =+[6]김해!$Q$89 -> 71900.183 | AE13: =+Y13-AB13 -> 24861.965 | AF13: =+Z13-AC13 -> 15943.266 | AG13: =+AA13-AD13 -> 28301.682
B14: 정관 | G14: =+I14 -> 정관 | I14: 정관 | J14: =+IFERROR(HLOOKUP($B14,'[1]6월'!$D$6:$BN$259,2,),)/1000 -> 17 | K14: =+IFERROR(HLOOKUP($B14,'[2]6월'!$F$6:$CP$99,2,),)/1000 -> 19.584 | L14: =+K14-J14 -> 2.584 | M14: =+IFERROR(HLOOKUP($B14,'[3]6월'!$F$6:$CC$57,2,),)/1000 -> 19.957 | N14: =+K14-M14 -> -0.373 | O14: =+IFERROR(HLOOKUP($B14,'[1]6월'!$D$6:$BN$259,3,),)/1000 -> 1768 | P14: =+IFERROR(HLOOKUP($B14,'[2]6월'!$F$6:$CP$99,3,),)/1000 -> 1952.774 | Q14: =+P14-O14 -> 184.774 | R14: =+IFERROR(HLOOKUP($B14,'[3]6월'!$F$6:$CC$57,3,),)/1000 -> 2055.7826 | S14: =+P14-R14 -> -103.0086 | T14: =+IFERROR(HLOOKUP($B14,'[1]6월'!$D$6:$BN$259,16,),)/1000 -> 230.2157 | U14: =+IFERROR(HLOOKUP($B14,'[2]6월'!$F$6:$CP$99,16,),)/1000 -> 142.38129 | V14: =+U14-T14 -> -87.834406 | W14: =+IFERROR(HLOOKUP($B14,'[3]6월'!$F$6:$CC$57,16,),)/1000 -> 368.10467 | X14: =+U14-W14 -> -225.72338 | Y14: =+[5]정관!$Q$85 -> 104000 | Z14: =+[5]정관!$R$85 -> 99712.725 | AA14: =+[6]정관!$Q$85 -> 103010.6 | AB14: =+[5]정관!$Q$89 -> 77868.031 | AC14: =+[5]정관!$R$89 -> 80844.669 | AD14: =+[6]정관!$Q$89 -> 75355.061 | AE14: =+Y14-AB14 -> 26131.969 | AF14: =+Z14-AC14 -> 18868.056 | AG14: =+AA14-AD14 -> 27655.542
B15: 양산 | G15: =+I15 -> 양산 | I15: 양산 | J15: =+IFERROR(HLOOKUP($B15,'[1]6월'!$D$6:$BN$259,2,),)/1000 -> 10 | K15: =+IFERROR(HLOOKUP($B15,'[2]6월'!$F$6:$CP$99,2,),)/1000 -> 12.081 | L15: =+K15-J15 -> 2.081 | M15: =+IFERROR(HLOOKUP($B15,'[3]6월'!$F$6:$CC$57,2,),)/1000 -> 17.548 | N15: =+K15-M15 -> -5.467 | O15: =+IFERROR(HLOOKUP($B15,'[1]6월'!$D$6:$BN$259,3,),)/1000 -> 963.85316 | P15: =+IFERROR(HLOOKUP($B15,'[2]6월'!$F$6:$CP$99,3,),)/1000 -> 1127.2838 | Q15: =+P15-O15 -> 163.43064 | R15: =+IFERROR(HLOOKUP($B15,'[3]6월'!$F$6:$CC$57,3,),)/1000 -> 1641.2462 | S15: =+P15-R15 -> -513.9624 | T15: =+IFERROR(HLOOKUP($B15,'[1]6월'!$D$6:$BN$259,16,),)/1000 -> 112.78897 | U15: =+IFERROR(HLOOKUP($B15,'[2]6월'!$F$6:$CP$99,16,),)/1000 -> 79.077275 | V15: =+U15-T15 -> -33.711694 | W15: =+IFERROR(HLOOKUP($B15,'[3]6월'!$F$6:$CC$57,16,),)/1000 -> 311.39311 | X15: =+U15-W15 -> -232.31584 | Y15: =+[5]양산!$Q$85 -> 96385.316 | Z15: =+[5]양산!$R$85 -> 93310.471 | AA15: =+[6]양산!$Q$85 -> 93528.961 | AB15: =+[5]양산!$Q$89 -> 69597.591 | AC15: =+[5]양산!$R$89 -> 74393.84 | AD15: =+[6]양산!$Q$89 -> 68124.296 | AE15: =+Y15-AB15 -> 26787.725 | AF15: =+Z15-AC15 -> 18916.631 | AG15: =+AA15-AD15 -> 25404.665
B16: 창원 | G16: =+I16 -> 창원 | I16: 창원 | J16: =+IFERROR(HLOOKUP($B16,'[1]6월'!$D$6:$BN$259,2,),)/1000 -> 17 | K16: =+IFERROR(HLOOKUP($B16,'[2]6월'!$F$6:$CP$99,2,),)/1000 -> 20.596 | L16: =+K16-J16 -> 3.596 | M16: =+IFERROR(HLOOKUP($B16,'[3]6월'!$F$6:$CC$57,2,),)/1000 -> 20.557 | N16: =+K16-M16 -> 0.039 | O16: =+IFERROR(HLOOKUP($B16,'[1]6월'!$D$6:$BN$259,3,),)/1000 -> 1728.067 | P16: =+IFERROR(HLOOKUP($B16,'[2]6월'!$F$6:$CP$99,3,),)/1000 -> 2041.9576 | Q16: =+P16-O16 -> 313.8906 | R16: =+IFERROR(HLOOKUP($B16,'[3]6월'!$F$6:$CC$57,3,),)/1000 -> 2001.3488 | S16: =+P16-R16 -> 40.6088 | T16: =+IFERROR(HLOOKUP($B16,'[1]6월'!$D$6:$BN$259,16,),)/1000 -> 264.21305 | U16: =+IFERROR(HLOOKUP($B16,'[2]6월'!$F$6:$CP$99,16,),)/1000 -> 281.4937 | V16: =+U16-T16 -> 17.280655 | W16: =+IFERROR(HLOOKUP($B16,'[3]6월'!$F$6:$CC$57,16,),)/1000 -> 423.39159 | X16: =+U16-W16 -> -141.89788 | Y16: =+[5]창원!$Q$85 -> 101651 | Z16: =+[5]창원!$R$85 -> 99143.406 | AA16: =+[6]창원!$Q$85 -> 97356.073 | AB16: =+[5]창원!$Q$89 -> 72300.629 | AC16: =+[5]창원!$R$89 -> 74759.318 | AD16: =+[6]창원!$Q$89 -> 66837.89 | AE16: =+Y16-AB16 -> 29350.371 | AF16: =+Z16-AC16 -> 24384.088 | AG16: =+AA16-AD16 -> 30518.184
B17: 대구 | G17: =+I17 -> 대구 | I17: 대구 | J17: =+IFERROR(HLOOKUP($B17,'[1]6월'!$D$6:$BN$259,2,),)/1000 -> 16.5 | K17: =+IFERROR(HLOOKUP($B17,'[2]6월'!$F$6:$CP$99,2,),)/1000 -> 15.957 | L17: =+K17-J17 -> -0.543 | M17: =+IFERROR(HLOOKUP($B17,'[3]6월'!$F$6:$CC$57,2,),)/1000 -> 18.367 | N17: =+K17-M17 -> -2.41 | O17: =+IFERROR(HLOOKUP($B17,'[1]6월'!$D$6:$BN$259,3,),)/1000 -> 1613.04 | P17: =+IFERROR(HLOOKUP($B17,'[2]6월'!$F$6:$CP$99,3,),)/1000 -> 1689.6666 | Q17: =+P17-O17 -> 76.62657 | R17: =+IFERROR(HLOOKUP($B17,'[3]6월'!$F$6:$CC$57,3,),)/1000 -> 1757.3783 | S17: =+P17-R17 -> -67.71173 | T17: =+IFERROR(HLOOKUP($B17,'[1]6월'!$D$6:$BN$259,16,),)/1000 -> 306.08988 | U17: =+IFERROR(HLOOKUP($B17,'[2]6월'!$F$6:$CP$99,16,),)/1000 -> 285.78178 | V17: =+U17-T17 -> -20.308101 | W17: =+IFERROR(HLOOKUP($B17,'[3]6월'!$F$6:$CC$57,16,),)/1000 -> 371.82623 | X17: =+U17-W17 -> -86.044448 | Y17: =+[5]대구!$Q$85 -> 97760 | Z17: =+[5]대구!$R$85 -> 105888.74 | AA17: =+[6]대구!$Q$85 -> 95666.26 | AB17: =+[5]대구!$Q$89 -> 68358.488 | AC17: =+[5]대구!$R$89 -> 76495.675 | AD17: =+[6]대구!$Q$89 -> 66158.542 | AE17: =+Y17-AB17 -> 29401.512 | AF17: =+Z17-AC17 -> 29393.061 | AG17: =+AA17-AD17 -> 29507.718
B18: 울산 | G18: =+I18 -> 울산 | I18: 울산 | J18: =+IFERROR(HLOOKUP($B18,'[1]6월'!$D$6:$BN$259,2,),)/1000 -> 11 | K18: =+IFERROR(HLOOKUP($B18,'[2]6월'!$F$6:$CP$99,2,),)/1000 -> 14.496 | L18: =+K18-J18 -> 3.496 | M18: =+IFERROR(HLOOKUP($B18,'[3]6월'!$F$6:$CC$57,2,),)/1000 -> 8.687 | N18: =+K18-M18 -> 5.809 | O18: =+IFERROR(HLOOKUP($B18,'[1]6월'!$D$6:$BN$259,3,),)/1000 -> 1113.4317 | P18: =+IFERROR(HLOOKUP($B18,'[2]6월'!$F$6:$CP$99,3,),)/1000 -> 1547.3991 | Q18: =+P18-O18 -> 433.96741 | R18: =+IFERROR(HLOOKUP($B18,'[3]6월'!$F$6:$CC$57,3,),)/1000 -> 839.83615 | S18: =+P18-R18 -> 707.563 | T18: =+IFERROR(HLOOKUP($B18,'[1]6월'!$D$6:$BN$259,16,),)/1000 -> 122.02935 | U18: =+IFERROR(HLOOKUP($B18,'[2]6월'!$F$6:$CP$99,16,),)/1000 -> 273.46478 | V18: =+U18-T18 -> 151.43543 | W18: =+IFERROR(HLOOKUP($B18,'[3]6월'!$F$6:$CC$57,16,),)/1000 -> 102.44357 | X18: =+U18-W18 -> 171.0212 | Y18: =+[5]울산!$Q$85 -> 101221.07 | Z18: =+[5]울산!$R$85 -> 106746.63 | AA18: =+[6]울산!$Q$85 -> 96682.853 | AB18: =+[5]울산!$Q$89 -> 77493.608 | AC18: =+[5]울산!$R$89 -> 79098.881 | AD18: =+[6]울산!$Q$89 -> 72088.073 | AE18: =+Y18-AB18 -> 23727.459 | AF18: =+Z18-AC18 -> 27647.749 | AG18: =+AA18-AD18 -> 24594.78
B19: 아산 | G19: =+I19 -> 아산 | I19: 아산 | J19: =+IFERROR(HLOOKUP($B19,'[1]6월'!$D$6:$BN$259,2,),)/1000 -> 24 | K19: =+IFERROR(HLOOKUP($B19,'[2]6월'!$F$6:$CP$99,2,),)/1000 -> 30.673 | L19: =+K19-J19 -> 6.673 | M19: =+IFERROR(HLOOKUP($B19,'[3]6월'!$F$6:$CC$57,2,),)/1000 -> 24.8 | N19: =+K19-M19 -> 5.873 | O19: =+IFERROR(HLOOKUP($B19,'[1]6월'!$D$6:$BN$259,3,),)/1000 -> 2424.0036 | P19: =+IFERROR(HLOOKUP($B19,'[2]6월'!$F$6:$CP$99,3,),)/1000 -> 3094.9295 | Q19: =+P19-O19 -> 670.92586 | R19: =+IFERROR(HLOOKUP($B19,'[3]6월'!$F$6:$CC$57,3,),)/1000 -> 2440.2958 | S19: =+P19-R19 -> 654.63366 | T19: =+IFERROR(HLOOKUP($B19,'[1]6월'!$D$6:$BN$259,16,),)/1000 -> 387.74728 | U19: =+IFERROR(HLOOKUP($B19,'[2]6월'!$F$6:$CP$99,16,),)/1000 -> 517.15088 | V19: =+U19-T19 -> 129.4036 | W19: =+IFERROR(HLOOKUP($B19,'[3]6월'!$F$6:$CC$57,16,),)/1000 -> 467.73002 | X19: =+U19-W19 -> 49.420864 | Y19: =+[5]아산!$Q$85 -> 101000.15 | Z19: =+[5]아산!$R$85 -> 100900.77 | AA19: =+[6]아산!$Q$85 -> 98555.127 | AB19: =+[5]아산!$Q$89 -> 75742.611 | AC19: =+[5]아산!$R$89 -> 75826.368 | AD19: =+[6]아산!$Q$89 -> 71190.348 | AE19: =+Y19-AB19 -> 25257.539 | AF19: =+Z19-AC19 -> 25074.407 | AG19: =+AA19-AD19 -> 27364.779
B20: 전주 | G20: =+I20 -> 전주 | I20: 전주 | J20: =+IFERROR(HLOOKUP($B20,'[1]6월'!$D$6:$BN$259,2,),)/1000 -> 13 | K20: =+IFERROR(HLOOKUP($B20,'[2]6월'!$F$6:$CP$99,2,),)/1000 -> 7.9935 | L20: =+K20-J20 -> -5.0065 | M20: =+IFERROR(HLOOKUP($B20,'[3]6월'!$F$6:$CC$57,2,),)/1000 -> 12.6475 | N20: =+K20-M20 -> -4.654 | O20: =+IFERROR(HLOOKUP($B20,'[1]6월'!$D$6:$BN$259,3,),)/1000 -> 1347.8929 | P20: =+IFERROR(HLOOKUP($B20,'[2]6월'!$F$6:$CP$99,3,),)/1000 -> 745.8426 | Q20: =+P20-O20 -> -602.05029 | R20: =+IFERROR(HLOOKUP($B20,'[3]6월'!$F$6:$CC$57,3,),)/1000 -> 1250.7507 | S20: =+P20-R20 -> -504.90805 | T20: =+IFERROR(HLOOKUP($B20,'[1]6월'!$D$6:$BN$259,16,),)/1000 -> 249.37979 | U20: =+IFERROR(HLOOKUP($B20,'[2]6월'!$F$6:$CP$99,16,),)/1000 -> 26.426647 | V20: =+U20-T20 -> -222.95314 | W20: =+IFERROR(HLOOKUP($B20,'[3]6월'!$F$6:$CC$57,16,),)/1000 -> 281.72896 | X20: =+U20-W20 -> -255.30232 | Y20: =+[5]전주!$Q$85 -> 103684.07 | Z20: =+[5]전주!$R$85 -> 93306.136 | AA20: =+[6]전주!$Q$85 -> 99035.303 | AB20: =+[5]전주!$Q$89 -> 73031.273 | AC20: =+[5]전주!$R$89 -> 69399.752 | AD20: =+[6]전주!$Q$89 -> 66752.807 | AE20: =+Y20-AB20 -> 30652.796 | AF20: =+Z20-AC20 -> 23906.384 | AG20: =+AA20-AD20 -> 32282.496
B21: 군산 | G21: =+I21 -> 군산 | I21: 군산 | J21: =+IFERROR(HLOOKUP($B21,'[1]6월'!$D$6:$BN$259,2,),)/1000 -> 7.5 | K21: =+IFERROR(HLOOKUP($B21,'[2]6월'!$F$6:$CP$99,2,),)/1000 -> 10.45 | L21: =+K21-J21 -> 2.95 | M21: =+IFERROR(HLOOKUP($B21,'[3]6월'!$F$6:$CC$57,2,),)/1000 -> 8.807 | N21: =+K21-M21 -> 1.643 | O21: =+IFERROR(HLOOKUP($B21,'[1]6월'!$D$6:$BN$259,3,),)/1000 -> 817.18473 | P21: =+IFERROR(HLOOKUP($B21,'[2]6월'!$F$6:$CP$99,3,),)/1000 -> 1231.4346 | Q21: =+P21-O21 -> 414.24987 | R21: =+IFERROR(HLOOKUP($B21,'[3]6월'!$F$6:$CC$57,3,),)/1000 -> 871.30717 | S21: =+P21-R21 -> 360.12743 | T21: =+IFERROR(HLOOKUP($B21,'[1]6월'!$D$6:$BN$259,16,),)/1000 -> 217.12346 | U21: =+IFERROR(HLOOKUP($B21,'[2]6월'!$F$6:$CP$99,16,),)/1000 -> 359.65576 | V21: =+U21-T21 -> 142.5323 | W21: =+IFERROR(HLOOKUP($B21,'[3]6월'!$F$6:$CC$57,16,),)/1000 -> 209.08494 | X21: =+U21-W21 -> 150.57082 | Y21: =+[5]군산!$Q$85 -> 108957.96 | Z21: =+[5]군산!$R$85 -> 117840.63 | AA21: =+[6]군산!$Q$85 -> 98570.921 | AB21: =+[5]군산!$Q$89 -> 69325.559 | AC21: =+[5]군산!$R$89 -> 75736.722 | AD21: =+[6]군산!$Q$89 -> 64797.832 | AE21: =+Y21-AB21 -> 39632.406 | AF21: =+Z21-AC21 -> 42103.909 | AG21: =+AA21-AD21 -> 33773.089
B22: 원주 | G22: =+I22 -> 원주 | I22: 원주 | J22: =+IFERROR(HLOOKUP($B22,'[1]6월'!$D$6:$BN$259,2,),)/1000 -> 5 | K22: =+IFERROR(HLOOKUP($B22,'[2]6월'!$F$6:$CP$99,2,),)/1000 -> 6.349 | L22: =+K22-J22 -> 1.349 | M22: =+IFERROR(HLOOKUP($B22,'[3]6월'!$F$6:$CC$57,2,),)/1000 -> 4.638 | N22: =+K22-M22 -> 1.711 | O22: =+IFERROR(HLOOKUP($B22,'[1]6월'!$D$6:$BN$259,3,),)/1000 -> 539.5 | P22: =+IFERROR(HLOOKUP($B22,'[2]6월'!$F$6:$CP$99,3,),)/1000 -> 730.5149 | Q22: =+P22-O22 -> 191.0149 | R22: =+IFERROR(HLOOKUP($B22,'[3]6월'!$F$6:$CC$57,3,),)/1000 -> 468.8184 | S22: =+P22-R22 -> 261.6965 | T22: =+IFERROR(HLOOKUP($B22,'[1]6월'!$D$6:$BN$259,16,),)/1000 -> 88.524752 | U22: =+IFERROR(HLOOKUP($B22,'[2]6월'!$F$6:$CP$99,16,),)/1000 -> 157.5276 | V22: =+U22-T22 -> 69.00285 | W22: =+IFERROR(HLOOKUP($B22,'[3]6월'!$F$6:$CC$57,16,),)/1000 -> 76.760799 | X22: =+U22-W22 -> 80.766803 | Y22: =+[5]원주!$Q$85 -> 107900 | Z22: =+[5]원주!$R$85 -> 115059.84 | AA22: =+[6]원주!$Q$85 -> 101117.99 | AB22: =+[5]원주!$Q$89 -> 72494.918 | AC22: =+[5]원주!$R$89 -> 75609.7 | AD22: =+[6]원주!$Q$89 -> 68277.322 | AE22: =+Y22-AB22 -> 35405.082 | AF22: =+Z22-AC22 -> 39450.137 | AG22: =+AA22-AD22 -> 32840.671
B23: 제주 | G23: =+I23 -> 제주 | I23: 제주 | J23: =+IFERROR(HLOOKUP($B23,'[1]6월'!$D$6:$BN$259,2,),)/1000 -> 6 | K23: =+IFERROR(HLOOKUP($B23,'[2]6월'!$F$6:$CP$99,2,),)/1000 -> 4.611 | L23: =+K23-J23 -> -1.389 | M23: =+IFERROR(HLOOKUP($B23,'[3]6월'!$F$6:$CC$57,2,),)/1000 -> 8.3925 | N23: =+K23-M23 -> -3.7815 | O23: =+IFERROR(HLOOKUP($B23,'[1]6월'!$D$6:$BN$259,3,),)/1000 -> 760.8 | P23: =+IFERROR(HLOOKUP($B23,'[2]6월'!$F$6:$CP$99,3,),)/1000 -> 568.44685 | Q23: =+P23-O23 -> -192.35315 | R23: =+IFERROR(HLOOKUP($B23,'[3]6월'!$F$6:$CC$57,3,),)/1000 -> 1009.5331 | S23: =+P23-R23 -> -441.08622 | T23: =+IFERROR(HLOOKUP($B23,'[1]6월'!$D$6:$BN$259,16,),)/1000 -> 122.30759 | U23: =+IFERROR(HLOOKUP($B23,'[2]6월'!$F$6:$CP$99,16,),)/1000 -> 65.194074 | V23: =+U23-T23 -> -57.11352 | W23: =+IFERROR(HLOOKUP($B23,'[3]6월'!$F$6:$CC$57,16,),)/1000 -> 207.5061 | X23: =+U23-W23 -> -142.31202 | Y23: =+[5]제주!$Q$85 -> 126800 | Z23: =+[5]제주!$R$85 -> 123280.6 | AA23: =+[6]제주!$Q$85 -> 120298.27 | AB23: =+[5]제주!$Q$89 -> 91078.011 | AC23: =+[5]제주!$R$89 -> 90143.963 | AD23: =+[6]제주!$Q$89 -> 86402.017 | AE23: =+Y23-AB23 -> 35721.989 | AF23: =+Z23-AC23 -> 33136.637 | AG23: =+AA23-AD23 -> 33896.249
G24: =+I24 -> 수도권 | I24: 수도권 | J24: =SUM(J7:J10) -> 119.5 | K24: =SUM(K7:K10) -> 107.2852 | L24: =+K24-J24 -> -12.2148 | M24: =SUM(M7:M10) -> 144.232 | N24: =+K24-M24 -> -36.9468 | O24: =SUM(O7:O10) -> 11973.185 | P24: =SUM(P7:P10) -> 10510.875 | Q24: =+P24-O24 -> -1462.3096 | R24: =SUM(R7:R10) -> 13758.255 | S24: =+P24-R24 -> -3247.3803 | T24: =SUM(T7:T10) -> 1626.927 | U24: =SUM(U7:U10) -> 866.42165 | V24: =+U24-T24 -> -760.50534 | W24: =SUM(W7:W10) -> 2278.4009 | X24: =+U24-W24 -> -1411.9792 | Y24: =+[5]수도권!$Q$85 -> 100194.01 | Z24: =+[5]수도권!$R$85 -> 97972.586 | AA24: =+[6]수도권!$Q$85 -> 95370.959 | AB24: =+[5]수도권!$Q$89 -> 77342.534 | AC24: =+[5]수도권!$R$89 -> 80027.502 | AD24: =+[6]수도권!$Q$89 -> 72212.802 | AE24: =+Y24-AB24 -> 22851.48 | AF24: =+Z24-AC24 -> 17945.084 | AG24: =+AA24-AD24 -> 23158.157
G25: =+I25 -> 영남권 | I25: 영남권 | J25: =SUM(J11:J18) -> 128.5 | K25: =SUM(K11:K18) -> 137.792 | L25: =+K25-J25 -> 9.292 | M25: =SUM(M11:M18) -> 146.565 | N25: =+K25-M25 -> -8.773 | O25: =SUM(O11:O18) -> 13158.526 | P25: =SUM(P11:P18) -> 13894.994 | Q25: =+P25-O25 -> 736.46831 | R25: =SUM(R11:R18) -> 14607.755 | S25: =+P25-R25 -> -712.76049 | T25: =SUM(T11:T18) -> 1925.4949 | U25: =SUM(U11:U18) -> 1518.0696 | V25: =+U25-T25 -> -407.42521 | W25: =SUM(W11:W18) -> 2779.4182 | X25: =+U25-W25 -> -1261.3486 | Y25: =+[5]영남권!$Q$85 -> 102400.98 | Z25: =+[5]영남권!$R$85 -> 100840.36 | AA25: =+[6]영남권!$Q$85 -> 99670.721 | AB25: =+[5]영남권!$Q$89 -> 74820.372 | AC25: =+[5]영남권!$R$89 -> 78131.984 | AD25: =+[6]영남권!$Q$89 -> 71056.777 | AE25: =+Y25-AB25 -> 27580.609 | AF25: =+Z25-AC25 -> 22708.372 | AG25: =+AA25-AD25 -> 28613.943
G26: =+I26 -> 중부권 | I26: 중부권 | J26: =SUM(J19:J23) -> 55.5 | K26: =SUM(K19:K23) -> 60.0765 | L26: =+K26-J26 -> 4.5765 | M26: =SUM(M19:M23) -> 59.285 | N26: =+K26-M26 -> 0.7915 | O26: =SUM(O19:O23) -> 5889.3812 | P26: =SUM(P19:P23) -> 6371.1684 | Q26: =+P26-O26 -> 481.78719 | R26: =SUM(R19:R23) -> 6040.7051 | S26: =+P26-R26 -> 330.46331 | T26: =SUM(T19:T23) -> 1065.0829 | U26: =SUM(U19:U23) -> 1125.955 | V26: =+U26-T26 -> 60.872087 | W26: =SUM(W19:W23) -> 1242.8108 | X26: =+U26-W26 -> -116.85586 | Y26: =+[5]중부권!$Q$85 -> 106114.98 | Z26: =+[5]중부권!$R$85 -> 106050.93 | AA26: =+[6]중부권!$Q$85 -> 102035.99 | AB26: =+[5]중부권!$Q$89 -> 75605.65 | AC26: =+[5]중부권!$R$89 -> 76044.867 | AD26: =+[6]중부권!$Q$89 -> 71271.842 | AE26: =+Y26-AB26 -> 30509.327 | AF26: =+Z26-AC26 -> 30006.058 | AG26: =+AA26-AD26 -> 30764.15
G27: =+K27/J27 -> 1.0054488 | H27: 레미콘 계 | J27: =SUM(J24:J26) -> 303.5 | K27: =SUM(K24:K26) -> 305.1537 | L27: =+K27-J27 -> 1.6537 | M27: =SUM(M24:M26) -> 350.082 | N27: =+K27-M27 -> -44.9283 | O27: =SUM(O24:O26) -> 31021.092 | P27: =SUM(P24:P26) -> 30777.038 | Q27: =+P27-O27 -> -244.05413 | R27: =SUM(R24:R26) -> 34406.715 | S27: =+P27-R27 -> -3629.6774 | T27: =SUM(T24:T26) -> 4617.5047 | U27: =SUM(U24:U26) -> 3510.4462 | V27: =+U27-T27 -> -1107.0585 | W27: =SUM(W24:W26) -> 6300.63 | X27: =+U27-W27 -> -2790.1837 | Y27: =+[5]합계!$Q$85 -> 102211.18 | Z27: =+[5]합계!$R$85 -> 100861.45 | AA27: =+[6]합계!$Q$85 -> 98290.639 | AB27: =+[5]합계!$Q$89 -> 75957.048 | AC27: =+[5]합계!$R$89 -> 78384.694 | AD27: =+[6]합계!$Q$89 -> 71567.894 | AE27: =+Y27-AB27 -> 26254.128 | AF27: =+Z27-AC27 -> 22476.76 | AG27: =+AA27-AD27 -> 26722.744
B28: 건자재 | E28: 건자재영업 | G28: 건자재 | H28: 건자재 | J28: =+IFERROR(HLOOKUP($B28,'[1]6월'!$D$6:$BN$259,2,),) -> 6100 | K28: =+IFERROR(HLOOKUP($E28,'[2]6월'!$F$6:$CP$99,2,),) -> 7982.061 | L28: =+K28-J28 -> 1882.061 | M28: =+IFERROR(HLOOKUP($E28,'[3]6월'!$F$6:$CC$57,2,),) -> 7070.5 | N28: =+K28-M28 -> 911.561 | O28: =+IFERROR(HLOOKUP($B28,'[1]6월'!$D$6:$BN$259,3,),)/1000 -> 7443.8253 | P28: =+IFERROR(HLOOKUP($E28,'[2]6월'!$F$6:$CP$99,3,),)/1000 -> 7873.3448 | Q28: =+P28-O28 -> 429.51951 | R28: =+IFERROR(HLOOKUP($E28,'[3]6월'!$F$6:$CC$57,3,),)/1000 -> 8947.0894 | S28: =+P28-R28 -> -1073.7446 | T28: =+IFERROR(HLOOKUP($B28,'[1]6월'!$D$6:$BN$259,16,),)/1000 -> 65.463103 | U28: =+IFERROR(HLOOKUP($E28,'[2]6월'!$F$6:$CP$99,16,),)/1000 -> 150.16984 | V28: =+U28-T28 -> 84.706737 | W28: =+IFERROR(HLOOKUP($E28,'[3]6월'!$F$6:$CC$57,16,),)/1000 -> 117.02504 | X28: =+U28-W28 -> 33.144798 | Y28: ■ 비고
B29: 부산모래장 | C29: 부산골재 | G29: =+I29 -> 부산모래장 | H29: 골재 | I29: 부산모래장 | J29: =+IFERROR(HLOOKUP($B29,'[1]6월'!$D$6:$BN$259,2,),)/1000 -> 27.56538 | K29: =+IFERROR(HLOOKUP($C29,'[2]6월'!$F$6:$CP$99,2,),)/1000 -> 18.49 | L29: =+K29-J29 -> -9.0753797 | M29: =+IFERROR(HLOOKUP($C29,'[3]6월'!$F$6:$CC$57,2,),)/1000 -> 27.381 | N29: =+K29-M29 -> -8.891 | O29: =+IFERROR(HLOOKUP($B29,'[1]6월'!$D$6:$BN$259,3,),)/1000 -> 783.26375 | P29: =+IFERROR(HLOOKUP($C29,'[2]6월'!$F$6:$CP$99,3,),)/1000 -> 536.244 | Q29: =+P29-O29 -> -247.01975 | R29: =+IFERROR(HLOOKUP($C29,'[3]6월'!$F$6:$CC$57,3,),)/1000 -> 793.573 | S29: =+P29-R29 -> -257.329 | T29: =+IFERROR(HLOOKUP($B29,'[1]6월'!$D$6:$BN$259,21,),)/1000 -> -13.063949 | U29: =+IFERROR(HLOOKUP($C29,'[2]6월'!$F$6:$CP$99,21,),)/1000 -> -53.966539 | V29: =+U29-T29 -> -40.90259 | W29: =+IFERROR(HLOOKUP($C29,'[3]6월'!$F$6:$CC$57,16,),)/1000 -> 8.366336 | X29: =+U29-W29 -> -62.332875 | Y29: - 대손환입 6.2억 : 집합 7.3억, ㈜신일 0.6억 환입 / 대손충당 남양건설㈜ 1.7억
B30: 서부산크라샤 | C30: 서부산골재 | G30: =+I30 -> 서부산CR | I30: 서부산CR | J30: =+IFERROR(HLOOKUP($B30,'[1]6월'!$D$6:$BN$259,2,),)/1000 -> 50.237673 | K30: =+IFERROR(HLOOKUP($C30,'[2]6월'!$F$6:$CP$99,2,),)/1000 -> 24.944 | L30: =+K30-J30 -> -25.293673 | M30: =+IFERROR(HLOOKUP($C30,'[3]6월'!$F$6:$CC$57,2,),)/1000 -> 33.392 | N30: =+K30-M30 -> -8.448 | O30: =+IFERROR(HLOOKUP($B30,'[1]6월'!$D$6:$BN$259,3,),)/1000 -> 619.24877 | P30: =+IFERROR(HLOOKUP($C30,'[2]6월'!$F$6:$CP$99,3,),)/1000 -> 344.552 | Q30: =+P30-O30 -> -274.69677 | R30: =+IFERROR(HLOOKUP($C30,'[3]6월'!$F$6:$CC$57,3,),)/1000 -> 396.256 | S30: =+P30-R30 -> -51.704 | T30: =+IFERROR(HLOOKUP($B30,'[1]6월'!$D$6:$BN$259,21,),)/1000 -> 174.71702 | U30: =+IFERROR(HLOOKUP($C30,'[2]6월'!$F$6:$CP$99,21,),)/1000 -> 23.263172 | V30: =+U30-T30 -> -151.45385 | W30: =+IFERROR(HLOOKUP($C30,'[3]6월'!$F$6:$CC$57,16,),)/1000 -> 52.48206 | X30: =+U30-W30 -> -29.218888
B31: 부산크라샤 | C31: 부산크라샤 | G31: =+I31 -> 부산CR | I31: 부산CR | J31: =+IFERROR(HLOOKUP($B31,'[1]6월'!$D$6:$BN$259,2,),)/1000 -> 41.645146 | K31: =+IFERROR(HLOOKUP($C31,'[2]6월'!$F$6:$CP$99,2,),)/1000 -> 32.89 | L31: =+K31-J31 -> -8.7551455 | M31: =+IFERROR(HLOOKUP($C31,'[3]6월'!$F$6:$CC$57,2,),)/1000 -> 3.8 | N31: =+K31-M31 -> 29.09 | O31: =+IFERROR(HLOOKUP($B31,'[1]6월'!$D$6:$BN$259,3,),)/1000 -> 748.14153 | P31: =+IFERROR(HLOOKUP($C31,'[2]6월'!$F$6:$CP$99,3,),)/1000 -> 596.203 | Q31: =+P31-O31 -> -151.93853 | R31: =+IFERROR(HLOOKUP($C31,'[3]6월'!$F$6:$CC$57,3,),)/1000 -> 67.48 | S31: =+P31-R31 -> 528.723 | T31: =+IFERROR(HLOOKUP($B31,'[1]6월'!$D$6:$BN$259,21,),)/1000 -> 49.613709 | U31: =+IFERROR(HLOOKUP($C31,'[2]6월'!$F$6:$CP$99,21,),)/1000 -> 6.6444047 | V31: =+U31-T31 -> -42.969305 | W31: =+IFERROR(HLOOKUP($C31,'[3]6월'!$F$6:$CC$57,16,),)/1000 -> -53.819569 | X31: =+U31-W31 -> 60.463974
H32: 골재 계 | J32: =SUM(J29:J31) -> 119.4482 | K32: =SUM(K29:K31) -> 76.324 | L32: =+K32-J32 -> -43.124199 | M32: =SUM(M29:M31) -> 64.573 | N32: =+K32-M32 -> 11.751 | O32: =SUM(O29:O31) -> 2150.6541 | P32: =SUM(P29:P31) -> 1476.999 | Q32: =+P32-O32 -> -673.65505 | R32: =SUM(R29:R31) -> 1257.309 | S32: =+P32-R32 -> 219.69 | T32: =SUM(T29:T31) -> 211.26679 | U32: =SUM(U29:U31) -> -24.058962 | V32: =+U32-T32 -> -235.32575 | W32: =SUM(W29:W31) -> 7.028827 | X32: =+U32-W32 -> -31.087789
B33: 포항임대 | C33: 속초임대 | D33: 강릉임대 | E33: 레미콘임대 계 | G33: =+I33 -> 레미콘임대 | H33: 기타 | I33: 레미콘임대 | L33: =+K33-J33 -> 0 | N33: =+K33-M33 -> 0 | O33: =(IFERROR(HLOOKUP($B33,'[1]6월'!$D$6:$BN$259,3,),)++IFERROR(HLOOKUP($C33,'[1]6월'!$D$6:$BN$259,3,),)+IFERROR(HLOOKUP($D33,'[1]6월'!$D$6:$BN$259,3,),))/1000 -> 90.84 | P33: =+IFERROR(HLOOKUP($E33,'[2]6월'!$F$6:$CP$99,3,),)/1000 -> 90.84 | Q33: =+P33-O33 -> 0 | R33: =+IFERROR(HLOOKUP($E33,'[3]6월'!$F$6:$CC$57,3,),)/1000 -> 84.59 | S33: =+P33-R33 -> 6.25 | T33: =(IFERROR(HLOOKUP($B33,'[1]6월'!$D$6:$BN$259,21,),)++IFERROR(HLOOKUP($C33,'[1]6월'!$D$6:$BN$259,21,),)+IFERROR(HLOOKUP($D33,'[1]6월'!$D$6:$BN$259,21,),))/1000 -> 13.943842 | U33: =+IFERROR(HLOOKUP($E33,'[2]6월'!$F$6:$CP$99,16,),)/1000 -> -23.482855 | V33: =+U33-T33 -> -37.426697 | W33: =+IFERROR(HLOOKUP($E33,'[3]6월'!$F$6:$CC$57,16,),)/1000 -> -3.942039 | X33: =+U33-W33 -> -19.540816
B34: 부동산임대 | C34: 주유소임대 | E34: 임대 계 | G34: =+I34 -> 임대 | I34: 임대 | L34: =+K34-J34 -> 0 | M34: 0 | N34: =+K34-M34 -> 0 | O34: =(+IFERROR(HLOOKUP($B34,'[1]6월'!$D$6:$BN$259,3,),)+IFERROR(HLOOKUP($C34,'[1]6월'!$D$6:$BN$259,3,),))/1000 -> 72.2975 | P34: =+IFERROR(HLOOKUP($E34,'[2]6월'!$F$6:$CP$99,3,),)/1000 -> 73.635212 | Q34: =+P34-O34 -> 1.3377117 | R34: =+IFERROR(HLOOKUP($E34,'[3]6월'!$F$6:$CC$57,3,),)/1000 -> 95.260091 | S34: =+P34-R34 -> -21.624879 | T34: =(+IFERROR(HLOOKUP($B34,'[1]6월'!$D$6:$BN$259,21,),)+IFERROR(HLOOKUP($C34,'[1]6월'!$D$6:$BN$259,21,),))/1000 -> 74.638401 | U34: =+IFERROR(HLOOKUP($E34,'[2]6월'!$F$6:$CP$99,16,),)/1000 -> 76.100837 | V34: =+U34-T34 -> 1.4624357 | W34: =+IFERROR(HLOOKUP($E34,'[3]6월'!$F$6:$CC$57,16,),)/1000 -> 98.057103 | X34: =+U34-W34 -> -21.956266
B35: 공 통 비 | G35: =+I35 -> 공통비 | I35: 공통비 | L35: =+K35-J35 -> 0 | N35: =+K35-M35 -> 0 | Q35: =+P35-O35 -> 0 | S35: =+P35-R35 -> 0 | T35: =-'[1]6월'!$Z$22/1000 -> -2614.3237 | U35: =+-'[2]6월'!$Z$22/1000 -> -2487.3998 | V35: =+U35-T35 -> 126.92383 | W35: =+-'[3]6월'!$Z$22/1000 -> -1613.42 | X35: =+U35-W35 -> -873.97987
G36: =+I36 -> OPC 소급분 | I36: OPC 소급분 | N36: =+K36-M36 -> 0 | Q36: =+P36-O36 -> 0 | S36: =+P36-R36 -> 0 | T36: =+'[1]6월'!$AS$26/1000 -> 1329.7 | U36: =-'[2]6월'!$BD$26/1000 -> 0 | V36: =+U36-T36 -> -1329.7 | W36: =-'[3]6월'!$BD$26/1000 -> 0 | X36: =+U36-W36 -> 0
G37: =+I37 -> 대손 | I37: 대손 | N37: =+K37-M37 -> 0 | Q37: =+P37-O37 -> 0 | S37: =+P37-R37 -> 0 | U37: ='[2]6월'!$BE$26/1000 -> 620.33483 | V37: =+U37-T37 -> 620.33483 | W37: ='[3]6월'!$BE$26/1000 -> -968.71633 | X37: =+U37-W37 -> 1589.0512
G38: =+I38 -> 미운영 공장 | I38: 미운영 공장 | M38: =SUM(M54:M57) -> 0 | N38: =+K38-M38 -> 0 | Q38: =+P38-O38 -> 0 | R38: =+IFERROR(HLOOKUP($I$38,'[3]6월'!$F$6:$BJ$50,3,),)/1000 -> 0 | S38: =+P38-R38 -> 0 | T38: =SUM('[1]6월'!$AM$26:$AQ$26)/1000 -> -50.424538 | U38: =+'[2]6월'!$BF$26/1000 -> -56.104233 | V38: =+U38-T38 -> -5.6796946 | W38: =+'[3]6월'!$BF$26/1000 -> -9.456456 | X38: =+U38-W38 -> -46.647777
B39: 기타 계 | G39: =+I39 -> 기타 | I39: 기타 | L39: =+K39-J39 -> 0 | N39: =+K39-M39 -> 0 | O39: =IFERROR(HLOOKUP($B39,'[1]6월'!$D$6:$BN$259,3,),)/1000 -> 1.77 | P39: =+('[2]6월'!$F$8-SUM('[2]6월'!$Z$8,'[2]6월'!$AH$8,'[2]6월'!$AN$8,'[2]6월'!$AO$8,'[2]6월'!$BA$8,'[2]6월'!$BD$8,'[2]6월'!$BE$8,'[2]6월'!$BF$8))/1000 -> 1.704 | Q39: =+P39-O39 -> -0.066 | R39: =+('[3]6월'!$F$8-SUM('[3]6월'!$Z$8,'[3]6월'!$AH$8,'[3]6월'!$AN$8,'[3]6월'!$AO$8,'[3]6월'!$BA$8,'[3]6월'!$BD$8,'[3]6월'!$BE$8,'[3]6월'!$BF$8))/1000 -> 1.7621 | S39: =+P39-R39 -> -0.0581 | T39: =+('[1]6월'!$E$26-'[1]6월'!$Z$26-'[1]6월'!$AA$26-'[1]6월'!$AE$26-'[1]6월'!$AL$26-'[1]6월'!$AM$26-'[1]6월'!$AN$26-'[1]6월'!$AO$26-'[1]6월'!$AP$26-'[1]6월'!$AQ$26-'[1]6월'!$AS$26)/1000 -> -68.088929 | U39: =+('[2]6월'!$F$26-SUM('[2]6월'!$Z$26,'[2]6월'!$AH$26,'[2]6월'!$AN$26,'[2]6월'!$AO$26,'[2]6월'!$BA$26,'[2]6월'!$BD$26,'[2]6월'!$BE$26,'[2]6월'!$BF$26))/1000 -> -90.356696 | V39: =+U39-T39 -> -22.267767 | W39: =+('[3]6월'!$F$26-SUM('[3]6월'!$Z$26,'[3]6월'!$AH$26,'[3]6월'!$AN$26,'[3]6월'!$AO$26,'[3]6월'!$BA$26,'[3]6월'!$BD$26,'[3]6월'!$BE$26,'[3]6월'!$BF$26))/1000 -> -78.86109 | X39: =+U39-W39 -> -11.495606
N40: =+K40-M40 -> 0 | Q40: =+P40-O40 -> 0 | S40: =+P40-R40 -> 0 | V40: =+U40-T40 -> 0
H41: 기타 계 | J41: =SUM(J33:J40) -> 0 | K41: =SUM(K33:K40) -> 0 | L41: =+K41-J41 -> 0 | M41: =SUM(M33:M40) -> 0 | N41: =+K41-M41 -> 0 | O41: =SUM(O33:O40) -> 164.9075 | P41: =SUM(P33:P40) -> 166.17921 | Q41: =+P41-O41 -> 1.2717117 | R41: =SUM(R33:R40) -> 181.61219 | S41: =+P41-R41 -> -15.432979 | T41: =SUM(T33:T40) -> -1314.5549 | U41: =SUM(U33:U40) -> -1960.908 | V41: =+U41-T41 -> -646.35306 | W41: =SUM(W33:W40) -> -2576.3388 | X41: =+U41-W41 -> 615.43083
U42: 19 | V42: 12.4
...

Sheet 사업장별(누계)
H3: □ 사업장별 손익실적(2024-06누계)
AG4: [단위 : 천㎥, 톤, 백만원]
H5: 구분 | J5: 물량 | O5: 매출 | T5: 영업이익(공통비 배부전) | Y5: 판매단가 | AB5: 변동비 | AE5: 공헌이익
J6: 계획 | K6: 실적 | L6: 차이 | M6: 전년 | N6: 차이 | O6: 계획 | P6: 실적 | Q6: 차이 | R6: 전년 | S6: 차이 | T6: 계획 | U6: 실적 | V6: 차이 | W6: 전년 | X6: 차이 | Y6: 계획 | Z6: 실적 | AA6: 전년 | AB6: 계획 | AC6: 실적 | AD6: 전년 | AE6: 계획 | AF6: 실적 | AG6: 전년
B7: 안양 | F7: =+U7/T7 -> 0.81377098 | G7: =+K7/J7 -> 1.006849 | H7: 레미콘 | I7: 안양 | J7: =+'사업장별(당월)'!J7+'[4]사업장별(누계)'!J7 -> 245 | K7: =+'사업장별(당월)'!K7+'[4]사업장별(누계)'!K7 -> 246.678 | L7: =+K7-J7 -> 1.678 | M7: =+'사업장별(당월)'!M7+'[4]사업장별(누계)'!M7 -> 273.585 | N7: =+K7-M7 -> -26.907 | O7: =+'사업장별(당월)'!O7+'[4]사업장별(누계)'!O7 -> 24443.855 | P7: =+'사업장별(당월)'!P7+'[4]사업장별(누계)'!P7 -> 24515.111 | Q7: =+P7-O7 -> 71.255944 | R7: =+'사업장별(당월)'!R7+'[4]사업장별(누계)'!R7 -> 25195.484 | S7: =+P7-R7 -> -680.37259 | T7: =+'사업장별(당월)'!T7+'[4]사업장별(누계)'!T7 -> 3168.067 | U7: =+'사업장별(당월)'!U7+'[4]사업장별(누계)'!U7 -> 2578.081 | V7: =+U7-T7 -> -589.98602 | W7: =+'사업장별(당월)'!W7+'[4]사업장별(누계)'!W7 -> 3600.9309 | X7: =+U7-W7 -> -1022.8499 | Y7: =+[11]안양!$Q$85 -> 99770.838 | Z7: =+[11]안양!$R$85 -> 99374.66 | AA7: =+[12]안양!$Q$85 -> 92071.611 | AB7: =+[11]안양!$Q$89 -> 79220.915 | AC7: =+[11]안양!$R$89 -> 81333.041 | AD7: =+[12]안양!$Q$89 -> 72424.501 | AE7: =+Y7-AB7 -> 20549.923 | AF7: =+Z7-AC7 -> 18041.619 | AG7: =+AA7-AD7 -> 19647.11 | AI7: 22.510942
B8: 인천 | F8: =+U8/T8 -> 0.82483389 | G8: =+K8/J8 -> 0.96042222 | H8: 직영 | I8: 인천 | J8: =+'사업장별(당월)'!J8+'[4]사업장별(누계)'!J8 -> 180 | K8: =+'사업장별(당월)'!K8+'[4]사업장별(누계)'!K8 -> 172.876 | L8: =+K8-J8 -> -7.124 | M8: =+'사업장별(당월)'!M8+'[4]사업장별(누계)'!M8 -> 236.407 | N8: =+K8-M8 -> -63.531 | O8: =+'사업장별(당월)'!O8+'[4]사업장별(누계)'!O8 -> 18179.561 | P8: =+'사업장별(당월)'!P8+'[4]사업장별(누계)'!P8 -> 17322.638 | Q8: =+P8-O8 -> -856.9237 | R8: =+'사업장별(당월)'!R8+'[4]사업장별(누계)'!R8 -> 22303.782 | S8: =+P8-R8 -> -4981.1441 | T8: =+'사업장별(당월)'!T8+'[4]사업장별(누계)'!T8 -> 1691.7895 | U8: =+'사업장별(당월)'!U8+'[4]사업장별(누계)'!U8 -> 1395.4453 | V8: =+U8-T8 -> -296.34417 | W8: =+'사업장별(당월)'!W8+'[4]사업장별(누계)'!W8 -> 2722.0365 | X8: =+U8-W8 -> -1326.5912 | Y8: =+[11]인천!$Q$85 -> 100997.56 | Z8: =+[11]인천!$R$85 -> 100202.67 | AA8: =+[12]인천!$Q$85 -> 94336.148 | AB8: =+[11]인천!$Q$89 -> 81428.035 | AC8: =+[11]인천!$R$89 -> 82122.86 | AD8: =+[12]인천!$Q$89 -> 75238.594 | AE8: =+Y8-AB8 -> 19569.527 | AF8: =+Z8-AC8 -> 18079.815 | AG8: =+AA8-AD8 -> 19097.553 | AI8: 12.217192
B9: 파주 | F9: =+U9/T9 -> 0.6409997 | G9: =+K9/J9 -> 1.0232464 | I9: 파주 | J9: =+'사업장별(당월)'!J9+'[4]사업장별(누계)'!J9 -> 151 | K9: =+'사업장별(당월)'!K9+'[4]사업장별(누계)'!K9 -> 154.5102 | L9: =+K9-J9 -> 3.5102 | M9: =+'사업장별(당월)'!M9+'[4]사업장별(누계)'!M9 -> 153.66 | N9: =+K9-M9 -> 0.8502 | O9: =+'사업장별(당월)'!O9+'[4]사업장별(누계)'!O9 -> 14817.269 | P9: =+'사업장별(당월)'!P9+'[4]사업장별(누계)'!P9 -> 15237.953 | Q9: =+P9-O9 -> 420.68468 | R9: =+'사업장별(당월)'!R9+'[4]사업장별(누계)'!R9 -> 13915.302 | S9: =+P9-R9 -> 1322.6515 | T9: =+'사업장별(당월)'!T9+'[4]사업장별(누계)'!T9 -> 1920.4543 | U9: =+'사업장별(당월)'!U9+'[4]사업장별(누계)'!U9 -> 1231.0106 | V9: =+U9-T9 -> -689.44366 | W9: =+'사업장별(당월)'!W9+'[4]사업장별(누계)'!W9 -> 1418.7954 | X9: =+U9-W9 -> -187.78479 | Y9: =+[11]파주!$Q$85 -> 98127.608 | Z9: =+[11]파주!$R$85 -> 98647.485 | AA9: =+[12]파주!$Q$85 -> 90534.843 | AB9: =+[11]파주!$Q$89 -> 76485.866 | AC9: =+[11]파주!$R$89 -> 81669.229 | AD9: =+[12]파주!$Q$89 -> 72706.497 | AE9: =+Y9-AB9 -> 21641.742 | AF9: =+Z9-AC9 -> 16978.256 | AG9: =+AA9-AD9 -> 17828.346 | AI9: 9.7481997
B10: 김포 | F10: =+U10/T10 -> 0.76704272 | G10: =+K10/J10 -> 0.87760119 | I10: 김포 | J10: =+'사업장별(당월)'!J10+'[4]사업장별(누계)'!J10 -> 84 | K10: =+'사업장별(당월)'!K10+'[4]사업장별(누계)'!K10 -> 73.7185 | L10: =+K10-J10 -> -10.2815 | M10: =+'사업장별(당월)'!M10+'[4]사업장별(누계)'!M10 -> 105.3395 | N10: =+K10-M10 -> -31.621 | O10: =+'사업장별(당월)'!O10+'[4]사업장별(누계)'!O10 -> 7982.837 | P10: =+'사업장별(당월)'!P10+'[4]사업장별(누계)'!P10 -> 7287.6592 | Q10: =+P10-O10 -> -695.17778 | R10: =+'사업장별(당월)'!R10+'[4]사업장별(누계)'!R10 -> 9333.4066 | S10: =+P10-R10 -> -2045.7474 | T10: =+'사업장별(당월)'!T10+'[4]사업장별(누계)'!T10 -> 953.13158 | U10: =+'사업장별(당월)'!U10+'[4]사업장별(누계)'!U10 -> 731.09263 | V10: =+U10-T10 -> -222.03894 | W10: =+'사업장별(당월)'!W10+'[4]사업장별(누계)'!W10 -> 1255.6415 | X10: =+U10-W10 -> -524.54887 | Y10: =+[11]김포!$Q$85 -> 95033.774 | Z10: =+[11]김포!$R$85 -> 98880.551 | AA10: =+[12]김포!$Q$85 -> 88547.824 | AB10: =+[11]김포!$Q$89 -> 71591.504 | AC10: =+[11]김포!$R$89 -> 75884.503 | AD10: =+[12]김포!$Q$89 -> 67223.703 | AE10: =+Y10-AB10 -> 23442.27 | AF10: =+Z10-AC10 -> 22996.047 | AG10: =+AA10-AD10 -> 21324.122 | AI10: 6.215745
B11: 부산 | F11: =+U11/T11 -> 0.93559675 | G11: =+K11/J11 -> 1.1670929 | I11: 부산 | J11: =+'사업장별(당월)'!J11+'[4]사업장별(누계)'!J11 -> 113 | K11: =+'사업장별(당월)'!K11+'[4]사업장별(누계)'!K11 -> 131.8815 | L11: =+K11-J11 -> 18.8815 | M11: =+'사업장별(당월)'!M11+'[4]사업장별(누계)'!M11 -> 148.9595 | N11: =+K11-M11 -> -17.078 | O11: =+'사업장별(당월)'!O11+'[4]사업장별(누계)'!O11 -> 12158.809 | P11: =+'사업장별(당월)'!P11+'[4]사업장별(누계)'!P11 -> 14056.407 | Q11: =+P11-O11 -> 1897.5981 | R11: =+'사업장별(당월)'!R11+'[4]사업장별(누계)'!R11 -> 15134.806 | S11: =+P11-R11 -> -1078.3991 | T11: =+'사업장별(당월)'!T11+'[4]사업장별(누계)'!T11 -> 1625.1374 | U11: =+'사업장별(당월)'!U11+'[4]사업장별(누계)'!U11 -> 1520.4732 | V11: =+U11-T11 -> -104.66413 | W11: =+'사업장별(당월)'!W11+'[4]사업장별(누계)'!W11 -> 2856.3739 | X11: =+U11-W11 -> -1335.9006 | Y11: =+[11]부산!$Q$85 -> 107600.08 | Z11: =+[11]부산!$R$85 -> 106583.61 | AA11: =+[12]부산!$Q$85 -> 101603.5 | AB11: =+[11]부산!$Q$89 -> 78633.325 | AC11: =+[11]부산!$R$89 -> 83433.784 | AD11: =+[12]부산!$Q$89 -> 72669.387 | AE11: =+Y11-AB11 -> 28966.752 | AF11: =+Z11-AC11 -> 23149.829 | AG11: =+AA11-AD11 -> 28934.109 | AI11: 14.018406
