Workbook

Sheet 표지
A6: 2025년 2월 마감 손익
A24: 건재사업본부

Sheet 손익총괄
C3: □ 건재사업본부 손익실적(2025-02)
X4: [단위 : 천㎥, 톤, 원/㎥, 원/톤, 백만원]
C5: 구분 | E5: 2월 | J5: 2월 누계 | P5: 2월 주요지표
A6: 2024년 12월 마감 손익 | E6: 계획 | F6: 실적 | G6: 계획대비 | H6: 전년 | I6: 전년대비 | J6: 계획 | K6: 실적 | L6: 계획대비 | M6: 전년 | N6: 전년대비
A7: =+F7/E7 -> 0.92854185 | B7: =+K7/J7 -> 0.8955265 | C7: 물량 | D7: 레미콘 | E7: =+'[1]2월'!$Z$7/1000 -> 227 | F7: =+'[2]2월'!$Z$7/1000 -> 210.779 | G7: =+F7-E7 -> -16.221 | H7: =+'[3]2월'!$Z$7/1000 -> 217.5565 | I7: =+F7-H7 -> -6.7775 | J7: =+'[1]2월누계'!$Z$7/1000 -> 434 | K7: =+'[2]2월누계'!$Z$7/1000 -> 388.6585 | L7: =+K7-J7 -> -45.3415 | M7: =+'[3]2월누계'!$Z$7/1000 -> 496.442 | N7: =+K7-M7 -> -107.7835 | Q7: □ 레미콘
D8: 철강재 | E8: =+'[1]2월'!$AA$7 -> 10200 | F8: =+'[2]2월'!$AO$7 -> 9724.523 | G8: =+F8-E8 -> -475.477 | H8: =+'[3]2월'!$AO$7 -> 6645.402 | I8: =+F8-H8 -> 3079.121 | J8: =+'[1]2월누계'!$AA$7 -> 20000 | K8: =+'[2]2월누계'!$AO$7 -> 18460.025 | L8: =+K8-J8 -> -1539.975 | M8: =+'[3]2월누계'!$AO$7 -> 13070.495 | N8: =+K8-M8 -> 5389.53 | Q8: 구분 | S8: 계획 | T8: 실적 | U8: 계획대비 | V8: 전년 | W8: 전년대비
D9: 골재 | E9: =+'[1]2월'!$AE$7/1000 -> 74.372195 | F9: =+'[2]2월'!$AN$7/1000 -> 57.937 | G9: =+F9-E9 -> -16.435195 | H9: =+'[3]2월'!$AN$7/1000 -> 65.272 | I9: =+F9-H9 -> -7.335 | J9: =+'[1]2월누계'!$AE$7/1000 -> 165.19049 | K9: =+'[2]2월누계'!$AN$7/1000 -> 106.189 | L9: =+K9-J9 -> -59.001486 | M9: =+'[3]2월누계'!$AN$7/1000 -> 149.789 | N9: =+K9-M9 -> -43.6 | Q9: 물량 | R9: 수도권 | S9: =+[4]수도권!$T$5/1000 -> 83 | T9: =+[4]수도권!$U$5/1000 -> 74.2395 | U9: =+T9-S9 -> -8.7605 | V9: =+[5]수도권!$T$5/1000 -> 85.559 | W9: =+T9-V9 -> -11.3195
C10: 매출 | D10: 레미콘 | E10: =+'[1]2월'!$Z$8/1000 -> 22820.87 | F10: =+'[2]2월'!$Z$8/1000 -> 21022.768 | G10: =+F10-E10 -> -1798.1018 | H10: =+'[3]2월'!$Z$8/1000 -> 22221.543 | I10: =+F10-H10 -> -1198.7749 | J10: =+'[1]2월누계'!$Z$8/1000 -> 43636.763 | K10: =+'[2]2월누계'!$Z$8/1000 -> 38997.16 | L10: =+K10-J10 -> -4639.6028 | M10: =+'[3]2월누계'!$Z$8/1000 -> 50097.188 | N10: =+K10-M10 -> -11100.029 | R10: 영남권 | S10: =+[4]영남권!$T$5/1000 -> 105 | T10: =+[4]영남권!$U$5/1000 -> 95.894 | U10: =+T10-S10 -> -9.106 | V10: =+[5]영남권!$T$5/1000 -> 100.9045 | W10: =+T10-V10 -> -5.0105
D11: 건자재 | E11: =+'[1]2월'!$AA$8/1000 -> 11165.946 | F11: =+'[2]2월'!$AO$8/1000 -> 8276.9951 | G11: =+F11-E11 -> -2888.9504 | H11: =+'[3]2월'!$AO$8/1000 -> 6765.658 | I11: =+F11-H11 -> 1511.3371 | J11: =+'[1]2월누계'!$AA$8/1000 -> 21897.268 | K11: =+'[2]2월누계'!$AO$8/1000 -> 15757.115 | L11: =+K11-J11 -> -6140.1536 | M11: =+'[3]2월누계'!$AO$8/1000 -> 14173.615 | N11: =+K11-M11 -> 1583.4997 | R11: 중부권 | S11: =+[4]중부권!$T$5/1000 -> 39 | T11: =+[4]중부권!$U$5/1000 -> 40.6455 | U11: =+T11-S11 -> 1.6455 | V11: =+[5]중부권!$T$5/1000 -> 31.093 | W11: =+T11-V11 -> 9.5525
D12: 골재 | E12: =+'[1]2월'!$AE$8/1000 -> 1594.8893 | F12: =+'[2]2월'!$AN$8/1000 -> 1242.5835 | G12: =+F12-E12 -> -352.30582 | H12: =+'[3]2월'!$AN$8/1000 -> 1297.0865 | I12: =+F12-H12 -> -54.503 | J12: =+'[1]2월누계'!$AE$8/1000 -> 3235.0838 | K12: =+'[2]2월누계'!$AN$8/1000 -> 2294.3315 | L12: =+K12-J12 -> -940.75227 | M12: =+'[3]2월누계'!$AN$8/1000 -> 3016.6065 | N12: =+K12-M12 -> -722.275 | Q12: 계 | S12: =SUM(S9:S11) -> 227 | T12: =SUM(T9:T11) -> 210.779 | U12: =+T12-S12 -> -16.221 | V12: =SUM(V9:V11) -> 217.5565 | W12: =+T12-V12 -> -6.7775
D13: 기타 | E13: =+'[1]2월'!$E$8/1000-E10-E11-E12 -> 166.7015 | F13: =+'[2]2월'!$F$8/1000-F10-F11-F12 -> 164.51937 | G13: =+F13-E13 -> -2.182132 | H13: =+'[3]2월'!$F$8/1000-H10-H11-H12 -> 164.52516 | I13: =+F13-H13 -> -0.005791 | J13: =+'[1]2월누계'!$E$8/1000-J10-J11-J12 -> 333.403 | K13: =+'[2]2월누계'!$F$8/1000-K10-K11-K12 -> 331.77197 | L13: =+K13-J13 -> -1.631033 | M13: =+'[3]2월누계'!$F$8/1000-M10-M11-M12 -> 329.00067 | N13: =+K13-M13 -> 2.771297 | Q13: 판매단가 | R13: 수도권 | S13: =+[4]수도권!$T$61 -> 97568.732 | T13: =+[4]수도권!$U$61 -> 96965.552 | U13: =+T13-S13 -> -603.17989 | V13: =+[5]수도권!$Q$85 -> 100756.04 | W13: =+T13-V13 -> -3790.4835
A14: =+F14/E14 -> 0.85897161 | B14: =+K14/J14 -> 0.83036595 | C14: 계 | E14: =SUM(E10:E13) -> 35748.406 | F14: =SUM(F10:F13) -> 30706.866 | G14: =+F14-E14 -> -5041.5402 | H14: =SUM(H10:H13) -> 30448.812 | I14: =+F14-H14 -> 258.0535 | J14: =SUM(J10:J13) -> 69102.518 | K14: =SUM(K10:K13) -> 57380.378 | L14: =+K14-J14 -> -11722.14 | M14: =SUM(M10:M13) -> 67616.411 | N14: =+K14-M14 -> -10236.033 | R14: 영남권 | S14: =+[4]영남권!$T$61 -> 100469.22 | T14: =+[4]영남권!$U$61 -> 100787.78 | U14: =+T14-S14 -> 318.56845 | V14: =+[5]영남권!$Q$85 -> 102784.62 | W14: =+T14-V14 -> -1996.8362
C15: 매출원가 | D15: 레미콘 | E15: =+('[1]2월'!$Z$10+'[1]2월'!$Z$19)/1000 -> 20757.627 | F15: =+('[2]2월'!$Z$10+'[2]2월'!$Z$19)/1000 -> 19459.467 | G15: =+F15-E15 -> -1298.1596 | H15: =+('[3]2월'!$Z$10+'[3]2월'!$Z$19)/1000 -> 19862.664 | I15: =+F15-H15 -> -403.1972 | J15: =+('[1]2월누계'!$Z$10+'[1]2월누계'!$Z$19)/1000 -> 40158.316 | K15: =+('[2]2월누계'!$Z$10+'[2]2월누계'!$Z$19)/1000 -> 36700.193 | L15: =+K15-J15 -> -3458.1237 | M15: =+('[3]2월누계'!$Z$10+'[3]2월누계'!$Z$19)/1000 -> 44742.197 | N15: =+K15-M15 -> -8042.004 | R15: 중부권 | S15: =+[4]중부권!$T$61 -> 107010.18 | T15: =+[4]중부권!$U$61 -> 102295.48 | U15: =+T15-S15 -> -4714.7018 | V15: =+[5]중부권!$Q$85 -> 103875.43 | W15: =+T15-V15 -> -1579.9476
D16: 건자재 | E16: =+('[1]2월'!$AA$10+'[1]2월'!$AA$19)/1000 -> 10864.469 | F16: =+('[2]2월'!$AO$10+'[2]2월'!$AO$19)/1000 -> 8127.3341 | G16: =+F16-E16 -> -2737.1347 | H16: =+('[3]2월'!$AO$10+'[3]2월'!$AO$19)/1000 -> 6592.5773 | I16: =+F16-H16 -> 1534.7568 | J16: =+('[1]2월누계'!$AA$10+'[1]2월누계'!$AA$19)/1000 -> 21305.651 | K16: =+('[2]2월누계'!$AO$10+'[2]2월누계'!$AO$19)/1000 -> 15461.543 | L16: =+K16-J16 -> -5844.1079 | M16: =+('[3]2월누계'!$AO$10+'[3]2월누계'!$AO$19)/1000 -> 13803.102 | N16: =+K16-M16 -> 1658.441 | Q16: 계 | S16: =+[4]합계!$T$61 -> 100532.46 | T16: =+[4]합계!$U$61 -> 99735.994 | U16: =+T16-S16 -> -796.47067 | V16: =+[5]합계!$Q$85 -> 102142.73 | W16: =+T16-V16 -> -2406.7354
D17: 골재 | E17: =+('[1]2월'!$AE$10+'[1]2월'!$AE$19)/1000 -> 1271.5348 | F17: =+('[2]2월'!$AN$10+'[2]2월'!$AN$19)/1000 -> 1294.0505 | G17: =+F17-E17 -> 22.51566 | H17: =+('[3]2월'!$AN$10+'[3]2월'!$AN$19)/1000 -> 1171.576 | I17: =+F17-H17 -> 122.47454 | J17: =+('[1]2월누계'!$AE$10+'[1]2월누계'!$AE$19)/1000 -> 2787.1378 | K17: =+('[2]2월누계'!$AN$10+'[2]2월누계'!$AN$19)/1000 -> 2576.316 | L17: =+K17-J17 -> -210.82179 | M17: =+('[3]2월누계'!$AN$10+'[3]2월누계'!$AN$19)/1000 -> 2664.8507 | N17: =+K17-M17 -> -88.534611 | Q17: 공헌이익 | R17: 수도권 | S17: =+[4]수도권!$Q$90 -> 15726.819 | T17: =+[4]수도권!$R$90 -> 14691.292 | U17: =+T17-S17 -> -1035.5275 | V17: =+[5]수도권!$Q$90 -> 19293.33 | W17: =+T17-V17 -> -4602.0378
D18: 기타 | E18: =+('[1]2월'!$E$10+'[1]2월'!$E$19)/1000-E15-E16-E17 -> 28.444279 | F18: =+('[2]2월'!$F$10+'[2]2월'!$F$19)/1000-F15-F16-F17 -> 28.233255 | G18: =+F18-E18 -> -0.211024 | H18: =+('[3]2월'!$F$10+'[3]2월'!$F$19)/1000-H15-H16-H17 -> 28.428296 | I18: =+F18-H18 -> -0.195041 | J18: =+('[1]2월누계'!$E$10+'[1]2월누계'!$E$19)/1000-J15-J16-J17 -> 56.888558 | K18: =+('[2]2월누계'!$F$10+'[2]2월누계'!$F$19)/1000-K15-K16-K17 -> 359.42361 | L18: =+K18-J18 -> 302.53505 | M18: =+('[3]2월누계'!$F$10+'[3]2월누계'!$F$19)/1000-M15-M16-M17 -> 56.940114 | N18: =+K18-M18 -> 302.4835 | R18: 영남권 | S18: =+[4]영남권!$Q$90 -> 20935.914 | T18: =+[4]영남권!$R$90 -> 20101.873 | U18: =+T18-S18 -> -834.04118 | V18: =+[5]영남권!$Q$90 -> 22654.141 | W18: =+T18-V18 -> -2552.2684
C19: 계 | E19: =SUM(E15:E18) -> 32922.075 | F19: =SUM(F15:F18) -> 28909.085 | G19: =+F19-E19 -> -4012.9897 | H19: =SUM(H15:H18) -> 27655.246 | I19: =+F19-H19 -> 1253.8391 | J19: =SUM(J15:J18) -> 64307.994 | K19: =SUM(K15:K18) -> 55097.476 | L19: =+K19-J19 -> -9210.5183 | M19: =SUM(M15:M18) -> 61267.09 | N19: =+K19-M19 -> -6169.6141 | R19: 중부권 | S19: =+[4]중부권!$Q$90 -> 27516.457 | T19: =+[4]중부권!$R$90 -> 22532.494 | U19: =+T19-S19 -> -4983.9635 | V19: =+[5]중부권!$Q$90 -> 26459.748 | W19: =+T19-V19 -> -3927.2545
C20: 매출이익 | D20: 레미콘 | E20: =+E10-E15 -> 2063.2427 | F20: =+F10-F15 -> 1563.3005 | G20: =+F20-E20 -> -499.94218 | H20: =+H10-H15 -> 2358.8782 | I20: =+F20-H20 -> -795.57766 | J20: =+J10-J15 -> 3478.4464 | K20: =+K10-K15 -> 2296.9672 | L20: =+K20-J20 -> -1181.4792 | M20: =+M10-M15 -> 5354.9919 | N20: =+K20-M20 -> -3058.0247 | Q20: 계 | S20: =+[4]합계!$Q$90 -> 20161.845 | T20: =+[4]합계!$R$90 -> 18672.912 | U20: =+T20-S20 -> -1488.933 | V20: =+[5]합계!$Q$90 -> 21876.256 | W20: =+T20-V20 -> -3203.344
D21: 건자재 | E21: =+E11-E16 -> 301.47673 | F21: =+F11-F16 -> 149.66104 | G21: =+F21-E21 -> -151.81568 | H21: =+H11-H16 -> 173.08068 | I21: =+F21-H21 -> -23.419635 | J21: =+J11-J16 -> 591.61723 | K21: =+K11-K16 -> 295.57153 | L21: =+K21-J21 -> -296.0457 | M21: =+M11-M16 -> 370.51289 | N21: =+K21-M21 -> -74.94135 | Q21: □ 건자재
D22: 골재 | E22: =+E12-E17 -> 323.35448 | F22: =+F12-F17 -> -51.467005 | G22: =+F22-E22 -> -374.82149 | H22: =+H12-H17 -> 125.51054 | I22: =+F22-H22 -> -176.97754 | J22: =+J12-J17 -> 447.94593 | K22: =+K12-K17 -> -281.98455 | L22: =+K22-J22 -> -729.93047 | M22: =+M12-M17 -> 351.75584 | N22: =+K22-M22 -> -633.74039 | Q22: 구분 | S22: 계획 | T22: 실적 | U22: 계획대비 | V22: 전년 | W22: 전년대비
D23: 기타 | E23: =+E13-E18 -> 138.25722 | F23: =+F13-F18 -> 136.28611 | G23: =+F23-E23 -> -1.971108 | H23: =+H13-H18 -> 136.09686 | I23: =+F23-H23 -> 0.18925 | J23: =+J13-J18 -> 276.51444 | K23: =+K13-K18 -> -27.651645 | L23: =+K23-J23 -> -304.16609 | M23: =+M13-M18 -> 272.06056 | N23: =+K23-M23 -> -299.7122 | Q23: 철강재 판매단가 | S23: =+'[6]2월'!$F$10 -> 872058.82 | T23: =+'[6]2월'!$G$10 -> 744684.73 | U23: =+T23-S23 -> -127374.09 | V23: =+'[6]2월'!$G$10 -> 744684.73 | W23: =+T23-V23 -> 0
C24: 계 | E24: =SUM(E20:E23) -> 2826.3311 | F24: =SUM(F20:F23) -> 1797.7807 | G24: =+F24-E24 -> -1028.5505 | H24: =SUM(H20:H23) -> 2793.5663 | I24: =+F24-H24 -> -995.78559 | J24: =SUM(J20:J23) -> 4794.524 | K24: =SUM(K20:K23) -> 2282.9025 | L24: =+K24-J24 -> -2511.6214 | M24: =SUM(M20:M23) -> 6349.3212 | N24: =+K24-M24 -> -4066.4186 | Q24: 철강재 마진률 | S24: =+'[6]2월'!$F$15 -> 0.02394688 | T24: =+'[6]2월'!$G$15 -> 0.015585145 | U24: =+T24-S24 -> -0.0083617349 | V24: =+'[6]2월'!$G$15 -> 0.015585145 | W24: =+T24-V24 -> 0
C25: 판관비 | D25: 레미콘 | E25: =+('[1]2월'!$Z$13+'[1]2월'!$Z$20)/1000 -> 688.11536 | F25: =+('[2]2월'!$Z$13+'[2]2월'!$Z$20)/1000 -> 621.32787 | G25: =+F25-E25 -> -66.787489 | H25: =+('[3]2월'!$Z$13+'[3]2월'!$Z$20)/1000 -> 661.97847 | I25: =+F25-H25 -> -40.6506 | J25: =+('[1]2월누계'!$Z$13+'[1]2월누계'!$Z$20)/1000 -> 1360.5939 | K25: =+('[2]2월누계'!$Z$13+'[2]2월누계'!$Z$20)/1000 -> 1331.8563 | L25: =+K25-J25 -> -28.737618 | M25: =+('[3]2월누계'!$Z$13+'[3]2월누계'!$Z$20)/1000 -> 1333.5029 | N25: =+K25-M25 -> -1.646581 | Q25: □ 골재
D26: 건자재 | E26: =+('[1]2월'!$AA$13+'[1]2월'!$AA$20)/1000 -> 129.85597 | F26: =+('[2]2월'!$AO$13+'[2]2월'!$AO$20)/1000 -> 138.79933 | G26: =+F26-E26 -> 8.943362 | H26: =+('[3]2월'!$AO$13+'[3]2월'!$AO$20)/1000 -> 131.236 | I26: =+F26-H26 -> 7.563331 | J26: =+('[1]2월누계'!$AA$13+'[1]2월누계'!$AA$20)/1000 -> 252.63516 | K26: =+('[2]2월누계'!$AO$13+'[2]2월누계'!$AO$20)/1000 -> 283.01257 | L26: =+K26-J26 -> 30.377417 | M26: =+('[3]2월누계'!$AO$13+'[3]2월누계'!$AO$20)/1000 -> 253.40099 | N26: =+K26-M26 -> 29.611578 | Q26: 구분 | S26: 계획 | T26: 실적 | U26: 계획대비 | V26: 전년 | W26: 전년대비
D27: 골재 | E27: =+('[1]2월'!$AE$13+'[1]2월'!$AE$20+'[1]2월'!$AE$22)/1000 -> 49.259851 | F27: =+('[2]2월'!$AN$13+'[2]2월'!$AN$20+'[2]2월'!$AN$22)/1000 -> 46.67513 | G27: =+F27-E27 -> -2.5847208 | H27: =+('[3]2월'!$AN$13+'[3]2월'!$AN$20+'[3]2월'!$AN$22)/1000 -> 46.331173 | I27: =+F27-H27 -> 0.3439575 | J27: =+('[1]2월누계'!$AE$13+'[1]2월누계'!$AE$20+'[1]2월누계'!$AE$22)/1000 -> 96.873784 | K27: =+('[2]2월누계'!$AN$13+'[2]2월누계'!$AN$20+'[2]2월누계'!$AN$22)/1000 -> 96.245044 | L27: =+K27-J27 -> -0.62873962 | M27: =+('[3]2월누계'!$AN$13+'[3]2월누계'!$AN$20+'[3]2월누계'!$AN$22)/1000 -> 88.502744 | N27: =+K27-M27 -> 7.7422997 | Q27: 판매량 | R27: 자가 | S27: =(+'[7]서부산크라샤(당월)'!$N$66+'[7]부산모래장(당월)'!$Q$48+'[7]부산크라샤(당월)'!$N$66)/1000 -> 21.674535 | T27: =(+'[7]서부산크라샤(당월)'!$O$66+'[7]부산모래장(당월)'!$R$48+'[7]부산크라샤(당월)'!$O$66)/1000 -> 24.268 | U27: =+T27-S27 -> 2.593465 | V27: =+'[7]부산모래장(당월)'!$S$85/1000 -> 31.41 | W27: =+T27-V27 -> -7.142
D28: 기타 | E28: =+('[1]2월'!$E$13+'[1]2월'!$E$20)/1000-E25-E26-E27+('[1]2월'!$E$22/1000) -> 1253.8521 | F28: =+('[2]2월'!$F$13+'[2]2월'!$F$20)/1000-F25-F26-F27+'[2]2월'!$F$22/1000 -> 1326.3483 | G28: =+F28-E28 -> 72.496271 | H28: =+('[3]2월'!$F$13+'[3]2월'!$F$20)/1000-H25-H26-H27+'[3]2월'!$F$22/1000 -> 794.7642 | I28: =+F28-H28 -> 531.58414 | J28: =+('[1]2월누계'!$E$13+'[1]2월누계'!$E$20)/1000-J25-J26-J27+('[1]2월누계'!$E$22/1000) -> 3099.6461 | K28: =+('[2]2월누계'!$F$13+'[2]2월누계'!$F$20)/1000-K25-K26-K27+'[2]2월누계'!$F$22/1000 -> 3471.1203 | L28: =+K28-J28 -> 371.47419 | M28: =+('[3]2월누계'!$F$13+'[3]2월누계'!$F$20)/1000-M25-M26-M27+'[3]2월누계'!$F$22/1000 -> 2399.5896 | N28: =+K28-M28 -> 1071.5307 | R28: 외판 | S28: =(+'[7]서부산크라샤(당월)'!$N$59+'[7]부산모래장(당월)'!$Q$47+'[7]부산크라샤(당월)'!$N$59)/1000 -> 7 | T28: =(+'[7]서부산크라샤(당월)'!$O$59+'[7]부산모래장(당월)'!$R$47+'[7]부산크라샤(당월)'!$O$59)/1000 -> 20.719 | U28: =+T28-S28 -> 13.719 | V28: =+'[7]부산모래장(당월)'!$S$86/1000 -> 26.527 | W28: =+T28-V28 -> -5.808
C29: 계 | E29: =SUM(E25:E28) -> 2121.0832 | F29: =SUM(F25:F28) -> 2133.1507 | G29: =+F29-E29 -> 12.067423 | H29: =SUM(H25:H28) -> 1634.3098 | I29: =+F29-H29 -> 498.84083 | J29: =SUM(J25:J28) -> 4809.749 | K29: =SUM(K25:K28) -> 5182.2342 | L29: =+K29-J29 -> 372.48525 | M29: =SUM(M25:M28) -> 4074.9962 | N29: =+K29-M29 -> 1107.238 | Q29: 합 계 | S29: =SUM(S27:S28) -> 28.674535 | T29: =SUM(T27:T28) -> 44.987 | U29: =+T29-S29 -> 16.312465 | V29: =SUM(V27:V28) -> 57.937 | W29: =+T29-V29 -> -12.95
C30: 영업이익 | D30: 레미콘 | E30: =+E20-E25 -> 1375.1273 | F30: =+F20-F25 -> 941.97265 | G30: =+F30-E30 -> -433.15469 | H30: =+H20-H25 -> 1696.8997 | I30: =+F30-H30 -> -754.92706 | J30: =+J20-J25 -> 2117.8524 | K30: =+K20-K25 -> 965.11089 | L30: =+K30-J30 -> -1152.7415 | M30: =+M20-M25 -> 4021.489 | N30: =+K30-M30 -> -3056.3781 | Q30: □ 기타내역(영업이익)
D31: % | E31: =+E30/E10 -> 0.060257447 | F31: =+F30/F10 -> 0.044807261 | G31: =+F31-E31 -> -0.015450186 | H31: =+H30/H10 -> 0.076362822 | I31: =+F31-H31 -> -0.031555561 | J31: =+J30/J10 -> 0.048533674 | K31: =+K30/K10 -> 0.024748235 | L31: =+K31-J31 -> -0.023785439 | M31: =+M30/M10 -> 0.080273746 | N31: =+K31-M31 -> -0.055525511 | Q31: 구분 | S31: 계획 | T31: 실적 | U31: 계획대비 | V31: 전년 | W31: 전년대비
D32: 건자재 | E32: =+E21-E26 -> 171.62076 | F32: =+F21-F26 -> 10.861713 | G32: =+F32-E32 -> -160.75904 | H32: =+H21-H26 -> 41.844679 | I32: =+F32-H32 -> -30.982966 | J32: =+J21-J26 -> 338.98208 | K32: =+K21-K26 -> 12.558962 | L32: =+K32-J32 -> -326.42312 | M32: =+M21-M26 -> 117.11189 | N32: =+K32-M32 -> -104.55293 | Q32: 레미콘임대 | S32: =+'사업장별(당월)'!T33 -> 72.523221 | T32: =+'사업장별(당월)'!U33 -> 72.530954 | U32: =+T32-S32 -> 0.007733 | V32: =+'사업장별(당월)'!W33 -> 71.965353 | W32: =+T32-V32 -> 0.565601
D33: 골재 | E33: =+E22-E27 -> 274.09463 | F33: =+F22-F27 -> -98.142135 | G33: =+F33-E33 -> -372.23676 | H33: =+H22-H27 -> 79.179365 | I33: =+F33-H33 -> -177.3215 | J33: =+J22-J27 -> 351.07214 | K33: =+K22-K27 -> -378.22959 | L33: =+K33-J33 -> -729.30173 | M33: =+M22-M27 -> 263.2531 | N33: =+K33-M33 -> -641.48269 | Q33: 임대 | S33: =+'사업장별(당월)'!T34 -> 63.964 | T33: =+'사업장별(당월)'!U34 -> 61.899625 | U33: =+T33-S33 -> -2.064375 | V33: =+'사업장별(당월)'!W34 -> 61.893705 | W33: =+T33-V33 -> 0.00592
D34: 기타 | E34: =+E23-E28 -> -1115.5948 | F34: =+F23-F28 -> -1190.0622 | G34: =+F34-E34 -> -74.467379 | H34: =+H23-H28 -> -658.66734 | I34: =+F34-H34 -> -531.39489 | J34: =+J23-J28 -> -2823.1317 | K34: =+K23-K28 -> -3498.7719 | L34: =+K34-J34 -> -675.64028 | M34: =+M23-M28 -> -2127.529 | N34: =+K34-M34 -> -1371.2429 | Q34: 공통비 | S34: =+'사업장별(당월)'!T35 -> -1202.7748 | T34: =+'사업장별(당월)'!U35 -> -1276.8971 | U34: =+T34-S34 -> -74.122279 | V34: =+'사업장별(당월)'!W35 -> -1053.317 | W34: =+T34-V34 -> -223.58013
C35: 계 | E35: =SUM(E30,E32:E34) -> 705.24788 | F35: =SUM(F30,F32:F34) -> -335.37 | G35: =+F35-E35 -> -1040.6179 | H35: =SUM(H30,H32:H34) -> 1159.2564 | I35: =+F35-H35 -> -1494.6264 | J35: =SUM(J30,J32:J34) -> -15.225002 | K35: =SUM(K30,K32:K34) -> -2899.3317 | L35: =+K35-J35 -> -2884.1067 | M35: =SUM(M30,M32:M34) -> 2274.325 | N35: =+K35-M35 -> -5173.6566 | Q35: 기타 | S35: =+S36-S32-S33-S34 -> -49.307241 | T35: =+T36-T32-T33-T34 -> -47.595699 | U35: =+T35-S35 -> 1.711542 | V35: =+V36-V32-V33-V34 -> 260.79058 | W35: =+T35-V35 -> -308.38628
D36: % | E36: =+E35/E14 -> 0.019728093 | F36: =+F35/F14 -> -0.010921662 | G36: =+F36-E36 -> -0.030649755 | H36: =+H35/H14 -> 0.038072303 | I36: =+F36-H36 -> -0.048993965 | J36: =+J35/J14 -> -0.00022032486 | K36: =+K35/K14 -> -0.050528278 | L36: =+K36-J36 -> -0.050307953 | M36: =+M35/M14 -> 0.033635695 | N36: =+K36-M36 -> -0.084163972 | Q36: 합계 | S36: =+'사업장별(당월)'!T41 -> -1115.5948 | T36: =+'사업장별(당월)'!U41 -> -1190.0622 | U36: =+T36-S36 -> -74.467379 | V36: =+'사업장별(당월)'!W41 -> -658.66734 | W36: =+T36-V36 -> -531.39489
E38: =+'[1]2월'!$E$26/1000 -> 705.24788 | F38: =+'[2]2월'!$F$26/1000 -> -335.37 | H38: =+'[3]2월'!$F$26/1000 -> 1159.2564 | J38: =+'[1]2월누계'!$E$26/1000 -> -15.225002 | K38: =+'[2]2월누계'!$F$26/1000 -> -2899.3317 | M38: =+'[3]2월누계'!$F$26/1000 -> 2274.325
E39: =+E35=E38 -> FALSE | F39: =+F35=F38 -> FALSE | H39: =+H35=H38 -> TRUE | J39: =+J35=J38 -> FALSE | K39: =+K35=K38 -> TRUE | M39: =+M35=M38 -> TRUE
E40: =+E35-E38 -> -3.524292e-12 | F40: =+F35-F38 -> -2.2737368e-12 | H40: =+H35-H38 -> 0 | J40: =+J35-J38 -> 5.5226934e-12 | K40: =+K35-K38 -> 0 | M40: =+M35-M38 -> 0

Sheet 사업장별(당월)
H3: □ 사업장별 손익실적(2025-02)
AG4: [단위 : 천㎥, 톤, 백만원]
H5: 구분 | J5: 물량 | O5: 매출 | T5: 영업이익(공통비 배부전) | Y5: 판매단가 | AB5: 변동비 | AE5: 공헌이익
A6: 2024년 2월 마감 손익 | J6: 계획 | K6: 실적 | L6: 차이 | M6: 전년 | N6: 차이 | O6: 계획 | P6: 실적 | Q6: 차이 | R6: 전년 | S6: 차이 | T6: 계획 | U6: 실적 | V6: 차이 | W6: 전년 | X6: 차이 | Y6: 계획 | Z6: 실적 | AA6: 전년 | AB6: 계획 | AC6: 실적 | AD6: 전년 | AE6: 계획 | AF6: 실적 | AG6: 전년
B7: 안양 | G7: =+I7 -> 안양 | H7: 레미콘 | I7: 안양 | J7: =+IFERROR(HLOOKUP($B7,'[1]2월'!$D$6:$BN$259,2,),)/1000 -> 32 | K7: =+IFERROR(HLOOKUP($B7,'[2]2월'!$F$6:$CP$99,2,),)/1000 -> 34.905 | L7: =+K7-J7 -> 2.905 | M7: =+IFERROR(HLOOKUP($B7,'[3]2월'!$F$6:$CC$57,2,),)/1000 -> 37.712 | N7: =+K7-M7 -> -2.807 | O7: =+IFERROR(HLOOKUP($B7,'[1]2월'!$D$6:$BN$259,3,),)/1000 -> 3151.7741 | P7: =+IFERROR(HLOOKUP($B7,'[2]2월'!$F$6:$CP$99,3,),)/1000 -> 3382.0325 | Q7: =+P7-O7 -> 230.25843 | R7: =+IFERROR(HLOOKUP($B7,'[3]2월'!$F$6:$CC$57,3,),)/1000 -> 3774.208 | S7: =+P7-R7 -> -392.17547 | T7: =+IFERROR(HLOOKUP($B7,'[1]2월'!$D$6:$BN$259,16,),)/1000 -> 171.79786 | U7: =+IFERROR(HLOOKUP($B7,'[2]2월'!$F$6:$CP$99,16,),)/1000 -> 265.58446 | V7: =+U7-T7 -> 93.786603 | W7: =+IFERROR(HLOOKUP($B7,'[3]2월'!$F$6:$CC$57,16,),)/1000 -> 451.30565 | X7: =+U7-W7 -> -185.72119 | Y7: =+[4]안양!$Q$85 -> 98492.941 | Z7: =+[4]안양!$R$85 -> 96859.207 | AA7: =+[5]안양!$Q$85 -> 100079.76 | AB7: =+[4]안양!$Q$89 -> 83104.865 | AC7: =+[4]안양!$R$89 -> 80767.793 | AD7: =+[5]안양!$Q$89 -> 79851.287 | AE7: =+Y7-AB7 -> 15388.075 | AF7: =+Z7-AC7 -> 16091.414 | AG7: =+AA7-AD7 -> 20228.476
B8: 인천 | G8: =+I8 -> 인천 | H8: 직영 | I8: 인천 | J8: =+IFERROR(HLOOKUP($B8,'[1]2월'!$D$6:$BN$259,2,),)/1000 -> 25 | K8: =+IFERROR(HLOOKUP($B8,'[2]2월'!$F$6:$CP$99,2,),)/1000 -> 21.485 | L8: =+K8-J8 -> -3.515 | M8: =+IFERROR(HLOOKUP($B8,'[3]2월'!$F$6:$CC$57,2,),)/1000 -> 23.5 | N8: =+K8-M8 -> -2.015 | O8: =+IFERROR(HLOOKUP($B8,'[1]2월'!$D$6:$BN$259,3,),)/1000 -> 2443.1979 | P8: =+IFERROR(HLOOKUP($B8,'[2]2월'!$F$6:$CP$99,3,),)/1000 -> 2095.0919 | Q8: =+P8-O8 -> -348.10596 | R8: =+IFERROR(HLOOKUP($B8,'[3]2월'!$F$6:$CC$57,3,),)/1000 -> 2356.7585 | S8: =+P8-R8 -> -261.66661 | T8: =+IFERROR(HLOOKUP($B8,'[1]2월'!$D$6:$BN$259,16,),)/1000 -> 70.245864 | U8: =+IFERROR(HLOOKUP($B8,'[2]2월'!$F$6:$CP$99,16,),)/1000 -> -49.38036 | V8: =+U8-T8 -> -119.62622 | W8: =+IFERROR(HLOOKUP($B8,'[3]2월'!$F$6:$CC$57,16,),)/1000 -> 137.95808 | X8: =+U8-W8 -> -187.33844 | Y8: =+[4]인천!$Q$85 -> 97727.915 | Z8: =+[4]인천!$R$85 -> 97514.168 | AA8: =+[5]인천!$Q$85 -> 100287.6 | AB8: =+[4]인천!$Q$89 -> 83665.025 | AC8: =+[4]인천!$R$89 -> 86203.914 | AD8: =+[5]인천!$Q$89 -> 82090.723 | AE8: =+Y8-AB8 -> 14062.89 | AF8: =+Z8-AC8 -> 11310.254 | AG8: =+AA8-AD8 -> 18196.874
B9: 파주 | G9: =+I9 -> 파주 | I9: 파주 | J9: =+IFERROR(HLOOKUP($B9,'[1]2월'!$D$6:$BN$259,2,),)/1000 -> 16 | K9: =+IFERROR(HLOOKUP($B9,'[2]2월'!$F$6:$CP$99,2,),)/1000 -> 10.445 | L9: =+K9-J9 -> -5.555 | M9: =+IFERROR(HLOOKUP($B9,'[3]2월'!$F$6:$CC$57,2,),)/1000 -> 18.47 | N9: =+K9-M9 -> -8.025 | O9: =+IFERROR(HLOOKUP($B9,'[1]2월'!$D$6:$BN$259,3,),)/1000 -> 1545.8977 | P9: =+IFERROR(HLOOKUP($B9,'[2]2월'!$F$6:$CP$99,3,),)/1000 -> 1017.4518 | Q9: =+P9-O9 -> -528.44585 | R9: =+IFERROR(HLOOKUP($B9,'[3]2월'!$F$6:$CC$57,3,),)/1000 -> 1919.2949 | S9: =+P9-R9 -> -901.84312 | T9: =+IFERROR(HLOOKUP($B9,'[1]2월'!$D$6:$BN$259,16,),)/1000 -> 22.670792 | U9: =+IFERROR(HLOOKUP($B9,'[2]2월'!$F$6:$CP$99,16,),)/1000 -> -42.738868 | V9: =+U9-T9 -> -65.40966 | W9: =+IFERROR(HLOOKUP($B9,'[3]2월'!$F$6:$CC$57,16,),)/1000 -> 125.58788 | X9: =+U9-W9 -> -168.32675 | Y9: =+[4]파주!$Q$85 -> 96618.603 | Z9: =+[4]파주!$R$85 -> 97410.416 | AA9: =+[5]파주!$Q$85 -> 103935.69 | AB9: =+[4]파주!$Q$89 -> 79434.415 | AC9: =+[4]파주!$R$89 -> 80870.416 | AD9: =+[5]파주!$Q$89 -> 84337.303 | AE9: =+Y9-AB9 -> 17184.188 | AF9: =+Z9-AC9 -> 16540.001 | AG9: =+AA9-AD9 -> 19598.387
B10: 김포 | G10: =+I10 -> 김포 | I10: 김포 | J10: =+IFERROR(HLOOKUP($B10,'[1]2월'!$D$6:$BN$259,2,),)/1000 -> 10 | K10: =+IFERROR(HLOOKUP($B10,'[2]2월'!$F$6:$CP$99,2,),)/1000 -> 7.4045 | L10: =+K10-J10 -> -2.5955 | M10: =+IFERROR(HLOOKUP($B10,'[3]2월'!$F$6:$CC$57,2,),)/1000 -> 5.877 | N10: =+K10-M10 -> 1.5275 | O10: =+IFERROR(HLOOKUP($B10,'[1]2월'!$D$6:$BN$259,3,),)/1000 -> 957.33513 | P10: =+IFERROR(HLOOKUP($B10,'[2]2월'!$F$6:$CP$99,3,),)/1000 -> 704.99124 | Q10: =+P10-O10 -> -252.34389 | R10: =+IFERROR(HLOOKUP($B10,'[3]2월'!$F$6:$CC$57,3,),)/1000 -> 570.04139 | S10: =+P10-R10 -> 134.94985 | T10: =+IFERROR(HLOOKUP($B10,'[1]2월'!$D$6:$BN$259,16,),)/1000 -> 26.816095 | U10: =+IFERROR(HLOOKUP($B10,'[2]2월'!$F$6:$CP$99,16,),)/1000 -> -46.86888 | V10: =+U10-T10 -> -73.684975 | W10: =+IFERROR(HLOOKUP($B10,'[3]2월'!$F$6:$CC$57,16,),)/1000 -> -50.621 | X10: =+U10-W10 -> 3.75212 | Y10: =+[4]김포!$Q$85 -> 95733.513 | Z10: =+[4]김포!$R$85 -> 95239.126 | AA10: =+[5]김포!$Q$85 -> 96995.302 | AB10: =+[4]김포!$Q$89 -> 77094.679 | AC10: =+[4]김포!$R$89 -> 79871.523 | AD10: =+[5]김포!$Q$89 -> 80274.495 | AE10: =+Y10-AB10 -> 18638.834 | AF10: =+Z10-AC10 -> 15367.602 | AG10: =+AA10-AD10 -> 16720.807
B11: 부산 | G11: =+I11 -> 부산 | I11: 부산 | J11: =+IFERROR(HLOOKUP($B11,'[1]2월'!$D$6:$BN$259,2,),)/1000 -> 19 | K11: =+IFERROR(HLOOKUP($B11,'[2]2월'!$F$6:$CP$99,2,),)/1000 -> 16.897 | L11: =+K11-J11 -> -2.103 | M11: =+IFERROR(HLOOKUP($B11,'[3]2월'!$F$6:$CC$57,2,),)/1000 -> 16.65 | N11: =+K11-M11 -> 0.247 | O11: =+IFERROR(HLOOKUP($B11,'[1]2월'!$D$6:$BN$259,3,),)/1000 -> 2046.2981 | P11: =+IFERROR(HLOOKUP($B11,'[2]2월'!$F$6:$CP$99,3,),)/1000 -> 1794.1025 | Q11: =+P11-O11 -> -252.19564 | R11: =+IFERROR(HLOOKUP($B11,'[3]2월'!$F$6:$CC$57,3,),)/1000 -> 1875.6439 | S11: =+P11-R11 -> -81.5414 | T11: =+IFERROR(HLOOKUP($B11,'[1]2월'!$D$6:$BN$259,16,),)/1000 -> 171.93637 | U11: =+IFERROR(HLOOKUP($B11,'[2]2월'!$F$6:$CP$99,16,),)/1000 -> 133.31258 | V11: =+U11-T11 -> -38.623789 | W11: =+IFERROR(HLOOKUP($B11,'[3]2월'!$F$6:$CC$57,16,),)/1000 -> 201.44822 | X11: =+U11-W11 -> -68.135646 | Y11: =+[4]부산!$Q$85 -> 107699.9 | Z11: =+[4]부산!$R$85 -> 106178.76 | AA11: =+[5]부산!$Q$85 -> 112651.29 | AB11: =+[4]부산!$Q$89 -> 85055.097 | AC11: =+[4]부산!$R$89 -> 84408.739 | AD11: =+[5]부산!$Q$89 -> 86432.204 | AE11: =+Y11-AB11 -> 22644.805 | AF11: =+Z11-AC11 -> 21770.02 | AG11: =+AA11-AD11 -> 26219.081
B12: 서부산 | G12: =+I12 -> 서부산 | I12: 서부산 | J12: =+IFERROR(HLOOKUP($B12,'[1]2월'!$D$6:$BN$259,2,),)/1000 -> 19 | K12: =+IFERROR(HLOOKUP($B12,'[2]2월'!$F$6:$CP$99,2,),)/1000 -> 17.85 | L12: =+K12-J12 -> -1.15 | M12: =+IFERROR(HLOOKUP($B12,'[3]2월'!$F$6:$CC$57,2,),)/1000 -> 16.841 | N12: =+K12-M12 -> 1.009 | O12: =+IFERROR(HLOOKUP($B12,'[1]2월'!$D$6:$BN$259,3,),)/1000 -> 1886.7074 | P12: =+IFERROR(HLOOKUP($B12,'[2]2월'!$F$6:$CP$99,3,),)/1000 -> 1700.7802 | Q12: =+P12-O12 -> -185.92719 | R12: =+IFERROR(HLOOKUP($B12,'[3]2월'!$F$6:$CC$57,3,),)/1000 -> 1729.3343 | S12: =+P12-R12 -> -28.55412 | T12: =+IFERROR(HLOOKUP($B12,'[1]2월'!$D$6:$BN$259,16,),)/1000 -> 156.91558 | U12: =+IFERROR(HLOOKUP($B12,'[2]2월'!$F$6:$CP$99,16,),)/1000 -> 77.502494 | V12: =+U12-T12 -> -79.41309 | W12: =+IFERROR(HLOOKUP($B12,'[3]2월'!$F$6:$CC$57,16,),)/1000 -> 118.8076 | X12: =+U12-W12 -> -41.305105 | Y12: =+[4]서부산!$Q$85 -> 99300.389 | Z12: =+[4]서부산!$R$85 -> 95281.804 | AA12: =+[5]서부산!$Q$85 -> 102685.96 | AB12: =+[4]서부산!$Q$89 -> 78710.43 | AC12: =+[4]서부산!$R$89 -> 78548.451 | AD12: =+[5]서부산!$Q$89 -> 81711.867 | AE12: =+Y12-AB12 -> 20589.959 | AF12: =+Z12-AC12 -> 16733.353 | AG12: =+AA12-AD12 -> 20974.097
B13: 김해 | G13: =+I13 -> 김해 | I13: 김해 | J13: =+IFERROR(HLOOKUP($B13,'[1]2월'!$D$6:$BN$259,2,),)/1000 -> 12 | K13: =+IFERROR(HLOOKUP($B13,'[2]2월'!$F$6:$CP$99,2,),)/1000 -> 4.58 | L13: =+K13-J13 -> -7.42 | M13: =+IFERROR(HLOOKUP($B13,'[3]2월'!$F$6:$CC$57,2,),)/1000 -> 8.639 | N13: =+K13-M13 -> -4.059 | O13: =+IFERROR(HLOOKUP($B13,'[1]2월'!$D$6:$BN$259,3,),)/1000 -> 1155.6033 | P13: =+IFERROR(HLOOKUP($B13,'[2]2월'!$F$6:$CP$99,3,),)/1000 -> 453.453 | Q13: =+P13-O13 -> -702.1503 | R13: =+IFERROR(HLOOKUP($B13,'[3]2월'!$F$6:$CC$57,3,),)/1000 -> 890.1857 | S13: =+P13-R13 -> -436.7327 | T13: =+IFERROR(HLOOKUP($B13,'[1]2월'!$D$6:$BN$259,16,),)/1000 -> 85.847828 | U13: =+IFERROR(HLOOKUP($B13,'[2]2월'!$F$6:$CP$99,16,),)/1000 -> -73.487828 | V13: =+U13-T13 -> -159.33566 | W13: =+IFERROR(HLOOKUP($B13,'[3]2월'!$F$6:$CC$57,16,),)/1000 -> 16.811886 | X13: =+U13-W13 -> -90.299714 | Y13: =+[4]김해!$Q$85 -> 96300.275 | Z13: =+[4]김해!$R$85 -> 99140.018 | AA13: =+[5]김해!$Q$85 -> 103042.68 | AB13: =+[4]김해!$Q$89 -> 76907.116 | AC13: =+[4]김해!$R$89 -> 83284.996 | AD13: =+[5]김해!$Q$89 -> 83785.984 | AE13: =+Y13-AB13 -> 19393.159 | AF13: =+Z13-AC13 -> 15855.022 | AG13: =+AA13-AD13 -> 19256.695
B14: 정관 | G14: =+I14 -> 정관 | I14: 정관 | J14: =+IFERROR(HLOOKUP($B14,'[1]2월'!$D$6:$BN$259,2,),)/1000 -> 18 | K14: =+IFERROR(HLOOKUP($B14,'[2]2월'!$F$6:$CP$99,2,),)/1000 -> 18.366 | L14: =+K14-J14 -> 0.366 | M14: =+IFERROR(HLOOKUP($B14,'[3]2월'!$F$6:$CC$57,2,),)/1000 -> 14.978 | N14: =+K14-M14 -> 3.388 | O14: =+IFERROR(HLOOKUP($B14,'[1]2월'!$D$6:$BN$259,3,),)/1000 -> 1836.0022 | P14: =+IFERROR(HLOOKUP($B14,'[2]2월'!$F$6:$CP$99,3,),)/1000 -> 1908.4609 | Q14: =+P14-O14 -> 72.458668 | R14: =+IFERROR(HLOOKUP($B14,'[3]2월'!$F$6:$CC$57,3,),)/1000 -> 1493.4374 | S14: =+P14-R14 -> 415.0235 | T14: =+IFERROR(HLOOKUP($B14,'[1]2월'!$D$6:$BN$259,16,),)/1000 -> 135.99039 | U14: =+IFERROR(HLOOKUP($B14,'[2]2월'!$F$6:$CP$99,16,),)/1000 -> 150.8114 | V14: =+U14-T14 -> 14.821004 | W14: =+IFERROR(HLOOKUP($B14,'[3]2월'!$F$6:$CC$57,16,),)/1000 -> 34.868347 | X14: =+U14-W14 -> 115.94305 | Y14: =+[4]정관!$Q$85 -> 102000.12 | Z14: =+[4]정관!$R$85 -> 103912.71 | AA14: =+[5]정관!$Q$85 -> 99708.733 | AB14: =+[4]정관!$Q$89 -> 81964.382 | AC14: =+[4]정관!$R$89 -> 85082.054 | AD14: =+[5]정관!$Q$89 -> 84310.743 | AE14: =+Y14-AB14 -> 20035.742 | AF14: =+Z14-AC14 -> 18830.66 | AG14: =+AA14-AD14 -> 15397.99
B15: 양산 | G15: =+I15 -> 양산 | I15: 양산 | J15: =+IFERROR(HLOOKUP($B15,'[1]2월'!$D$6:$BN$259,2,),)/1000 -> 10 | K15: =+IFERROR(HLOOKUP($B15,'[2]2월'!$F$6:$CP$99,2,),)/1000 -> 8.188 | L15: =+K15-J15 -> -1.812 | M15: =+IFERROR(HLOOKUP($B15,'[3]2월'!$F$6:$CC$57,2,),)/1000 -> 9.558 | N15: =+K15-M15 -> -1.37 | O15: =+IFERROR(HLOOKUP($B15,'[1]2월'!$D$6:$BN$259,3,),)/1000 -> 947.2425 | P15: =+IFERROR(HLOOKUP($B15,'[2]2월'!$F$6:$CP$99,3,),)/1000 -> 791.5705 | Q15: =+P15-O15 -> -155.672 | R15: =+IFERROR(HLOOKUP($B15,'[3]2월'!$F$6:$CC$57,3,),)/1000 -> 924.58643 | S15: =+P15-R15 -> -133.01593 | T15: =+IFERROR(HLOOKUP($B15,'[1]2월'!$D$6:$BN$259,16,),)/1000 -> 56.073825 | U15: =+IFERROR(HLOOKUP($B15,'[2]2월'!$F$6:$CP$99,16,),)/1000 -> 32.887764 | V15: =+U15-T15 -> -23.186061 | W15: =+IFERROR(HLOOKUP($B15,'[3]2월'!$F$6:$CC$57,16,),)/1000 -> 98.534238 | X15: =+U15-W15 -> -65.646474 | Y15: =+[4]양산!$Q$85 -> 94724.25 | Z15: =+[4]양산!$R$85 -> 96674.463 | AA15: =+[5]양산!$Q$85 -> 96734.299 | AB15: =+[4]양산!$Q$89 -> 74373.876 | AC15: =+[4]양산!$R$89 -> 74256.725 | AD15: =+[5]양산!$Q$89 -> 71459.126 | AE15: =+Y15-AB15 -> 20350.374 | AF15: =+Z15-AC15 -> 22417.738 | AG15: =+AA15-AD15 -> 25275.173
B16: 창원 | G16: =+I16 -> 창원 | I16: 창원 | J16: =+IFERROR(HLOOKUP($B16,'[1]2월'!$D$6:$BN$259,2,),)/1000 -> 7 | K16: =+IFERROR(HLOOKUP($B16,'[2]2월'!$F$6:$CP$99,2,),)/1000 -> 10.864 | L16: =+K16-J16 -> 3.864 | M16: =+IFERROR(HLOOKUP($B16,'[3]2월'!$F$6:$CC$57,2,),)/1000 -> 15.453 | N16: =+K16-M16 -> -4.589 | O16: =+IFERROR(HLOOKUP($B16,'[1]2월'!$D$6:$BN$259,3,),)/1000 -> 700.0022 | P16: =+IFERROR(HLOOKUP($B16,'[2]2월'!$F$6:$CP$99,3,),)/1000 -> 1085.93 | Q16: =+P16-O16 -> 385.92785 | R16: =+IFERROR(HLOOKUP($B16,'[3]2월'!$F$6:$CC$57,3,),)/1000 -> 1538.5332 | S16: =+P16-R16 -> -452.60315 | T16: =+IFERROR(HLOOKUP($B16,'[1]2월'!$D$6:$BN$259,16,),)/1000 -> -13.173998 | U16: =+IFERROR(HLOOKUP($B16,'[2]2월'!$F$6:$CP$99,16,),)/1000 -> 108.75022 | V16: =+U16-T16 -> 121.92422 | W16: =+IFERROR(HLOOKUP($B16,'[3]2월'!$F$6:$CC$57,16,),)/1000 -> 220.45765 | X16: =+U16-W16 -> -111.70743 | Y16: =+[4]창원!$Q$85 -> 100000.31 | Z16: =+[4]창원!$R$85 -> 99956.742 | AA16: =+[5]창원!$Q$85 -> 99562.104 | AB16: =+[4]창원!$Q$89 -> 75787.34 | AC16: =+[4]창원!$R$89 -> 74426.787 | AD16: =+[5]창원!$Q$89 -> 73759.236 | AE16: =+Y16-AB16 -> 24212.975 | AF16: =+Z16-AC16 -> 25529.956 | AG16: =+AA16-AD16 -> 25802.869
B17: 대구 | G17: =+I17 -> 대구 | I17: 대구 | J17: =+IFERROR(HLOOKUP($B17,'[1]2월'!$D$6:$BN$259,2,),)/1000 -> 11 | K17: =+IFERROR(HLOOKUP($B17,'[2]2월'!$F$6:$CP$99,2,),)/1000 -> 9.434 | L17: =+K17-J17 -> -1.566 | M17: =+IFERROR(HLOOKUP($B17,'[3]2월'!$F$6:$CC$57,2,),)/1000 -> 13.997 | N17: =+K17-M17 -> -4.563 | O17: =+IFERROR(HLOOKUP($B17,'[1]2월'!$D$6:$BN$259,3,),)/1000 -> 1063.872 | P17: =+IFERROR(HLOOKUP($B17,'[2]2월'!$F$6:$CP$99,3,),)/1000 -> 882.50667 | Q17: =+P17-O17 -> -181.36529 | R17: =+IFERROR(HLOOKUP($B17,'[3]2월'!$F$6:$CC$57,3,),)/1000 -> 1431.9897 | S17: =+P17-R17 -> -549.48303 | T17: =+IFERROR(HLOOKUP($B17,'[1]2월'!$D$6:$BN$259,16,),)/1000 -> 54.453551 | U17: =+IFERROR(HLOOKUP($B17,'[2]2월'!$F$6:$CP$99,16,),)/1000 -> 11.519029 | V17: =+U17-T17 -> -42.934522 | W17: =+IFERROR(HLOOKUP($B17,'[3]2월'!$F$6:$CC$57,16,),)/1000 -> 216.44189 | X17: =+U17-W17 -> -204.92286 | Y17: =+[4]대구!$Q$85 -> 96715.633 | Z17: =+[4]대구!$R$85 -> 93545.333 | AA17: =+[5]대구!$Q$85 -> 102306.9 | AB17: =+[4]대구!$Q$89 -> 74775.887 | AC17: =+[4]대구!$R$89 -> 76356.339 | AD17: =+[5]대구!$Q$89 -> 74620.402 | AE17: =+Y17-AB17 -> 21939.746 | AF17: =+Z17-AC17 -> 17188.994 | AG17: =+AA17-AD17 -> 27686.499
B18: 울산 | G18: =+I18 -> 울산 | I18: 울산 | J18: =+IFERROR(HLOOKUP($B18,'[1]2월'!$D$6:$BN$259,2,),)/1000 -> 9 | K18: =+IFERROR(HLOOKUP($B18,'[2]2월'!$F$6:$CP$99,2,),)/1000 -> 9.715 | L18: =+K18-J18 -> 0.715 | M18: =+IFERROR(HLOOKUP($B18,'[3]2월'!$F$6:$CC$57,2,),)/1000 -> 4.7885 | N18: =+K18-M18 -> 4.9265 | O18: =+IFERROR(HLOOKUP($B18,'[1]2월'!$D$6:$BN$259,3,),)/1000 -> 913.54 | P18: =+IFERROR(HLOOKUP($B18,'[2]2월'!$F$6:$CP$99,3,),)/1000 -> 1047.306 | Q18: =+P18-O18 -> 133.766 | R18: =+IFERROR(HLOOKUP($B18,'[3]2월'!$F$6:$CC$57,3,),)/1000 -> 487.72015 | S18: =+P18-R18 -> 559.58585 | T18: =+IFERROR(HLOOKUP($B18,'[1]2월'!$D$6:$BN$259,16,),)/1000 -> 20.987928 | U18: =+IFERROR(HLOOKUP($B18,'[2]2월'!$F$6:$CP$99,16,),)/1000 -> 78.01652 | V18: =+U18-T18 -> 57.028592 | W18: =+IFERROR(HLOOKUP($B18,'[3]2월'!$F$6:$CC$57,16,),)/1000 -> -66.050997 | X18: =+U18-W18 -> 144.06752 | Y18: =+[4]울산!$Q$85 -> 101504.44 | Z18: =+[4]울산!$R$85 -> 107802.99 | AA18: =+[5]울산!$Q$85 -> 101852.39 | AB18: =+[4]울산!$Q$89 -> 82713.62 | AC18: =+[4]울산!$R$89 -> 85472.134 | AD18: =+[5]울산!$Q$89 -> 86917.518 | AE18: =+Y18-AB18 -> 18790.824 | AF18: =+Z18-AC18 -> 22330.851 | AG18: =+AA18-AD18 -> 14934.868
B19: 아산 | G19: =+I19 -> 아산 | I19: 아산 | J19: =+IFERROR(HLOOKUP($B19,'[1]2월'!$D$6:$BN$259,2,),)/1000 -> 18 | K19: =+IFERROR(HLOOKUP($B19,'[2]2월'!$F$6:$CP$99,2,),)/1000 -> 17.767 | L19: =+K19-J19 -> -0.233 | M19: =+IFERROR(HLOOKUP($B19,'[3]2월'!$F$6:$CC$57,2,),)/1000 -> 17.471 | N19: =+K19-M19 -> 0.296 | O19: =+IFERROR(HLOOKUP($B19,'[1]2월'!$D$6:$BN$259,3,),)/1000 -> 1854 | P19: =+IFERROR(HLOOKUP($B19,'[2]2월'!$F$6:$CP$99,3,),)/1000 -> 1783.0426 | Q19: =+P19-O19 -> -70.9574 | R19: =+IFERROR(HLOOKUP($B19,'[3]2월'!$F$6:$CC$57,3,),)/1000 -> 1754.0612 | S19: =+P19-R19 -> 28.981445 | T19: =+IFERROR(HLOOKUP($B19,'[1]2월'!$D$6:$BN$259,16,),)/1000 -> 176.52372 | U19: =+IFERROR(HLOOKUP($B19,'[2]2월'!$F$6:$CP$99,16,),)/1000 -> 71.697309 | V19: =+U19-T19 -> -104.82641 | W19: =+IFERROR(HLOOKUP($B19,'[3]2월'!$F$6:$CC$57,16,),)/1000 -> 117.15924 | X19: =+U19-W19 -> -45.461929 | Y19: =+[4]아산!$Q$85 -> 103000 | Z19: =+[4]아산!$R$85 -> 100356.99 | AA19: =+[5]아산!$Q$85 -> 100398.44 | AB19: =+[4]아산!$Q$89 -> 79524.888 | AC19: =+[4]아산!$R$89 -> 83852.328 | AD19: =+[5]아산!$Q$89 -> 79376.802 | AE19: =+Y19-AB19 -> 23475.112 | AF19: =+Z19-AC19 -> 16504.66 | AG19: =+AA19-AD19 -> 21021.639
B20: 전주 | G20: =+I20 -> 전주 | I20: 전주 | J20: =+IFERROR(HLOOKUP($B20,'[1]2월'!$D$6:$BN$259,2,),)/1000 -> 7 | K20: =+IFERROR(HLOOKUP($B20,'[2]2월'!$F$6:$CP$99,2,),)/1000 -> 13.0765 | L20: =+K20-J20 -> 6.0765 | M20: =+IFERROR(HLOOKUP($B20,'[3]2월'!$F$6:$CC$57,2,),)/1000 -> 2.263 | N20: =+K20-M20 -> 10.8135 | O20: =+IFERROR(HLOOKUP($B20,'[1]2월'!$D$6:$BN$259,3,),)/1000 -> 678.03832 | P20: =+IFERROR(HLOOKUP($B20,'[2]2월'!$F$6:$CP$99,3,),)/1000 -> 1256.9671 | Q20: =+P20-O20 -> 578.9288 | R20: =+IFERROR(HLOOKUP($B20,'[3]2월'!$F$6:$CC$57,3,),)/1000 -> 226.082 | S20: =+P20-R20 -> 1030.8851 | T20: =+IFERROR(HLOOKUP($B20,'[1]2월'!$D$6:$BN$259,16,),)/1000 -> 12.032137 | U20: =+IFERROR(HLOOKUP($B20,'[2]2월'!$F$6:$CP$99,16,),)/1000 -> 149.1804 | V20: =+U20-T20 -> 137.14827 | W20: =+IFERROR(HLOOKUP($B20,'[3]2월'!$F$6:$CC$57,16,),)/1000 -> -81.422136 | X20: =+U20-W20 -> 230.60254 | Y20: =+[4]전주!$Q$85 -> 96862.617 | Z20: =+[4]전주!$R$85 -> 96124.125 | AA20: =+[5]전주!$Q$85 -> 99903.668 | AB20: =+[4]전주!$Q$89 -> 73679.261 | AC20: =+[4]전주!$R$89 -> 73533.899 | AD20: =+[5]전주!$Q$89 -> 73666.573 | AE20: =+Y20-AB20 -> 23183.356 | AF20: =+Z20-AC20 -> 22590.226 | AG20: =+AA20-AD20 -> 26237.095
B21: 군산 | G21: =+I21 -> 군산 | I21: 군산 | J21: =+IFERROR(HLOOKUP($B21,'[1]2월'!$D$6:$BN$259,2,),)/1000 -> 5 | K21: =+IFERROR(HLOOKUP($B21,'[2]2월'!$F$6:$CP$99,2,),)/1000 -> 3.896 | L21: =+K21-J21 -> -1.104 | M21: =+IFERROR(HLOOKUP($B21,'[3]2월'!$F$6:$CC$57,2,),)/1000 -> 5.554 | N21: =+K21-M21 -> -1.658 | O21: =+IFERROR(HLOOKUP($B21,'[1]2월'!$D$6:$BN$259,3,),)/1000 -> 557.60124 | P21: =+IFERROR(HLOOKUP($B21,'[2]2월'!$F$6:$CP$99,3,),)/1000 -> 414.87225 | Q21: =+P21-O21 -> -142.72899 | R21: =+IFERROR(HLOOKUP($B21,'[3]2월'!$F$6:$CC$57,3,),)/1000 -> 576.85868 | S21: =+P21-R21 -> -161.98643 | T21: =+IFERROR(HLOOKUP($B21,'[1]2월'!$D$6:$BN$259,16,),)/1000 -> 104.6721 | U21: =+IFERROR(HLOOKUP($B21,'[2]2월'!$F$6:$CP$99,16,),)/1000 -> 57.866905 | V21: =+U21-T21 -> -46.805192 | W21: =+IFERROR(HLOOKUP($B21,'[3]2월'!$F$6:$CC$57,16,),)/1000 -> 104.45301 | X21: =+U21-W21 -> -46.586102 | Y21: =+[4]군산!$Q$85 -> 111520.25 | Z21: =+[4]군산!$R$85 -> 106486.72 | AA21: =+[5]군산!$Q$85 -> 103863.64 | AB21: =+[4]군산!$Q$89 -> 73867.306 | AC21: =+[4]군산!$R$89 -> 71564.787 | AD21: =+[5]군산!$Q$89 -> 70822.396 | AE21: =+Y21-AB21 -> 37652.942 | AF21: =+Z21-AC21 -> 34921.93 | AG21: =+AA21-AD21 -> 33041.248
B22: 원주 | G22: =+I22 -> 원주 | I22: 원주 | J22: =+IFERROR(HLOOKUP($B22,'[1]2월'!$D$6:$BN$259,2,),)/1000 -> 2 | K22: =+IFERROR(HLOOKUP($B22,'[2]2월'!$F$6:$CP$99,2,),)/1000 -> 1.228 | L22: =+K22-J22 -> -0.772 | M22: =+IFERROR(HLOOKUP($B22,'[3]2월'!$F$6:$CC$57,2,),)/1000 -> 3.4065 | N22: =+K22-M22 -> -2.1785 | O22: =+IFERROR(HLOOKUP($B22,'[1]2월'!$D$6:$BN$259,3,),)/1000 -> 224 | P22: =+IFERROR(HLOOKUP($B22,'[2]2월'!$F$6:$CP$99,3,),)/1000 -> 138.4771 | Q22: =+P22-O22 -> -85.5229 | R22: =+IFERROR(HLOOKUP($B22,'[3]2월'!$F$6:$CC$57,3,),)/1000 -> 364.3647 | S22: =+P22-R22 -> -225.8876 | T22: =+IFERROR(HLOOKUP($B22,'[1]2월'!$D$6:$BN$259,16,),)/1000 -> -12.698378 | U22: =+IFERROR(HLOOKUP($B22,'[2]2월'!$F$6:$CP$99,16,),)/1000 -> -36.517007 | V22: =+U22-T22 -> -23.818629 | W22: =+IFERROR(HLOOKUP($B22,'[3]2월'!$F$6:$CC$57,16,),)/1000 -> 36.292712 | X22: =+U22-W22 -> -72.809719 | Y22: =+[4]원주!$Q$85 -> 112000 | Z22: =+[4]원주!$R$85 -> 112766.37 | AA22: =+[5]원주!$Q$85 -> 106985.05 | AB22: =+[4]원주!$Q$89 -> 75003.432 | AC22: =+[4]원주!$R$89 -> 75882.36 | AD22: =+[5]원주!$Q$89 -> 72527.647 | AE22: =+Y22-AB22 -> 36996.568 | AF22: =+Z22-AC22 -> 36884.008 | AG22: =+AA22-AD22 -> 34457.401
B23: 제주 | G23: =+I23 -> 제주 | I23: 제주 | J23: =+IFERROR(HLOOKUP($B23,'[1]2월'!$D$6:$BN$259,2,),)/1000 -> 7 | K23: =+IFERROR(HLOOKUP($B23,'[2]2월'!$F$6:$CP$99,2,),)/1000 -> 4.678 | L23: =+K23-J23 -> -2.322 | M23: =+IFERROR(HLOOKUP($B23,'[3]2월'!$F$6:$CC$57,2,),)/1000 -> 2.3985 | N23: =+K23-M23 -> 2.2795 | O23: =+IFERROR(HLOOKUP($B23,'[1]2월'!$D$6:$BN$259,3,),)/1000 -> 859.7575 | P23: =+IFERROR(HLOOKUP($B23,'[2]2월'!$F$6:$CP$99,3,),)/1000 -> 565.73136 | Q23: =+P23-O23 -> -294.02614 | R23: =+IFERROR(HLOOKUP($B23,'[3]2월'!$F$6:$CC$57,3,),)/1000 -> 308.44243 | S23: =+P23-R23 -> 257.28894 | T23: =+IFERROR(HLOOKUP($B23,'[1]2월'!$D$6:$BN$259,16,),)/1000 -> 134.03568 | U23: =+IFERROR(HLOOKUP($B23,'[2]2월'!$F$6:$CP$99,16,),)/1000 -> 53.836508 | V23: =+U23-T23 -> -80.199177 | W23: =+IFERROR(HLOOKUP($B23,'[3]2월'!$F$6:$CC$57,16,),)/1000 -> 14.867436 | X23: =+U23-W23 -> 38.969072 | Y23: =+[4]제주!$Q$85 -> 122822.5 | Z23: =+[4]제주!$R$85 -> 120936.46 | AA23: =+[5]제주!$Q$85 -> 128598.05 | AB23: =+[4]제주!$Q$89 -> 90529.859 | AC23: =+[4]제주!$R$89 -> 89525.331 | AD23: =+[5]제주!$Q$89 -> 88785.068 | AE23: =+Y23-AB23 -> 32292.641 | AF23: =+Z23-AC23 -> 31411.133 | AG23: =+AA23-AD23 -> 39812.983
G24: =+I24 -> 수도권 | I24: 수도권 | J24: =SUM(J7:J10) -> 83 | K24: =SUM(K7:K10) -> 74.2395 | L24: =+K24-J24 -> -8.7605 | M24: =SUM(M7:M10) -> 85.559 | N24: =+K24-M24 -> -11.3195 | O24: =SUM(O7:O10) -> 8098.2048 | P24: =SUM(P7:P10) -> 7199.5675 | Q24: =+P24-O24 -> -898.63727 | R24: =SUM(R7:R10) -> 8620.3028 | S24: =+P24-R24 -> -1420.7353 | T24: =SUM(T7:T10) -> 291.53061 | U24: =SUM(U7:U10) -> 126.59635 | V24: =+U24-T24 -> -164.93426 | W24: =SUM(W7:W10) -> 664.23061 | X24: =+U24-W24 -> -537.63426 | Y24: =+[4]수도권!$Q$85 -> 97568.732 | Z24: =+[4]수도권!$R$85 -> 96965.552 | AA24: =+[5]수도권!$Q$85 -> 100756.04 | AB24: =+[4]수도권!$Q$89 -> 81841.913 | AC24: =+[4]수도권!$R$89 -> 82274.26 | AD24: =+[5]수도권!$Q$89 -> 81462.706 | AE24: =+Y24-AB24 -> 15726.819 | AF24: =+Z24-AC24 -> 14691.292 | AG24: =+AA24-AD24 -> 19293.33
G25: =+I25 -> 영남권 | I25: 영남권 | J25: =SUM(J11:J18) -> 105 | K25: =SUM(K11:K18) -> 95.894 | L25: =+K25-J25 -> -9.106 | M25: =SUM(M11:M18) -> 100.9045 | N25: =+K25-M25 -> -5.0105 | O25: =SUM(O11:O18) -> 10549.268 | P25: =SUM(P11:P18) -> 9664.1098 | Q25: =+P25-O25 -> -885.15791 | R25: =SUM(R11:R18) -> 10371.431 | S25: =+P25-R25 -> -707.32098 | T25: =SUM(T11:T18) -> 669.03148 | U25: =SUM(U11:U18) -> 519.31218 | V25: =+U25-T25 -> -149.7193 | W25: =SUM(W11:W18) -> 841.31884 | X25: =+U25-W25 -> -322.00666 | Y25: =+[4]영남권!$Q$85 -> 100469.22 | Z25: =+[4]영남권!$R$85 -> 100787.78 | AA25: =+[5]영남권!$Q$85 -> 102784.62 | AB25: =+[4]영남권!$Q$89 -> 79533.302 | AC25: =+[4]영남권!$R$89 -> 80685.912 | AD25: =+[5]영남권!$Q$89 -> 80130.48 | AE25: =+Y25-AB25 -> 20935.914 | AF25: =+Z25-AC25 -> 20101.873 | AG25: =+AA25-AD25 -> 22654.141
G26: =+I26 -> 중부권 | I26: 중부권 | J26: =SUM(J19:J23) -> 39 | K26: =SUM(K19:K23) -> 40.6455 | L26: =+K26-J26 -> 1.6455 | M26: =SUM(M19:M23) -> 31.093 | N26: =+K26-M26 -> 9.5525 | O26: =SUM(O19:O23) -> 4173.3971 | P26: =SUM(P19:P23) -> 4159.0904 | Q26: =+P26-O26 -> -14.306627 | R26: =SUM(R19:R23) -> 3229.809 | S26: =+P26-R26 -> 929.28147 | T26: =SUM(T19:T23) -> 414.56526 | U26: =SUM(U19:U23) -> 296.06412 | V26: =+U26-T26 -> -118.50114 | W26: =SUM(W19:W23) -> 191.35026 | X26: =+U26-W26 -> 104.71386 | Y26: =+[4]중부권!$Q$85 -> 107010.18 | Z26: =+[4]중부권!$R$85 -> 102295.48 | AA26: =+[5]중부권!$Q$85 -> 103875.43 | AB26: =+[4]중부권!$Q$89 -> 79493.724 | AC26: =+[4]중부권!$R$89 -> 79762.985 | AD26: =+[5]중부권!$Q$89 -> 77415.679 | AE26: =+Y26-AB26 -> 27516.457 | AF26: =+Z26-AC26 -> 22532.494 | AG26: =+AA26-AD26 -> 26459.748
G27: =+K27/J27 -> 0.92854185 | H27: 레미콘 계 | J27: =SUM(J24:J26) -> 227 | K27: =SUM(K24:K26) -> 210.779 | L27: =+K27-J27 -> -16.221 | M27: =SUM(M24:M26) -> 217.5565 | N27: =+K27-M27 -> -6.7775 | O27: =SUM(O24:O26) -> 22820.87 | P27: =SUM(P24:P26) -> 21022.768 | Q27: =+P27-O27 -> -1798.1018 | R27: =SUM(R24:R26) -> 22221.543 | S27: =+P27-R27 -> -1198.7749 | T27: =SUM(T24:T26) -> 1375.1273 | U27: =SUM(U24:U26) -> 941.97265 | V27: =+U27-T27 -> -433.15469 | W27: =SUM(W24:W26) -> 1696.8997 | X27: =+U27-W27 -> -754.92706 | Y27: =+[4]합계!$Q$85 -> 100532.46 | Z27: =+[4]합계!$R$85 -> 99735.994 | AA27: =+[5]합계!$Q$85 -> 102142.73 | AB27: =+[4]합계!$Q$89 -> 80370.62 | AC27: =+[4]합계!$R$89 -> 81063.082 | AD27: =+[5]합계!$Q$89 -> 80266.474 | AE27: =+Y27-AB27 -> 20161.845 | AF27: =+Z27-AC27 -> 18672.912 | AG27: =+AA27-AD27 -> 21876.256
B28: 건자재 | E28: 건자재영업 | G28: 건자재 | H28: 건자재 | J28: =+IFERROR(HLOOKUP($B28,'[1]2월'!$D$6:$BN$259,2,),) -> 10200 | K28: =+IFERROR(HLOOKUP($E28,'[2]2월'!$F$6:$CP$99,2,),) -> 9724.523 | L28: =+K28-J28 -> -475.477 | M28: =+IFERROR(HLOOKUP($E28,'[3]2월'!$F$6:$CC$57,2,),) -> 6645.402 | N28: =+K28-M28 -> 3079.121 | O28: =+IFERROR(HLOOKUP($B28,'[1]2월'!$D$6:$BN$259,3,),)/1000 -> 11165.946 | P28: =+IFERROR(HLOOKUP($E28,'[2]2월'!$F$6:$CP$99,3,),)/1000 -> 8276.9951 | Q28: =+P28-O28 -> -2888.9504 | R28: =+IFERROR(HLOOKUP($E28,'[3]2월'!$F$6:$CC$57,3,),)/1000 -> 6765.658 | S28: =+P28-R28 -> 1511.3371 | T28: =+IFERROR(HLOOKUP($B28,'[1]2월'!$D$6:$BN$259,16,),)/1000 -> 171.62076 | U28: =+IFERROR(HLOOKUP($E28,'[2]2월'!$F$6:$CP$99,16,),)/1000 -> 10.861713 | V28: =+U28-T28 -> -160.75904 | W28: =+IFERROR(HLOOKUP($E28,'[3]2월'!$F$6:$CC$57,16,),)/1000 -> 41.844679 | X28: =+U28-W28 -> -30.982966 | Y28: ■ 비고
B29: 부산모래장 | C29: 부산골재 | G29: =+I29 -> 부산모래장 | H29: 골재 | I29: 부산모래장 | J29: =+IFERROR(HLOOKUP($B29,'[1]2월'!$D$6:$BN$259,2,),)/1000 -> 16.714188 | K29: =+IFERROR(HLOOKUP($C29,'[2]2월'!$F$6:$CP$99,2,),)/1000 -> 24.573 | L29: =+K29-J29 -> 7.8588118 | M29: =+IFERROR(HLOOKUP($C29,'[3]2월'!$F$6:$CC$57,2,),)/1000 -> 18.623 | N29: =+K29-M29 -> 5.95 | O29: =+IFERROR(HLOOKUP($B29,'[1]2월'!$D$6:$BN$259,3,),)/1000 -> 677.0087 | P29: =+IFERROR(HLOOKUP($C29,'[2]2월'!$F$6:$CP$99,3,),)/1000 -> 679.8605 | Q29: =+P29-O29 -> 2.8517957 | R29: =+IFERROR(HLOOKUP($C29,'[3]2월'!$F$6:$CC$57,3,),)/1000 -> 535.572 | S29: =+P29-R29 -> 144.2885 | T29: =+IFERROR(HLOOKUP($B29,'[1]2월'!$D$6:$BN$259,21,),)/1000 -> 206.49877 | U29: =+IFERROR(HLOOKUP($C29,'[2]2월'!$F$6:$CP$99,21,),)/1000 -> 5.3680995 | V29: =+U29-T29 -> -201.13067 | W29: =+IFERROR(HLOOKUP($C29,'[3]2월'!$F$6:$CC$57,21,),)/1000 -> 33.694013 | X29: =+U29-W29 -> -28.325913
B30: 서부산크라샤 | C30: 서부산골재 | G30: =+I30 -> 서부산CR | I30: 서부산CR | J30: =+IFERROR(HLOOKUP($B30,'[1]2월'!$D$6:$BN$259,2,),)/1000 -> 45.69766 | K30: =+IFERROR(HLOOKUP($C30,'[2]2월'!$F$6:$CP$99,2,),)/1000 -> 12.95 | L30: =+K30-J30 -> -32.74766 | M30: =+IFERROR(HLOOKUP($C30,'[3]2월'!$F$6:$CC$57,2,),)/1000 -> 23.046 | N30: =+K30-M30 -> -10.096 | O30: =+IFERROR(HLOOKUP($B30,'[1]2월'!$D$6:$BN$259,3,),)/1000 -> 664.49243 | P30: =+IFERROR(HLOOKUP($C30,'[2]2월'!$F$6:$CP$99,3,),)/1000 -> 179.002 | Q30: =+P30-O30 -> -485.49043 | R30: =+IFERROR(HLOOKUP($C30,'[3]2월'!$F$6:$CC$57,3,),)/1000 -> 318.718 | S30: =+P30-R30 -> -139.716 | T30: =+IFERROR(HLOOKUP($B30,'[1]2월'!$D$6:$BN$259,21,),)/1000 -> 98.380765 | U30: =+IFERROR(HLOOKUP($C30,'[2]2월'!$F$6:$CP$99,21,),)/1000 -> 2.8212828 | V30: =+U30-T30 -> -95.559482 | W30: =+IFERROR(HLOOKUP($C30,'[3]2월'!$F$6:$CC$57,21,),)/1000 -> 37.250623 | X30: =+U30-W30 -> -34.42934
B31: 부산크라샤 | C31: 부산크라샤 | G31: =+I31 -> 부산CR | I31: 부산CR | J31: =+IFERROR(HLOOKUP($B31,'[1]2월'!$D$6:$BN$259,2,),)/1000 -> 11.960347 | K31: =+IFERROR(HLOOKUP($C31,'[2]2월'!$F$6:$CP$99,2,),)/1000 -> 20.414 | L31: =+K31-J31 -> 8.4536532 | M31: =+IFERROR(HLOOKUP($C31,'[3]2월'!$F$6:$CC$57,2,),)/1000 -> 23.603 | N31: =+K31-M31 -> -3.189 | O31: =+IFERROR(HLOOKUP($B31,'[1]2월'!$D$6:$BN$259,3,),)/1000 -> 253.38819 | P31: =+IFERROR(HLOOKUP($C31,'[2]2월'!$F$6:$CP$99,3,),)/1000 -> 383.721 | Q31: =+P31-O31 -> 130.33281 | R31: =+IFERROR(HLOOKUP($C31,'[3]2월'!$F$6:$CC$57,3,),)/1000 -> 442.7965 | S31: =+P31-R31 -> -59.0755 | T31: =+IFERROR(HLOOKUP($B31,'[1]2월'!$D$6:$BN$259,21,),)/1000 -> -30.784903 | U31: =+IFERROR(HLOOKUP($C31,'[2]2월'!$F$6:$CP$99,21,),)/1000 -> -106.33152 | V31: =+U31-T31 -> -75.546615 | W31: =+IFERROR(HLOOKUP($C31,'[3]2월'!$F$6:$CC$57,21,),)/1000 -> 8.2347302 | X31: =+U31-W31 -> -114.56625
H32: 골재 계 | J32: =SUM(J29:J31) -> 74.372195 | K32: =SUM(K29:K31) -> 57.937 | L32: =+K32-J32 -> -16.435195 | M32: =SUM(M29:M31) -> 65.272 | N32: =+K32-M32 -> -7.335 | O32: =SUM(O29:O31) -> 1594.8893 | P32: =SUM(P29:P31) -> 1242.5835 | Q32: =+P32-O32 -> -352.30582 | R32: =SUM(R29:R31) -> 1297.0865 | S32: =+P32-R32 -> -54.503 | T32: =SUM(T29:T31) -> 274.09463 | U32: =SUM(U29:U31) -> -98.142135 | V32: =+U32-T32 -> -372.23676 | W32: =SUM(W29:W31) -> 79.179365 | X32: =+U32-W32 -> -177.3215
B33: 포항임대 | C33: 속초임대 | D33: 강릉임대 | E33: 레미콘임대 계 | G33: =+I33 -> 레미콘임대 | H33: 기타 | I33: 레미콘임대 | L33: =+K33-J33 -> 0 | N33: =+K33-M33 -> 0 | O33: =(IFERROR(HLOOKUP($B33,'[1]2월'!$D$6:$BN$259,3,),)++IFERROR(HLOOKUP($C33,'[1]2월'!$D$6:$BN$259,3,),)+IFERROR(HLOOKUP($D33,'[1]2월'!$D$6:$BN$259,3,),))/1000 -> 90.84 | P33: =+IFERROR(HLOOKUP($E33,'[2]2월'!$F$6:$CP$99,3,),)/1000 -> 90.84 | Q33: =+P33-O33 -> 0 | R33: =+IFERROR(HLOOKUP($E33,'[3]2월'!$F$6:$CC$57,3,),)/1000 -> 90.84 | S33: =+P33-R33 -> 0 | T33: =(IFERROR(HLOOKUP($B33,'[1]2월'!$D$6:$BN$259,21,),)++IFERROR(HLOOKUP($C33,'[1]2월'!$D$6:$BN$259,21,),)+IFERROR(HLOOKUP($D33,'[1]2월'!$D$6:$BN$259,21,),))/1000 -> 72.523221 | U33: =+IFERROR(HLOOKUP($E33,'[2]2월'!$F$6:$CP$99,16,),)/1000 -> 72.530954 | V33: =+U33-T33 -> 0.007733 | W33: =+IFERROR(HLOOKUP($E33,'[3]2월'!$F$6:$CC$57,16,),)/1000 -> 71.965353 | X33: =+U33-W33 -> 0.565601
B34: 부동산임대 | C34: 주유소임대 | E34: 임대 계 | G34: =+I34 -> 임대 | I34: 임대 | L34: =+K34-J34 -> 0 | M34: 0 | N34: =+K34-M34 -> 0 | O34: =(+IFERROR(HLOOKUP($B34,'[1]2월'!$D$6:$BN$259,3,),)+IFERROR(HLOOKUP($C34,'[1]2월'!$D$6:$BN$259,3,),))/1000 -> 74.0915 | P34: =+IFERROR(HLOOKUP($E34,'[2]2월'!$F$6:$CP$99,3,),)/1000 -> 71.999518 | Q34: =+P34-O34 -> -2.091982 | R34: =+IFERROR(HLOOKUP($E34,'[3]2월'!$F$6:$CC$57,3,),)/1000 -> 71.982759 | S34: =+P34-R34 -> 0.016759 | T34: =(+IFERROR(HLOOKUP($B34,'[1]2월'!$D$6:$BN$259,21,),)+IFERROR(HLOOKUP($C34,'[1]2월'!$D$6:$BN$259,21,),))/1000 -> 63.964 | U34: =+IFERROR(HLOOKUP($E34,'[2]2월'!$F$6:$CP$99,16,),)/1000 -> 61.899625 | V34: =+U34-T34 -> -2.064375 | W34: =+IFERROR(HLOOKUP($E34,'[3]2월'!$F$6:$CC$57,16,),)/1000 -> 61.893705 | X34: =+U34-W34 -> 0.00592
B35: 공 통 비 | G35: =+I35 -> 공통비 | I35: 공통비 | L35: =+K35-J35 -> 0 | N35: =+K35-M35 -> 0 | Q35: =+P35-O35 -> 0 | S35: =+P35-R35 -> 0 | T35: =-'[1]2월'!$Z$22/1000 -> -1202.7748 | U35: =+-'[2]2월'!$Z$22/1000 -> -1276.8971 | V35: =+U35-T35 -> -74.122279 | W35: =+-'[3]2월'!$Z$22/1000 -> -1053.317 | X35: =+U35-W35 -> -223.58013
G36: =+I36 -> OPC 소급분 | I36: OPC 소급분 | N36: =+K36-M36 -> 0 | Q36: =+P36-O36 -> 0 | S36: =+P36-R36 -> 0 | T36: =+'[1]2월'!$AS$26/1000 -> 0 | U36: ='[2]2월'!$BD$26/1000 -> 0 | V36: =+U36-T36 -> 0 | W36: =-'[3]2월'!$BD$26/1000 -> 0 | X36: =+U36-W36 -> 0
G37: =+I37 -> 대손 | I37: 대손 | N37: =+K37-M37 -> 0 | Q37: =+P37-O37 -> 0 | S37: =+P37-R37 -> 0 | U37: ='[2]2월'!$BE$26/1000 -> 0 | V37: =+U37-T37 -> 0 | W37: ='[3]2월'!$BE$26/1000 -> 310.72653 | X37: =+U37-W37 -> -310.72653
G38: =+I38 -> 미운영 공장 | I38: 미운영 공장 | M38: =SUM(M54:M59) -> 0 | N38: =+K38-M38 -> 0 | Q38: =+P38-O38 -> 0 | R38: =+IFERROR(HLOOKUP($I$38,'[3]2월'!$F$6:$BJ$50,3,),)/1000 -> 0 | S38: =+P38-R38 -> 0 | T38: =SUM('[1]2월'!$AM$26:$AQ$26)/1000 -> -32.504496 | U38: =+'[2]2월'!$BF$26/1000 -> -31.585609 | V38: =+U38-T38 -> 0.918887 | W38: =+'[3]2월'!$BF$26/1000 -> -35.452237 | X38: =+U38-W38 -> 3.866628
B39: 기타 계 | G39: =+I39 -> 퇴직금 | I39: 퇴직금 | U39: =+'[2]2월'!$BG$26/1000 -> 0 | V39: =+U39-T39 -> 0 | X39: =+U39-W39 -> 0
G40: =+I40 -> 기타 | I40: 기타 | L40: =+K40-J40 -> 0 | N40: =+K40-M40 -> 0 | O40: =IFERROR(HLOOKUP($B39,'[1]2월'!$D$6:$BN$259,3,),)/1000 -> 1.77 | P40: =+('[2]2월'!$F$8-SUM('[2]2월'!$Z$8,'[2]2월'!$AH$8,'[2]2월'!$AN$8,'[2]2월'!$AO$8,'[2]2월'!$BA$8,'[2]2월'!$BD$8,'[2]2월'!$BE$8,'[2]2월'!$BF$8))/1000 -> 1.67985 | Q40: =+P40-O40 -> -0.09015 | R40: =+('[3]2월'!$F$8-SUM('[3]2월'!$Z$8,'[3]2월'!$AH$8,'[3]2월'!$AN$8,'[3]2월'!$AO$8,'[3]2월'!$BA$8,'[3]2월'!$BD$8,'[3]2월'!$BE$8,'[3]2월'!$BF$8))/1000 -> 1.7024 | S40: =+P40-R40 -> -0.02255 | T40: =+('[1]2월'!$E$26-'[1]2월'!$Z$26-'[1]2월'!$AA$26-'[1]2월'!$AE$26-'[1]2월'!$AL$26-'[1]2월'!$AM$26-'[1]2월'!$AN$26-'[1]2월'!$AO$26-'[1]2월'!$AP$26-'[1]2월'!$AQ$26-'[1]2월'!$AS$26)/1000 -> -16.802745 | U40: =+('[2]2월'!$F$26-SUM('[2]2월'!$Z$26,'[2]2월'!$AH$26,'[2]2월'!$AN$26,'[2]2월'!$AO$26,'[2]2월'!$BA$26,'[2]2월'!$BD$26,'[2]2월'!$BE$26,'[2]2월'!$BF$26))/1000-U39 -> -16.01009 | V40: =+U40-T40 -> 0.792655 | W40: =+('[3]2월'!$F$26-SUM('[3]2월'!$Z$26,'[3]2월'!$AH$26,'[3]2월'!$AN$26,'[3]2월'!$AO$26,'[3]2월'!$BA$26,'[3]2월'!$BD$26,'[3]2월'!$BE$26,'[3]2월'!$BF$26))/1000 -> -14.483713 | X40: =+U40-W40 -> -1.526377
H41: 기타 계 | J41: =SUM(J33:J40) -> 0 | K41: =SUM(K33:K40) -> 0 | L41: =+K41-J41 -> 0 | M41: =SUM(M33:M40) -> 0 | N41: =+K41-M41 -> 0 | O41: =SUM(O33:O40) -> 166.7015 | P41: =SUM(P33:P40) -> 164.51937 | Q41: =+P41-O41 -> -2.182132 | R41: =SUM(R33:R40) -> 164.52516 | S41: =+P41-R41 -> -0.005791 | T41: =SUM(T33:T40) -> -1115.5948 | U41: =SUM(U33:U40) -> -1190.0622 | V41: =+U41-T41 -> -74.467379 | W41: =SUM(W33:W40) -> -658.66734 | X41: =+U41-W41 -> -531.39489
U42: 19 | V42: 12.4
...

Sheet 사업장별(누계)
H3: □ 사업장별 손익실적(2025-02누계)
AG4: [단위 : 천㎥, 톤, 백만원]
H5: 구분 | J5: 물량 | O5: 매출 | T5: 영업이익(공통비 배부전) | Y5: 판매단가 | AB5: 변동비 | AE5: 공헌이익
A6: 2024년 2월누계 마감 손익 | J6: 계획 | K6: 실적 | L6: 차이 | M6: 전년 | N6: 차이 | O6: 계획 | P6: 실적 | Q6: 차이 | R6: 전년 | S6: 차이 | T6: 계획 | U6: 실적 | V6: 차이 | W6: 전년 | X6: 차이 | Y6: 계획 | Z6: 실적 | AA6: 전년 | AB6: 계획 | AC6: 실적 | AD6: 전년 | AE6: 계획 | AF6: 실적 | AG6: 전년
B7: 안양 | G7: =+I7 -> 안양 | H7: 레미콘 | I7: 안양 | J7: =+IFERROR(HLOOKUP($B7,'[1]2월누계'!$D$6:$BN$259,2,),)/1000 -> 62 | K7: =+IFERROR(HLOOKUP($B7,'[2]2월누계'!$F$6:$CP$99,2,),)/1000 -> 62.102 | L7: =+K7-J7 -> 0.102 | M7: =+IFERROR(HLOOKUP($B7,'[3]2월누계'!$F$6:$CC$57,2,),)/1000 -> 83.473 | N7: =+K7-M7 -> -21.371 | O7: =+IFERROR(HLOOKUP($B7,'[1]2월누계'!$D$6:$BN$259,3,),)/1000 -> 6098.348 | P7: =+IFERROR(HLOOKUP($B7,'[2]2월누계'!$F$6:$CP$99,3,),)/1000 -> 6088.3026 | Q7: =+P7-O7 -> -10.045462 | R7: =+IFERROR(HLOOKUP($B7,'[3]2월누계'!$F$6:$CC$57,3,),)/1000 -> 8145.4069 | S7: =+P7-R7 -> -2057.1043 | T7: =+IFERROR(HLOOKUP($B7,'[1]2월누계'!$D$6:$BN$259,16,),)/1000 -> 325.93432 | U7: =+IFERROR(HLOOKUP($B7,'[2]2월누계'!$F$6:$CP$99,16,),)/1000 -> 353.64214 | V7: =+U7-T7 -> 27.707821 | W7: =+IFERROR(HLOOKUP($B7,'[3]2월누계'!$F$6:$CC$57,16,),)/1000 -> 788.53204 | X7: =+U7-W7 -> -434.8899 | Y7: =+[8]안양!$Q$85 -> 98219.131 | Z7: =+[8]안양!$R$85 -> 98025.663 | AA7: =+[9]안양!$Q$85 -> 97581.336 | AB7: =+[8]안양!$Q$89 -> 82566.624 | AC7: =+[8]안양!$R$89 -> 82531.062 | AD7: =+[9]안양!$Q$89 -> 80540.048 | AE7: =+Y7-AB7 -> 15652.507 | AF7: =+Z7-AC7 -> 15494.601 | AG7: =+AA7-AD7 -> 17041.289
B8: 인천 | G8: =+I8 -> 인천 | H8: 직영 | I8: 인천 | J8: =+IFERROR(HLOOKUP($B8,'[1]2월누계'!$D$6:$BN$259,2,),)/1000 -> 50 | K8: =+IFERROR(HLOOKUP($B8,'[2]2월누계'!$F$6:$CP$99,2,),)/1000 -> 37.389 | L8: =+K8-J8 -> -12.611 | M8: =+IFERROR(HLOOKUP($B8,'[3]2월누계'!$F$6:$CC$57,2,),)/1000 -> 51.84 | N8: =+K8-M8 -> -14.451 | O8: =+IFERROR(HLOOKUP($B8,'[1]2월누계'!$D$6:$BN$259,3,),)/1000 -> 4877.1862 | P8: =+IFERROR(HLOOKUP($B8,'[2]2월누계'!$F$6:$CP$99,3,),)/1000 -> 3697.3737 | Q8: =+P8-O8 -> -1179.8125 | R8: =+IFERROR(HLOOKUP($B8,'[3]2월누계'!$F$6:$CC$57,3,),)/1000 -> 5123.5698 | S8: =+P8-R8 -> -1426.1961 | T8: =+IFERROR(HLOOKUP($B8,'[1]2월누계'!$D$6:$BN$259,16,),)/1000 -> 88.87654 | U8: =+IFERROR(HLOOKUP($B8,'[2]2월누계'!$F$6:$CP$99,16,),)/1000 -> -176.5301 | V8: =+U8-T8 -> -265.40664 | W8: =+IFERROR(HLOOKUP($B8,'[3]2월누계'!$F$6:$CC$57,16,),)/1000 -> 240.8827 | X8: =+U8-W8 -> -417.41281 | Y8: =+[8]인천!$Q$85 -> 97359.535 | Z8: =+[8]인천!$R$85 -> 98889.345 | AA8: =+[9]인천!$Q$85 -> 98834.295 | AB8: =+[8]인천!$Q$89 -> 83665.025 | AC8: =+[8]인천!$R$89 -> 87267.4 | AD8: =+[9]인천!$Q$89 -> 83169.154 | AE8: =+Y8-AB8 -> 13694.51 | AF8: =+Z8-AC8 -> 11621.945 | AG8: =+AA8-AD8 -> 15665.141
B9: 파주 | G9: =+I9 -> 파주 | I9: 파주 | J9: =+IFERROR(HLOOKUP($B9,'[1]2월누계'!$D$6:$BN$259,2,),)/1000 -> 30 | K9: =+IFERROR(HLOOKUP($B9,'[2]2월누계'!$F$6:$CP$99,2,),)/1000 -> 18.888 | L9: =+K9-J9 -> -11.112 | M9: =+IFERROR(HLOOKUP($B9,'[3]2월누계'!$F$6:$CC$57,2,),)/1000 -> 41.352 | N9: =+K9-M9 -> -22.464 | O9: =+IFERROR(HLOOKUP($B9,'[1]2월누계'!$D$6:$BN$259,3,),)/1000 -> 2893.6265 | P9: =+IFERROR(HLOOKUP($B9,'[2]2월누계'!$F$6:$CP$99,3,),)/1000 -> 1818.6236 | Q9: =+P9-O9 -> -1075.0029 | R9: =+IFERROR(HLOOKUP($B9,'[3]2월누계'!$F$6:$CC$57,3,),)/1000 -> 4220.6218 | S9: =+P9-R9 -> -2401.9982 | T9: =+IFERROR(HLOOKUP($B9,'[1]2월누계'!$D$6:$BN$259,16,),)/1000 -> 9.1280336 | U9: =+IFERROR(HLOOKUP($B9,'[2]2월누계'!$F$6:$CP$99,16,),)/1000 -> -149.28401 | V9: =+U9-T9 -> -158.41205 | W9: =+IFERROR(HLOOKUP($B9,'[3]2월누계'!$F$6:$CC$57,16,),)/1000 -> 241.86419 | X9: =+U9-W9 -> -391.14821 | Y9: =+[8]파주!$Q$85 -> 96266.346 | Z9: =+[8]파주!$R$85 -> 96284.604 | AA9: =+[9]파주!$Q$85 -> 102073.71 | AB9: =+[8]파주!$Q$89 -> 79356.82 | AC9: =+[8]파주!$R$89 -> 80397.388 | AD9: =+[9]파주!$Q$89 -> 84198.573 | AE9: =+Y9-AB9 -> 16909.526 | AF9: =+Z9-AC9 -> 15887.216 | AG9: =+AA9-AD9 -> 17875.138
B10: 김포 | G10: =+I10 -> 김포 | I10: 김포 | J10: =+IFERROR(HLOOKUP($B10,'[1]2월누계'!$D$6:$BN$259,2,),)/1000 -> 17 | K10: =+IFERROR(HLOOKUP($B10,'[2]2월누계'!$F$6:$CP$99,2,),)/1000 -> 12.789 | L10: =+K10-J10 -> -4.211 | M10: =+IFERROR(HLOOKUP($B10,'[3]2월누계'!$F$6:$CC$57,2,),)/1000 -> 11.158 | N10: =+K10-M10 -> 1.631 | O10: =+IFERROR(HLOOKUP($B10,'[1]2월누계'!$D$6:$BN$259,3,),)/1000 -> 1638.0249 | P10: =+IFERROR(HLOOKUP($B10,'[2]2월누계'!$F$6:$CP$99,3,),)/1000 -> 1231.197 | Q10: =+P10-O10 -> -406.82793 | R10: =+IFERROR(HLOOKUP($B10,'[3]2월누계'!$F$6:$CC$57,3,),)/1000 -> 1056.885 | S10: =+P10-R10 -> 174.31201 | T10: =+IFERROR(HLOOKUP($B10,'[1]2월누계'!$D$6:$BN$259,16,),)/1000 -> -7.6073115 | U10: =+IFERROR(HLOOKUP($B10,'[2]2월누계'!$F$6:$CP$99,16,),)/1000 -> -154.20578 | V10: =+U10-T10 -> -146.59846 | W10: =+IFERROR(HLOOKUP($B10,'[3]2월누계'!$F$6:$CC$57,16,),)/1000 -> -120.97256 | X10: =+U10-W10 -> -33.233214 | Y10: =+[8]김포!$Q$85 -> 97241.4 | Z10: =+[8]김포!$R$85 -> 96287.157 | AA10: =+[9]김포!$Q$85 -> 94719.931 | AB10: =+[8]김포!$Q$89 -> 77127.928 | AC10: =+[8]김포!$R$89 -> 82811.251 | AD10: =+[9]김포!$Q$89 -> 78222.841 | AE10: =+Y10-AB10 -> 20113.472 | AF10: =+Z10-AC10 -> 13475.905 | AG10: =+AA10-AD10 -> 16497.091
B11: 부산 | G11: =+I11 -> 부산 | I11: 부산 | J11: =+IFERROR(HLOOKUP($B11,'[1]2월누계'!$D$6:$BN$259,2,),)/1000 -> 36 | K11: =+IFERROR(HLOOKUP($B11,'[2]2월누계'!$F$6:$CP$99,2,),)/1000 -> 30.628 | L11: =+K11-J11 -> -5.372 | M11: =+IFERROR(HLOOKUP($B11,'[3]2월누계'!$F$6:$CC$57,2,),)/1000 -> 40.465 | N11: =+K11-M11 -> -9.837 | O11: =+IFERROR(HLOOKUP($B11,'[1]2월누계'!$D$6:$BN$259,3,),)/1000 -> 3877.2024 | P11: =+IFERROR(HLOOKUP($B11,'[2]2월누계'!$F$6:$CP$99,3,),)/1000 -> 3240.3391 | Q11: =+P11-O11 -> -636.86335 | R11: =+IFERROR(HLOOKUP($B11,'[3]2월누계'!$F$6:$CC$57,3,),)/1000 -> 4393.8048 | S11: =+P11-R11 -> -1153.4657 | T11: =+IFERROR(HLOOKUP($B11,'[1]2월누계'!$D$6:$BN$259,16,),)/1000 -> 263.60494 | U11: =+IFERROR(HLOOKUP($B11,'[2]2월누계'!$F$6:$CP$99,16,),)/1000 -> 160.24382 | V11: =+U11-T11 -> -103.36113 | W11: =+IFERROR(HLOOKUP($B11,'[3]2월누계'!$F$6:$CC$57,16,),)/1000 -> 500.25937 | X11: =+U11-W11 -> -340.01556 | Y11: =+[8]부산!$Q$85 -> 107700.25 | Z11: =+[8]부산!$R$85 -> 105796.63 | AA11: =+[9]부산!$Q$85 -> 108582.84 | AB11: =+[8]부산!$Q$89 -> 84823.952 | AC11: =+[8]부산!$R$89 -> 84537.426 | AD11: =+[9]부산!$Q$89 -> 84409.345 | AE11: =+Y11-AB11 -> 22876.301 | AF11: =+Z11-AC11 -> 21259.201 | AG11: =+AA11-AD11 -> 24173.498
B12: 서부산 | G12: =+I12 -> 서부산 | I12: 서부산 | J12: =+IFERROR(HLOOKUP($B12,'[1]2월누계'!$D$6:$BN$259,2,),)/1000 -> 34 | K12: =+IFERROR(HLOOKUP($B12,'[2]2월누계'!$F$6:$CP$99,2,),)/1000 -> 30.296 | L12: =+K12-J12 -> -3.704 | M12: =+IFERROR(HLOOKUP($B12,'[3]2월누계'!$F$6:$CC$57,2,),)/1000 -> 40.751 | N12: =+K12-M12 -> -10.455 | O12: =+IFERROR(HLOOKUP($B12,'[1]2월누계'!$D$6:$BN$259,3,),)/1000 -> 3376.2099 | P12: =+IFERROR(HLOOKUP($B12,'[2]2월누계'!$F$6:$CP$99,3,),)/1000 -> 2920.6094 | Q12: =+P12-O12 -> -455.60053 | R12: =+IFERROR(HLOOKUP($B12,'[3]2월누계'!$F$6:$CC$57,3,),)/1000 -> 4067.8206 | S12: =+P12-R12 -> -1147.2112 | T12: =+IFERROR(HLOOKUP($B12,'[1]2월누계'!$D$6:$BN$259,16,),)/1000 -> 209.09506 | U12: =+IFERROR(HLOOKUP($B12,'[2]2월누계'!$F$6:$CP$99,16,),)/1000 -> 112.66153 | V12: =+U12-T12 -> -96.433529 | W12: =+IFERROR(HLOOKUP($B12,'[3]2월누계'!$F$6:$CC$57,16,),)/1000 -> 316.896 | X12: =+U12-W12 -> -204.23447 | Y12: =+[8]서부산!$Q$85 -> 99300.169 | Z12: =+[8]서부산!$R$85 -> 96402.476 | AA12: =+[9]서부산!$Q$85 -> 99821.369 | AB12: =+[8]서부산!$Q$89 -> 78874.154 | AC12: =+[8]서부산!$R$89 -> 77993.925 | AD12: =+[9]서부산!$Q$89 -> 80640.022 | AE12: =+Y12-AB12 -> 20426.015 | AF12: =+Z12-AC12 -> 18408.55 | AG12: =+AA12-AD12 -> 19181.347
B13: 김해 | G13: =+I13 -> 김해 | I13: 김해 | J13: =+IFERROR(HLOOKUP($B13,'[1]2월누계'!$D$6:$BN$259,2,),)/1000 -> 24 | K13: =+IFERROR(HLOOKUP($B13,'[2]2월누계'!$F$6:$CP$99,2,),)/1000 -> 9.797 | L13: =+K13-J13 -> -14.203 | M13: =+IFERROR(HLOOKUP($B13,'[3]2월누계'!$F$6:$CC$57,2,),)/1000 -> 20.978 | N13: =+K13-M13 -> -11.181 | O13: =+IFERROR(HLOOKUP($B13,'[1]2월누계'!$D$6:$BN$259,3,),)/1000 -> 2311.2066 | P13: =+IFERROR(HLOOKUP($B13,'[2]2월누계'!$F$6:$CP$99,3,),)/1000 -> 946.1099 | Q13: =+P13-O13 -> -1365.0967 | R13: =+IFERROR(HLOOKUP($B13,'[3]2월누계'!$F$6:$CC$57,3,),)/1000 -> 2115.8959 | S13: =+P13-R13 -> -1169.786 | T13: =+IFERROR(HLOOKUP($B13,'[1]2월누계'!$D$6:$BN$259,16,),)/1000 -> 142.75029 | U13: =+IFERROR(HLOOKUP($B13,'[2]2월누계'!$F$6:$CP$99,16,),)/1000 -> -137.97555 | V13: =+U13-T13 -> -280.72584 | W13: =+IFERROR(HLOOKUP($B13,'[3]2월누계'!$F$6:$CC$57,16,),)/1000 -> 99.251055 | X13: =+U13-W13 -> -237.2266 | Y13: =+[8]김해!$Q$85 -> 96300.275 | Z13: =+[8]김해!$R$85 -> 96617.046 | AA13: =+[9]김해!$Q$85 -> 100865.57 | AB13: =+[8]김해!$Q$89 -> 77158.582 | AC13: =+[8]김해!$R$89 -> 79590.536 | AD13: =+[9]김해!$Q$89 -> 81962.048 | AE13: =+Y13-AB13 -> 19141.693 | AF13: =+Z13-AC13 -> 17026.51 | AG13: =+AA13-AD13 -> 18903.52
B14: 정관 | G14: =+I14 -> 정관 | I14: 정관 | J14: =+IFERROR(HLOOKUP($B14,'[1]2월누계'!$D$6:$BN$259,2,),)/1000 -> 36 | K14: =+IFERROR(HLOOKUP($B14,'[2]2월누계'!$F$6:$CP$99,2,),)/1000 -> 34.533 | L14: =+K14-J14 -> -1.467 | M14: =+IFERROR(HLOOKUP($B14,'[3]2월누계'!$F$6:$CC$57,2,),)/1000 -> 36.4955 | N14: =+K14-M14 -> -1.9625 | O14: =+IFERROR(HLOOKUP($B14,'[1]2월누계'!$D$6:$BN$259,3,),)/1000 -> 3671.9965 | P14: =+IFERROR(HLOOKUP($B14,'[2]2월누계'!$F$6:$CP$99,3,),)/1000 -> 3573.7502 | Q14: =+P14-O14 -> -98.24633 | R14: =+IFERROR(HLOOKUP($B14,'[3]2월누계'!$F$6:$CC$57,3,),)/1000 -> 3711.543 | S14: =+P14-R14 -> -137.79285 | T14: =+IFERROR(HLOOKUP($B14,'[1]2월누계'!$D$6:$BN$259,16,),)/1000 -> 266.22006 | U14: =+IFERROR(HLOOKUP($B14,'[2]2월누계'!$F$6:$CP$99,16,),)/1000 -> 245.21989 | V14: =+U14-T14 -> -21.000173 | W14: =+IFERROR(HLOOKUP($B14,'[3]2월누계'!$F$6:$CC$57,16,),)/1000 -> 291.83419 | X14: =+U14-W14 -> -46.614301 | Y14: =+[8]정관!$Q$85 -> 101999.68 | Z14: =+[8]정관!$R$85 -> 103487.97 | AA14: =+[9]정관!$Q$85 -> 101698.65 | AB14: =+[8]정관!$Q$89 -> 81923.101 | AC14: =+[8]정관!$R$89 -> 85181.27 | AD14: =+[9]정관!$Q$89 -> 82925.775 | AE14: =+Y14-AB14 -> 20076.582 | AF14: =+Z14-AC14 -> 18306.704 | AG14: =+AA14-AD14 -> 18772.874
