Workbook

Sheet 파워BI용
B2: 구분 | D2: 계획 | E2: 실적 | F2: 차이 | G2: 전년 | H2: 차이 | J2: 캡쳐도구 사용 → PNG 저장 → 파워BI 삽입 → 이미지
B3: 판매량 | C3: 레미콘 | D3: =+'사업장별(누계)_건자재제외'!$J$27 -> 2438.5 | E3: =+'사업장별(누계)_건자재제외'!$K$27 -> 2103.4088 | F3: =+E3/D3 -> 0.86258307 | G3: =+'사업장별(누계)_건자재제외'!$M$27 -> 2528.7135 | H3: =+E3/G3 -> 0.83180986
C4: 골재 | D4: =+'사업장별(누계)_건자재제외'!$J$31 -> 863.24609 | E4: =+'사업장별(누계)_건자재제외'!$K$31 -> 583.443 | F4: =+E4/D4 -> 0.675871 | G4: =+'사업장별(누계)_건자재제외'!$M$31 -> 654.215 | H4: =+E4/G4 -> 0.8918215
B5: 매출액 | C5: 레미콘 | D5: =+'사업장별(누계)_건자재제외'!$O$27 -> 245750.61 | E5: =+'사업장별(누계)_건자재제외'!$P$27 -> 206858.46 | F5: =+E5-D5 -> -38892.152 | G5: =+'사업장별(누계)_건자재제외'!$R$27 -> 255794.31 | H5: =+E5-G5 -> -48935.848
C6: 골재 | D6: =+'사업장별(누계)_건자재제외'!$O$31 -> 15946.555 | E6: =+'사업장별(누계)_건자재제외'!$P$31 -> 12077.289 | F6: =+E6-D6 -> -3869.2662 | G6: =+'사업장별(누계)'!$R$32 -> 13129.786 | H6: =+E6-G6 -> -1052.4966
C7: 기타 | D7: =+D8-D5-D6 -> 1356.4735 | E7: =+E8-E5-E6 -> 1185.8852 | F7: =+E7-D7 -> -170.58829 | G7: =+G8-G5-G6 -> 1489.8753 | H7: =+E7-G7 -> -303.99013
C8: 계 | D8: =+'사업장별(누계)_건자재제외'!$O$42 -> 263053.64 | E8: =+'사업장별(누계)_건자재제외'!$P$42 -> 220121.64 | F8: =+E8-D8 -> -42932.007 | G8: =+'사업장별(누계)_건자재제외'!$R$42 -> 270413.97 | H8: =+E8-G8 -> -50292.334
B9: 영업이익 | C9: 레미콘 | D9: =+('사업장별(누계)_건자재제외'!$T$27+'사업장별(누계)_건자재제외'!$T$34) -> 8603.7624 | E9: =+'사업장별(누계)_건자재제외'!$U$27+'사업장별(누계)_건자재제외'!$U$34 -> -3531.9282 | F9: =+E9-D9 -> -12135.691 | G9: =+'사업장별(누계)_건자재제외'!$W$27+'사업장별(누계)_건자재제외'!$W$34 -> 15240.027 | H9: =+E9-G9 -> -18771.955
C10: (%) | D10: =+D9/D5 -> 0.035010136 | E10: =+E9/E5 -> -0.01707413 | F10: =+E10-D10 -> -0.052084266 | G10: =+G9/G5 -> 0.059579225 | H10: =+E10-G10 -> -0.076653355
C11: 골재 | D11: =+'사업장별(누계)_건자재제외'!$T$31 -> 1514.359 | E11: =+'사업장별(누계)_건자재제외'!$U$31 -> -703.90962 | F11: =+E11-D11 -> -2218.2686 | G11: =+'사업장별(누계)_건자재제외'!$W$31 -> 145.9626 | H11: =+E11-G11 -> -849.87222
C12: 기타 | D12: =+D13-D9-D11 -> 225.70208 | E12: =+E13-E9-E11 -> -1434.6246 | F12: =+E12-D12 -> -1660.3267 | G12: =+G13-G9-G11 -> 547.37753 | H12: =+E12-G12 -> -1982.0021
C13: 계 | D13: =+'사업장별(누계)_건자재제외'!$T$42 -> 10343.823 | E13: =+'사업장별(누계)_건자재제외'!$U$42 -> -5670.4625 | F13: =+E13-D13 -> -16014.286 | G13: =+'사업장별(누계)_건자재제외'!$W$42 -> 15933.367 | H13: =+E13-G13 -> -21603.829
D14: =+D13/D8 -> 0.039322107 | E14: =+E13/E8 -> -0.025760587 | F14: =+E14-D14 -> -0.065082694 | G14: =+G13/G8 -> 0.058922129 | H14: =+E14-G14 -> -0.084682715

Sheet 표지
A6: 2025년 9월 마감 손익
A24: 건재사업본부

Sheet 손익총괄
C3: □ 건재사업본부 손익실적(2025-09)
X4: [단위 : 천㎥, 톤, 원/㎥, 원/톤, 백만원]
C5: 구분 | E5: 9월 | J5: 9월 누계 | P5: 9월 주요지표
E6: 계획 | F6: 실적 | G6: 계획대비 | H6: 전년 | I6: 전년대비 | J6: 계획 | K6: 실적 | L6: 계획대비 | M6: 전년 | N6: 전년대비
C7: 물량 | D7: 레미콘 | E7: =+'[1]9월'!$Z$7/1000 -> 300 | F7: =+'[2]9월'!$Z$7/1000 -> 250.341 | G7: =+F7-E7 -> -49.659 | H7: =+'[3]9월'!$Z$7/1000 -> 236.2843 | I7: =+F7-H7 -> 14.0567 | J7: =+'[1]9월누계'!$Z$7/1000 -> 2438.5 | K7: =+'[2]9월누계'!$Z$7/1000 -> 2103.4088 | L7: =+K7-J7 -> -335.09118 | M7: =+'[3]9월누계'!$Z$7/1000 -> 2528.7135 | N7: =+K7-M7 -> -425.30468 | Q7: □ 레미콘
D8: 철강재 | E8: =+'[1]9월'!$AA$7 -> 12600 | F8: =+'[2]9월'!$AO$7 -> 7943.905 | G8: =+F8-E8 -> -4656.095 | H8: =+'[3]9월'!$AO$7 -> 7354.628 | I8: =+F8-H8 -> 589.277 | J8: =+'[1]9월누계'!$AA$7 -> 100900 | K8: =+'[2]9월누계'!$AO$7 -> 84893.855 | L8: =+K8-J8 -> -16006.145 | M8: =+'[3]9월누계'!$AO$7 -> 77967.344 | N8: =+K8-M8 -> 6926.511 | Q8: 구분 | S8: 계획 | T8: 실적 | U8: 계획대비 | V8: 전년 | W8: 전년대비
D9: 골재 | E9: =+'[1]9월'!$AE$7/1000 -> 104.99566 | F9: =+'[2]9월'!$AN$7/1000 -> 74.273 | G9: =+F9-E9 -> -30.722665 | H9: =+'[3]9월'!$AN$7/1000 -> 46.951 | I9: =+F9-H9 -> 27.322 | J9: =+'[1]9월누계'!$AE$7/1000 -> 863.24609 | K9: =+'[2]9월누계'!$AN$7/1000 -> 583.443 | L9: =+K9-J9 -> -279.80309 | M9: =+'[3]9월누계'!$AN$7/1000 -> 654.215 | N9: =+K9-M9 -> -70.772 | Q9: 물량 | R9: 수도권 | S9: =+[4]수도권!$T$5/1000 -> 113 | T9: =+[4]수도권!$U$5/1000 -> 88.903 | U9: =+T9-S9 -> -24.097 | V9: =+[5]수도권!$T$5/1000 -> 75.6348 | W9: =+T9-V9 -> 13.2682
C10: 매출 | D10: 레미콘 | E10: =+'[1]9월'!$Z$8/1000 -> 30570.517 | F10: =+'[2]9월'!$Z$8/1000 -> 24527.918 | G10: =+F10-E10 -> -6042.5996 | H10: =+'[3]9월'!$Z$8/1000 -> 23619.373 | I10: =+F10-H10 -> 908.54505 | J10: =+'[1]9월누계'!$Z$8/1000 -> 245750.61 | K10: =+'[2]9월누계'!$Z$8/1000 -> 206858.46 | L10: =+K10-J10 -> -38892.152 | M10: =+'[3]9월누계'!$Z$8/1000 -> 255794.31 | N10: =+K10-M10 -> -48935.848 | R10: 영남권 | S10: =+[4]영남권!$T$5/1000 -> 126 | T10: =+[4]영남권!$U$5/1000 -> 110.37 | U10: =+T10-S10 -> -15.63 | V10: =+[5]영남권!$T$5/1000 -> 111.844 | W10: =+T10-V10 -> -1.474
D11: 건자재 | E11: =+'[1]9월'!$AA$8/1000 -> 13712.919 | F11: =+'[2]9월'!$AO$8/1000 -> 7610.2078 | G11: =+F11-E11 -> -6102.7111 | H11: =+'[3]9월'!$AO$8/1000 -> 7720.8259 | I11: =+F11-H11 -> -110.61809 | J11: =+'[1]9월누계'!$AA$8/1000 -> 110204.91 | K11: =+'[2]9월누계'!$AO$8/1000 -> 76897.59 | L11: =+K11-J11 -> -33307.319 | M11: =+'[3]9월누계'!$AO$8/1000 -> 77932.391 | N11: =+K11-M11 -> -1034.8011 | R11: 중부권 | S11: =+[4]중부권!$T$5/1000 -> 61 | T11: =+[4]중부권!$U$5/1000 -> 51.068 | U11: =+T11-S11 -> -9.932 | V11: =+[5]중부권!$T$5/1000 -> 48.8055 | W11: =+T11-V11 -> 2.2625
D12: 골재 | E12: =+'[1]9월'!$AE$8/1000 -> 1923.4901 | F12: =+'[2]9월'!$AN$8/1000 -> 1434.7645 | G12: =+F12-E12 -> -488.72558 | H12: =+'[3]9월'!$AN$8/1000 -> 885.7455 | I12: =+F12-H12 -> 549.019 | J12: =+'[1]9월누계'!$AE$8/1000 -> 15946.555 | K12: =+'[2]9월누계'!$AN$8/1000 -> 12077.289 | L12: =+K12-J12 -> -3869.2662 | M12: =+'[3]9월누계'!$AN$8/1000 -> 13129.786 | N12: =+K12-M12 -> -1052.4966 | Q12: 계 | S12: =SUM(S9:S11) -> 300 | T12: =SUM(T9:T11) -> 250.341 | U12: =+T12-S12 -> -49.659 | V12: =SUM(V9:V11) -> 236.2843 | W12: =+T12-V12 -> 14.0567
D13: 기타 | E13: =+'[1]9월'!$E$8/1000-E10-E11-E12 -> 142.52817 | F13: =+'[2]9월'!$F$8/1000-F10-F11-F12 -> 118.84472 | G13: =+F13-E13 -> -23.683442 | H13: =+'[3]9월'!$F$8/1000-H10-H11-H12 -> 165.97438 | I13: =+F13-H13 -> -47.129656 | J13: =+'[1]9월누계'!$E$8/1000-J10-J11-J12 -> 1356.4735 | K13: =+'[2]9월누계'!$F$8/1000-K10-K11-K12 -> 1185.8852 | L13: =+K13-J13 -> -170.58828 | M13: =+'[3]9월누계'!$F$8/1000-M10-M11-M12 -> 1489.8753 | N13: =+K13-M13 -> -303.99013 | Q13: 판매단가 | R13: 수도권 | S13: =+[4]수도권!$T$61 -> 100156.13 | T13: =+[4]수도권!$U$61 -> 95819.566 | U13: =+T13-S13 -> -4336.5677 | V13: =+[5]수도권!$Q$85 -> 97749.491 | W13: =+T13-V13 -> -1929.9258
C14: 계 | E14: =SUM(E10:E13) -> 46349.454 | F14: =SUM(F10:F13) -> 33691.735 | G14: =+F14-E14 -> -12657.72 | H14: =SUM(H10:H13) -> 32391.918 | I14: =+F14-H14 -> 1299.8163 | J14: =SUM(J10:J13) -> 373258.55 | K14: =SUM(K10:K13) -> 297019.23 | L14: =+K14-J14 -> -76239.326 | M14: =SUM(M10:M13) -> 348346.36 | N14: =+K14-M14 -> -51327.135 | R14: 영남권 | S14: =+[4]영남권!$T$61 -> 100736.67 | T14: =+[4]영남권!$U$61 -> 98462.668 | U14: =+T14-S14 -> -2274.0062 | V14: =+[5]영남권!$Q$85 -> 99624.762 | W14: =+T14-V14 -> -1162.0932
C15: 매출원가 | D15: 레미콘 | E15: =+('[1]9월'!$Z$10+'[1]9월'!$Z$19)/1000 -> 26289.919 | F15: =+('[2]9월'!$Z$10+'[2]9월'!$Z$19)/1000 -> 22729.856 | G15: =+F15-E15 -> -3560.063 | H15: =+('[3]9월'!$Z$10+'[3]9월'!$Z$19)/1000 -> 21000.008 | I15: =+F15-H15 -> 1729.848 | J15: =+('[1]9월누계'!$Z$10+'[1]9월누계'!$Z$19)/1000 -> 217121.59 | K15: =+('[2]9월누계'!$Z$10+'[2]9월누계'!$Z$19)/1000 -> 190033.9 | L15: =+K15-J15 -> -27087.694 | M15: =+('[3]9월누계'!$Z$10+'[3]9월누계'!$Z$19)/1000 -> 221505 | N15: =+K15-M15 -> -31471.101 | R15: 중부권 | S15: =+[4]중부권!$T$61 -> 107541.86 | T15: =+[4]중부권!$U$61 -> 100727.81 | U15: =+T15-S15 -> -6814.0439 | V15: =+[5]중부권!$Q$85 -> 104305.46 | W15: =+T15-V15 -> -3577.6451
D16: 건자재 | E16: =+('[1]9월'!$AA$10+'[1]9월'!$AA$19)/1000 -> 13342.736 | F16: =+('[2]9월'!$AO$10+'[2]9월'!$AO$19)/1000 -> 7426.4884 | G16: =+F16-E16 -> -5916.2479 | H16: =+('[3]9월'!$AO$10+'[3]9월'!$AO$19)/1000 -> 7575.1952 | I16: =+F16-H16 -> -148.70685 | J16: =+('[1]9월누계'!$AA$10+'[1]9월누계'!$AA$19)/1000 -> 107229.38 | K16: =+('[2]9월누계'!$AO$10+'[2]9월누계'!$AO$19)/1000 -> 75591.089 | L16: =+K16-J16 -> -31638.293 | M16: =+('[3]9월누계'!$AO$10+'[3]9월누계'!$AO$19)/1000 -> 76231.984 | N16: =+K16-M16 -> -640.89483 | Q16: 계 | S16: =+[4]합계!$T$61 -> 101901.72 | T16: =+[4]합계!$U$61 -> 97987.042 | U16: =+T16-S16 -> -3914.6823 | V16: =+[5]합계!$Q$85 -> 99989.728 | W16: =+T16-V16 -> -2002.6863
D17: 골재 | E17: =+('[1]9월'!$AE$10+'[1]9월'!$AE$19)/1000 -> 1654.1043 | F17: =+('[2]9월'!$AN$10+'[2]9월'!$AN$19)/1000 -> 1368.6693 | G17: =+F17-E17 -> -285.43501 | H17: =+('[3]9월'!$AN$10+'[3]9월'!$AN$19)/1000 -> 1111.2439 | I17: =+F17-H17 -> 257.42532 | J17: =+('[1]9월누계'!$AE$10+'[1]9월누계'!$AE$19)/1000 -> 13997.065 | K17: =+('[2]9월누계'!$AN$10+'[2]9월누계'!$AN$19)/1000 -> 12347.722 | L17: =+K17-J17 -> -1649.3434 | M17: =+('[3]9월누계'!$AN$10+'[3]9월누계'!$AN$19)/1000 -> 12454.683 | N17: =+K17-M17 -> -106.96128 | Q17: 공헌이익 | R17: 수도권 | S17: =+[4]수도권!$Q$90 -> 19270.25 | T17: =+[4]수도권!$R$90 -> 13424.303 | U17: =+T17-S17 -> -5845.9471 | V17: =+[5]수도권!$Q$90 -> 18269.6 | W17: =+T17-V17 -> -4845.2972
D18: 기타 | E18: =+('[1]9월'!$E$10+'[1]9월'!$E$19)/1000-E15-E16-E17 -> 52.588339 | F18: =+('[2]9월'!$F$10+'[2]9월'!$F$19)/1000-F15-F16-F17 -> 14.196039 | G18: =+F18-E18 -> -38.3923 | H18: =+('[3]9월'!$F$10+'[3]9월'!$F$19)/1000-H15-H16-H17 -> -238.70688 | I18: =+F18-H18 -> 252.90292 | J18: =+('[1]9월누계'!$E$10+'[1]9월누계'!$E$19)/1000-J15-J16-J17 -> 541.24816 | K18: =+('[2]9월누계'!$F$10+'[2]9월누계'!$F$19)/1000-K15-K16-K17 -> 459.4009 | L18: =+K18-J18 -> -81.847259 | M18: =+('[3]9월누계'!$F$10+'[3]9월누계'!$F$19)/1000-M15-M16-M17 -> -109.09169 | N18: =+K18-M18 -> 568.49259 | R18: 영남권 | S18: =+[4]영남권!$Q$90 -> 21855.367 | T18: =+[4]영남권!$R$90 -> 19124.76 | U18: =+T18-S18 -> -2730.6063 | V18: =+[5]영남권!$Q$90 -> 22140.925 | W18: =+T18-V18 -> -3016.1645
C19: 계 | E19: =SUM(E15:E18) -> 41339.348 | F19: =SUM(F15:F18) -> 31539.21 | G19: =+F19-E19 -> -9800.1381 | H19: =SUM(H15:H18) -> 29447.741 | I19: =+F19-H19 -> 2091.4694 | J19: =SUM(J15:J18) -> 338889.29 | K19: =SUM(K15:K18) -> 278432.11 | L19: =+K19-J19 -> -60457.177 | M19: =SUM(M15:M18) -> 310082.57 | N19: =+K19-M19 -> -31650.464 | R19: 중부권 | S19: =+[4]중부권!$Q$90 -> 29751.161 | T19: =+[4]중부권!$R$90 -> 21863.231 | U19: =+T19-S19 -> -7887.9293 | V19: =+[5]중부권!$Q$90 -> 29079.27 | W19: =+T19-V19 -> -7216.039
C20: 매출이익 | D20: 레미콘 | E20: =+E10-E15 -> 4280.5979 | F20: =+F10-F15 -> 1798.0613 | G20: =+F20-E20 -> -2482.5366 | H20: =+H10-H15 -> 2619.3642 | I20: =+F20-H20 -> -821.30294 | J20: =+J10-J15 -> 28629.024 | K20: =+K10-K15 -> 16824.565 | L20: =+K20-J20 -> -11804.459 | M20: =+M10-M15 -> 34289.312 | N20: =+K20-M20 -> -17464.747 | Q20: 계 | S20: =+[4]합계!$Q$90 -> 22487.117 | T20: =+[4]합계!$R$90 -> 17661.851 | U20: =+T20-S20 -> -4825.2668 | V20: =+[5]합계!$Q$90 -> 22332.224 | W20: =+T20-V20 -> -4670.3734
D21: 건자재 | E21: =+E11-E16 -> 370.18261 | F21: =+F11-F16 -> 183.71938 | G21: =+F21-E21 -> -186.46323 | H21: =+H11-H16 -> 145.63062 | I21: =+F21-H21 -> 38.088761 | J21: =+J11-J16 -> 2975.5269 | K21: =+K11-K16 -> 1306.5007 | L21: =+K21-J21 -> -1669.0263 | M21: =+M11-M16 -> 1700.4069 | N21: =+K21-M21 -> -393.90622 | Q21: □ 건자재
D22: 골재 | E22: =+E12-E17 -> 269.38582 | F22: =+F12-F17 -> 66.095246 | G22: =+F22-E22 -> -203.29058 | H22: =+H12-H17 -> -225.49843 | I22: =+F22-H22 -> 291.59368 | J22: =+J12-J17 -> 1949.4901 | K22: =+K12-K17 -> -270.43262 | L22: =+K22-J22 -> -2219.9228 | M22: =+M12-M17 -> 675.10268 | N22: =+K22-M22 -> -945.5353 | Q22: 구분 | S22: 계획 | T22: 실적 | U22: 계획대비 | V22: 전년 | W22: 전년대비
D23: 기타 | E23: =+E13-E18 -> 89.939828 | F23: =+F13-F18 -> 104.64869 | G23: =+F23-E23 -> 14.708858 | H23: =+H13-H18 -> 404.68127 | I23: =+F23-H23 -> -300.03258 | J23: =+J13-J18 -> 815.22534 | K23: =+K13-K18 -> 726.48431 | L23: =+K23-J23 -> -88.741026 | M23: =+M13-M18 -> 1598.967 | N23: =+K23-M23 -> -872.48272 | Q23: 철강재 판매단가 | S23: =+'[6]9월'!$F$10 -> 873809.52 | T23: =+'[6]9월'!$G$10 -> 791593.63 | U23: =+T23-S23 -> -82215.89 | V23: =+'[7]9월'!$G$10 -> 879572.43 | W23: =+T23-V23 -> -87978.795
C24: 계 | E24: =SUM(E20:E23) -> 5010.1062 | F24: =SUM(F20:F23) -> 2152.5246 | G24: =+F24-E24 -> -2857.5816 | H24: =SUM(H20:H23) -> 2944.1777 | I24: =+F24-H24 -> -791.65308 | J24: =SUM(J20:J23) -> 34369.266 | K24: =SUM(K20:K23) -> 18587.117 | L24: =+K24-J24 -> -15782.149 | M24: =SUM(M20:M23) -> 38263.789 | N24: =+K24-M24 -> -19676.671 | Q24: 철강재 마진률 | S24: =+'[6]9월'!$F$15 -> 0.024058583 | T24: =+'[6]9월'!$G$15 -> 0.024112163 | U24: =+T24-S24 -> 5.3580105e-05 | V24: =+'[6]9월'!$G$15 -> 0.024112163 | W24: =+T24-V24 -> 0
C25: 판관비 | D25: 레미콘 | E25: =+('[1]9월'!$Z$13+'[1]9월'!$Z$20)/1000 -> 725.97045 | F25: =+('[2]9월'!$Z$13+'[2]9월'!$Z$20)/1000 -> 819.36919 | G25: =+F25-E25 -> 93.39874 | H25: =+('[3]9월'!$Z$13+'[3]9월'!$Z$20)/1000 -> 886.62886 | I25: =+F25-H25 -> -67.259668 | J25: =+('[1]9월누계'!$Z$13+'[1]9월누계'!$Z$20)/1000 -> 6091.2777 | K25: =+('[2]9월누계'!$Z$13+'[2]9월누계'!$Z$20)/1000 -> 6184.0913 | L25: =+K25-J25 -> 92.81359 | M25: =+('[3]9월누계'!$Z$13+'[3]9월누계'!$Z$20)/1000 -> 6157.4466 | N25: =+K25-M25 -> 26.644682 | Q25: □ 골재
D26: 건자재 | E26: =+('[1]9월'!$AA$13+'[1]9월'!$AA$20)/1000 -> 145.83719 | F26: =+('[2]9월'!$AO$13+'[2]9월'!$AO$20)/1000 -> 170.04674 | G26: =+F26-E26 -> 24.20955 | H26: =+('[3]9월'!$AO$13+'[3]9월'!$AO$20)/1000 -> 161.20982 | I26: =+F26-H26 -> 8.836919 | J26: =+('[1]9월누계'!$AA$13+'[1]9월누계'!$AA$20)/1000 -> 1160.3548 | K26: =+('[2]9월누계'!$AO$13+'[2]9월누계'!$AO$20)/1000 -> 1346.164 | L26: =+K26-J26 -> 185.80919 | M26: =+('[3]9월누계'!$AO$13+'[3]9월누계'!$AO$20)/1000 -> 1260.9085 | N26: =+K26-M26 -> 85.255496 | Q26: 구분 | S26: 계획 | T26: 실적 | U26: 계획대비 | V26: 전년 | W26: 전년대비
D27: 골재 | E27: =+('[1]9월'!$AE$13+'[1]9월'!$AE$20+'[1]9월'!$AE$22)/1000 -> 50.756076 | F27: =+('[2]9월'!$AN$13+'[2]9월'!$AN$20+'[2]9월'!$AN$22)/1000 -> 56.892355 | G27: =+F27-E27 -> 6.1362789 | H27: =+('[3]9월'!$AN$13+'[3]9월'!$AN$20+'[3]9월'!$AN$22)/1000 -> 87.482063 | I27: =+F27-H27 -> -30.589708 | J27: =+('[1]9월누계'!$AE$13+'[1]9월누계'!$AE$20+'[1]9월누계'!$AE$22)/1000 -> 435.13115 | K27: =+('[2]9월누계'!$AN$13+'[2]9월누계'!$AN$20+'[2]9월누계'!$AN$22)/1000 -> 433.477 | L27: =+K27-J27 -> -1.6541447 | M27: =+('[3]9월누계'!$AN$13+'[3]9월누계'!$AN$20+'[3]9월누계'!$AN$22)/1000 -> 529.14008 | N27: =+K27-M27 -> -95.663083 | Q27: 판매량 | R27: 자가 | S27: =+[8]원가손익!$W$10+[9]원가손익!$W$13+[10]손익!$F$10 -> 59995.665 | T27: =+[8]원가손익!$X$10+[9]원가손익!$X$13+[10]손익!$G$10 -> 48433 | U27: =+T27-S27 -> -11562.665 | V27: =+'[11]부산모래장(당월)'!$S$85 -> 32178 | W27: =+T27-V27 -> 16255
D28: 기타 | E28: =+('[1]9월'!$E$13+'[1]9월'!$E$20)/1000-E25-E26-E27+('[1]9월'!$E$22/1000) -> 1316.8819 | F28: =+('[2]9월'!$F$13+'[2]9월'!$F$20)/1000-F25-F26-F27+'[2]9월'!$F$22/1000 -> 1809.6135 | G28: =+F28-E28 -> 492.73155 | H28: =+('[3]9월'!$F$13+'[3]9월'!$F$20)/1000-H25-H26-H27+'[3]9월'!$F$22/1000 -> 979.18979 | I28: =+F28-H28 -> 830.42366 | J28: =+('[1]9월누계'!$E$13+'[1]9월누계'!$E$20)/1000-J25-J26-J27+('[1]9월누계'!$E$22/1000) -> 14523.507 | K28: =+('[2]9월누계'!$F$13+'[2]9월누계'!$F$20)/1000-K25-K26-K27+'[2]9월누계'!$F$22/1000 -> 16333.511 | L28: =+K28-J28 -> 1810.0039 | M28: =+('[3]9월누계'!$F$13+'[3]9월누계'!$F$20)/1000-M25-M26-M27+'[3]9월누계'!$F$22/1000 -> 13943.428 | N28: =+K28-M28 -> 2390.0826 | R28: 외판 | S28: =+[8]원가손익!$W$14+[9]원가손익!$W$15+[10]손익!$F$12 -> 45000 | T28: =+[8]원가손익!$X$14+[9]원가손익!$X$15+[10]손익!$G$12 -> 25840 | U28: =+T28-S28 -> -19160 | V28: =+'[11]부산모래장(당월)'!$S$86 -> 14773 | W28: =+T28-V28 -> 11067
C29: 계 | E29: =SUM(E25:E28) -> 2239.4456 | F29: =SUM(F25:F28) -> 2855.9217 | G29: =+F29-E29 -> 616.47612 | H29: =SUM(H25:H28) -> 2114.5105 | I29: =+F29-H29 -> 741.4112 | J29: =SUM(J25:J28) -> 22210.271 | K29: =SUM(K25:K28) -> 24297.243 | L29: =+K29-J29 -> 2086.9725 | M29: =SUM(M25:M28) -> 21890.923 | N29: =+K29-M29 -> 2406.3197 | Q29: 합 계 | S29: =SUM(S27:S28) -> 104995.66 | T29: =SUM(T27:T28) -> 74273 | U29: =+T29-S29 -> -30722.665 | V29: =SUM(V27:V28) -> 46951 | W29: =+T29-V29 -> 27322
C30: 영업이익 | D30: 레미콘 | E30: =+E20-E25 -> 3554.6275 | F30: =+F20-F25 -> 978.69212 | G30: =+F30-E30 -> -2575.9354 | H30: =+H20-H25 -> 1732.7354 | I30: =+F30-H30 -> -754.04327 | J30: =+J20-J25 -> 22537.746 | K30: =+K20-K25 -> 10640.474 | L30: =+K30-J30 -> -11897.272 | M30: =+M20-M25 -> 28131.865 | N30: =+K30-M30 -> -17491.392 | Q30: □ 기타내역(영업이익)
D31: % | E31: =+E30/E10 -> 0.11627633 | F31: =+F30/F10 -> 0.03990115 | G31: =+F31-E31 -> -0.076375178 | H31: =+H30/H10 -> 0.073360771 | I31: =+F31-H31 -> -0.033459621 | J31: =+J30/J10 -> 0.091709826 | K31: =+K30/K10 -> 0.051438426 | L31: =+K31-J31 -> -0.0402714 | M31: =+M30/M10 -> 0.10997846 | N31: =+K31-M31 -> -0.058540039 | Q31: 구분 | S31: 계획 | T31: 실적 | U31: 계획대비 | V31: 전년 | W31: 전년대비
D32: 건자재 | E32: =+E21-E26 -> 224.34542 | F32: =+F21-F26 -> 13.67264 | G32: =+F32-E32 -> -210.67278 | H32: =+H21-H26 -> -15.579202 | I32: =+F32-H32 -> 29.251842 | J32: =+J21-J26 -> 1815.1721 | K32: =+K21-K26 -> -39.663349 | L32: =+K32-J32 -> -1854.8354 | M32: =+M21-M26 -> 439.49837 | N32: =+K32-M32 -> -479.16172 | Q32: 레미콘임대 | S32: =+'사업장별(당월)'!T33 -> 51.473204 | T32: =+'사업장별(당월)'!U33 -> 25.88862 | U32: =+T32-S32 -> -25.584584 | V32: =+'사업장별(당월)'!W33 -> 76.004227 | W32: =+T32-V32 -> -50.115607
D33: 골재 | E33: =+E22-E27 -> 218.62975 | F33: =+F22-F27 -> 9.202891 | G33: =+F33-E33 -> -209.42686 | H33: =+H22-H27 -> -312.9805 | I33: =+F33-H33 -> 322.18339 | J33: =+J22-J27 -> 1514.359 | K33: =+K22-K27 -> -703.90962 | L33: =+K33-J33 -> -2218.2686 | M33: =+M22-M27 -> 145.9626 | N33: =+K33-M33 -> -849.87222 | Q33: 임대 | S33: =+'사업장별(당월)'!T34 -> 76.533944 | T33: =+'사업장별(당월)'!U34 -> 70.267687 | U33: =+T33-S33 -> -6.266257 | V33: =+'사업장별(당월)'!W34 -> 75.78999 | W33: =+T33-V33 -> -5.522303
D34: 기타 | E34: =+E23-E28 -> -1226.9421 | F34: =+F23-F28 -> -1704.9648 | G34: =+F34-E34 -> -478.02269 | H34: =+H23-H28 -> -574.50853 | I34: =+F34-H34 -> -1130.4562 | J34: =+J23-J28 -> -13708.282 | K34: =+K23-K28 -> -15607.026 | L34: =+K34-J34 -> -1898.7449 | M34: =+M23-M28 -> -12344.461 | N34: =+K34-M34 -> -3262.5653 | Q34: 공통비 | S34: =+'사업장별(당월)'!T35 -> -1279.5789 | T34: =+'사업장별(당월)'!U35 -> -1380.7743 | U34: =+T34-S34 -> -101.19543 | V34: =+'사업장별(당월)'!W35 -> -1368.6461 | W34: =+T34-V34 -> -12.128206
C35: 계 | E35: =SUM(E30,E32:E34) -> 2770.6606 | F35: =SUM(F30,F32:F34) -> -703.39712 | G35: =+F35-E35 -> -3474.0577 | H35: =SUM(H30,H32:H34) -> 829.66716 | I35: =+F35-H35 -> -1533.0643 | J35: =SUM(J30,J32:J34) -> 12158.996 | K35: =SUM(K30,K32:K34) -> -5710.1258 | L35: =+K35-J35 -> -17869.121 | M35: =SUM(M30,M32:M34) -> 16372.865 | N35: =+K35-M35 -> -22082.991 | Q35: 기타 | S35: =+S36-S32-S33-S34 -> -75.370363 | T35: =+T36-T32-T33-T34 -> -420.34679 | U35: =+T35-S35 -> -344.97642 | V35: =+V36-V32-V33-V34 -> 642.34334 | W35: =+T35-V35 -> -1062.6901
D36: % | E36: =+E35/E14 -> 0.059777631 | F36: =+F35/F14 -> -0.020877438 | G36: =+F36-E36 -> -0.080655069 | H36: =+H35/H14 -> 0.0256134 | I36: =+F36-H36 -> -0.046490838 | J36: =+J35/J14 -> 0.032575263 | K36: =+K35/K14 -> -0.019224768 | L36: =+K36-J36 -> -0.051800032 | M36: =+M35/M14 -> 0.047001683 | N36: =+K36-M36 -> -0.066226451 | Q36: 합계 | S36: =+'사업장별(당월)'!T41 -> -1226.9421 | T36: =+'사업장별(당월)'!U41 -> -1704.9648 | U36: =+T36-S36 -> -478.02269 | V36: =+'사업장별(당월)'!W41 -> -574.50853 | W36: =+T36-V36 -> -1130.4562
E38: =+'[1]9월'!$E$26/1000 -> 2770.6606 | F38: =+'[2]9월'!$F$26/1000 -> -703.39712 | H38: =+'[3]9월'!$F$26/1000 -> 829.66716 | J38: =+'[1]9월누계'!$E$26/1000 -> 12158.996 | K38: =+'[2]9월누계'!$F$26/1000 -> -5710.1258 | M38: =+'[3]9월누계'!$F$26/1000 -> 16372.865
E39: =+E35=E38 -> TRUE | F39: =+F35=F38 -> FALSE | H39: =+H35=H38 -> FALSE | J39: =+J35=J38 -> FALSE | K39: =+K35=K38 -> FALSE | M39: =+M35=M38 -> TRUE
E40: =+E35-E38 -> -4.5474735e-12 | F40: =+F35-F38 -> -2.8421709e-12 | H40: =+H35-H38 -> 3.4106051e-12 | J40: =+J35-J38 -> 0 | K40: =+K35-K38 -> 3.4560799e-11 | M40: =+M35-M38 -> 3.2741809e-11

Sheet 레미콘 영업이익
H3: □ 레미콘 영업이익(9월)
H5: 구분 | J5: 9월 | T5: 9월누계
J6: 영업이익(공통비 배부전) | O6: 영업이익(공통비 배부후) | T6: 영업이익(공통비 배부전) | Y6: 영업이익(공통비 배부전)
A7: 2024년 9월 마감 손익 | J7: 계획 | K7: 실적 | L7: 차이 | M7: 전년 | N7: 차이 | O7: 계획 | P7: 실적 | Q7: 차이 | R7: 전년 | S7: 차이 | T7: 계획 | U7: 실적 | V7: 차이 | W7: 전년 | X7: 차이 | Y7: 계획 | Z7: 실적 | AA7: 차이 | AB7: 전년 | AC7: 차이
B8: 안양 | H8: 레미콘 | I8: 안양 | J8: =+[4]안양!$H$86/1000 -> 524.41267 | K8: =+[4]안양!$I$86/1000 -> 252.5489 | L8: =+K8-J8 -> -271.86377 | M8: =+[5]안양!$H$86/1000 -> 202.0324 | N8: =+K8-M8 -> 50.516497 | O8: =+[4]안양!$H$92/1000 -> 351.89691 | P8: =+[4]안양!$I$92/1000 -> 80.499761 | Q8: =+P8-O8 -> -271.39715 | R8: =+[5]안양!$H$92/1000 -> 37.785195 | S8: =+P8-R8 -> 42.714566 | T8: =+[12]안양!$H$86/1000 -> 3111.4304 | U8: =+[12]안양!$I$86/1000 -> 1943.5608 | V8: =+U8-T8 -> -1167.8696 | W8: =+[13]안양!$H$86/1000 -> 3343.7299 | X8: =+U8-W8 -> -1400.1692 | Y8: =+[12]안양!$H$92/1000 -> 1184.3354 | Z8: =+[12]안양!$I$92/1000 -> 49.689828 | AA8: =+Z8-Y8 -> -1134.6455 | AB8: =+[13]안양!$H$92/1000 -> 1669.9229 | AC8: =+Z8-AB8 -> -1620.2331
B9: 인천 | H9: 직영 | I9: 인천 | J9: =+[4]인천!$H$86/1000 -> 387.6129 | K9: =+[4]인천!$I$86/1000 -> -66.326553 | L9: =+K9-J9 -> -453.93946 | M9: =+[5]인천!$H$86/1000 -> -68.39704 | N9: =+K9-M9 -> 2.070487 | O9: =+[4]인천!$H$92/1000 -> 250.07052 | P9: =+[4]인천!$I$92/1000 -> -225.62111 | Q9: =+P9-O9 -> -475.69162 | R9: =+[5]인천!$H$92/1000 -> -171.87698 | S9: =+P9-R9 -> -53.744132 | T9: =+[12]인천!$H$86/1000 -> 1248.016 | U9: =+[12]인천!$I$86/1000 -> 248.33137 | V9: =+U9-T9 -> -999.68461 | W9: =+[13]인천!$H$86/1000 -> 1598.468 | X9: =+U9-W9 -> -1350.1366 | Y9: =+[12]인천!$H$92/1000 -> -142.85933 | Z9: =+[12]인천!$I$92/1000 -> -1343.8872 | AA9: =+Z9-Y9 -> -1201.0279 | AB9: =+[13]인천!$H$92/1000 -> 388.52058 | AC9: =+Z9-AB9 -> -1732.4078
B10: 파주 | I10: 파주 | J10: =+[4]파주!$H$86/1000 -> 132.59526 | K10: =+[4]파주!$I$86/1000 -> -43.489316 | L10: =+K10-J10 -> -176.08458 | M10: =+[5]파주!$H$86/1000 -> 106.24983 | N10: =+K10-M10 -> -149.73915 | O10: =+[4]파주!$H$92/1000 -> 36.714278 | P10: =+[4]파주!$I$92/1000 -> -126.17362 | Q10: =+P10-O10 -> -162.8879 | R10: =+[5]파주!$H$92/1000 -> 2.33302 | S10: =+P10-R10 -> -128.50664 | T10: =+[12]파주!$H$86/1000 -> 924.82778 | U10: =+[12]파주!$I$86/1000 -> -343.23294 | V10: =+U10-T10 -> -1268.0607 | W10: =+[13]파주!$H$86/1000 -> 1620.52 | X10: =+U10-W10 -> -1963.7529 | Y10: =+[12]파주!$H$92/1000 -> -81.036471 | Z10: =+[12]파주!$I$92/1000 -> -1060.9175 | AA10: =+Z10-Y10 -> -979.88104 | AB10: =+[13]파주!$H$92/1000 -> 535.24932 | AC10: =+Z10-AB10 -> -1596.1668
B11: 김포 | I11: 김포 | J11: =+[4]김포!$H$86/1000 -> 110.62527 | K11: =+[4]김포!$I$86/1000 -> -79.489792 | L11: =+K11-J11 -> -190.11506 | M11: =+[5]김포!$H$86/1000 -> 29.041857 | N11: =+K11-M11 -> -108.53165 | O11: =+[4]김포!$H$92/1000 -> 47.502118 | P11: =+[4]김포!$I$92/1000 -> -131.54913 | Q11: =+P11-O11 -> -179.05124 | R11: =+[5]김포!$H$92/1000 -> -25.325467 | S11: =+P11-R11 -> -106.22366 | T11: =+[12]김포!$H$86/1000 -> 771.50592 | U11: =+[12]김포!$I$86/1000 -> -50.408565 | V11: =+U11-T11 -> -821.91449 | W11: =+[13]김포!$H$86/1000 -> 861.13719 | X11: =+U11-W11 -> -911.54576 | Y11: =+[12]김포!$H$92/1000 -> 108.72162 | Z11: =+[12]김포!$I$92/1000 -> -627.03788 | AA11: =+Z11-Y11 -> -735.75951 | AB11: =+[13]김포!$H$92/1000 -> 373.74908 | AC11: =+Z11-AB11 -> -1000.787
B12: 부산 | I12: 부산 | J12: =+[4]부산!$H$86/1000 -> 222.14546 | K12: =+[4]부산!$I$86/1000 -> 155.08344 | L12: =+K12-J12 -> -67.062024 | M12: =+[5]부산!$H$86/1000 -> 167.22155 | N12: =+K12-M12 -> -12.138112 | O12: =+[4]부산!$H$92/1000 -> 124.23661 | P12: =+[4]부산!$I$92/1000 -> 28.96739 | Q12: =+P12-O12 -> -95.269223 | R12: =+[5]부산!$H$92/1000 -> 62.068411 | S12: =+P12-R12 -> -33.101021 | T12: =+[12]부산!$H$86/1000 -> 1630.3157 | U12: =+[12]부산!$I$86/1000 -> 1775.6783 | V12: =+U12-T12 -> 145.36261 | W12: =+[13]부산!$H$86/1000 -> 1993.2543 | X12: =+U12-W12 -> -217.57605 | Y12: =+[12]부산!$H$92/1000 -> 518.08818 | Z12: =+[12]부산!$I$92/1000 -> 427.0529 | AA12: =+Z12-Y12 -> -91.035287 | AB12: =+[13]부산!$H$92/1000 -> 1006.8312 | AC12: =+Z12-AB12 -> -579.77832
B13: 서부산 | I13: 서부산 | J13: =+[4]서부산!$H$86/1000 -> 262.68395 | K13: =+[4]서부산!$I$86/1000 -> 149.85117 | L13: =+K13-J13 -> -112.83278 | M13: =+[5]서부산!$H$86/1000 -> 84.673494 | N13: =+K13-M13 -> 65.177675 | O13: =+[4]서부산!$H$92/1000 -> 172.41147 | P13: =+[4]서부산!$I$92/1000 -> 38.920761 | Q13: =+P13-O13 -> -133.4907 | R13: =+[5]서부산!$H$92/1000 -> 6.5416569 | S13: =+P13-R13 -> 32.379104 | T13: =+[12]서부산!$H$86/1000 -> 1633.6255 | U13: =+[12]서부산!$I$86/1000 -> 1008.0573 | V13: =+U13-T13 -> -625.56821 | W13: =+[13]서부산!$H$86/1000 -> 2157.998 | X13: =+U13-W13 -> -1149.9408 | Y13: =+[12]서부산!$H$92/1000 -> 629.74386 | Z13: =+[12]서부산!$I$92/1000 -> -8.1956009 | AA13: =+Z13-Y13 -> -637.93946 | AB13: =+[13]서부산!$H$92/1000 -> 1184.6448 | AC13: =+Z13-AB13 -> -1192.8404
B14: 김해 | I14: 김해 | J14: =+[4]김해!$H$86/1000 -> 115.18251 | K14: =+[4]김해!$I$86/1000 -> -78.322141 | L14: =+K14-J14 -> -193.50465 | M14: =+[5]김해!$H$86/1000 -> -2.729523 | N14: =+K14-M14 -> -75.592618 | O14: =+[4]김해!$H$92/1000 -> 56.819006 | P14: =+[4]김해!$I$92/1000 -> -119.50721 | Q14: =+P14-O14 -> -176.32621 | R14: =+[5]김해!$H$92/1000 -> -70.157853 | S14: =+P14-R14 -> -49.349355 | T14: =+[12]김해!$H$86/1000 -> 1009.2323 | U14: =+[12]김해!$I$86/1000 -> -308.43197 | V14: =+U14-T14 -> -1317.6643 | W14: =+[13]김해!$H$86/1000 -> 709.65761 | X14: =+U14-W14 -> -1018.0896 | Y14: =+[12]김해!$H$92/1000 -> 321.63806 | Z14: =+[12]김해!$I$92/1000 -> -802.98653 | AA14: =+Z14-Y14 -> -1124.6246 | AB14: =+[13]김해!$H$92/1000 -> 122.68806 | AC14: =+Z14-AB14 -> -925.67458
B15: 정관 | I15: 정관 | J15: =+[4]정관!$H$86/1000 -> 164.10726 | K15: =+[4]정관!$I$86/1000 -> 173.69429 | L15: =+K15-J15 -> 9.5870287 | M15: =+[5]정관!$H$86/1000 -> 103.5454 | N15: =+K15-M15 -> 70.148889 | O15: =+[4]정관!$H$92/1000 -> 80.211189 | P15: =+[4]정관!$I$92/1000 -> 36.773601 | Q15: =+P15-O15 -> -43.437588 | R15: =+[5]정관!$H$92/1000 -> 1.1696044 | S15: =+P15-R15 -> 35.603997 | T15: =+[12]정관!$H$86/1000 -> 1420.3153 | U15: =+[12]정관!$I$86/1000 -> 1637.4455 | V15: =+U15-T15 -> 217.13018 | W15: =+[13]정관!$H$86/1000 -> 1600.251 | X15: =+U15-W15 -> 37.194519 | Y15: =+[12]정관!$H$92/1000 -> 407.22641 | Z15: =+[12]정관!$I$92/1000 -> 252.21251 | AA15: =+Z15-Y15 -> -155.01389 | AB15: =+[13]정관!$H$92/1000 -> 692.99955 | AC15: =+Z15-AB15 -> -440.78704
B16: 양산 | I16: 양산 | J16: =+[4]양산!$H$86/1000 -> 106.81807 | K16: =+[4]양산!$I$86/1000 -> -35.259846 | L16: =+K16-J16 -> -142.07791 | M16: =+[5]양산!$H$86/1000 -> 69.602208 | N16: =+K16-M16 -> -104.86205 | O16: =+[4]양산!$H$92/1000 -> 57.82852 | P16: =+[4]양산!$I$92/1000 -> -68.520147 | Q16: =+P16-O16 -> -126.34867 | R16: =+[5]양산!$H$92/1000 -> 2.5798045 | S16: =+P16-R16 -> -71.099952 | T16: =+[12]양산!$H$86/1000 -> 803.93013 | U16: =+[12]양산!$I$86/1000 -> -32.841495 | V16: =+U16-T16 -> -836.77163 | W16: =+[13]양산!$H$86/1000 -> 933.80031 | X16: =+U16-W16 -> -966.64181 | Y16: =+[12]양산!$H$92/1000 -> 242.3016 | Z16: =+[12]양산!$I$92/1000 -> -457.73681 | AA16: =+Z16-Y16 -> -700.03841 | AB16: =+[13]양산!$H$92/1000 -> 399.43568 | AC16: =+Z16-AB16 -> -857.17249
B17: 창원 | I17: 창원 | J17: =+[4]창원!$H$86/1000 -> 145.2062 | K17: =+[4]창원!$I$86/1000 -> -63.359208 | L17: =+K17-J17 -> -208.56541 | M17: =+[5]창원!$H$86/1000 -> 152.25467 | N17: =+K17-M17 -> -215.61387 | O17: =+[4]창원!$H$92/1000 -> 88.309959 | P17: =+[4]창원!$I$92/1000 -> -98.219376 | Q17: =+P17-O17 -> -186.52934 | R17: =+[5]창원!$H$92/1000 -> 62.692442 | S17: =+P17-R17 -> -160.91182 | T17: =+[12]창원!$H$86/1000 -> 851.69278 | U17: =+[12]창원!$I$86/1000 -> 279.17026 | V17: =+U17-T17 -> -572.52252 | W17: =+[13]창원!$H$86/1000 -> 2362.1912 | X17: =+U17-W17 -> -2083.0209 | Y17: =+[12]창원!$H$92/1000 -> 248.12376 | Z17: =+[12]창원!$I$92/1000 -> -288.16014 | AA17: =+Z17-Y17 -> -536.2839 | AB17: =+[13]창원!$H$92/1000 -> 1543.8577 | AC17: =+Z17-AB17 -> -1832.0178
B18: 대구 | I18: 대구 | J18: =+[4]대구!$H$86/1000 -> 99.040367 | K18: =+[4]대구!$I$86/1000 -> 42.684097 | L18: =+K18-J18 -> -56.35627 | M18: =+[5]대구!$H$86/1000 -> 137.65472 | N18: =+K18-M18 -> -94.970627 | O18: =+[4]대구!$H$92/1000 -> 49.049252 | P18: =+[4]대구!$I$92/1000 -> -23.285742 | Q18: =+P18-O18 -> -72.334994 | R18: =+[5]대구!$H$92/1000 -> 55.660624 | S18: =+P18-R18 -> -78.946366 | T18: =+[12]대구!$H$86/1000 -> 965.08074 | U18: =+[12]대구!$I$86/1000 -> 84.779201 | V18: =+U18-T18 -> -880.30154 | W18: =+[13]대구!$H$86/1000 -> 2116.0697 | X18: =+U18-W18 -> -2031.2905 | Y18: =+[12]대구!$H$92/1000 -> 349.66534 | Z18: =+[12]대구!$I$92/1000 -> -487.65606 | AA18: =+Z18-Y18 -> -837.3214 | AB18: =+[13]대구!$H$92/1000 -> 1394.0252 | AC18: =+Z18-AB18 -> -1881.6812
B19: 울산 | I19: 울산 | J19: =+[4]울산!$H$86/1000 -> 156.77601 | K19: =+[4]울산!$I$86/1000 -> 178.43166 | L19: =+K19-J19 -> 21.655651 | M19: =+[5]울산!$H$86/1000 -> 78.459948 | N19: =+K19-M19 -> 99.971712 | O19: =+[4]울산!$H$92/1000 -> 93.621762 | P19: =+[4]울산!$I$92/1000 -> 94.816607 | Q19: =+P19-O19 -> 1.1948455 | R19: =+[5]울산!$H$92/1000 -> 8.574251 | S19: =+P19-R19 -> 86.242356 | T19: =+[12]울산!$H$86/1000 -> 811.41718 | U19: =+[12]울산!$I$86/1000 -> 884.60064 | V19: =+U19-T19 -> 73.183461 | W19: =+[13]울산!$H$86/1000 -> 1080.4193 | X19: =+U19-W19 -> -195.81871 | Y19: =+[12]울산!$H$92/1000 -> 181.53644 | Z19: =+[12]울산!$I$92/1000 -> 168.09671 | AA19: =+Z19-Y19 -> -13.439735 | AB19: =+[13]울산!$H$92/1000 -> 560.66744 | AC19: =+Z19-AB19 -> -392.57073
B20: 아산 | I20: 아산 | J20: =+[4]아산!$H$86/1000 -> 399.79482 | K20: =+[4]아산!$I$86/1000 -> 79.527224 | L20: =+K20-J20 -> -320.2676 | M20: =+[5]아산!$H$86/1000 -> 256.65218 | N20: =+K20-M20 -> -177.12496 | O20: =+[4]아산!$H$92/1000 -> 293.22904 | P20: =+[4]아산!$I$92/1000 -> -40.808154 | Q20: =+P20-O20 -> -334.03719 | R20: =+[5]아산!$H$92/1000 -> 128.8666 | S20: =+P20-R20 -> -169.67476 | T20: =+[12]아산!$H$86/1000 -> 2582.8281 | U20: =+[12]아산!$I$86/1000 -> 775.93852 | V20: =+U20-T20 -> -1806.8895 | W20: =+[13]아산!$H$86/1000 -> 3364.5258 | X20: =+U20-W20 -> -2588.5873 | Y20: =+[12]아산!$H$92/1000 -> 1480.3216 | Z20: =+[12]아산!$I$92/1000 -> -438.83462 | AA20: =+Z20-Y20 -> -1919.1562 | AB20: =+[13]아산!$H$92/1000 -> 2218.555 | AC20: =+Z20-AB20 -> -2657.3896
B21: 전주 | I21: 전주 | J21: =+[4]전주!$H$86/1000 -> 175.60275 | K21: =+[4]전주!$I$86/1000 -> 174.72593 | L21: =+K21-J21 -> -0.87681845 | M21: =+[5]전주!$H$86/1000 -> 98.002099 | N21: =+K21-M21 -> 76.723833 | O21: =+[4]전주!$H$92/1000 -> 127.50461 | P21: =+[4]전주!$I$92/1000 -> 93.651666 | Q21: =+P21-O21 -> -33.852943 | R21: =+[5]전주!$H$92/1000 -> 42.408032 | S21: =+P21-R21 -> 51.243634 | T21: =+[12]전주!$H$86/1000 -> 996.57497 | U21: =+[12]전주!$I$86/1000 -> 1109.4876 | V21: =+U21-T21 -> 112.91266 | W21: =+[13]전주!$H$86/1000 -> 513.82139 | X21: =+U21-W21 -> 595.66623 | Y21: =+[12]전주!$H$92/1000 -> 490.13136 | Z21: =+[12]전주!$I$92/1000 -> 378.88199 | AA21: =+Z21-Y21 -> -111.24936 | AB21: =+[13]전주!$H$92/1000 -> 167.5324 | AC21: =+Z21-AB21 -> 211.34959
B22: 군산 | I22: 군산 | J22: =+[4]군산!$H$86/1000 -> 232.89281 | K22: =+[4]군산!$I$86/1000 -> 70.14253 | L22: =+K22-J22 -> -162.75028 | M22: =+[5]군산!$H$86/1000 -> 252.01421 | N22: =+K22-M22 -> -181.87168 | O22: =+[4]군산!$H$92/1000 -> 197.30245 | P22: =+[4]군산!$I$92/1000 -> 43.560891 | Q22: =+P22-O22 -> -153.74156 | R22: =+[5]군산!$H$92/1000 -> 201.36668 | S22: =+P22-R22 -> -157.80579 | T22: =+[12]군산!$H$86/1000 -> 1634.8092 | U22: =+[12]군산!$I$86/1000 -> 912.85209 | V22: =+U22-T22 -> -721.9571 | W22: =+[13]군산!$H$86/1000 -> 2422.0773 | X22: =+U22-W22 -> -1509.2252 | Y22: =+[12]군산!$H$92/1000 -> 1261.4879 | Z22: =+[12]군산!$I$92/1000 -> 588.09566 | AA22: =+Z22-Y22 -> -673.39221 | AB22: =+[13]군산!$H$92/1000 -> 1995.2157 | AC22: =+Z22-AB22 -> -1407.12
B23: 원주 | I23: 원주 | J23: =+[4]원주!$H$86/1000 -> 128.61965 | K23: =+[4]원주!$I$86/1000 -> 32.572096 | L23: =+K23-J23 -> -96.047556 | M23: =+[5]원주!$H$86/1000 -> 107.1387 | N23: =+K23-M23 -> -74.566607 | O23: =+[4]원주!$H$92/1000 -> 101.87872 | P23: =+[4]원주!$I$92/1000 -> 11.972985 | Q23: =+P23-O23 -> -89.905737 | R23: =+[5]원주!$H$92/1000 -> 73.635637 | S23: =+P23-R23 -> -61.662652 | T23: =+[12]원주!$H$86/1000 -> 699.09406 | U23: =+[12]원주!$I$86/1000 -> 82.862911 | V23: =+U23-T23 -> -616.23114 | W23: =+[13]원주!$H$86/1000 -> 1128.7028 | X23: =+U23-W23 -> -1045.8399 | Y23: =+[12]원주!$H$92/1000 -> 456.13431 | Z23: =+[12]원주!$I$92/1000 -> -97.829559 | AA23: =+Z23-Y23 -> -553.96387 | AB23: =+[13]원주!$H$92/1000 -> 854.39831 | AC23: =+Z23-AB23 -> -952.22787
B24: 제주 | I24: 제주 | J24: =+[4]제주!$H$86/1000 -> 190.51152 | K24: =+[4]제주!$I$86/1000 -> 35.677639 | L24: =+K24-J24 -> -154.83388 | M24: =+[5]제주!$H$86/1000 -> -40.681329 | N24: =+K24-M24 -> 76.358968 | O24: =+[4]제주!$H$92/1000 -> 146.46221 | P24: =+[4]제주!$I$92/1000 -> 2.4386467 | Q24: =+P24-O24 -> -144.02356 | R24: =+[5]제주!$H$92/1000 -> -54.232353 | S24: =+P24-R24 -> 56.671 | T24: =+[12]제주!$H$86/1000 -> 1443.0501 | U24: =+[12]제주!$I$86/1000 -> 632.62419 | V24: =+U24-T24 -> -810.42593 | W24: =+[13]제주!$H$86/1000 -> 325.24142 | X24: =+U24-W24 -> 307.38277 | Y24: =+[12]제주!$H$92/1000 -> 948.20246 | Z24: =+[12]제주!$I$92/1000 -> 217.28412 | AA24: =+Z24-Y24 -> -730.91834 | AB24: =+[13]제주!$H$92/1000 -> 131.73385 | AC24: =+Z24-AB24 -> 85.550274
I25: 수도권 | J25: =SUM(J8:J11) -> 1155.2461 | K25: =SUM(K8:K11) -> 63.243237 | L25: =+K25-J25 -> -1092.0029 | M25: =SUM(M8:M11) -> 268.92705 | N25: =+K25-M25 -> -205.68381 | O25: =SUM(O8:O11) -> 686.18382 | P25: =SUM(P8:P11) -> -402.84409 | Q25: =+P25-O25 -> -1089.0279 | R25: =SUM(R8:R11) -> -157.08423 | S25: =+P25-R25 -> -245.75986 | T25: =SUM(T8:T11) -> 6055.7801 | U25: =SUM(U8:U11) -> 1798.2506 | V25: =+U25-T25 -> -4257.5294 | W25: =SUM(W8:W11) -> 7423.8551 | X25: =+U25-W25 -> -5625.6045 | Y25: =SUM(Y8:Y11) -> 1069.1612 | Z25: =SUM(Z8:Z11) -> -2982.1528 | AA25: =+Z25-Y25 -> -4051.314 | AB25: =SUM(AB8:AB11) -> 2967.4419 | AC25: =+Z25-AB25 -> -5949.5947
I26: 영남권 | J26: =SUM(J12:J19) -> 1271.9598 | K26: =SUM(K12:K19) -> 522.80346 | L26: =+K26-J26 -> -749.15636 | M26: =SUM(M12:M19) -> 790.68247 | N26: =+K26-M26 -> -267.87901 | O26: =SUM(O12:O19) -> 722.48777 | P26: =SUM(P12:P19) -> -110.05411 | Q26: =+P26-O26 -> -832.54188 | R26: =SUM(R12:R19) -> 129.12894 | S26: =+P26-R26 -> -239.18305 | T26: =SUM(T12:T19) -> 9125.6096 | U26: =SUM(U12:U19) -> 5328.4576 | V26: =+U26-T26 -> -3797.1519 | W26: =SUM(W12:W19) -> 12953.641 | X26: =+U26-W26 -> -7625.1838 | Y26: =SUM(Y12:Y19) -> 2898.3237 | Z26: =SUM(Z12:Z19) -> -1197.373 | AA26: =+Z26-Y26 -> -4095.6967 | AB26: =SUM(AB12:AB19) -> 6905.1496 | AC26: =+Z26-AB26 -> -8102.5226
I27: 중부권 | J27: =SUM(J20:J24) -> 1127.4216 | K27: =SUM(K20:K24) -> 392.64542 | L27: =+K27-J27 -> -734.77614 | M27: =SUM(M20:M24) -> 673.12587 | N27: =+K27-M27 -> -280.48045 | O27: =SUM(O20:O24) -> 866.37703 | P27: =SUM(P20:P24) -> 110.81603 | Q27: =+P27-O27 -> -755.561 | R27: =SUM(R20:R24) -> 392.0446 | S27: =+P27-R27 -> -281.22856 | T27: =SUM(T20:T24) -> 7356.3564 | U27: =SUM(U20:U24) -> 3513.7653 | V27: =+U27-T27 -> -3842.5911 | W27: =SUM(W20:W24) -> 7754.3687 | X27: =+U27-W27 -> -4240.6034 | Y27: =SUM(Y20:Y24) -> 4636.2776 | Z27: =SUM(Z20:Z24) -> 647.59759 | AA27: =+Z27-Y27 -> -3988.68 | AB27: =SUM(AB20:AB24) -> 5367.4352 | AC27: =+Z27-AB27 -> -4719.8376
H28: 레미콘 계 | J28: =SUM(J25:J27) -> 3554.6275 | K28: =SUM(K25:K27) -> 978.69212 | L28: =+K28-J28 -> -2575.9354 | M28: =SUM(M25:M27) -> 1732.7354 | N28: =+K28-M28 -> -754.04327 | O28: =SUM(O25:O27) -> 2275.0486 | P28: =SUM(P25:P27) -> -402.08217 | Q28: =+P28-O28 -> -2677.1308 | R28: =SUM(R25:R27) -> 364.08931 | S28: =+P28-R28 -> -766.17148 | T28: =SUM(T25:T27) -> 22537.746 | U28: =SUM(U25:U27) -> 10640.474 | V28: =+U28-T28 -> -11897.272 | W28: =SUM(W25:W27) -> 28131.865 | X28: =+U28-W28 -> -17491.392 | Y28: =SUM(Y25:Y27) -> 8603.7624 | Z28: =SUM(Z25:Z27) -> -3531.9282 | AA28: =+Z28-Y28 -> -12135.691 | AB28: =SUM(AB25:AB27) -> 15240.027 | AC28: =+Z28-AB28 -> -18771.955

Sheet 사업장별(당월)
H3: □ 사업장별 손익실적(2025-09)
AG4: [단위 : 천㎥, 톤, 백만원]
H5: 구분 | J5: 물량 | O5: 매출 | T5: 영업이익(공통비 배부전) | Y5: 판매단가 | AB5: 변동비 | AE5: 공헌이익
A6: 2024년 9월 마감 손익 | J6: 계획 | K6: 실적 | L6: 차이 | M6: 전년 | N6: 차이 | O6: 계획 | P6: 실적 | Q6: 차이 | R6: 전년 | S6: 차이 | T6: 계획 | U6: 실적 | V6: 차이 | W6: 전년 | X6: 차이 | Y6: 계획 | Z6: 실적 | AA6: 전년 | AB6: 계획 | AC6: 실적 | AD6: 전년 | AE6: 계획 | AF6: 실적 | AG6: 전년
B7: 안양 | G7: =+I7 -> 안양 | H7: 레미콘 | I7: 안양 | J7: =+IFERROR(HLOOKUP($B7,'[1]9월'!$D$6:$BN$259,2,),)/1000 -> 41 | K7: =+IFERROR(HLOOKUP($B7,'[2]9월'!$F$6:$CP$99,2,),)/1000 -> 31.877 | L7: =+K7-J7 -> -9.123 | M7: =+IFERROR(HLOOKUP($B7,'[3]9월'!$F$6:$CC$57,2,),)/1000 -> 28.4 | N7: =+K7-M7 -> 3.477 | O7: =+IFERROR(HLOOKUP($B7,'[1]9월'!$D$6:$BN$259,3,),)/1000 -> 4162.5002 | P7: =+IFERROR(HLOOKUP($B7,'[2]9월'!$F$6:$CP$99,3,),)/1000 -> 3143.5581 | Q7: =+P7-O7 -> -1018.9421 | R7: =+IFERROR(HLOOKUP($B7,'[3]9월'!$F$6:$CC$57,3,),)/1000 -> 2850.3839 | S7: =+P7-R7 -> 293.17421 | T7: =+IFERROR(HLOOKUP($B7,'[1]9월'!$D$6:$BN$259,16,),)/1000 -> 524.41267 | U7: =+IFERROR(HLOOKUP($B7,'[2]9월'!$F$6:$CP$99,16,),)/1000 -> 252.5489 | V7: =+U7-T7 -> -271.86377 | W7: =+IFERROR(HLOOKUP($B7,'[3]9월'!$F$6:$CC$57,16,),)/1000 -> 202.0324 | X7: =+U7-W7 -> 50.516497 | Y7: =+[4]안양!$Q$85 -> 101524.39 | Z7: =+[4]안양!$R$85 -> 98622.172 | AA7: =+[5]안양!$Q$85 -> 100365.63 | AB7: =+[4]안양!$Q$89 -> 81127.527 | AC7: =+[4]안양!$R$89 -> 80246.895 | AD7: =+[5]안양!$Q$89 -> 81650.507 | AE7: =+Y7-AB7 -> 20396.868 | AF7: =+Z7-AC7 -> 18375.277 | AG7: =+AA7-AD7 -> 18715.124
B8: 인천 | G8: =+I8 -> 인천 | H8: 직영 | I8: 인천 | J8: =+IFERROR(HLOOKUP($B8,'[1]9월'!$D$6:$BN$259,2,),)/1000 -> 32 | K8: =+IFERROR(HLOOKUP($B8,'[2]9월'!$F$6:$CP$99,2,),)/1000 -> 30.29 | L8: =+K8-J8 -> -1.71 | M8: =+IFERROR(HLOOKUP($B8,'[3]9월'!$F$6:$CC$57,2,),)/1000 -> 18.327 | N8: =+K8-M8 -> 11.963 | O8: =+IFERROR(HLOOKUP($B8,'[1]9월'!$D$6:$BN$259,3,),)/1000 -> 3318.6545 | P8: =+IFERROR(HLOOKUP($B8,'[2]9월'!$F$6:$CP$99,3,),)/1000 -> 2910.5156 | Q8: =+P8-O8 -> -408.13889 | R8: =+IFERROR(HLOOKUP($B8,'[3]9월'!$F$6:$CC$57,3,),)/1000 -> 1795.8147 | S8: =+P8-R8 -> 1114.7009 | T8: =+IFERROR(HLOOKUP($B8,'[1]9월'!$D$6:$BN$259,16,),)/1000 -> 387.6129 | U8: =+IFERROR(HLOOKUP($B8,'[2]9월'!$F$6:$CP$99,16,),)/1000 -> -66.326553 | V8: =+U8-T8 -> -453.93946 | W8: =+IFERROR(HLOOKUP($B8,'[3]9월'!$F$6:$CC$57,16,),)/1000 -> -68.39704 | X8: =+U8-W8 -> 2.070487 | Y8: =+[4]인천!$Q$85 -> 103707.95 | Z8: =+[4]인천!$R$85 -> 96088.332 | AA8: =+[5]인천!$Q$85 -> 97987.379 | AB8: =+[4]인천!$Q$89 -> 82252.916 | AC8: =+[4]인천!$R$89 -> 86406.049 | AD8: =+[5]인천!$Q$89 -> 82653.877 | AE8: =+Y8-AB8 -> 21455.036 | AF8: =+Z8-AC8 -> 9682.283 | AG8: =+AA8-AD8 -> 15333.502
B9: 파주 | G9: =+I9 -> 파주 | I9: 파주 | J9: =+IFERROR(HLOOKUP($B9,'[1]9월'!$D$6:$BN$259,2,),)/1000 -> 24 | K9: =+IFERROR(HLOOKUP($B9,'[2]9월'!$F$6:$CP$99,2,),)/1000 -> 16.448 | L9: =+K9-J9 -> -7.552 | M9: =+IFERROR(HLOOKUP($B9,'[3]9월'!$F$6:$CC$57,2,),)/1000 -> 19.1078 | N9: =+K9-M9 -> -2.6598 | O9: =+IFERROR(HLOOKUP($B9,'[1]9월'!$D$6:$BN$259,3,),)/1000 -> 2313.4385 | P9: =+IFERROR(HLOOKUP($B9,'[2]9월'!$F$6:$CP$99,3,),)/1000 -> 1510.7481 | Q9: =+P9-O9 -> -802.69035 | R9: =+IFERROR(HLOOKUP($B9,'[3]9월'!$F$6:$CC$57,3,),)/1000 -> 1803.3963 | S9: =+P9-R9 -> -292.6482 | T9: =+IFERROR(HLOOKUP($B9,'[1]9월'!$D$6:$BN$259,16,),)/1000 -> 132.59526 | U9: =+IFERROR(HLOOKUP($B9,'[2]9월'!$F$6:$CP$99,16,),)/1000 -> -43.489316 | V9: =+U9-T9 -> -176.08458 | W9: =+IFERROR(HLOOKUP($B9,'[3]9월'!$F$6:$CC$57,16,),)/1000 -> 106.24983 | X9: =+U9-W9 -> -149.73915 | Y9: =+[4]파주!$Q$85 -> 96393.269 | Z9: =+[4]파주!$R$85 -> 91863.064 | AA9: =+[5]파주!$Q$85 -> 94365.024 | AB9: =+[4]파주!$Q$89 -> 81555.71 | AC9: =+[4]파주!$R$89 -> 79943.314 | AD9: =+[5]파주!$Q$89 -> 75826.434 | AE9: =+Y9-AB9 -> 14837.559 | AF9: =+Z9-AC9 -> 11919.75 | AG9: =+AA9-AD9 -> 18538.59
B10: 김포 | G10: =+I10 -> 김포 | I10: 김포 | J10: =+IFERROR(HLOOKUP($B10,'[1]9월'!$D$6:$BN$259,2,),)/1000 -> 16 | K10: =+IFERROR(HLOOKUP($B10,'[2]9월'!$F$6:$CP$99,2,),)/1000 -> 10.288 | L10: =+K10-J10 -> -5.712 | M10: =+IFERROR(HLOOKUP($B10,'[3]9월'!$F$6:$CC$57,2,),)/1000 -> 9.8 | N10: =+K10-M10 -> 0.488 | O10: =+IFERROR(HLOOKUP($B10,'[1]9월'!$D$6:$BN$259,3,),)/1000 -> 1523.05 | P10: =+IFERROR(HLOOKUP($B10,'[2]9월'!$F$6:$CP$99,3,),)/1000 -> 951.19071 | Q10: =+P10-O10 -> -571.85924 | R10: =+IFERROR(HLOOKUP($B10,'[3]9월'!$F$6:$CC$57,3,),)/1000 -> 943.50309 | S10: =+P10-R10 -> 7.687619 | T10: =+IFERROR(HLOOKUP($B10,'[1]9월'!$D$6:$BN$259,16,),)/1000 -> 110.62527 | U10: =+IFERROR(HLOOKUP($B10,'[2]9월'!$F$6:$CP$99,16,),)/1000 -> -79.489792 | V10: =+U10-T10 -> -190.11506 | W10: =+IFERROR(HLOOKUP($B10,'[3]9월'!$F$6:$CC$57,16,),)/1000 -> 29.041857 | X10: =+U10-W10 -> -108.53165 | Y10: =+[4]김포!$Q$85 -> 95190.622 | Z10: =+[4]김포!$R$85 -> 92479.295 | AA10: =+[5]김포!$Q$85 -> 96275.826 | AB10: =+[4]김포!$Q$89 -> 76527.866 | AC10: =+[4]김포!$R$89 -> 81027.53 | AD10: =+[5]김포!$Q$89 -> 74300.021 | AE10: =+Y10-AB10 -> 18662.755 | AF10: =+Z10-AC10 -> 11451.765 | AG10: =+AA10-AD10 -> 21975.804
B11: 부산 | G11: =+I11 -> 부산 | I11: 부산 | J11: =+IFERROR(HLOOKUP($B11,'[1]9월'!$D$6:$BN$259,2,),)/1000 -> 21 | K11: =+IFERROR(HLOOKUP($B11,'[2]9월'!$F$6:$CP$99,2,),)/1000 -> 20.199 | L11: =+K11-J11 -> -0.801 | M11: =+IFERROR(HLOOKUP($B11,'[3]9월'!$F$6:$CC$57,2,),)/1000 -> 15.517 | N11: =+K11-M11 -> 4.682 | O11: =+IFERROR(HLOOKUP($B11,'[1]9월'!$D$6:$BN$259,3,),)/1000 -> 2261.6974 | P11: =+IFERROR(HLOOKUP($B11,'[2]9월'!$F$6:$CP$99,3,),)/1000 -> 2164.6865 | Q11: =+P11-O11 -> -97.010835 | R11: =+IFERROR(HLOOKUP($B11,'[3]9월'!$F$6:$CC$57,3,),)/1000 -> 1769.7428 | S11: =+P11-R11 -> 394.94373 | T11: =+IFERROR(HLOOKUP($B11,'[1]9월'!$D$6:$BN$259,16,),)/1000 -> 222.14546 | U11: =+IFERROR(HLOOKUP($B11,'[2]9월'!$F$6:$CP$99,16,),)/1000 -> 155.08344 | V11: =+U11-T11 -> -67.062024 | W11: =+IFERROR(HLOOKUP($B11,'[3]9월'!$F$6:$CC$57,16,),)/1000 -> 167.22155 | X11: =+U11-W11 -> -12.138112 | Y11: =+[4]부산!$Q$85 -> 107699.87 | Z11: =+[4]부산!$R$85 -> 107168 | AA11: =+[5]부산!$Q$85 -> 114051.87 | AB11: =+[4]부산!$Q$89 -> 84681.417 | AC11: =+[4]부산!$R$89 -> 85757.042 | AD11: =+[5]부산!$Q$89 -> 84631.159 | AE11: =+Y11-AB11 -> 23018.458 | AF11: =+Z11-AC11 -> 21410.962 | AG11: =+AA11-AD11 -> 29420.706
B12: 서부산 | G12: =+I12 -> 서부산 | I12: 서부산 | J12: =+IFERROR(HLOOKUP($B12,'[1]9월'!$D$6:$BN$259,2,),)/1000 -> 21 | K12: =+IFERROR(HLOOKUP($B12,'[2]9월'!$F$6:$CP$99,2,),)/1000 -> 19.618 | L12: =+K12-J12 -> -1.382 | M12: =+IFERROR(HLOOKUP($B12,'[3]9월'!$F$6:$CC$57,2,),)/1000 -> 13.004 | N12: =+K12-M12 -> 6.614 | O12: =+IFERROR(HLOOKUP($B12,'[1]9월'!$D$6:$BN$259,3,),)/1000 -> 2085.2971 | P12: =+IFERROR(HLOOKUP($B12,'[2]9월'!$F$6:$CP$99,3,),)/1000 -> 1904.0365 | Q12: =+P12-O12 -> -181.26057 | R12: =+IFERROR(HLOOKUP($B12,'[3]9월'!$F$6:$CC$57,3,),)/1000 -> 1314.9703 | S12: =+P12-R12 -> 589.0662 | T12: =+IFERROR(HLOOKUP($B12,'[1]9월'!$D$6:$BN$259,16,),)/1000 -> 262.68395 | U12: =+IFERROR(HLOOKUP($B12,'[2]9월'!$F$6:$CP$99,16,),)/1000 -> 149.85117 | V12: =+U12-T12 -> -112.83278 | W12: =+IFERROR(HLOOKUP($B12,'[3]9월'!$F$6:$CC$57,16,),)/1000 -> 84.673494 | X12: =+U12-W12 -> 65.177675 | Y12: =+[4]서부산!$Q$85 -> 99299.86 | Z12: =+[4]서부산!$R$85 -> 97055.587 | AA12: =+[5]서부산!$Q$85 -> 101120.45 | AB12: =+[4]서부산!$Q$89 -> 77319.895 | AC12: =+[4]서부산!$R$89 -> 77542.314 | AD12: =+[5]서부산!$Q$89 -> 78001.326 | AE12: =+Y12-AB12 -> 21979.965 | AF12: =+Z12-AC12 -> 19513.273 | AG12: =+AA12-AD12 -> 23119.122
B13: 김해 | G13: =+I13 -> 김해 | I13: 김해 | J13: =+IFERROR(HLOOKUP($B13,'[1]9월'!$D$6:$BN$259,2,),)/1000 -> 14 | K13: =+IFERROR(HLOOKUP($B13,'[2]9월'!$F$6:$CP$99,2,),)/1000 -> 7.988 | L13: =+K13-J13 -> -6.012 | M13: =+IFERROR(HLOOKUP($B13,'[3]9월'!$F$6:$CC$57,2,),)/1000 -> 12.705 | N13: =+K13-M13 -> -4.717 | O13: =+IFERROR(HLOOKUP($B13,'[1]9월'!$D$6:$BN$259,3,),)/1000 -> 1348.1986 | P13: =+IFERROR(HLOOKUP($B13,'[2]9월'!$F$6:$CP$99,3,),)/1000 -> 706.9105 | Q13: =+P13-O13 -> -641.2881 | R13: =+IFERROR(HLOOKUP($B13,'[3]9월'!$F$6:$CC$57,3,),)/1000 -> 1134.8287 | S13: =+P13-R13 -> -427.9182 | T13: =+IFERROR(HLOOKUP($B13,'[1]9월'!$D$6:$BN$259,16,),)/1000 -> 115.18251 | U13: =+IFERROR(HLOOKUP($B13,'[2]9월'!$F$6:$CP$99,16,),)/1000 -> -78.322141 | V13: =+U13-T13 -> -193.50465 | W13: =+IFERROR(HLOOKUP($B13,'[3]9월'!$F$6:$CC$57,16,),)/1000 -> -2.729523 | X13: =+U13-W13 -> -75.592618 | Y13: =+[4]김해!$Q$85 -> 96299.9 | Z13: =+[4]김해!$R$85 -> 88617.202 | AA13: =+[5]김해!$Q$85 -> 89286.803 | AB13: =+[4]김해!$Q$89 -> 77194.604 | AC13: =+[4]김해!$R$89 -> 77871.709 | AD13: =+[5]김해!$Q$89 -> 75888.627 | AE13: =+Y13-AB13 -> 19105.296 | AF13: =+Z13-AC13 -> 10745.493 | AG13: =+AA13-AD13 -> 13398.176
B14: 정관 | G14: =+I14 -> 정관 | I14: 정관 | J14: =+IFERROR(HLOOKUP($B14,'[1]9월'!$D$6:$BN$259,2,),)/1000 -> 19 | K14: =+IFERROR(HLOOKUP($B14,'[2]9월'!$F$6:$CP$99,2,),)/1000 -> 23.4405 | L14: =+K14-J14 -> 4.4405 | M14: =+IFERROR(HLOOKUP($B14,'[3]9월'!$F$6:$CC$57,2,),)/1000 -> 16.976 | N14: =+K14-M14 -> 6.4645 | O14: =+IFERROR(HLOOKUP($B14,'[1]9월'!$D$6:$BN$259,3,),)/1000 -> 1938.0018 | P14: =+IFERROR(HLOOKUP($B14,'[2]9월'!$F$6:$CP$99,3,),)/1000 -> 2350.14 | Q14: =+P14-O14 -> 412.13821 | R14: =+IFERROR(HLOOKUP($B14,'[3]9월'!$F$6:$CC$57,3,),)/1000 -> 1722.9997 | S14: =+P14-R14 -> 627.1403 | T14: =+IFERROR(HLOOKUP($B14,'[1]9월'!$D$6:$BN$259,16,),)/1000 -> 164.10726 | U14: =+IFERROR(HLOOKUP($B14,'[2]9월'!$F$6:$CP$99,16,),)/1000 -> 173.69429 | V14: =+U14-T14 -> 9.5870287 | W14: =+IFERROR(HLOOKUP($B14,'[3]9월'!$F$6:$CC$57,16,),)/1000 -> 103.5454 | X14: =+U14-W14 -> 70.148889 | Y14: =+[4]정관!$Q$85 -> 102000.09 | Z14: =+[4]정관!$R$85 -> 100259.81 | AA14: =+[5]정관!$Q$85 -> 101496.21 | AB14: =+[4]정관!$Q$89 -> 82152.96 | AC14: =+[4]정관!$R$89 -> 82090.776 | AD14: =+[5]정관!$Q$89 -> 81278.39 | AE14: =+Y14-AB14 -> 19847.134 | AF14: =+Z14-AC14 -> 18169.03 | AG14: =+AA14-AD14 -> 20217.822
B15: 양산 | G15: =+I15 -> 양산 | I15: 양산 | J15: =+IFERROR(HLOOKUP($B15,'[1]9월'!$D$6:$BN$259,2,),)/1000 -> 12 | K15: =+IFERROR(HLOOKUP($B15,'[2]9월'!$F$6:$CP$99,2,),)/1000 -> 6.061 | L15: =+K15-J15 -> -5.939 | M15: =+IFERROR(HLOOKUP($B15,'[3]9월'!$F$6:$CC$57,2,),)/1000 -> 12.518 | N15: =+K15-M15 -> -6.457 | O15: =+IFERROR(HLOOKUP($B15,'[1]9월'!$D$6:$BN$259,3,),)/1000 -> 1131.66 | P15: =+IFERROR(HLOOKUP($B15,'[2]9월'!$F$6:$CP$99,3,),)/1000 -> 570.8879 | Q15: =+P15-O15 -> -560.7721 | R15: =+IFERROR(HLOOKUP($B15,'[3]9월'!$F$6:$CC$57,3,),)/1000 -> 1127.9969 | S15: =+P15-R15 -> -557.109 | T15: =+IFERROR(HLOOKUP($B15,'[1]9월'!$D$6:$BN$259,16,),)/1000 -> 106.81807 | U15: =+IFERROR(HLOOKUP($B15,'[2]9월'!$F$6:$CP$99,16,),)/1000 -> -35.259846 | V15: =+U15-T15 -> -142.07791 | W15: =+IFERROR(HLOOKUP($B15,'[3]9월'!$F$6:$CC$57,16,),)/1000 -> 69.602208 | X15: =+U15-W15 -> -104.86205 | Y15: =+[4]양산!$Q$85 -> 94305 | Z15: =+[4]양산!$R$85 -> 94190.381 | AA15: =+[5]양산!$Q$85 -> 90109.994 | AB15: =+[4]양산!$Q$89 -> 73438.432 | AC15: =+[4]양산!$R$89 -> 76835.776 | AD15: =+[5]양산!$Q$89 -> 71969.385 | AE15: =+Y15-AB15 -> 20866.568 | AF15: =+Z15-AC15 -> 17354.605 | AG15: =+AA15-AD15 -> 18140.609
B16: 창원 | G16: =+I16 -> 창원 | I16: 창원 | J16: =+IFERROR(HLOOKUP($B16,'[1]9월'!$D$6:$BN$259,2,),)/1000 -> 13 | K16: =+IFERROR(HLOOKUP($B16,'[2]9월'!$F$6:$CP$99,2,),)/1000 -> 6.546 | L16: =+K16-J16 -> -6.454 | M16: =+IFERROR(HLOOKUP($B16,'[3]9월'!$F$6:$CC$57,2,),)/1000 -> 14.953 | N16: =+K16-M16 -> -8.407 | O16: =+IFERROR(HLOOKUP($B16,'[1]9월'!$D$6:$BN$259,3,),)/1000 -> 1314.3049 | P16: =+IFERROR(HLOOKUP($B16,'[2]9월'!$F$6:$CP$99,3,),)/1000 -> 598.3484 | Q16: =+P16-O16 -> -715.95654 | R16: =+IFERROR(HLOOKUP($B16,'[3]9월'!$F$6:$CC$57,3,),)/1000 -> 1507.3454 | S16: =+P16-R16 -> -908.997 | T16: =+IFERROR(HLOOKUP($B16,'[1]9월'!$D$6:$BN$259,16,),)/1000 -> 145.2062 | U16: =+IFERROR(HLOOKUP($B16,'[2]9월'!$F$6:$CP$99,16,),)/1000 -> -63.359208 | V16: =+U16-T16 -> -208.56541 | W16: =+IFERROR(HLOOKUP($B16,'[3]9월'!$F$6:$CC$57,16,),)/1000 -> 152.25467 | X16: =+U16-W16 -> -215.61387 | Y16: =+[4]창원!$Q$85 -> 101100.38 | Z16: =+[4]창원!$R$85 -> 91406.722 | AA16: =+[5]창원!$Q$85 -> 100805.55 | AB16: =+[4]창원!$Q$89 -> 76060.57 | AC16: =+[4]창원!$R$89 -> 71724.152 | AD16: =+[5]창원!$Q$89 -> 74736.793 | AE16: =+Y16-AB16 -> 25039.81 | AF16: =+Z16-AC16 -> 19682.57 | AG16: =+AA16-AD16 -> 26068.757
B17: 대구 | G17: =+I17 -> 대구 | I17: 대구 | J17: =+IFERROR(HLOOKUP($B17,'[1]9월'!$D$6:$BN$259,2,),)/1000 -> 12 | K17: =+IFERROR(HLOOKUP($B17,'[2]9월'!$F$6:$CP$99,2,),)/1000 -> 13.3385 | L17: =+K17-J17 -> 1.3385 | M17: =+IFERROR(HLOOKUP($B17,'[3]9월'!$F$6:$CC$57,2,),)/1000 -> 14.191 | N17: =+K17-M17 -> -0.8525 | O17: =+IFERROR(HLOOKUP($B17,'[1]9월'!$D$6:$BN$259,3,),)/1000 -> 1154.7962 | P17: =+IFERROR(HLOOKUP($B17,'[2]9월'!$F$6:$CP$99,3,),)/1000 -> 1132.3224 | Q17: =+P17-O17 -> -22.473887 | R17: =+IFERROR(HLOOKUP($B17,'[3]9월'!$F$6:$CC$57,3,),)/1000 -> 1379.9727 | S17: =+P17-R17 -> -247.6504 | T17: =+IFERROR(HLOOKUP($B17,'[1]9월'!$D$6:$BN$259,16,),)/1000 -> 99.040367 | U17: =+IFERROR(HLOOKUP($B17,'[2]9월'!$F$6:$CP$99,16,),)/1000 -> 42.684097 | V17: =+U17-T17 -> -56.35627 | W17: =+IFERROR(HLOOKUP($B17,'[3]9월'!$F$6:$CC$57,16,),)/1000 -> 137.65472 | X17: =+U17-W17 -> -94.970627 | Y17: =+[4]대구!$Q$85 -> 96233.02 | Z17: =+[4]대구!$R$85 -> 84891.281 | AA17: =+[5]대구!$Q$85 -> 97242.812 | AB17: =+[4]대구!$Q$89 -> 72550.614 | AC17: =+[4]대구!$R$89 -> 69930.589 | AD17: =+[5]대구!$Q$89 -> 72709.872 | AE17: =+Y17-AB17 -> 23682.406 | AF17: =+Z17-AC17 -> 14960.692 | AG17: =+AA17-AD17 -> 24532.94
B18: 울산 | G18: =+I18 -> 울산 | I18: 울산 | J18: =+IFERROR(HLOOKUP($B18,'[1]9월'!$D$6:$BN$259,2,),)/1000 -> 14 | K18: =+IFERROR(HLOOKUP($B18,'[2]9월'!$F$6:$CP$99,2,),)/1000 -> 13.179 | L18: =+K18-J18 -> -0.821 | M18: =+IFERROR(HLOOKUP($B18,'[3]9월'!$F$6:$CC$57,2,),)/1000 -> 11.98 | N18: =+K18-M18 -> 1.199 | O18: =+IFERROR(HLOOKUP($B18,'[1]9월'!$D$6:$BN$259,3,),)/1000 -> 1458.865 | P18: =+IFERROR(HLOOKUP($B18,'[2]9월'!$F$6:$CP$99,3,),)/1000 -> 1435.1891 | Q18: =+P18-O18 -> -23.6759 | R18: =+IFERROR(HLOOKUP($B18,'[3]9월'!$F$6:$CC$57,3,),)/1000 -> 1176.1866 | S18: =+P18-R18 -> 259.00255 | T18: =+IFERROR(HLOOKUP($B18,'[1]9월'!$D$6:$BN$259,16,),)/1000 -> 156.77601 | U18: =+IFERROR(HLOOKUP($B18,'[2]9월'!$F$6:$CP$99,16,),)/1000 -> 178.43166 | V18: =+U18-T18 -> 21.655651 | W18: =+IFERROR(HLOOKUP($B18,'[3]9월'!$F$6:$CC$57,16,),)/1000 -> 78.459948 | X18: =+U18-W18 -> 99.971712 | Y18: =+[4]울산!$Q$85 -> 104204.64 | Z18: =+[4]울산!$R$85 -> 108899.7 | AA18: =+[5]울산!$Q$85 -> 98179.178 | AB18: =+[4]울산!$Q$89 -> 82480.758 | AC18: =+[4]울산!$R$89 -> 82498.145 | AD18: =+[5]울산!$Q$89 -> 78607.479 | AE18: =+Y18-AB18 -> 21723.885 | AF18: =+Z18-AC18 -> 26401.552 | AG18: =+AA18-AD18 -> 19571.699
B19: 아산 | G19: =+I19 -> 아산 | I19: 아산 | J19: =+IFERROR(HLOOKUP($B19,'[1]9월'!$D$6:$BN$259,2,),)/1000 -> 26 | K19: =+IFERROR(HLOOKUP($B19,'[2]9월'!$F$6:$CP$99,2,),)/1000 -> 23.459 | L19: =+K19-J19 -> -2.541 | M19: =+IFERROR(HLOOKUP($B19,'[3]9월'!$F$6:$CC$57,2,),)/1000 -> 23.352 | N19: =+K19-M19 -> 0.107 | O19: =+IFERROR(HLOOKUP($B19,'[1]9월'!$D$6:$BN$259,3,),)/1000 -> 2678 | P19: =+IFERROR(HLOOKUP($B19,'[2]9월'!$F$6:$CP$99,3,),)/1000 -> 2198.6815 | Q19: =+P19-O19 -> -479.31849 | R19: =+IFERROR(HLOOKUP($B19,'[3]9월'!$F$6:$CC$57,3,),)/1000 -> 2315.0378 | S19: =+P19-R19 -> -116.35625 | T19: =+IFERROR(HLOOKUP($B19,'[1]9월'!$D$6:$BN$259,16,),)/1000 -> 399.79482 | U19: =+IFERROR(HLOOKUP($B19,'[2]9월'!$F$6:$CP$99,16,),)/1000 -> 79.527224 | V19: =+U19-T19 -> -320.2676 | W19: =+IFERROR(HLOOKUP($B19,'[3]9월'!$F$6:$CC$57,16,),)/1000 -> 256.65218 | X19: =+U19-W19 -> -177.12496 | Y19: =+[4]아산!$Q$85 -> 103000 | Z19: =+[4]아산!$R$85 -> 93724.435 | AA19: =+[5]아산!$Q$85 -> 99026.219 | AB19: =+[4]아산!$Q$89 -> 77918.038 | AC19: =+[4]아산!$R$89 -> 79487.178 | AD19: =+[5]아산!$Q$89 -> 76440.336 | AE19: =+Y19-AB19 -> 25081.962 | AF19: =+Z19-AC19 -> 14237.257 | AG19: =+AA19-AD19 -> 22585.883
B20: 전주 | G20: =+I20 -> 전주 | I20: 전주 | J20: =+IFERROR(HLOOKUP($B20,'[1]9월'!$D$6:$BN$259,2,),)/1000 -> 12 | K20: =+IFERROR(HLOOKUP($B20,'[2]9월'!$F$6:$CP$99,2,),)/1000 -> 15.058 | L20: =+K20-J20 -> 3.058 | M20: =+IFERROR(HLOOKUP($B20,'[3]9월'!$F$6:$CC$57,2,),)/1000 -> 10.103 | N20: =+K20-M20 -> 4.955 | O20: =+IFERROR(HLOOKUP($B20,'[1]9월'!$D$6:$BN$259,3,),)/1000 -> 1208.7071 | P20: =+IFERROR(HLOOKUP($B20,'[2]9월'!$F$6:$CP$99,3,),)/1000 -> 1481.3307 | Q20: =+P20-O20 -> 272.6236 | R20: =+IFERROR(HLOOKUP($B20,'[3]9월'!$F$6:$CC$57,3,),)/1000 -> 1007.1744 | S20: =+P20-R20 -> 474.1563 | T20: =+IFERROR(HLOOKUP($B20,'[1]9월'!$D$6:$BN$259,16,),)/1000 -> 175.60275 | U20: =+IFERROR(HLOOKUP($B20,'[2]9월'!$F$6:$CP$99,16,),)/1000 -> 174.72593 | V20: =+U20-T20 -> -0.87681845 | W20: =+IFERROR(HLOOKUP($B20,'[3]9월'!$F$6:$CC$57,16,),)/1000 -> 98.002099 | X20: =+U20-W20 -> 76.723833 | Y20: =+[4]전주!$Q$85 -> 100725.59 | Z20: =+[4]전주!$R$85 -> 98374.997 | AA20: =+[5]전주!$Q$85 -> 99690.626 | AB20: =+[4]전주!$Q$89 -> 73247.442 | AC20: =+[4]전주!$R$89 -> 75716.659 | AD20: =+[5]전주!$Q$89 -> 72859.165 | AE20: =+Y20-AB20 -> 27478.15 | AF20: =+Z20-AC20 -> 22658.338 | AG20: =+AA20-AD20 -> 26831.462
B21: 군산 | G21: =+I21 -> 군산 | I21: 군산 | J21: =+IFERROR(HLOOKUP($B21,'[1]9월'!$D$6:$BN$259,2,),)/1000 -> 8 | K21: =+IFERROR(HLOOKUP($B21,'[2]9월'!$F$6:$CP$99,2,),)/1000 -> 4.3985 | L21: =+K21-J21 -> -3.6015 | M21: =+IFERROR(HLOOKUP($B21,'[3]9월'!$F$6:$CC$57,2,),)/1000 -> 7.883 | N21: =+K21-M21 -> -3.4845 | O21: =+IFERROR(HLOOKUP($B21,'[1]9월'!$D$6:$BN$259,3,),)/1000 -> 894.38615 | P21: =+IFERROR(HLOOKUP($B21,'[2]9월'!$F$6:$CP$99,3,),)/1000 -> 485.6806 | Q21: =+P21-O21 -> -408.70555 | R21: =+IFERROR(HLOOKUP($B21,'[3]9월'!$F$6:$CC$57,3,),)/1000 -> 917.5602 | S21: =+P21-R21 -> -431.8796 | T21: =+IFERROR(HLOOKUP($B21,'[1]9월'!$D$6:$BN$259,16,),)/1000 -> 232.89281 | U21: =+IFERROR(HLOOKUP($B21,'[2]9월'!$F$6:$CP$99,16,),)/1000 -> 70.14253 | V21: =+U21-T21 -> -162.75028 | W21: =+IFERROR(HLOOKUP($B21,'[3]9월'!$F$6:$CC$57,16,),)/1000 -> 252.01421 | X21: =+U21-W21 -> -181.87168 | Y21: =+[4]군산!$Q$85 -> 111798.27 | Z21: =+[4]군산!$R$85 -> 110265.3 | AA21: =+[5]군산!$Q$85 -> 116414.49 | AB21: =+[4]군산!$Q$89 -> 72435.635 | AC21: =+[4]군산!$R$89 -> 72207.09 | AD21: =+[5]군산!$Q$89 -> 72940.628 | AE21: =+Y21-AB21 -> 39362.633 | AF21: =+Z21-AC21 -> 38058.214 | AG21: =+AA21-AD21 -> 43473.867
B22: 원주 | G22: =+I22 -> 원주 | I22: 원주 | J22: =+IFERROR(HLOOKUP($B22,'[1]9월'!$D$6:$BN$259,2,),)/1000 -> 6 | K22: =+IFERROR(HLOOKUP($B22,'[2]9월'!$F$6:$CP$99,2,),)/1000 -> 3.3585 | L22: =+K22-J22 -> -2.6415 | M22: =+IFERROR(HLOOKUP($B22,'[3]9월'!$F$6:$CC$57,2,),)/1000 -> 5.359 | N22: =+K22-M22 -> -2.0005 | O22: =+IFERROR(HLOOKUP($B22,'[1]9월'!$D$6:$BN$259,3,),)/1000 -> 672 | P22: =+IFERROR(HLOOKUP($B22,'[2]9월'!$F$6:$CP$99,3,),)/1000 -> 376.37215 | Q22: =+P22-O22 -> -295.62785 | R22: =+IFERROR(HLOOKUP($B22,'[3]9월'!$F$6:$CC$57,3,),)/1000 -> 606.961 | S22: =+P22-R22 -> -230.58885 | T22: =+IFERROR(HLOOKUP($B22,'[1]9월'!$D$6:$BN$259,16,),)/1000 -> 128.61965 | U22: =+IFERROR(HLOOKUP($B22,'[2]9월'!$F$6:$CP$99,16,),)/1000 -> 32.572096 | V22: =+U22-T22 -> -96.047556 | W22: =+IFERROR(HLOOKUP($B22,'[3]9월'!$F$6:$CC$57,16,),)/1000 -> 107.1387 | X22: =+U22-W22 -> -74.566607 | Y22: =+[4]원주!$Q$85 -> 112000 | Z22: =+[4]원주!$R$85 -> 112065.55 | AA22: =+[5]원주!$Q$85 -> 113260.12 | AB22: =+[4]원주!$Q$89 -> 73072.22 | AC22: =+[4]원주!$R$89 -> 71797.687 | AD22: =+[5]원주!$Q$89 -> 73534.477 | AE22: =+Y22-AB22 -> 38927.78 | AF22: =+Z22-AC22 -> 40267.861 | AG22: =+AA22-AD22 -> 39725.647
B23: 제주 | F23: =+K27-J27 -> -49.659 | G23: =+I23 -> 제주 | I23: 제주 | J23: =+IFERROR(HLOOKUP($B23,'[1]9월'!$D$6:$BN$259,2,),)/1000 -> 9 | K23: =+IFERROR(HLOOKUP($B23,'[2]9월'!$F$6:$CP$99,2,),)/1000 -> 4.794 | L23: =+K23-J23 -> -4.206 | M23: =+IFERROR(HLOOKUP($B23,'[3]9월'!$F$6:$CC$57,2,),)/1000 -> 2.1085 | N23: =+K23-M23 -> 2.6855 | O23: =+IFERROR(HLOOKUP($B23,'[1]9월'!$D$6:$BN$259,3,),)/1000 -> 1106.96 | P23: =+IFERROR(HLOOKUP($B23,'[2]9월'!$F$6:$CP$99,3,),)/1000 -> 607.31897 | Q23: =+P23-O23 -> -499.64103 | R23: =+IFERROR(HLOOKUP($B23,'[3]9월'!$F$6:$CC$57,3,),)/1000 -> 245.49822 | S23: =+P23-R23 -> 361.82075 | T23: =+IFERROR(HLOOKUP($B23,'[1]9월'!$D$6:$BN$259,16,),)/1000 -> 190.51152 | U23: =+IFERROR(HLOOKUP($B23,'[2]9월'!$F$6:$CP$99,16,),)/1000 -> 35.677639 | V23: =+U23-T23 -> -154.83388 | W23: =+IFERROR(HLOOKUP($B23,'[3]9월'!$F$6:$CC$57,16,),)/1000 -> -40.681329 | X23: =+U23-W23 -> 76.358968 | Y23: =+[4]제주!$Q$85 -> 122995.56 | Z23: =+[4]제주!$R$85 -> 126594.93 | AA23: =+[5]제주!$Q$85 -> 116432.64 | AB23: =+[4]제주!$Q$89 -> 91386.196 | AC23: =+[4]제주!$R$89 -> 96807.174 | AD23: =+[5]제주!$Q$89 -> 86083.475 | AE23: =+Y23-AB23 -> 31609.36 | AF23: =+Z23-AC23 -> 29787.753 | AG23: =+AA23-AD23 -> 30349.163
F24: =+K24/J24 -> 0.78675221 | G24: =+I24 -> 수도권 | I24: 수도권 | J24: =SUM(J7:J10) -> 113 | K24: =SUM(K7:K10) -> 88.903 | L24: =+K24-J24 -> -24.097 | M24: =SUM(M7:M10) -> 75.6348 | N24: =+K24-M24 -> 13.2682 | O24: =SUM(O7:O10) -> 11317.643 | P24: =SUM(P7:P10) -> 8516.0125 | Q24: =+P24-O24 -> -2801.6305 | R24: =SUM(R7:R10) -> 7393.098 | S24: =+P24-R24 -> 1122.9145 | T24: =SUM(T7:T10) -> 1155.2461 | U24: =SUM(U7:U10) -> 63.243237 | V24: =+U24-T24 -> -1092.0029 | W24: =SUM(W7:W10) -> 268.92705 | X24: =+U24-W24 -> -205.68381 | Y24: =+[4]수도권!$Q$85 -> 100156.13 | Z24: =+[4]수도권!$R$85 -> 95819.566 | AA24: =+[5]수도권!$Q$85 -> 97749.491 | AB24: =+[4]수도권!$Q$89 -> 80885.883 | AC24: =+[4]수도권!$R$89 -> 82395.263 | AD24: =+[5]수도권!$Q$89 -> 79479.892 | AE24: =+Y24-AB24 -> 19270.25 | AF24: =+Z24-AC24 -> 13424.303 | AG24: =+AA24-AD24 -> 18269.6
F25: =+K25/J25 -> 0.87595238 | G25: =+I25 -> 영남권 | I25: 영남권 | J25: =SUM(J11:J18) -> 126 | K25: =SUM(K11:K18) -> 110.37 | L25: =+K25-J25 -> -15.63 | M25: =SUM(M11:M18) -> 111.844 | N25: =+K25-M25 -> -1.474 | O25: =SUM(O11:O18) -> 12692.821 | P25: =SUM(P11:P18) -> 10862.521 | Q25: =+P25-O25 -> -1830.2997 | R25: =SUM(R11:R18) -> 11134.043 | S25: =+P25-R25 -> -271.52182 | T25: =SUM(T11:T18) -> 1271.9598 | U25: =SUM(U11:U18) -> 522.80346 | V25: =+U25-T25 -> -749.15636 | W25: =SUM(W11:W18) -> 790.68247 | X25: =+U25-W25 -> -267.87901 | Y25: =+[4]영남권!$Q$85 -> 100736.67 | Z25: =+[4]영남권!$R$85 -> 98462.668 | AA25: =+[5]영남권!$Q$85 -> 99624.762 | AB25: =+[4]영남권!$Q$89 -> 78881.308 | AC25: =+[4]영남권!$R$89 -> 79337.908 | AD25: =+[5]영남권!$Q$89 -> 77483.837 | AE25: =+Y25-AB25 -> 21855.367 | AF25: =+Z25-AC25 -> 19124.76 | AG25: =+AA25-AD25 -> 22140.925
F26: =+K26/J26 -> 0.83718033 | G26: =+I26 -> 중부권 | I26: 중부권 | J26: =SUM(J19:J23) -> 61 | K26: =SUM(K19:K23) -> 51.068 | L26: =+K26-J26 -> -9.932 | M26: =SUM(M19:M23) -> 48.8055 | N26: =+K26-M26 -> 2.2625 | O26: =SUM(O19:O23) -> 6560.0532 | P26: =SUM(P19:P23) -> 5149.3839 | Q26: =+P26-O26 -> -1410.6693 | R26: =SUM(R19:R23) -> 5092.2316 | S26: =+P26-R26 -> 57.15235 | T26: =SUM(T19:T23) -> 1127.4216 | U26: =SUM(U19:U23) -> 392.64542 | V26: =+U26-T26 -> -734.77614 | W26: =SUM(W19:W23) -> 673.12587 | X26: =+U26-W26 -> -280.48045 | Y26: =+[4]중부권!$Q$85 -> 107541.86 | Z26: =+[4]중부권!$R$85 -> 100727.81 | AA26: =+[5]중부권!$Q$85 -> 104305.46 | AB26: =+[4]중부권!$Q$89 -> 77790.696 | AC26: =+[4]중부권!$R$89 -> 78864.581 | AD26: =+[5]중부권!$Q$89 -> 75226.187 | AE26: =+Y26-AB26 -> 29751.161 | AF26: =+Z26-AC26 -> 21863.231 | AG26: =+AA26-AD26 -> 29079.27
F27: =+K27/M27 -> 1.0594906 | G27: =+K27/J27 -> 0.83447 | H27: 레미콘 계 | J27: =SUM(J24:J26) -> 300 | K27: =SUM(K24:K26) -> 250.341 | L27: =+K27-J27 -> -49.659 | M27: =SUM(M24:M26) -> 236.2843 | N27: =+K27-M27 -> 14.0567 | O27: =SUM(O24:O26) -> 30570.517 | P27: =SUM(P24:P26) -> 24527.918 | Q27: =+P27-O27 -> -6042.5996 | R27: =SUM(R24:R26) -> 23619.373 | S27: =+P27-R27 -> 908.54505 | T27: =SUM(T24:T26) -> 3554.6275 | U27: =SUM(U24:U26) -> 978.69212 | V27: =+U27-T27 -> -2575.9354 | W27: =SUM(W24:W26) -> 1732.7354 | X27: =+U27-W27 -> -754.04327 | Y27: =+[4]합계!$Q$85 -> 101901.72 | Z27: =+[4]합계!$R$85 -> 97987.042 | AA27: =+[5]합계!$Q$85 -> 99989.728 | AB27: =+[4]합계!$Q$89 -> 79414.607 | AC27: =+[4]합계!$R$89 -> 80325.191 | AD27: =+[5]합계!$Q$89 -> 77657.504 | AE27: =+Y27-AB27 -> 22487.117 | AF27: =+Z27-AC27 -> 17661.851 | AG27: =+AA27-AD27 -> 22332.224 | AI27: =+AF27-AE27 -> -4825.2668 | AJ27: =+AF27-AG27 -> -4670.3734
B28: 건자재 | E28: 건자재영업 | G28: 건자재 | H28: 건자재 | J28: =+IFERROR(HLOOKUP($B28,'[1]9월'!$D$6:$BN$259,2,),) -> 12600 | K28: =+IFERROR(HLOOKUP($E28,'[2]9월'!$F$6:$CP$99,2,),) -> 7943.905 | L28: =+K28-J28 -> -4656.095 | M28: =+IFERROR(HLOOKUP($E28,'[3]9월'!$F$6:$CC$57,2,),) -> 7354.628 | N28: =+K28-M28 -> 589.277 | O28: =+IFERROR(HLOOKUP($B28,'[1]9월'!$D$6:$BN$259,3,),)/1000 -> 13712.919 | P28: =+IFERROR(HLOOKUP($E28,'[2]9월'!$F$6:$CP$99,3,),)/1000 -> 7610.2078 | Q28: =+P28-O28 -> -6102.7111 | R28: =+IFERROR(HLOOKUP($E28,'[3]9월'!$F$6:$CC$57,3,),)/1000 -> 7720.8259 | S28: =+P28-R28 -> -110.61809 | T28: =+IFERROR(HLOOKUP($B28,'[1]9월'!$D$6:$BN$259,16,),)/1000 -> 224.34542 | U28: =+IFERROR(HLOOKUP($E28,'[2]9월'!$F$6:$CP$99,16,),)/1000 -> 13.67264 | V28: =+U28-T28 -> -210.67278 | W28: =+IFERROR(HLOOKUP($E28,'[3]9월'!$F$6:$CC$57,16,),)/1000 -> -15.579202 | X28: =+U28-W28 -> 29.251842 | Y28: ■ 비고
