Workbook

Sheet 표지
A6: 2025년 7월 마감 손익
A24: 건재사업본부

Sheet 손익총괄
C3: □ 건재사업본부 손익실적(2025-07)
X4: [단위 : 천㎥, 톤, 원/㎥, 원/톤, 백만원]
C5: 구분 | E5: 7월 | J5: 7월 누계 | P5: 7월 주요지표
E6: 계획 | F6: 실적 | G6: 계획대비 | H6: 전년 | I6: 전년대비 | J6: 계획 | K6: 실적 | L6: 계획대비 | M6: 전년 | N6: 전년대비
C7: 물량 | D7: 레미콘 | E7: =+'[1]7월'!$Z$7/1000 -> 284 | F7: =+'[2]7월'!$Z$7/1000 -> 224.8465 | G7: =+F7-E7 -> -59.1535 | H7: =+'[3]7월'!$Z$7/1000 -> 256.6575 | I7: =+F7-H7 -> -31.811 | J7: =+'[1]7월누계'!$Z$7/1000 -> 1867 | K7: =+'[2]7월누계'!$Z$7/1000 -> 1652.7105 | L7: =+K7-J7 -> -214.2895 | M7: =+'[3]7월누계'!$Z$7/1000 -> 2034.9062 | N7: =+K7-M7 -> -382.1957 | Q7: □ 레미콘
D8: 철강재 | E8: =+'[1]7월'!$AA$7 -> 13500 | F8: =+'[2]7월'!$AO$7 -> 7798.862 | G8: =+F8-E8 -> -5701.138 | H8: =+'[3]7월'!$AO$7 -> 12986.91 | I8: =+F8-H8 -> -5188.048 | J8: =+'[1]7월누계'!$AA$7 -> 75700 | K8: =+'[2]7월누계'!$AO$7 -> 70135.201 | L8: =+K8-J8 -> -5564.799 | M8: =+'[3]7월누계'!$AO$7 -> 61066.958 | N8: =+K8-M8 -> 9068.243 | Q8: 구분 | S8: 계획 | T8: 실적 | U8: 계획대비 | V8: 전년 | W8: 전년대비
D9: 골재 | E9: =+'[1]7월'!$AE$7/1000 -> 106.36044 | F9: =+'[2]7월'!$AN$7/1000 -> 65.769 | G9: =+F9-E9 -> -40.591441 | H9: =+'[3]7월'!$AN$7/1000 -> 60.962 | I9: =+F9-H9 -> 4.807 | J9: =+'[1]7월누계'!$AE$7/1000 -> 663.11954 | K9: =+'[2]7월누계'!$AN$7/1000 -> 442.083 | L9: =+K9-J9 -> -221.03654 | M9: =+'[3]7월누계'!$AN$7/1000 -> 557.661 | N9: =+K9-M9 -> -115.578 | Q9: 물량 | R9: 수도권 | S9: =+[4]수도권!$T$5/1000 -> 107 | T9: =+[4]수도권!$U$5/1000 -> 78.037 | U9: =+T9-S9 -> -28.963 | V9: =+[5]수도권!$T$5/1000 -> 89.348 | W9: =+T9-V9 -> -11.311
C10: 매출 | D10: 레미콘 | E10: =+'[1]7월'!$Z$8/1000 -> 28604.057 | F10: =+'[2]7월'!$Z$8/1000 -> 22210.14 | G10: =+F10-E10 -> -6393.9169 | H10: =+'[3]7월'!$Z$8/1000 -> 26139.233 | I10: =+F10-H10 -> -3929.0934 | J10: =+'[1]7월누계'!$Z$8/1000 -> 187656.36 | K10: =+'[2]7월누계'!$Z$8/1000 -> 162879.82 | L10: =+K10-J10 -> -24776.545 | M10: =+'[3]7월누계'!$Z$8/1000 -> 206378.1 | N10: =+K10-M10 -> -43498.279 | R10: 영남권 | S10: =+[4]영남권!$T$5/1000 -> 121.5 | T10: =+[4]영남권!$U$5/1000 -> 105.781 | U10: =+T10-S10 -> -15.719 | V10: =+[5]영남권!$T$5/1000 -> 118.756 | W10: =+T10-V10 -> -12.975
D11: 건자재 | E11: =+'[1]7월'!$AA$8/1000 -> 14694.152 | F11: =+'[2]7월'!$AO$8/1000 -> 7354.8666 | G11: =+F11-E11 -> -7339.2858 | H11: =+'[3]7월'!$AO$8/1000 -> 11314.649 | I11: =+F11-H11 -> -3959.782 | J11: =+'[1]7월누계'!$AA$8/1000 -> 82779.071 | K11: =+'[2]7월누계'!$AO$8/1000 -> 62876.308 | L11: =+K11-J11 -> -19902.763 | M11: =+'[3]7월누계'!$AO$8/1000 -> 60718.387 | N11: =+K11-M11 -> 2157.9214 | R11: 중부권 | S11: =+[4]중부권!$T$5/1000 -> 55.5 | T11: =+[4]중부권!$U$5/1000 -> 41.0285 | U11: =+T11-S11 -> -14.4715 | V11: =+[5]중부권!$T$5/1000 -> 48.5535 | W11: =+T11-V11 -> -7.525
D12: 골재 | E12: =+'[1]7월'!$AE$8/1000 -> 1964.7695 | F12: =+'[2]7월'!$AN$8/1000 -> 1337.6405 | G12: =+F12-E12 -> -627.12897 | H12: =+'[3]7월'!$AN$8/1000 -> 1241.323 | I12: =+F12-H12 -> 96.3175 | J12: =+'[1]7월누계'!$AE$8/1000 -> 12310.549 | K12: =+'[2]7월누계'!$AN$8/1000 -> 9317.8465 | L12: =+K12-J12 -> -2992.7029 | M12: =+'[3]7월누계'!$AN$8/1000 -> 11222.53 | N12: =+K12-M12 -> -1904.6831 | Q12: 계 | S12: =SUM(S9:S11) -> 284 | T12: =SUM(T9:T11) -> 224.8465 | U12: =+T12-S12 -> -59.1535 | V12: =SUM(V9:V11) -> 256.6575 | W12: =+T12-V12 -> -31.811
D13: 기타 | E13: =+'[1]7월'!$E$8/1000-E10-E11-E12 -> 142.52817 | F13: =+'[2]7월'!$F$8/1000-F10-F11-F12 -> 118.80699 | G13: =+F13-E13 -> -23.721175 | H13: =+'[3]7월'!$F$8/1000-H10-H11-H12 -> 165.44935 | I13: =+F13-H13 -> -46.642361 | J13: =+'[1]7월누계'!$E$8/1000-J10-J11-J12 -> 1070.2172 | K13: =+'[2]7월누계'!$F$8/1000-K10-K11-K12 -> 947.72304 | L13: =+K13-J13 -> -122.49412 | M13: =+'[3]7월누계'!$F$8/1000-M10-M11-M12 -> 1157.2093 | N13: =+K13-M13 -> -209.48629 | Q13: 판매단가 | R13: 수도권 | S13: =+[4]수도권!$T$61 -> 97456.22 | T13: =+[4]수도권!$U$61 -> 96700.299 | U13: =+T13-S13 -> -755.92071 | V13: =+[5]수도권!$Q$85 -> 98771.936 | W13: =+T13-V13 -> -2071.6375
C14: 계 | E14: =SUM(E10:E13) -> 45405.507 | F14: =SUM(F10:F13) -> 31021.454 | G14: =+F14-E14 -> -14384.053 | H14: =SUM(H10:H13) -> 38860.654 | I14: =+F14-H14 -> -7839.2002 | J14: =SUM(J10:J13) -> 283816.2 | K14: =SUM(K10:K13) -> 236021.69 | L14: =+K14-J14 -> -47794.505 | M14: =SUM(M10:M13) -> 279476.22 | N14: =+K14-M14 -> -43454.527 | R14: 영남권 | S14: =+[4]영남권!$T$61 -> 100570.95 | T14: =+[4]영남권!$U$61 -> 98825.474 | U14: =+T14-S14 -> -1745.4752 | V14: =+[5]영남권!$Q$85 -> 102226.32 | W14: =+T14-V14 -> -3400.8451
C15: 매출원가 | D15: 레미콘 | E15: =+('[1]7월'!$Z$10+'[1]7월'!$Z$19)/1000 -> 25037.256 | F15: =+('[2]7월'!$Z$10+'[2]7월'!$Z$19)/1000 -> 20153.952 | G15: =+F15-E15 -> -4883.3041 | H15: =+('[3]7월'!$Z$10+'[3]7월'!$Z$19)/1000 -> 22759.689 | I15: =+F15-H15 -> -2605.7372 | J15: =+('[1]7월누계'!$Z$10+'[1]7월누계'!$Z$19)/1000 -> 166993.34 | K15: =+('[2]7월누계'!$Z$10+'[2]7월누계'!$Z$19)/1000 -> 149096.57 | L15: =+K15-J15 -> -17896.767 | M15: =+('[3]7월누계'!$Z$10+'[3]7월누계'!$Z$19)/1000 -> 178110.18 | N15: =+K15-M15 -> -29013.604 | R15: 중부권 | S15: =+[4]중부권!$T$61 -> 107331.01 | T15: =+[4]중부권!$U$61 -> 102649.88 | U15: =+T15-S15 -> -4681.1328 | V15: =+[5]중부권!$Q$85 -> 106628.96 | W15: =+T15-V15 -> -3979.0821
D16: 건자재 | E16: =+('[1]7월'!$AA$10+'[1]7월'!$AA$19)/1000 -> 14298.333 | F16: =+('[2]7월'!$AO$10+'[2]7월'!$AO$19)/1000 -> 7238.2875 | G16: =+F16-E16 -> -7060.046 | H16: =+('[3]7월'!$AO$10+'[3]7월'!$AO$19)/1000 -> 11193.013 | I16: =+F16-H16 -> -3954.7255 | J16: =+('[1]7월누계'!$AA$10+'[1]7월누계'!$AA$19)/1000 -> 80543.909 | K16: =+('[2]7월누계'!$AO$10+'[2]7월누계'!$AO$19)/1000 -> 61900.816 | L16: =+K16-J16 -> -18643.093 | M16: =+('[3]7월누계'!$AO$10+'[3]7월누계'!$AO$19)/1000 -> 59364.069 | N16: =+K16-M16 -> 2536.7473 | Q16: 계 | S16: =+[4]합계!$T$61 -> 100718.51 | T16: =+[4]합계!$U$61 -> 98789.633 | U16: =+T16-S16 -> -1928.8776 | V16: =+[5]합계!$Q$85 -> 101862.36 | W16: =+T16-V16 -> -3072.7231
D17: 골재 | E17: =+('[1]7월'!$AE$10+'[1]7월'!$AE$19)/1000 -> 1703.7501 | F17: =+('[2]7월'!$AN$10+'[2]7월'!$AN$19)/1000 -> 1388.1363 | G17: =+F17-E17 -> -315.61384 | H17: =+('[3]7월'!$AN$10+'[3]7월'!$AN$19)/1000 -> 1252.1428 | I17: =+F17-H17 -> 135.99348 | J17: =+('[1]7월누계'!$AE$10+'[1]7월누계'!$AE$19)/1000 -> 10758.448 | K17: =+('[2]7월누계'!$AN$10+'[2]7월누계'!$AN$19)/1000 -> 9611.998 | L17: =+K17-J17 -> -1146.4501 | M17: =+('[3]7월누계'!$AN$10+'[3]7월누계'!$AN$19)/1000 -> 10244.78 | N17: =+K17-M17 -> -632.782 | Q17: 공헌이익 | R17: 수도권 | S17: =+[4]수도권!$Q$90 -> 17126.382 | T17: =+[4]수도권!$R$90 -> 16548.722 | U17: =+T17-S17 -> -577.6601 | V17: =+[5]수도권!$Q$90 -> 17992.981 | W17: =+T17-V17 -> -1444.2589
D18: 기타 | E18: =+('[1]7월'!$E$10+'[1]7월'!$E$19)/1000-E15-E16-E17 -> 68.375599 | F18: =+('[2]7월'!$F$10+'[2]7월'!$F$19)/1000-F15-F16-F17 -> 19.214443 | G18: =+F18-E18 -> -49.161156 | H18: =+('[3]7월'!$F$10+'[3]7월'!$F$19)/1000-H15-H16-H17 -> 25.575635 | I18: =+F18-H18 -> -6.361192 | J18: =+('[1]7월누계'!$E$10+'[1]7월누계'!$E$19)/1000-J15-J16-J17 -> 420.28422 | K18: =+('[2]7월누계'!$F$10+'[2]7월누계'!$F$19)/1000-K15-K16-K17 -> 425.88299 | L18: =+K18-J18 -> 5.59877 | M18: =+('[3]7월누계'!$F$10+'[3]7월누계'!$F$19)/1000-M15-M16-M17 -> 351.13889 | N18: =+K18-M18 -> 74.744105 | R18: 영남권 | S18: =+[4]영남권!$Q$90 -> 21769.337 | T18: =+[4]영남권!$R$90 -> 20505.629 | U18: =+T18-S18 -> -1263.7088 | V18: =+[5]영남권!$Q$90 -> 22717.772 | W18: =+T18-V18 -> -2212.1433
C19: 계 | E19: =SUM(E15:E18) -> 41107.715 | F19: =SUM(F15:F18) -> 28799.59 | G19: =+F19-E19 -> -12308.125 | H19: =SUM(H15:H18) -> 35230.421 | I19: =+F19-H19 -> -6430.8304 | J19: =SUM(J15:J18) -> 258715.98 | K19: =SUM(K15:K18) -> 221035.27 | L19: =+K19-J19 -> -37680.712 | M19: =SUM(M15:M18) -> 248070.17 | N19: =+K19-M19 -> -27034.895 | R19: 중부권 | S19: =+[4]중부권!$Q$90 -> 29345.536 | T19: =+[4]중부권!$R$90 -> 23773.356 | U19: =+T19-S19 -> -5572.1797 | V19: =+[5]중부권!$Q$90 -> 30402.808 | W19: =+T19-V19 -> -6629.4519
C20: 매출이익 | D20: 레미콘 | E20: =+E10-E15 -> 3566.8007 | F20: =+F10-F15 -> 2056.1879 | G20: =+F20-E20 -> -1510.6129 | H20: =+H10-H15 -> 3379.544 | I20: =+F20-H20 -> -1323.3562 | J20: =+J10-J15 -> 20663.021 | K20: =+K10-K15 -> 13783.243 | L20: =+K20-J20 -> -6879.778 | M20: =+M10-M15 -> 28267.918 | N20: =+K20-M20 -> -14484.675 | Q20: 계 | S20: =+[4]합계!$Q$90 -> 21500.615 | T20: =+[4]합계!$R$90 -> 19736.082 | U20: =+T20-S20 -> -1764.533 | V20: =+[5]합계!$Q$90 -> 22535.083 | W20: =+T20-V20 -> -2799.001
D21: 건자재 | E21: =+E11-E16 -> 395.81892 | F21: =+F11-F16 -> 116.57918 | G21: =+F21-E21 -> -279.23974 | H21: =+H11-H16 -> 121.6357 | I21: =+F21-H21 -> -5.056518 | J21: =+J11-J16 -> 2235.1617 | K21: =+K11-K16 -> 975.49167 | L21: =+K21-J21 -> -1259.67 | M21: =+M11-M16 -> 1354.3176 | N21: =+K21-M21 -> -378.82593 | Q21: □ 건자재
D22: 골재 | E22: =+E12-E17 -> 261.01937 | F22: =+F12-F17 -> -50.495761 | G22: =+F22-E22 -> -311.51513 | H22: =+H12-H17 -> -10.819778 | I22: =+F22-H22 -> -39.675983 | J22: =+J12-J17 -> 1552.1013 | K22: =+K12-K17 -> -294.1515 | L22: =+K22-J22 -> -1846.2528 | M22: =+M12-M17 -> 977.74958 | N22: =+K22-M22 -> -1271.9011 | Q22: 구분 | S22: 계획 | T22: 실적 | U22: 계획대비 | V22: 전년 | W22: 전년대비
D23: 기타 | E23: =+E13-E18 -> 74.152568 | F23: =+F13-F18 -> 99.592549 | G23: =+F23-E23 -> 25.439981 | H23: =+H13-H18 -> 139.87372 | I23: =+F23-H23 -> -40.281169 | J23: =+J13-J18 -> 649.93294 | K23: =+K13-K18 -> 521.84005 | L23: =+K23-J23 -> -128.09289 | M23: =+M13-M18 -> 806.07045 | N23: =+K23-M23 -> -284.2304 | Q23: 철강재 판매단가 | S23: =+'[6]7월'!$F$10 -> 872222.22 | T23: =+'[6]7월'!$G$10 -> 794077.93 | U23: =+T23-S23 -> -78144.291 | V23: =+'[7]7월'!$G$10 -> 751049.21 | W23: =+T23-V23 -> 43028.722
C24: 계 | E24: =SUM(E20:E23) -> 4297.7916 | F24: =SUM(F20:F23) -> 2221.8638 | G24: =+F24-E24 -> -2075.9278 | H24: =SUM(H20:H23) -> 3630.2337 | I24: =+F24-H24 -> -1408.3698 | J24: =SUM(J20:J23) -> 25100.217 | K24: =SUM(K20:K23) -> 14986.423 | L24: =+K24-J24 -> -10113.794 | M24: =SUM(M20:M23) -> 31406.055 | N24: =+K24-M24 -> -16419.632 | Q24: 철강재 마진률 | S24: =+'[6]7월'!$F$15 -> 0.023957325 | T24: =+'[6]7월'!$G$15 -> 0.013537465 | U24: =+T24-S24 -> -0.01041986 | V24: =+'[6]7월'!$G$15 -> 0.013537465 | W24: =+T24-V24 -> 0
C25: 판관비 | D25: 레미콘 | E25: =+('[1]7월'!$Z$13+'[1]7월'!$Z$20)/1000 -> 661.11474 | F25: =+('[2]7월'!$Z$13+'[2]7월'!$Z$20)/1000 -> 678.98856 | G25: =+F25-E25 -> 17.873822 | H25: =+('[3]7월'!$Z$13+'[3]7월'!$Z$20)/1000 -> 654.54649 | I25: =+F25-H25 -> 24.442074 | J25: =+('[1]7월누계'!$Z$13+'[1]7월누계'!$Z$20)/1000 -> 4714.2925 | K25: =+('[2]7월누계'!$Z$13+'[2]7월누계'!$Z$20)/1000 -> 4701.93 | L25: =+K25-J25 -> -12.362489 | M25: =+('[3]7월누계'!$Z$13+'[3]7월누계'!$Z$20)/1000 -> 4621.0579 | N25: =+K25-M25 -> 80.872093 | Q25: □ 골재
D26: 건자재 | E26: =+('[1]7월'!$AA$13+'[1]7월'!$AA$20)/1000 -> 122.29035 | F26: =+('[2]7월'!$AO$13+'[2]7월'!$AO$20)/1000 -> 163.40207 | G26: =+F26-E26 -> 41.111723 | H26: =+('[3]7월'!$AO$13+'[3]7월'!$AO$20)/1000 -> 161.20531 | I26: =+F26-H26 -> 2.196758 | J26: =+('[1]7월누계'!$AA$13+'[1]7월누계'!$AA$20)/1000 -> 892.2273 | K26: =+('[2]7월누계'!$AO$13+'[2]7월누계'!$AO$20)/1000 -> 1046.9887 | L26: =+K26-J26 -> 154.7614 | M26: =+('[3]7월누계'!$AO$13+'[3]7월누계'!$AO$20)/1000 -> 978.76478 | N26: =+K26-M26 -> 68.223915 | Q26: 구분 | S26: 계획 | T26: 실적 | U26: 계획대비 | V26: 전년 | W26: 전년대비
D27: 골재 | E27: =+('[1]7월'!$AE$13+'[1]7월'!$AE$20+'[1]7월'!$AE$22)/1000 -> 46.912637 | F27: =+('[2]7월'!$AN$13+'[2]7월'!$AN$20+'[2]7월'!$AN$22)/1000 -> 46.779093 | G27: =+F27-E27 -> -0.13354381 | H27: =+('[3]7월'!$AN$13+'[3]7월'!$AN$20+'[3]7월'!$AN$22)/1000 -> 99.736892 | I27: =+F27-H27 -> -52.957799 | J27: =+('[1]7월누계'!$AE$13+'[1]7월누계'!$AE$20+'[1]7월누계'!$AE$22)/1000 -> 337.5913 | K27: =+('[2]7월누계'!$AN$13+'[2]7월누계'!$AN$20+'[2]7월누계'!$AN$22)/1000 -> 329.95713 | L27: =+K27-J27 -> -7.6341747 | M27: =+('[3]7월누계'!$AN$13+'[3]7월누계'!$AN$20+'[3]7월누계'!$AN$22)/1000 -> 367.788 | N27: =+K27-M27 -> -37.830874 | Q27: 판매량 | R27: 자가 | S27: =('[8]부산모래장(당월)'!$Q$48+[9]원가손익!$W$13+[10]손익!$F$10)/1000 -> 58.360441 | T27: =('[8]부산모래장(당월)'!$R$48+[9]원가손익!$X$13+[10]손익!$G$10)/1000 -> 43.82 | U27: =+T27-S27 -> -14.540441 | V27: =+[11]손익총괄!$V$27 -> 35.025 | W27: =+T27-V27 -> 8.795
D28: 기타 | E28: =+('[1]7월'!$E$13+'[1]7월'!$E$20)/1000-E25-E26-E27+('[1]7월'!$E$22/1000) -> 1453.5445 | F28: =+('[2]7월'!$F$13+'[2]7월'!$F$20)/1000-F25-F26-F27+'[2]7월'!$F$22/1000 -> 1410.3215 | G28: =+F28-E28 -> -43.222995 | H28: =+('[3]7월'!$F$13+'[3]7월'!$F$20)/1000-H25-H26-H27+'[3]7월'!$F$22/1000 -> 1394.2481 | I28: =+F28-H28 -> 16.073493 | J28: =+('[1]7월누계'!$E$13+'[1]7월누계'!$E$20)/1000-J25-J26-J27+('[1]7월누계'!$E$22/1000) -> 11822.46 | K28: =+('[2]7월누계'!$F$13+'[2]7월누계'!$F$20)/1000-K25-K26-K27+'[2]7월누계'!$F$22/1000 -> 13151.498 | L28: =+K28-J28 -> 1329.0378 | M28: =+('[3]7월누계'!$F$13+'[3]7월누계'!$F$20)/1000-M25-M26-M27+'[3]7월누계'!$F$22/1000 -> 11771.612 | N28: =+K28-M28 -> 1379.8864 | R28: 외판 | S28: =('[8]부산모래장(당월)'!$Q$47+[9]원가손익!$W$15+[10]손익!$F$12)/1000 -> 48 | T28: =('[8]부산모래장(당월)'!$R$47+[9]원가손익!$X$15+[10]손익!$G$12)/1000 -> 21.949 | U28: =+T28-S28 -> -26.051 | V28: =+[11]손익총괄!$V$28 -> 12.553 | W28: =+T28-V28 -> 9.396
C29: 계 | E29: =SUM(E25:E28) -> 2283.8623 | F29: =SUM(F25:F28) -> 2299.4913 | G29: =+F29-E29 -> 15.629006 | H29: =SUM(H25:H28) -> 2309.7367 | I29: =+F29-H29 -> -10.245474 | J29: =SUM(J25:J28) -> 17766.571 | K29: =SUM(K25:K28) -> 19230.374 | L29: =+K29-J29 -> 1463.8025 | M29: =SUM(M25:M28) -> 17739.222 | N29: =+K29-M29 -> 1491.1515 | Q29: 합 계 | S29: =SUM(S27:S28) -> 106.36044 | T29: =SUM(T27:T28) -> 65.769 | U29: =+T29-S29 -> -40.591441 | V29: =SUM(V27:V28) -> 47.578 | W29: =+T29-V29 -> 18.191
C30: 영업이익 | D30: 레미콘 | E30: =+E20-E25 -> 2905.686 | F30: =+F20-F25 -> 1377.1993 | G30: =+F30-E30 -> -1528.4867 | H30: =+H20-H25 -> 2724.9975 | I30: =+F30-H30 -> -1347.7982 | J30: =+J20-J25 -> 15948.728 | K30: =+K20-K25 -> 9081.3128 | L30: =+K30-J30 -> -6867.4155 | M30: =+M20-M25 -> 23646.86 | N30: =+K30-M30 -> -14565.547 | Q30: □ 기타내역(영업이익)
D31: % | E31: =+E30/E10 -> 0.101583 | F31: =+F30/F10 -> 0.062007682 | G31: =+F31-E31 -> -0.03957532 | H31: =+H30/H10 -> 0.10424933 | I31: =+F31-H31 -> -0.042241646 | J31: =+J30/J10 -> 0.08498901 | K31: =+K30/K10 -> 0.055754685 | L31: =+K31-J31 -> -0.029234325 | M31: =+M30/M10 -> 0.11458028 | N31: =+K31-M31 -> -0.058825594 | Q31: 구분 | S31: 계획 | T31: 실적 | U31: 계획대비 | V31: 전년 | W31: 전년대비
D32: 건자재 | E32: =+E21-E26 -> 273.52857 | F32: =+F21-F26 -> -46.822892 | G32: =+F32-E32 -> -320.35146 | H32: =+H21-H26 -> -39.569616 | I32: =+F32-H32 -> -7.253276 | J32: =+J21-J26 -> 1342.9344 | K32: =+K21-K26 -> -71.497023 | L32: =+K32-J32 -> -1414.4314 | M32: =+M21-M26 -> 375.55282 | N32: =+K32-M32 -> -447.04984 | Q32: 레미콘임대 | S32: =+'사업장별(당월)'!T33 -> 48.278888 | T32: =+'사업장별(당월)'!U33 -> 23.255776 | U32: =+T32-S32 -> -25.023112 | V32: =+'사업장별(당월)'!W33 -> 72.53547 | W32: =+T32-V32 -> -49.279694
D33: 골재 | E33: =+E22-E27 -> 214.10673 | F33: =+F22-F27 -> -97.274854 | G33: =+F33-E33 -> -311.38159 | H33: =+H22-H27 -> -110.55667 | I33: =+F33-H33 -> 13.281816 | J33: =+J22-J27 -> 1214.51 | K33: =+K22-K27 -> -624.10863 | L33: =+K33-J33 -> -1838.6186 | M33: =+M22-M27 -> 609.96158 | N33: =+K33-M33 -> -1234.0702 | Q33: 임대 | S33: =+'사업장별(당월)'!T34 -> 63.941 | T33: =+'사업장별(당월)'!U34 -> 66.530123 | U33: =+T33-S33 -> 2.589123 | V33: =+'사업장별(당월)'!W34 -> 62.661397 | W33: =+T33-V33 -> 3.868726
D34: 기타 | E34: =+E23-E28 -> -1379.392 | F34: =+F23-F28 -> -1310.729 | G34: =+F34-E34 -> 68.662976 | H34: =+H23-H28 -> -1254.3743 | I34: =+F34-H34 -> -56.354662 | J34: =+J23-J28 -> -11172.527 | K34: =+K23-K28 -> -12629.658 | L34: =+K34-J34 -> -1457.1307 | M34: =+M23-M28 -> -10965.541 | N34: =+K34-M34 -> -1664.1168 | Q34: 공통비 | S34: =+'사업장별(당월)'!T35 -> -1373.93 | T34: =+'사업장별(당월)'!U35 -> -1353.2625 | U34: =+T34-S34 -> 20.667534 | V34: =+'사업장별(당월)'!W35 -> -1338.4279 | W34: =+T34-V34 -> -14.834581
C35: 계 | E35: =SUM(E30,E32:E34) -> 2013.9293 | F35: =SUM(F30,F32:F34) -> -77.627447 | G35: =+F35-E35 -> -2091.5568 | H35: =SUM(H30,H32:H34) -> 1320.4969 | I35: =+F35-H35 -> -1398.1244 | J35: =SUM(J30,J32:J34) -> 7333.6453 | K35: =SUM(K30,K32:K34) -> -4243.9509 | L35: =+K35-J35 -> -11577.596 | M35: =SUM(M30,M32:M34) -> 13666.833 | N35: =+K35-M35 -> -17910.784 | Q35: 기타 | S35: =+S36-S32-S33-S34 -> -117.68187 | T35: =+T36-T32-T33-T34 -> -47.25244 | U35: =+T35-S35 -> 70.429431 | V35: =+V36-V32-V33-V34 -> -51.143327 | W35: =+T35-V35 -> 3.890887
D36: % | E36: =+E35/E14 -> 0.044354296 | F36: =+F35/F14 -> -0.0025023794 | G36: =+F36-E36 -> -0.046856676 | H36: =+H35/H14 -> 0.033980305 | I36: =+F36-H36 -> -0.036482685 | J36: =+J35/J14 -> 0.025839418 | K36: =+K35/K14 -> -0.01798119 | L36: =+K36-J36 -> -0.043820608 | M36: =+M35/M14 -> 0.048901594 | N36: =+K36-M36 -> -0.066882784 | Q36: 합계 | S36: =+'사업장별(당월)'!T41 -> -1379.392 | T36: =+'사업장별(당월)'!U41 -> -1310.729 | U36: =+T36-S36 -> 68.662976 | V36: =+'사업장별(당월)'!W41 -> -1254.3743 | W36: =+T36-V36 -> -56.354662
E38: =+'[1]7월'!$E$26/1000 -> 2013.9293 | F38: =+'[2]7월'!$F$26/1000 -> -77.627447 | H38: =+'[3]7월'!$F$26/1000 -> 1320.4969 | J38: =+'[1]7월누계'!$E$26/1000 -> 7333.6453 | K38: =+'[2]7월누계'!$F$26/1000 -> -4243.9509 | M38: =+'[3]7월누계'!$F$26/1000 -> 13666.833
E39: =+E35=E38 -> TRUE | F39: =+F35=F38 -> FALSE | H39: =+H35=H38 -> TRUE | J39: =+J35=J38 -> FALSE | K39: =+K35=K38 -> FALSE | M39: =+M35=M38 -> FALSE
E40: =+E35-E38 -> 0 | F40: =+F35-F38 -> 1.4495072e-12 | H40: =+H35-H38 -> 5.9117156e-12 | J40: =+J35-J38 -> 2.8194336e-11 | K40: =+K35-K38 -> 1.0913936e-11 | M40: =+M35-M38 -> 3.2741809e-11

Sheet 사업장별(당월)
H3: □ 사업장별 손익실적(2025-07)
AG4: [단위 : 천㎥, 톤, 백만원]
H5: 구분 | J5: 물량 | O5: 매출 | T5: 영업이익(공통비 배부전) | Y5: 판매단가 | AB5: 변동비 | AE5: 공헌이익
A6: 2024년 7월 마감 손익 | J6: 계획 | K6: 실적 | L6: 차이 | M6: 전년 | N6: 차이 | O6: 계획 | P6: 실적 | Q6: 차이 | R6: 전년 | S6: 차이 | T6: 계획 | U6: 실적 | V6: 차이 | W6: 전년 | X6: 차이 | Y6: 계획 | Z6: 실적 | AA6: 전년 | AB6: 계획 | AC6: 실적 | AD6: 전년 | AE6: 계획 | AF6: 실적 | AG6: 전년
B7: 안양 | G7: =+I7 -> 안양 | H7: 레미콘 | I7: 안양 | J7: =+IFERROR(HLOOKUP($B7,'[1]7월'!$D$6:$BN$259,2,),)/1000 -> 38 | K7: =+IFERROR(HLOOKUP($B7,'[2]7월'!$F$6:$CP$99,2,),)/1000 -> 31.797 | L7: =+K7-J7 -> -6.203 | M7: =+IFERROR(HLOOKUP($B7,'[3]7월'!$F$6:$CC$57,2,),)/1000 -> 30.154 | N7: =+K7-M7 -> 1.643 | O7: =+IFERROR(HLOOKUP($B7,'[1]7월'!$D$6:$BN$259,3,),)/1000 -> 3742.7249 | P7: =+IFERROR(HLOOKUP($B7,'[2]7월'!$F$6:$CP$99,3,),)/1000 -> 3065.7501 | Q7: =+P7-O7 -> -676.9748 | R7: =+IFERROR(HLOOKUP($B7,'[3]7월'!$F$6:$CC$57,3,),)/1000 -> 3033.8332 | S7: =+P7-R7 -> 31.916851 | T7: =+IFERROR(HLOOKUP($B7,'[1]7월'!$D$6:$BN$259,16,),)/1000 -> 350.33093 | U7: =+IFERROR(HLOOKUP($B7,'[2]7월'!$F$6:$CP$99,16,),)/1000 -> 271.23666 | V7: =+U7-T7 -> -79.094267 | W7: =+IFERROR(HLOOKUP($B7,'[3]7월'!$F$6:$CC$57,16,),)/1000 -> 258.59623 | X7: =+U7-W7 -> 12.640431 | Y7: =+[4]안양!$Q$85 -> 98492.76 | Z7: =+[4]안양!$R$85 -> 96371.938 | AA7: =+[5]안양!$Q$85 -> 100611.3 | AB7: =+[4]안양!$Q$89 -> 81031.53 | AC7: =+[4]안양!$R$89 -> 78315.096 | AD7: =+[5]안양!$Q$89 -> 82629.791 | AE7: =+Y7-AB7 -> 17461.23 | AF7: =+Z7-AC7 -> 18056.842 | AG7: =+AA7-AD7 -> 17981.511
B8: 인천 | G8: =+I8 -> 인천 | H8: 직영 | I8: 인천 | J8: =+IFERROR(HLOOKUP($B8,'[1]7월'!$D$6:$BN$259,2,),)/1000 -> 32 | K8: =+IFERROR(HLOOKUP($B8,'[2]7월'!$F$6:$CP$99,2,),)/1000 -> 25.068 | L8: =+K8-J8 -> -6.932 | M8: =+IFERROR(HLOOKUP($B8,'[3]7월'!$F$6:$CC$57,2,),)/1000 -> 25.908 | N8: =+K8-M8 -> -0.84 | O8: =+IFERROR(HLOOKUP($B8,'[1]7월'!$D$6:$BN$259,3,),)/1000 -> 3128.9993 | P8: =+IFERROR(HLOOKUP($B8,'[2]7월'!$F$6:$CP$99,3,),)/1000 -> 2445.4704 | Q8: =+P8-O8 -> -683.5289 | R8: =+IFERROR(HLOOKUP($B8,'[3]7월'!$F$6:$CC$57,3,),)/1000 -> 2597.1843 | S8: =+P8-R8 -> -151.71385 | T8: =+IFERROR(HLOOKUP($B8,'[1]7월'!$D$6:$BN$259,16,),)/1000 -> 199.14701 | U8: =+IFERROR(HLOOKUP($B8,'[2]7월'!$F$6:$CP$99,16,),)/1000 -> 21.73516 | V8: =+U8-T8 -> -177.41185 | W8: =+IFERROR(HLOOKUP($B8,'[3]7월'!$F$6:$CC$57,16,),)/1000 -> 199.80018 | X8: =+U8-W8 -> -178.06502 | Y8: =+[4]인천!$Q$85 -> 97781.229 | Z8: =+[4]인천!$R$85 -> 97553.472 | AA8: =+[5]인천!$Q$85 -> 100279.7 | AB8: =+[4]인천!$Q$89 -> 82252.916 | AC8: =+[4]인천!$R$89 -> 83904.922 | AD8: =+[5]인천!$Q$89 -> 81647.893 | AE8: =+Y8-AB8 -> 15528.313 | AF8: =+Z8-AC8 -> 13648.55 | AG8: =+AA8-AD8 -> 18631.808
B9: 파주 | G9: =+I9 -> 파주 | I9: 파주 | J9: =+IFERROR(HLOOKUP($B9,'[1]7월'!$D$6:$BN$259,2,),)/1000 -> 22 | K9: =+IFERROR(HLOOKUP($B9,'[2]7월'!$F$6:$CP$99,2,),)/1000 -> 11.935 | L9: =+K9-J9 -> -10.065 | M9: =+IFERROR(HLOOKUP($B9,'[3]7월'!$F$6:$CC$57,2,),)/1000 -> 24.724 | N9: =+K9-M9 -> -12.789 | O9: =+IFERROR(HLOOKUP($B9,'[1]7월'!$D$6:$BN$259,3,),)/1000 -> 2139.9721 | P9: =+IFERROR(HLOOKUP($B9,'[2]7월'!$F$6:$CP$99,3,),)/1000 -> 1126.2308 | Q9: =+P9-O9 -> -1013.7413 | R9: =+IFERROR(HLOOKUP($B9,'[3]7월'!$F$6:$CC$57,3,),)/1000 -> 2369.8819 | S9: =+P9-R9 -> -1243.6511 | T9: =+IFERROR(HLOOKUP($B9,'[1]7월'!$D$6:$BN$259,16,),)/1000 -> 146.87531 | U9: =+IFERROR(HLOOKUP($B9,'[2]7월'!$F$6:$CP$99,16,),)/1000 -> -22.290701 | V9: =+U9-T9 -> -169.16601 | W9: =+IFERROR(HLOOKUP($B9,'[3]7월'!$F$6:$CC$57,16,),)/1000 -> 171.334 | X9: =+U9-W9 -> -193.6247 | Y9: =+[4]파주!$Q$85 -> 97271.457 | Z9: =+[4]파주!$R$85 -> 94629.836 | AA9: =+[5]파주!$Q$85 -> 95898.5 | AB9: =+[4]파주!$Q$89 -> 79794.628 | AC9: =+[4]파주!$R$89 -> 77368.205 | AD9: =+[5]파주!$Q$89 -> 79787.149 | AE9: =+Y9-AB9 -> 17476.83 | AF9: =+Z9-AC9 -> 17261.631 | AG9: =+AA9-AD9 -> 16111.351
B10: 김포 | G10: =+I10 -> 김포 | I10: 김포 | J10: =+IFERROR(HLOOKUP($B10,'[1]7월'!$D$6:$BN$259,2,),)/1000 -> 15 | K10: =+IFERROR(HLOOKUP($B10,'[2]7월'!$F$6:$CP$99,2,),)/1000 -> 9.237 | L10: =+K10-J10 -> -5.763 | M10: =+IFERROR(HLOOKUP($B10,'[3]7월'!$F$6:$CC$57,2,),)/1000 -> 8.562 | N10: =+K10-M10 -> 0.675 | O10: =+IFERROR(HLOOKUP($B10,'[1]7월'!$D$6:$BN$259,3,),)/1000 -> 1416.1192 | P10: =+IFERROR(HLOOKUP($B10,'[2]7월'!$F$6:$CP$99,3,),)/1000 -> 905.93786 | Q10: =+P10-O10 -> -510.18138 | R10: =+IFERROR(HLOOKUP($B10,'[3]7월'!$F$6:$CC$57,3,),)/1000 -> 821.12558 | S10: =+P10-R10 -> 84.812279 | T10: =+IFERROR(HLOOKUP($B10,'[1]7월'!$D$6:$BN$259,16,),)/1000 -> 113.33171 | U10: =+IFERROR(HLOOKUP($B10,'[2]7월'!$F$6:$CP$99,16,),)/1000 -> -8.469041 | V10: =+U10-T10 -> -121.80075 | W10: =+IFERROR(HLOOKUP($B10,'[3]7월'!$F$6:$CC$57,16,),)/1000 -> 32.553125 | X10: =+U10-W10 -> -41.022166 | Y10: =+[4]김포!$Q$85 -> 94407.949 | Z10: =+[4]김포!$R$85 -> 98077.066 | AA10: =+[5]김포!$Q$85 -> 95902.436 | AB10: =+[4]김포!$Q$89 -> 75234.625 | AC10: =+[4]김포!$R$89 -> 79718.483 | AD10: =+[5]김포!$Q$89 -> 74436.951 | AE10: =+Y10-AB10 -> 19173.324 | AF10: =+Z10-AC10 -> 18358.583 | AG10: =+AA10-AD10 -> 21465.485
B11: 부산 | G11: =+I11 -> 부산 | I11: 부산 | J11: =+IFERROR(HLOOKUP($B11,'[1]7월'!$D$6:$BN$259,2,),)/1000 -> 21 | K11: =+IFERROR(HLOOKUP($B11,'[2]7월'!$F$6:$CP$99,2,),)/1000 -> 20.063 | L11: =+K11-J11 -> -0.937 | M11: =+IFERROR(HLOOKUP($B11,'[3]7월'!$F$6:$CC$57,2,),)/1000 -> 17.425 | N11: =+K11-M11 -> 2.638 | O11: =+IFERROR(HLOOKUP($B11,'[1]7월'!$D$6:$BN$259,3,),)/1000 -> 2261.7039 | P11: =+IFERROR(HLOOKUP($B11,'[2]7월'!$F$6:$CP$99,3,),)/1000 -> 2213.7341 | Q11: =+P11-O11 -> -47.969782 | R11: =+IFERROR(HLOOKUP($B11,'[3]7월'!$F$6:$CC$57,3,),)/1000 -> 1927.916 | S11: =+P11-R11 -> 285.8181 | T11: =+IFERROR(HLOOKUP($B11,'[1]7월'!$D$6:$BN$259,16,),)/1000 -> 203.15402 | U11: =+IFERROR(HLOOKUP($B11,'[2]7월'!$F$6:$CP$99,16,),)/1000 -> 219.61332 | V11: =+U11-T11 -> 16.459294 | W11: =+IFERROR(HLOOKUP($B11,'[3]7월'!$F$6:$CC$57,16,),)/1000 -> 190.61798 | X11: =+U11-W11 -> 28.995339 | Y11: =+[4]부산!$Q$85 -> 107700.18 | Z11: =+[4]부산!$R$85 -> 110339.14 | AA11: =+[5]부산!$Q$85 -> 110640.8 | AB11: =+[4]부산!$Q$89 -> 84924.284 | AC11: =+[4]부산!$R$89 -> 86758.587 | AD11: =+[5]부산!$Q$89 -> 84480.701 | AE11: =+Y11-AB11 -> 22775.901 | AF11: =+Z11-AC11 -> 23580.549 | AG11: =+AA11-AD11 -> 26160.103
B12: 서부산 | G12: =+I12 -> 서부산 | I12: 서부산 | J12: =+IFERROR(HLOOKUP($B12,'[1]7월'!$D$6:$BN$259,2,),)/1000 -> 20 | K12: =+IFERROR(HLOOKUP($B12,'[2]7월'!$F$6:$CP$99,2,),)/1000 -> 16.44 | L12: =+K12-J12 -> -3.56 | M12: =+IFERROR(HLOOKUP($B12,'[3]7월'!$F$6:$CC$57,2,),)/1000 -> 20.05 | N12: =+K12-M12 -> -3.61 | O12: =+IFERROR(HLOOKUP($B12,'[1]7월'!$D$6:$BN$259,3,),)/1000 -> 1985.9922 | P12: =+IFERROR(HLOOKUP($B12,'[2]7월'!$F$6:$CP$99,3,),)/1000 -> 1693.0968 | Q12: =+P12-O12 -> -292.89538 | R12: =+IFERROR(HLOOKUP($B12,'[3]7월'!$F$6:$CC$57,3,),)/1000 -> 2059.0346 | S12: =+P12-R12 -> -365.9378 | T12: =+IFERROR(HLOOKUP($B12,'[1]7월'!$D$6:$BN$259,16,),)/1000 -> 206.85424 | U12: =+IFERROR(HLOOKUP($B12,'[2]7월'!$F$6:$CP$99,16,),)/1000 -> 189.74493 | V12: =+U12-T12 -> -17.109305 | W12: =+IFERROR(HLOOKUP($B12,'[3]7월'!$F$6:$CC$57,16,),)/1000 -> 225.63006 | X12: =+U12-W12 -> -35.88513 | Y12: =+[4]서부산!$Q$85 -> 99299.609 | Z12: =+[4]서부산!$R$85 -> 102986.42 | AA12: =+[5]서부산!$Q$85 -> 102695.88 | AB12: =+[4]서부산!$Q$89 -> 77397.349 | AC12: =+[4]서부산!$R$89 -> 78679.176 | AD12: =+[5]서부산!$Q$89 -> 79119.203 | AE12: =+Y12-AB12 -> 21902.26 | AF12: =+Z12-AC12 -> 24307.247 | AG12: =+AA12-AD12 -> 23576.674
B13: 김해 | G13: =+I13 -> 김해 | I13: 김해 | J13: =+IFERROR(HLOOKUP($B13,'[1]7월'!$D$6:$BN$259,2,),)/1000 -> 13 | K13: =+IFERROR(HLOOKUP($B13,'[2]7월'!$F$6:$CP$99,2,),)/1000 -> 7.547 | L13: =+K13-J13 -> -5.453 | M13: =+IFERROR(HLOOKUP($B13,'[3]7월'!$F$6:$CC$57,2,),)/1000 -> 11.781 | N13: =+K13-M13 -> -4.234 | O13: =+IFERROR(HLOOKUP($B13,'[1]7월'!$D$6:$BN$259,3,),)/1000 -> 1251.8957 | P13: =+IFERROR(HLOOKUP($B13,'[2]7월'!$F$6:$CP$99,3,),)/1000 -> 713.887 | Q13: =+P13-O13 -> -538.00875 | R13: =+IFERROR(HLOOKUP($B13,'[3]7월'!$F$6:$CC$57,3,),)/1000 -> 1132.0667 | S13: =+P13-R13 -> -418.1797 | T13: =+IFERROR(HLOOKUP($B13,'[1]7월'!$D$6:$BN$259,16,),)/1000 -> 107.85098 | U13: =+IFERROR(HLOOKUP($B13,'[2]7월'!$F$6:$CP$99,16,),)/1000 -> -5.057841 | V13: =+U13-T13 -> -112.90882 | W13: =+IFERROR(HLOOKUP($B13,'[3]7월'!$F$6:$CC$57,16,),)/1000 -> 38.555588 | X13: =+U13-W13 -> -43.613429 | Y13: =+[4]김해!$Q$85 -> 96299.673 | Z13: =+[4]김해!$R$85 -> 94496.48 | AA13: =+[5]김해!$Q$85 -> 96092.581 | AB13: =+[4]김해!$Q$89 -> 76700.282 | AC13: =+[4]김해!$R$89 -> 77490.149 | AD13: =+[5]김해!$Q$89 -> 80907.956 | AE13: =+Y13-AB13 -> 19599.391 | AF13: =+Z13-AC13 -> 17006.331 | AG13: =+AA13-AD13 -> 15184.626
B14: 정관 | G14: =+I14 -> 정관 | I14: 정관 | J14: =+IFERROR(HLOOKUP($B14,'[1]7월'!$D$6:$BN$259,2,),)/1000 -> 19 | K14: =+IFERROR(HLOOKUP($B14,'[2]7월'!$F$6:$CP$99,2,),)/1000 -> 23.754 | L14: =+K14-J14 -> 4.754 | M14: =+IFERROR(HLOOKUP($B14,'[3]7월'!$F$6:$CC$57,2,),)/1000 -> 17.288 | N14: =+K14-M14 -> 6.466 | O14: =+IFERROR(HLOOKUP($B14,'[1]7월'!$D$6:$BN$259,3,),)/1000 -> 1938.0082 | P14: =+IFERROR(HLOOKUP($B14,'[2]7월'!$F$6:$CP$99,3,),)/1000 -> 2293.0672 | Q14: =+P14-O14 -> 355.05895 | R14: =+IFERROR(HLOOKUP($B14,'[3]7월'!$F$6:$CC$57,3,),)/1000 -> 1737.7844 | S14: =+P14-R14 -> 555.2828 | T14: =+IFERROR(HLOOKUP($B14,'[1]7월'!$D$6:$BN$259,16,),)/1000 -> 166.78418 | U14: =+IFERROR(HLOOKUP($B14,'[2]7월'!$F$6:$CP$99,16,),)/1000 -> 202.85136 | V14: =+U14-T14 -> 36.067174 | W14: =+IFERROR(HLOOKUP($B14,'[3]7월'!$F$6:$CC$57,16,),)/1000 -> 137.84952 | X14: =+U14-W14 -> 65.001843 | Y14: =+[4]정관!$Q$85 -> 102000.43 | Z14: =+[4]정관!$R$85 -> 96533.94 | AA14: =+[5]정관!$Q$85 -> 100519.69 | AB14: =+[4]정관!$Q$89 -> 82328.422 | AC14: =+[4]정관!$R$89 -> 78973.256 | AD14: =+[5]정관!$Q$89 -> 81910.423 | AE14: =+Y14-AB14 -> 19672.012 | AF14: =+Z14-AC14 -> 17560.684 | AG14: =+AA14-AD14 -> 18609.267
B15: 양산 | G15: =+I15 -> 양산 | I15: 양산 | J15: =+IFERROR(HLOOKUP($B15,'[1]7월'!$D$6:$BN$259,2,),)/1000 -> 11 | K15: =+IFERROR(HLOOKUP($B15,'[2]7월'!$F$6:$CP$99,2,),)/1000 -> 6.588 | L15: =+K15-J15 -> -4.412 | M15: =+IFERROR(HLOOKUP($B15,'[3]7월'!$F$6:$CC$57,2,),)/1000 -> 11.07 | N15: =+K15-M15 -> -4.482 | O15: =+IFERROR(HLOOKUP($B15,'[1]7월'!$D$6:$BN$259,3,),)/1000 -> 1043.0943 | P15: =+IFERROR(HLOOKUP($B15,'[2]7월'!$F$6:$CP$99,3,),)/1000 -> 606.3894 | Q15: =+P15-O15 -> -436.70485 | R15: =+IFERROR(HLOOKUP($B15,'[3]7월'!$F$6:$CC$57,3,),)/1000 -> 1022.5878 | S15: =+P15-R15 -> -416.19837 | T15: =+IFERROR(HLOOKUP($B15,'[1]7월'!$D$6:$BN$259,16,),)/1000 -> 84.782211 | U15: =+IFERROR(HLOOKUP($B15,'[2]7월'!$F$6:$CP$99,16,),)/1000 -> -16.390338 | V15: =+U15-T15 -> -101.17255 | W15: =+IFERROR(HLOOKUP($B15,'[3]7월'!$F$6:$CC$57,16,),)/1000 -> 49.592748 | X15: =+U15-W15 -> -65.983086 | Y15: =+[4]양산!$Q$85 -> 94826.75 | Z15: =+[4]양산!$R$85 -> 91860.056 | AA15: =+[5]양산!$Q$85 -> 92374.686 | AB15: =+[4]양산!$Q$89 -> 73664.74 | AC15: =+[4]양산!$R$89 -> 73920.262 | AD15: =+[5]양산!$Q$89 -> 75762.253 | AE15: =+Y15-AB15 -> 21162.01 | AF15: =+Z15-AC15 -> 17939.794 | AG15: =+AA15-AD15 -> 16612.433
B16: 창원 | G16: =+I16 -> 창원 | I16: 창원 | J16: =+IFERROR(HLOOKUP($B16,'[1]7월'!$D$6:$BN$259,2,),)/1000 -> 13 | K16: =+IFERROR(HLOOKUP($B16,'[2]7월'!$F$6:$CP$99,2,),)/1000 -> 10.308 | L16: =+K16-J16 -> -2.692 | M16: =+IFERROR(HLOOKUP($B16,'[3]7월'!$F$6:$CC$57,2,),)/1000 -> 13.4055 | N16: =+K16-M16 -> -3.0975 | O16: =+IFERROR(HLOOKUP($B16,'[1]7월'!$D$6:$BN$259,3,),)/1000 -> 1314.3049 | P16: =+IFERROR(HLOOKUP($B16,'[2]7월'!$F$6:$CP$99,3,),)/1000 -> 905.65475 | Q16: =+P16-O16 -> -408.65019 | R16: =+IFERROR(HLOOKUP($B16,'[3]7월'!$F$6:$CC$57,3,),)/1000 -> 1358.995 | S16: =+P16-R16 -> -453.3403 | T16: =+IFERROR(HLOOKUP($B16,'[1]7월'!$D$6:$BN$259,16,),)/1000 -> 147.05171 | U16: =+IFERROR(HLOOKUP($B16,'[2]7월'!$F$6:$CP$99,16,),)/1000 -> 31.227734 | V16: =+U16-T16 -> -115.82398 | W16: =+IFERROR(HLOOKUP($B16,'[3]7월'!$F$6:$CC$57,16,),)/1000 -> 173.4925 | X16: =+U16-W16 -> -142.26476 | Y16: =+[4]창원!$Q$85 -> 101100.38 | Z16: =+[4]창원!$R$85 -> 87859.405 | AA16: =+[5]창원!$Q$85 -> 101375.93 | AB16: =+[4]창원!$Q$89 -> 76060.57 | AC16: =+[4]창원!$R$89 -> 68889.416 | AD16: =+[5]창원!$Q$89 -> 74138.455 | AE16: =+Y16-AB16 -> 25039.81 | AF16: =+Z16-AC16 -> 18969.989 | AG16: =+AA16-AD16 -> 27237.476
B17: 대구 | G17: =+I17 -> 대구 | I17: 대구 | J17: =+IFERROR(HLOOKUP($B17,'[1]7월'!$D$6:$BN$259,2,),)/1000 -> 12.5 | K17: =+IFERROR(HLOOKUP($B17,'[2]7월'!$F$6:$CP$99,2,),)/1000 -> 8.0065 | L17: =+K17-J17 -> -4.4935 | M17: =+IFERROR(HLOOKUP($B17,'[3]7월'!$F$6:$CC$57,2,),)/1000 -> 12.691 | N17: =+K17-M17 -> -4.6845 | O17: =+IFERROR(HLOOKUP($B17,'[1]7월'!$D$6:$BN$259,3,),)/1000 -> 1198.9511 | P17: =+IFERROR(HLOOKUP($B17,'[2]7월'!$F$6:$CP$99,3,),)/1000 -> 694.6579 | Q17: =+P17-O17 -> -504.29316 | R17: =+IFERROR(HLOOKUP($B17,'[3]7월'!$F$6:$CC$57,3,),)/1000 -> 1308.7025 | S17: =+P17-R17 -> -614.04464 | T17: =+IFERROR(HLOOKUP($B17,'[1]7월'!$D$6:$BN$259,16,),)/1000 -> 121.12418 | U17: =+IFERROR(HLOOKUP($B17,'[2]7월'!$F$6:$CP$99,16,),)/1000 -> -8.611968 | V17: =+U17-T17 -> -129.73615 | W17: =+IFERROR(HLOOKUP($B17,'[3]7월'!$F$6:$CC$57,16,),)/1000 -> 175.5937 | X17: =+U17-W17 -> -184.20567 | Y17: =+[4]대구!$Q$85 -> 95916.085 | Z17: =+[4]대구!$R$85 -> 86761.744 | AA17: =+[5]대구!$Q$85 -> 103120.52 | AB17: =+[4]대구!$Q$89 -> 72533.292 | AC17: =+[4]대구!$R$89 -> 71247.791 | AD17: =+[5]대구!$Q$89 -> 75635.831 | AE17: =+Y17-AB17 -> 23382.793 | AF17: =+Z17-AC17 -> 15513.953 | AG17: =+AA17-AD17 -> 27484.69
B18: 울산 | G18: =+I18 -> 울산 | I18: 울산 | J18: =+IFERROR(HLOOKUP($B18,'[1]7월'!$D$6:$BN$259,2,),)/1000 -> 12 | K18: =+IFERROR(HLOOKUP($B18,'[2]7월'!$F$6:$CP$99,2,),)/1000 -> 13.0745 | L18: =+K18-J18 -> 1.0745 | M18: =+IFERROR(HLOOKUP($B18,'[3]7월'!$F$6:$CC$57,2,),)/1000 -> 15.0455 | N18: =+K18-M18 -> -1.971 | O18: =+IFERROR(HLOOKUP($B18,'[1]7월'!$D$6:$BN$259,3,),)/1000 -> 1225.42 | P18: =+IFERROR(HLOOKUP($B18,'[2]7월'!$F$6:$CP$99,3,),)/1000 -> 1333.2398 | Q18: =+P18-O18 -> 107.81977 | R18: =+IFERROR(HLOOKUP($B18,'[3]7월'!$F$6:$CC$57,3,),)/1000 -> 1592.9121 | S18: =+P18-R18 -> -259.67233 | T18: =+IFERROR(HLOOKUP($B18,'[1]7월'!$D$6:$BN$259,16,),)/1000 -> 101.43202 | U18: =+IFERROR(HLOOKUP($B18,'[2]7월'!$F$6:$CP$99,16,),)/1000 -> 168.08502 | V18: =+U18-T18 -> 66.652996 | W18: =+IFERROR(HLOOKUP($B18,'[3]7월'!$F$6:$CC$57,16,),)/1000 -> 240.50593 | X18: =+U18-W18 -> -72.420912 | Y18: =+[4]울산!$Q$85 -> 102118.33 | Z18: =+[4]울산!$R$85 -> 101972.52 | AA18: =+[5]울산!$Q$85 -> 105872.99 | AB18: =+[4]울산!$Q$89 -> 81327.456 | AC18: =+[4]울산!$R$89 -> 78109.378 | AD18: =+[5]울산!$Q$89 -> 81253.354 | AE18: =+Y18-AB18 -> 20790.877 | AF18: =+Z18-AC18 -> 23863.146 | AG18: =+AA18-AD18 -> 24619.638
B19: 아산 | G19: =+I19 -> 아산 | I19: 아산 | J19: =+IFERROR(HLOOKUP($B19,'[1]7월'!$D$6:$BN$259,2,),)/1000 -> 24 | K19: =+IFERROR(HLOOKUP($B19,'[2]7월'!$F$6:$CP$99,2,),)/1000 -> 19.911 | L19: =+K19-J19 -> -4.089 | M19: =+IFERROR(HLOOKUP($B19,'[3]7월'!$F$6:$CC$57,2,),)/1000 -> 24.195 | N19: =+K19-M19 -> -4.284 | O19: =+IFERROR(HLOOKUP($B19,'[1]7월'!$D$6:$BN$259,3,),)/1000 -> 2472 | P19: =+IFERROR(HLOOKUP($B19,'[2]7월'!$F$6:$CP$99,3,),)/1000 -> 1844.2038 | Q19: =+P19-O19 -> -627.79621 | R19: =+IFERROR(HLOOKUP($B19,'[3]7월'!$F$6:$CC$57,3,),)/1000 -> 2473.766 | S19: =+P19-R19 -> -629.56223 | T19: =+IFERROR(HLOOKUP($B19,'[1]7월'!$D$6:$BN$259,16,),)/1000 -> 353.83816 | U19: =+IFERROR(HLOOKUP($B19,'[2]7월'!$F$6:$CP$99,16,),)/1000 -> 70.33137 | V19: =+U19-T19 -> -283.50679 | W19: =+IFERROR(HLOOKUP($B19,'[3]7월'!$F$6:$CC$57,16,),)/1000 -> 395.11046 | X19: =+U19-W19 -> -324.77909 | Y19: =+[4]아산!$Q$85 -> 103000 | Z19: =+[4]아산!$R$85 -> 92622.359 | AA19: =+[5]아산!$Q$85 -> 102242.86 | AB19: =+[4]아산!$Q$89 -> 77935.242 | AC19: =+[4]아산!$R$89 -> 77514.598 | AD19: =+[5]아산!$Q$89 -> 75710.543 | AE19: =+Y19-AB19 -> 25064.758 | AF19: =+Z19-AC19 -> 15107.761 | AG19: =+AA19-AD19 -> 26532.318
B20: 전주 | G20: =+I20 -> 전주 | I20: 전주 | J20: =+IFERROR(HLOOKUP($B20,'[1]7월'!$D$6:$BN$259,2,),)/1000 -> 12 | K20: =+IFERROR(HLOOKUP($B20,'[2]7월'!$F$6:$CP$99,2,),)/1000 -> 5.565 | L20: =+K20-J20 -> -6.435 | M20: =+IFERROR(HLOOKUP($B20,'[3]7월'!$F$6:$CC$57,2,),)/1000 -> 8.0735 | N20: =+K20-M20 -> -2.5085 | O20: =+IFERROR(HLOOKUP($B20,'[1]7월'!$D$6:$BN$259,3,),)/1000 -> 1204.8425 | P20: =+IFERROR(HLOOKUP($B20,'[2]7월'!$F$6:$CP$99,3,),)/1000 -> 548.22096 | Q20: =+P20-O20 -> -656.62156 | R20: =+IFERROR(HLOOKUP($B20,'[3]7월'!$F$6:$CC$57,3,),)/1000 -> 767.062 | S20: =+P20-R20 -> -218.84104 | T20: =+IFERROR(HLOOKUP($B20,'[1]7월'!$D$6:$BN$259,16,),)/1000 -> 175.46359 | U20: =+IFERROR(HLOOKUP($B20,'[2]7월'!$F$6:$CP$99,16,),)/1000 -> -28.654789 | V20: =+U20-T20 -> -204.11838 | W20: =+IFERROR(HLOOKUP($B20,'[3]7월'!$F$6:$CC$57,16,),)/1000 -> 44.821658 | X20: =+U20-W20 -> -73.476447 | Y20: =+[4]전주!$Q$85 -> 100403.54 | Z20: =+[4]전주!$R$85 -> 98512.302 | AA20: =+[5]전주!$Q$85 -> 95009.847 | AB20: =+[4]전주!$Q$89 -> 72688.918 | AC20: =+[4]전주!$R$89 -> 76945.124 | AD20: =+[5]전주!$Q$89 -> 71872.966 | AE20: =+Y20-AB20 -> 27714.625 | AF20: =+Z20-AC20 -> 21567.178 | AG20: =+AA20-AD20 -> 23136.881
B21: 군산 | G21: =+I21 -> 군산 | I21: 군산 | J21: =+IFERROR(HLOOKUP($B21,'[1]7월'!$D$6:$BN$259,2,),)/1000 -> 6.5 | K21: =+IFERROR(HLOOKUP($B21,'[2]7월'!$F$6:$CP$99,2,),)/1000 -> 5.149 | L21: =+K21-J21 -> -1.351 | M21: =+IFERROR(HLOOKUP($B21,'[3]7월'!$F$6:$CC$57,2,),)/1000 -> 7.211 | N21: =+K21-M21 -> -2.062 | O21: =+IFERROR(HLOOKUP($B21,'[1]7월'!$D$6:$BN$259,3,),)/1000 -> 725.0687 | P21: =+IFERROR(HLOOKUP($B21,'[2]7월'!$F$6:$CP$99,3,),)/1000 -> 602.2503 | Q21: =+P21-O21 -> -122.8184 | R21: =+IFERROR(HLOOKUP($B21,'[3]7월'!$F$6:$CC$57,3,),)/1000 -> 865.03425 | S21: =+P21-R21 -> -262.78395 | T21: =+IFERROR(HLOOKUP($B21,'[1]7월'!$D$6:$BN$259,16,),)/1000 -> 173.50943 | U21: =+IFERROR(HLOOKUP($B21,'[2]7월'!$F$6:$CP$99,16,),)/1000 -> 131.91551 | V21: =+U21-T21 -> -41.593919 | W21: =+IFERROR(HLOOKUP($B21,'[3]7월'!$F$6:$CC$57,16,),)/1000 -> 241.03226 | X21: =+U21-W21 -> -109.11675 | Y21: =+[4]군산!$Q$85 -> 111549.03 | Z21: =+[4]군산!$R$85 -> 116964.52 | AA21: =+[5]군산!$Q$85 -> 119960.37 | AB21: =+[4]군산!$Q$89 -> 72379.463 | AC21: =+[4]군산!$R$89 -> 75340.117 | AD21: =+[5]군산!$Q$89 -> 75163.432 | AE21: =+Y21-AB21 -> 39169.567 | AF21: =+Z21-AC21 -> 41624.4 | AG21: =+AA21-AD21 -> 44796.941
B22: 원주 | G22: =+I22 -> 원주 | I22: 원주 | J22: =+IFERROR(HLOOKUP($B22,'[1]7월'!$D$6:$BN$259,2,),)/1000 -> 4 | K22: =+IFERROR(HLOOKUP($B22,'[2]7월'!$F$6:$CP$99,2,),)/1000 -> 4.105 | L22: =+K22-J22 -> 0.105 | M22: =+IFERROR(HLOOKUP($B22,'[3]7월'!$F$6:$CC$57,2,),)/1000 -> 5.1725 | N22: =+K22-M22 -> -1.0675 | O22: =+IFERROR(HLOOKUP($B22,'[1]7월'!$D$6:$BN$259,3,),)/1000 -> 448 | P22: =+IFERROR(HLOOKUP($B22,'[2]7월'!$F$6:$CP$99,3,),)/1000 -> 443.9354 | Q22: =+P22-O22 -> -4.0646 | R22: =+IFERROR(HLOOKUP($B22,'[3]7월'!$F$6:$CC$57,3,),)/1000 -> 592.47664 | S22: =+P22-R22 -> -148.54124 | T22: =+IFERROR(HLOOKUP($B22,'[1]7월'!$D$6:$BN$259,16,),)/1000 -> 68.202561 | U22: =+IFERROR(HLOOKUP($B22,'[2]7월'!$F$6:$CP$99,16,),)/1000 -> 72.104996 | V22: =+U22-T22 -> 3.9024349 | W22: =+IFERROR(HLOOKUP($B22,'[3]7월'!$F$6:$CC$57,16,),)/1000 -> 120.92349 | X22: =+U22-W22 -> -48.81849 | Y22: =+[4]원주!$Q$85 -> 112000 | Z22: =+[4]원주!$R$85 -> 108145.04 | AA22: =+[5]원주!$Q$85 -> 114543.58 | AB22: =+[4]원주!$Q$89 -> 73134.72 | AC22: =+[4]원주!$R$89 -> 69467.388 | AD22: =+[5]원주!$Q$89 -> 75019.456 | AE22: =+Y22-AB22 -> 38865.28 | AF22: =+Z22-AC22 -> 38677.655 | AG22: =+AA22-AD22 -> 39524.12
B23: 제주 | F23: =+K27-J27 -> -59.1535 | G23: =+I23 -> 제주 | I23: 제주 | J23: =+IFERROR(HLOOKUP($B23,'[1]7월'!$D$6:$BN$259,2,),)/1000 -> 9 | K23: =+IFERROR(HLOOKUP($B23,'[2]7월'!$F$6:$CP$99,2,),)/1000 -> 6.2985 | L23: =+K23-J23 -> -2.7015 | M23: =+IFERROR(HLOOKUP($B23,'[3]7월'!$F$6:$CC$57,2,),)/1000 -> 3.9015 | N23: =+K23-M23 -> 2.397 | O23: =+IFERROR(HLOOKUP($B23,'[1]7월'!$D$6:$BN$259,3,),)/1000 -> 1106.96 | P23: =+IFERROR(HLOOKUP($B23,'[2]7월'!$F$6:$CP$99,3,),)/1000 -> 774.41358 | Q23: =+P23-O23 -> -332.54642 | R23: =+IFERROR(HLOOKUP($B23,'[3]7월'!$F$6:$CC$57,3,),)/1000 -> 478.87041 | S23: =+P23-R23 -> 295.54317 | T23: =+IFERROR(HLOOKUP($B23,'[1]7월'!$D$6:$BN$259,16,),)/1000 -> 185.95373 | U23: =+IFERROR(HLOOKUP($B23,'[2]7월'!$F$6:$CP$99,16,),)/1000 -> 87.827914 | V23: =+U23-T23 -> -98.125816 | W23: =+IFERROR(HLOOKUP($B23,'[3]7월'!$F$6:$CC$57,16,),)/1000 -> 28.988095 | X23: =+U23-W23 -> 58.839819 | Y23: =+[4]제주!$Q$85 -> 122995.56 | Z23: =+[4]제주!$R$85 -> 123104.52 | AA23: =+[5]제주!$Q$85 -> 122740.08 | AB23: =+[4]제주!$Q$89 -> 91386.196 | AC23: =+[4]제주!$R$89 -> 94176.91 | AD23: =+[5]제주!$Q$89 -> 92008.574 | AE23: =+Y23-AB23 -> 31609.36 | AF23: =+Z23-AC23 -> 28927.608 | AG23: =+AA23-AD23 -> 30731.502
F24: =+K24/J24 -> 0.72931776 | G24: =+I24 -> 수도권 | I24: 수도권 | J24: =SUM(J7:J10) -> 107 | K24: =SUM(K7:K10) -> 78.037 | L24: =+K24-J24 -> -28.963 | M24: =SUM(M7:M10) -> 89.348 | N24: =+K24-M24 -> -11.311 | O24: =SUM(O7:O10) -> 10427.816 | P24: =SUM(P7:P10) -> 7543.3891 | Q24: =+P24-O24 -> -2884.4264 | R24: =SUM(R7:R10) -> 8822.025 | S24: =+P24-R24 -> -1278.6358 | T24: =SUM(T7:T10) -> 809.68496 | U24: =SUM(U7:U10) -> 262.21208 | V24: =+U24-T24 -> -547.47288 | W24: =SUM(W7:W10) -> 662.28354 | X24: =+U24-W24 -> -400.07146 | Y24: =+[4]수도권!$Q$85 -> 97456.22 | Z24: =+[4]수도권!$R$85 -> 96700.299 | AA24: =+[5]수도권!$Q$85 -> 98771.936 | AB24: =+[4]수도권!$Q$89 -> 80329.838 | AC24: =+[4]수도권!$R$89 -> 80151.577 | AD24: =+[5]수도권!$Q$89 -> 80778.956 | AE24: =+Y24-AB24 -> 17126.382 | AF24: =+Z24-AC24 -> 16548.722 | AG24: =+AA24-AD24 -> 17992.981
F25: =+K25/J25 -> 0.87062551 | G25: =+I25 -> 영남권 | I25: 영남권 | J25: =SUM(J11:J18) -> 121.5 | K25: =SUM(K11:K18) -> 105.781 | L25: =+K25-J25 -> -15.719 | M25: =SUM(M11:M18) -> 118.756 | N25: =+K25-M25 -> -12.975 | O25: =SUM(O11:O18) -> 12219.37 | P25: =SUM(P11:P18) -> 10453.727 | Q25: =+P25-O25 -> -1765.6434 | R25: =SUM(R11:R18) -> 12139.999 | S25: =+P25-R25 -> -1686.2722 | T25: =SUM(T11:T18) -> 1139.0335 | U25: =SUM(U11:U18) -> 781.46222 | V25: =+U25-T25 -> -357.57133 | W25: =SUM(W11:W18) -> 1231.838 | X25: =+U25-W25 -> -450.37581 | Y25: =+[4]영남권!$Q$85 -> 100570.95 | Z25: =+[4]영남권!$R$85 -> 98825.474 | AA25: =+[5]영남권!$Q$85 -> 102226.32 | AB25: =+[4]영남권!$Q$89 -> 78801.612 | AC25: =+[4]영남권!$R$89 -> 78319.845 | AD25: =+[5]영남권!$Q$89 -> 79508.547 | AE25: =+Y25-AB25 -> 21769.337 | AF25: =+Z25-AC25 -> 20505.629 | AG25: =+AA25-AD25 -> 22717.772
F26: =+K26/J26 -> 0.73925225 | G26: =+I26 -> 중부권 | I26: 중부권 | J26: =SUM(J19:J23) -> 55.5 | K26: =SUM(K19:K23) -> 41.0285 | L26: =+K26-J26 -> -14.4715 | M26: =SUM(M19:M23) -> 48.5535 | N26: =+K26-M26 -> -7.525 | O26: =SUM(O19:O23) -> 5956.8712 | P26: =SUM(P19:P23) -> 4213.024 | Q26: =+P26-O26 -> -1743.8472 | R26: =SUM(R19:R23) -> 5177.2093 | S26: =+P26-R26 -> -964.18529 | T26: =SUM(T19:T23) -> 956.96748 | U26: =SUM(U19:U23) -> 333.525 | V26: =+U26-T26 -> -623.44248 | W26: =SUM(W19:W23) -> 830.87596 | X26: =+U26-W26 -> -497.35096 | Y26: =+[4]중부권!$Q$85 -> 107331.01 | Z26: =+[4]중부권!$R$85 -> 102649.88 | AA26: =+[5]중부권!$Q$85 -> 106628.96 | AB26: =+[4]중부권!$Q$89 -> 77985.477 | AC26: =+[4]중부권!$R$89 -> 78876.524 | AD26: =+[5]중부권!$Q$89 -> 76226.154 | AE26: =+Y26-AB26 -> 29345.536 | AF26: =+Z26-AC26 -> 23773.356 | AG26: =+AA26-AD26 -> 30402.808
F27: =+K27/M27 -> 0.87605661 | G27: =+K27/J27 -> 0.79171303 | H27: 레미콘 계 | J27: =SUM(J24:J26) -> 284 | K27: =SUM(K24:K26) -> 224.8465 | L27: =+K27-J27 -> -59.1535 | M27: =SUM(M24:M26) -> 256.6575 | N27: =+K27-M27 -> -31.811 | O27: =SUM(O24:O26) -> 28604.057 | P27: =SUM(P24:P26) -> 22210.14 | Q27: =+P27-O27 -> -6393.9169 | R27: =SUM(R24:R26) -> 26139.233 | S27: =+P27-R27 -> -3929.0934 | T27: =SUM(T24:T26) -> 2905.686 | U27: =SUM(U24:U26) -> 1377.1993 | V27: =+U27-T27 -> -1528.4867 | W27: =SUM(W24:W26) -> 2724.9975 | X27: =+U27-W27 -> -1347.7982 | Y27: =+[4]합계!$Q$85 -> 100718.51 | Z27: =+[4]합계!$R$85 -> 98789.633 | AA27: =+[5]합계!$Q$85 -> 101862.36 | AB27: =+[4]합계!$Q$89 -> 79217.896 | AC27: =+[4]합계!$R$89 -> 79053.551 | AD27: =+[5]합계!$Q$89 -> 79327.273 | AE27: =+Y27-AB27 -> 21500.615 | AF27: =+Z27-AC27 -> 19736.082 | AG27: =+AA27-AD27 -> 22535.083 | AI27: =+AF27-AE27 -> -1764.533 | AJ27: =+AF27-AG27 -> -2799.001
B28: 건자재 | E28: 건자재영업 | G28: 건자재 | H28: 건자재 | J28: =+IFERROR(HLOOKUP($B28,'[1]7월'!$D$6:$BN$259,2,),) -> 13500 | K28: =+IFERROR(HLOOKUP($E28,'[2]7월'!$F$6:$CP$99,2,),) -> 7798.862 | L28: =+K28-J28 -> -5701.138 | M28: =+IFERROR(HLOOKUP($E28,'[3]7월'!$F$6:$CC$57,2,),) -> 12986.91 | N28: =+K28-M28 -> -5188.048 | O28: =+IFERROR(HLOOKUP($B28,'[1]7월'!$D$6:$BN$259,3,),)/1000 -> 14694.152 | P28: =+IFERROR(HLOOKUP($E28,'[2]7월'!$F$6:$CP$99,3,),)/1000 -> 7354.8666 | Q28: =+P28-O28 -> -7339.2858 | R28: =+IFERROR(HLOOKUP($E28,'[3]7월'!$F$6:$CC$57,3,),)/1000 -> 11314.649 | S28: =+P28-R28 -> -3959.782 | T28: =+IFERROR(HLOOKUP($B28,'[1]7월'!$D$6:$BN$259,16,),)/1000 -> 273.52857 | U28: =+IFERROR(HLOOKUP($E28,'[2]7월'!$F$6:$CP$99,16,),)/1000 -> -46.822892 | V28: =+U28-T28 -> -320.35146 | W28: =+IFERROR(HLOOKUP($E28,'[3]7월'!$F$6:$CC$57,16,),)/1000 -> -39.569616 | X28: =+U28-W28 -> -7.253276 | Y28: ■ 비고
B29: 부산모래장 | C29: 부산골재 | G29: =+I29 -> 부산모래장 | H29: 골재 | I29: 부산모래장 | J29: =+IFERROR(HLOOKUP($B29,'[1]7월'!$D$6:$BN$259,2,),)/1000 -> 24.308476 | K29: =+IFERROR(HLOOKUP($C29,'[2]7월'!$F$6:$CP$99,2,),)/1000 -> 23.993 | L29: =+K29-J29 -> -0.31547635 | M29: =+IFERROR(HLOOKUP($C29,'[3]7월'!$F$6:$CC$57,2,),)/1000 -> 14.977 | N29: =+K29-M29 -> 9.016 | O29: =+IFERROR(HLOOKUP($B29,'[1]7월'!$D$6:$BN$259,3,),)/1000 -> 662.58299 | P29: =+IFERROR(HLOOKUP($C29,'[2]7월'!$F$6:$CP$99,3,),)/1000 -> 674.2855 | Q29: =+P29-O29 -> 11.702515 | R29: =+IFERROR(HLOOKUP($C29,'[3]7월'!$F$6:$CC$57,3,),)/1000 -> 424.8905 | S29: =+P29-R29 -> 249.395 | T29: =+IFERROR(HLOOKUP($B29,'[1]7월'!$D$6:$BN$259,21,),)/1000 -> 50.948055 | U29: =+IFERROR(HLOOKUP($C29,'[2]7월'!$F$6:$CP$99,21,),)/1000 -> 27.624891 | V29: =+U29-T29 -> -23.323163 | W29: =+IFERROR(HLOOKUP($C29,'[3]7월'!$F$6:$CC$57,21,),)/1000 -> 64.377342 | X29: =+U29-W29 -> -36.752451 | Y29: - 7월 판가 1군 마이너스 계산서 0.4억(164원/㎥↓)
B30: 서부산크라샤 | C30: 서부산골재 | G30: =+I30 -> 서부산CR | I30: 서부산CR | J30: =+IFERROR(HLOOKUP($B30,'[1]7월'!$D$6:$BN$259,2,),)/1000 -> 42.648757 | K30: =+IFERROR(HLOOKUP($C30,'[2]7월'!$F$6:$CP$99,2,),)/1000 -> 25.238 | L30: =+K30-J30 -> -17.410757 | M30: =+IFERROR(HLOOKUP($C30,'[3]7월'!$F$6:$CC$57,2,),)/1000 -> 10.47 | N30: =+K30-M30 -> 14.768 | O30: =+IFERROR(HLOOKUP($B30,'[1]7월'!$D$6:$BN$259,3,),)/1000 -> 629.91451 | P30: =+IFERROR(HLOOKUP($C30,'[2]7월'!$F$6:$CP$99,3,),)/1000 -> 333.336 | Q30: =+P30-O30 -> -296.57851 | R30: =+IFERROR(HLOOKUP($C30,'[3]7월'!$F$6:$CC$57,3,),)/1000 -> 168.03 | S30: =+P30-R30 -> 165.306 | T30: =+IFERROR(HLOOKUP($B30,'[1]7월'!$D$6:$BN$259,21,),)/1000 -> 91.000835 | U30: =+IFERROR(HLOOKUP($C30,'[2]7월'!$F$6:$CP$99,21,),)/1000 -> 12.022306 | V30: =+U30-T30 -> -78.978529 | W30: =+IFERROR(HLOOKUP($C30,'[3]7월'!$F$6:$CC$57,21,),)/1000 -> -61.232674 | X30: =+U30-W30 -> 73.25498 | Y30: - 운반비 협상
B31: 부산크라샤 | C31: 부산크라샤 | G31: =+I31 -> 부산CR | I31: 부산CR | J31: =+IFERROR(HLOOKUP($B31,'[1]7월'!$D$6:$BN$259,2,),)/1000 -> 39.403208 | K31: =+IFERROR(HLOOKUP($C31,'[2]7월'!$F$6:$CP$99,2,),)/1000 -> 16.538 | L31: =+K31-J31 -> -22.865208 | M31: =+IFERROR(HLOOKUP($C31,'[3]7월'!$F$6:$CC$57,2,),)/1000 -> 35.515 | N31: =+K31-M31 -> -18.977 | O31: =+IFERROR(HLOOKUP($B31,'[1]7월'!$D$6:$BN$259,3,),)/1000 -> 672.27198 | P31: =+IFERROR(HLOOKUP($C31,'[2]7월'!$F$6:$CP$99,3,),)/1000 -> 330.019 | Q31: =+P31-O31 -> -342.25298 | R31: =+IFERROR(HLOOKUP($C31,'[3]7월'!$F$6:$CC$57,3,),)/1000 -> 648.4025 | S31: =+P31-R31 -> -318.3835 | T31: =+IFERROR(HLOOKUP($B31,'[1]7월'!$D$6:$BN$259,21,),)/1000 -> 72.157845 | U31: =+IFERROR(HLOOKUP($C31,'[2]7월'!$F$6:$CP$99,21,),)/1000 -> -136.92205 | V31: =+U31-T31 -> -209.0799 | W31: =+IFERROR(HLOOKUP($C31,'[3]7월'!$F$6:$CC$57,21,),)/1000 -> -113.70134 | X31: =+U31-W31 -> -23.220714 | Y31: 아산 : 3,600원/회(1년 계약)
H32: 골재 계 | J32: =SUM(J29:J31) -> 106.36044 | K32: =SUM(K29:K31) -> 65.769 | L32: =+K32-J32 -> -40.591441 | M32: =SUM(M29:M31) -> 60.962 | N32: =+K32-M32 -> 4.807 | O32: =SUM(O29:O31) -> 1964.7695 | P32: =SUM(P29:P31) -> 1337.6405 | Q32: =+P32-O32 -> -627.12897 | R32: =SUM(R29:R31) -> 1241.323 | S32: =+P32-R32 -> 96.3175 | T32: =SUM(T29:T31) -> 214.10673 | U32: =SUM(U29:U31) -> -97.274854 | V32: =+U32-T32 -> -311.38159 | W32: =SUM(W29:W31) -> -110.55667 | X32: =+U32-W32 -> 13.281816 | Y32: 원주 : 2,000원/회(1년 계약)
B33: 포항임대 | C33: 속초임대 | D33: 강릉임대 | E33: 레미콘임대 계 | G33: =+I33 -> 레미콘임대 | H33: 기타 | I33: 레미콘임대 | L33: =+K33-J33 -> 0 | N33: =+K33-M33 -> 0 | O33: =(IFERROR(HLOOKUP($B33,'[1]7월'!$D$6:$BN$259,3,),)++IFERROR(HLOOKUP($C33,'[1]7월'!$D$6:$BN$259,3,),)+IFERROR(HLOOKUP($D33,'[1]7월'!$D$6:$BN$259,3,),))/1000 -> 66.666667 | P33: =+IFERROR(HLOOKUP($E33,'[2]7월'!$F$6:$CP$99,3,),)/1000 -> 43.34 | Q33: =+P33-O33 -> -23.326667 | R33: =+IFERROR(HLOOKUP($E33,'[3]7월'!$F$6:$CC$57,3,),)/1000 -> 90.84 | S33: =+P33-R33 -> -47.5 | T33: =(IFERROR(HLOOKUP($B33,'[1]7월'!$D$6:$BN$259,21,),)++IFERROR(HLOOKUP($C33,'[1]7월'!$D$6:$BN$259,21,),)+IFERROR(HLOOKUP($D33,'[1]7월'!$D$6:$BN$259,21,),))/1000 -> 48.278888 | U33: =+IFERROR(HLOOKUP($E33,'[2]7월'!$F$6:$CP$99,16,),)/1000 -> 23.255776 | V33: =+U33-T33 -> -25.023112 | W33: =+IFERROR(HLOOKUP($E33,'[3]7월'!$F$6:$CC$57,16,),)/1000 -> 72.53547 | X33: =+U33-W33 -> -49.279694 | Y33: 대구 : 1,500원/회(1년 계약)
B34: 부동산임대 | C34: 주유소임대 | E34: 임대 계 | G34: =+I34 -> 임대 | I34: 임대 | L34: =+K34-J34 -> 0 | M34: 0 | N34: =+K34-M34 -> 0 | O34: =(+IFERROR(HLOOKUP($B34,'[1]7월'!$D$6:$BN$259,3,),)+IFERROR(HLOOKUP($C34,'[1]7월'!$D$6:$BN$259,3,),))/1000 -> 74.0915 | P34: =+IFERROR(HLOOKUP($E34,'[2]7월'!$F$6:$CP$99,3,),)/1000 -> 73.779592 | Q34: =+P34-O34 -> -0.311908 | R34: =+IFERROR(HLOOKUP($E34,'[3]7월'!$F$6:$CC$57,3,),)/1000 -> 72.793153 | S34: =+P34-R34 -> 0.986439 | T34: =(+IFERROR(HLOOKUP($B34,'[1]7월'!$D$6:$BN$259,21,),)+IFERROR(HLOOKUP($C34,'[1]7월'!$D$6:$BN$259,21,),))/1000 -> 63.941 | U34: =+IFERROR(HLOOKUP($E34,'[2]7월'!$F$6:$CP$99,16,),)/1000 -> 66.530123 | V34: =+U34-T34 -> 2.589123 | W34: =+IFERROR(HLOOKUP($E34,'[3]7월'!$F$6:$CC$57,16,),)/1000 -> 62.661397 | X34: =+U34-W34 -> 3.868726 | Y34: 군산 : 2,500원/회(2년 계약완료, 25년 2,500원, 26년 3,500원)
B35: 공 통 비 | G35: =+I35 -> 공통비 | I35: 공통비 | L35: =+K35-J35 -> 0 | N35: =+K35-M35 -> 0 | Q35: =+P35-O35 -> 0 | S35: =+P35-R35 -> 0 | T35: =-'[1]7월'!$Z$22/1000 -> -1373.93 | U35: =+-'[2]7월'!$Z$22/1000 -> -1353.2625 | V35: =+U35-T35 -> 20.667534 | W35: =+-'[3]7월'!$Z$22/1000 -> -1338.4279 | X35: =+U35-W35 -> -14.834581
G36: =+I36 -> OPC 소급분 | I36: OPC 소급분 | N36: =+K36-M36 -> 0 | Q36: =+P36-O36 -> 0 | S36: =+P36-R36 -> 0 | U36: ='[2]7월'!$BD$26/1000 -> 0 | V36: =+U36-T36 -> 0 | W36: =-'[3]7월'!$BD$26/1000 -> 0 | X36: =+U36-W36 -> 0
G37: =+I37 -> 대손 | I37: 대손 | N37: =+K37-M37 -> 0 | Q37: =+P37-O37 -> 0 | S37: =+P37-R37 -> 0 | U37: ='[2]7월'!$BE$26/1000 -> 0 | V37: =+U37-T37 -> 0 | W37: ='[3]7월'!$BE$26/1000 -> 0 | X37: =+U37-W37 -> 0
G38: =+I38 -> 미운영 공장 | I38: 미운영 공장 | M38: =SUM(M54:M59) -> 0 | N38: =+K38-M38 -> 0 | Q38: =+P38-O38 -> 0 | R38: =+IFERROR(HLOOKUP($I$38,'[3]7월'!$F$6:$BJ$50,3,),)/1000 -> 0 | S38: =+P38-R38 -> 0 | T38: =SUM('[1]7월'!$AM$26:$AQ$26)/1000 -> -32.543496 | U38: =+'[2]7월'!$BF$26/1000 -> -31.873744 | V38: =+U38-T38 -> 0.669752 | W38: =+'[3]7월'!$BF$26/1000 -> -34.386782 | X38: =+U38-W38 -> 2.513038
B39: 기타 계 | G39: =+I39 -> 퇴직위로금 | I39: 퇴직위로금 | U39: =+'[2]7월'!$BG$26/1000 -> 0 | V39: =+U39-T39 -> 0 | X39: =+U39-W39 -> 0
G40: =+I40 -> 기타 | I40: 기타 | L40: =+K40-J40 -> 0 | N40: =+K40-M40 -> 0 | O40: =IFERROR(HLOOKUP($B39,'[1]7월'!$D$6:$BN$259,3,),)/1000 -> 1.77 | P40: =+('[2]7월'!$F$8-SUM('[2]7월'!$Z$8,'[2]7월'!$AH$8,'[2]7월'!$AN$8,'[2]7월'!$AO$8,'[2]7월'!$BA$8,'[2]7월'!$BD$8,'[2]7월'!$BE$8,'[2]7월'!$BF$8))/1000 -> 1.6874 | Q40: =+P40-O40 -> -0.0826 | R40: =+('[3]7월'!$F$8-SUM('[3]7월'!$Z$8,'[3]7월'!$AH$8,'[3]7월'!$AN$8,'[3]7월'!$AO$8,'[3]7월'!$BA$8,'[3]7월'!$BD$8,'[3]7월'!$BE$8,'[3]7월'!$BF$8))/1000 -> 1.8162 | S40: =+P40-R40 -> -0.1288 | T40: =+('[1]7월'!$E$26-'[1]7월'!$Z$26-'[1]7월'!$AA$26-'[1]7월'!$AE$26-'[1]7월'!$AL$26-'[1]7월'!$AM$26-'[1]7월'!$AN$26-'[1]7월'!$AO$26-'[1]7월'!$AP$26-'[1]7월'!$AQ$26-'[1]7월'!$AS$26+'[1]7월'!$AS$26)/1000 -> -85.138375 | U40: =+('[2]7월'!$F$26-SUM('[2]7월'!$Z$26,'[2]7월'!$AH$26,'[2]7월'!$AN$26,'[2]7월'!$AO$26,'[2]7월'!$BA$26,'[2]7월'!$BD$26,'[2]7월'!$BE$26,'[2]7월'!$BF$26))/1000-U39 -> -15.378696 | V40: =+U40-T40 -> 69.759679 | W40: =+('[3]7월'!$F$26-SUM('[3]7월'!$Z$26,'[3]7월'!$AH$26,'[3]7월'!$AN$26,'[3]7월'!$AO$26,'[3]7월'!$BA$26,'[3]7월'!$BD$26,'[3]7월'!$BE$26,'[3]7월'!$BF$26))/1000 -> -16.756545 | X40: =+U40-W40 -> 1.377849
H41: 기타 계 | J41: =SUM(J33:J40) -> 0 | K41: =SUM(K33:K40) -> 0 | L41: =+K41-J41 -> 0 | M41: =SUM(M33:M40) -> 0 | N41: =+K41-M41 -> 0 | O41: =SUM(O33:O40) -> 142.52817 | P41: =SUM(P33:P40) -> 118.80699 | Q41: =+P41-O41 -> -23.721175 | R41: =SUM(R33:R40) -> 165.44935 | S41: =+P41-R41 -> -46.642361 | T41: =SUM(T33:T40) -> -1379.392 | U41: =SUM(U33:U40) -> -1310.729 | V41: =+U41-T41 -> 68.662976 | W41: =SUM(W33:W40) -> -1254.3743 | X41: =+U41-W41 -> -56.354662
U42: 19 | V42: 12.4
...

Sheet 사업장별(누계)
H3: □ 사업장별 손익실적(2025-07누계)
AG4: [단위 : 천㎥, 톤, 백만원]
H5: 구분 | J5: 물량 | O5: 매출 | T5: 영업이익(공통비 배부전) | Y5: 판매단가 | AB5: 변동비 | AE5: 공헌이익
A6: 2024년 7월누계 마감 손익 | J6: 계획 | K6: 실적 | L6: 차이 | M6: 전년 | N6: 차이 | O6: 계획 | P6: 실적 | Q6: 차이 | R6: 전년 | S6: 차이 | T6: 계획 | U6: 실적 | V6: 차이 | W6: 전년 | X6: 차이 | Y6: 계획 | Z6: 실적 | AA6: 전년 | AB6: 계획 | AC6: 실적 | AD6: 전년 | AE6: 계획 | AF6: 실적 | AG6: 전년
B7: 안양 | G7: =+I7 -> 안양 | H7: 레미콘 | I7: 안양 | J7: =+IFERROR(HLOOKUP($B7,'[1]7월누계'!$D$6:$BN$259,2,),)/1000 -> 262 | K7: =+IFERROR(HLOOKUP($B7,'[2]7월누계'!$F$6:$CP$99,2,),)/1000 -> 238.107 | L7: =+K7-J7 -> -23.893 | M7: =+IFERROR(HLOOKUP($B7,'[3]7월누계'!$F$6:$CC$57,2,),)/1000 -> 276.832 | N7: =+K7-M7 -> -38.725 | O7: =+IFERROR(HLOOKUP($B7,'[1]7월누계'!$D$6:$BN$259,3,),)/1000 -> 25720.807 | P7: =+IFERROR(HLOOKUP($B7,'[2]7월누계'!$F$6:$CP$99,3,),)/1000 -> 22856.8 | Q7: =+P7-O7 -> -2864.0071 | R7: =+IFERROR(HLOOKUP($B7,'[3]7월누계'!$F$6:$CC$57,3,),)/1000 -> 27548.945 | S7: =+P7-R7 -> -4692.1445 | T7: =+IFERROR(HLOOKUP($B7,'[1]7월누계'!$D$6:$BN$259,16,),)/1000 -> 2065.5085 | U7: =+IFERROR(HLOOKUP($B7,'[2]7월누계'!$F$6:$CP$99,16,),)/1000 -> 1602.4604 | V7: =+U7-T7 -> -463.04812 | W7: =+IFERROR(HLOOKUP($B7,'[3]7월누계'!$F$6:$CC$57,16,),)/1000 -> 2836.6772 | X7: =+U7-W7 -> -1234.2168 | Y7: =+[12]안양!$Q$85 -> 98171.02 | Z7: =+[12]안양!$R$85 -> 95976.652 | AA7: =+[13]안양!$Q$85 -> 99509.44 | AB7: =+[12]안양!$Q$89 -> 81855.034 | AC7: =+[12]안양!$R$89 -> 79900.868 | AD7: =+[13]안양!$Q$89 -> 81474.35 | AE7: =+Y7-AB7 -> 16315.986 | AF7: =+Z7-AC7 -> 16075.785 | AG7: =+AA7-AD7 -> 18035.089
B8: 인천 | G8: =+I8 -> 인천 | H8: 직영 | I8: 인천 | J8: =+IFERROR(HLOOKUP($B8,'[1]7월누계'!$D$6:$BN$259,2,),)/1000 -> 192 | K8: =+IFERROR(HLOOKUP($B8,'[2]7월누계'!$F$6:$CP$99,2,),)/1000 -> 192.278 | L8: =+K8-J8 -> 0.278 | M8: =+IFERROR(HLOOKUP($B8,'[3]7월누계'!$F$6:$CC$57,2,),)/1000 -> 198.784 | N8: =+K8-M8 -> -6.506 | O8: =+IFERROR(HLOOKUP($B8,'[1]7월누계'!$D$6:$BN$259,3,),)/1000 -> 18797.024 | P8: =+IFERROR(HLOOKUP($B8,'[2]7월누계'!$F$6:$CP$99,3,),)/1000 -> 18805.492 | Q8: =+P8-O8 -> 8.4681561 | R8: =+IFERROR(HLOOKUP($B8,'[3]7월누계'!$F$6:$CC$57,3,),)/1000 -> 19919.822 | S8: =+P8-R8 -> -1114.3298 | T8: =+IFERROR(HLOOKUP($B8,'[1]7월누계'!$D$6:$BN$259,16,),)/1000 -> 704.44751 | U8: =+IFERROR(HLOOKUP($B8,'[2]7월누계'!$F$6:$CP$99,16,),)/1000 -> 384.92254 | V8: =+U8-T8 -> -319.52497 | W8: =+IFERROR(HLOOKUP($B8,'[3]7월누계'!$F$6:$CC$57,16,),)/1000 -> 1595.2455 | X8: =+U8-W8 -> -1210.3229 | Y8: =+[12]인천!$Q$85 -> 97901.166 | Z8: =+[12]인천!$R$85 -> 97861.93 | AA8: =+[13]인천!$Q$85 -> 100212.69 | AB8: =+[12]인천!$Q$89 -> 82953.62 | AC8: =+[12]인천!$R$89 -> 84274.322 | AD8: =+[13]인천!$Q$89 -> 82061.112 | AE8: =+Y8-AB8 -> 14947.546 | AF8: =+Z8-AC8 -> 13587.608 | AG8: =+AA8-AD8 -> 18151.578
B9: 파주 | G9: =+I9 -> 파주 | I9: 파주 | J9: =+IFERROR(HLOOKUP($B9,'[1]7월누계'!$D$6:$BN$259,2,),)/1000 -> 139 | K9: =+IFERROR(HLOOKUP($B9,'[2]7월누계'!$F$6:$CP$99,2,),)/1000 -> 83.38 | L9: =+K9-J9 -> -55.62 | M9: =+IFERROR(HLOOKUP($B9,'[3]7월누계'!$F$6:$CC$57,2,),)/1000 -> 179.2342 | N9: =+K9-M9 -> -95.8542 | O9: =+IFERROR(HLOOKUP($B9,'[1]7월누계'!$D$6:$BN$259,3,),)/1000 -> 13405.925 | P9: =+IFERROR(HLOOKUP($B9,'[2]7월누계'!$F$6:$CP$99,3,),)/1000 -> 7735.3402 | Q9: =+P9-O9 -> -5670.5846 | R9: =+IFERROR(HLOOKUP($B9,'[3]7월누계'!$F$6:$CC$57,3,),)/1000 -> 17607.835 | S9: =+P9-R9 -> -9872.4951 | T9: =+IFERROR(HLOOKUP($B9,'[1]7월누계'!$D$6:$BN$259,16,),)/1000 -> 637.7155 | U9: =+IFERROR(HLOOKUP($B9,'[2]7월누계'!$F$6:$CP$99,16,),)/1000 -> -311.44205 | V9: =+U9-T9 -> -949.15755 | W9: =+IFERROR(HLOOKUP($B9,'[3]7월누계'!$F$6:$CC$57,16,),)/1000 -> 1402.3446 | X9: =+U9-W9 -> -1713.7867 | Y9: =+[12]파주!$Q$85 -> 96445.503 | Z9: =+[12]파주!$R$85 -> 92821.253 | AA9: =+[13]파주!$Q$85 -> 98269.313 | AB9: =+[12]파주!$Q$89 -> 79769.978 | AC9: =+[12]파주!$R$89 -> 78082.604 | AD9: =+[13]파주!$Q$89 -> 81410.232 | AE9: =+Y9-AB9 -> 16675.525 | AF9: =+Z9-AC9 -> 14738.65 | AG9: =+AA9-AD9 -> 16859.082
B10: 김포 | G10: =+I10 -> 김포 | I10: 김포 | J10: =+IFERROR(HLOOKUP($B10,'[1]7월누계'!$D$6:$BN$259,2,),)/1000 -> 95 | K10: =+IFERROR(HLOOKUP($B10,'[2]7월누계'!$F$6:$CP$99,2,),)/1000 -> 69.554 | L10: =+K10-J10 -> -25.446 | M10: =+IFERROR(HLOOKUP($B10,'[3]7월누계'!$F$6:$CC$57,2,),)/1000 -> 82.2805 | N10: =+K10-M10 -> -12.7265 | O10: =+IFERROR(HLOOKUP($B10,'[1]7월누계'!$D$6:$BN$259,3,),)/1000 -> 9018.9341 | P10: =+IFERROR(HLOOKUP($B10,'[2]7월누계'!$F$6:$CP$99,3,),)/1000 -> 6657.3694 | Q10: =+P10-O10 -> -2361.5647 | R10: =+IFERROR(HLOOKUP($B10,'[3]7월누계'!$F$6:$CC$57,3,),)/1000 -> 8108.7848 | S10: =+P10-R10 -> -1451.4154 | T10: =+IFERROR(HLOOKUP($B10,'[1]7월누계'!$D$6:$BN$259,16,),)/1000 -> 550.53059 | U10: =+IFERROR(HLOOKUP($B10,'[2]7월누계'!$F$6:$CP$99,16,),)/1000 -> 16.401495 | V10: =+U10-T10 -> -534.1291 | W10: =+IFERROR(HLOOKUP($B10,'[3]7월누계'!$F$6:$CC$57,16,),)/1000 -> 763.64576 | X10: =+U10-W10 -> -747.24426 | Y10: =+[12]김포!$Q$85 -> 94936.149 | Z10: =+[12]김포!$R$85 -> 95769.731 | AA10: =+[13]김포!$Q$85 -> 98569.378 | AB10: =+[12]김포!$Q$89 -> 76178.317 | AC10: =+[12]김포!$R$89 -> 78006.543 | AD10: =+[13]김포!$Q$89 -> 75733.317 | AE10: =+Y10-AB10 -> 18757.832 | AF10: =+Z10-AC10 -> 17763.188 | AG10: =+AA10-AD10 -> 22836.061
B11: 부산 | G11: =+I11 -> 부산 | I11: 부산 | J11: =+IFERROR(HLOOKUP($B11,'[1]7월누계'!$D$6:$BN$259,2,),)/1000 -> 140 | K11: =+IFERROR(HLOOKUP($B11,'[2]7월누계'!$F$6:$CP$99,2,),)/1000 -> 138.107 | L11: =+K11-J11 -> -1.893 | M11: =+IFERROR(HLOOKUP($B11,'[3]7월누계'!$F$6:$CC$57,2,),)/1000 -> 149.3065 | N11: =+K11-M11 -> -11.1995 | O11: =+IFERROR(HLOOKUP($B11,'[1]7월누계'!$D$6:$BN$259,3,),)/1000 -> 15077.994 | P11: =+IFERROR(HLOOKUP($B11,'[2]7월누계'!$F$6:$CP$99,3,),)/1000 -> 14905.965 | Q11: =+P11-O11 -> -172.02952 | R11: =+IFERROR(HLOOKUP($B11,'[3]7월누계'!$F$6:$CC$57,3,),)/1000 -> 15984.323 | S11: =+P11-R11 -> -1078.358 | T11: =+IFERROR(HLOOKUP($B11,'[1]7월누계'!$D$6:$BN$259,16,),)/1000 -> 1270.7247 | U11: =+IFERROR(HLOOKUP($B11,'[2]7월누계'!$F$6:$CP$99,16,),)/1000 -> 1469.7138 | V11: =+U11-T11 -> 198.98914 | W11: =+IFERROR(HLOOKUP($B11,'[3]7월누계'!$F$6:$CC$57,16,),)/1000 -> 1711.0912 | X11: =+U11-W11 -> -241.37739 | Y11: =+[12]부산!$Q$85 -> 107699.96 | Z11: =+[12]부산!$R$85 -> 107930.55 | AA11: =+[13]부산!$Q$85 -> 107057.11 | AB11: =+[12]부산!$Q$89 -> 84790.768 | AC11: =+[12]부산!$R$89 -> 84408.626 | AD11: =+[13]부산!$Q$89 -> 83555.495 | AE11: =+Y11-AB11 -> 22909.191 | AF11: =+Z11-AC11 -> 23521.926 | AG11: =+AA11-AD11 -> 23501.618
B12: 서부산 | G12: =+I12 -> 서부산 | I12: 서부산 | J12: =+IFERROR(HLOOKUP($B12,'[1]7월누계'!$D$6:$BN$259,2,),)/1000 -> 137 | K12: =+IFERROR(HLOOKUP($B12,'[2]7월누계'!$F$6:$CP$99,2,),)/1000 -> 114.501 | L12: =+K12-J12 -> -22.499 | M12: =+IFERROR(HLOOKUP($B12,'[3]7월누계'!$F$6:$CC$57,2,),)/1000 -> 156.642 | N12: =+K12-M12 -> -42.141 | O12: =+IFERROR(HLOOKUP($B12,'[1]7월누계'!$D$6:$BN$259,3,),)/1000 -> 13604.104 | P12: =+IFERROR(HLOOKUP($B12,'[2]7월누계'!$F$6:$CP$99,3,),)/1000 -> 11209.827 | Q12: =+P12-O12 -> -2394.2771 | R12: =+IFERROR(HLOOKUP($B12,'[3]7월누계'!$F$6:$CC$57,3,),)/1000 -> 15865.3 | S12: =+P12-R12 -> -4655.4733 | T12: =+IFERROR(HLOOKUP($B12,'[1]7월누계'!$D$6:$BN$259,16,),)/1000 -> 1218.2429 | U12: =+IFERROR(HLOOKUP($B12,'[2]7월누계'!$F$6:$CP$99,16,),)/1000 -> 735.26145 | V12: =+U12-T12 -> -482.98147 | W12: =+IFERROR(HLOOKUP($B12,'[3]7월누계'!$F$6:$CC$57,16,),)/1000 -> 1886.5928 | X12: =+U12-W12 -> -1151.3314 | Y12: =+[12]서부산!$Q$85 -> 99300.031 | Z12: =+[12]서부산!$R$85 -> 97959.792 | AA12: =+[13]서부산!$Q$85 -> 101283.39 | AB12: =+[12]서부산!$Q$89 -> 78366.732 | AC12: =+[12]서부산!$R$89 -> 77494.779 | AD12: =+[13]서부산!$Q$89 -> 79088.307 | AE12: =+Y12-AB12 -> 20933.299 | AF12: =+Z12-AC12 -> 20465.013 | AG12: =+AA12-AD12 -> 22195.087
B13: 김해 | G13: =+I13 -> 김해 | I13: 김해 | J13: =+IFERROR(HLOOKUP($B13,'[1]7월누계'!$D$6:$BN$259,2,),)/1000 -> 95 | K13: =+IFERROR(HLOOKUP($B13,'[2]7월누계'!$F$6:$CP$99,2,),)/1000 -> 62.116 | L13: =+K13-J13 -> -32.884 | M13: =+IFERROR(HLOOKUP($B13,'[3]7월누계'!$F$6:$CC$57,2,),)/1000 -> 91.09 | N13: =+K13-M13 -> -28.974 | O13: =+IFERROR(HLOOKUP($B13,'[1]7월누계'!$D$6:$BN$259,3,),)/1000 -> 9148.4915 | P13: =+IFERROR(HLOOKUP($B13,'[2]7월누계'!$F$6:$CP$99,3,),)/1000 -> 5574.2964 | Q13: =+P13-O13 -> -3574.1951 | R13: =+IFERROR(HLOOKUP($B13,'[3]7월누계'!$F$6:$CC$57,3,),)/1000 -> 8849.638 | S13: =+P13-R13 -> -3275.3416 | T13: =+IFERROR(HLOOKUP($B13,'[1]7월누계'!$D$6:$BN$259,16,),)/1000 -> 784.88632 | U13: =+IFERROR(HLOOKUP($B13,'[2]7월누계'!$F$6:$CP$99,16,),)/1000 -> -177.90697 | V13: =+U13-T13 -> -962.79328 | W13: =+IFERROR(HLOOKUP($B13,'[3]7월누계'!$F$6:$CC$57,16,),)/1000 -> 582.39447 | X13: =+U13-W13 -> -760.30144 | Y13: =+[12]김해!$Q$85 -> 96299.911 | Z13: =+[12]김해!$R$85 -> 89711.732 | AA13: =+[13]김해!$Q$85 -> 97228.123 | AB13: =+[12]김해!$Q$89 -> 76562.794 | AC13: =+[12]김해!$R$89 -> 76181.251 | AD13: =+[13]김해!$Q$89 -> 79599.415 | AE13: =+Y13-AB13 -> 19737.117 | AF13: =+Z13-AC13 -> 13530.481 | AG13: =+AA13-AD13 -> 17628.708
B14: 정관 | G14: =+I14 -> 정관 | I14: 정관 | J14: =+IFERROR(HLOOKUP($B14,'[1]7월누계'!$D$6:$BN$259,2,),)/1000 -> 133 | K14: =+IFERROR(HLOOKUP($B14,'[2]7월누계'!$F$6:$CP$99,2,),)/1000 -> 150.3365 | L14: =+K14-J14 -> 17.3365 | M14: =+IFERROR(HLOOKUP($B14,'[3]7월누계'!$F$6:$CC$57,2,),)/1000 -> 139.6315 | N14: =+K14-M14 -> 10.705 | O14: =+IFERROR(HLOOKUP($B14,'[1]7월누계'!$D$6:$BN$259,3,),)/1000 -> 13565.975 | P14: =+IFERROR(HLOOKUP($B14,'[2]7월누계'!$F$6:$CP$99,3,),)/1000 -> 15024.61 | Q14: =+P14-O14 -> 1458.6345 | R14: =+IFERROR(HLOOKUP($B14,'[3]7월누계'!$F$6:$CC$57,3,),)/1000 -> 14219.548 | S14: =+P14-R14 -> 805.06232 | T14: =+IFERROR(HLOOKUP($B14,'[1]7월누계'!$D$6:$BN$259,16,),)/1000 -> 1103.5651 | U14: =+IFERROR(HLOOKUP($B14,'[2]7월누계'!$F$6:$CP$99,16,),)/1000 -> 1306.7956 | V14: =+U14-T14 -> 203.23058 | W14: =+IFERROR(HLOOKUP($B14,'[3]7월누계'!$F$6:$CC$57,16,),)/1000 -> 1378.9305 | X14: =+U14-W14 -> -72.134852 | Y14: =+[12]정관!$Q$85 -> 101999.82 | Z14: =+[12]정관!$R$85 -> 99962.445 | AA14: =+[13]정관!$Q$85 -> 101836.25 | AB14: =+[12]정관!$Q$89 -> 82131.322 | AC14: =+[12]정관!$R$89 -> 81907.244 | AD14: =+[13]정관!$Q$89 -> 81998.953 | AE14: =+Y14-AB14 -> 19868.493 | AF14: =+Z14-AC14 -> 18055.201 | AG14: =+AA14-AD14 -> 19837.292
