Workbook

Sheet 표지
A6: 2025년 3월 마감 손익
A24: 건재사업본부

Sheet 손익총괄
C3: □ 건재사업본부 손익실적(2025-03)
X4: [단위 : 천㎥, 톤, 원/㎥, 원/톤, 백만원]
C5: 구분 | E5: 3월 | J5: 3월 누계 | P5: 3월 주요지표
A6: 2024년 12월 마감 손익 | E6: 계획 | F6: 실적 | G6: 계획대비 | H6: 전년 | I6: 전년대비 | J6: 계획 | K6: 실적 | L6: 계획대비 | M6: 전년 | N6: 전년대비
A7: =+F7/E7 -> 0.97409158 | B7: =+K7/J7 -> 0.92586351 | C7: 물량 | D7: 레미콘 | E7: =+'[1]3월'!$Z$7/1000 -> 273 | F7: =+'[2]3월'!$Z$7/1000 -> 265.927 | G7: =+F7-E7 -> -7.073 | H7: =+'[3]3월'!$Z$7/1000 -> 298.4865 | I7: =+F7-H7 -> -32.5595 | J7: =+'[1]3월누계'!$Z$7/1000 -> 707 | K7: =+'[2]3월누계'!$Z$7/1000 -> 654.5855 | L7: =+K7-J7 -> -52.4145 | M7: =+'[3]3월누계'!$Z$7/1000 -> 794.9285 | N7: =+K7-M7 -> -140.343 | Q7: □ 레미콘
D8: 철강재 | E8: =+'[1]3월'!$AA$7 -> 10200 | F8: =+'[2]3월'!$AO$7 -> 15762.77 | G8: =+F8-E8 -> 5562.77 | H8: =+'[3]3월'!$AO$7 -> 8665.068 | I8: =+F8-H8 -> 7097.702 | J8: =+'[1]3월누계'!$AA$7 -> 30200 | K8: =+'[2]3월누계'!$AO$7 -> 34222.795 | L8: =+K8-J8 -> 4022.795 | M8: =+'[3]3월누계'!$AO$7 -> 21735.563 | N8: =+K8-M8 -> 12487.232 | Q8: 구분 | S8: 계획 | T8: 실적 | U8: 계획대비 | V8: 전년 | W8: 전년대비
D9: 골재 | E9: =+'[1]3월'!$AE$7/1000 -> 78.27623 | F9: =+'[2]3월'!$AN$7/1000 -> 61.211 | G9: =+F9-E9 -> -17.06523 | H9: =+'[3]3월'!$AN$7/1000 -> 84.928 | I9: =+F9-H9 -> -23.717 | J9: =+'[1]3월누계'!$AE$7/1000 -> 243.46672 | K9: =+'[2]3월누계'!$AN$7/1000 -> 167.4 | L9: =+K9-J9 -> -76.066716 | M9: =+'[3]3월누계'!$AN$7/1000 -> 234.717 | N9: =+K9-M9 -> -67.317 | Q9: 물량 | R9: 수도권 | S9: =+[4]수도권!$T$5/1000 -> 101 | T9: =+[4]수도권!$U$5/1000 -> 93.47 | U9: =+T9-S9 -> -7.53 | V9: =+[5]수도권!$T$5/1000 -> 110.047 | W9: =+T9-V9 -> -16.577
C10: 매출 | D10: 레미콘 | E10: =+'[1]3월'!$Z$8/1000 -> 27398.711 | F10: =+'[2]3월'!$Z$8/1000 -> 25879.148 | G10: =+F10-E10 -> -1519.563 | H10: =+'[3]3월'!$Z$8/1000 -> 30505.252 | I10: =+F10-H10 -> -4626.1043 | J10: =+'[1]3월누계'!$Z$8/1000 -> 71035.473 | K10: =+'[2]3월누계'!$Z$8/1000 -> 64876.307 | L10: =+K10-J10 -> -6159.1659 | M10: =+'[3]3월누계'!$Z$8/1000 -> 80602.44 | N10: =+K10-M10 -> -15726.133 | R10: 영남권 | S10: =+[4]영남권!$T$5/1000 -> 120.5 | T10: =+[4]영남권!$U$5/1000 -> 117.338 | U10: =+T10-S10 -> -3.162 | V10: =+[5]영남권!$T$5/1000 -> 134.5 | W10: =+T10-V10 -> -17.162
D11: 건자재 | E11: =+'[1]3월'!$AA$8/1000 -> 11165.946 | F11: =+'[2]3월'!$AO$8/1000 -> 12535.229 | G11: =+F11-E11 -> 1369.2831 | H11: =+'[3]3월'!$AO$8/1000 -> 8759.9178 | I11: =+F11-H11 -> 3775.3109 | J11: =+'[1]3월누계'!$AA$8/1000 -> 33063.214 | K11: =+'[2]3월누계'!$AO$8/1000 -> 28292.343 | L11: =+K11-J11 -> -4770.8704 | M11: =+'[3]3월누계'!$AO$8/1000 -> 22933.533 | N11: =+K11-M11 -> 5358.8106 | R11: 중부권 | S11: =+[4]중부권!$T$5/1000 -> 51.5 | T11: =+[4]중부권!$U$5/1000 -> 55.119 | U11: =+T11-S11 -> 3.619 | V11: =+[5]중부권!$T$5/1000 -> 53.9395 | W11: =+T11-V11 -> 1.1795
D12: 골재 | E12: =+'[1]3월'!$AE$8/1000 -> 1269.7349 | F12: =+'[2]3월'!$AN$8/1000 -> 1283.417 | G12: =+F12-E12 -> 13.682068 | H12: =+'[3]3월'!$AN$8/1000 -> 1765.0027 | I12: =+F12-H12 -> -481.58567 | J12: =+'[1]3월누계'!$AE$8/1000 -> 4504.8187 | K12: =+'[2]3월누계'!$AN$8/1000 -> 3577.7485 | L12: =+K12-J12 -> -927.0702 | M12: =+'[3]3월누계'!$AN$8/1000 -> 4781.6092 | N12: =+K12-M12 -> -1203.8607 | Q12: 계 | S12: =SUM(S9:S11) -> 273 | T12: =SUM(T9:T11) -> 265.927 | U12: =+T12-S12 -> -7.073 | V12: =SUM(V9:V11) -> 298.4865 | W12: =+T12-V12 -> -32.5595
D13: 기타 | E13: =+'[1]3월'!$E$8/1000-E10-E11-E12 -> 166.7015 | F13: =+'[2]3월'!$F$8/1000-F10-F11-F12 -> 141.06233 | G13: =+F13-E13 -> -25.639173 | H13: =+'[3]3월'!$F$8/1000-H10-H11-H12 -> 164.55387 | I13: =+F13-H13 -> -23.491541 | J13: =+'[1]3월누계'!$E$8/1000-J10-J11-J12 -> 500.1045 | K13: =+'[2]3월누계'!$F$8/1000-K10-K11-K12 -> 472.83429 | L13: =+K13-J13 -> -27.270206 | M13: =+'[3]3월누계'!$F$8/1000-M10-M11-M12 -> 493.55454 | N13: =+K13-M13 -> -20.720244 | Q13: 판매단가 | R13: 수도권 | S13: =+[4]수도권!$T$61 -> 97002.569 | T13: =+[4]수도권!$U$61 -> 93007.036 | U13: =+T13-S13 -> -3995.5331 | V13: =+[5]수도권!$Q$85 -> 101292.86 | W13: =+T13-V13 -> -8285.8283
A14: =+F14/E14 -> 0.99594419 | B14: =+K14/J14 -> 0.89107256 | C14: 계 | E14: =SUM(E10:E13) -> 40001.093 | F14: =SUM(F10:F13) -> 39838.856 | G14: =+F14-E14 -> -162.237 | H14: =SUM(H10:H13) -> 41194.726 | I14: =+F14-H14 -> -1355.8707 | J14: =SUM(J10:J13) -> 109103.61 | K14: =SUM(K10:K13) -> 97219.234 | L14: =+K14-J14 -> -11884.377 | M14: =SUM(M10:M13) -> 108811.14 | N14: =+K14-M14 -> -11591.903 | R14: 영남권 | S14: =+[4]영남권!$T$61 -> 100667.16 | T14: =+[4]영남권!$U$61 -> 98256.721 | U14: =+T14-S14 -> -2410.4355 | V14: =+[5]영남권!$Q$85 -> 101364.13 | W14: =+T14-V14 -> -3107.4046
C15: 매출원가 | D15: 레미콘 | E15: =+('[1]3월'!$Z$10+'[1]3월'!$Z$19)/1000 -> 24508.882 | F15: =+('[2]3월'!$Z$10+'[2]3월'!$Z$19)/1000 -> 23517.883 | G15: =+F15-E15 -> -990.99855 | H15: =+('[3]3월'!$Z$10+'[3]3월'!$Z$19)/1000 -> 26174.702 | I15: =+F15-H15 -> -2656.819 | J15: =+('[1]3월누계'!$Z$10+'[1]3월누계'!$Z$19)/1000 -> 64667.198 | K15: =+('[2]3월누계'!$Z$10+'[2]3월누계'!$Z$19)/1000 -> 60218.076 | L15: =+K15-J15 -> -4449.1222 | M15: =+('[3]3월누계'!$Z$10+'[3]3월누계'!$Z$19)/1000 -> 70916.899 | N15: =+K15-M15 -> -10698.823 | R15: 중부권 | S15: =+[4]중부권!$T$61 -> 106234.15 | T15: =+[4]중부권!$U$61 -> 102574.02 | U15: =+T15-S15 -> -3660.1367 | V15: =+[5]중부권!$Q$85 -> 106231.06 | W15: =+T15-V15 -> -3657.0489
D16: 건자재 | E16: =+('[1]3월'!$AA$10+'[1]3월'!$AA$19)/1000 -> 10864.469 | F16: =+('[2]3월'!$AO$10+'[2]3월'!$AO$19)/1000 -> 12498.384 | G16: =+F16-E16 -> 1633.9153 | H16: =+('[3]3월'!$AO$10+'[3]3월'!$AO$19)/1000 -> 8596.6222 | I16: =+F16-H16 -> 3901.7619 | J16: =+('[1]3월누계'!$AA$10+'[1]3월누계'!$AA$19)/1000 -> 32170.12 | K16: =+('[2]3월누계'!$AO$10+'[2]3월누계'!$AO$19)/1000 -> 27959.927 | L16: =+K16-J16 -> -4210.1925 | M16: =+('[3]3월누계'!$AO$10+'[3]3월누계'!$AO$19)/1000 -> 22399.724 | N16: =+K16-M16 -> 5560.2029 | Q16: 계 | S16: =+[4]합계!$T$61 -> 100361.58 | T16: =+[4]합계!$U$61 -> 97314.829 | U16: =+T16-S16 -> -3046.7487 | V16: =+[5]합계!$Q$85 -> 102216.11 | W16: =+T16-V16 -> -4901.2824
D17: 골재 | E17: =+('[1]3월'!$AE$10+'[1]3월'!$AE$19)/1000 -> 1212.6048 | F17: =+('[2]3월'!$AN$10+'[2]3월'!$AN$19)/1000 -> 1364.7504 | G17: =+F17-E17 -> 152.14559 | H17: =+('[3]3월'!$AN$10+'[3]3월'!$AN$19)/1000 -> 1564.4598 | I17: =+F17-H17 -> -199.70936 | J17: =+('[1]3월누계'!$AE$10+'[1]3월누계'!$AE$19)/1000 -> 3999.7427 | K17: =+('[2]3월누계'!$AN$10+'[2]3월누계'!$AN$19)/1000 -> 3941.0665 | L17: =+K17-J17 -> -58.6762 | M17: =+('[3]3월누계'!$AN$10+'[3]3월누계'!$AN$19)/1000 -> 4229.3105 | N17: =+K17-M17 -> -288.24398 | Q17: 공헌이익 | R17: 수도권 | S17: =+[4]수도권!$Q$90 -> 15550.625 | T17: =+[4]수도권!$R$90 -> 12300.18 | U17: =+T17-S17 -> -3250.4445 | V17: =+[5]수도권!$Q$90 -> 19077.909 | W17: =+T17-V17 -> -6777.7289
D18: 기타 | E18: =+('[1]3월'!$E$10+'[1]3월'!$E$19)/1000-E15-E16-E17 -> 52.494339 | F18: =+('[2]3월'!$F$10+'[2]3월'!$F$19)/1000-F15-F16-F17 -> 22.176476 | G18: =+F18-E18 -> -30.317863 | H18: =+('[3]3월'!$F$10+'[3]3월'!$F$19)/1000-H15-H16-H17 -> 14.536916 | I18: =+F18-H18 -> 7.63956 | J18: =+('[1]3월누계'!$E$10+'[1]3월누계'!$E$19)/1000-J15-J16-J17 -> 109.3829 | K18: =+('[2]3월누계'!$F$10+'[2]3월누계'!$F$19)/1000-K15-K16-K17 -> 381.60009 | L18: =+K18-J18 -> 272.21719 | M18: =+('[3]3월누계'!$F$10+'[3]3월누계'!$F$19)/1000-M15-M16-M17 -> 71.47703 | N18: =+K18-M18 -> 310.12306 | R18: 영남권 | S18: =+[4]영남권!$Q$90 -> 21640.406 | T18: =+[4]영남권!$R$90 -> 20424.307 | U18: =+T18-S18 -> -1216.0995 | V18: =+[5]영남권!$Q$90 -> 22198.4 | W18: =+T18-V18 -> -1774.0929
C19: 계 | E19: =SUM(E15:E18) -> 36638.45 | F19: =SUM(F15:F18) -> 37403.194 | G19: =+F19-E19 -> 764.74448 | H19: =SUM(H15:H18) -> 36350.321 | I19: =+F19-H19 -> 1052.8731 | J19: =SUM(J15:J18) -> 100946.44 | K19: =SUM(K15:K18) -> 92500.67 | L19: =+K19-J19 -> -8445.7738 | M19: =SUM(M15:M18) -> 97617.411 | N19: =+K19-M19 -> -5116.741 | R19: 중부권 | S19: =+[4]중부권!$Q$90 -> 27345.93 | T19: =+[4]중부권!$R$90 -> 21953.416 | U19: =+T19-S19 -> -5392.5136 | V19: =+[5]중부권!$Q$90 -> 29414.592 | W19: =+T19-V19 -> -7461.1758
C20: 매출이익 | D20: 레미콘 | E20: =+E10-E15 -> 2889.8289 | F20: =+F10-F15 -> 2361.2644 | G20: =+F20-E20 -> -528.56448 | H20: =+H10-H15 -> 4330.5497 | I20: =+F20-H20 -> -1969.2853 | J20: =+J10-J15 -> 6368.2752 | K20: =+K10-K15 -> 4658.2316 | L20: =+K20-J20 -> -1710.0436 | M20: =+M10-M15 -> 9685.5416 | N20: =+K20-M20 -> -5027.31 | Q20: 계 | S20: =+[4]합계!$Q$90 -> 20463.727 | T20: =+[4]합계!$R$90 -> 17907.066 | U20: =+T20-S20 -> -2556.6607 | V20: =+[5]합계!$Q$90 -> 22348.202 | W20: =+T20-V20 -> -4441.1361
D21: 건자재 | E21: =+E11-E16 -> 301.47673 | F21: =+F11-F16 -> 36.844564 | G21: =+F21-E21 -> -264.63216 | H21: =+H11-H16 -> 163.29556 | I21: =+F21-H21 -> -126.45099 | J21: =+J11-J16 -> 893.09396 | K21: =+K11-K16 -> 332.4161 | L21: =+K21-J21 -> -560.67786 | M21: =+M11-M16 -> 533.80844 | N21: =+K21-M21 -> -201.39234 | Q21: □ 건자재
D22: 골재 | E22: =+E12-E17 -> 57.130083 | F22: =+F12-F17 -> -81.333441 | G22: =+F22-E22 -> -138.46352 | H22: =+H12-H17 -> 200.54287 | I22: =+F22-H22 -> -281.87631 | J22: =+J12-J17 -> 505.07601 | K22: =+K12-K17 -> -363.31799 | L22: =+K22-J22 -> -868.394 | M22: =+M12-M17 -> 552.29871 | N22: =+K22-M22 -> -915.6167 | Q22: 구분 | S22: 계획 | T22: 실적 | U22: 계획대비 | V22: 전년 | W22: 전년대비
D23: 기타 | E23: =+E13-E18 -> 114.20716 | F23: =+F13-F18 -> 118.88585 | G23: =+F23-E23 -> 4.67869 | H23: =+H13-H18 -> 150.01695 | I23: =+F23-H23 -> -31.131101 | J23: =+J13-J18 -> 390.7216 | K23: =+K13-K18 -> 91.234206 | L23: =+K23-J23 -> -299.4874 | M23: =+M13-M18 -> 422.07751 | N23: =+K23-M23 -> -330.8433 | Q23: 철강재 판매단가 | S23: =+'[6]3월'!$F$10 -> 872058.82 | T23: =+'[6]3월'!$G$10 -> 736140.84 | U23: =+T23-S23 -> -135917.98 | V23: =+'[6]3월'!$G$10 -> 736140.84 | W23: =+T23-V23 -> 0
C24: 계 | E24: =SUM(E20:E23) -> 3362.6428 | F24: =SUM(F20:F23) -> 2435.6614 | G24: =+F24-E24 -> -926.98148 | H24: =SUM(H20:H23) -> 4844.4051 | I24: =+F24-H24 -> -2408.7437 | J24: =SUM(J20:J23) -> 8157.1668 | K24: =SUM(K20:K23) -> 4718.5639 | L24: =+K24-J24 -> -3438.6029 | M24: =SUM(M20:M23) -> 11193.726 | N24: =+K24-M24 -> -6475.1624 | Q24: 철강재 마진률 | S24: =+'[6]3월'!$F$15 -> 0.02394688 | T24: =+'[6]3월'!$G$15 -> 0.0014844908 | U24: =+T24-S24 -> -0.022462389 | V24: =+'[6]3월'!$G$15 -> 0.0014844908 | W24: =+T24-V24 -> 0
C25: 판관비 | D25: 레미콘 | E25: =+('[1]3월'!$Z$13+'[1]3월'!$Z$20)/1000 -> 683.8664 | F25: =+('[2]3월'!$Z$13+'[2]3월'!$Z$20)/1000 -> 668.37766 | G25: =+F25-E25 -> -15.48874 | H25: =+('[3]3월'!$Z$13+'[3]3월'!$Z$20)/1000 -> 638.65116 | I25: =+F25-H25 -> 29.726496 | J25: =+('[1]3월누계'!$Z$13+'[1]3월누계'!$Z$20)/1000 -> 2044.4603 | K25: =+('[2]3월누계'!$Z$13+'[2]3월누계'!$Z$20)/1000 -> 2000.234 | L25: =+K25-J25 -> -44.226358 | M25: =+('[3]3월누계'!$Z$13+'[3]3월누계'!$Z$20)/1000 -> 1972.154 | N25: =+K25-M25 -> 28.079915 | Q25: □ 골재
D26: 건자재 | E26: =+('[1]3월'!$AA$13+'[1]3월'!$AA$20)/1000 -> 136.58177 | F26: =+('[2]3월'!$AO$13+'[2]3월'!$AO$20)/1000 -> 155.71491 | G26: =+F26-E26 -> 19.133144 | H26: =+('[3]3월'!$AO$13+'[3]3월'!$AO$20)/1000 -> 131.64021 | I26: =+F26-H26 -> 24.0747 | J26: =+('[1]3월누계'!$AA$13+'[1]3월누계'!$AA$20)/1000 -> 389.21692 | K26: =+('[2]3월누계'!$AO$13+'[2]3월누계'!$AO$20)/1000 -> 438.72749 | L26: =+K26-J26 -> 49.510561 | M26: =+('[3]3월누계'!$AO$13+'[3]3월누계'!$AO$20)/1000 -> 385.04121 | N26: =+K26-M26 -> 53.686278 | Q26: 구분 | S26: 계획 | T26: 실적 | U26: 계획대비 | V26: 전년 | W26: 전년대비
D27: 골재 | E27: =+('[1]3월'!$AE$13+'[1]3월'!$AE$20+'[1]3월'!$AE$22)/1000 -> 46.973995 | F27: =+('[2]3월'!$AN$13+'[2]3월'!$AN$20+'[2]3월'!$AN$22)/1000 -> 45.48203 | G27: =+F27-E27 -> -1.4919647 | H27: =+('[3]3월'!$AN$13+'[3]3월'!$AN$20+'[3]3월'!$AN$22)/1000 -> 44.675271 | I27: =+F27-H27 -> 0.80675916 | J27: =+('[1]3월누계'!$AE$13+'[1]3월누계'!$AE$20+'[1]3월누계'!$AE$22)/1000 -> 143.84778 | K27: =+('[2]3월누계'!$AN$13+'[2]3월누계'!$AN$20+'[2]3월누계'!$AN$22)/1000 -> 141.72707 | L27: =+K27-J27 -> -2.1207043 | M27: =+('[3]3월누계'!$AN$13+'[3]3월누계'!$AN$20+'[3]3월누계'!$AN$22)/1000 -> 133.17802 | N27: =+K27-M27 -> 8.5490589 | Q27: 판매량 | R27: 자가 | S27: =(+'[7]서부산크라샤(당월)'!$W$66+'[7]부산모래장(당월)'!$Q$48+'[7]부산크라샤(당월)'!$T$66)/1000 -> 50.27613 | T27: =(+'[7]서부산크라샤(당월)'!$X$66+'[7]부산모래장(당월)'!$R$48+'[7]부산크라샤(당월)'!$U$66)/1000 -> 38.83 | U27: =+T27-S27 -> -11.44613 | V27: =+[8]손익총괄!$V$27 -> 34.244 | W27: =+T27-V27 -> 4.586
D28: 기타 | E28: =+('[1]3월'!$E$13+'[1]3월'!$E$20)/1000-E25-E26-E27+('[1]3월'!$E$22/1000) -> 1431.6335 | F28: =+('[2]3월'!$F$13+'[2]3월'!$F$20)/1000-F25-F26-F27+'[2]3월'!$F$22/1000 -> 1876.0986 | G28: =+F28-E28 -> 444.4651 | H28: =+('[3]3월'!$F$13+'[3]3월'!$F$20)/1000-H25-H26-H27+'[3]3월'!$F$22/1000 -> 3152.7443 | I28: =+F28-H28 -> -1276.6458 | J28: =+('[1]3월누계'!$E$13+'[1]3월누계'!$E$20)/1000-J25-J26-J27+('[1]3월누계'!$E$22/1000) -> 4531.2796 | K28: =+('[2]3월누계'!$F$13+'[2]3월누계'!$F$20)/1000-K25-K26-K27+'[2]3월누계'!$F$22/1000 -> 5347.2188 | L28: =+K28-J28 -> 815.93929 | M28: =+('[3]3월누계'!$F$13+'[3]3월누계'!$F$20)/1000-M25-M26-M27+'[3]3월누계'!$F$22/1000 -> 5552.3339 | N28: =+K28-M28 -> -205.11509 | R28: 외판 | S28: =(+'[7]서부산크라샤(당월)'!$W$59+'[7]부산모래장(당월)'!$Q$47+'[7]부산크라샤(당월)'!$T$59)/1000 -> 28 | T28: =(+'[7]서부산크라샤(당월)'!$X$59+'[7]부산모래장(당월)'!$R$47+'[7]부산크라샤(당월)'!$U$59)/1000 -> 17.491 | U28: =+T28-S28 -> -10.509 | V28: =+[8]손익총괄!$V$28 -> 22.216 | W28: =+T28-V28 -> -4.725
C29: 계 | E29: =SUM(E25:E28) -> 2299.0556 | F29: =SUM(F25:F28) -> 2745.6732 | G29: =+F29-E29 -> 446.61754 | H29: =SUM(H25:H28) -> 3967.711 | I29: =+F29-H29 -> -1222.0378 | J29: =SUM(J25:J28) -> 7108.8046 | K29: =SUM(K25:K28) -> 7927.9074 | L29: =+K29-J29 -> 819.10279 | M29: =SUM(M25:M28) -> 8042.7072 | N29: =+K29-M29 -> -114.79984 | Q29: 합 계 | S29: =SUM(S27:S28) -> 78.27613 | T29: =SUM(T27:T28) -> 56.321 | U29: =+T29-S29 -> -21.95513 | V29: =SUM(V27:V28) -> 56.46 | W29: =+T29-V29 -> -0.139
C30: 영업이익 | D30: 레미콘 | E30: =+E20-E25 -> 2205.9625 | F30: =+F20-F25 -> 1692.8867 | G30: =+F30-E30 -> -513.07574 | H30: =+H20-H25 -> 3691.8986 | I30: =+F30-H30 -> -1999.0118 | J30: =+J20-J25 -> 4323.8149 | K30: =+K20-K25 -> 2657.9976 | L30: =+K30-J30 -> -1665.8173 | M30: =+M20-M25 -> 7713.3876 | N30: =+K30-M30 -> -5055.3899 | Q30: □ 기타내역(영업이익)
D31: % | E31: =+E30/E10 -> 0.080513368 | F31: =+F30/F10 -> 0.065415089 | G31: =+F31-E31 -> -0.01509828 | H31: =+H30/H10 -> 0.12102501 | I31: =+F31-H31 -> -0.055609926 | J31: =+J30/J10 -> 0.06086839 | K31: =+K30/K10 -> 0.040970236 | L31: =+K31-J31 -> -0.019898154 | M31: =+M30/M10 -> 0.0956967 | N31: =+K31-M31 -> -0.054726464 | Q31: 구분 | S31: 계획 | T31: 실적 | U31: 계획대비 | V31: 전년 | W31: 전년대비
D32: 건자재 | E32: =+E21-E26 -> 164.89496 | F32: =+F21-F26 -> -118.87035 | G32: =+F32-E32 -> -283.76531 | H32: =+H21-H26 -> 31.655346 | I32: =+F32-H32 -> -150.52569 | J32: =+J21-J26 -> 503.87703 | K32: =+K21-K26 -> -106.31139 | L32: =+K32-J32 -> -610.18842 | M32: =+M21-M26 -> 148.76724 | N32: =+K32-M32 -> -255.07862 | Q32: 레미콘임대 | S32: =+'사업장별(당월)'!T33 -> 75.717537 | T32: =+'사업장별(당월)'!U33 -> 46.568992 | U32: =+T32-S32 -> -29.148545 | V32: =+'사업장별(당월)'!W33 -> 75.121657 | W32: =+T32-V32 -> -28.552665
D33: 골재 | E33: =+E22-E27 -> 10.156088 | F33: =+F22-F27 -> -126.81547 | G33: =+F33-E33 -> -136.97156 | H33: =+H22-H27 -> 155.8676 | I33: =+F33-H33 -> -282.68307 | J33: =+J22-J27 -> 361.22823 | K33: =+K22-K27 -> -505.04506 | L33: =+K33-J33 -> -866.27329 | M33: =+M22-M27 -> 419.12069 | N33: =+K33-M33 -> -924.16575 | Q33: 임대 | S33: =+'사업장별(당월)'!T34 -> 76.556944 | T33: =+'사업장별(당월)'!U34 -> 76.003665 | U33: =+T33-S33 -> -0.553279 | V33: =+'사업장별(당월)'!W34 -> 74.495595 | W33: =+T33-V33 -> 1.50807
D34: 기타 | E34: =+E23-E28 -> -1317.4263 | F34: =+F23-F28 -> -1757.2127 | G34: =+F34-E34 -> -439.78641 | H34: =+H23-H28 -> -3002.7274 | I34: =+F34-H34 -> 1245.5147 | J34: =+J23-J28 -> -4140.5579 | K34: =+K23-K28 -> -5255.9846 | L34: =+K34-J34 -> -1115.4267 | M34: =+M23-M28 -> -5130.2564 | N34: =+K34-M34 -> -125.72821 | Q34: 공통비 | S34: =+'사업장별(당월)'!T35 -> -1394.3694 | T34: =+'사업장별(당월)'!U35 -> -1338.7445 | U34: =+T34-S34 -> 55.624936 | V34: =+'사업장별(당월)'!W35 -> -1237.7949 | W34: =+T34-V34 -> -100.94957
C35: 계 | E35: =SUM(E30,E32:E34) -> 1063.5872 | F35: =SUM(F30,F32:F34) -> -310.01179 | G35: =+F35-E35 -> -1373.599 | H35: =SUM(H30,H32:H34) -> 876.69411 | I35: =+F35-H35 -> -1186.7059 | J35: =SUM(J30,J32:J34) -> 1048.3622 | K35: =SUM(K30,K32:K34) -> -3209.3435 | L35: =+K35-J35 -> -4257.7057 | M35: =SUM(M30,M32:M34) -> 3151.0191 | N35: =+K35-M35 -> -6360.3625 | Q35: 기타 | S35: =+S36-S32-S33-S34 -> -75.331363 | T35: =+T36-T32-T33-T34 -> -541.04088 | U35: =+T35-S35 -> -465.70952 | V35: =+V36-V32-V33-V34 -> -1914.5497 | W35: =+T35-V35 -> 1373.5089
D36: % | E36: =+E35/E14 -> 0.026588954 | F36: =+F35/F14 -> -0.0077816439 | G36: =+F36-E36 -> -0.034370598 | H36: =+H35/H14 -> 0.021281707 | I36: =+F36-H36 -> -0.029063351 | J36: =+J35/J14 -> 0.0096088683 | K36: =+K35/K14 -> -0.033011405 | L36: =+K36-J36 -> -0.042620273 | M36: =+M35/M14 -> 0.028958608 | N36: =+K36-M36 -> -0.061970013 | Q36: 합계 | S36: =+'사업장별(당월)'!T41 -> -1317.4263 | T36: =+'사업장별(당월)'!U41 -> -1757.2127 | U36: =+T36-S36 -> -439.78641 | V36: =+'사업장별(당월)'!W41 -> -3002.7274 | W36: =+T36-V36 -> 1245.5147
E38: =+'[1]3월'!$E$26/1000 -> 1063.5872 | F38: =+'[2]3월'!$F$26/1000 -> -310.01179 | H38: =+'[3]3월'!$F$26/1000 -> 876.69411 | J38: =+'[1]3월누계'!$E$26/1000 -> 1048.3622 | K38: =+'[2]3월누계'!$F$26/1000 -> -3209.3435 | M38: =+'[3]3월누계'!$F$26/1000 -> 3151.0191
E39: =+E35=E38 -> TRUE | F39: =+F35=F38 -> FALSE | H39: =+H35=H38 -> FALSE | J39: =+J35=J38 -> TRUE | K39: =+K35=K38 -> TRUE | M39: =+M35=M38 -> FALSE
E40: =+E35-E38 -> 0 | F40: =+F35-F38 -> 5.4001248e-12 | H40: =+H35-H38 -> 1.1368684e-12 | J40: =+J35-J38 -> 0 | K40: =+K35-K38 -> 0 | M40: =+M35-M38 -> -8.1854523e-12

Sheet 사업장별(당월)
H3: □ 사업장별 손익실적(2025-03)
AG4: [단위 : 천㎥, 톤, 백만원]
H5: 구분 | J5: 물량 | O5: 매출 | T5: 영업이익(공통비 배부전) | Y5: 판매단가 | AB5: 변동비 | AE5: 공헌이익
A6: 2024년 3월 마감 손익 | J6: 계획 | K6: 실적 | L6: 차이 | M6: 전년 | N6: 차이 | O6: 계획 | P6: 실적 | Q6: 차이 | R6: 전년 | S6: 차이 | T6: 계획 | U6: 실적 | V6: 차이 | W6: 전년 | X6: 차이 | Y6: 계획 | Z6: 실적 | AA6: 전년 | AB6: 계획 | AC6: 실적 | AD6: 전년 | AE6: 계획 | AF6: 실적 | AG6: 전년
B7: 안양 | G7: =+I7 -> 안양 | H7: 레미콘 | I7: 안양 | J7: =+IFERROR(HLOOKUP($B7,'[1]3월'!$D$6:$BN$259,2,),)/1000 -> 38 | K7: =+IFERROR(HLOOKUP($B7,'[2]3월'!$F$6:$CP$99,2,),)/1000 -> 38.108 | L7: =+K7-J7 -> 0.108 | M7: =+IFERROR(HLOOKUP($B7,'[3]3월'!$F$6:$CC$57,2,),)/1000 -> 40.978 | N7: =+K7-M7 -> -2.87 | O7: =+IFERROR(HLOOKUP($B7,'[1]3월'!$D$6:$BN$259,3,),)/1000 -> 3708.2155 | P7: =+IFERROR(HLOOKUP($B7,'[2]3월'!$F$6:$CP$99,3,),)/1000 -> 3546.3356 | Q7: =+P7-O7 -> -161.87988 | R7: =+IFERROR(HLOOKUP($B7,'[3]3월'!$F$6:$CC$57,3,),)/1000 -> 4078.3749 | S7: =+P7-R7 -> -532.03928 | T7: =+IFERROR(HLOOKUP($B7,'[1]3월'!$D$6:$BN$259,16,),)/1000 -> 264.43407 | U7: =+IFERROR(HLOOKUP($B7,'[2]3월'!$F$6:$CP$99,16,),)/1000 -> 190.6149 | V7: =+U7-T7 -> -73.819167 | W7: =+IFERROR(HLOOKUP($B7,'[3]3월'!$F$6:$CC$57,16,),)/1000 -> 402.62876 | X7: =+U7-W7 -> -212.01386 | Y7: =+[4]안양!$Q$85 -> 97584.619 | Z7: =+[4]안양!$R$85 -> 93013.191 | AA7: =+[5]안양!$Q$85 -> 99525.963 | AB7: =+[4]안양!$Q$89 -> 82379.79 | AC7: =+[4]안양!$R$89 -> 80028.849 | AD7: =+[5]안양!$Q$89 -> 82835.122 | AE7: =+Y7-AB7 -> 15204.829 | AF7: =+Z7-AC7 -> 12984.342 | AG7: =+AA7-AD7 -> 16690.841 | AJ7: 190.6149 | AK7: =+U7-AJ7 -> 0
B8: 인천 | G8: =+I8 -> 인천 | H8: 직영 | I8: 인천 | J8: =+IFERROR(HLOOKUP($B8,'[1]3월'!$D$6:$BN$259,2,),)/1000 -> 30 | K8: =+IFERROR(HLOOKUP($B8,'[2]3월'!$F$6:$CP$99,2,),)/1000 -> 32.763 | L8: =+K8-J8 -> 2.763 | M8: =+IFERROR(HLOOKUP($B8,'[3]3월'!$F$6:$CC$57,2,),)/1000 -> 31.816 | N8: =+K8-M8 -> 0.947 | O8: =+IFERROR(HLOOKUP($B8,'[1]3월'!$D$6:$BN$259,3,),)/1000 -> 2930.5965 | P8: =+IFERROR(HLOOKUP($B8,'[2]3월'!$F$6:$CP$99,3,),)/1000 -> 3135.3549 | Q8: =+P8-O8 -> 204.75844 | R8: =+IFERROR(HLOOKUP($B8,'[3]3월'!$F$6:$CC$57,3,),)/1000 -> 3319.8121 | S8: =+P8-R8 -> -184.45716 | T8: =+IFERROR(HLOOKUP($B8,'[1]3월'!$D$6:$BN$259,16,),)/1000 -> 93.223035 | U8: =+IFERROR(HLOOKUP($B8,'[2]3월'!$F$6:$CP$99,16,),)/1000 -> 97.876781 | V8: =+U8-T8 -> 4.6537461 | W8: =+IFERROR(HLOOKUP($B8,'[3]3월'!$F$6:$CC$57,16,),)/1000 -> 383.64319 | X8: =+U8-W8 -> -285.76641 | Y8: =+[4]인천!$Q$85 -> 97686.55 | Z8: =+[4]인천!$R$85 -> 95722.432 | AA8: =+[5]인천!$Q$85 -> 104344.11 | AB8: =+[4]인천!$Q$89 -> 83596.748 | AC8: =+[4]인천!$R$89 -> 84108.984 | AD8: =+[5]인천!$Q$89 -> 83563.84 | AE8: =+Y8-AB8 -> 14089.802 | AF8: =+Z8-AC8 -> 11613.448 | AG8: =+AA8-AD8 -> 20780.267 | AJ8: 97.876781 | AK8: =+U8-AJ8 -> 0
B9: 파주 | G9: =+I9 -> 파주 | I9: 파주 | J9: =+IFERROR(HLOOKUP($B9,'[1]3월'!$D$6:$BN$259,2,),)/1000 -> 18 | K9: =+IFERROR(HLOOKUP($B9,'[2]3월'!$F$6:$CP$99,2,),)/1000 -> 10.788 | L9: =+K9-J9 -> -7.212 | M9: =+IFERROR(HLOOKUP($B9,'[3]3월'!$F$6:$CC$57,2,),)/1000 -> 24.852 | N9: =+K9-M9 -> -14.064 | O9: =+IFERROR(HLOOKUP($B9,'[1]3월'!$D$6:$BN$259,3,),)/1000 -> 1740.7232 | P9: =+IFERROR(HLOOKUP($B9,'[2]3월'!$F$6:$CP$99,3,),)/1000 -> 908.57352 | Q9: =+P9-O9 -> -832.14971 | R9: =+IFERROR(HLOOKUP($B9,'[3]3월'!$F$6:$CC$57,3,),)/1000 -> 2542.437 | S9: =+P9-R9 -> -1633.8635 | T9: =+IFERROR(HLOOKUP($B9,'[1]3월'!$D$6:$BN$259,16,),)/1000 -> 61.356914 | U9: =+IFERROR(HLOOKUP($B9,'[2]3월'!$F$6:$CP$99,16,),)/1000 -> -148.3122 | V9: =+U9-T9 -> -209.66911 | W9: =+IFERROR(HLOOKUP($B9,'[3]3월'!$F$6:$CC$57,16,),)/1000 -> 246.07782 | X9: =+U9-W9 -> -394.39002 | Y9: =+[4]파주!$Q$85 -> 96706.846 | Z9: =+[4]파주!$R$85 -> 84220.756 | AA9: =+[5]파주!$Q$85 -> 102308.19 | AB9: =+[4]파주!$Q$89 -> 79798.662 | AC9: =+[4]파주!$R$89 -> 77980.048 | AD9: =+[5]파주!$Q$89 -> 83204.708 | AE9: =+Y9-AB9 -> 16908.184 | AF9: =+Z9-AC9 -> 6240.708 | AG9: =+AA9-AD9 -> 19103.481 | AJ9: -150.17249 | AK9: =+U9-AJ9 -> 1.860294
B10: 김포 | G10: =+I10 -> 김포 | I10: 김포 | J10: =+IFERROR(HLOOKUP($B10,'[1]3월'!$D$6:$BN$259,2,),)/1000 -> 15 | K10: =+IFERROR(HLOOKUP($B10,'[2]3월'!$F$6:$CP$99,2,),)/1000 -> 11.811 | L10: =+K10-J10 -> -3.189 | M10: =+IFERROR(HLOOKUP($B10,'[3]3월'!$F$6:$CC$57,2,),)/1000 -> 12.401 | N10: =+K10-M10 -> -0.59 | O10: =+IFERROR(HLOOKUP($B10,'[1]3월'!$D$6:$BN$259,3,),)/1000 -> 1417.7242 | P10: =+IFERROR(HLOOKUP($B10,'[2]3월'!$F$6:$CP$99,3,),)/1000 -> 1104.7602 | Q10: =+P10-O10 -> -312.96403 | R10: =+IFERROR(HLOOKUP($B10,'[3]3월'!$F$6:$CC$57,3,),)/1000 -> 1206.2439 | S10: =+P10-R10 -> -101.48377 | T10: =+IFERROR(HLOOKUP($B10,'[1]3월'!$D$6:$BN$259,16,),)/1000 -> 86.308698 | U10: =+IFERROR(HLOOKUP($B10,'[2]3월'!$F$6:$CP$99,16,),)/1000 -> 38.862012 | V10: =+U10-T10 -> -47.446686 | W10: =+IFERROR(HLOOKUP($B10,'[3]3월'!$F$6:$CC$57,16,),)/1000 -> 115.38405 | X10: =+U10-W10 -> -76.52204 | Y10: =+[4]김포!$Q$85 -> 94514.947 | Z10: =+[4]김포!$R$85 -> 93540.988 | AA10: =+[5]김포!$Q$85 -> 97269.892 | AB10: =+[4]김포!$Q$89 -> 76795.731 | AC10: =+[4]김포!$R$89 -> 75925.281 | AD10: =+[5]김포!$Q$89 -> 74721.474 | AE10: =+Y10-AB10 -> 17719.216 | AF10: =+Z10-AC10 -> 17615.707 | AG10: =+AA10-AD10 -> 22548.418 | AJ10: 38.862012 | AK10: =+U10-AJ10 -> 0
B11: 부산 | G11: =+I11 -> 부산 | I11: 부산 | J11: =+IFERROR(HLOOKUP($B11,'[1]3월'!$D$6:$BN$259,2,),)/1000 -> 21 | K11: =+IFERROR(HLOOKUP($B11,'[2]3월'!$F$6:$CP$99,2,),)/1000 -> 23.72 | L11: =+K11-J11 -> 2.72 | M11: =+IFERROR(HLOOKUP($B11,'[3]3월'!$F$6:$CC$57,2,),)/1000 -> 21.643 | N11: =+K11-M11 -> 2.077 | O11: =+IFERROR(HLOOKUP($B11,'[1]3월'!$D$6:$BN$259,3,),)/1000 -> 2261.7028 | P11: =+IFERROR(HLOOKUP($B11,'[2]3월'!$F$6:$CP$99,3,),)/1000 -> 2548.5624 | Q11: =+P11-O11 -> 286.85964 | R11: =+IFERROR(HLOOKUP($B11,'[3]3월'!$F$6:$CC$57,3,),)/1000 -> 2301.5966 | S11: =+P11-R11 -> 246.96578 | T11: =+IFERROR(HLOOKUP($B11,'[1]3월'!$D$6:$BN$259,16,),)/1000 -> 206.37935 | U11: =+IFERROR(HLOOKUP($B11,'[2]3월'!$F$6:$CP$99,16,),)/1000 -> 403.32277 | V11: =+U11-T11 -> 196.94342 | W11: =+IFERROR(HLOOKUP($B11,'[3]3월'!$F$6:$CC$57,16,),)/1000 -> 237.07459 | X11: =+U11-W11 -> 166.24818 | Y11: =+[4]부산!$Q$85 -> 107700.13 | Z11: =+[4]부산!$R$85 -> 107443.61 | AA11: =+[5]부산!$Q$85 -> 106343.7 | AB11: =+[4]부산!$Q$89 -> 84760.712 | AC11: =+[4]부산!$R$89 -> 80237.381 | AD11: =+[5]부산!$Q$89 -> 84400.455 | AE11: =+Y11-AB11 -> 22939.421 | AF11: =+Z11-AC11 -> 27206.229 | AG11: =+AA11-AD11 -> 21943.243 | AJ11: 431.4712 | AK11: =+U11-AJ11 -> -28.148422 | AL11: =199422/1000000 -> 0.199422 | AM11: =+AK11+AL11 -> -27.949
B12: 서부산 | G12: =+I12 -> 서부산 | I12: 서부산 | J12: =+IFERROR(HLOOKUP($B12,'[1]3월'!$D$6:$BN$259,2,),)/1000 -> 20 | K12: =+IFERROR(HLOOKUP($B12,'[2]3월'!$F$6:$CP$99,2,),)/1000 -> 17.535 | L12: =+K12-J12 -> -2.465 | M12: =+IFERROR(HLOOKUP($B12,'[3]3월'!$F$6:$CC$57,2,),)/1000 -> 23.104 | N12: =+K12-M12 -> -5.569 | O12: =+IFERROR(HLOOKUP($B12,'[1]3월'!$D$6:$BN$259,3,),)/1000 -> 1986.0058 | P12: =+IFERROR(HLOOKUP($B12,'[2]3월'!$F$6:$CP$99,3,),)/1000 -> 1689.652 | Q12: =+P12-O12 -> -296.35373 | R12: =+IFERROR(HLOOKUP($B12,'[3]3월'!$F$6:$CC$57,3,),)/1000 -> 2353.7109 | S12: =+P12-R12 -> -664.05888 | T12: =+IFERROR(HLOOKUP($B12,'[1]3월'!$D$6:$BN$259,16,),)/1000 -> 183.74819 | U12: =+IFERROR(HLOOKUP($B12,'[2]3월'!$F$6:$CP$99,16,),)/1000 -> 146.35766 | V12: =+U12-T12 -> -37.390532 | W12: =+IFERROR(HLOOKUP($B12,'[3]3월'!$F$6:$CC$57,16,),)/1000 -> 346.17788 | X12: =+U12-W12 -> -199.82023 | Y12: =+[4]서부산!$Q$85 -> 99300.288 | Z12: =+[4]서부산!$R$85 -> 96358.826 | AA12: =+[5]서부산!$Q$85 -> 101874.61 | AB12: =+[4]서부산!$Q$89 -> 78861.631 | AC12: =+[4]서부산!$R$89 -> 75437.947 | AD12: =+[5]서부산!$Q$89 -> 78936.836 | AE12: =+Y12-AB12 -> 20438.656 | AF12: =+Z12-AC12 -> 20920.879 | AG12: =+AA12-AD12 -> 22937.771 | AJ12: 144.86001 | AK12: =+U12-AJ12 -> 1.497645
B13: 김해 | G13: =+I13 -> 김해 | I13: 김해 | J13: =+IFERROR(HLOOKUP($B13,'[1]3월'!$D$6:$BN$259,2,),)/1000 -> 13 | K13: =+IFERROR(HLOOKUP($B13,'[2]3월'!$F$6:$CP$99,2,),)/1000 -> 12.503 | L13: =+K13-J13 -> -0.497 | M13: =+IFERROR(HLOOKUP($B13,'[3]3월'!$F$6:$CC$57,2,),)/1000 -> 14.128 | N13: =+K13-M13 -> -1.625 | O13: =+IFERROR(HLOOKUP($B13,'[1]3월'!$D$6:$BN$259,3,),)/1000 -> 1251.8957 | P13: =+IFERROR(HLOOKUP($B13,'[2]3월'!$F$6:$CP$99,3,),)/1000 -> 1140.8359 | Q13: =+P13-O13 -> -111.05985 | R13: =+IFERROR(HLOOKUP($B13,'[3]3월'!$F$6:$CC$57,3,),)/1000 -> 1362.6295 | S13: =+P13-R13 -> -221.7936 | T13: =+IFERROR(HLOOKUP($B13,'[1]3월'!$D$6:$BN$259,16,),)/1000 -> 101.5797 | U13: =+IFERROR(HLOOKUP($B13,'[2]3월'!$F$6:$CP$99,16,),)/1000 -> 55.355958 | V13: =+U13-T13 -> -46.223738 | W13: =+IFERROR(HLOOKUP($B13,'[3]3월'!$F$6:$CC$57,16,),)/1000 -> 100.67253 | X13: =+U13-W13 -> -45.316569 | Y13: =+[4]김해!$Q$85 -> 96299.673 | Z13: =+[4]김해!$R$85 -> 91228.592 | AA13: =+[5]김해!$Q$85 -> 96687.289 | AB13: =+[4]김해!$Q$89 -> 75819.874 | AC13: =+[4]김해!$R$89 -> 75407.766 | AD13: =+[5]김해!$Q$89 -> 79530.474 | AE13: =+Y13-AB13 -> 20479.799 | AF13: =+Z13-AC13 -> 15820.827 | AG13: =+AA13-AD13 -> 17156.814 | AJ13: 55.355958 | AK13: =+U13-AJ13 -> 0
B14: 정관 | G14: =+I14 -> 정관 | I14: 정관 | J14: =+IFERROR(HLOOKUP($B14,'[1]3월'!$D$6:$BN$259,2,),)/1000 -> 20 | K14: =+IFERROR(HLOOKUP($B14,'[2]3월'!$F$6:$CP$99,2,),)/1000 -> 19.81 | L14: =+K14-J14 -> -0.19 | M14: =+IFERROR(HLOOKUP($B14,'[3]3월'!$F$6:$CC$57,2,),)/1000 -> 20.677 | N14: =+K14-M14 -> -0.867 | O14: =+IFERROR(HLOOKUP($B14,'[1]3월'!$D$6:$BN$259,3,),)/1000 -> 2039.9916 | P14: =+IFERROR(HLOOKUP($B14,'[2]3월'!$F$6:$CP$99,3,),)/1000 -> 1937.8749 | Q14: =+P14-O14 -> -102.11673 | R14: =+IFERROR(HLOOKUP($B14,'[3]3월'!$F$6:$CC$57,3,),)/1000 -> 2137.7737 | S14: =+P14-R14 -> -199.89881 | T14: =+IFERROR(HLOOKUP($B14,'[1]3월'!$D$6:$BN$259,16,),)/1000 -> 175.64322 | U14: =+IFERROR(HLOOKUP($B14,'[2]3월'!$F$6:$CP$99,16,),)/1000 -> 121.8508 | V14: =+U14-T14 -> -53.792416 | W14: =+IFERROR(HLOOKUP($B14,'[3]3월'!$F$6:$CC$57,16,),)/1000 -> 246.30266 | X14: =+U14-W14 -> -124.45186 | Y14: =+[4]정관!$Q$85 -> 101999.58 | Z14: =+[4]정관!$R$85 -> 97823.064 | AA14: =+[5]정관!$Q$85 -> 103388.97 | AB14: =+[4]정관!$Q$89 -> 81893.772 | AC14: =+[4]정관!$R$89 -> 82325.942 | AD14: =+[5]정관!$Q$89 -> 82316.125 | AE14: =+Y14-AB14 -> 20105.809 | AF14: =+Z14-AC14 -> 15497.121 | AG14: =+AA14-AD14 -> 21072.843 | AJ14: 121.8508 | AK14: =+U14-AJ14 -> 0
B15: 양산 | G15: =+I15 -> 양산 | I15: 양산 | J15: =+IFERROR(HLOOKUP($B15,'[1]3월'!$D$6:$BN$259,2,),)/1000 -> 11 | K15: =+IFERROR(HLOOKUP($B15,'[2]3월'!$F$6:$CP$99,2,),)/1000 -> 9.625 | L15: =+K15-J15 -> -1.375 | M15: =+IFERROR(HLOOKUP($B15,'[3]3월'!$F$6:$CC$57,2,),)/1000 -> 13.47 | N15: =+K15-M15 -> -3.845 | O15: =+IFERROR(HLOOKUP($B15,'[1]3월'!$D$6:$BN$259,3,),)/1000 -> 1043.0943 | P15: =+IFERROR(HLOOKUP($B15,'[2]3월'!$F$6:$CP$99,3,),)/1000 -> 913.03398 | Q15: =+P15-O15 -> -130.06027 | R15: =+IFERROR(HLOOKUP($B15,'[3]3월'!$F$6:$CC$57,3,),)/1000 -> 1230.1273 | S15: =+P15-R15 -> -317.0933 | T15: =+IFERROR(HLOOKUP($B15,'[1]3월'!$D$6:$BN$259,16,),)/1000 -> 83.657618 | U15: =+IFERROR(HLOOKUP($B15,'[2]3월'!$F$6:$CP$99,16,),)/1000 -> 64.674861 | V15: =+U15-T15 -> -18.982757 | W15: =+IFERROR(HLOOKUP($B15,'[3]3월'!$F$6:$CC$57,16,),)/1000 -> 132.96661 | X15: =+U15-W15 -> -68.291748 | Y15: =+[4]양산!$Q$85 -> 94826.75 | Z15: =+[4]양산!$R$85 -> 94860.673 | AA15: =+[5]양산!$Q$85 -> 91323.48 | AB15: =+[4]양산!$Q$89 -> 74283.706 | AC15: =+[4]양산!$R$89 -> 72164.361 | AD15: =+[5]양산!$Q$89 -> 71355.878 | AE15: =+Y15-AB15 -> 20543.044 | AF15: =+Z15-AC15 -> 22696.312 | AG15: =+AA15-AD15 -> 19967.603 | AJ15: 64.674861 | AK15: =+U15-AJ15 -> 0
B16: 창원 | G16: =+I16 -> 창원 | I16: 창원 | J16: =+IFERROR(HLOOKUP($B16,'[1]3월'!$D$6:$BN$259,2,),)/1000 -> 11 | K16: =+IFERROR(HLOOKUP($B16,'[2]3월'!$F$6:$CP$99,2,),)/1000 -> 10.865 | L16: =+K16-J16 -> -0.135 | M16: =+IFERROR(HLOOKUP($B16,'[3]3월'!$F$6:$CC$57,2,),)/1000 -> 18.723 | N16: =+K16-M16 -> -7.858 | O16: =+IFERROR(HLOOKUP($B16,'[1]3월'!$D$6:$BN$259,3,),)/1000 -> 1100.0049 | P16: =+IFERROR(HLOOKUP($B16,'[2]3월'!$F$6:$CP$99,3,),)/1000 -> 1063.0202 | Q16: =+P16-O16 -> -36.984719 | R16: =+IFERROR(HLOOKUP($B16,'[3]3월'!$F$6:$CC$57,3,),)/1000 -> 1905.079 | S16: =+P16-R16 -> -842.05877 | T16: =+IFERROR(HLOOKUP($B16,'[1]3월'!$D$6:$BN$259,16,),)/1000 -> 59.751358 | U16: =+IFERROR(HLOOKUP($B16,'[2]3월'!$F$6:$CP$99,16,),)/1000 -> 89.749104 | V16: =+U16-T16 -> 29.997746 | W16: =+IFERROR(HLOOKUP($B16,'[3]3월'!$F$6:$CC$57,16,),)/1000 -> 321.83747 | X16: =+U16-W16 -> -232.08836 | Y16: =+[4]창원!$Q$85 -> 100000.45 | Z16: =+[4]창원!$R$85 -> 97838.954 | AA16: =+[5]창원!$Q$85 -> 101750.73 | AB16: =+[4]창원!$Q$89 -> 75686.622 | AC16: =+[4]창원!$R$89 -> 73565.78 | AD16: =+[5]창원!$Q$89 -> 74990.256 | AE16: =+Y16-AB16 -> 24313.827 | AF16: =+Z16-AC16 -> 24273.173 | AG16: =+AA16-AD16 -> 26760.478 | AJ16: 89.749104 | AK16: =+U16-AJ16 -> 0
B17: 대구 | G17: =+I17 -> 대구 | I17: 대구 | J17: =+IFERROR(HLOOKUP($B17,'[1]3월'!$D$6:$BN$259,2,),)/1000 -> 12.5 | K17: =+IFERROR(HLOOKUP($B17,'[2]3월'!$F$6:$CP$99,2,),)/1000 -> 11.223 | L17: =+K17-J17 -> -1.277 | M17: =+IFERROR(HLOOKUP($B17,'[3]3월'!$F$6:$CC$57,2,),)/1000 -> 15.572 | N17: =+K17-M17 -> -4.349 | O17: =+IFERROR(HLOOKUP($B17,'[1]3월'!$D$6:$BN$259,3,),)/1000 -> 1228.2853 | P17: =+IFERROR(HLOOKUP($B17,'[2]3월'!$F$6:$CP$99,3,),)/1000 -> 978.89496 | Q17: =+P17-O17 -> -249.39032 | R17: =+IFERROR(HLOOKUP($B17,'[3]3월'!$F$6:$CC$57,3,),)/1000 -> 1576.5958 | S17: =+P17-R17 -> -597.70088 | T17: =+IFERROR(HLOOKUP($B17,'[1]3월'!$D$6:$BN$259,16,),)/1000 -> 123.11139 | U17: =+IFERROR(HLOOKUP($B17,'[2]3월'!$F$6:$CP$99,16,),)/1000 -> -23.079407 | V17: =+U17-T17 -> -146.1908 | W17: =+IFERROR(HLOOKUP($B17,'[3]3월'!$F$6:$CC$57,16,),)/1000 -> 198.15277 | X17: =+U17-W17 -> -221.23218 | Y17: =+[4]대구!$Q$85 -> 98262.823 | Z17: =+[4]대구!$R$85 -> 87222.219 | AA17: =+[5]대구!$Q$85 -> 101245.56 | AB17: =+[4]대구!$Q$89 -> 72963.433 | AC17: =+[4]대구!$R$89 -> 74076.489 | AD17: =+[5]대구!$Q$89 -> 77193.44 | AE17: =+Y17-AB17 -> 25299.389 | AF17: =+Z17-AC17 -> 13145.73 | AG17: =+AA17-AD17 -> 24052.119 | AJ17: -23.079407 | AK17: =+U17-AJ17 -> 0
B18: 울산 | G18: =+I18 -> 울산 | I18: 울산 | J18: =+IFERROR(HLOOKUP($B18,'[1]3월'!$D$6:$BN$259,2,),)/1000 -> 12 | K18: =+IFERROR(HLOOKUP($B18,'[2]3월'!$F$6:$CP$99,2,),)/1000 -> 12.057 | L18: =+K18-J18 -> 0.057 | M18: =+IFERROR(HLOOKUP($B18,'[3]3월'!$F$6:$CC$57,2,),)/1000 -> 7.183 | N18: =+K18-M18 -> 4.874 | O18: =+IFERROR(HLOOKUP($B18,'[1]3월'!$D$6:$BN$259,3,),)/1000 -> 1219.412 | P18: =+IFERROR(HLOOKUP($B18,'[2]3월'!$F$6:$CP$99,3,),)/1000 -> 1257.1629 | Q18: =+P18-O18 -> 37.7509 | R18: =+IFERROR(HLOOKUP($B18,'[3]3월'!$F$6:$CC$57,3,),)/1000 -> 760.20834 | S18: =+P18-R18 -> 496.95456 | T18: =+IFERROR(HLOOKUP($B18,'[1]3월'!$D$6:$BN$259,16,),)/1000 -> 67.742901 | U18: =+IFERROR(HLOOKUP($B18,'[2]3월'!$F$6:$CP$99,16,),)/1000 -> 108.61426 | V18: =+U18-T18 -> 40.871358 | W18: =+IFERROR(HLOOKUP($B18,'[3]3월'!$F$6:$CC$57,16,),)/1000 -> 30.862733 | X18: =+U18-W18 -> 77.751526 | Y18: =+[4]울산!$Q$85 -> 101617.67 | Z18: =+[4]울산!$R$85 -> 104268.3 | AA18: =+[5]울산!$Q$85 -> 105834.38 | AB18: =+[4]울산!$Q$89 -> 81688.791 | AC18: =+[4]울산!$R$89 -> 83859.972 | AD18: =+[5]울산!$Q$89 -> 83954.888 | AE18: =+Y18-AB18 -> 19928.876 | AF18: =+Z18-AC18 -> 20408.329 | AG18: =+AA18-AD18 -> 21879.491 | AJ18: 106.69987 | AK18: =+U18-AJ18 -> 1.914392
B19: 아산 | G19: =+I19 -> 아산 | I19: 아산 | J19: =+IFERROR(HLOOKUP($B19,'[1]3월'!$D$6:$BN$259,2,),)/1000 -> 23 | K19: =+IFERROR(HLOOKUP($B19,'[2]3월'!$F$6:$CP$99,2,),)/1000 -> 23.404 | L19: =+K19-J19 -> 0.404 | M19: =+IFERROR(HLOOKUP($B19,'[3]3월'!$F$6:$CC$57,2,),)/1000 -> 27.772 | N19: =+K19-M19 -> -4.368 | O19: =+IFERROR(HLOOKUP($B19,'[1]3월'!$D$6:$BN$259,3,),)/1000 -> 2369 | P19: =+IFERROR(HLOOKUP($B19,'[2]3월'!$F$6:$CP$99,3,),)/1000 -> 2354.1826 | Q19: =+P19-O19 -> -14.817356 | R19: =+IFERROR(HLOOKUP($B19,'[3]3월'!$F$6:$CC$57,3,),)/1000 -> 2853.2172 | S19: =+P19-R19 -> -499.03456 | T19: =+IFERROR(HLOOKUP($B19,'[1]3월'!$D$6:$BN$259,16,),)/1000 -> 259.49035 | U19: =+IFERROR(HLOOKUP($B19,'[2]3월'!$F$6:$CP$99,16,),)/1000 -> 139.57025 | V19: =+U19-T19 -> -119.9201 | W19: =+IFERROR(HLOOKUP($B19,'[3]3월'!$F$6:$CC$57,16,),)/1000 -> 386.52773 | X19: =+U19-W19 -> -246.95749 | Y19: =+[4]아산!$Q$85 -> 103000 | Z19: =+[4]아산!$R$85 -> 100519.81 | AA19: =+[5]아산!$Q$85 -> 102685.24 | AB19: =+[4]아산!$Q$89 -> 80205.648 | AC19: =+[4]아산!$R$89 -> 84239.872 | AD19: =+[5]아산!$Q$89 -> 79375.617 | AE19: =+Y19-AB19 -> 22794.352 | AF19: =+Z19-AC19 -> 16279.937 | AG19: =+AA19-AD19 -> 23309.621 | AJ19: 139.57025 | AK19: =+U19-AJ19 -> 0
B20: 전주 | G20: =+I20 -> 전주 | I20: 전주 | J20: =+IFERROR(HLOOKUP($B20,'[1]3월'!$D$6:$BN$259,2,),)/1000 -> 10 | K20: =+IFERROR(HLOOKUP($B20,'[2]3월'!$F$6:$CP$99,2,),)/1000 -> 17.8155 | L20: =+K20-J20 -> 7.8155 | M20: =+IFERROR(HLOOKUP($B20,'[3]3월'!$F$6:$CC$57,2,),)/1000 -> 7.133 | N20: =+K20-M20 -> 10.6825 | O20: =+IFERROR(HLOOKUP($B20,'[1]3월'!$D$6:$BN$259,3,),)/1000 -> 970.52091 | P20: =+IFERROR(HLOOKUP($B20,'[2]3월'!$F$6:$CP$99,3,),)/1000 -> 1722.0858 | Q20: =+P20-O20 -> 751.56488 | R20: =+IFERROR(HLOOKUP($B20,'[3]3월'!$F$6:$CC$57,3,),)/1000 -> 668.37119 | S20: =+P20-R20 -> 1053.7146 | T20: =+IFERROR(HLOOKUP($B20,'[1]3월'!$D$6:$BN$259,16,),)/1000 -> 72.293371 | U20: =+IFERROR(HLOOKUP($B20,'[2]3월'!$F$6:$CP$99,16,),)/1000 -> 206.10743 | V20: =+U20-T20 -> 133.81406 | W20: =+IFERROR(HLOOKUP($B20,'[3]3월'!$F$6:$CC$57,16,),)/1000 -> 10.43893 | X20: =+U20-W20 -> 195.6685 | Y20: =+[4]전주!$Q$85 -> 97052.091 | Z20: =+[4]전주!$R$85 -> 96662.221 | AA20: =+[5]전주!$Q$85 -> 93701.275 | AB20: =+[4]전주!$Q$89 -> 73874.501 | AC20: =+[4]전주!$R$89 -> 75942.791 | AD20: =+[5]전주!$Q$89 -> 71268.039 | AE20: =+Y20-AB20 -> 23177.59 | AF20: =+Z20-AC20 -> 20719.429 | AG20: =+AA20-AD20 -> 22433.236 | AJ20: 206.10743 | AK20: =+U20-AJ20 -> 0
B21: 군산 | G21: =+I21 -> 군산 | I21: 군산 | J21: =+IFERROR(HLOOKUP($B21,'[1]3월'!$D$6:$BN$259,2,),)/1000 -> 7.5 | K21: =+IFERROR(HLOOKUP($B21,'[2]3월'!$F$6:$CP$99,2,),)/1000 -> 5.4375 | L21: =+K21-J21 -> -2.0625 | M21: =+IFERROR(HLOOKUP($B21,'[3]3월'!$F$6:$CC$57,2,),)/1000 -> 8.978 | N21: =+K21-M21 -> -3.5405 | O21: =+IFERROR(HLOOKUP($B21,'[1]3월'!$D$6:$BN$259,3,),)/1000 -> 823.78044 | P21: =+IFERROR(HLOOKUP($B21,'[2]3월'!$F$6:$CP$99,3,),)/1000 -> 622.1095 | Q21: =+P21-O21 -> -201.67094 | R21: =+IFERROR(HLOOKUP($B21,'[3]3월'!$F$6:$CC$57,3,),)/1000 -> 1017.8315 | S21: =+P21-R21 -> -395.72205 | T21: =+IFERROR(HLOOKUP($B21,'[1]3월'!$D$6:$BN$259,16,),)/1000 -> 194.05781 | U21: =+IFERROR(HLOOKUP($B21,'[2]3월'!$F$6:$CP$99,16,),)/1000 -> 131.89843 | V21: =+U21-T21 -> -62.159381 | W21: =+IFERROR(HLOOKUP($B21,'[3]3월'!$F$6:$CC$57,16,),)/1000 -> 313.98711 | X21: =+U21-W21 -> -182.08868 | Y21: =+[4]군산!$Q$85 -> 109837.39 | Z21: =+[4]군산!$R$85 -> 114410.94 | AA21: =+[5]군산!$Q$85 -> 113442.55 | AB21: =+[4]군산!$Q$89 -> 72839.442 | AC21: =+[4]군산!$R$89 -> 74829.89 | AD21: =+[5]군산!$Q$89 -> 70413.769 | AE21: =+Y21-AB21 -> 36997.95 | AF21: =+Z21-AC21 -> 39581.053 | AG21: =+AA21-AD21 -> 43028.785 | AJ21: 131.89843 | AK21: =+U21-AJ21 -> 0
B22: 원주 | G22: =+I22 -> 원주 | I22: 원주 | J22: =+IFERROR(HLOOKUP($B22,'[1]3월'!$D$6:$BN$259,2,),)/1000 -> 4 | K22: =+IFERROR(HLOOKUP($B22,'[2]3월'!$F$6:$CP$99,2,),)/1000 -> 2.4635 | L22: =+K22-J22 -> -1.5365 | M22: =+IFERROR(HLOOKUP($B22,'[3]3월'!$F$6:$CC$57,2,),)/1000 -> 6.2085 | N22: =+K22-M22 -> -3.745 | O22: =+IFERROR(HLOOKUP($B22,'[1]3월'!$D$6:$BN$259,3,),)/1000 -> 448 | P22: =+IFERROR(HLOOKUP($B22,'[2]3월'!$F$6:$CP$99,3,),)/1000 -> 229.70775 | Q22: =+P22-O22 -> -218.29225 | R22: =+IFERROR(HLOOKUP($B22,'[3]3월'!$F$6:$CC$57,3,),)/1000 -> 692.2704 | S22: =+P22-R22 -> -462.56265 | T22: =+IFERROR(HLOOKUP($B22,'[1]3월'!$D$6:$BN$259,16,),)/1000 -> 44.706408 | U22: =+IFERROR(HLOOKUP($B22,'[2]3월'!$F$6:$CP$99,16,),)/1000 -> -35.664611 | V22: =+U22-T22 -> -80.371019 | W22: =+IFERROR(HLOOKUP($B22,'[3]3월'!$F$6:$CC$57,16,),)/1000 -> 145.91854 | X22: =+U22-W22 -> -181.58316 | Y22: =+[4]원주!$Q$85 -> 112000 | Z22: =+[4]원주!$R$85 -> 93244.471 | AA22: =+[5]원주!$Q$85 -> 111513.97 | AB22: =+[4]원주!$Q$89 -> 74815.932 | AC22: =+[4]원주!$R$89 -> 72003.515 | AD22: =+[5]원주!$Q$89 -> 73875.972 | AE22: =+Y22-AB22 -> 37184.068 | AF22: =+Z22-AC22 -> 21240.956 | AG22: =+AA22-AD22 -> 37637.994 | AJ22: -35.664611 | AK22: =+U22-AJ22 -> 0
B23: 제주 | G23: =+I23 -> 제주 | I23: 제주 | J23: =+IFERROR(HLOOKUP($B23,'[1]3월'!$D$6:$BN$259,2,),)/1000 -> 7 | K23: =+IFERROR(HLOOKUP($B23,'[2]3월'!$F$6:$CP$99,2,),)/1000 -> 5.9985 | L23: =+K23-J23 -> -1.0015 | M23: =+IFERROR(HLOOKUP($B23,'[3]3월'!$F$6:$CC$57,2,),)/1000 -> 3.848 | N23: =+K23-M23 -> 2.1505 | O23: =+IFERROR(HLOOKUP($B23,'[1]3월'!$D$6:$BN$259,3,),)/1000 -> 859.7575 | P23: =+IFERROR(HLOOKUP($B23,'[2]3월'!$F$6:$CP$99,3,),)/1000 -> 727.00038 | Q23: =+P23-O23 -> -132.75712 | R23: =+IFERROR(HLOOKUP($B23,'[3]3월'!$F$6:$CC$57,3,),)/1000 -> 498.9725 | S23: =+P23-R23 -> 228.02788 | T23: =+IFERROR(HLOOKUP($B23,'[1]3월'!$D$6:$BN$259,16,),)/1000 -> 128.4781 | U23: =+IFERROR(HLOOKUP($B23,'[2]3월'!$F$6:$CP$99,16,),)/1000 -> 105.08774 | V23: =+U23-T23 -> -23.390365 | W23: =+IFERROR(HLOOKUP($B23,'[3]3월'!$F$6:$CC$57,16,),)/1000 -> 73.24519 | X23: =+U23-W23 -> 31.842548 | Y23: =+[4]제주!$Q$85 -> 122822.5 | Z23: =+[4]제주!$R$85 -> 121197.03 | AA23: =+[5]제주!$Q$85 -> 129670.61 | AB23: =+[4]제주!$Q$89 -> 90529.859 | AC23: =+[4]제주!$R$89 -> 89275.848 | AD23: =+[5]제주!$Q$89 -> 88327.903 | AE23: =+Y23-AB23 -> 32292.641 | AF23: =+Z23-AC23 -> 31921.182 | AG23: =+AA23-AD23 -> 41342.705 | AJ23: 104.00225 | AK23: =+U23-AJ23 -> 1.08549
G24: =+I24 -> 수도권 | I24: 수도권 | J24: =SUM(J7:J10) -> 101 | K24: =SUM(K7:K10) -> 93.47 | L24: =+K24-J24 -> -7.53 | M24: =SUM(M7:M10) -> 110.047 | N24: =+K24-M24 -> -16.577 | O24: =SUM(O7:O10) -> 9797.2594 | P24: =SUM(P7:P10) -> 8695.0243 | Q24: =+P24-O24 -> -1102.2352 | R24: =SUM(R7:R10) -> 11146.868 | S24: =+P24-R24 -> -2451.8437 | T24: =SUM(T7:T10) -> 505.32272 | U24: =SUM(U7:U10) -> 179.04149 | V24: =+U24-T24 -> -326.28122 | W24: =SUM(W7:W10) -> 1147.7338 | X24: =+U24-W24 -> -968.69233 | Y24: =+[4]수도권!$Q$85 -> 97002.569 | Z24: =+[4]수도권!$R$85 -> 93007.036 | AA24: =+[5]수도권!$Q$85 -> 101292.86 | AB24: =+[4]수도권!$Q$89 -> 81451.944 | AC24: =+[4]수도권!$R$89 -> 80706.855 | AD24: =+[5]수도권!$Q$89 -> 82214.955 | AE24: =+Y24-AB24 -> 15550.625 | AF24: =+Z24-AC24 -> 12300.18 | AG24: =+AA24-AD24 -> 19077.909 | AJ24: 177.1812 | AK24: =+U24-AJ24 -> 1.860294
G25: =+I25 -> 영남권 | I25: 영남권 | J25: =SUM(J11:J18) -> 120.5 | K25: =SUM(K11:K18) -> 117.338 | L25: =+K25-J25 -> -3.162 | M25: =SUM(M11:M18) -> 134.5 | N25: =+K25-M25 -> -17.162 | O25: =SUM(O11:O18) -> 12130.392 | P25: =SUM(P11:P18) -> 11529.037 | Q25: =+P25-O25 -> -601.35508 | R25: =SUM(R11:R18) -> 13627.721 | S25: =+P25-R25 -> -2098.6839 | T25: =SUM(T11:T18) -> 1001.6137 | U25: =SUM(U11:U18) -> 966.84601 | V25: =+U25-T25 -> -34.767716 | W25: =SUM(W11:W18) -> 1614.0472 | X25: =+U25-W25 -> -647.20124 | Y25: =+[4]영남권!$Q$85 -> 100667.16 | Z25: =+[4]영남권!$R$85 -> 98256.721 | AA25: =+[5]영남권!$Q$85 -> 101364.13 | AB25: =+[4]영남권!$Q$89 -> 79026.75 | AC25: =+[4]영남권!$R$89 -> 77832.414 | AD25: =+[5]영남권!$Q$89 -> 79165.726 | AE25: =+Y25-AB25 -> 21640.406 | AF25: =+Z25-AC25 -> 20424.307 | AG25: =+AA25-AD25 -> 22198.4 | AJ25: 991.58239 | AK25: =+U25-AJ25 -> -24.736385
G26: =+I26 -> 중부권 | I26: 중부권 | J26: =SUM(J19:J23) -> 51.5 | K26: =SUM(K19:K23) -> 55.119 | L26: =+K26-J26 -> 3.619 | M26: =SUM(M19:M23) -> 53.9395 | N26: =+K26-M26 -> 1.1795 | O26: =SUM(O19:O23) -> 5471.0588 | P26: =SUM(P19:P23) -> 5655.0861 | Q26: =+P26-O26 -> 184.02722 | R26: =SUM(R19:R23) -> 5730.6628 | S26: =+P26-R26 -> -75.576772 | T26: =SUM(T19:T23) -> 699.02604 | U26: =SUM(U19:U23) -> 546.99923 | V26: =+U26-T26 -> -152.02681 | W26: =SUM(W19:W23) -> 930.1175 | X26: =+U26-W26 -> -383.11827 | Y26: =+[4]중부권!$Q$85 -> 106234.15 | Z26: =+[4]중부권!$R$85 -> 102574.02 | AA26: =+[5]중부권!$Q$85 -> 106231.06 | AB26: =+[4]중부권!$Q$89 -> 78888.223 | AC26: =+[4]중부권!$R$89 -> 80620.6 | AD26: =+[5]중부권!$Q$89 -> 76816.473 | AE26: =+Y26-AB26 -> 27345.93 | AF26: =+Z26-AC26 -> 21953.416 | AG26: =+AA26-AD26 -> 29414.592 | AJ26: 545.91374 | AK26: =+U26-AJ26 -> 1.08549
F27: =+K27/M27 -> 0.89091801 | G27: =+K27/J27 -> 0.97409158 | H27: 레미콘 계 | J27: =SUM(J24:J26) -> 273 | K27: =SUM(K24:K26) -> 265.927 | L27: =+K27-J27 -> -7.073 | M27: =SUM(M24:M26) -> 298.4865 | N27: =+K27-M27 -> -32.5595 | O27: =SUM(O24:O26) -> 27398.711 | P27: =SUM(P24:P26) -> 25879.148 | Q27: =+P27-O27 -> -1519.563 | R27: =SUM(R24:R26) -> 30505.252 | S27: =+P27-R27 -> -4626.1043 | T27: =SUM(T24:T26) -> 2205.9625 | U27: =SUM(U24:U26) -> 1692.8867 | V27: =+U27-T27 -> -513.07574 | W27: =SUM(W24:W26) -> 3691.8986 | X27: =+U27-W27 -> -1999.0118 | Y27: =+[4]합계!$Q$85 -> 100361.58 | Z27: =+[4]합계!$R$85 -> 97314.829 | AA27: =+[5]합계!$Q$85 -> 102216.11 | AB27: =+[4]합계!$Q$89 -> 79897.851 | AC27: =+[4]합계!$R$89 -> 79407.763 | AD27: =+[5]합계!$Q$89 -> 79867.909 | AE27: =+Y27-AB27 -> 20463.727 | AF27: =+Z27-AC27 -> 17907.066 | AG27: =+AA27-AD27 -> 22348.202 | AJ27: 1714.6773 | AK27: =+U27-AJ27 -> -21.790601
B28: 건자재 | E28: 건자재영업 | G28: 건자재 | H28: 건자재 | J28: =+IFERROR(HLOOKUP($B28,'[1]3월'!$D$6:$BN$259,2,),) -> 10200 | K28: =+IFERROR(HLOOKUP($E28,'[2]3월'!$F$6:$CP$99,2,),) -> 15762.77 | L28: =+K28-J28 -> 5562.77 | M28: =+IFERROR(HLOOKUP($E28,'[3]3월'!$F$6:$CC$57,2,),) -> 8665.068 | N28: =+K28-M28 -> 7097.702 | O28: =+IFERROR(HLOOKUP($B28,'[1]3월'!$D$6:$BN$259,3,),)/1000 -> 11165.946 | P28: =+IFERROR(HLOOKUP($E28,'[2]3월'!$F$6:$CP$99,3,),)/1000 -> 12535.229 | Q28: =+P28-O28 -> 1369.2831 | R28: =+IFERROR(HLOOKUP($E28,'[3]3월'!$F$6:$CC$57,3,),)/1000 -> 8759.9178 | S28: =+P28-R28 -> 3775.3109 | T28: =+IFERROR(HLOOKUP($B28,'[1]3월'!$D$6:$BN$259,16,),)/1000 -> 164.89496 | U28: =+IFERROR(HLOOKUP($E28,'[2]3월'!$F$6:$CP$99,16,),)/1000 -> -118.87035 | V28: =+U28-T28 -> -283.76531 | W28: =+IFERROR(HLOOKUP($E28,'[3]3월'!$F$6:$CC$57,16,),)/1000 -> 31.655346 | X28: =+U28-W28 -> -150.52569 | Y28: ■ 비고 | AJ28: -118.87035 | AK28: =+U28-AJ28 -> 0
B29: 부산모래장 | C29: 부산골재 | G29: =+I29 -> 부산모래장 | H29: 골재 | I29: 부산모래장 | J29: =+IFERROR(HLOOKUP($B29,'[1]3월'!$D$6:$BN$259,2,),)/1000 -> 14.476033 | K29: =+IFERROR(HLOOKUP($C29,'[2]3월'!$F$6:$CP$99,2,),)/1000 -> 23.849 | L29: =+K29-J29 -> 9.3729673 | M29: =+IFERROR(HLOOKUP($C29,'[3]3월'!$F$6:$CC$57,2,),)/1000 -> 20.278 | N29: =+K29-M29 -> 3.571 | O29: =+IFERROR(HLOOKUP($B29,'[1]3월'!$D$6:$BN$259,3,),)/1000 -> 328.11643 | P29: =+IFERROR(HLOOKUP($C29,'[2]3월'!$F$6:$CP$99,3,),)/1000 -> 728.01 | Q29: =+P29-O29 -> 399.89357 | R29: =+IFERROR(HLOOKUP($C29,'[3]3월'!$F$6:$CC$57,3,),)/1000 -> 667.14967 | S29: =+P29-R29 -> 60.860328 | T29: =+IFERROR(HLOOKUP($B29,'[1]3월'!$D$6:$BN$259,21,),)/1000 -> -18.125732 | U29: =+IFERROR(HLOOKUP($C29,'[2]3월'!$F$6:$CP$99,21,),)/1000 -> 19.852408 | V29: =+U29-T29 -> 37.978141 | W29: =+IFERROR(HLOOKUP($C29,'[3]3월'!$F$6:$CC$57,21,),)/1000 -> 62.624016 | X29: =+U29-W29 -> -42.771607 | Y29: - 수도권/부산권 1군 판매단가 인하(3/1자) | AJ29: -6.290804 | AK29: =+U29-AJ29 -> 26.143213
B30: 서부산크라샤 | C30: 서부산골재 | G30: =+I30 -> 서부산CR | I30: 서부산CR | J30: =+IFERROR(HLOOKUP($B30,'[1]3월'!$D$6:$BN$259,2,),)/1000 -> 63.800097 | K30: =+IFERROR(HLOOKUP($C30,'[2]3월'!$F$6:$CP$99,2,),)/1000 -> 32.472 | L30: =+K30-J30 -> -31.328097 | M30: =+IFERROR(HLOOKUP($C30,'[3]3월'!$F$6:$CC$57,2,),)/1000 -> 21.556 | N30: =+K30-M30 -> 10.916 | O30: =+IFERROR(HLOOKUP($B30,'[1]3월'!$D$6:$BN$259,3,),)/1000 -> 941.6185 | P30: =+IFERROR(HLOOKUP($C30,'[2]3월'!$F$6:$CP$99,3,),)/1000 -> 461.312 | Q30: =+P30-O30 -> -480.3065 | R30: =+IFERROR(HLOOKUP($C30,'[3]3월'!$F$6:$CC$57,3,),)/1000 -> 310.084 | S30: =+P30-R30 -> 151.228 | T30: =+IFERROR(HLOOKUP($B30,'[1]3월'!$D$6:$BN$259,21,),)/1000 -> 251.76465 | U30: =+IFERROR(HLOOKUP($C30,'[2]3월'!$F$6:$CP$99,21,),)/1000 -> 165.9782 | V30: =+U30-T30 -> -85.786457 | W30: =+IFERROR(HLOOKUP($C30,'[3]3월'!$F$6:$CC$57,21,),)/1000 -> 45.27456 | X30: =+U30-W30 -> 120.70364 | Y30: · 수도권 2,300원(2.1% ↓) | AJ30: 162.33834 | AK30: =+U30-AJ30 -> 3.6398584
B31: 부산크라샤 | C31: 부산크라샤 | G31: =+I31 -> 부산CR | I31: 부산CR | J31: =+IFERROR(HLOOKUP($B31,'[1]3월'!$D$6:$BN$259,2,),)/1000 -> 0.0001 | K31: =+IFERROR(HLOOKUP($C31,'[2]3월'!$F$6:$CP$99,2,),)/1000 -> 4.89 | L31: =+K31-J31 -> 4.8899 | M31: =+IFERROR(HLOOKUP($C31,'[3]3월'!$F$6:$CC$57,2,),)/1000 -> 43.094 | N31: =+K31-M31 -> -38.204 | O31: =+IFERROR(HLOOKUP($B31,'[1]3월'!$D$6:$BN$259,3,),)/1000 -> 0 | P31: =+IFERROR(HLOOKUP($C31,'[2]3월'!$F$6:$CP$99,3,),)/1000 -> 94.095 | Q31: =+P31-O31 -> 94.095 | R31: =+IFERROR(HLOOKUP($C31,'[3]3월'!$F$6:$CC$57,3,),)/1000 -> 787.769 | S31: =+P31-R31 -> -693.674 | T31: =+IFERROR(HLOOKUP($B31,'[1]3월'!$D$6:$BN$259,21,),)/1000 -> -223.48283 | U31: =+IFERROR(HLOOKUP($C31,'[2]3월'!$F$6:$CP$99,21,),)/1000 -> -312.64607 | V31: =+U31-T31 -> -89.163243 | W31: =+IFERROR(HLOOKUP($C31,'[3]3월'!$F$6:$CC$57,21,),)/1000 -> 47.96902 | X31: =+U31-W31 -> -360.61509 | Y31: · 부산권 1,900원(1.7% ↓) | AJ31: -313.93526 | AK31: =+U31-AJ31 -> 1.2891882
H32: 골재 계 | J32: =SUM(J29:J31) -> 78.27623 | K32: =SUM(K29:K31) -> 61.211 | L32: =+K32-J32 -> -17.06523 | M32: =SUM(M29:M31) -> 84.928 | N32: =+K32-M32 -> -23.717 | O32: =SUM(O29:O31) -> 1269.7349 | P32: =SUM(P29:P31) -> 1283.417 | Q32: =+P32-O32 -> 13.682068 | R32: =SUM(R29:R31) -> 1765.0027 | S32: =+P32-R32 -> -481.58567 | T32: =SUM(T29:T31) -> 10.156088 | U32: =SUM(U29:U31) -> -126.81547 | V32: =+U32-T32 -> -136.97156 | W32: =SUM(W29:W31) -> 155.8676 | X32: =+U32-W32 -> -282.68307 | Y32: - 1군 판가 소급분(마이너스 계산서) : 4.9억 | AJ32: -157.88773 | AK32: =+U32-AJ32 -> 31.072259 | AL32: =283175/1000000 -> 0.283175 | AM32: =+AK32-AL32 -> 30.789084
B33: 포항임대 | C33: 속초임대 | D33: 강릉임대 | E33: 레미콘임대 계 | G33: =+I33 -> 레미콘임대 | H33: 기타 | I33: 레미콘임대 | L33: =+K33-J33 -> 0 | N33: =+K33-M33 -> 0 | O33: =(IFERROR(HLOOKUP($B33,'[1]3월'!$D$6:$BN$259,3,),)++IFERROR(HLOOKUP($C33,'[1]3월'!$D$6:$BN$259,3,),)+IFERROR(HLOOKUP($D33,'[1]3월'!$D$6:$BN$259,3,),))/1000 -> 90.84 | P33: =+IFERROR(HLOOKUP($E33,'[2]3월'!$F$6:$CP$99,3,),)/1000 -> 65.84 | Q33: =+P33-O33 -> -25 | R33: =+IFERROR(HLOOKUP($E33,'[3]3월'!$F$6:$CC$57,3,),)/1000 -> 90.84 | S33: =+P33-R33 -> -25 | T33: =(IFERROR(HLOOKUP($B33,'[1]3월'!$D$6:$BN$259,21,),)++IFERROR(HLOOKUP($C33,'[1]3월'!$D$6:$BN$259,21,),)+IFERROR(HLOOKUP($D33,'[1]3월'!$D$6:$BN$259,21,),))/1000 -> 75.717537 | U33: =+IFERROR(HLOOKUP($E33,'[2]3월'!$F$6:$CP$99,16,),)/1000 -> 46.568992 | V33: =+U33-T33 -> -29.148545 | W33: =+IFERROR(HLOOKUP($E33,'[3]3월'!$F$6:$CC$57,16,),)/1000 -> 75.121657 | X33: =+U33-W33 -> -28.552665 | Y33: · GS(4.4억), 라인산업(0.2억), 호반건설(0.1억), 계룡건설산업(0.1억) | AJ33: 46.568992 | AK33: =+U33-AJ33 -> 0
B34: 부동산임대 | C34: 주유소임대 | E34: 임대 계 | G34: =+I34 -> 임대 | I34: 임대 | L34: =+K34-J34 -> 0 | M34: 0 | N34: =+K34-M34 -> 0 | O34: =(+IFERROR(HLOOKUP($B34,'[1]3월'!$D$6:$BN$259,3,),)+IFERROR(HLOOKUP($C34,'[1]3월'!$D$6:$BN$259,3,),))/1000 -> 74.0915 | P34: =+IFERROR(HLOOKUP($E34,'[2]3월'!$F$6:$CP$99,3,),)/1000 -> 73.542477 | Q34: =+P34-O34 -> -0.549023 | R34: =+IFERROR(HLOOKUP($E34,'[3]3월'!$F$6:$CC$57,3,),)/1000 -> 72.011468 | S34: =+P34-R34 -> 1.531009 | T34: =(+IFERROR(HLOOKUP($B34,'[1]3월'!$D$6:$BN$259,21,),)+IFERROR(HLOOKUP($C34,'[1]3월'!$D$6:$BN$259,21,),))/1000 -> 76.556944 | U34: =+IFERROR(HLOOKUP($E34,'[2]3월'!$F$6:$CP$99,16,),)/1000 -> 76.003665 | V34: =+U34-T34 -> -0.553279 | W34: =+IFERROR(HLOOKUP($E34,'[3]3월'!$F$6:$CC$57,16,),)/1000 -> 74.495595 | X34: =+U34-W34 -> 1.50807 | AJ34: 76.003665 | AK34: =+U34-AJ34 -> 0
B35: 공 통 비 | G35: =+I35 -> 공통비 | I35: 공통비 | L35: =+K35-J35 -> 0 | N35: =+K35-M35 -> 0 | Q35: =+P35-O35 -> 0 | S35: =+P35-R35 -> 0 | T35: =-'[1]3월'!$Z$22/1000 -> -1394.3694 | U35: =+-'[2]3월'!$Z$22/1000 -> -1338.7445 | V35: =+U35-T35 -> 55.624936 | W35: =+-'[3]3월'!$Z$22/1000 -> -1237.7949 | X35: =+U35-W35 -> -100.94957 | Y35: - 대손 : 5.2억 | AJ35: -1338.9314 | AK35: =+U35-AJ35 -> 0.1868979
G36: =+I36 -> OPC 소급분 | I36: OPC 소급분 | N36: =+K36-M36 -> 0 | Q36: =+P36-O36 -> 0 | S36: =+P36-R36 -> 0 | U36: ='[2]3월'!$BD$26/1000 -> 0 | V36: =+U36-T36 -> 0 | W36: =-'[3]3월'!$BD$26/1000 -> 0 | X36: =+U36-W36 -> 0 | Y36: · 집합대손 2.2억 // 개별대손 3억(삼정이앤시) → 안양 2.9억, 양산 0.1억 | AJ36: 0 | AK36: =+U36-AJ36 -> 0
G37: =+I37 -> 대손 | I37: 대손 | N37: =+K37-M37 -> 0 | Q37: =+P37-O37 -> 0 | S37: =+P37-R37 -> 0 | U37: ='[2]3월'!$BE$26/1000 -> -522.39605 | V37: =+U37-T37 -> -522.39605 | W37: ='[3]3월'!$BE$26/1000 -> -1906.5691 | X37: =+U37-W37 -> 1384.173 | AJ37: -522.40025 | AK37: =+U37-AJ37 -> 0.004194 | AO37: =+AK32+AK11 -> 2.9238371 | AP37: =+AO37*1000000 -> 2923837.1 | AQ37: =199422+283175 -> 482597
G38: =+I38 -> 미운영 공장 | I38: 미운영 공장 | M38: =SUM(M54:M59) -> 0 | N38: =+K38-M38 -> 0 | Q38: =+P38-O38 -> 0 | R38: =+IFERROR(HLOOKUP($I$38,'[3]3월'!$F$6:$BJ$50,3,),)/1000 -> 0 | S38: =+P38-R38 -> 0 | T38: =SUM('[1]3월'!$AM$26:$AQ$26)/1000 -> -0.148809 | U38: =+'[2]3월'!$BF$26/1000 -> -7.533661 | V38: =+U38-T38 -> -7.384852 | W38: =+'[3]3월'!$BF$26/1000 -> -1.614152 | X38: =+U38-W38 -> -5.919509 | AJ38: -7.533661 | AK38: =+U38-AJ38 -> 0 | AQ38: =+AP37-AQ37 -> 2441240.1
B39: 기타 계 | G39: =+I39 -> 퇴직위로금 | I39: 퇴직위로금 | U39: =+'[2]3월'!$BG$26/1000 -> 0 | V39: =+U39-T39 -> 0 | X39: =+U39-W39 -> 0 | AJ39: 0 | AK39: =+U39-AJ39 -> 0
G40: =+I40 -> 기타 | I40: 기타 | L40: =+K40-J40 -> 0 | N40: =+K40-M40 -> 0 | O40: =IFERROR(HLOOKUP($B39,'[1]3월'!$D$6:$BN$259,3,),)/1000 -> 1.77 | P40: =+('[2]3월'!$F$8-SUM('[2]3월'!$Z$8,'[2]3월'!$AH$8,'[2]3월'!$AN$8,'[2]3월'!$AO$8,'[2]3월'!$BA$8,'[2]3월'!$BD$8,'[2]3월'!$BE$8,'[2]3월'!$BF$8))/1000 -> 1.67985 | Q40: =+P40-O40 -> -0.09015 | R40: =+('[3]3월'!$F$8-SUM('[3]3월'!$Z$8,'[3]3월'!$AH$8,'[3]3월'!$AN$8,'[3]3월'!$AO$8,'[3]3월'!$BA$8,'[3]3월'!$BD$8,'[3]3월'!$BE$8,'[3]3월'!$BF$8))/1000 -> 1.7024 | S40: =+P40-R40 -> -0.02255 | T40: =+('[1]3월'!$E$26-'[1]3월'!$Z$26-'[1]3월'!$AA$26-'[1]3월'!$AE$26-'[1]3월'!$AL$26-'[1]3월'!$AM$26-'[1]3월'!$AN$26-'[1]3월'!$AO$26-'[1]3월'!$AP$26-'[1]3월'!$AQ$26-'[1]3월'!$AS$26+'[1]3월'!$AS$26)/1000 -> -75.182554 | U40: =+('[2]3월'!$F$26-SUM('[2]3월'!$Z$26,'[2]3월'!$AH$26,'[2]3월'!$AN$26,'[2]3월'!$AO$26,'[2]3월'!$BA$26,'[2]3월'!$BD$26,'[2]3월'!$BE$26,'[2]3월'!$BF$26))/1000-U39 -> -11.11117 | V40: =+U40-T40 -> 64.071384 | W40: =+('[3]3월'!$F$26-SUM('[3]3월'!$Z$26,'[3]3월'!$AH$26,'[3]3월'!$AN$26,'[3]3월'!$AO$26,'[3]3월'!$BA$26,'[3]3월'!$BD$26,'[3]3월'!$BE$26,'[3]3월'!$BF$26))/1000 -> -6.366509 | X40: =+U40-W40 -> -4.744661 | AJ40: -11.111171 | AK40: =+U40-AJ40 -> 1.0000035e-06
H41: 기타 계 | J41: =SUM(J33:J40) -> 0 | K41: =SUM(K33:K40) -> 0 | L41: =+K41-J41 -> 0 | M41: =SUM(M33:M40) -> 0 | N41: =+K41-M41 -> 0 | O41: =SUM(O33:O40) -> 166.7015 | P41: =SUM(P33:P40) -> 141.06233 | Q41: =+P41-O41 -> -25.639173 | R41: =SUM(R33:R40) -> 164.55387 | S41: =+P41-R41 -> -23.491541 | T41: =SUM(T33:T40) -> -1317.4263 | U41: =SUM(U33:U40) -> -1757.2127 | V41: =+U41-T41 -> -439.78641 | W41: =SUM(W33:W40) -> -3002.7274 | X41: =+U41-W41 -> 1245.5147 | AJ41: -1757.4038 | AK41: =+U41-AJ41 -> 0.1910929
U42: 19 | V42: 12.4 | AJ42: 19 | AK42: =+U42-AJ42 -> 0 | AO42: 10121748
...

Sheet 사업장별(누계)
H3: □ 사업장별 손익실적(2025-03누계)
AG4: [단위 : 천㎥, 톤, 백만원]
H5: 구분 | J5: 물량 | O5: 매출 | T5: 영업이익(공통비 배부전) | Y5: 판매단가 | AB5: 변동비 | AE5: 공헌이익
A6: 2024년 3월누계 마감 손익 | J6: 계획 | K6: 실적 | L6: 차이 | M6: 전년 | N6: 차이 | O6: 계획 | P6: 실적 | Q6: 차이 | R6: 전년 | S6: 차이 | T6: 계획 | U6: 실적 | V6: 차이 | W6: 전년 | X6: 차이 | Y6: 계획 | Z6: 실적 | AA6: 전년 | AB6: 계획 | AC6: 실적 | AD6: 전년 | AE6: 계획 | AF6: 실적 | AG6: 전년
B7: 안양 | G7: =+I7 -> 안양 | H7: 레미콘 | I7: 안양 | J7: =+IFERROR(HLOOKUP($B7,'[1]3월누계'!$D$6:$BN$259,2,),)/1000 -> 100 | K7: =+IFERROR(HLOOKUP($B7,'[2]3월누계'!$F$6:$CP$99,2,),)/1000 -> 100.21 | L7: =+K7-J7 -> 0.21 | M7: =+IFERROR(HLOOKUP($B7,'[3]3월누계'!$F$6:$CC$57,2,),)/1000 -> 124.451 | N7: =+K7-M7 -> -24.241 | O7: =+IFERROR(HLOOKUP($B7,'[1]3월누계'!$D$6:$BN$259,3,),)/1000 -> 9806.5635 | P7: =+IFERROR(HLOOKUP($B7,'[2]3월누계'!$F$6:$CP$99,3,),)/1000 -> 9634.6382 | Q7: =+P7-O7 -> -171.92534 | R7: =+IFERROR(HLOOKUP($B7,'[3]3월누계'!$F$6:$CC$57,3,),)/1000 -> 12223.782 | S7: =+P7-R7 -> -2589.1436 | T7: =+IFERROR(HLOOKUP($B7,'[1]3월누계'!$D$6:$BN$259,16,),)/1000 -> 590.36839 | U7: =+IFERROR(HLOOKUP($B7,'[2]3월누계'!$F$6:$CP$99,16,),)/1000 -> 544.25705 | V7: =+U7-T7 -> -46.111346 | W7: =+IFERROR(HLOOKUP($B7,'[3]3월누계'!$F$6:$CC$57,16,),)/1000 -> 1191.1608 | X7: =+U7-W7 -> -646.90376 | Y7: =+[9]안양!$Q$85 -> 98065.635 | Z7: =+[9]안양!$R$85 -> 96121.69 | AA7: =+[10]안양!$Q$85 -> 98221.644 | AB7: =+[9]안양!$Q$89 -> 82667.864 | AC7: =+[9]안양!$R$89 -> 81579.544 | AD7: =+[10]안양!$Q$89 -> 81295.712 | AE7: =+Y7-AB7 -> 15397.771 | AF7: =+Z7-AC7 -> 14542.146 | AG7: =+AA7-AD7 -> 16925.932
B8: 인천 | G8: =+I8 -> 인천 | H8: 직영 | I8: 인천 | J8: =+IFERROR(HLOOKUP($B8,'[1]3월누계'!$D$6:$BN$259,2,),)/1000 -> 80 | K8: =+IFERROR(HLOOKUP($B8,'[2]3월누계'!$F$6:$CP$99,2,),)/1000 -> 70.152 | L8: =+K8-J8 -> -9.848 | M8: =+IFERROR(HLOOKUP($B8,'[3]3월누계'!$F$6:$CC$57,2,),)/1000 -> 83.656 | N8: =+K8-M8 -> -13.504 | O8: =+IFERROR(HLOOKUP($B8,'[1]3월누계'!$D$6:$BN$259,3,),)/1000 -> 7807.7827 | P8: =+IFERROR(HLOOKUP($B8,'[2]3월누계'!$F$6:$CP$99,3,),)/1000 -> 6832.7286 | Q8: =+P8-O8 -> -975.05408 | R8: =+IFERROR(HLOOKUP($B8,'[3]3월누계'!$F$6:$CC$57,3,),)/1000 -> 8443.3819 | S8: =+P8-R8 -> -1610.6533 | T8: =+IFERROR(HLOOKUP($B8,'[1]3월누계'!$D$6:$BN$259,16,),)/1000 -> 182.09957 | U8: =+IFERROR(HLOOKUP($B8,'[2]3월누계'!$F$6:$CP$99,16,),)/1000 -> -78.653321 | V8: =+U8-T8 -> -260.7529 | W8: =+IFERROR(HLOOKUP($B8,'[3]3월누계'!$F$6:$CC$57,16,),)/1000 -> 624.52589 | X8: =+U8-W8 -> -703.17922 | Y8: =+[9]인천!$Q$85 -> 97597.284 | Z8: =+[9]인천!$R$85 -> 97415.809 | AA8: =+[10]인천!$Q$85 -> 100929.78 | AB8: =+[9]인천!$Q$89 -> 83639.421 | AC8: =+[9]인천!$R$89 -> 85798.574 | AD8: =+[10]인천!$Q$89 -> 83319.257 | AE8: =+Y8-AB8 -> 13957.863 | AF8: =+Z8-AC8 -> 11617.235 | AG8: =+AA8-AD8 -> 17610.527
B9: 파주 | G9: =+I9 -> 파주 | I9: 파주 | J9: =+IFERROR(HLOOKUP($B9,'[1]3월누계'!$D$6:$BN$259,2,),)/1000 -> 48 | K9: =+IFERROR(HLOOKUP($B9,'[2]3월누계'!$F$6:$CP$99,2,),)/1000 -> 29.676 | L9: =+K9-J9 -> -18.324 | M9: =+IFERROR(HLOOKUP($B9,'[3]3월누계'!$F$6:$CC$57,2,),)/1000 -> 66.204 | N9: =+K9-M9 -> -36.528 | O9: =+IFERROR(HLOOKUP($B9,'[1]3월누계'!$D$6:$BN$259,3,),)/1000 -> 4634.3497 | P9: =+IFERROR(HLOOKUP($B9,'[2]3월누계'!$F$6:$CP$99,3,),)/1000 -> 2727.1971 | Q9: =+P9-O9 -> -1907.1526 | R9: =+IFERROR(HLOOKUP($B9,'[3]3월누계'!$F$6:$CC$57,3,),)/1000 -> 6763.0588 | S9: =+P9-R9 -> -4035.8617 | T9: =+IFERROR(HLOOKUP($B9,'[1]3월누계'!$D$6:$BN$259,16,),)/1000 -> 70.484947 | U9: =+IFERROR(HLOOKUP($B9,'[2]3월누계'!$F$6:$CP$99,16,),)/1000 -> -297.59622 | V9: =+U9-T9 -> -368.08116 | W9: =+IFERROR(HLOOKUP($B9,'[3]3월누계'!$F$6:$CC$57,16,),)/1000 -> 487.94201 | X9: =+U9-W9 -> -785.53823 | Y9: =+[9]파주!$Q$85 -> 96548.953 | Z9: =+[9]파주!$R$85 -> 91899.081 | AA9: =+[10]파주!$Q$85 -> 102161.74 | AB9: =+[9]파주!$Q$89 -> 79548.376 | AC9: =+[9]파주!$R$89 -> 79518.799 | AD9: =+[10]파주!$Q$89 -> 83825.434 | AE9: =+Y9-AB9 -> 17000.577 | AF9: =+Z9-AC9 -> 12380.281 | AG9: =+AA9-AD9 -> 18336.304
B10: 김포 | G10: =+I10 -> 김포 | I10: 김포 | J10: =+IFERROR(HLOOKUP($B10,'[1]3월누계'!$D$6:$BN$259,2,),)/1000 -> 32 | K10: =+IFERROR(HLOOKUP($B10,'[2]3월누계'!$F$6:$CP$99,2,),)/1000 -> 24.6 | L10: =+K10-J10 -> -7.4 | M10: =+IFERROR(HLOOKUP($B10,'[3]3월누계'!$F$6:$CC$57,2,),)/1000 -> 23.559 | N10: =+K10-M10 -> 1.041 | O10: =+IFERROR(HLOOKUP($B10,'[1]3월누계'!$D$6:$BN$259,3,),)/1000 -> 3055.7491 | P10: =+IFERROR(HLOOKUP($B10,'[2]3월누계'!$F$6:$CP$99,3,),)/1000 -> 2335.9572 | Q10: =+P10-O10 -> -719.79196 | R10: =+IFERROR(HLOOKUP($B10,'[3]3월누계'!$F$6:$CC$57,3,),)/1000 -> 2263.1289 | S10: =+P10-R10 -> 72.828245 | T10: =+IFERROR(HLOOKUP($B10,'[1]3월누계'!$D$6:$BN$259,16,),)/1000 -> 78.701387 | U10: =+IFERROR(HLOOKUP($B10,'[2]3월누계'!$F$6:$CP$99,16,),)/1000 -> -115.34376 | V10: =+U10-T10 -> -194.04515 | W10: =+IFERROR(HLOOKUP($B10,'[3]3월누계'!$F$6:$CC$57,16,),)/1000 -> -5.58851 | X10: =+U10-W10 -> -109.75525 | Y10: =+[9]김포!$Q$85 -> 95492.16 | Z10: =+[9]김포!$R$85 -> 94978.777 | AA10: =+[10]김포!$Q$85 -> 96062.181 | AB10: =+[9]김포!$Q$89 -> 76961.82 | AC10: =+[9]김포!$R$89 -> 79532.124 | AD10: =+[10]김포!$Q$89 -> 76381.196 | AE10: =+Y10-AB10 -> 18530.34 | AF10: =+Z10-AC10 -> 15446.653 | AG10: =+AA10-AD10 -> 19680.985
B11: 부산 | G11: =+I11 -> 부산 | I11: 부산 | J11: =+IFERROR(HLOOKUP($B11,'[1]3월누계'!$D$6:$BN$259,2,),)/1000 -> 57 | K11: =+IFERROR(HLOOKUP($B11,'[2]3월누계'!$F$6:$CP$99,2,),)/1000 -> 54.348 | L11: =+K11-J11 -> -2.652 | M11: =+IFERROR(HLOOKUP($B11,'[3]3월누계'!$F$6:$CC$57,2,),)/1000 -> 62.108 | N11: =+K11-M11 -> -7.76 | O11: =+IFERROR(HLOOKUP($B11,'[1]3월누계'!$D$6:$BN$259,3,),)/1000 -> 6138.9052 | P11: =+IFERROR(HLOOKUP($B11,'[2]3월누계'!$F$6:$CP$99,3,),)/1000 -> 5788.9015 | Q11: =+P11-O11 -> -350.0037 | R11: =+IFERROR(HLOOKUP($B11,'[3]3월누계'!$F$6:$CC$57,3,),)/1000 -> 6695.4014 | S11: =+P11-R11 -> -906.49989 | T11: =+IFERROR(HLOOKUP($B11,'[1]3월누계'!$D$6:$BN$259,16,),)/1000 -> 469.98429 | U11: =+IFERROR(HLOOKUP($B11,'[2]3월누계'!$F$6:$CP$99,16,),)/1000 -> 563.56659 | V11: =+U11-T11 -> 93.582296 | W11: =+IFERROR(HLOOKUP($B11,'[3]3월누계'!$F$6:$CC$57,16,),)/1000 -> 737.33397 | X11: =+U11-W11 -> -173.76738 | Y11: =+[9]부산!$Q$85 -> 107700.09 | Z11: =+[9]부산!$R$85 -> 106515.45 | AA11: =+[10]부산!$Q$85 -> 107802.56 | AB11: =+[9]부산!$Q$89 -> 84877.701 | AC11: =+[9]부산!$R$89 -> 82661.996 | AD11: =+[10]부산!$Q$89 -> 84406.225 | AE11: =+Y11-AB11 -> 22822.39 | AF11: =+Z11-AC11 -> 23853.451 | AG11: =+AA11-AD11 -> 23396.335
B12: 서부산 | G12: =+I12 -> 서부산 | I12: 서부산 | J12: =+IFERROR(HLOOKUP($B12,'[1]3월누계'!$D$6:$BN$259,2,),)/1000 -> 54 | K12: =+IFERROR(HLOOKUP($B12,'[2]3월누계'!$F$6:$CP$99,2,),)/1000 -> 47.831 | L12: =+K12-J12 -> -6.169 | M12: =+IFERROR(HLOOKUP($B12,'[3]3월누계'!$F$6:$CC$57,2,),)/1000 -> 63.855 | N12: =+K12-M12 -> -16.024 | O12: =+IFERROR(HLOOKUP($B12,'[1]3월누계'!$D$6:$BN$259,3,),)/1000 -> 5362.2157 | P12: =+IFERROR(HLOOKUP($B12,'[2]3월누계'!$F$6:$CP$99,3,),)/1000 -> 4610.2614 | Q12: =+P12-O12 -> -751.95427 | R12: =+IFERROR(HLOOKUP($B12,'[3]3월누계'!$F$6:$CC$57,3,),)/1000 -> 6421.5315 | S12: =+P12-R12 -> -1811.2701 | T12: =+IFERROR(HLOOKUP($B12,'[1]3월누계'!$D$6:$BN$259,16,),)/1000 -> 392.84324 | U12: =+IFERROR(HLOOKUP($B12,'[2]3월누계'!$F$6:$CP$99,16,),)/1000 -> 259.01918 | V12: =+U12-T12 -> -133.82406 | W12: =+IFERROR(HLOOKUP($B12,'[3]3월누계'!$F$6:$CC$57,16,),)/1000 -> 663.07388 | X12: =+U12-W12 -> -404.0547 | Y12: =+[9]서부산!$Q$85 -> 99300.29 | Z12: =+[9]서부산!$R$85 -> 96386.474 | AA12: =+[10]서부산!$Q$85 -> 100564.27 | AB12: =+[9]서부산!$Q$89 -> 78811.909 | AC12: =+[9]서부산!$R$89 -> 77069.977 | AD12: =+[10]서부산!$Q$89 -> 80023.775 | AE12: =+Y12-AB12 -> 20488.381 | AF12: =+Z12-AC12 -> 19316.496 | AG12: =+AA12-AD12 -> 20540.495
