Workbook

Sheet 표지
A6: 2025년 6월 마감 손익
A24: 건재사업본부

Sheet 손익총괄
C3: □ 건재사업본부 손익실적(2025-05)
X4: [단위 : 천㎥, 톤, 원/㎥, 원/톤, 백만원]
C5: 구분 | E5: 6월 | J5: 6월 누계 | P5: 6월 주요지표
A6: 2024년 12월 마감 손익 | E6: 계획 | F6: 실적 | G6: 계획대비 | H6: 전년 | I6: 전년대비 | J6: 계획 | K6: 실적 | L6: 계획대비 | M6: 전년 | N6: 전년대비
A7: =+F7/E7 -> 0.87389655 | B7: =+K7/J7 -> 0.90199874 | C7: 물량 | D7: 레미콘 | E7: =+'[1]6월'!$Z$7/1000 -> 290 | F7: =+'[2]6월'!$Z$7/1000 -> 253.43 | G7: =+F7-E7 -> -36.57 | H7: =+'[3]6월'!$Z$7/1000 -> 305.1537 | I7: =+F7-H7 -> -51.7237 | J7: =+'[1]6월누계'!$Z$7/1000 -> 1583 | K7: =+'[2]6월누계'!$Z$7/1000 -> 1427.864 | L7: =+K7-J7 -> -155.136 | M7: =+'[3]6월누계'!$Z$7/1000 -> 1778.2487 | N7: =+K7-M7 -> -350.3847 | Q7: □ 레미콘
D8: 철강재 | E8: =+'[1]6월'!$AA$7 -> 10200 | F8: =+'[2]6월'!$AO$7 -> 6733.593 | G8: =+F8-E8 -> -3466.407 | H8: =+'[3]6월'!$AO$7 -> 7982.061 | I8: =+F8-H8 -> -1248.468 | J8: =+'[1]6월누계'!$AA$7 -> 62200 | K8: =+'[2]6월누계'!$AO$7 -> 62336.339 | L8: =+K8-J8 -> 136.339 | M8: =+'[3]6월누계'!$AO$7 -> 48080.048 | N8: =+K8-M8 -> 14256.291 | Q8: 구분 | S8: 계획 | T8: 실적 | U8: 계획대비 | V8: 전년 | W8: 전년대비
D9: 골재 | E9: =+'[1]6월'!$AE$7/1000 -> 112.56103 | F9: =+'[2]6월'!$AN$7/1000 -> 71.2 | G9: =+F9-E9 -> -41.361032 | H9: =+'[3]6월'!$AN$7/1000 -> 76.324 | I9: =+F9-H9 -> -5.124 | J9: =+'[1]6월누계'!$AE$7/1000 -> 556.7591 | K9: =+'[2]6월누계'!$AN$7/1000 -> 376.314 | L9: =+K9-J9 -> -180.4451 | M9: =+'[3]6월누계'!$AN$7/1000 -> 496.699 | N9: =+K9-M9 -> -120.385 | Q9: 물량 | R9: 수도권 | S9: =+[4]수도권!$T$5/1000 -> 106 | T9: =+[4]수도권!$U$5/1000 -> 95.1235 | U9: =+T9-S9 -> -10.8765 | V9: =+[5]수도권!$T$5/1000 -> 107.2852 | W9: =+T9-V9 -> -12.1617
C10: 매출 | D10: 레미콘 | E10: =+'[1]6월'!$Z$8/1000 -> 29166.334 | F10: =+'[2]6월'!$Z$8/1000 -> 24731.186 | G10: =+F10-E10 -> -4435.1477 | H10: =+'[3]6월'!$Z$8/1000 -> 30777.038 | I10: =+F10-H10 -> -6045.8514 | J10: =+'[1]6월누계'!$Z$8/1000 -> 159052.3 | K10: =+'[2]6월누계'!$Z$8/1000 -> 140669.68 | L10: =+K10-J10 -> -18382.628 | M10: =+'[3]6월누계'!$Z$8/1000 -> 180238.86 | N10: =+K10-M10 -> -39569.186 | R10: 영남권 | S10: =+[4]영남권!$T$5/1000 -> 126.5 | T10: =+[4]영남권!$U$5/1000 -> 109.2535 | U10: =+T10-S10 -> -17.2465 | V10: =+[5]영남권!$T$5/1000 -> 137.792 | W10: =+T10-V10 -> -28.5385
D11: 건자재 | E11: =+'[1]6월'!$AA$8/1000 -> 11165.946 | F11: =+'[2]6월'!$AO$8/1000 -> 7056.4882 | G11: =+F11-E11 -> -4109.4574 | H11: =+'[3]6월'!$AO$8/1000 -> 7873.3448 | I11: =+F11-H11 -> -816.85662 | J11: =+'[1]6월누계'!$AA$8/1000 -> 68084.919 | K11: =+'[2]6월누계'!$AO$8/1000 -> 55521.441 | L11: =+K11-J11 -> -12563.477 | M11: =+'[3]6월누계'!$AO$8/1000 -> 49403.738 | N11: =+K11-M11 -> 6117.7034 | R11: 중부권 | S11: =+[4]중부권!$T$5/1000 -> 57.5 | T11: =+[4]중부권!$U$5/1000 -> 49.053 | U11: =+T11-S11 -> -8.447 | V11: =+[5]중부권!$T$5/1000 -> 60.0765 | W11: =+T11-V11 -> -11.0235
D12: 골재 | E12: =+'[1]6월'!$AE$8/1000 -> 2031.1208 | F12: =+'[2]6월'!$AN$8/1000 -> 1485.765 | G12: =+F12-E12 -> -545.35584 | H12: =+'[3]6월'!$AN$8/1000 -> 1476.999 | I12: =+F12-H12 -> 8.766 | J12: =+'[1]6월누계'!$AE$8/1000 -> 10345.78 | K12: =+'[2]6월누계'!$AN$8/1000 -> 7980.206 | L12: =+K12-J12 -> -2365.5739 | M12: =+'[3]6월누계'!$AN$8/1000 -> 9981.2066 | N12: =+K12-M12 -> -2001.0006 | Q12: 계 | S12: =SUM(S9:S11) -> 290 | T12: =SUM(T9:T11) -> 253.43 | U12: =+T12-S12 -> -36.57 | V12: =SUM(V9:V11) -> 305.1537 | W12: =+T12-V12 -> -51.7237
D13: 기타 | E13: =+'[1]6월'!$E$8/1000-E10-E11-E12 -> 142.52817 | F13: =+'[2]6월'!$F$8/1000-F10-F11-F12 -> 118.80441 | G13: =+F13-E13 -> -23.723755 | H13: =+'[3]6월'!$F$8/1000-H10-H11-H12 -> 166.17921 | I13: =+F13-H13 -> -47.3748 | J13: =+'[1]6월누계'!$E$8/1000-J10-J11-J12 -> 927.689 | K13: =+'[2]6월누계'!$F$8/1000-K10-K11-K12 -> 828.91605 | L13: =+K13-J13 -> -98.772949 | M13: =+'[3]6월누계'!$F$8/1000-M10-M11-M12 -> 991.75998 | N13: =+K13-M13 -> -162.84393 | Q13: 판매단가 | R13: 수도권 | S13: =+[4]수도권!$T$61 -> 97357.075 | T13: =+[4]수도권!$U$61 -> 95549.029 | U13: =+T13-S13 -> -1808.0453 | V13: =+[5]수도권!$Q$85 -> 97972.586 | W13: =+T13-V13 -> -2423.5562
A14: =+F14/E14 -> 0.78559027 | B14: =+K14/J14 -> 0.85986177 | C14: 계 | E14: =SUM(E10:E13) -> 42505.929 | F14: =SUM(F10:F13) -> 33392.244 | G14: =+F14-E14 -> -9113.6847 | H14: =SUM(H10:H13) -> 40293.561 | I14: =+F14-H14 -> -6901.3168 | J14: =SUM(J10:J13) -> 238410.69 | K14: =SUM(K10:K13) -> 205000.24 | L14: =+K14-J14 -> -33410.452 | M14: =SUM(M10:M13) -> 240615.57 | N14: =+K14-M14 -> -35615.327 | R14: 영남권 | S14: =+[4]영남권!$T$61 -> 100502.78 | T14: =+[4]영남권!$U$61 -> 97932.156 | U14: =+T14-S14 -> -2570.6226 | V14: =+[5]영남권!$Q$85 -> 100840.36 | W14: =+T14-V14 -> -2908.2004
C15: 매출원가 | D15: 레미콘 | E15: =+('[1]6월'!$Z$10+'[1]6월'!$Z$19)/1000 -> 25817.69 | F15: =+('[2]6월'!$Z$10+'[2]6월'!$Z$19)/1000 -> 22710.577 | G15: =+F15-E15 -> -3107.1134 | H15: =+('[3]6월'!$Z$10+'[3]6월'!$Z$19)/1000 -> 26624.109 | I15: =+F15-H15 -> -3913.5322 | J15: =+('[1]6월누계'!$Z$10+'[1]6월누계'!$Z$19)/1000 -> 141956.08 | K15: =+('[2]6월누계'!$Z$10+'[2]6월누계'!$Z$19)/1000 -> 128942.62 | L15: =+K15-J15 -> -13013.463 | M15: =+('[3]6월누계'!$Z$10+'[3]6월누계'!$Z$19)/1000 -> 155350.49 | N15: =+K15-M15 -> -26407.867 | R15: 중부권 | S15: =+[4]중부권!$T$61 -> 106658.83 | T15: =+[4]중부권!$U$61 -> 100796.99 | U15: =+T15-S15 -> -5861.8411 | V15: =+[5]중부권!$Q$85 -> 106050.93 | W15: =+T15-V15 -> -5253.9364
D16: 건자재 | E16: =+('[1]6월'!$AA$10+'[1]6월'!$AA$19)/1000 -> 10864.469 | F16: =+('[2]6월'!$AO$10+'[2]6월'!$AO$19)/1000 -> 6881.4304 | G16: =+F16-E16 -> -3983.0385 | H16: =+('[3]6월'!$AO$10+'[3]6월'!$AO$19)/1000 -> 7592.3476 | I16: =+F16-H16 -> -710.91722 | J16: =+('[1]6월누계'!$AA$10+'[1]6월누계'!$AA$19)/1000 -> 66245.576 | K16: =+('[2]6월누계'!$AO$10+'[2]6월누계'!$AO$19)/1000 -> 54662.529 | L16: =+K16-J16 -> -11583.047 | M16: =+('[3]6월누계'!$AO$10+'[3]6월누계'!$AO$19)/1000 -> 48171.056 | N16: =+K16-M16 -> 6491.4728 | Q16: 계 | S16: =+[4]합계!$T$61 -> 100573.57 | T16: =+[4]합계!$U$61 -> 97599.047 | U16: =+T16-S16 -> -2974.5188 | V16: =+[5]합계!$Q$85 -> 100861.45 | W16: =+T16-V16 -> -3262.4069
D17: 골재 | E17: =+('[1]6월'!$AE$10+'[1]6월'!$AE$19)/1000 -> 1911.7528 | F17: =+('[2]6월'!$AN$10+'[2]6월'!$AN$19)/1000 -> 1529.7349 | G17: =+F17-E17 -> -382.01786 | H17: =+('[3]6월'!$AN$10+'[3]6월'!$AN$19)/1000 -> 1456.8969 | I17: =+F17-H17 -> 72.838035 | J17: =+('[1]6월누계'!$AE$10+'[1]6월누계'!$AE$19)/1000 -> 9054.698 | K17: =+('[2]6월누계'!$AN$10+'[2]6월누계'!$AN$19)/1000 -> 8223.8617 | L17: =+K17-J17 -> -830.83622 | M17: =+('[3]6월누계'!$AN$10+'[3]6월누계'!$AN$19)/1000 -> 8992.6372 | N17: =+K17-M17 -> -768.77548 | Q17: 공헌이익 | R17: 수도권 | S17: =+[4]수도권!$Q$90 -> 16889.229 | T17: =+[4]수도권!$R$90 -> 16301.599 | U17: =+T17-S17 -> -587.62971 | V17: =+[5]수도권!$Q$90 -> 17945.084 | W17: =+T17-V17 -> -1643.4847
D18: 기타 | E18: =+('[1]6월'!$E$10+'[1]6월'!$E$19)/1000-E15-E16-E17 -> 105.96253 | F18: =+('[2]6월'!$F$10+'[2]6월'!$F$19)/1000-F15-F16-F17 -> -16.020748 | G18: =+F18-E18 -> -121.98328 | H18: =+('[3]6월'!$F$10+'[3]6월'!$F$19)/1000-H15-H16-H17 -> 194.15654 | I18: =+F18-H18 -> -210.17729 | J18: =+('[1]6월누계'!$E$10+'[1]6월누계'!$E$19)/1000-J15-J16-J17 -> 351.90862 | K18: =+('[2]6월누계'!$F$10+'[2]6월누계'!$F$19)/1000-K15-K16-K17 -> 406.66855 | L18: =+K18-J18 -> 54.759926 | M18: =+('[3]6월누계'!$F$10+'[3]6월누계'!$F$19)/1000-M15-M16-M17 -> 325.56325 | N18: =+K18-M18 -> 81.105297 | R18: 영남권 | S18: =+[4]영남권!$Q$90 -> 21901.963 | T18: =+[4]영남권!$R$90 -> 19516.974 | U18: =+T18-S18 -> -2384.9888 | V18: =+[5]영남권!$Q$90 -> 22708.372 | W18: =+T18-V18 -> -3191.3984
C19: 계 | E19: =SUM(E15:E18) -> 38699.874 | F19: =SUM(F15:F18) -> 31105.721 | G19: =+F19-E19 -> -7594.153 | H19: =SUM(H15:H18) -> 35867.51 | I19: =+F19-H19 -> -4761.7886 | J19: =SUM(J15:J18) -> 217608.27 | K19: =SUM(K15:K18) -> 192235.68 | L19: =+K19-J19 -> -25372.586 | M19: =SUM(M15:M18) -> 212839.74 | N19: =+K19-M19 -> -20604.064 | R19: 중부권 | S19: =+[4]중부권!$Q$90 -> 29080.826 | T19: =+[4]중부권!$R$90 -> 22568.423 | U19: =+T19-S19 -> -6512.4031 | V19: =+[5]중부권!$Q$90 -> 30006.058 | W19: =+T19-V19 -> -7437.6352
C20: 매출이익 | D20: 레미콘 | E20: =+E10-E15 -> 3348.6439 | F20: =+F10-F15 -> 2020.6096 | G20: =+F20-E20 -> -1328.0343 | H20: =+H10-H15 -> 4152.9289 | I20: =+F20-H20 -> -2132.3193 | J20: =+J10-J15 -> 17096.22 | K20: =+K10-K15 -> 11727.055 | L20: =+K20-J20 -> -5369.1651 | M20: =+M10-M15 -> 24888.374 | N20: =+K20-M20 -> -13161.319 | Q20: 계 | S20: =+[4]합계!$Q$90 -> 21493.117 | T20: =+[4]합계!$R$90 -> 18909.89 | U20: =+T20-S20 -> -2583.2276 | V20: =+[5]합계!$Q$90 -> 22476.76 | W20: =+T20-V20 -> -3566.8706
D21: 건자재 | E21: =+E11-E16 -> 301.47673 | F21: =+F11-F16 -> 175.0578 | G21: =+F21-E21 -> -126.41892 | H21: =+H11-H16 -> 280.9972 | I21: =+F21-H21 -> -105.93939 | J21: =+J11-J16 -> 1839.3428 | K21: =+K11-K16 -> 858.91249 | L21: =+K21-J21 -> -980.4303 | M21: =+M11-M16 -> 1232.6819 | N21: =+K21-M21 -> -373.76941 | Q21: □ 건자재
D22: 골재 | E22: =+E12-E17 -> 119.36806 | F22: =+F12-F17 -> -43.969915 | G22: =+F22-E22 -> -163.33797 | H22: =+H12-H17 -> 20.10212 | I22: =+F22-H22 -> -64.072035 | J22: =+J12-J17 -> 1291.0819 | K22: =+K12-K17 -> -243.65574 | L22: =+K22-J22 -> -1534.7377 | M22: =+M12-M17 -> 988.56936 | N22: =+K22-M22 -> -1232.2251 | Q22: 구분 | S22: 계획 | T22: 실적 | U22: 계획대비 | V22: 전년 | W22: 전년대비
D23: 기타 | E23: =+E13-E18 -> 36.565638 | F23: =+F13-F18 -> 134.82516 | G23: =+F23-E23 -> 98.259522 | H23: =+H13-H18 -> -27.977325 | I23: =+F23-H23 -> 162.80249 | J23: =+J13-J18 -> 575.78038 | K23: =+K13-K18 -> 422.2475 | L23: =+K23-J23 -> -153.53287 | M23: =+M13-M18 -> 666.19673 | N23: =+K23-M23 -> -243.94923 | Q23: 철강재 판매단가 | S23: =+'[6]6월'!$F$10 -> 872058.82 | T23: =+'[6]6월'!$G$10 -> 779915.73 | U23: =+T23-S23 -> -92143.098 | V23: =+'[7]6월'!$G$10 -> 785072.68 | W23: =+T23-V23 -> -5156.9519
C24: 계 | E24: =SUM(E20:E23) -> 3806.0543 | F24: =SUM(F20:F23) -> 2286.5227 | G24: =+F24-E24 -> -1519.5317 | H24: =SUM(H20:H23) -> 4426.0509 | I24: =+F24-H24 -> -2139.5282 | J24: =SUM(J20:J23) -> 20802.425 | K24: =SUM(K20:K23) -> 12764.559 | L24: =+K24-J24 -> -8037.866 | M24: =SUM(M20:M23) -> 27775.822 | N24: =+K24-M24 -> -15011.262 | Q24: 철강재 마진률 | S24: =+'[6]6월'!$F$15 -> 0.02394688 | T24: =+'[6]6월'!$G$15 -> 0.025690431 | U24: =+T24-S24 -> 0.0017435505 | V24: =+'[6]6월'!$G$15 -> 0.025690431 | W24: =+T24-V24 -> 0
C25: 판관비 | D25: 레미콘 | E25: =+('[1]6월'!$Z$13+'[1]6월'!$Z$20)/1000 -> 688.69596 | F25: =+('[2]6월'!$Z$13+'[2]6월'!$Z$20)/1000 -> 694.4757 | G25: =+F25-E25 -> 5.779745 | H25: =+('[3]6월'!$Z$13+'[3]6월'!$Z$20)/1000 -> 642.48265 | I25: =+F25-H25 -> 51.993052 | J25: =+('[1]6월누계'!$Z$13+'[1]6월누계'!$Z$20)/1000 -> 4053.1778 | K25: =+('[2]6월누계'!$Z$13+'[2]6월누계'!$Z$20)/1000 -> 4022.9415 | L25: =+K25-J25 -> -30.236311 | M25: =+('[3]6월누계'!$Z$13+'[3]6월누계'!$Z$20)/1000 -> 3966.5114 | N25: =+K25-M25 -> 56.430019 | Q25: □ 골재
D26: 건자재 | E26: =+('[1]6월'!$AA$13+'[1]6월'!$AA$20)/1000 -> 133.61733 | F26: =+('[2]6월'!$AO$13+'[2]6월'!$AO$20)/1000 -> 139.41173 | G26: =+F26-E26 -> 5.794407 | H26: =+('[3]6월'!$AO$13+'[3]6월'!$AO$20)/1000 -> 130.82736 | I26: =+F26-H26 -> 8.584376 | J26: =+('[1]6월누계'!$AA$13+'[1]6월누계'!$AA$20)/1000 -> 769.93695 | K26: =+('[2]6월누계'!$AO$13+'[2]6월누계'!$AO$20)/1000 -> 883.58662 | L26: =+K26-J26 -> 113.64967 | M26: =+('[3]6월누계'!$AO$13+'[3]6월누계'!$AO$20)/1000 -> 817.55946 | N26: =+K26-M26 -> 66.027157 | Q26: 구분 | S26: 계획 | T26: 실적 | U26: 계획대비 | V26: 전년 | W26: 전년대비
D27: 골재 | E27: =+('[1]6월'!$AE$13+'[1]6월'!$AE$20+'[1]6월'!$AE$22)/1000 -> 53.284008 | F27: =+('[2]6월'!$AN$13+'[2]6월'!$AN$20+'[2]6월'!$AN$22)/1000 -> 48.576527 | G27: =+F27-E27 -> -4.7074808 | H27: =+('[3]6월'!$AN$13+'[3]6월'!$AN$20+'[3]6월'!$AN$22)/1000 -> 44.161082 | I27: =+F27-H27 -> 4.4154443 | J27: =+('[1]6월누계'!$AE$13+'[1]6월누계'!$AE$20+'[1]6월누계'!$AE$22)/1000 -> 290.67866 | K27: =+('[2]6월누계'!$AN$13+'[2]6월누계'!$AN$20+'[2]6월누계'!$AN$22)/1000 -> 283.17803 | L27: =+K27-J27 -> -7.5006309 | M27: =+('[3]6월누계'!$AN$13+'[3]6월누계'!$AN$20+'[3]6월누계'!$AN$22)/1000 -> 268.05111 | N27: =+K27-M27 -> 15.126925 | Q27: 판매량 | R27: 자가 | S27: =('[8]부산모래장(당월)'!$Q$48+[9]원가손익!$W$13+[10]손익!$F$10)/1000 -> 60.236782 | T27: =('[8]부산모래장(당월)'!$R$48+[9]원가손익!$X$13+[10]손익!$G$10)/1000 -> 43.506 | U27: =+T27-S27 -> -16.730782 | V27: =+[11]손익총괄!$V$27 -> 46.66 | W27: =+T27-V27 -> -3.154
D28: 기타 | E28: =+('[1]6월'!$E$13+'[1]6월'!$E$20)/1000-E25-E26-E27+('[1]6월'!$E$22/1000) -> 2691.733 | F28: =+('[2]6월'!$F$13+'[2]6월'!$F$20)/1000-F25-F26-F27+'[2]6월'!$F$22/1000 -> 3213.6692 | G28: =+F28-E28 -> 521.93621 | H28: =+('[3]6월'!$F$13+'[3]6월'!$F$20)/1000-H25-H26-H27+'[3]6월'!$F$22/1000 -> 1932.9306 | I28: =+F28-H28 -> 1280.7385 | J28: =+('[1]6월누계'!$E$13+'[1]6월누계'!$E$20)/1000-J25-J26-J27+('[1]6월누계'!$E$22/1000) -> 10368.916 | K28: =+('[2]6월누계'!$F$13+'[2]6월누계'!$F$20)/1000-K25-K26-K27+'[2]6월누계'!$F$22/1000 -> 11741.177 | L28: =+K28-J28 -> 1372.2608 | M28: =+('[3]6월누계'!$F$13+'[3]6월누계'!$F$20)/1000-M25-M26-M27+'[3]6월누계'!$F$22/1000 -> 10377.364 | N28: =+K28-M28 -> 1363.8129 | R28: 외판 | S28: =('[8]부산모래장(당월)'!$Q$47+[9]원가손익!$W$15+[10]손익!$F$12)/1000 -> 55.5 | T28: =('[8]부산모래장(당월)'!$R$47+[9]원가손익!$X$15+[10]손익!$G$12)/1000 -> 26.183 | U28: =+T28-S28 -> -29.317 | V28: =+[11]손익총괄!$V$28 -> 17.913 | W28: =+T28-V28 -> 8.27
C29: 계 | E29: =SUM(E25:E28) -> 3567.3303 | F29: =SUM(F25:F28) -> 4096.1331 | G29: =+F29-E29 -> 528.80288 | H29: =SUM(H25:H28) -> 2750.4017 | I29: =+F29-H29 -> 1345.7314 | J29: =SUM(J25:J28) -> 15482.709 | K29: =SUM(K25:K28) -> 16930.883 | L29: =+K29-J29 -> 1448.1735 | M29: =SUM(M25:M28) -> 15429.486 | N29: =+K29-M29 -> 1501.397 | Q29: 합 계 | S29: =SUM(S27:S28) -> 115.73678 | T29: =SUM(T27:T28) -> 69.689 | U29: =+T29-S29 -> -46.047782 | V29: =SUM(V27:V28) -> 64.573 | W29: =+T29-V29 -> 5.116
C30: 영업이익 | D30: 레미콘 | E30: =+E20-E25 -> 2659.948 | F30: =+F20-F25 -> 1326.1339 | G30: =+F30-E30 -> -1333.814 | H30: =+H20-H25 -> 3510.4462 | I30: =+F30-H30 -> -2184.3123 | J30: =+J20-J25 -> 13043.042 | K30: =+K20-K25 -> 7704.1135 | L30: =+K30-J30 -> -5338.9288 | M30: =+M20-M25 -> 20921.862 | N30: =+K30-M30 -> -13217.749 | Q30: □ 기타내역(영업이익)
D31: % | E31: =+E30/E10 -> 0.091199256 | F31: =+F30/F10 -> 0.05362193 | G31: =+F31-E31 -> -0.037577326 | H31: =+H30/H10 -> 0.11406056 | I31: =+F31-H31 -> -0.060438633 | J31: =+J30/J10 -> 0.082004737 | K31: =+K30/K10 -> 0.054767408 | L31: =+K31-J31 -> -0.027237329 | M31: =+M30/M10 -> 0.11607853 | N31: =+K31-M31 -> -0.061311122 | Q31: 구분 | S31: 계획 | T31: 실적 | U31: 계획대비 | V31: 전년 | W31: 전년대비
D32: 건자재 | E32: =+E21-E26 -> 167.8594 | F32: =+F21-F26 -> 35.646069 | G32: =+F32-E32 -> -132.21333 | H32: =+H21-H26 -> 150.16984 | I32: =+F32-H32 -> -114.52377 | J32: =+J21-J26 -> 1069.4058 | K32: =+K21-K26 -> -24.674131 | L32: =+K32-J32 -> -1094.08 | M32: =+M21-M26 -> 415.12243 | N32: =+K32-M32 -> -439.79657 | Q32: 레미콘임대 | S32: =+'사업장별(당월)'!T33 -> -1.9239863 | T32: =+'사업장별(당월)'!U33 -> -32.2143 | U32: =+T32-S32 -> -30.290314 | V32: =+'사업장별(당월)'!W33 -> -23.482855 | W32: =+T32-V32 -> -8.731445
D33: 골재 | E33: =+E22-E27 -> 66.08405 | F33: =+F22-F27 -> -92.546442 | G33: =+F33-E33 -> -158.63049 | H33: =+H22-H27 -> -24.058962 | I33: =+F33-H33 -> -68.487479 | J33: =+J22-J27 -> 1000.4033 | K33: =+K22-K27 -> -526.83377 | L33: =+K33-J33 -> -1527.2371 | M33: =+M22-M27 -> 720.51825 | N33: =+K33-M33 -> -1247.352 | Q33: 임대 | S33: =+'사업장별(당월)'!T34 -> 76.556944 | T33: =+'사업장별(당월)'!U34 -> 73.218889 | U33: =+T33-S33 -> -3.338055 | V33: =+'사업장별(당월)'!W34 -> 76.100837 | W33: =+T33-V33 -> -2.881948
D34: 기타 | E34: =+E23-E28 -> -2655.1673 | F34: =+F23-F28 -> -3078.844 | G34: =+F34-E34 -> -423.67669 | H34: =+H23-H28 -> -1960.908 | I34: =+F34-H34 -> -1117.9361 | J34: =+J23-J28 -> -9793.1354 | K34: =+K23-K28 -> -11318.929 | L34: =+K34-J34 -> -1525.7936 | M34: =+M23-M28 -> -9711.1669 | N34: =+K34-M34 -> -1607.7621 | Q34: 공통비 | S34: =+'사업장별(당월)'!T35 -> -2607.3115 | T34: =+'사업장별(당월)'!U35 -> -2809.4658 | U34: =+T34-S34 -> -202.15433 | V34: =+'사업장별(당월)'!W35 -> -2487.3998 | W34: =+T34-V34 -> -322.06597
C35: 계 | E35: =SUM(E30,E32:E34) -> 238.72408 | F35: =SUM(F30,F32:F34) -> -1809.6105 | G35: =+F35-E35 -> -2048.3345 | H35: =SUM(H30,H32:H34) -> 1675.6492 | I35: =+F35-H35 -> -3485.2596 | J35: =SUM(J30,J32:J34) -> 5319.716 | K35: =SUM(K30,K32:K34) -> -4166.3234 | L35: =+K35-J35 -> -9486.0394 | M35: =SUM(M30,M32:M34) -> 12346.336 | N35: =+K35-M35 -> -16512.659 | Q35: 기타 | S35: =+S36-S32-S33-S34 -> -122.4888 | T35: =+T36-T32-T33-T34 -> -310.3828 | U35: =+T35-S35 -> -187.89399 | V35: =+V36-V32-V33-V34 -> 473.8739 | W35: =+T35-V35 -> -784.2567
D36: % | E36: =+E35/E14 -> 0.0056162538 | F36: =+F35/F14 -> -0.054192538 | G36: =+F36-E36 -> -0.059808792 | H36: =+H35/H14 -> 0.041586028 | I36: =+F36-H36 -> -0.095778567 | J36: =+J35/J14 -> 0.022313244 | K36: =+K35/K14 -> -0.020323505 | L36: =+K36-J36 -> -0.04263675 | M36: =+M35/M14 -> 0.051311459 | N36: =+K36-M36 -> -0.071634965 | Q36: 합계 | S36: =+'사업장별(당월)'!T41 -> -2655.1673 | T36: =+'사업장별(당월)'!U41 -> -3078.844 | U36: =+T36-S36 -> -423.67669 | V36: =+'사업장별(당월)'!W41 -> -1960.908 | W36: =+T36-V36 -> -1117.9361
E38: =+'[1]6월'!$E$26/1000 -> 238.72408 | F38: =+'[2]6월'!$F$26/1000 -> -1809.6105 | H38: =+'[3]6월'!$F$26/1000 -> 1675.6492 | J38: =+'[1]6월누계'!$E$26/1000 -> 5319.716 | K38: =+'[2]6월누계'!$F$26/1000 -> -4166.3234 | M38: =+'[3]6월누계'!$F$26/1000 -> 12346.336
E39: =+E35=E38 -> FALSE | F39: =+F35=F38 -> TRUE | H39: =+H35=H38 -> FALSE | J39: =+J35=J38 -> FALSE | K39: =+K35=K38 -> TRUE | M39: =+M35=M38 -> TRUE
E40: =+E35-E38 -> 1.3642421e-12 | F40: =+F35-F38 -> 0 | H40: =+H35-H38 -> -6.8212103e-12 | J40: =+J35-J38 -> 0 | K40: =+K35-K38 -> 0 | M40: =+M35-M38 -> 0

Sheet 사업장별(당월)
H3: □ 사업장별 손익실적(2025-06)
AG4: [단위 : 천㎥, 톤, 백만원]
H5: 구분 | J5: 물량 | O5: 매출 | T5: 영업이익(공통비 배부전) | Y5: 판매단가 | AB5: 변동비 | AE5: 공헌이익
A6: 2024년 6월 마감 손익 | J6: 계획 | K6: 실적 | L6: 차이 | M6: 전년 | N6: 차이 | O6: 계획 | P6: 실적 | Q6: 차이 | R6: 전년 | S6: 차이 | T6: 계획 | U6: 실적 | V6: 차이 | W6: 전년 | X6: 차이 | Y6: 계획 | Z6: 실적 | AA6: 전년 | AB6: 계획 | AC6: 실적 | AD6: 전년 | AE6: 계획 | AF6: 실적 | AG6: 전년
B7: 안양 | G7: =+I7 -> 안양 | H7: 레미콘 | I7: 안양 | J7: =+IFERROR(HLOOKUP($B7,'[1]6월'!$D$6:$BN$259,2,),)/1000 -> 42 | K7: =+IFERROR(HLOOKUP($B7,'[2]6월'!$F$6:$CP$99,2,),)/1000 -> 34.536 | L7: =+K7-J7 -> -7.464 | M7: =+IFERROR(HLOOKUP($B7,'[3]6월'!$F$6:$CC$57,2,),)/1000 -> 35.374 | N7: =+K7-M7 -> -0.838 | O7: =+IFERROR(HLOOKUP($B7,'[1]6월'!$D$6:$BN$259,3,),)/1000 -> 4133.2121 | P7: =+IFERROR(HLOOKUP($B7,'[2]6월'!$F$6:$CP$99,3,),)/1000 -> 3316.1411 | Q7: =+P7-O7 -> -817.07098 | R7: =+IFERROR(HLOOKUP($B7,'[3]6월'!$F$6:$CC$57,3,),)/1000 -> 3552.1473 | S7: =+P7-R7 -> -236.00619 | T7: =+IFERROR(HLOOKUP($B7,'[1]6월'!$D$6:$BN$259,16,),)/1000 -> 348.62122 | U7: =+IFERROR(HLOOKUP($B7,'[2]6월'!$F$6:$CP$99,16,),)/1000 -> 223.43829 | V7: =+U7-T7 -> -125.18293 | W7: =+IFERROR(HLOOKUP($B7,'[3]6월'!$F$6:$CC$57,16,),)/1000 -> 326.98677 | X7: =+U7-W7 -> -103.54848 | Y7: =+[4]안양!$Q$85 -> 98409.811 | Z7: =+[4]안양!$R$85 -> 96027.028 | AA7: =+[5]안양!$Q$85 -> 100399.7 | AB7: =+[4]안양!$Q$89 -> 81464.438 | AC7: =+[4]안양!$R$89 -> 77852.534 | AD7: =+[5]안양!$Q$89 -> 81293.291 | AE7: =+Y7-AB7 -> 16945.373 | AF7: =+Z7-AC7 -> 18174.494 | AG7: =+AA7-AD7 -> 19106.408
B8: 인천 | G8: =+I8 -> 인천 | H8: 직영 | I8: 인천 | J8: =+IFERROR(HLOOKUP($B8,'[1]6월'!$D$6:$BN$259,2,),)/1000 -> 25 | K8: =+IFERROR(HLOOKUP($B8,'[2]6월'!$F$6:$CP$99,2,),)/1000 -> 31.384 | L8: =+K8-J8 -> 6.384 | M8: =+IFERROR(HLOOKUP($B8,'[3]6월'!$F$6:$CC$57,2,),)/1000 -> 28.969 | N8: =+K8-M8 -> 2.415 | O8: =+IFERROR(HLOOKUP($B8,'[1]6월'!$D$6:$BN$259,3,),)/1000 -> 2453.0911 | P8: =+IFERROR(HLOOKUP($B8,'[2]6월'!$F$6:$CP$99,3,),)/1000 -> 3030.343 | Q8: =+P8-O8 -> 577.25188 | R8: =+IFERROR(HLOOKUP($B8,'[3]6월'!$F$6:$CC$57,3,),)/1000 -> 2858.2985 | S8: =+P8-R8 -> 172.04452 | T8: =+IFERROR(HLOOKUP($B8,'[1]6월'!$D$6:$BN$259,16,),)/1000 -> 34.119049 | U8: =+IFERROR(HLOOKUP($B8,'[2]6월'!$F$6:$CP$99,16,),)/1000 -> 58.69906 | V8: =+U8-T8 -> 24.580011 | W8: =+IFERROR(HLOOKUP($B8,'[3]6월'!$F$6:$CC$57,16,),)/1000 -> 173.72608 | X8: =+U8-W8 -> -115.02702 | Y8: =+[4]인천!$Q$85 -> 98123.644 | Z8: =+[4]인천!$R$85 -> 96556.939 | AA8: =+[5]인천!$Q$85 -> 98667.488 | AB8: =+[4]인천!$Q$89 -> 82366.592 | AC8: =+[4]인천!$R$89 -> 83278.753 | AD8: =+[5]인천!$Q$89 -> 81685.367 | AE8: =+Y8-AB8 -> 15757.052 | AF8: =+Z8-AC8 -> 13278.186 | AG8: =+AA8-AD8 -> 16982.12
B9: 파주 | G9: =+I9 -> 파주 | I9: 파주 | J9: =+IFERROR(HLOOKUP($B9,'[1]6월'!$D$6:$BN$259,2,),)/1000 -> 23 | K9: =+IFERROR(HLOOKUP($B9,'[2]6월'!$F$6:$CP$99,2,),)/1000 -> 16.752 | L9: =+K9-J9 -> -6.248 | M9: =+IFERROR(HLOOKUP($B9,'[3]6월'!$F$6:$CC$57,2,),)/1000 -> 31.1242 | N9: =+K9-M9 -> -14.3722 | O9: =+IFERROR(HLOOKUP($B9,'[1]6월'!$D$6:$BN$259,3,),)/1000 -> 2219.0674 | P9: =+IFERROR(HLOOKUP($B9,'[2]6월'!$F$6:$CP$99,3,),)/1000 -> 1552.3683 | Q9: =+P9-O9 -> -666.69908 | R9: =+IFERROR(HLOOKUP($B9,'[3]6월'!$F$6:$CC$57,3,),)/1000 -> 2951.5883 | S9: =+P9-R9 -> -1399.22 | T9: =+IFERROR(HLOOKUP($B9,'[1]6월'!$D$6:$BN$259,16,),)/1000 -> 151.09665 | U9: =+IFERROR(HLOOKUP($B9,'[2]6월'!$F$6:$CP$99,16,),)/1000 -> 52.434515 | V9: =+U9-T9 -> -98.662136 | W9: =+IFERROR(HLOOKUP($B9,'[3]6월'!$F$6:$CC$57,16,),)/1000 -> 256.19066 | X9: =+U9-W9 -> -203.75615 | Y9: =+[4]파주!$Q$85 -> 96481.19 | Z9: =+[4]파주!$R$85 -> 92654.579 | AA9: =+[5]파주!$Q$85 -> 94837.488 | AB9: =+[4]파주!$Q$89 -> 79787.647 | AC9: =+[4]파주!$R$89 -> 76912.383 | AD9: =+[5]파주!$Q$89 -> 79548.98 | AE9: =+Y9-AB9 -> 16693.543 | AF9: =+Z9-AC9 -> 15742.196 | AG9: =+AA9-AD9 -> 15288.508
B10: 김포 | G10: =+I10 -> 김포 | I10: 김포 | J10: =+IFERROR(HLOOKUP($B10,'[1]6월'!$D$6:$BN$259,2,),)/1000 -> 16 | K10: =+IFERROR(HLOOKUP($B10,'[2]6월'!$F$6:$CP$99,2,),)/1000 -> 12.4515 | L10: =+K10-J10 -> -3.5485 | M10: =+IFERROR(HLOOKUP($B10,'[3]6월'!$F$6:$CC$57,2,),)/1000 -> 11.818 | N10: =+K10-M10 -> 0.6335 | O10: =+IFERROR(HLOOKUP($B10,'[1]6월'!$D$6:$BN$259,3,),)/1000 -> 1514.4794 | P10: =+IFERROR(HLOOKUP($B10,'[2]6월'!$F$6:$CP$99,3,),)/1000 -> 1188.4695 | Q10: =+P10-O10 -> -326.00992 | R10: =+IFERROR(HLOOKUP($B10,'[3]6월'!$F$6:$CC$57,3,),)/1000 -> 1148.841 | S10: =+P10-R10 -> 39.628444 | T10: =+IFERROR(HLOOKUP($B10,'[1]6월'!$D$6:$BN$259,16,),)/1000 -> 117.21328 | U10: =+IFERROR(HLOOKUP($B10,'[2]6월'!$F$6:$CP$99,16,),)/1000 -> 44.420114 | V10: =+U10-T10 -> -72.793166 | W10: =+IFERROR(HLOOKUP($B10,'[3]6월'!$F$6:$CC$57,16,),)/1000 -> 109.51813 | X10: =+U10-W10 -> -65.098017 | Y10: =+[4]김포!$Q$85 -> 94654.961 | Z10: =+[4]김포!$R$85 -> 95523.649 | AA10: =+[5]김포!$Q$85 -> 97204.532 | AB10: =+[4]김포!$Q$89 -> 75862.787 | AC10: =+[4]김포!$R$89 -> 75944.515 | AD10: =+[5]김포!$Q$89 -> 73416.58 | AE10: =+Y10-AB10 -> 18792.174 | AF10: =+Z10-AC10 -> 19579.135 | AG10: =+AA10-AD10 -> 23787.951
B11: 부산 | G11: =+I11 -> 부산 | I11: 부산 | J11: =+IFERROR(HLOOKUP($B11,'[1]6월'!$D$6:$BN$259,2,),)/1000 -> 20 | K11: =+IFERROR(HLOOKUP($B11,'[2]6월'!$F$6:$CP$99,2,),)/1000 -> 22.418 | L11: =+K11-J11 -> 2.418 | M11: =+IFERROR(HLOOKUP($B11,'[3]6월'!$F$6:$CC$57,2,),)/1000 -> 18.738 | N11: =+K11-M11 -> 3.68 | O11: =+IFERROR(HLOOKUP($B11,'[1]6월'!$D$6:$BN$259,3,),)/1000 -> 2153.9997 | P11: =+IFERROR(HLOOKUP($B11,'[2]6월'!$F$6:$CP$99,3,),)/1000 -> 2477.2466 | Q11: =+P11-O11 -> 323.24685 | R11: =+IFERROR(HLOOKUP($B11,'[3]6월'!$F$6:$CC$57,3,),)/1000 -> 1988.3392 | S11: =+P11-R11 -> 488.90745 | T11: =+IFERROR(HLOOKUP($B11,'[1]6월'!$D$6:$BN$259,16,),)/1000 -> 135.90221 | U11: =+IFERROR(HLOOKUP($B11,'[2]6월'!$F$6:$CP$99,16,),)/1000 -> 265.89067 | V11: =+U11-T11 -> 129.98846 | W11: =+IFERROR(HLOOKUP($B11,'[3]6월'!$F$6:$CC$57,16,),)/1000 -> 118.63264 | X11: =+U11-W11 -> 147.25803 | Y11: =+[4]부산!$Q$85 -> 107699.99 | Z11: =+[4]부산!$R$85 -> 110502.57 | AA11: =+[5]부산!$Q$85 -> 106112.67 | AB11: =+[4]부산!$Q$89 -> 84806.942 | AC11: =+[4]부산!$R$89 -> 85372.301 | AD11: =+[5]부산!$Q$89 -> 82775.926 | AE11: =+Y11-AB11 -> 22893.045 | AF11: =+Z11-AC11 -> 25130.268 | AG11: =+AA11-AD11 -> 23336.741
B12: 서부산 | G12: =+I12 -> 서부산 | I12: 서부산 | J12: =+IFERROR(HLOOKUP($B12,'[1]6월'!$D$6:$BN$259,2,),)/1000 -> 20 | K12: =+IFERROR(HLOOKUP($B12,'[2]6월'!$F$6:$CP$99,2,),)/1000 -> 13.691 | L12: =+K12-J12 -> -6.309 | M12: =+IFERROR(HLOOKUP($B12,'[3]6월'!$F$6:$CC$57,2,),)/1000 -> 23.641 | N12: =+K12-M12 -> -9.95 | O12: =+IFERROR(HLOOKUP($B12,'[1]6월'!$D$6:$BN$259,3,),)/1000 -> 1985.997 | P12: =+IFERROR(HLOOKUP($B12,'[2]6월'!$F$6:$CP$99,3,),)/1000 -> 1357.6603 | Q12: =+P12-O12 -> -628.33674 | R12: =+IFERROR(HLOOKUP($B12,'[3]6월'!$F$6:$CC$57,3,),)/1000 -> 2359.6325 | S12: =+P12-R12 -> -1001.9722 | T12: =+IFERROR(HLOOKUP($B12,'[1]6월'!$D$6:$BN$259,16,),)/1000 -> 191.23259 | U12: =+IFERROR(HLOOKUP($B12,'[2]6월'!$F$6:$CP$99,16,),)/1000 -> 41.622446 | V12: =+U12-T12 -> -149.61014 | W12: =+IFERROR(HLOOKUP($B12,'[3]6월'!$F$6:$CC$57,16,),)/1000 -> 278.69374 | X12: =+U12-W12 -> -237.07129 | Y12: =+[4]서부산!$Q$85 -> 99299.852 | Z12: =+[4]서부산!$R$85 -> 99164.436 | AA12: =+[5]서부산!$Q$85 -> 99811.027 | AB12: =+[4]서부산!$Q$89 -> 77397.349 | AC12: =+[4]서부산!$R$89 -> 77248.845 | AD12: =+[5]서부산!$Q$89 -> 77851.89 | AE12: =+Y12-AB12 -> 21902.503 | AF12: =+Z12-AC12 -> 21915.592 | AG12: =+AA12-AD12 -> 21959.137
B13: 김해 | G13: =+I13 -> 김해 | I13: 김해 | J13: =+IFERROR(HLOOKUP($B13,'[1]6월'!$D$6:$BN$259,2,),)/1000 -> 15 | K13: =+IFERROR(HLOOKUP($B13,'[2]6월'!$F$6:$CP$99,2,),)/1000 -> 12.166 | L13: =+K13-J13 -> -2.834 | M13: =+IFERROR(HLOOKUP($B13,'[3]6월'!$F$6:$CC$57,2,),)/1000 -> 12.699 | N13: =+K13-M13 -> -0.533 | O13: =+IFERROR(HLOOKUP($B13,'[1]6월'!$D$6:$BN$259,3,),)/1000 -> 1444.4978 | P13: =+IFERROR(HLOOKUP($B13,'[2]6월'!$F$6:$CP$99,3,),)/1000 -> 1046.7147 | Q13: =+P13-O13 -> -397.7831 | R13: =+IFERROR(HLOOKUP($B13,'[3]6월'!$F$6:$CC$57,3,),)/1000 -> 1187.9416 | S13: =+P13-R13 -> -141.2269 | T13: =+IFERROR(HLOOKUP($B13,'[1]6월'!$D$6:$BN$259,16,),)/1000 -> 136.56194 | U13: =+IFERROR(HLOOKUP($B13,'[2]6월'!$F$6:$CP$99,16,),)/1000 -> 3.598305 | V13: =+U13-T13 -> -132.96364 | W13: =+IFERROR(HLOOKUP($B13,'[3]6월'!$F$6:$CC$57,16,),)/1000 -> 58.544437 | X13: =+U13-W13 -> -54.946132 | Y13: =+[4]김해!$Q$85 -> 96299.853 | Z13: =+[4]김해!$R$85 -> 86036.06 | AA13: =+[5]김해!$Q$85 -> 93546.074 | AB13: =+[4]김해!$Q$89 -> 76676.718 | AC13: =+[4]김해!$R$89 -> 73045.404 | AD13: =+[5]김해!$Q$89 -> 77602.809 | AE13: =+Y13-AB13 -> 19623.135 | AF13: =+Z13-AC13 -> 12990.656 | AG13: =+AA13-AD13 -> 15943.266
B14: 정관 | G14: =+I14 -> 정관 | I14: 정관 | J14: =+IFERROR(HLOOKUP($B14,'[1]6월'!$D$6:$BN$259,2,),)/1000 -> 19 | K14: =+IFERROR(HLOOKUP($B14,'[2]6월'!$F$6:$CP$99,2,),)/1000 -> 25.1725 | L14: =+K14-J14 -> 6.1725 | M14: =+IFERROR(HLOOKUP($B14,'[3]6월'!$F$6:$CC$57,2,),)/1000 -> 19.584 | N14: =+K14-M14 -> 5.5885 | O14: =+IFERROR(HLOOKUP($B14,'[1]6월'!$D$6:$BN$259,3,),)/1000 -> 1937.9914 | P14: =+IFERROR(HLOOKUP($B14,'[2]6월'!$F$6:$CP$99,3,),)/1000 -> 2514.551 | Q14: =+P14-O14 -> 576.5596 | R14: =+IFERROR(HLOOKUP($B14,'[3]6월'!$F$6:$CC$57,3,),)/1000 -> 1952.774 | S14: =+P14-R14 -> 561.77698 | T14: =+IFERROR(HLOOKUP($B14,'[1]6월'!$D$6:$BN$259,16,),)/1000 -> 142.30579 | U14: =+IFERROR(HLOOKUP($B14,'[2]6월'!$F$6:$CP$99,16,),)/1000 -> 254.99888 | V14: =+U14-T14 -> 112.69309 | W14: =+IFERROR(HLOOKUP($B14,'[3]6월'!$F$6:$CC$57,16,),)/1000 -> 142.38129 | X14: =+U14-W14 -> 112.61759 | Y14: =+[4]정관!$Q$85 -> 101999.55 | Z14: =+[4]정관!$R$85 -> 99892.779 | AA14: =+[5]정관!$Q$85 -> 99712.725 | AB14: =+[4]정관!$Q$89 -> 82319.876 | AC14: =+[4]정관!$R$89 -> 80753.318 | AD14: =+[5]정관!$Q$89 -> 80844.669 | AE14: =+Y14-AB14 -> 19679.67 | AF14: =+Z14-AC14 -> 19139.461 | AG14: =+AA14-AD14 -> 18868.056
B15: 양산 | G15: =+I15 -> 양산 | I15: 양산 | J15: =+IFERROR(HLOOKUP($B15,'[1]6월'!$D$6:$BN$259,2,),)/1000 -> 12 | K15: =+IFERROR(HLOOKUP($B15,'[2]6월'!$F$6:$CP$99,2,),)/1000 -> 9.065 | L15: =+K15-J15 -> -2.935 | M15: =+IFERROR(HLOOKUP($B15,'[3]6월'!$F$6:$CC$57,2,),)/1000 -> 12.081 | N15: =+K15-M15 -> -3.016 | O15: =+IFERROR(HLOOKUP($B15,'[1]6월'!$D$6:$BN$259,3,),)/1000 -> 1133.46 | P15: =+IFERROR(HLOOKUP($B15,'[2]6월'!$F$6:$CP$99,3,),)/1000 -> 825.0472 | Q15: =+P15-O15 -> -308.4128 | R15: =+IFERROR(HLOOKUP($B15,'[3]6월'!$F$6:$CC$57,3,),)/1000 -> 1127.2838 | S15: =+P15-R15 -> -302.2366 | T15: =+IFERROR(HLOOKUP($B15,'[1]6월'!$D$6:$BN$259,16,),)/1000 -> 102.04454 | U15: =+IFERROR(HLOOKUP($B15,'[2]6월'!$F$6:$CP$99,16,),)/1000 -> 22.080589 | V15: =+U15-T15 -> -79.963948 | W15: =+IFERROR(HLOOKUP($B15,'[3]6월'!$F$6:$CC$57,16,),)/1000 -> 79.077275 | X15: =+U15-W15 -> -56.996686 | Y15: =+[4]양산!$Q$85 -> 94455 | Z15: =+[4]양산!$R$85 -> 91014.584 | AA15: =+[5]양산!$Q$85 -> 93310.471 | AB15: =+[4]양산!$Q$89 -> 73138.031 | AC15: =+[4]양산!$R$89 -> 72380.167 | AD15: =+[5]양산!$Q$89 -> 74393.84 | AE15: =+Y15-AB15 -> 21316.969 | AF15: =+Z15-AC15 -> 18634.416 | AG15: =+AA15-AD15 -> 18916.631
B16: 창원 | G16: =+I16 -> 창원 | I16: 창원 | J16: =+IFERROR(HLOOKUP($B16,'[1]6월'!$D$6:$BN$259,2,),)/1000 -> 14 | K16: =+IFERROR(HLOOKUP($B16,'[2]6월'!$F$6:$CP$99,2,),)/1000 -> 8.634 | L16: =+K16-J16 -> -5.366 | M16: =+IFERROR(HLOOKUP($B16,'[3]6월'!$F$6:$CC$57,2,),)/1000 -> 20.596 | N16: =+K16-M16 -> -11.962 | O16: =+IFERROR(HLOOKUP($B16,'[1]6월'!$D$6:$BN$259,3,),)/1000 -> 1415.4014 | P16: =+IFERROR(HLOOKUP($B16,'[2]6월'!$F$6:$CP$99,3,),)/1000 -> 810.1545 | Q16: =+P16-O16 -> -605.24693 | R16: =+IFERROR(HLOOKUP($B16,'[3]6월'!$F$6:$CC$57,3,),)/1000 -> 2041.9576 | S16: =+P16-R16 -> -1231.8031 | T16: =+IFERROR(HLOOKUP($B16,'[1]6월'!$D$6:$BN$259,16,),)/1000 -> 110.79062 | U16: =+IFERROR(HLOOKUP($B16,'[2]6월'!$F$6:$CP$99,16,),)/1000 -> -32.809767 | V16: =+U16-T16 -> -143.60039 | W16: =+IFERROR(HLOOKUP($B16,'[3]6월'!$F$6:$CC$57,16,),)/1000 -> 281.4937 | X16: =+U16-W16 -> -314.30347 | Y16: =+[4]창원!$Q$85 -> 101100.1 | Z16: =+[4]창원!$R$85 -> 93833.044 | AA16: =+[5]창원!$Q$85 -> 99143.406 | AB16: =+[4]창원!$Q$89 -> 76221.409 | AC16: =+[4]창원!$R$89 -> 72275.631 | AD16: =+[5]창원!$Q$89 -> 74759.318 | AE16: =+Y16-AB16 -> 24878.693 | AF16: =+Z16-AC16 -> 21557.412 | AG16: =+AA16-AD16 -> 24384.088
B17: 대구 | G17: =+I17 -> 대구 | I17: 대구 | J17: =+IFERROR(HLOOKUP($B17,'[1]6월'!$D$6:$BN$259,2,),)/1000 -> 13 | K17: =+IFERROR(HLOOKUP($B17,'[2]6월'!$F$6:$CP$99,2,),)/1000 -> 9.731 | L17: =+K17-J17 -> -3.269 | M17: =+IFERROR(HLOOKUP($B17,'[3]6월'!$F$6:$CC$57,2,),)/1000 -> 15.957 | N17: =+K17-M17 -> -6.226 | O17: =+IFERROR(HLOOKUP($B17,'[1]6월'!$D$6:$BN$259,3,),)/1000 -> 1267.2631 | P17: =+IFERROR(HLOOKUP($B17,'[2]6월'!$F$6:$CP$99,3,),)/1000 -> 840.0075 | Q17: =+P17-O17 -> -427.25556 | R17: =+IFERROR(HLOOKUP($B17,'[3]6월'!$F$6:$CC$57,3,),)/1000 -> 1689.6666 | S17: =+P17-R17 -> -849.65907 | T17: =+IFERROR(HLOOKUP($B17,'[1]6월'!$D$6:$BN$259,16,),)/1000 -> 126.71723 | U17: =+IFERROR(HLOOKUP($B17,'[2]6월'!$F$6:$CP$99,16,),)/1000 -> -2.303044 | V17: =+U17-T17 -> -129.02027 | W17: =+IFERROR(HLOOKUP($B17,'[3]6월'!$F$6:$CC$57,16,),)/1000 -> 285.78178 | X17: =+U17-W17 -> -288.08483 | Y17: =+[4]대구!$Q$85 -> 97481.774 | Z17: =+[4]대구!$R$85 -> 86322.834 | AA17: =+[5]대구!$Q$85 -> 105888.74 | AB17: =+[4]대구!$Q$89 -> 72123.552 | AC17: =+[4]대구!$R$89 -> 70519.348 | AD17: =+[5]대구!$Q$89 -> 76495.675 | AE17: =+Y17-AB17 -> 25358.222 | AF17: =+Z17-AC17 -> 15803.487 | AG17: =+AA17-AD17 -> 29393.061
B18: 울산 | G18: =+I18 -> 울산 | I18: 울산 | J18: =+IFERROR(HLOOKUP($B18,'[1]6월'!$D$6:$BN$259,2,),)/1000 -> 13.5 | K18: =+IFERROR(HLOOKUP($B18,'[2]6월'!$F$6:$CP$99,2,),)/1000 -> 8.376 | L18: =+K18-J18 -> -5.124 | M18: =+IFERROR(HLOOKUP($B18,'[3]6월'!$F$6:$CC$57,2,),)/1000 -> 14.496 | N18: =+K18-M18 -> -6.12 | O18: =+IFERROR(HLOOKUP($B18,'[1]6월'!$D$6:$BN$259,3,),)/1000 -> 1374.991 | P18: =+IFERROR(HLOOKUP($B18,'[2]6월'!$F$6:$CP$99,3,),)/1000 -> 828.049 | Q18: =+P18-O18 -> -546.942 | R18: =+IFERROR(HLOOKUP($B18,'[3]6월'!$F$6:$CC$57,3,),)/1000 -> 1547.3991 | S18: =+P18-R18 -> -719.35015 | T18: =+IFERROR(HLOOKUP($B18,'[1]6월'!$D$6:$BN$259,16,),)/1000 -> 115.7246 | U18: =+IFERROR(HLOOKUP($B18,'[2]6월'!$F$6:$CP$99,16,),)/1000 -> -38.647879 | V18: =+U18-T18 -> -154.37248 | W18: =+IFERROR(HLOOKUP($B18,'[3]6월'!$F$6:$CC$57,16,),)/1000 -> 273.46478 | X18: =+U18-W18 -> -312.11265 | Y18: =+[4]울산!$Q$85 -> 101851.19 | Z18: =+[4]울산!$R$85 -> 98859.718 | AA18: =+[5]울산!$Q$85 -> 106746.63 | AB18: =+[4]울산!$Q$89 -> 81653.824 | AC18: =+[4]울산!$R$89 -> 84325.735 | AD18: =+[5]울산!$Q$89 -> 79098.881 | AE18: =+Y18-AB18 -> 20197.361 | AF18: =+Z18-AC18 -> 14533.983 | AG18: =+AA18-AD18 -> 27647.749
B19: 아산 | G19: =+I19 -> 아산 | I19: 아산 | J19: =+IFERROR(HLOOKUP($B19,'[1]6월'!$D$6:$BN$259,2,),)/1000 -> 24 | K19: =+IFERROR(HLOOKUP($B19,'[2]6월'!$F$6:$CP$99,2,),)/1000 -> 22.926 | L19: =+K19-J19 -> -1.074 | M19: =+IFERROR(HLOOKUP($B19,'[3]6월'!$F$6:$CC$57,2,),)/1000 -> 30.673 | N19: =+K19-M19 -> -7.747 | O19: =+IFERROR(HLOOKUP($B19,'[1]6월'!$D$6:$BN$259,3,),)/1000 -> 2472 | P19: =+IFERROR(HLOOKUP($B19,'[2]6월'!$F$6:$CP$99,3,),)/1000 -> 2159.1979 | Q19: =+P19-O19 -> -312.80213 | R19: =+IFERROR(HLOOKUP($B19,'[3]6월'!$F$6:$CC$57,3,),)/1000 -> 3094.9295 | S19: =+P19-R19 -> -935.73159 | T19: =+IFERROR(HLOOKUP($B19,'[1]6월'!$D$6:$BN$259,16,),)/1000 -> 346.68497 | U19: =+IFERROR(HLOOKUP($B19,'[2]6월'!$F$6:$CP$99,16,),)/1000 -> 102.05387 | V19: =+U19-T19 -> -244.6311 | W19: =+IFERROR(HLOOKUP($B19,'[3]6월'!$F$6:$CC$57,16,),)/1000 -> 517.15088 | X19: =+U19-W19 -> -415.09701 | Y19: =+[4]아산!$Q$85 -> 103000 | Z19: =+[4]아산!$R$85 -> 94181.186 | AA19: =+[5]아산!$Q$85 -> 100900.77 | AB19: =+[4]아산!$Q$89 -> 77429.805 | AC19: =+[4]아산!$R$89 -> 78981.571 | AD19: =+[5]아산!$Q$89 -> 75826.368 | AE19: =+Y19-AB19 -> 25570.195 | AF19: =+Z19-AC19 -> 15199.615 | AG19: =+AA19-AD19 -> 25074.407
B20: 전주 | G20: =+I20 -> 전주 | I20: 전주 | J20: =+IFERROR(HLOOKUP($B20,'[1]6월'!$D$6:$BN$259,2,),)/1000 -> 12 | K20: =+IFERROR(HLOOKUP($B20,'[2]6월'!$F$6:$CP$99,2,),)/1000 -> 11.656 | L20: =+K20-J20 -> -0.344 | M20: =+IFERROR(HLOOKUP($B20,'[3]6월'!$F$6:$CC$57,2,),)/1000 -> 7.9935 | N20: =+K20-M20 -> 3.6625 | O20: =+IFERROR(HLOOKUP($B20,'[1]6월'!$D$6:$BN$259,3,),)/1000 -> 1162.9867 | P20: =+IFERROR(HLOOKUP($B20,'[2]6월'!$F$6:$CP$99,3,),)/1000 -> 1115.7701 | Q20: =+P20-O20 -> -47.21658 | R20: =+IFERROR(HLOOKUP($B20,'[3]6월'!$F$6:$CC$57,3,),)/1000 -> 745.8426 | S20: =+P20-R20 -> 369.92755 | T20: =+IFERROR(HLOOKUP($B20,'[1]6월'!$D$6:$BN$259,16,),)/1000 -> 123.74469 | U20: =+IFERROR(HLOOKUP($B20,'[2]6월'!$F$6:$CP$99,16,),)/1000 -> 88.636493 | V20: =+U20-T20 -> -35.108196 | W20: =+IFERROR(HLOOKUP($B20,'[3]6월'!$F$6:$CC$57,16,),)/1000 -> 26.426647 | X20: =+U20-W20 -> 62.209846 | Y20: =+[4]전주!$Q$85 -> 96915.561 | Z20: =+[4]전주!$R$85 -> 95711.808 | AA20: =+[5]전주!$Q$85 -> 93306.136 | AB20: =+[4]전주!$Q$89 -> 73196.209 | AC20: =+[4]전주!$R$89 -> 74839.857 | AD20: =+[5]전주!$Q$89 -> 69399.752 | AE20: =+Y20-AB20 -> 23719.352 | AF20: =+Z20-AC20 -> 20871.951 | AG20: =+AA20-AD20 -> 23906.384
B21: 군산 | G21: =+I21 -> 군산 | I21: 군산 | J21: =+IFERROR(HLOOKUP($B21,'[1]6월'!$D$6:$BN$259,2,),)/1000 -> 6.5 | K21: =+IFERROR(HLOOKUP($B21,'[2]6월'!$F$6:$CP$99,2,),)/1000 -> 5.354 | L21: =+K21-J21 -> -1.146 | M21: =+IFERROR(HLOOKUP($B21,'[3]6월'!$F$6:$CC$57,2,),)/1000 -> 10.45 | N21: =+K21-M21 -> -5.096 | O21: =+IFERROR(HLOOKUP($B21,'[1]6월'!$D$6:$BN$259,3,),)/1000 -> 718.93599 | P21: =+IFERROR(HLOOKUP($B21,'[2]6월'!$F$6:$CP$99,3,),)/1000 -> 593.4438 | Q21: =+P21-O21 -> -125.49219 | R21: =+IFERROR(HLOOKUP($B21,'[3]6월'!$F$6:$CC$57,3,),)/1000 -> 1231.4346 | S21: =+P21-R21 -> -637.9908 | T21: =+IFERROR(HLOOKUP($B21,'[1]6월'!$D$6:$BN$259,16,),)/1000 -> 157.64927 | U21: =+IFERROR(HLOOKUP($B21,'[2]6월'!$F$6:$CP$99,16,),)/1000 -> 117.55183 | V21: =+U21-T21 -> -40.097437 | W21: =+IFERROR(HLOOKUP($B21,'[3]6월'!$F$6:$CC$57,16,),)/1000 -> 359.65576 | X21: =+U21-W21 -> -242.10393 | Y21: =+[4]군산!$Q$85 -> 110605.54 | Z21: =+[4]군산!$R$85 -> 110841.2 | AA21: =+[5]군산!$Q$85 -> 117840.63 | AB21: =+[4]군산!$Q$89 -> 71663.023 | AC21: =+[4]군산!$R$89 -> 72455.982 | AD21: =+[5]군산!$Q$89 -> 75736.722 | AE21: =+Y21-AB21 -> 38942.513 | AF21: =+Z21-AC21 -> 38385.221 | AG21: =+AA21-AD21 -> 42103.909
B22: 원주 | G22: =+I22 -> 원주 | I22: 원주 | J22: =+IFERROR(HLOOKUP($B22,'[1]6월'!$D$6:$BN$259,2,),)/1000 -> 6 | K22: =+IFERROR(HLOOKUP($B22,'[2]6월'!$F$6:$CP$99,2,),)/1000 -> 4.028 | L22: =+K22-J22 -> -1.972 | M22: =+IFERROR(HLOOKUP($B22,'[3]6월'!$F$6:$CC$57,2,),)/1000 -> 6.349 | N22: =+K22-M22 -> -2.321 | O22: =+IFERROR(HLOOKUP($B22,'[1]6월'!$D$6:$BN$259,3,),)/1000 -> 672 | P22: =+IFERROR(HLOOKUP($B22,'[2]6월'!$F$6:$CP$99,3,),)/1000 -> 434.3115 | Q22: =+P22-O22 -> -237.6885 | R22: =+IFERROR(HLOOKUP($B22,'[3]6월'!$F$6:$CC$57,3,),)/1000 -> 730.5149 | S22: =+P22-R22 -> -296.2034 | T22: =+IFERROR(HLOOKUP($B22,'[1]6월'!$D$6:$BN$259,16,),)/1000 -> 137.76133 | U22: =+IFERROR(HLOOKUP($B22,'[2]6월'!$F$6:$CP$99,16,),)/1000 -> 61.353452 | V22: =+U22-T22 -> -76.407875 | W22: =+IFERROR(HLOOKUP($B22,'[3]6월'!$F$6:$CC$57,16,),)/1000 -> 157.5276 | X22: =+U22-W22 -> -96.17415 | Y22: =+[4]원주!$Q$85 -> 112000 | Z22: =+[4]원주!$R$85 -> 107831.65 | AA22: =+[5]원주!$Q$85 -> 115059.84 | AB22: =+[4]원주!$Q$89 -> 72629.999 | AC22: =+[4]원주!$R$89 -> 69838.045 | AD22: =+[5]원주!$Q$89 -> 75609.7 | AE22: =+Y22-AB22 -> 39370.001 | AF22: =+Z22-AC22 -> 37993.606 | AG22: =+AA22-AD22 -> 39450.137
B23: 제주 | F23: =+K27-J27 -> -36.57 | G23: =+I23 -> 제주 | I23: 제주 | J23: =+IFERROR(HLOOKUP($B23,'[1]6월'!$D$6:$BN$259,2,),)/1000 -> 9 | K23: =+IFERROR(HLOOKUP($B23,'[2]6월'!$F$6:$CP$99,2,),)/1000 -> 5.089 | L23: =+K23-J23 -> -3.911 | M23: =+IFERROR(HLOOKUP($B23,'[3]6월'!$F$6:$CC$57,2,),)/1000 -> 4.611 | N23: =+K23-M23 -> 0.478 | O23: =+IFERROR(HLOOKUP($B23,'[1]6월'!$D$6:$BN$259,3,),)/1000 -> 1106.96 | P23: =+IFERROR(HLOOKUP($B23,'[2]6월'!$F$6:$CP$99,3,),)/1000 -> 641.71046 | Q23: =+P23-O23 -> -465.24954 | R23: =+IFERROR(HLOOKUP($B23,'[3]6월'!$F$6:$CC$57,3,),)/1000 -> 568.44685 | S23: =+P23-R23 -> 73.263612 | T23: =+IFERROR(HLOOKUP($B23,'[1]6월'!$D$6:$BN$259,16,),)/1000 -> 181.77801 | U23: =+IFERROR(HLOOKUP($B23,'[2]6월'!$F$6:$CP$99,16,),)/1000 -> 63.116116 | V23: =+U23-T23 -> -118.66189 | W23: =+IFERROR(HLOOKUP($B23,'[3]6월'!$F$6:$CC$57,16,),)/1000 -> 65.194074 | X23: =+U23-W23 -> -2.077958 | Y23: =+[4]제주!$Q$85 -> 122995.56 | Z23: =+[4]제주!$R$85 -> 126097.56 | AA23: =+[5]제주!$Q$85 -> 123280.6 | AB23: =+[4]제주!$Q$89 -> 91386.196 | AC23: =+[4]제주!$R$89 -> 95299.243 | AD23: =+[5]제주!$Q$89 -> 90143.963 | AE23: =+Y23-AB23 -> 31609.36 | AF23: =+Z23-AC23 -> 30798.312 | AG23: =+AA23-AD23 -> 33136.637
F24: =+K24/J24 -> 0.89739151 | G24: =+I24 -> 수도권 | I24: 수도권 | J24: =SUM(J7:J10) -> 106 | K24: =SUM(K7:K10) -> 95.1235 | L24: =+K24-J24 -> -10.8765 | M24: =SUM(M7:M10) -> 107.2852 | N24: =+K24-M24 -> -12.1617 | O24: =SUM(O7:O10) -> 10319.85 | P24: =SUM(P7:P10) -> 9087.3218 | Q24: =+P24-O24 -> -1232.5281 | R24: =SUM(R7:R10) -> 10510.875 | S24: =+P24-R24 -> -1423.5532 | T24: =SUM(T7:T10) -> 651.0502 | U24: =SUM(U7:U10) -> 378.99198 | V24: =+U24-T24 -> -272.05822 | W24: =SUM(W7:W10) -> 866.42165 | X24: =+U24-W24 -> -487.42966 | Y24: =+[4]수도권!$Q$85 -> 97357.075 | Z24: =+[4]수도권!$R$85 -> 95549.029 | AA24: =+[5]수도권!$Q$85 -> 97972.586 | AB24: =+[4]수도권!$Q$89 -> 80467.846 | AC24: =+[4]수도권!$R$89 -> 79247.43 | AD24: =+[5]수도권!$Q$89 -> 80027.502 | AE24: =+Y24-AB24 -> 16889.229 | AF24: =+Z24-AC24 -> 16301.599 | AG24: =+AA24-AD24 -> 17945.084
F25: =+K25/J25 -> 0.86366403 | G25: =+I25 -> 영남권 | I25: 영남권 | J25: =SUM(J11:J18) -> 126.5 | K25: =SUM(K11:K18) -> 109.2535 | L25: =+K25-J25 -> -17.2465 | M25: =SUM(M11:M18) -> 137.792 | N25: =+K25-M25 -> -28.5385 | O25: =SUM(O11:O18) -> 12713.601 | P25: =SUM(P11:P18) -> 10699.431 | Q25: =+P25-O25 -> -2014.1707 | R25: =SUM(R11:R18) -> 13894.994 | S25: =+P25-R25 -> -3195.5636 | T25: =SUM(T11:T18) -> 1061.2795 | U25: =SUM(U11:U18) -> 514.43019 | V25: =+U25-T25 -> -546.84931 | W25: =SUM(W11:W18) -> 1518.0696 | X25: =+U25-W25 -> -1003.6394 | Y25: =+[4]영남권!$Q$85 -> 100502.78 | Z25: =+[4]영남권!$R$85 -> 97932.156 | AA25: =+[5]영남권!$Q$85 -> 100840.36 | AB25: =+[4]영남권!$Q$89 -> 78600.815 | AC25: =+[4]영남권!$R$89 -> 78415.182 | AD25: =+[5]영남권!$Q$89 -> 78131.984 | AE25: =+Y25-AB25 -> 21901.963 | AF25: =+Z25-AC25 -> 19516.974 | AG25: =+AA25-AD25 -> 22708.372
F26: =+K26/J26 -> 0.85309565 | G26: =+I26 -> 중부권 | I26: 중부권 | J26: =SUM(J19:J23) -> 57.5 | K26: =SUM(K19:K23) -> 49.053 | L26: =+K26-J26 -> -8.447 | M26: =SUM(M19:M23) -> 60.0765 | N26: =+K26-M26 -> -11.0235 | O26: =SUM(O19:O23) -> 6132.8827 | P26: =SUM(P19:P23) -> 4944.4338 | Q26: =+P26-O26 -> -1188.4489 | R26: =SUM(R19:R23) -> 6371.1684 | S26: =+P26-R26 -> -1426.7346 | T26: =SUM(T19:T23) -> 947.61825 | U26: =SUM(U19:U23) -> 432.71176 | V26: =+U26-T26 -> -514.9065 | W26: =SUM(W19:W23) -> 1125.955 | X26: =+U26-W26 -> -693.24321 | Y26: =+[4]중부권!$Q$85 -> 106658.83 | Z26: =+[4]중부권!$R$85 -> 100796.99 | AA26: =+[5]중부권!$Q$85 -> 106050.93 | AB26: =+[4]중부권!$Q$89 -> 77578.004 | AC26: =+[4]중부권!$R$89 -> 78228.566 | AD26: =+[5]중부권!$Q$89 -> 76044.867 | AE26: =+Y26-AB26 -> 29080.826 | AF26: =+Z26-AC26 -> 22568.423 | AG26: =+AA26-AD26 -> 30006.058
F27: =+K27/M27 -> 0.83049952 | G27: =+K27/J27 -> 0.87389655 | H27: 레미콘 계 | J27: =SUM(J24:J26) -> 290 | K27: =SUM(K24:K26) -> 253.43 | L27: =+K27-J27 -> -36.57 | M27: =SUM(M24:M26) -> 305.1537 | N27: =+K27-M27 -> -51.7237 | O27: =SUM(O24:O26) -> 29166.334 | P27: =SUM(P24:P26) -> 24731.186 | Q27: =+P27-O27 -> -4435.1477 | R27: =SUM(R24:R26) -> 30777.038 | S27: =+P27-R27 -> -6045.8514 | T27: =SUM(T24:T26) -> 2659.948 | U27: =SUM(U24:U26) -> 1326.1339 | V27: =+U27-T27 -> -1333.814 | W27: =SUM(W24:W26) -> 3510.4462 | X27: =+U27-W27 -> -2184.3123 | Y27: =+[4]합계!$Q$85 -> 100573.57 | Z27: =+[4]합계!$R$85 -> 97599.047 | AA27: =+[5]합계!$Q$85 -> 100861.45 | AB27: =+[4]합계!$Q$89 -> 79080.448 | AC27: =+[4]합계!$R$89 -> 78689.157 | AD27: =+[5]합계!$Q$89 -> 78384.694 | AE27: =+Y27-AB27 -> 21493.117 | AF27: =+Z27-AC27 -> 18909.89 | AG27: =+AA27-AD27 -> 22476.76 | AI27: =+AF27-AE27 -> -2583.2276 | AJ27: =+AF27-AG27 -> -3566.8706
B28: 건자재 | E28: 건자재영업 | G28: 건자재 | H28: 건자재 | J28: =+IFERROR(HLOOKUP($B28,'[1]6월'!$D$6:$BN$259,2,),) -> 10200 | K28: =+IFERROR(HLOOKUP($E28,'[2]6월'!$F$6:$CP$99,2,),) -> 6733.593 | L28: =+K28-J28 -> -3466.407 | M28: =+IFERROR(HLOOKUP($E28,'[3]6월'!$F$6:$CC$57,2,),) -> 7982.061 | N28: =+K28-M28 -> -1248.468 | O28: =+IFERROR(HLOOKUP($B28,'[1]6월'!$D$6:$BN$259,3,),)/1000 -> 11165.946 | P28: =+IFERROR(HLOOKUP($E28,'[2]6월'!$F$6:$CP$99,3,),)/1000 -> 7056.4882 | Q28: =+P28-O28 -> -4109.4574 | R28: =+IFERROR(HLOOKUP($E28,'[3]6월'!$F$6:$CC$57,3,),)/1000 -> 7873.3448 | S28: =+P28-R28 -> -816.85662 | T28: =+IFERROR(HLOOKUP($B28,'[1]6월'!$D$6:$BN$259,16,),)/1000 -> 167.8594 | U28: =+IFERROR(HLOOKUP($E28,'[2]6월'!$F$6:$CP$99,16,),)/1000 -> 35.646069 | V28: =+U28-T28 -> -132.21333 | W28: =+IFERROR(HLOOKUP($E28,'[3]6월'!$F$6:$CC$57,16,),)/1000 -> 150.16984 | X28: =+U28-W28 -> -114.52377 | Y28: ■ 비고
B29: 부산모래장 | C29: 부산골재 | G29: =+I29 -> 부산모래장 | H29: 골재 | I29: 부산모래장 | J29: =+IFERROR(HLOOKUP($B29,'[1]6월'!$D$6:$BN$259,2,),)/1000 -> 24.456225 | K29: =+IFERROR(HLOOKUP($C29,'[2]6월'!$F$6:$CP$99,2,),)/1000 -> 27.089 | L29: =+K29-J29 -> 2.6327751 | M29: =+IFERROR(HLOOKUP($C29,'[3]6월'!$F$6:$CC$57,2,),)/1000 -> 18.49 | N29: =+K29-M29 -> 8.599 | O29: =+IFERROR(HLOOKUP($B29,'[1]6월'!$D$6:$BN$259,3,),)/1000 -> 663.60657 | P29: =+IFERROR(HLOOKUP($C29,'[2]6월'!$F$6:$CP$99,3,),)/1000 -> 759.9665 | Q29: =+P29-O29 -> 96.359929 | R29: =+IFERROR(HLOOKUP($C29,'[3]6월'!$F$6:$CC$57,3,),)/1000 -> 536.244 | S29: =+P29-R29 -> 223.7225 | T29: =+IFERROR(HLOOKUP($B29,'[1]6월'!$D$6:$BN$259,21,),)/1000 -> -4.2897891 | U29: =+IFERROR(HLOOKUP($C29,'[2]6월'!$F$6:$CP$99,21,),)/1000 -> -51.607761 | V29: =+U29-T29 -> -47.317972 | W29: =+IFERROR(HLOOKUP($C29,'[3]6월'!$F$6:$CC$57,21,),)/1000 -> -53.966539 | X29: =+U29-W29 -> 2.3587775 | Y29: - 6월 판가 1군 마이너스 계산서 0.8억
B30: 서부산크라샤 | C30: 서부산골재 | G30: =+I30 -> 서부산CR | I30: 서부산CR | J30: =+IFERROR(HLOOKUP($B30,'[1]6월'!$D$6:$BN$259,2,),)/1000 -> 47.619138 | K30: =+IFERROR(HLOOKUP($C30,'[2]6월'!$F$6:$CP$99,2,),)/1000 -> 24.568 | L30: =+K30-J30 -> -23.051138 | M30: =+IFERROR(HLOOKUP($C30,'[3]6월'!$F$6:$CC$57,2,),)/1000 -> 24.944 | N30: =+K30-M30 -> -0.376 | O30: =+IFERROR(HLOOKUP($B30,'[1]6월'!$D$6:$BN$259,3,),)/1000 -> 687.6158 | P30: =+IFERROR(HLOOKUP($C30,'[2]6월'!$F$6:$CP$99,3,),)/1000 -> 339.352 | Q30: =+P30-O30 -> -348.2638 | R30: =+IFERROR(HLOOKUP($C30,'[3]6월'!$F$6:$CC$57,3,),)/1000 -> 344.552 | S30: =+P30-R30 -> -5.2 | T30: =+IFERROR(HLOOKUP($B30,'[1]6월'!$D$6:$BN$259,21,),)/1000 -> 22.68311 | U30: =+IFERROR(HLOOKUP($C30,'[2]6월'!$F$6:$CP$99,21,),)/1000 -> 22.764294 | V30: =+U30-T30 -> 0.081183755 | W30: =+IFERROR(HLOOKUP($C30,'[3]6월'!$F$6:$CC$57,21,),)/1000 -> 23.263172 | X30: =+U30-W30 -> -0.49887744 | Y30: - 운반비 : 2개년 합의 인상 적용(6/1) → 인천, 김포 3,300원/회 ↑
B31: 부산크라샤 | C31: 부산크라샤 | G31: =+I31 -> 부산CR | I31: 부산CR | J31: =+IFERROR(HLOOKUP($B31,'[1]6월'!$D$6:$BN$259,2,),)/1000 -> 40.485669 | K31: =+IFERROR(HLOOKUP($C31,'[2]6월'!$F$6:$CP$99,2,),)/1000 -> 19.543 | L31: =+K31-J31 -> -20.942669 | M31: =+IFERROR(HLOOKUP($C31,'[3]6월'!$F$6:$CC$57,2,),)/1000 -> 32.89 | N31: =+K31-M31 -> -13.347 | O31: =+IFERROR(HLOOKUP($B31,'[1]6월'!$D$6:$BN$259,3,),)/1000 -> 679.89846 | P31: =+IFERROR(HLOOKUP($C31,'[2]6월'!$F$6:$CP$99,3,),)/1000 -> 386.4465 | Q31: =+P31-O31 -> -293.45196 | R31: =+IFERROR(HLOOKUP($C31,'[3]6월'!$F$6:$CC$57,3,),)/1000 -> 596.203 | S31: =+P31-R31 -> -209.7565 | T31: =+IFERROR(HLOOKUP($B31,'[1]6월'!$D$6:$BN$259,21,),)/1000 -> 47.690728 | U31: =+IFERROR(HLOOKUP($C31,'[2]6월'!$F$6:$CP$99,21,),)/1000 -> -63.702975 | V31: =+U31-T31 -> -111.3937 | W31: =+IFERROR(HLOOKUP($C31,'[3]6월'!$F$6:$CC$57,21,),)/1000 -> 6.6444047 | X31: =+U31-W31 -> -70.347379 | Y31: - 세금과공과 : 18.4억 선반영(건축물 0.9억, 토지세 6.3억, 종합부동산세 11.3억)
H32: 골재 계 | J32: =SUM(J29:J31) -> 112.56103 | K32: =SUM(K29:K31) -> 71.2 | L32: =+K32-J32 -> -41.361032 | M32: =SUM(M29:M31) -> 76.324 | N32: =+K32-M32 -> -5.124 | O32: =SUM(O29:O31) -> 2031.1208 | P32: =SUM(P29:P31) -> 1485.765 | Q32: =+P32-O32 -> -545.35584 | R32: =SUM(R29:R31) -> 1476.999 | S32: =+P32-R32 -> 8.766 | T32: =SUM(T29:T31) -> 66.08405 | U32: =SUM(U29:U31) -> -92.546442 | V32: =+U32-T32 -> -158.63049 | W32: =SUM(W29:W31) -> -24.058962 | X32: =+U32-W32 -> -68.487479
B33: 포항임대 | C33: 속초임대 | D33: 강릉임대 | E33: 레미콘임대 계 | G33: =+I33 -> 레미콘임대 | H33: 기타 | I33: 레미콘임대 | L33: =+K33-J33 -> 0 | N33: =+K33-M33 -> 0 | O33: =(IFERROR(HLOOKUP($B33,'[1]6월'!$D$6:$BN$259,3,),)++IFERROR(HLOOKUP($C33,'[1]6월'!$D$6:$BN$259,3,),)+IFERROR(HLOOKUP($D33,'[1]6월'!$D$6:$BN$259,3,),))/1000 -> 66.666667 | P33: =+IFERROR(HLOOKUP($E33,'[2]6월'!$F$6:$CP$99,3,),)/1000 -> 43.34 | Q33: =+P33-O33 -> -23.326667 | R33: =+IFERROR(HLOOKUP($E33,'[3]6월'!$F$6:$CC$57,3,),)/1000 -> 90.84 | S33: =+P33-R33 -> -47.5 | T33: =(IFERROR(HLOOKUP($B33,'[1]6월'!$D$6:$BN$259,21,),)++IFERROR(HLOOKUP($C33,'[1]6월'!$D$6:$BN$259,21,),)+IFERROR(HLOOKUP($D33,'[1]6월'!$D$6:$BN$259,21,),))/1000 -> -1.9239863 | U33: =+IFERROR(HLOOKUP($E33,'[2]6월'!$F$6:$CP$99,16,),)/1000 -> -32.2143 | V33: =+U33-T33 -> -30.290314 | W33: =+IFERROR(HLOOKUP($E33,'[3]6월'!$F$6:$CC$57,16,),)/1000 -> -23.482855 | X33: =+U33-W33 -> -8.731445
B34: 부동산임대 | C34: 주유소임대 | E34: 임대 계 | G34: =+I34 -> 임대 | I34: 임대 | L34: =+K34-J34 -> 0 | M34: 0 | N34: =+K34-M34 -> 0 | O34: =(+IFERROR(HLOOKUP($B34,'[1]6월'!$D$6:$BN$259,3,),)+IFERROR(HLOOKUP($C34,'[1]6월'!$D$6:$BN$259,3,),))/1000 -> 74.0915 | P34: =+IFERROR(HLOOKUP($E34,'[2]6월'!$F$6:$CP$99,3,),)/1000 -> 73.777012 | Q34: =+P34-O34 -> -0.314488 | R34: =+IFERROR(HLOOKUP($E34,'[3]6월'!$F$6:$CC$57,3,),)/1000 -> 73.635212 | S34: =+P34-R34 -> 0.1418 | T34: =(+IFERROR(HLOOKUP($B34,'[1]6월'!$D$6:$BN$259,21,),)+IFERROR(HLOOKUP($C34,'[1]6월'!$D$6:$BN$259,21,),))/1000 -> 76.556944 | U34: =+IFERROR(HLOOKUP($E34,'[2]6월'!$F$6:$CP$99,16,),)/1000 -> 73.218889 | V34: =+U34-T34 -> -3.338055 | W34: =+IFERROR(HLOOKUP($E34,'[3]6월'!$F$6:$CC$57,16,),)/1000 -> 76.100837 | X34: =+U34-W34 -> -2.881948
B35: 공 통 비 | G35: =+I35 -> 공통비 | I35: 공통비 | L35: =+K35-J35 -> 0 | N35: =+K35-M35 -> 0 | Q35: =+P35-O35 -> 0 | S35: =+P35-R35 -> 0 | T35: =-'[1]6월'!$Z$22/1000 -> -2607.3115 | U35: =+-'[2]6월'!$Z$22/1000 -> -2809.4658 | V35: =+U35-T35 -> -202.15433 | W35: =+-'[3]6월'!$Z$22/1000 -> -2487.3998 | X35: =+U35-W35 -> -322.06597
G36: =+I36 -> OPC 소급분 | I36: OPC 소급분 | N36: =+K36-M36 -> 0 | Q36: =+P36-O36 -> 0 | S36: =+P36-R36 -> 0 | U36: ='[2]6월'!$BD$26/1000 -> 0 | V36: =+U36-T36 -> 0 | W36: =-'[3]6월'!$BD$26/1000 -> 0 | X36: =+U36-W36 -> 0
G37: =+I37 -> 대손 | I37: 대손 | N37: =+K37-M37 -> 0 | Q37: =+P37-O37 -> 0 | S37: =+P37-R37 -> 0 | U37: ='[2]6월'!$BE$26/1000 -> -306.31368 | V37: =+U37-T37 -> -306.31368 | W37: ='[3]6월'!$BE$26/1000 -> 620.33483 | X37: =+U37-W37 -> -926.64852
G38: =+I38 -> 미운영 공장 | I38: 미운영 공장 | M38: =SUM(M54:M59) -> 0 | N38: =+K38-M38 -> 0 | Q38: =+P38-O38 -> 0 | R38: =+IFERROR(HLOOKUP($I$38,'[3]6월'!$F$6:$BJ$50,3,),)/1000 -> 0 | S38: =+P38-R38 -> 0 | T38: =SUM('[1]6월'!$AM$26:$AQ$26)/1000 -> -47.306249 | U38: =+'[2]6월'!$BF$26/1000 -> -47.528175 | V38: =+U38-T38 -> -0.221926 | W38: =+'[3]6월'!$BF$26/1000 -> -56.104233 | X38: =+U38-W38 -> 8.576058
B39: 기타 계 | G39: =+I39 -> 퇴직위로금 | I39: 퇴직위로금 | U39: =+'[2]6월'!$BG$26/1000 -> 0 | V39: =+U39-T39 -> 0 | X39: =+U39-W39 -> 0
G40: =+I40 -> 기타 | I40: 기타 | L40: =+K40-J40 -> 0 | N40: =+K40-M40 -> 0 | O40: =IFERROR(HLOOKUP($B39,'[1]6월'!$D$6:$BN$259,3,),)/1000 -> 1.77 | P40: =+('[2]6월'!$F$8-SUM('[2]6월'!$Z$8,'[2]6월'!$AH$8,'[2]6월'!$AN$8,'[2]6월'!$AO$8,'[2]6월'!$BA$8,'[2]6월'!$BD$8,'[2]6월'!$BE$8,'[2]6월'!$BF$8))/1000 -> 1.6874 | Q40: =+P40-O40 -> -0.0826 | R40: =+('[3]6월'!$F$8-SUM('[3]6월'!$Z$8,'[3]6월'!$AH$8,'[3]6월'!$AN$8,'[3]6월'!$AO$8,'[3]6월'!$BA$8,'[3]6월'!$BD$8,'[3]6월'!$BE$8,'[3]6월'!$BF$8))/1000 -> 1.704 | S40: =+P40-R40 -> -0.0166 | T40: =+('[1]6월'!$E$26-'[1]6월'!$Z$26-'[1]6월'!$AA$26-'[1]6월'!$AE$26-'[1]6월'!$AL$26-'[1]6월'!$AM$26-'[1]6월'!$AN$26-'[1]6월'!$AO$26-'[1]6월'!$AP$26-'[1]6월'!$AQ$26-'[1]6월'!$AS$26+'[1]6월'!$AS$26)/1000 -> -75.182554 | U40: =+('[2]6월'!$F$26-SUM('[2]6월'!$Z$26,'[2]6월'!$AH$26,'[2]6월'!$AN$26,'[2]6월'!$AO$26,'[2]6월'!$BA$26,'[2]6월'!$BD$26,'[2]6월'!$BE$26,'[2]6월'!$BF$26))/1000-U39 -> 43.45906 | V40: =+U40-T40 -> 118.64161 | W40: =+('[3]6월'!$F$26-SUM('[3]6월'!$Z$26,'[3]6월'!$AH$26,'[3]6월'!$AN$26,'[3]6월'!$AO$26,'[3]6월'!$BA$26,'[3]6월'!$BD$26,'[3]6월'!$BE$26,'[3]6월'!$BF$26))/1000 -> -90.356696 | X40: =+U40-W40 -> 133.81576
H41: 기타 계 | J41: =SUM(J33:J40) -> 0 | K41: =SUM(K33:K40) -> 0 | L41: =+K41-J41 -> 0 | M41: =SUM(M33:M40) -> 0 | N41: =+K41-M41 -> 0 | O41: =SUM(O33:O40) -> 142.52817 | P41: =SUM(P33:P40) -> 118.80441 | Q41: =+P41-O41 -> -23.723755 | R41: =SUM(R33:R40) -> 166.17921 | S41: =+P41-R41 -> -47.3748 | T41: =SUM(T33:T40) -> -2655.1673 | U41: =SUM(U33:U40) -> -3078.844 | V41: =+U41-T41 -> -423.67669 | W41: =SUM(W33:W40) -> -1960.908 | X41: =+U41-W41 -> -1117.9361
U42: 19 | V42: 12.4
...

Sheet 사업장별(누계)
H3: □ 사업장별 손익실적(2025-06누계)
AG4: [단위 : 천㎥, 톤, 백만원]
H5: 구분 | J5: 물량 | O5: 매출 | T5: 영업이익(공통비 배부전) | Y5: 판매단가 | AB5: 변동비 | AE5: 공헌이익
A6: 2024년 6월누계 마감 손익 | J6: 계획 | K6: 실적 | L6: 차이 | M6: 전년 | N6: 차이 | O6: 계획 | P6: 실적 | Q6: 차이 | R6: 전년 | S6: 차이 | T6: 계획 | U6: 실적 | V6: 차이 | W6: 전년 | X6: 차이 | Y6: 계획 | Z6: 실적 | AA6: 전년 | AB6: 계획 | AC6: 실적 | AD6: 전년 | AE6: 계획 | AF6: 실적 | AG6: 전년
B7: 안양 | G7: =+I7 -> 안양 | H7: 레미콘 | I7: 안양 | J7: =+IFERROR(HLOOKUP($B7,'[1]6월누계'!$D$6:$BN$259,2,),)/1000 -> 224 | K7: =+IFERROR(HLOOKUP($B7,'[2]6월누계'!$F$6:$CP$99,2,),)/1000 -> 206.31 | L7: =+K7-J7 -> -17.69 | M7: =+IFERROR(HLOOKUP($B7,'[3]6월누계'!$F$6:$CC$57,2,),)/1000 -> 246.678 | N7: =+K7-M7 -> -40.368 | O7: =+IFERROR(HLOOKUP($B7,'[1]6월누계'!$D$6:$BN$259,3,),)/1000 -> 21978.082 | P7: =+IFERROR(HLOOKUP($B7,'[2]6월누계'!$F$6:$CP$99,3,),)/1000 -> 19791.05 | Q7: =+P7-O7 -> -2187.0323 | R7: =+IFERROR(HLOOKUP($B7,'[3]6월누계'!$F$6:$CC$57,3,),)/1000 -> 24515.111 | S7: =+P7-R7 -> -4724.0613 | T7: =+IFERROR(HLOOKUP($B7,'[1]6월누계'!$D$6:$BN$259,16,),)/1000 -> 1715.1776 | U7: =+IFERROR(HLOOKUP($B7,'[2]6월누계'!$F$6:$CP$99,16,),)/1000 -> 1331.2237 | V7: =+U7-T7 -> -383.95386 | W7: =+IFERROR(HLOOKUP($B7,'[3]6월누계'!$F$6:$CC$57,16,),)/1000 -> 2578.081 | X7: =+U7-W7 -> -1246.8573 | Y7: =+[12]안양!$Q$85 -> 98116.439 | Z7: =+[12]안양!$R$85 -> 95915.634 | AA7: =+[13]안양!$Q$85 -> 99374.66 | AB7: =+[12]안양!$Q$89 -> 81994.735 | AC7: =+[12]안양!$R$89 -> 80146.083 | AD7: =+[13]안양!$Q$89 -> 81333.041 | AE7: =+Y7-AB7 -> 16121.703 | AF7: =+Z7-AC7 -> 15769.551 | AG7: =+AA7-AD7 -> 18041.619
B8: 인천 | G8: =+I8 -> 인천 | H8: 직영 | I8: 인천 | J8: =+IFERROR(HLOOKUP($B8,'[1]6월누계'!$D$6:$BN$259,2,),)/1000 -> 160 | K8: =+IFERROR(HLOOKUP($B8,'[2]6월누계'!$F$6:$CP$99,2,),)/1000 -> 167.21 | L8: =+K8-J8 -> 7.21 | M8: =+IFERROR(HLOOKUP($B8,'[3]6월누계'!$F$6:$CC$57,2,),)/1000 -> 172.876 | N8: =+K8-M8 -> -5.666 | O8: =+IFERROR(HLOOKUP($B8,'[1]6월누계'!$D$6:$BN$259,3,),)/1000 -> 15668.025 | P8: =+IFERROR(HLOOKUP($B8,'[2]6월누계'!$F$6:$CP$99,3,),)/1000 -> 16360.022 | Q8: =+P8-O8 -> 691.99706 | R8: =+IFERROR(HLOOKUP($B8,'[3]6월누계'!$F$6:$CC$57,3,),)/1000 -> 17322.638 | S8: =+P8-R8 -> -962.61591 | T8: =+IFERROR(HLOOKUP($B8,'[1]6월누계'!$D$6:$BN$259,16,),)/1000 -> 505.30049 | U8: =+IFERROR(HLOOKUP($B8,'[2]6월누계'!$F$6:$CP$99,16,),)/1000 -> 363.18738 | V8: =+U8-T8 -> -142.11312 | W8: =+IFERROR(HLOOKUP($B8,'[3]6월누계'!$F$6:$CC$57,16,),)/1000 -> 1395.4453 | X8: =+U8-W8 -> -1032.2579 | Y8: =+[12]인천!$Q$85 -> 97925.153 | Z8: =+[12]인천!$R$85 -> 97908.548 | AA8: =+[13]인천!$Q$85 -> 100202.67 | AB8: =+[12]인천!$Q$89 -> 83093.761 | AC8: =+[12]인천!$R$89 -> 84330.164 | AD8: =+[13]인천!$Q$89 -> 82122.86 | AE8: =+Y8-AB8 -> 14831.393 | AF8: =+Z8-AC8 -> 13578.385 | AG8: =+AA8-AD8 -> 18079.815
B9: 파주 | G9: =+I9 -> 파주 | I9: 파주 | J9: =+IFERROR(HLOOKUP($B9,'[1]6월누계'!$D$6:$BN$259,2,),)/1000 -> 117 | K9: =+IFERROR(HLOOKUP($B9,'[2]6월누계'!$F$6:$CP$99,2,),)/1000 -> 71.445 | L9: =+K9-J9 -> -45.555 | M9: =+IFERROR(HLOOKUP($B9,'[3]6월누계'!$F$6:$CC$57,2,),)/1000 -> 154.5102 | N9: =+K9-M9 -> -83.0652 | O9: =+IFERROR(HLOOKUP($B9,'[1]6월누계'!$D$6:$BN$259,3,),)/1000 -> 11265.953 | P9: =+IFERROR(HLOOKUP($B9,'[2]6월누계'!$F$6:$CP$99,3,),)/1000 -> 6609.1095 | Q9: =+P9-O9 -> -4656.8433 | R9: =+IFERROR(HLOOKUP($B9,'[3]6월누계'!$F$6:$CC$57,3,),)/1000 -> 15237.953 | S9: =+P9-R9 -> -8628.844 | T9: =+IFERROR(HLOOKUP($B9,'[1]6월누계'!$D$6:$BN$259,16,),)/1000 -> 490.84019 | U9: =+IFERROR(HLOOKUP($B9,'[2]6월누계'!$F$6:$CP$99,16,),)/1000 -> -289.15135 | V9: =+U9-T9 -> -779.99154 | W9: =+IFERROR(HLOOKUP($B9,'[3]6월누계'!$F$6:$CC$57,16,),)/1000 -> 1231.0106 | X9: =+U9-W9 -> -1520.162 | Y9: =+[12]파주!$Q$85 -> 96290.195 | Z9: =+[12]파주!$R$85 -> 92528.644 | AA9: =+[13]파주!$Q$85 -> 98647.485 | AB9: =+[12]파주!$Q$89 -> 79765.343 | AC9: =+[12]파주!$R$89 -> 78198.297 | AD9: =+[13]파주!$Q$89 -> 81669.229 | AE9: =+Y9-AB9 -> 16524.852 | AF9: =+Z9-AC9 -> 14330.347 | AG9: =+AA9-AD9 -> 16978.256
B10: 김포 | G10: =+I10 -> 김포 | I10: 김포 | J10: =+IFERROR(HLOOKUP($B10,'[1]6월누계'!$D$6:$BN$259,2,),)/1000 -> 80 | K10: =+IFERROR(HLOOKUP($B10,'[2]6월누계'!$F$6:$CP$99,2,),)/1000 -> 60.317 | L10: =+K10-J10 -> -19.683 | M10: =+IFERROR(HLOOKUP($B10,'[3]6월누계'!$F$6:$CC$57,2,),)/1000 -> 73.7185 | N10: =+K10-M10 -> -13.4015 | O10: =+IFERROR(HLOOKUP($B10,'[1]6월누계'!$D$6:$BN$259,3,),)/1000 -> 7602.8149 | P10: =+IFERROR(HLOOKUP($B10,'[2]6월누계'!$F$6:$CP$99,3,),)/1000 -> 5751.4316 | Q10: =+P10-O10 -> -1851.3833 | R10: =+IFERROR(HLOOKUP($B10,'[3]6월누계'!$F$6:$CC$57,3,),)/1000 -> 7287.6592 | S10: =+P10-R10 -> -1536.2276 | T10: =+IFERROR(HLOOKUP($B10,'[1]6월누계'!$D$6:$BN$259,16,),)/1000 -> 437.19888 | U10: =+IFERROR(HLOOKUP($B10,'[2]6월누계'!$F$6:$CP$99,16,),)/1000 -> 24.870536 | V10: =+U10-T10 -> -412.32835 | W10: =+IFERROR(HLOOKUP($B10,'[3]6월누계'!$F$6:$CC$57,16,),)/1000 -> 731.09263 | X10: =+U10-W10 -> -706.2221 | Y10: =+[12]김포!$Q$85 -> 95035.186 | Z10: =+[12]김포!$R$85 -> 95412.079 | AA10: =+[13]김포!$Q$85 -> 98880.551 | AB10: =+[12]김포!$Q$89 -> 76355.259 | AC10: =+[12]김포!$R$89 -> 77741.284 | AD10: =+[13]김포!$Q$89 -> 75884.503 | AE10: =+Y10-AB10 -> 18679.927 | AF10: =+Z10-AC10 -> 17670.795 | AG10: =+AA10-AD10 -> 22996.047
B11: 부산 | G11: =+I11 -> 부산 | I11: 부산 | J11: =+IFERROR(HLOOKUP($B11,'[1]6월누계'!$D$6:$BN$259,2,),)/1000 -> 119 | K11: =+IFERROR(HLOOKUP($B11,'[2]6월누계'!$F$6:$CP$99,2,),)/1000 -> 118.044 | L11: =+K11-J11 -> -0.956 | M11: =+IFERROR(HLOOKUP($B11,'[3]6월누계'!$F$6:$CC$57,2,),)/1000 -> 131.8815 | N11: =+K11-M11 -> -13.8375 | O11: =+IFERROR(HLOOKUP($B11,'[1]6월누계'!$D$6:$BN$259,3,),)/1000 -> 12816.29 | P11: =+IFERROR(HLOOKUP($B11,'[2]6월누계'!$F$6:$CP$99,3,),)/1000 -> 12692.231 | Q11: =+P11-O11 -> -124.05974 | R11: =+IFERROR(HLOOKUP($B11,'[3]6월누계'!$F$6:$CC$57,3,),)/1000 -> 14056.407 | S11: =+P11-R11 -> -1364.1761 | T11: =+IFERROR(HLOOKUP($B11,'[1]6월누계'!$D$6:$BN$259,16,),)/1000 -> 1067.5707 | U11: =+IFERROR(HLOOKUP($B11,'[2]6월누계'!$F$6:$CP$99,16,),)/1000 -> 1250.1005 | V11: =+U11-T11 -> 182.52984 | W11: =+IFERROR(HLOOKUP($B11,'[3]6월누계'!$F$6:$CC$57,16,),)/1000 -> 1520.4732 | X11: =+U11-W11 -> -270.37273 | Y11: =+[12]부산!$Q$85 -> 107699.92 | Z11: =+[12]부산!$R$85 -> 107521.18 | AA11: =+[13]부산!$Q$85 -> 106583.61 | AB11: =+[12]부산!$Q$89 -> 84767.207 | AC11: =+[12]부산!$R$89 -> 84010.362 | AD11: =+[13]부산!$Q$89 -> 83433.784 | AE11: =+Y11-AB11 -> 22932.713 | AF11: =+Z11-AC11 -> 23510.822 | AG11: =+AA11-AD11 -> 23149.829
B12: 서부산 | G12: =+I12 -> 서부산 | I12: 서부산 | J12: =+IFERROR(HLOOKUP($B12,'[1]6월누계'!$D$6:$BN$259,2,),)/1000 -> 117 | K12: =+IFERROR(HLOOKUP($B12,'[2]6월누계'!$F$6:$CP$99,2,),)/1000 -> 98.061 | L12: =+K12-J12 -> -18.939 | M12: =+IFERROR(HLOOKUP($B12,'[3]6월누계'!$F$6:$CC$57,2,),)/1000 -> 136.592 | N12: =+K12-M12 -> -38.531 | O12: =+IFERROR(HLOOKUP($B12,'[1]6월누계'!$D$6:$BN$259,3,),)/1000 -> 11618.112 | P12: =+IFERROR(HLOOKUP($B12,'[2]6월누계'!$F$6:$CP$99,3,),)/1000 -> 9516.7303 | Q12: =+P12-O12 -> -2101.3817 | R12: =+IFERROR(HLOOKUP($B12,'[3]6월누계'!$F$6:$CC$57,3,),)/1000 -> 13806.266 | S12: =+P12-R12 -> -4289.5355 | T12: =+IFERROR(HLOOKUP($B12,'[1]6월누계'!$D$6:$BN$259,16,),)/1000 -> 1011.3887 | U12: =+IFERROR(HLOOKUP($B12,'[2]6월누계'!$F$6:$CP$99,16,),)/1000 -> 545.51652 | V12: =+U12-T12 -> -465.87217 | W12: =+IFERROR(HLOOKUP($B12,'[3]6월누계'!$F$6:$CC$57,16,),)/1000 -> 1660.9628 | X12: =+U12-W12 -> -1115.4463 | Y12: =+[12]서부산!$Q$85 -> 99300.103 | Z12: =+[12]서부산!$R$85 -> 97110.84 | AA12: =+[13]서부산!$Q$85 -> 101076.68 | AB12: =+[12]서부산!$Q$89 -> 78532.439 | AC12: =+[12]서부산!$R$89 -> 77298.57 | AD12: =+[13]서부산!$Q$89 -> 79083.398 | AE12: =+Y12-AB12 -> 20767.664 | AF12: =+Z12-AC12 -> 19812.271 | AG12: =+AA12-AD12 -> 21993.282
B13: 김해 | G13: =+I13 -> 김해 | I13: 김해 | J13: =+IFERROR(HLOOKUP($B13,'[1]6월누계'!$D$6:$BN$259,2,),)/1000 -> 82 | K13: =+IFERROR(HLOOKUP($B13,'[2]6월누계'!$F$6:$CP$99,2,),)/1000 -> 54.569 | L13: =+K13-J13 -> -27.431 | M13: =+IFERROR(HLOOKUP($B13,'[3]6월누계'!$F$6:$CC$57,2,),)/1000 -> 79.309 | N13: =+K13-M13 -> -24.74 | O13: =+IFERROR(HLOOKUP($B13,'[1]6월누계'!$D$6:$BN$259,3,),)/1000 -> 7896.5957 | P13: =+IFERROR(HLOOKUP($B13,'[2]6월누계'!$F$6:$CP$99,3,),)/1000 -> 4860.4094 | Q13: =+P13-O13 -> -3036.1863 | R13: =+IFERROR(HLOOKUP($B13,'[3]6월누계'!$F$6:$CC$57,3,),)/1000 -> 7717.5713 | S13: =+P13-R13 -> -2857.1619 | T13: =+IFERROR(HLOOKUP($B13,'[1]6월누계'!$D$6:$BN$259,16,),)/1000 -> 677.03534 | U13: =+IFERROR(HLOOKUP($B13,'[2]6월누계'!$F$6:$CP$99,16,),)/1000 -> -172.84912 | V13: =+U13-T13 -> -849.88446 | W13: =+IFERROR(HLOOKUP($B13,'[3]6월누계'!$F$6:$CC$57,16,),)/1000 -> 543.83888 | X13: =+U13-W13 -> -716.68801 | Y13: =+[12]김해!$Q$85 -> 96299.948 | Z13: =+[12]김해!$R$85 -> 89066.239 | AA13: =+[13]김해!$Q$85 -> 97399.068 | AB13: =+[12]김해!$Q$89 -> 76540.997 | AC13: =+[12]김해!$R$89 -> 76004.672 | AD13: =+[13]김해!$Q$89 -> 79402.427 | AE13: =+Y13-AB13 -> 19758.951 | AF13: =+Z13-AC13 -> 13061.567 | AG13: =+AA13-AD13 -> 17996.641
B14: 정관 | G14: =+I14 -> 정관 | I14: 정관 | J14: =+IFERROR(HLOOKUP($B14,'[1]6월누계'!$D$6:$BN$259,2,),)/1000 -> 114 | K14: =+IFERROR(HLOOKUP($B14,'[2]6월누계'!$F$6:$CP$99,2,),)/1000 -> 126.5825 | L14: =+K14-J14 -> 12.5825 | M14: =+IFERROR(HLOOKUP($B14,'[3]6월누계'!$F$6:$CC$57,2,),)/1000 -> 122.3435 | N14: =+K14-M14 -> 4.239 | O14: =+IFERROR(HLOOKUP($B14,'[1]6월누계'!$D$6:$BN$259,3,),)/1000 -> 11627.967 | P14: =+IFERROR(HLOOKUP($B14,'[2]6월누계'!$F$6:$CP$99,3,),)/1000 -> 12731.543 | Q14: =+P14-O14 -> 1103.5756 | R14: =+IFERROR(HLOOKUP($B14,'[3]6월누계'!$F$6:$CC$57,3,),)/1000 -> 12481.763 | S14: =+P14-R14 -> 249.77952 | T14: =+IFERROR(HLOOKUP($B14,'[1]6월누계'!$D$6:$BN$259,16,),)/1000 -> 936.78088 | U14: =+IFERROR(HLOOKUP($B14,'[2]6월누계'!$F$6:$CP$99,16,),)/1000 -> 1103.9443 | V14: =+U14-T14 -> 167.16341 | W14: =+IFERROR(HLOOKUP($B14,'[3]6월누계'!$F$6:$CC$57,16,),)/1000 -> 1241.081 | X14: =+U14-W14 -> -137.1367 | Y14: =+[12]정관!$Q$85 -> 101999.71 | Z14: =+[12]정관!$R$85 -> 100608.18 | AA14: =+[13]정관!$Q$85 -> 102022.28 | AB14: =+[12]정관!$Q$89 -> 82098.472 | AC14: =+[12]정관!$R$89 -> 82460.201 | AD14: =+[13]정관!$Q$89 -> 82011.464 | AE14: =+Y14-AB14 -> 19901.24 | AF14: =+Z14-AC14 -> 18147.976 | AG14: =+AA14-AD14 -> 20010.819
