Workbook

Sheet 파워BI용
B2: 구분 | D2: 계획 | E2: 실적 | F2: 차이 | G2: 전년 | H2: 차이 | J2: 캡쳐도구 사용 → PNG 저장 → 파워BI 삽입 → 이미지
B3: 판매량 | C3: 레미콘 | D3: =+'사업장별(당월)_건자재제외'!$J$27 -> 271.5 | E3: =+'사업장별(당월)_건자재제외'!$K$27 -> 200.35732 | F3: =+E3/D3 -> 0.73796435 | G3: =+'사업장별(당월)_건자재제외'!$M$27 -> 257.523 | H3: =+E3/G3 -> 0.77801719
C4: 골재 | D4: =+'사업장별(당월)_건자재제외'!$J$31 -> 95.130878 | E4: =+'사업장별(당월)_건자재제외'!$K$31 -> 67.087 | F4: =+E4/D4 -> 0.70520741 | G4: =+'사업장별(당월)_건자재제외'!$M$31 -> 49.603 | H4: =+E4/G4 -> 1.3524787
B5: 매출액 | C5: 레미콘 | D5: =+'사업장별(당월)_건자재제외'!$O$27 -> 27523.735 | E5: =+'사업장별(당월)_건자재제외'!$P$27 -> 19450.728 | F5: =+E5-D5 -> -8073.0075 | G5: =+'사업장별(당월)_건자재제외'!$R$27 -> 25796.841 | H5: =+E5-G5 -> -6346.1137
C6: 골재 | D6: =+'사업장별(당월)_건자재제외'!$O$31 -> 1712.5157 | E6: =+'사업장별(당월)_건자재제외'!$P$31 -> 1324.678 | F6: =+E6-D6 -> -387.8377 | G6: =+'사업장별(당월)'!$R$32 -> 1021.5105 | H6: =+E6-G6 -> 303.1675
C7: 기타 | D7: =+D8-D5-D6 -> 143.72817 | E7: =+E8-E5-E6 -> 119.31745 | F7: =+E7-D7 -> -24.41072 | G7: =+G8-G5-G6 -> 166.69163 | H7: =+E7-G7 -> -47.37418
C8: 계 | D8: =+'사업장별(당월)_건자재제외'!$O$42 -> 29379.979 | E8: =+'사업장별(당월)_건자재제외'!$P$42 -> 20894.723 | F8: =+E8-D8 -> -8485.2559 | G8: =+'사업장별(당월)_건자재제외'!$R$42 -> 26985.044 | H8: =+E8-G8 -> -6090.3203
B9: 영업이익 | C9: 레미콘 | D9: =+('사업장별(당월)_건자재제외'!$T$27+'사업장별(당월)_건자재제외'!$T$34) -> 1729.8402 | E9: =+'사업장별(당월)_건자재제외'!$U$27+'사업장별(당월)_건자재제외'!$U$34 -> -734.8949 | F9: =+E9-D9 -> -2464.7351 | G9: =+'사업장별(당월)_건자재제외'!$W$27+'사업장별(당월)_건자재제외'!$W$34 -> 1619.8495 | H9: =+E9-G9 -> -2354.7444
C10: (%) | D10: =+D9/D5 -> 0.062849034 | E10: =+E9/E5 -> -0.037782386 | F10: =+E10-D10 -> -0.10063142 | G10: =+G9/G5 -> 0.06279255 | H10: =+E10-G10 -> -0.10057494
C11: 골재 | D11: =+'사업장별(당월)_건자재제외'!$T$31 -> 81.21924 | E11: =+'사업장별(당월)_건자재제외'!$U$31 -> -89.003885 | F11: =+E11-D11 -> -170.22312 | G11: =+'사업장별(당월)_건자재제외'!$W$31 -> -151.01849 | H11: =+E11-G11 -> 62.014603
C12: 기타 | D12: =+D13-D9-D11 -> -4.2619833 | E12: =+E13-E9-E11 -> 42.959931 | F12: =+E12-D12 -> 47.221914 | G12: =+G13-G9-G11 -> 328.00952 | H12: =+E12-G12 -> -285.04959
C13: 계 | D13: =+'사업장별(당월)_건자재제외'!$T$42 -> 1806.7974 | E13: =+'사업장별(당월)_건자재제외'!$U$42 -> -780.93885 | F13: =+E13-D13 -> -2587.7363 | G13: =+'사업장별(당월)_건자재제외'!$W$42 -> 1796.8405 | H13: =+E13-G13 -> -2577.7793
D14: =+D13/D8 -> 0.061497573 | E14: =+E13/E8 -> -0.037374932 | F14: =+E14-D14 -> -0.098872505 | G14: =+G13/G8 -> 0.066586533 | H14: =+E14-G14 -> -0.10396146

Sheet 표지
A6: 2025년 8월 마감 손익
A24: 건재사업본부

Sheet 손익총괄
C3: □ 건재사업본부 손익실적(2025-08)
X4: [단위 : 천㎥, 톤, 원/㎥, 원/톤, 백만원]
C5: 구분 | E5: 8월 | J5: 8월 누계 | P5: 8월 주요지표
E6: 계획 | F6: 실적 | G6: 계획대비 | H6: 전년 | I6: 전년대비 | J6: 계획 | K6: 실적 | L6: 계획대비 | M6: 전년 | N6: 전년대비
C7: 물량 | D7: 레미콘 | E7: =+'[1]8월'!$Z$7/1000 -> 271.5 | F7: =+'[2]8월'!$Z$7/1000 -> 200.35732 | G7: =+F7-E7 -> -71.14268 | H7: =+'[3]8월'!$Z$7/1000 -> 257.523 | I7: =+F7-H7 -> -57.16568 | J7: =+'[1]8월누계'!$Z$7/1000 -> 2138.5 | K7: =+'[2]8월누계'!$Z$7/1000 -> 1853.0678 | L7: =+K7-J7 -> -285.43218 | M7: =+'[3]8월누계'!$Z$7/1000 -> 2292.4292 | N7: =+K7-M7 -> -439.36138 | Q7: □ 레미콘
D8: 철강재 | E8: =+'[1]8월'!$AA$7 -> 12600 | F8: =+'[2]8월'!$AO$7 -> 6814.749 | G8: =+F8-E8 -> -5785.251 | H8: =+'[3]8월'!$AO$7 -> 9545.758 | I8: =+F8-H8 -> -2731.009 | J8: =+'[1]8월누계'!$AA$7 -> 88300 | K8: =+'[2]8월누계'!$AO$7 -> 76949.95 | L8: =+K8-J8 -> -11350.05 | M8: =+'[3]8월누계'!$AO$7 -> 70612.716 | N8: =+K8-M8 -> 6337.234 | Q8: 구분 | S8: 계획 | T8: 실적 | U8: 계획대비 | V8: 전년 | W8: 전년대비
D9: 골재 | E9: =+'[1]8월'!$AE$7/1000 -> 95.130878 | F9: =+'[2]8월'!$AN$7/1000 -> 67.087 | G9: =+F9-E9 -> -28.043878 | H9: =+'[3]8월'!$AN$7/1000 -> 49.603 | I9: =+F9-H9 -> 17.484 | J9: =+'[1]8월누계'!$AE$7/1000 -> 758.25042 | K9: =+'[2]8월누계'!$AN$7/1000 -> 509.17 | L9: =+K9-J9 -> -249.08042 | M9: =+'[3]8월누계'!$AN$7/1000 -> 607.264 | N9: =+K9-M9 -> -98.094 | Q9: 물량 | R9: 수도권 | S9: =+[4]수도권!$T$5/1000 -> 102 | T9: =+[4]수도권!$U$5/1000 -> 69.48432 | U9: =+T9-S9 -> -32.51568 | V9: =+[5]수도권!$T$5/1000 -> 82.492 | W9: =+T9-V9 -> -13.00768
C10: 매출 | D10: 레미콘 | E10: =+'[1]8월'!$Z$8/1000 -> 27523.735 | F10: =+'[2]8월'!$Z$8/1000 -> 19450.728 | G10: =+F10-E10 -> -8073.0075 | H10: =+'[3]8월'!$Z$8/1000 -> 25796.841 | I10: =+F10-H10 -> -6346.1137 | J10: =+'[1]8월누계'!$Z$8/1000 -> 215180.1 | K10: =+'[2]8월누계'!$Z$8/1000 -> 182330.54 | L10: =+K10-J10 -> -32849.553 | M10: =+'[3]8월누계'!$Z$8/1000 -> 232174.94 | N10: =+K10-M10 -> -49844.393 | R10: 영남권 | S10: =+[4]영남권!$T$5/1000 -> 114.5 | T10: =+[4]영남권!$U$5/1000 -> 94.706 | U10: =+T10-S10 -> -19.794 | V10: =+[5]영남권!$T$5/1000 -> 125.6115 | W10: =+T10-V10 -> -30.9055
D11: 건자재 | E11: =+'[1]8월'!$AA$8/1000 -> 13712.919 | F11: =+'[2]8월'!$AO$8/1000 -> 6411.0741 | G11: =+F11-E11 -> -7301.8448 | H11: =+'[3]8월'!$AO$8/1000 -> 9493.1785 | I11: =+F11-H11 -> -3082.1043 | J11: =+'[1]8월누계'!$AA$8/1000 -> 96491.99 | K11: =+'[2]8월누계'!$AO$8/1000 -> 69287.382 | L11: =+K11-J11 -> -27204.608 | M11: =+'[3]8월누계'!$AO$8/1000 -> 70211.565 | N11: =+K11-M11 -> -924.18296 | R11: 중부권 | S11: =+[4]중부권!$T$5/1000 -> 55 | T11: =+[4]중부권!$U$5/1000 -> 36.167 | U11: =+T11-S11 -> -18.833 | V11: =+[5]중부권!$T$5/1000 -> 49.4195 | W11: =+T11-V11 -> -13.2525
D12: 골재 | E12: =+'[1]8월'!$AE$8/1000 -> 1712.5157 | F12: =+'[2]8월'!$AN$8/1000 -> 1324.678 | G12: =+F12-E12 -> -387.8377 | H12: =+'[3]8월'!$AN$8/1000 -> 1021.5105 | I12: =+F12-H12 -> 303.1675 | J12: =+'[1]8월누계'!$AE$8/1000 -> 14023.065 | K12: =+'[2]8월누계'!$AN$8/1000 -> 10642.524 | L12: =+K12-J12 -> -3380.5406 | M12: =+'[3]8월누계'!$AN$8/1000 -> 12244.04 | N12: =+K12-M12 -> -1601.5156 | Q12: 계 | S12: =SUM(S9:S11) -> 271.5 | T12: =SUM(T9:T11) -> 200.35732 | U12: =+T12-S12 -> -71.14268 | V12: =SUM(V9:V11) -> 257.523 | W12: =+T12-V12 -> -57.16568
D13: 기타 | E13: =+'[1]8월'!$E$8/1000-E10-E11-E12 -> 143.72817 | F13: =+'[2]8월'!$F$8/1000-F10-F11-F12 -> 119.31745 | G13: =+F13-E13 -> -24.41072 | H13: =+'[3]8월'!$F$8/1000-H10-H11-H12 -> 166.69163 | I13: =+F13-H13 -> -47.37418 | J13: =+'[1]8월누계'!$E$8/1000-J10-J11-J12 -> 1213.9453 | K13: =+'[2]8월누계'!$F$8/1000-K10-K11-K12 -> 1067.0405 | L13: =+K13-J13 -> -146.90484 | M13: =+'[3]8월누계'!$F$8/1000-M10-M11-M12 -> 1323.901 | N13: =+K13-M13 -> -256.86047 | Q13: 판매단가 | R13: 수도권 | S13: =+[4]수도권!$T$61 -> 99005.917 | T13: =+[4]수도권!$U$61 -> 95390.139 | U13: =+T13-S13 -> -3615.7781 | V13: =+[5]수도권!$Q$85 -> 98331.463 | W13: =+T13-V13 -> -2941.3243
C14: 계 | E14: =SUM(E10:E13) -> 43092.898 | F14: =SUM(F10:F13) -> 27305.797 | G14: =+F14-E14 -> -15787.101 | H14: =SUM(H10:H13) -> 36478.222 | I14: =+F14-H14 -> -9172.4247 | J14: =SUM(J10:J13) -> 326909.1 | K14: =SUM(K10:K13) -> 263327.49 | L14: =+K14-J14 -> -63581.606 | M14: =SUM(M10:M13) -> 315954.44 | N14: =+K14-M14 -> -52626.952 | R14: 영남권 | S14: =+[4]영남권!$T$61 -> 100430.8 | T14: =+[4]영남권!$U$61 -> 96920.994 | U14: =+T14-S14 -> -3509.8042 | V14: =+[5]영남권!$Q$85 -> 99644.239 | W14: =+T14-V14 -> -2723.245
C15: 매출원가 | D15: 레미콘 | E15: =+('[1]8월'!$Z$10+'[1]8월'!$Z$19)/1000 -> 23838.33 | F15: =+('[2]8월'!$Z$10+'[2]8월'!$Z$19)/1000 -> 18207.467 | G15: =+F15-E15 -> -5630.8633 | H15: =+('[3]8월'!$Z$10+'[3]8월'!$Z$19)/1000 -> 22394.811 | I15: =+F15-H15 -> -4187.3443 | J15: =+('[1]8월누계'!$Z$10+'[1]8월누계'!$Z$19)/1000 -> 190831.67 | K15: =+('[2]8월누계'!$Z$10+'[2]8월누계'!$Z$19)/1000 -> 167304.04 | L15: =+K15-J15 -> -23527.631 | M15: =+('[3]8월누계'!$Z$10+'[3]8월누계'!$Z$19)/1000 -> 200504.99 | N15: =+K15-M15 -> -33200.949 | R15: 중부권 | S15: =+[4]중부권!$T$61 -> 107741.92 | T15: =+[4]중부권!$U$61 -> 101046.16 | U15: =+T15-S15 -> -6695.7574 | V15: =+[5]중부권!$Q$85 -> 104659.87 | W15: =+T15-V15 -> -3613.7159
D16: 건자재 | E16: =+('[1]8월'!$AA$10+'[1]8월'!$AA$19)/1000 -> 13342.736 | F16: =+('[2]8월'!$AO$10+'[2]8월'!$AO$19)/1000 -> 6263.7845 | G16: =+F16-E16 -> -7078.9518 | H16: =+('[3]8월'!$AO$10+'[3]8월'!$AO$19)/1000 -> 9292.7198 | I16: =+F16-H16 -> -3028.9353 | J16: =+('[1]8월누계'!$AA$10+'[1]8월누계'!$AA$19)/1000 -> 93886.646 | K16: =+('[2]8월누계'!$AO$10+'[2]8월누계'!$AO$19)/1000 -> 68164.601 | L16: =+K16-J16 -> -25722.045 | M16: =+('[3]8월누계'!$AO$10+'[3]8월누계'!$AO$19)/1000 -> 68656.789 | N16: =+K16-M16 -> -492.18798 | Q16: 계 | S16: =+[4]합계!$T$61 -> 101376.56 | T16: =+[4]합계!$U$61 -> 97142.344 | U16: =+T16-S16 -> -4234.2132 | V16: =+[5]합계!$Q$85 -> 100188.2 | W16: =+T16-V16 -> -3045.8538
D17: 골재 | E17: =+('[1]8월'!$AE$10+'[1]8월'!$AE$19)/1000 -> 1584.5127 | F17: =+('[2]8월'!$AN$10+'[2]8월'!$AN$19)/1000 -> 1367.0544 | G17: =+F17-E17 -> -217.45833 | H17: =+('[3]8월'!$AN$10+'[3]8월'!$AN$19)/1000 -> 1098.659 | I17: =+F17-H17 -> 268.3954 | J17: =+('[1]8월누계'!$AE$10+'[1]8월누계'!$AE$19)/1000 -> 12342.961 | K17: =+('[2]8월누계'!$AN$10+'[2]8월누계'!$AN$19)/1000 -> 10979.052 | L17: =+K17-J17 -> -1363.9084 | M17: =+('[3]8월누계'!$AN$10+'[3]8월누계'!$AN$19)/1000 -> 11343.439 | N17: =+K17-M17 -> -364.3866 | Q17: 공헌이익 | R17: 수도권 | S17: =+[4]수도권!$Q$90 -> 18614.67 | T17: =+[4]수도권!$R$90 -> 15012.539 | U17: =+T17-S17 -> -3602.1304 | V17: =+[5]수도권!$Q$90 -> 17913.385 | W17: =+T17-V17 -> -2900.8456
D18: 기타 | E18: =+('[1]8월'!$E$10+'[1]8월'!$E$19)/1000-E15-E16-E17 -> 68.375599 | F18: =+('[2]8월'!$F$10+'[2]8월'!$F$19)/1000-F15-F16-F17 -> 19.32187 | G18: =+F18-E18 -> -49.053729 | H18: =+('[3]8월'!$F$10+'[3]8월'!$F$19)/1000-H15-H16-H17 -> -221.52369 | I18: =+F18-H18 -> 240.84556 | J18: =+('[1]8월누계'!$E$10+'[1]8월누계'!$E$19)/1000-J15-J16-J17 -> 488.65982 | K18: =+('[2]8월누계'!$F$10+'[2]8월누계'!$F$19)/1000-K15-K16-K17 -> 445.20486 | L18: =+K18-J18 -> -43.454959 | M18: =+('[3]8월누계'!$F$10+'[3]8월누계'!$F$19)/1000-M15-M16-M17 -> 129.6152 | N18: =+K18-M18 -> 315.58967 | R18: 영남권 | S18: =+[4]영남권!$Q$90 -> 21890.751 | T18: =+[4]영남권!$R$90 -> 18421.761 | U18: =+T18-S18 -> -3468.9898 | V18: =+[5]영남권!$Q$90 -> 21784.811 | W18: =+T18-V18 -> -3363.05
C19: 계 | E19: =SUM(E15:E18) -> 38833.955 | F19: =SUM(F15:F18) -> 25857.628 | G19: =+F19-E19 -> -12976.327 | H19: =SUM(H15:H18) -> 32564.666 | I19: =+F19-H19 -> -6707.0386 | J19: =SUM(J15:J18) -> 297549.94 | K19: =SUM(K15:K18) -> 246892.9 | L19: =+K19-J19 -> -50657.039 | M19: =SUM(M15:M18) -> 280634.83 | N19: =+K19-M19 -> -33741.933 | R19: 중부권 | S19: =+[4]중부권!$Q$90 -> 30215.606 | T19: =+[4]중부권!$R$90 -> 22438.35 | U19: =+T19-S19 -> -7777.2564 | V19: =+[5]중부권!$Q$90 -> 30716.283 | W19: =+T19-V19 -> -8277.9333
C20: 매출이익 | D20: 레미콘 | E20: =+E10-E15 -> 3685.405 | F20: =+F10-F15 -> 1243.2607 | G20: =+F20-E20 -> -2442.1443 | H20: =+H10-H15 -> 3402.0301 | I20: =+F20-H20 -> -2158.7694 | J20: =+J10-J15 -> 24348.426 | K20: =+K10-K15 -> 15026.504 | L20: =+K20-J20 -> -9321.9222 | M20: =+M10-M15 -> 31669.948 | N20: =+K20-M20 -> -16643.444 | Q20: 계 | S20: =+[4]합계!$Q$90 -> 22346.393 | T20: =+[4]합계!$R$90 -> 17977.151 | U20: =+T20-S20 -> -4369.242 | V20: =+[5]합계!$Q$90 -> 22264.3 | W20: =+T20-V20 -> -4287.1496
D21: 건자재 | E21: =+E11-E16 -> 370.18261 | F21: =+F11-F16 -> 147.28963 | G21: =+F21-E21 -> -222.89298 | H21: =+H11-H16 -> 200.45869 | I21: =+F21-H21 -> -53.169057 | J21: =+J11-J16 -> 2605.3443 | K21: =+K11-K16 -> 1122.7813 | L21: =+K21-J21 -> -1482.563 | M21: =+M11-M16 -> 1554.7763 | N21: =+K21-M21 -> -431.99498 | Q21: □ 건자재
D22: 골재 | E22: =+E12-E17 -> 128.00301 | F22: =+F12-F17 -> -42.376366 | G22: =+F22-E22 -> -170.37937 | H22: =+H12-H17 -> -77.148467 | I22: =+F22-H22 -> 34.772101 | J22: =+J12-J17 -> 1680.1043 | K22: =+K12-K17 -> -336.52786 | L22: =+K22-J22 -> -2016.6322 | M22: =+M12-M17 -> 900.60112 | N22: =+K22-M22 -> -1237.129 | Q22: 구분 | S22: 계획 | T22: 실적 | U22: 계획대비 | V22: 전년 | W22: 전년대비
D23: 기타 | E23: =+E13-E18 -> 75.352568 | F23: =+F13-F18 -> 99.995577 | G23: =+F23-E23 -> 24.643009 | H23: =+H13-H18 -> 388.21532 | I23: =+F23-H23 -> -288.21974 | J23: =+J13-J18 -> 725.28551 | K23: =+K13-K18 -> 621.83563 | L23: =+K23-J23 -> -103.44988 | M23: =+M13-M18 -> 1194.2858 | N23: =+K23-M23 -> -572.45014 | Q23: 철강재 판매단가 | S23: =+'[6]8월'!$F$10 -> 873809.52 | T23: =+'[6]8월'!$G$10 -> 765881.72 | U23: =+T23-S23 -> -107927.81 | V23: =+'[7]8월'!$G$10 -> 846014.53 | W23: =+T23-V23 -> -80132.81
C24: 계 | E24: =SUM(E20:E23) -> 4258.9432 | F24: =SUM(F20:F23) -> 1448.1696 | G24: =+F24-E24 -> -2810.7736 | H24: =SUM(H20:H23) -> 3913.5557 | I24: =+F24-H24 -> -2465.3861 | J24: =SUM(J20:J23) -> 29359.16 | K24: =SUM(K20:K23) -> 16434.593 | L24: =+K24-J24 -> -12924.567 | M24: =SUM(M20:M23) -> 35319.611 | N24: =+K24-M24 -> -18885.018 | Q24: 철강재 마진률 | S24: =+'[6]8월'!$F$15 -> 0.024058583 | T24: =+'[6]8월'!$G$15 -> 0.02261517 | U24: =+T24-S24 -> -0.0014434128 | V24: =+'[6]8월'!$G$15 -> 0.02261517 | W24: =+T24-V24 -> 0
C25: 판관비 | D25: 레미콘 | E25: =+('[1]8월'!$Z$13+'[1]8월'!$Z$20)/1000 -> 651.01474 | F25: =+('[2]8월'!$Z$13+'[2]8월'!$Z$20)/1000 -> 662.79208 | G25: =+F25-E25 -> 11.777339 | H25: =+('[3]8월'!$Z$13+'[3]8월'!$Z$20)/1000 -> 649.75983 | I25: =+F25-H25 -> 13.032257 | J25: =+('[1]8월누계'!$Z$13+'[1]8월누계'!$Z$20)/1000 -> 5365.3073 | K25: =+('[2]8월누계'!$Z$13+'[2]8월누계'!$Z$20)/1000 -> 5364.7221 | L25: =+K25-J25 -> -0.58515 | M25: =+('[3]8월누계'!$Z$13+'[3]8월누계'!$Z$20)/1000 -> 5270.8178 | N25: =+K25-M25 -> 93.90435 | Q25: □ 골재
D26: 건자재 | E26: =+('[1]8월'!$AA$13+'[1]8월'!$AA$20)/1000 -> 122.29035 | F26: =+('[2]8월'!$AO$13+'[2]8월'!$AO$20)/1000 -> 129.1286 | G26: =+F26-E26 -> 6.838248 | H26: =+('[3]8월'!$AO$13+'[3]8월'!$AO$20)/1000 -> 120.93393 | I26: =+F26-H26 -> 8.194662 | J26: =+('[1]8월누계'!$AA$13+'[1]8월누계'!$AA$20)/1000 -> 1014.5176 | K26: =+('[2]8월누계'!$AO$13+'[2]8월누계'!$AO$20)/1000 -> 1176.1173 | L26: =+K26-J26 -> 161.59964 | M26: =+('[3]8월누계'!$AO$13+'[3]8월누계'!$AO$20)/1000 -> 1099.6987 | N26: =+K26-M26 -> 76.418577 | Q26: 구분 | S26: 계획 | T26: 실적 | U26: 계획대비 | V26: 전년 | W26: 전년대비
D27: 골재 | E27: =+('[1]8월'!$AE$13+'[1]8월'!$AE$20+'[1]8월'!$AE$22)/1000 -> 46.783768 | F27: =+('[2]8월'!$AN$13+'[2]8월'!$AN$20+'[2]8월'!$AN$22)/1000 -> 46.627519 | G27: =+F27-E27 -> -0.15624885 | H27: =+('[3]8월'!$AN$13+'[3]8월'!$AN$20+'[3]8월'!$AN$22)/1000 -> 73.87002 | I27: =+F27-H27 -> -27.242502 | J27: =+('[1]8월누계'!$AE$13+'[1]8월누계'!$AE$20+'[1]8월누계'!$AE$22)/1000 -> 384.37507 | K27: =+('[2]8월누계'!$AN$13+'[2]8월누계'!$AN$20+'[2]8월누계'!$AN$22)/1000 -> 376.58465 | L27: =+K27-J27 -> -7.7904236 | M27: =+('[3]8월누계'!$AN$13+'[3]8월누계'!$AN$20+'[3]8월누계'!$AN$22)/1000 -> 441.65802 | N27: =+K27-M27 -> -65.073375 | Q27: 판매량 | R27: 자가 | S27: =+[8]원가손익!$W$10+[9]원가손익!$W$13+[10]손익!$F$10 -> 50130.878 | T27: =+[8]원가손익!$X$10+[9]원가손익!$X$13+[10]손익!$G$10 -> 43505 | U27: =+T27-S27 -> -6625.8785 | V27: =+'[11]부산모래장(당월)'!$S$85 -> 36904 | W27: =+T27-V27 -> 6601
D28: 기타 | E28: =+('[1]8월'!$E$13+'[1]8월'!$E$20)/1000-E25-E26-E27+('[1]8월'!$E$22/1000) -> 1384.1646 | F28: =+('[2]8월'!$F$13+'[2]8월'!$F$20)/1000-F25-F26-F27+'[2]8월'!$F$22/1000 -> 1372.3992 | G28: =+F28-E28 -> -11.765427 | H28: =+('[3]8월'!$F$13+'[3]8월'!$F$20)/1000-H25-H26-H27+'[3]8월'!$F$22/1000 -> 1192.6266 | I28: =+F28-H28 -> 179.77255 | J28: =+('[1]8월누계'!$E$13+'[1]8월누계'!$E$20)/1000-J25-J26-J27+('[1]8월누계'!$E$22/1000) -> 13206.625 | K28: =+('[2]8월누계'!$F$13+'[2]8월누계'!$F$20)/1000-K25-K26-K27+'[2]8월누계'!$F$22/1000 -> 14523.897 | L28: =+K28-J28 -> 1317.2723 | M28: =+('[3]8월누계'!$F$13+'[3]8월누계'!$F$20)/1000-M25-M26-M27+'[3]8월누계'!$F$22/1000 -> 12964.238 | N28: =+K28-M28 -> 1559.6589 | R28: 외판 | S28: =+[8]원가손익!$W$14+[9]원가손익!$W$15+[10]손익!$F$12 -> 45000 | T28: =+[8]원가손익!$X$14+[9]원가손익!$X$15+[10]손익!$G$12 -> 23582 | U28: =+T28-S28 -> -21418 | V28: =+'[11]부산모래장(당월)'!$S$86 -> 12699 | W28: =+T28-V28 -> 10883
C29: 계 | E29: =SUM(E25:E28) -> 2204.2535 | F29: =SUM(F25:F28) -> 2210.9474 | G29: =+F29-E29 -> 6.6939115 | H29: =SUM(H25:H28) -> 2037.1904 | I29: =+F29-H29 -> 173.75697 | J29: =SUM(J25:J28) -> 19970.825 | K29: =SUM(K25:K28) -> 21441.321 | L29: =+K29-J29 -> 1470.4964 | M29: =SUM(M25:M28) -> 19776.413 | N29: =+K29-M29 -> 1664.9085 | Q29: 합 계 | S29: =SUM(S27:S28) -> 95130.878 | T29: =SUM(T27:T28) -> 67087 | U29: =+T29-S29 -> -28043.878 | V29: =SUM(V27:V28) -> 49603 | W29: =+T29-V29 -> 17484
C30: 영업이익 | D30: 레미콘 | E30: =+E20-E25 -> 3034.3902 | F30: =+F20-F25 -> 580.46864 | G30: =+F30-E30 -> -2453.9216 | H30: =+H20-H25 -> 2752.2703 | I30: =+F30-H30 -> -2171.8017 | J30: =+J20-J25 -> 18983.119 | K30: =+K20-K25 -> 9661.7815 | L30: =+K30-J30 -> -9321.3371 | M30: =+M20-M25 -> 26399.13 | N30: =+K30-M30 -> -16737.348 | Q30: □ 기타내역(영업이익)
D31: % | E31: =+E30/E10 -> 0.11024631 | F31: =+F30/F10 -> 0.029843029 | G31: =+F31-E31 -> -0.08040328 | H31: =+H30/H10 -> 0.1066902 | I31: =+F31-H31 -> -0.076847175 | J31: =+J30/J10 -> 0.088219677 | K31: =+K30/K10 -> 0.052990471 | L31: =+K31-J31 -> -0.035229205 | M31: =+M30/M10 -> 0.11370362 | N31: =+K31-M31 -> -0.060713145 | Q31: 구분 | S31: 계획 | T31: 실적 | U31: 계획대비 | V31: 전년 | W31: 전년대비
D32: 건자재 | E32: =+E21-E26 -> 247.89226 | F32: =+F21-F26 -> 18.161034 | G32: =+F32-E32 -> -229.73123 | H32: =+H21-H26 -> 79.524753 | I32: =+F32-H32 -> -61.363719 | J32: =+J21-J26 -> 1590.8267 | K32: =+K21-K26 -> -53.335989 | L32: =+K32-J32 -> -1644.1627 | M32: =+M21-M26 -> 455.07757 | N32: =+K32-M32 -> -508.41356 | Q32: 레미콘임대 | S32: =+'사업장별(당월)'!T33 -> 48.278888 | T32: =+'사업장별(당월)'!U33 -> 23.588175 | U32: =+T32-S32 -> -24.690713 | V32: =+'사업장별(당월)'!W33 -> 71.958276 | W32: =+T32-V32 -> -48.370101
D33: 골재 | E33: =+E22-E27 -> 81.21924 | F33: =+F22-F27 -> -89.003885 | G33: =+F33-E33 -> -170.22312 | H33: =+H22-H27 -> -151.01849 | I33: =+F33-H33 -> 62.014603 | J33: =+J22-J27 -> 1295.7293 | K33: =+K22-K27 -> -713.11251 | L33: =+K33-J33 -> -2008.8418 | M33: =+M22-M27 -> 458.9431 | N33: =+K33-M33 -> -1172.0556 | Q33: 임대 | S33: =+'사업장별(당월)'!T34 -> 65.141 | T33: =+'사업장별(당월)'!U34 -> 67.040578 | U33: =+T33-S33 -> 1.899578 | V33: =+'사업장별(당월)'!W34 -> 63.903671 | W33: =+T33-V33 -> 3.136907
D34: 기타 | E34: =+E23-E28 -> -1308.812 | F34: =+F23-F28 -> -1272.4036 | G34: =+F34-E34 -> 36.408436 | H34: =+H23-H28 -> -804.41132 | I34: =+F34-H34 -> -467.99229 | J34: =+J23-J28 -> -12481.339 | K34: =+K23-K28 -> -13902.062 | L34: =+K34-J34 -> -1420.7222 | M34: =+M23-M28 -> -11769.953 | N34: =+K34-M34 -> -2132.1091 | Q34: 공통비 | S34: =+'사업장별(당월)'!T35 -> -1304.5501 | T34: =+'사업장별(당월)'!U35 -> -1315.3635 | U34: =+T34-S34 -> -10.813478 | V34: =+'사업장별(당월)'!W35 -> -1132.4208 | W34: =+T34-V34 -> -182.9427
C35: 계 | E35: =SUM(E30,E32:E34) -> 2054.6897 | F35: =SUM(F30,F32:F34) -> -762.77782 | G35: =+F35-E35 -> -2817.4675 | H35: =SUM(H30,H32:H34) -> 1876.3652 | I35: =+F35-H35 -> -2639.1431 | J35: =SUM(J30,J32:J34) -> 9388.335 | K35: =SUM(K30,K32:K34) -> -5006.7287 | L35: =+K35-J35 -> -14395.064 | M35: =SUM(M30,M32:M34) -> 15543.198 | N35: =+K35-M35 -> -20549.927 | Q35: 기타 | S35: =+S36-S32-S33-S34 -> -117.68187 | T35: =+T36-T32-T33-T34 -> -47.668822 | U35: =+T35-S35 -> 70.013049 | V35: =+V36-V32-V33-V34 -> 192.14758 | W35: =+T35-V35 -> -239.8164
D36: % | E36: =+E35/E14 -> 0.047680471 | F36: =+F35/F14 -> -0.027934647 | G36: =+F36-E36 -> -0.075615119 | H36: =+H35/H14 -> 0.051437958 | I36: =+F36-H36 -> -0.079372605 | J36: =+J35/J14 -> 0.028718488 | K36: =+K35/K14 -> -0.019013316 | L36: =+K36-J36 -> -0.047731804 | M36: =+M35/M14 -> 0.049194428 | N36: =+K36-M36 -> -0.068207743 | Q36: 합계 | S36: =+'사업장별(당월)'!T41 -> -1308.812 | T36: =+'사업장별(당월)'!U41 -> -1272.4036 | U36: =+T36-S36 -> 36.408436 | V36: =+'사업장별(당월)'!W41 -> -804.41132 | W36: =+T36-V36 -> -467.99229
E38: =+'[1]8월'!$E$26/1000 -> 2054.6897 | F38: =+'[2]8월'!$F$26/1000 -> -762.77782 | H38: =+'[3]8월'!$F$26/1000 -> 1876.3652 | J38: =+'[1]8월누계'!$E$26/1000 -> 9388.335 | K38: =+'[2]8월누계'!$F$26/1000 -> -5006.7287 | M38: =+'[3]8월누계'!$F$26/1000 -> 15543.198
E39: =+E35=E38 -> TRUE | F39: =+F35=F38 -> FALSE | H39: =+H35=H38 -> TRUE | J39: =+J35=J38 -> FALSE | K39: =+K35=K38 -> FALSE | M39: =+M35=M38 -> TRUE
E40: =+E35-E38 -> 0 | F40: =+F35-F38 -> 2.7284841e-12 | H40: =+H35-H38 -> -2.7284841e-12 | J40: =+J35-J38 -> 1.8189894e-11 | K40: =+K35-K38 -> 2.5465852e-11 | M40: =+M35-M38 -> 0

Sheet 레미콘 영업이익
H3: □ 레미콘 영업이익(8월)
H5: 구분 | J5: 8월 | T5: 8월누계
J6: 영업이익(공통비 배부전) | O6: 영업이익(공통비 배부후) | T6: 영업이익(공통비 배부전) | Y6: 영업이익(공통비 배부전)
A7: 2024년 8월 마감 손익 | J7: 계획 | K7: 실적 | L7: 차이 | M7: 전년 | N7: 차이 | O7: 계획 | P7: 실적 | Q7: 차이 | R7: 전년 | S7: 차이 | T7: 계획 | U7: 실적 | V7: 차이 | W7: 전년 | X7: 차이 | Y7: 계획 | Z7: 실적 | AA7: 차이 | AB7: 전년 | AC7: 차이
B8: 안양 | H8: 레미콘 | I8: 안양 | J8: =+[4]안양!$H$86/1000 -> 521.50923 | K8: =+[4]안양!$I$86/1000 -> 88.551493 | L8: =+K8-J8 -> -432.95774 | M8: =+[5]안양!$H$86/1000 -> 305.02032 | N8: =+K8-M8 -> -216.46883 | O8: =+[4]안양!$H$92/1000 -> 329.83292 | P8: =+[4]안양!$I$92/1000 -> -59.732409 | Q8: =+P8-O8 -> -389.56533 | R8: =+[5]안양!$H$92/1000 -> 174.78769 | S8: =+P8-R8 -> -234.5201 | T8: =+[12]안양!$H$86/1000 -> 2587.0177 | U8: =+[12]안양!$I$86/1000 -> 1691.0119 | V8: =+U8-T8 -> -896.00586 | W8: =+[13]안양!$H$86/1000 -> 3141.6975 | X8: =+U8-W8 -> -1450.6857 | Y8: =+[12]안양!$H$92/1000 -> 832.43845 | Z8: =+[12]안양!$I$92/1000 -> -30.809932 | AA8: =+Z8-Y8 -> -863.24838 | AB8: =+[13]안양!$H$92/1000 -> 1632.1377 | AC8: =+Z8-AB8 -> -1662.9476
B9: 인천 | H9: 직영 | I9: 인천 | J9: =+[4]인천!$H$86/1000 -> 155.95557 | K9: =+[4]인천!$I$86/1000 -> -70.264612 | L9: =+K9-J9 -> -226.22018 | M9: =+[5]인천!$H$86/1000 -> 71.619563 | N9: =+K9-M9 -> -141.88418 | O9: =+[4]인천!$H$92/1000 -> 33.889315 | P9: =+[4]인천!$I$92/1000 -> -214.17261 | Q9: =+P9-O9 -> -248.06192 | R9: =+[5]인천!$H$92/1000 -> -31.241659 | S9: =+P9-R9 -> -182.93095 | T9: =+[12]인천!$H$86/1000 -> 860.40308 | U9: =+[12]인천!$I$86/1000 -> 314.65792 | V9: =+U9-T9 -> -545.74515 | W9: =+[13]인천!$H$86/1000 -> 1666.865 | X9: =+U9-W9 -> -1352.2071 | Y9: =+[12]인천!$H$92/1000 -> -392.92985 | Z9: =+[12]인천!$I$92/1000 -> -1118.2661 | AA9: =+Z9-Y9 -> -725.33629 | AB9: =+[13]인천!$H$92/1000 -> 560.39755 | AC9: =+Z9-AB9 -> -1678.6637
B10: 파주 | I10: 파주 | J10: =+[4]파주!$H$86/1000 -> 154.51702 | K10: =+[4]파주!$I$86/1000 -> 11.698428 | L10: =+K10-J10 -> -142.8186 | M10: =+[5]파주!$H$86/1000 -> 111.92552 | N10: =+K10-M10 -> -100.22709 | O10: =+[4]파주!$H$92/1000 -> 52.769216 | P10: =+[4]파주!$I$92/1000 -> -68.846307 | Q10: =+P10-O10 -> -121.61552 | R10: =+[5]파주!$H$92/1000 -> 31.75744 | S10: =+P10-R10 -> -100.60375 | T10: =+[12]파주!$H$86/1000 -> 792.23252 | U10: =+[12]파주!$I$86/1000 -> -299.74362 | V10: =+U10-T10 -> -1091.9761 | W10: =+[13]파주!$H$86/1000 -> 1514.2702 | X10: =+U10-W10 -> -1814.0138 | Y10: =+[12]파주!$H$92/1000 -> -117.75075 | Z10: =+[12]파주!$I$92/1000 -> -934.74389 | AA10: =+Z10-Y10 -> -816.99314 | AB10: =+[13]파주!$H$92/1000 -> 532.9163 | AC10: =+Z10-AB10 -> -1467.6602
B11: 김포 | I11: 김포 | J11: =+[4]김포!$H$86/1000 -> 110.35007 | K11: =+[4]김포!$I$86/1000 -> 12.679732 | L11: =+K11-J11 -> -97.670334 | M11: =+[5]김포!$H$86/1000 -> 68.449578 | N11: =+K11-M11 -> -55.769846 | O11: =+[4]김포!$H$92/1000 -> 47.931924 | P11: =+[4]김포!$I$92/1000 -> -50.462848 | Q11: =+P11-O11 -> -98.394772 | R11: =+[5]김포!$H$92/1000 -> 24.635656 | S11: =+P11-R11 -> -75.098504 | T11: =+[12]김포!$H$86/1000 -> 660.88066 | U11: =+[12]김포!$I$86/1000 -> 29.081227 | V11: =+U11-T11 -> -631.79943 | W11: =+[13]김포!$H$86/1000 -> 832.09534 | X11: =+U11-W11 -> -803.01411 | Y11: =+[12]김포!$H$92/1000 -> 61.219504 | Z11: =+[12]김포!$I$92/1000 -> -495.48876 | AA11: =+Z11-Y11 -> -556.70826 | AB11: =+[13]김포!$H$92/1000 -> 399.07454 | AC11: =+Z11-AB11 -> -894.5633
B12: 부산 | I12: 부산 | J12: =+[4]부산!$H$86/1000 -> 137.44552 | K12: =+[4]부산!$I$86/1000 -> 150.88101 | L12: =+K12-J12 -> 13.435496 | M12: =+[5]부산!$H$86/1000 -> 114.94156 | N12: =+K12-M12 -> 35.939457 | O12: =+[4]부산!$H$92/1000 -> 48.732293 | P12: =+[4]부산!$I$92/1000 -> 10.586744 | Q12: =+P12-O12 -> -38.145549 | R12: =+[5]부산!$H$92/1000 -> 36.307658 | S12: =+P12-R12 -> -25.720913 | T12: =+[12]부산!$H$86/1000 -> 1408.1702 | U12: =+[12]부산!$I$86/1000 -> 1620.5948 | V12: =+U12-T12 -> 212.42463 | W12: =+[13]부산!$H$86/1000 -> 1826.0328 | X12: =+U12-W12 -> -205.43794 | Y12: =+[12]부산!$H$92/1000 -> 393.85157 | Z12: =+[12]부산!$I$92/1000 -> 398.0855 | AA12: =+Z12-Y12 -> 4.2339361 | AB12: =+[13]부산!$H$92/1000 -> 944.7628 | AC12: =+Z12-AB12 -> -546.6773
B13: 서부산 | I13: 서부산 | J13: =+[4]서부산!$H$86/1000 -> 152.69859 | K13: =+[4]서부산!$I$86/1000 -> 122.94464 | L13: =+K13-J13 -> -29.753955 | M13: =+[5]서부산!$H$86/1000 -> 186.73169 | N13: =+K13-M13 -> -63.787053 | O13: =+[4]서부산!$H$92/1000 -> 70.904782 | P13: =+[4]서부산!$I$92/1000 -> 11.129312 | Q13: =+P13-O13 -> -59.77547 | R13: =+[5]서부산!$H$92/1000 -> 106.99912 | S13: =+P13-R13 -> -95.869805 | T13: =+[12]서부산!$H$86/1000 -> 1370.9415 | U13: =+[12]서부산!$I$86/1000 -> 858.20609 | V13: =+U13-T13 -> -512.73543 | W13: =+[13]서부산!$H$86/1000 -> 2073.3245 | X13: =+U13-W13 -> -1215.1184 | Y13: =+[12]서부산!$H$92/1000 -> 457.33239 | Z13: =+[12]서부산!$I$92/1000 -> -47.116362 | AA13: =+Z13-Y13 -> -504.44875 | AB13: =+[13]서부산!$H$92/1000 -> 1178.1031 | AC13: =+Z13-AB13 -> -1225.2195
B14: 김해 | I14: 김해 | J14: =+[4]김해!$H$86/1000 -> 109.16349 | K14: =+[4]김해!$I$86/1000 -> -52.202861 | L14: =+K14-J14 -> -161.36635 | M14: =+[5]김해!$H$86/1000 -> 129.99266 | N14: =+K14-M14 -> -182.19552 | O14: =+[4]김해!$H$92/1000 -> 48.505071 | P14: =+[4]김해!$I$92/1000 -> -97.544173 | Q14: =+P14-O14 -> -146.04924 | R14: =+[5]김해!$H$92/1000 -> 60.379681 | S14: =+P14-R14 -> -157.92385 | T14: =+[12]김해!$H$86/1000 -> 894.04981 | U14: =+[12]김해!$I$86/1000 -> -230.10983 | V14: =+U14-T14 -> -1124.1596 | W14: =+[13]김해!$H$86/1000 -> 712.38713 | X14: =+U14-W14 -> -942.49696 | Y14: =+[12]김해!$H$92/1000 -> 264.81906 | Z14: =+[12]김해!$I$92/1000 -> -683.47932 | AA14: =+Z14-Y14 -> -948.29838 | AB14: =+[13]김해!$H$92/1000 -> 192.84591 | AC14: =+Z14-AB14 -> -876.32523
B15: 정관 | I15: 정관 | J15: =+[4]정관!$H$86/1000 -> 152.64297 | K15: =+[4]정관!$I$86/1000 -> 156.95554 | L15: =+K15-J15 -> 4.3125657 | M15: =+[5]정관!$H$86/1000 -> 117.77506 | N15: =+K15-M15 -> 39.180482 | O15: =+[4]정관!$H$92/1000 -> 63.682587 | P15: =+[4]정관!$I$92/1000 -> 12.653236 | Q15: =+P15-O15 -> -51.029351 | R15: =+[5]정관!$H$92/1000 -> 35.04148 | S15: =+P15-R15 -> -22.388245 | T15: =+[12]정관!$H$86/1000 -> 1256.208 | U15: =+[12]정관!$I$86/1000 -> 1463.7512 | V15: =+U15-T15 -> 207.54315 | W15: =+[13]정관!$H$86/1000 -> 1496.7056 | X15: =+U15-W15 -> -32.95437 | Y15: =+[12]정관!$H$92/1000 -> 327.01522 | Z15: =+[12]정관!$I$92/1000 -> 215.43891 | AA15: =+Z15-Y15 -> -111.57631 | AB15: =+[13]정관!$H$92/1000 -> 691.82994 | AC15: =+Z15-AB15 -> -476.39103
B16: 양산 | I16: 양산 | J16: =+[4]양산!$H$86/1000 -> 118.40443 | K16: =+[4]양산!$I$86/1000 -> -62.460978 | L16: =+K16-J16 -> -180.86541 | M16: =+[5]양산!$H$86/1000 -> 84.714054 | N16: =+K16-M16 -> -147.17503 | O16: =+[4]양산!$H$92/1000 -> 63.528215 | P16: =+[4]양산!$I$92/1000 -> -87.850245 | Q16: =+P16-O16 -> -151.37846 | R16: =+[5]양산!$H$92/1000 -> 34.060274 | S16: =+P16-R16 -> -121.91052 | T16: =+[12]양산!$H$86/1000 -> 697.11207 | U16: =+[12]양산!$I$86/1000 -> 2.418351 | V16: =+U16-T16 -> -694.69372 | W16: =+[13]양산!$H$86/1000 -> 864.1981 | X16: =+U16-W16 -> -861.77975 | Y16: =+[12]양산!$H$92/1000 -> 184.47308 | Z16: =+[12]양산!$I$92/1000 -> -389.21666 | AA16: =+Z16-Y16 -> -573.68975 | AB16: =+[13]양산!$H$92/1000 -> 396.85587 | AC16: =+Z16-AB16 -> -786.07254
B17: 창원 | I17: 창원 | J17: =+[4]창원!$H$86/1000 -> 147.81171 | K17: =+[4]창원!$I$86/1000 -> -12.880638 | L17: =+K17-J17 -> -160.69235 | M17: =+[5]창원!$H$86/1000 -> 252.53771 | N17: =+K17-M17 -> -265.41834 | O17: =+[4]창원!$H$92/1000 -> 84.129364 | P17: =+[4]창원!$I$92/1000 -> -56.868133 | Q17: =+P17-O17 -> -140.9975 | R17: =+[5]창원!$H$92/1000 -> 178.22893 | S17: =+P17-R17 -> -235.09706 | T17: =+[12]창원!$H$86/1000 -> 706.48657 | U17: =+[12]창원!$I$86/1000 -> 342.52946 | V17: =+U17-T17 -> -363.95711 | W17: =+[13]창원!$H$86/1000 -> 2209.9365 | X17: =+U17-W17 -> -1867.4071 | Y17: =+[12]창원!$H$92/1000 -> 159.8138 | Z17: =+[12]창원!$I$92/1000 -> -189.94077 | AA17: =+Z17-Y17 -> -349.75457 | AB17: =+[13]창원!$H$92/1000 -> 1481.1653 | AC17: =+Z17-AB17 -> -1671.106
B18: 대구 | I18: 대구 | J18: =+[4]대구!$H$86/1000 -> 130.69121 | K18: =+[4]대구!$I$86/1000 -> 13.899454 | L18: =+K18-J18 -> -116.79175 | M18: =+[5]대구!$H$86/1000 -> 205.51536 | N18: =+K18-M18 -> -191.6159 | O18: =+[4]대구!$H$92/1000 -> 72.450085 | P18: =+[4]대구!$I$92/1000 -> -47.404891 | Q18: =+P18-O18 -> -119.85498 | R18: =+[5]대구!$H$92/1000 -> 141.89992 | S18: =+P18-R18 -> -189.30481 | T18: =+[12]대구!$H$86/1000 -> 866.04037 | U18: =+[12]대구!$I$86/1000 -> 42.095104 | V18: =+U18-T18 -> -823.94527 | W18: =+[13]대구!$H$86/1000 -> 1978.415 | X18: =+U18-W18 -> -1936.3199 | Y18: =+[12]대구!$H$92/1000 -> 300.61609 | Z18: =+[12]대구!$I$92/1000 -> -464.37032 | AA18: =+Z18-Y18 -> -764.98641 | AB18: =+[13]대구!$H$92/1000 -> 1338.3645 | AC18: =+Z18-AB18 -> -1802.7349
B19: 울산 | I19: 울산 | J19: =+[4]울산!$H$86/1000 -> 123.08733 | K19: =+[4]울산!$I$86/1000 -> 46.051256 | L19: =+K19-J19 -> -77.036078 | M19: =+[5]울산!$H$86/1000 -> 205.15454 | N19: =+K19-M19 -> -159.10329 | O19: =+[4]울산!$H$92/1000 -> 62.833098 | P19: =+[4]울산!$I$92/1000 -> -20.370711 | Q19: =+P19-O19 -> -83.203808 | R19: =+[5]울산!$H$92/1000 -> 145.58357 | S19: =+P19-R19 -> -165.95429 | T19: =+[12]울산!$H$86/1000 -> 654.64117 | U19: =+[12]울산!$I$86/1000 -> 706.16898 | V19: =+U19-T19 -> 51.52781 | W19: =+[13]울산!$H$86/1000 -> 1001.9594 | X19: =+U19-W19 -> -295.79042 | Y19: =+[12]울산!$H$92/1000 -> 87.91468 | Z19: =+[12]울산!$I$92/1000 -> 73.280099 | AA19: =+Z19-Y19 -> -14.634581 | AB19: =+[13]울산!$H$92/1000 -> 552.09319 | AC19: =+Z19-AB19 -> -478.81309
B20: 아산 | I20: 아산 | J20: =+[4]아산!$H$86/1000 -> 300.4957 | K20: =+[4]아산!$I$86/1000 -> 29.798174 | L20: =+K20-J20 -> -270.69752 | M20: =+[5]아산!$H$86/1000 -> 395.17701 | N20: =+K20-M20 -> -365.37883 | O20: =+[4]아산!$H$92/1000 -> 202.13846 | P20: =+[4]아산!$I$92/1000 -> -79.081658 | Q20: =+P20-O20 -> -281.22012 | R20: =+[5]아산!$H$92/1000 -> 300.78919 | S20: =+P20-R20 -> -379.87085 | T20: =+[12]아산!$H$86/1000 -> 2183.0332 | U20: =+[12]아산!$I$86/1000 -> 696.4113 | V20: =+U20-T20 -> -1486.6219 | W20: =+[13]아산!$H$86/1000 -> 3107.8737 | X20: =+U20-W20 -> -2411.4624 | Y20: =+[12]아산!$H$92/1000 -> 1187.0925 | Z20: =+[12]아산!$I$92/1000 -> -398.02647 | AA20: =+Z20-Y20 -> -1585.119 | AB20: =+[13]아산!$H$92/1000 -> 2089.6884 | AC20: =+Z20-AB20 -> -2487.7149
B21: 전주 | I21: 전주 | J21: =+[4]전주!$H$86/1000 -> 183.67955 | K21: =+[4]전주!$I$86/1000 -> 23.432485 | L21: =+K21-J21 -> -160.24707 | M21: =+[5]전주!$H$86/1000 -> 82.209062 | N21: =+K21-M21 -> -58.776577 | O21: =+[4]전주!$H$92/1000 -> 128.90287 | P21: =+[4]전주!$I$92/1000 -> -26.0945 | Q21: =+P21-O21 -> -154.99737 | R21: =+[5]전주!$H$92/1000 -> 44.329137 | S21: =+P21-R21 -> -70.423637 | T21: =+[12]전주!$H$86/1000 -> 820.97222 | U21: =+[12]전주!$I$86/1000 -> 934.7617 | V21: =+U21-T21 -> 113.78948 | W21: =+[13]전주!$H$86/1000 -> 415.8193 | X21: =+U21-W21 -> 518.9424 | Y21: =+[12]전주!$H$92/1000 -> 362.62675 | Z21: =+[12]전주!$I$92/1000 -> 285.23033 | AA21: =+Z21-Y21 -> -77.39642 | AB21: =+[13]전주!$H$92/1000 -> 125.12437 | AC21: =+Z21-AB21 -> 160.10596
B22: 군산 | I22: 군산 | J22: =+[4]군산!$H$86/1000 -> 233.40876 | K22: =+[4]군산!$I$86/1000 -> 89.004881 | L22: =+K22-J22 -> -144.40388 | M22: =+[5]군산!$H$86/1000 -> 250.95442 | N22: =+K22-M22 -> -161.94954 | O22: =+[4]군산!$H$92/1000 -> 192.8819 | P22: =+[4]군산!$I$92/1000 -> 57.083761 | Q22: =+P22-O22 -> -135.79814 | R22: =+[5]군산!$H$92/1000 -> 214.59821 | S22: =+P22-R22 -> -157.51445 | T22: =+[12]군산!$H$86/1000 -> 1401.9164 | U22: =+[12]군산!$I$86/1000 -> 842.70956 | V22: =+U22-T22 -> -559.20682 | W22: =+[13]군산!$H$86/1000 -> 2170.0631 | X22: =+U22-W22 -> -1327.3535 | Y22: =+[12]군산!$H$92/1000 -> 1064.1854 | Z22: =+[12]군산!$I$92/1000 -> 544.53477 | AA22: =+Z22-Y22 -> -519.65065 | AB22: =+[13]군산!$H$92/1000 -> 1793.849 | AC22: =+Z22-AB22 -> -1249.3142
B23: 원주 | I23: 원주 | J23: =+[4]원주!$H$86/1000 -> 109.87534 | K23: =+[4]원주!$I$86/1000 -> 2.170287 | L23: =+K23-J23 -> -107.70505 | M23: =+[5]원주!$H$86/1000 -> 125.92494 | N23: =+K23-M23 -> -123.75465 | O23: =+[4]원주!$H$92/1000 -> 84.410685 | P23: =+[4]원주!$I$92/1000 -> -13.205873 | Q23: =+P23-O23 -> -97.616558 | R23: =+[5]원주!$H$92/1000 -> 98.637453 | S23: =+P23-R23 -> -111.84333 | T23: =+[12]원주!$H$86/1000 -> 570.4744 | U23: =+[12]원주!$I$86/1000 -> 50.290815 | V23: =+U23-T23 -> -520.18359 | W23: =+[13]원주!$H$86/1000 -> 1021.5641 | X23: =+U23-W23 -> -971.27326 | Y23: =+[12]원주!$H$92/1000 -> 354.25559 | Z23: =+[12]원주!$I$92/1000 -> -109.80254 | AA23: =+Z23-Y23 -> -464.05813 | AB23: =+[13]원주!$H$92/1000 -> 780.76267 | AC23: =+Z23-AB23 -> -890.56521
B24: 제주 | I24: 제주 | J24: =+[4]제주!$H$86/1000 -> 192.65373 | K24: =+[4]제주!$I$86/1000 -> 30.210348 | L24: =+K24-J24 -> -162.44338 | M24: =+[5]제주!$H$86/1000 -> 43.627251 | N24: =+K24-M24 -> -13.416903 | O24: =+[4]제주!$H$92/1000 -> 142.31738 | P24: =+[4]제주!$I$92/1000 -> -4.7135971 | Q24: =+P24-O24 -> -147.03098 | R24: =+[5]제주!$H$92/1000 -> 23.05571 | S24: =+P24-R24 -> -27.769307 | T24: =+[12]제주!$H$86/1000 -> 1252.5386 | U24: =+[12]제주!$I$86/1000 -> 596.94655 | V24: =+U24-T24 -> -655.59205 | W24: =+[13]제주!$H$86/1000 -> 365.92274 | X24: =+U24-W24 -> 231.02381 | Y24: =+[12]제주!$H$92/1000 -> 801.74025 | Z24: =+[12]제주!$I$92/1000 -> 214.84547 | AA24: =+Z24-Y24 -> -586.89477 | AB24: =+[13]제주!$H$92/1000 -> 185.9662 | AC24: =+Z24-AB24 -> 28.879274
I25: 수도권 | J25: =SUM(J8:J11) -> 942.33189 | K25: =SUM(K8:K11) -> 42.665041 | L25: =+K25-J25 -> -899.66685 | M25: =SUM(M8:M11) -> 557.01498 | N25: =+K25-M25 -> -514.34994 | O25: =SUM(O8:O11) -> 464.42337 | P25: =SUM(P8:P11) -> -393.21417 | Q25: =+P25-O25 -> -857.63755 | R25: =SUM(R8:R11) -> 199.93913 | S25: =+P25-R25 -> -593.1533 | T25: =SUM(T8:T11) -> 4900.534 | U25: =SUM(U8:U11) -> 1735.0074 | V25: =+U25-T25 -> -3165.5266 | W25: =SUM(W8:W11) -> 7154.9281 | X25: =+U25-W25 -> -5419.9207 | Y25: =SUM(Y8:Y11) -> 382.97735 | Z25: =SUM(Z8:Z11) -> -2579.3087 | AA25: =+Z25-Y25 -> -2962.2861 | AB25: =SUM(AB8:AB11) -> 3124.5261 | AC25: =+Z25-AB25 -> -5703.8348
I26: 영남권 | J26: =SUM(J12:J19) -> 1071.9453 | K26: =SUM(K12:K19) -> 363.18743 | L26: =+K26-J26 -> -708.75784 | M26: =SUM(M12:M19) -> 1297.3626 | N26: =+K26-M26 -> -934.1752 | O26: =SUM(O12:O19) -> 514.76549 | P26: =SUM(P12:P19) -> -275.66886 | Q26: =+P26-O26 -> -790.43435 | R26: =SUM(R12:R19) -> 738.50063 | S26: =+P26-R26 -> -1014.1695 | T26: =SUM(T12:T19) -> 7853.6497 | U26: =SUM(U12:U19) -> 4805.6542 | V26: =+U26-T26 -> -3047.9956 | W26: =SUM(W12:W19) -> 12162.959 | X26: =+U26-W26 -> -7357.3048 | Y26: =SUM(Y12:Y19) -> 2175.8359 | Z26: =SUM(Z12:Z19) -> -1087.3189 | AA26: =+Z26-Y26 -> -3263.1548 | AB26: =SUM(AB12:AB19) -> 6776.0206 | AC26: =+Z26-AB26 -> -7863.3395
I27: 중부권 | J27: =SUM(J20:J24) -> 1020.1131 | K27: =SUM(K20:K24) -> 174.61617 | L27: =+K27-J27 -> -845.4969 | M27: =SUM(M20:M24) -> 897.89268 | N27: =+K27-M27 -> -723.27651 | O27: =SUM(O20:O24) -> 750.6513 | P27: =SUM(P20:P24) -> -66.011867 | Q27: =+P27-O27 -> -816.66317 | R27: =SUM(R20:R24) -> 681.4097 | S27: =+P27-R27 -> -747.42156 | T27: =SUM(T20:T24) -> 6228.9348 | U27: =SUM(U20:U24) -> 3121.1199 | V27: =+U27-T27 -> -3107.8149 | W27: =SUM(W20:W24) -> 7081.2429 | X27: =+U27-W27 -> -3960.1229 | Y27: =SUM(Y20:Y24) -> 3769.9005 | Z27: =SUM(Z20:Z24) -> 536.78156 | AA27: =+Z27-Y27 -> -3233.119 | AB27: =SUM(AB20:AB24) -> 4975.3906 | AC27: =+Z27-AB27 -> -4438.6091
H28: 레미콘 계 | J28: =SUM(J25:J27) -> 3034.3902 | K28: =SUM(K25:K27) -> 580.46864 | L28: =+K28-J28 -> -2453.9216 | M28: =SUM(M25:M27) -> 2752.2703 | N28: =+K28-M28 -> -2171.8017 | O28: =SUM(O25:O27) -> 1729.8402 | P28: =SUM(P25:P27) -> -734.8949 | Q28: =+P28-O28 -> -2464.7351 | R28: =SUM(R25:R27) -> 1619.8495 | S28: =+P28-R28 -> -2354.7444 | T28: =SUM(T25:T27) -> 18983.119 | U28: =SUM(U25:U27) -> 9661.7815 | V28: =+U28-T28 -> -9321.3371 | W28: =SUM(W25:W27) -> 26399.13 | X28: =+U28-W28 -> -16737.348 | Y28: =SUM(Y25:Y27) -> 6328.7138 | Z28: =SUM(Z25:Z27) -> -3129.8461 | AA28: =+Z28-Y28 -> -9458.5599 | AB28: =SUM(AB25:AB27) -> 14875.937 | AC28: =+Z28-AB28 -> -18005.783

Sheet 사업장별(당월)
H3: □ 사업장별 손익실적(2025-08)
AG4: [단위 : 천㎥, 톤, 백만원]
H5: 구분 | J5: 물량 | O5: 매출 | T5: 영업이익(공통비 배부전) | Y5: 판매단가 | AB5: 변동비 | AE5: 공헌이익
A6: 2024년 8월 마감 손익 | J6: 계획 | K6: 실적 | L6: 차이 | M6: 전년 | N6: 차이 | O6: 계획 | P6: 실적 | Q6: 차이 | R6: 전년 | S6: 차이 | T6: 계획 | U6: 실적 | V6: 차이 | W6: 전년 | X6: 차이 | Y6: 계획 | Z6: 실적 | AA6: 전년 | AB6: 계획 | AC6: 실적 | AD6: 전년 | AE6: 계획 | AF6: 실적 | AG6: 전년
B7: 안양 | G7: =+I7 -> 안양 | H7: 레미콘 | I7: 안양 | J7: =+IFERROR(HLOOKUP($B7,'[1]8월'!$D$6:$BN$259,2,),)/1000 -> 40 | K7: =+IFERROR(HLOOKUP($B7,'[2]8월'!$F$6:$CP$99,2,),)/1000 -> 23.449 | L7: =+K7-J7 -> -16.551 | M7: =+IFERROR(HLOOKUP($B7,'[3]8월'!$F$6:$CC$57,2,),)/1000 -> 29.384 | N7: =+K7-M7 -> -5.935 | O7: =+IFERROR(HLOOKUP($B7,'[1]8월'!$D$6:$BN$259,3,),)/1000 -> 4050.2795 | P7: =+IFERROR(HLOOKUP($B7,'[2]8월'!$F$6:$CP$99,3,),)/1000 -> 2252.0606 | Q7: =+P7-O7 -> -1798.2189 | R7: =+IFERROR(HLOOKUP($B7,'[3]8월'!$F$6:$CC$57,3,),)/1000 -> 2958.1096 | S7: =+P7-R7 -> -706.04903 | T7: =+IFERROR(HLOOKUP($B7,'[1]8월'!$D$6:$BN$259,16,),)/1000 -> 521.50923 | U7: =+IFERROR(HLOOKUP($B7,'[2]8월'!$F$6:$CP$99,16,),)/1000 -> 88.551493 | V7: =+U7-T7 -> -432.95774 | W7: =+IFERROR(HLOOKUP($B7,'[3]8월'!$F$6:$CC$57,16,),)/1000 -> 305.02032 | X7: =+U7-W7 -> -216.46883 | Y7: =+[4]안양!$Q$85 -> 101256.99 | Z7: =+[4]안양!$R$85 -> 96040.793 | AA7: =+[5]안양!$Q$85 -> 100670.76 | AB7: =+[4]안양!$Q$89 -> 81036.261 | AC7: =+[4]안양!$R$89 -> 79887.109 | AD7: =+[5]안양!$Q$89 -> 80931.093 | AE7: =+Y7-AB7 -> 20220.726 | AF7: =+Z7-AC7 -> 16153.684 | AG7: =+AA7-AD7 -> 19739.666
B8: 인천 | G8: =+I8 -> 인천 | H8: 직영 | I8: 인천 | J8: =+IFERROR(HLOOKUP($B8,'[1]8월'!$D$6:$BN$259,2,),)/1000 -> 26 | K8: =+IFERROR(HLOOKUP($B8,'[2]8월'!$F$6:$CP$99,2,),)/1000 -> 23.226 | L8: =+K8-J8 -> -2.774 | M8: =+IFERROR(HLOOKUP($B8,'[3]8월'!$F$6:$CC$57,2,),)/1000 -> 23.503 | N8: =+K8-M8 -> -0.277 | O8: =+IFERROR(HLOOKUP($B8,'[1]8월'!$D$6:$BN$259,3,),)/1000 -> 2579.3613 | P8: =+IFERROR(HLOOKUP($B8,'[2]8월'!$F$6:$CP$99,3,),)/1000 -> 2185.6015 | Q8: =+P8-O8 -> -393.75977 | R8: =+IFERROR(HLOOKUP($B8,'[3]8월'!$F$6:$CC$57,3,),)/1000 -> 2336.3942 | S8: =+P8-R8 -> -150.79266 | T8: =+IFERROR(HLOOKUP($B8,'[1]8월'!$D$6:$BN$259,16,),)/1000 -> 155.95557 | U8: =+IFERROR(HLOOKUP($B8,'[2]8월'!$F$6:$CP$99,16,),)/1000 -> -70.264612 | V8: =+U8-T8 -> -226.22018 | W8: =+IFERROR(HLOOKUP($B8,'[3]8월'!$F$6:$CC$57,16,),)/1000 -> 71.619563 | X8: =+U8-W8 -> -141.88418 | Y8: =+[4]인천!$Q$85 -> 99206.204 | Z8: =+[4]인천!$R$85 -> 94256.418 | AA8: =+[5]인천!$Q$85 -> 99419.046 | AB8: =+[4]인천!$Q$89 -> 82346.605 | AC8: =+[4]인천!$R$89 -> 83081.086 | AD8: =+[5]인천!$Q$89 -> 84513.241 | AE8: =+Y8-AB8 -> 16859.599 | AF8: =+Z8-AC8 -> 11175.333 | AG8: =+AA8-AD8 -> 14905.805
B9: 파주 | G9: =+I9 -> 파주 | I9: 파주 | J9: =+IFERROR(HLOOKUP($B9,'[1]8월'!$D$6:$BN$259,2,),)/1000 -> 22 | K9: =+IFERROR(HLOOKUP($B9,'[2]8월'!$F$6:$CP$99,2,),)/1000 -> 12.851 | L9: =+K9-J9 -> -9.149 | M9: =+IFERROR(HLOOKUP($B9,'[3]8월'!$F$6:$CC$57,2,),)/1000 -> 19.088 | N9: =+K9-M9 -> -6.237 | O9: =+IFERROR(HLOOKUP($B9,'[1]8월'!$D$6:$BN$259,3,),)/1000 -> 2150.0156 | P9: =+IFERROR(HLOOKUP($B9,'[2]8월'!$F$6:$CP$99,3,),)/1000 -> 1223.2725 | Q9: =+P9-O9 -> -926.74312 | R9: =+IFERROR(HLOOKUP($B9,'[3]8월'!$F$6:$CC$57,3,),)/1000 -> 1820.9412 | S9: =+P9-R9 -> -597.6687 | T9: =+IFERROR(HLOOKUP($B9,'[1]8월'!$D$6:$BN$259,16,),)/1000 -> 154.51702 | U9: =+IFERROR(HLOOKUP($B9,'[2]8월'!$F$6:$CP$99,16,),)/1000 -> 11.698428 | V9: =+U9-T9 -> -142.8186 | W9: =+IFERROR(HLOOKUP($B9,'[3]8월'!$F$6:$CC$57,16,),)/1000 -> 111.92552 | X9: =+U9-W9 -> -100.22709 | Y9: =+[4]파주!$Q$85 -> 97727.983 | Z9: =+[4]파주!$R$85 -> 95316.059 | AA9: =+[5]파주!$Q$85 -> 95387.216 | AB9: =+[4]파주!$Q$89 -> 80409.825 | AC9: =+[4]파주!$R$89 -> 78428.563 | AD9: =+[5]파주!$Q$89 -> 78173.187 | AE9: =+Y9-AB9 -> 17318.158 | AF9: =+Z9-AC9 -> 16887.496 | AG9: =+AA9-AD9 -> 17214.03
B10: 김포 | G10: =+I10 -> 김포 | I10: 김포 | J10: =+IFERROR(HLOOKUP($B10,'[1]8월'!$D$6:$BN$259,2,),)/1000 -> 14 | K10: =+IFERROR(HLOOKUP($B10,'[2]8월'!$F$6:$CP$99,2,),)/1000 -> 9.95832 | L10: =+K10-J10 -> -4.04168 | M10: =+IFERROR(HLOOKUP($B10,'[3]8월'!$F$6:$CC$57,2,),)/1000 -> 10.517 | N10: =+K10-M10 -> -0.55868 | O10: =+IFERROR(HLOOKUP($B10,'[1]8월'!$D$6:$BN$259,3,),)/1000 -> 1318.9471 | P10: =+IFERROR(HLOOKUP($B10,'[2]8월'!$F$6:$CP$99,3,),)/1000 -> 958.97742 | Q10: =+P10-O10 -> -359.96972 | R10: =+IFERROR(HLOOKUP($B10,'[3]8월'!$F$6:$CC$57,3,),)/1000 -> 995.19129 | S10: =+P10-R10 -> -36.213876 | T10: =+IFERROR(HLOOKUP($B10,'[1]8월'!$D$6:$BN$259,16,),)/1000 -> 110.35007 | U10: =+IFERROR(HLOOKUP($B10,'[2]8월'!$F$6:$CP$99,16,),)/1000 -> 12.679732 | V10: =+U10-T10 -> -97.670334 | W10: =+IFERROR(HLOOKUP($B10,'[3]8월'!$F$6:$CC$57,16,),)/1000 -> 68.449578 | X10: =+U10-W10 -> -55.769846 | Y10: =+[4]김포!$Q$85 -> 94210.51 | Z10: =+[4]김포!$R$85 -> 96573.795 | AA10: =+[5]김포!$Q$85 -> 94621.354 | AB10: =+[4]김포!$Q$89 -> 74887.78 | AC10: =+[4]김포!$R$89 -> 77749.629 | AD10: =+[5]김포!$Q$89 -> 73782.182 | AE10: =+Y10-AB10 -> 19322.73 | AF10: =+Z10-AC10 -> 18824.165 | AG10: =+AA10-AD10 -> 20839.172
B11: 부산 | G11: =+I11 -> 부산 | I11: 부산 | J11: =+IFERROR(HLOOKUP($B11,'[1]8월'!$D$6:$BN$259,2,),)/1000 -> 17 | K11: =+IFERROR(HLOOKUP($B11,'[2]8월'!$F$6:$CP$99,2,),)/1000 -> 19.281 | L11: =+K11-J11 -> 2.281 | M11: =+IFERROR(HLOOKUP($B11,'[3]8월'!$F$6:$CC$57,2,),)/1000 -> 15.667 | N11: =+K11-M11 -> 3.614 | O11: =+IFERROR(HLOOKUP($B11,'[1]8월'!$D$6:$BN$259,3,),)/1000 -> 1830.9034 | P11: =+IFERROR(HLOOKUP($B11,'[2]8월'!$F$6:$CP$99,3,),)/1000 -> 2015.1315 | Q11: =+P11-O11 -> 184.22808 | R11: =+IFERROR(HLOOKUP($B11,'[3]8월'!$F$6:$CC$57,3,),)/1000 -> 1760.8091 | S11: =+P11-R11 -> 254.32245 | T11: =+IFERROR(HLOOKUP($B11,'[1]8월'!$D$6:$BN$259,16,),)/1000 -> 137.44552 | U11: =+IFERROR(HLOOKUP($B11,'[2]8월'!$F$6:$CP$99,16,),)/1000 -> 150.88101 | V11: =+U11-T11 -> 13.435496 | W11: =+IFERROR(HLOOKUP($B11,'[3]8월'!$F$6:$CC$57,16,),)/1000 -> 114.94156 | X11: =+U11-W11 -> 35.939457 | Y11: =+[4]부산!$Q$85 -> 107700.2 | Z11: =+[4]부산!$R$85 -> 104513.85 | AA11: =+[5]부산!$Q$85 -> 112389.68 | AB11: =+[4]부산!$Q$89 -> 84793.02 | AC11: =+[4]부산!$R$89 -> 83877.408 | AD11: =+[5]부산!$Q$89 -> 87284.553 | AE11: =+Y11-AB11 -> 22907.181 | AF11: =+Z11-AC11 -> 20636.44 | AG11: =+AA11-AD11 -> 25105.122
B12: 서부산 | G12: =+I12 -> 서부산 | I12: 서부산 | J12: =+IFERROR(HLOOKUP($B12,'[1]8월'!$D$6:$BN$259,2,),)/1000 -> 17 | K12: =+IFERROR(HLOOKUP($B12,'[2]8월'!$F$6:$CP$99,2,),)/1000 -> 16.329 | L12: =+K12-J12 -> -0.671 | M12: =+IFERROR(HLOOKUP($B12,'[3]8월'!$F$6:$CC$57,2,),)/1000 -> 17.863 | N12: =+K12-M12 -> -1.534 | O12: =+IFERROR(HLOOKUP($B12,'[1]8월'!$D$6:$BN$259,3,),)/1000 -> 1688.0974 | P12: =+IFERROR(HLOOKUP($B12,'[2]8월'!$F$6:$CP$99,3,),)/1000 -> 1606.0712 | Q12: =+P12-O12 -> -82.026238 | R12: =+IFERROR(HLOOKUP($B12,'[3]8월'!$F$6:$CC$57,3,),)/1000 -> 1785.4111 | S12: =+P12-R12 -> -179.33992 | T12: =+IFERROR(HLOOKUP($B12,'[1]8월'!$D$6:$BN$259,16,),)/1000 -> 152.69859 | U12: =+IFERROR(HLOOKUP($B12,'[2]8월'!$F$6:$CP$99,16,),)/1000 -> 122.94464 | V12: =+U12-T12 -> -29.753955 | W12: =+IFERROR(HLOOKUP($B12,'[3]8월'!$F$6:$CC$57,16,),)/1000 -> 186.73169 | X12: =+U12-W12 -> -63.787053 | Y12: =+[4]서부산!$Q$85 -> 99299.849 | Z12: =+[4]서부산!$R$85 -> 98356.985 | AA12: =+[5]서부산!$Q$85 -> 99969.049 | AB12: =+[4]서부산!$Q$89 -> 77452.15 | AC12: =+[4]서부산!$R$89 -> 77829.948 | AD12: =+[5]서부산!$Q$89 -> 78079.119 | AE12: =+Y12-AB12 -> 21847.699 | AF12: =+Z12-AC12 -> 20527.036 | AG12: =+AA12-AD12 -> 21889.93
B13: 김해 | G13: =+I13 -> 김해 | I13: 김해 | J13: =+IFERROR(HLOOKUP($B13,'[1]8월'!$D$6:$BN$259,2,),)/1000 -> 13 | K13: =+IFERROR(HLOOKUP($B13,'[2]8월'!$F$6:$CP$99,2,),)/1000 -> 7.188 | L13: =+K13-J13 -> -5.812 | M13: =+IFERROR(HLOOKUP($B13,'[3]8월'!$F$6:$CC$57,2,),)/1000 -> 16.833 | N13: =+K13-M13 -> -9.645 | O13: =+IFERROR(HLOOKUP($B13,'[1]8월'!$D$6:$BN$259,3,),)/1000 -> 1251.8957 | P13: =+IFERROR(HLOOKUP($B13,'[2]8월'!$F$6:$CP$99,3,),)/1000 -> 651.2647 | Q13: =+P13-O13 -> -600.63105 | R13: =+IFERROR(HLOOKUP($B13,'[3]8월'!$F$6:$CC$57,3,),)/1000 -> 1558.8082 | S13: =+P13-R13 -> -907.5435 | T13: =+IFERROR(HLOOKUP($B13,'[1]8월'!$D$6:$BN$259,16,),)/1000 -> 109.16349 | U13: =+IFERROR(HLOOKUP($B13,'[2]8월'!$F$6:$CP$99,16,),)/1000 -> -52.202861 | V13: =+U13-T13 -> -161.36635 | W13: =+IFERROR(HLOOKUP($B13,'[3]8월'!$F$6:$CC$57,16,),)/1000 -> 129.99266 | X13: =+U13-W13 -> -182.19552 | Y13: =+[4]김해!$Q$85 -> 96299.673 | Z13: =+[4]김해!$R$85 -> 90295.743 | AA13: =+[5]김해!$Q$85 -> 92674.742 | AB13: =+[4]김해!$Q$89 -> 76704.191 | AC13: =+[4]김해!$R$89 -> 78955.752 | AD13: =+[5]김해!$Q$89 -> 76470.439 | AE13: =+Y13-AB13 -> 19595.482 | AF13: =+Z13-AC13 -> 11339.99 | AG13: =+AA13-AD13 -> 16204.303
B14: 정관 | G14: =+I14 -> 정관 | I14: 정관 | J14: =+IFERROR(HLOOKUP($B14,'[1]8월'!$D$6:$BN$259,2,),)/1000 -> 18 | K14: =+IFERROR(HLOOKUP($B14,'[2]8월'!$F$6:$CP$99,2,),)/1000 -> 21.485 | L14: =+K14-J14 -> 3.485 | M14: =+IFERROR(HLOOKUP($B14,'[3]8월'!$F$6:$CC$57,2,),)/1000 -> 18.826 | N14: =+K14-M14 -> 2.659 | O14: =+IFERROR(HLOOKUP($B14,'[1]8월'!$D$6:$BN$259,3,),)/1000 -> 1836.0044 | P14: =+IFERROR(HLOOKUP($B14,'[2]8월'!$F$6:$CP$99,3,),)/1000 -> 2072.7013 | Q14: =+P14-O14 -> 236.69687 | R14: =+IFERROR(HLOOKUP($B14,'[3]8월'!$F$6:$CC$57,3,),)/1000 -> 1852.611 | S14: =+P14-R14 -> 220.09028 | T14: =+IFERROR(HLOOKUP($B14,'[1]8월'!$D$6:$BN$259,16,),)/1000 -> 152.64297 | U14: =+IFERROR(HLOOKUP($B14,'[2]8월'!$F$6:$CP$99,16,),)/1000 -> 156.95554 | V14: =+U14-T14 -> 4.3125657 | W14: =+IFERROR(HLOOKUP($B14,'[3]8월'!$F$6:$CC$57,16,),)/1000 -> 117.77506 | X14: =+U14-W14 -> 39.180482 | Y14: =+[4]정관!$Q$85 -> 102000.25 | Z14: =+[4]정관!$R$85 -> 96472.017 | AA14: =+[5]정관!$Q$85 -> 98407.043 | AB14: =+[4]정관!$Q$89 -> 82394.133 | AC14: =+[4]정관!$R$89 -> 79678.57 | AD14: =+[5]정관!$Q$89 -> 81011.244 | AE14: =+Y14-AB14 -> 19606.112 | AF14: =+Z14-AC14 -> 16793.446 | AG14: =+AA14-AD14 -> 17395.799
B15: 양산 | G15: =+I15 -> 양산 | I15: 양산 | J15: =+IFERROR(HLOOKUP($B15,'[1]8월'!$D$6:$BN$259,2,),)/1000 -> 12 | K15: =+IFERROR(HLOOKUP($B15,'[2]8월'!$F$6:$CP$99,2,),)/1000 -> 4.157 | L15: =+K15-J15 -> -7.843 | M15: =+IFERROR(HLOOKUP($B15,'[3]8월'!$F$6:$CC$57,2,),)/1000 -> 12.848 | N15: =+K15-M15 -> -8.691 | O15: =+IFERROR(HLOOKUP($B15,'[1]8월'!$D$6:$BN$259,3,),)/1000 -> 1132.56 | P15: =+IFERROR(HLOOKUP($B15,'[2]8월'!$F$6:$CP$99,3,),)/1000 -> 364.6814 | Q15: =+P15-O15 -> -767.8786 | R15: =+IFERROR(HLOOKUP($B15,'[3]8월'!$F$6:$CC$57,3,),)/1000 -> 1134.2644 | S15: =+P15-R15 -> -769.58301 | T15: =+IFERROR(HLOOKUP($B15,'[1]8월'!$D$6:$BN$259,16,),)/1000 -> 118.40443 | U15: =+IFERROR(HLOOKUP($B15,'[2]8월'!$F$6:$CP$99,16,),)/1000 -> -62.460978 | V15: =+U15-T15 -> -180.86541 | W15: =+IFERROR(HLOOKUP($B15,'[3]8월'!$F$6:$CC$57,16,),)/1000 -> 84.714054 | X15: =+U15-W15 -> -147.17503 | Y15: =+[4]양산!$Q$85 -> 94380 | Z15: =+[4]양산!$R$85 -> 87727.063 | AA15: =+[5]양산!$Q$85 -> 88283.344 | AB15: =+[4]양산!$Q$89 -> 73252.889 | AC15: =+[4]양산!$R$89 -> 71971.931 | AD15: =+[5]양산!$Q$89 -> 71277.489 | AE15: =+Y15-AB15 -> 21127.111 | AF15: =+Z15-AC15 -> 15755.132 | AG15: =+AA15-AD15 -> 17005.856
B16: 창원 | G16: =+I16 -> 창원 | I16: 창원 | J16: =+IFERROR(HLOOKUP($B16,'[1]8월'!$D$6:$BN$259,2,),)/1000 -> 13 | K16: =+IFERROR(HLOOKUP($B16,'[2]8월'!$F$6:$CP$99,2,),)/1000 -> 6.785 | L16: =+K16-J16 -> -6.215 | M16: =+IFERROR(HLOOKUP($B16,'[3]8월'!$F$6:$CC$57,2,),)/1000 -> 16.344 | N16: =+K16-M16 -> -9.559 | O16: =+IFERROR(HLOOKUP($B16,'[1]8월'!$D$6:$BN$259,3,),)/1000 -> 1314.3049 | P16: =+IFERROR(HLOOKUP($B16,'[2]8월'!$F$6:$CP$99,3,),)/1000 -> 631.819 | Q16: =+P16-O16 -> -682.48594 | R16: =+IFERROR(HLOOKUP($B16,'[3]8월'!$F$6:$CC$57,3,),)/1000 -> 1663.9588 | S16: =+P16-R16 -> -1032.1398 | T16: =+IFERROR(HLOOKUP($B16,'[1]8월'!$D$6:$BN$259,16,),)/1000 -> 147.81171 | U16: =+IFERROR(HLOOKUP($B16,'[2]8월'!$F$6:$CP$99,16,),)/1000 -> -12.880638 | V16: =+U16-T16 -> -160.69235 | W16: =+IFERROR(HLOOKUP($B16,'[3]8월'!$F$6:$CC$57,16,),)/1000 -> 252.53771 | X16: =+U16-W16 -> -265.41834 | Y16: =+[4]창원!$Q$85 -> 101100.38 | Z16: =+[4]창원!$R$85 -> 93119.971 | AA16: =+[5]창원!$Q$85 -> 101808.54 | AB16: =+[4]창원!$Q$89 -> 76060.57 | AC16: =+[4]창원!$R$89 -> 71110.435 | AD16: =+[5]창원!$Q$89 -> 75301.226 | AE16: =+Y16-AB16 -> 25039.81 | AF16: =+Z16-AC16 -> 22009.535 | AG16: =+AA16-AD16 -> 26507.315
B17: 대구 | G17: =+I17 -> 대구 | I17: 대구 | J17: =+IFERROR(HLOOKUP($B17,'[1]8월'!$D$6:$BN$259,2,),)/1000 -> 12.5 | K17: =+IFERROR(HLOOKUP($B17,'[2]8월'!$F$6:$CP$99,2,),)/1000 -> 9.987 | L17: =+K17-J17 -> -2.513 | M17: =+IFERROR(HLOOKUP($B17,'[3]8월'!$F$6:$CC$57,2,),)/1000 -> 14.6265 | N17: =+K17-M17 -> -4.6395 | O17: =+IFERROR(HLOOKUP($B17,'[1]8월'!$D$6:$BN$259,3,),)/1000 -> 1202.0064 | P17: =+IFERROR(HLOOKUP($B17,'[2]8월'!$F$6:$CP$99,3,),)/1000 -> 880.5514 | Q17: =+P17-O17 -> -321.45502 | R17: =+IFERROR(HLOOKUP($B17,'[3]8월'!$F$6:$CC$57,3,),)/1000 -> 1424.5083 | S17: =+P17-R17 -> -543.95685 | T17: =+IFERROR(HLOOKUP($B17,'[1]8월'!$D$6:$BN$259,16,),)/1000 -> 130.69121 | U17: =+IFERROR(HLOOKUP($B17,'[2]8월'!$F$6:$CP$99,16,),)/1000 -> 13.899454 | V17: =+U17-T17 -> -116.79175 | W17: =+IFERROR(HLOOKUP($B17,'[3]8월'!$F$6:$CC$57,16,),)/1000 -> 205.51536 | X17: =+U17-W17 -> -191.6159 | Y17: =+[4]대구!$Q$85 -> 96160.514 | Z17: =+[4]대구!$R$85 -> 88369.706 | AA17: =+[5]대구!$Q$85 -> 97392.285 | AB17: =+[4]대구!$Q$89 -> 72533.292 | AC17: =+[4]대구!$R$89 -> 73304.629 | AD17: =+[5]대구!$Q$89 -> 72111.381 | AE17: =+Y17-AB17 -> 23627.222 | AF17: =+Z17-AC17 -> 15065.078 | AG17: =+AA17-AD17 -> 25280.903
B18: 울산 | G18: =+I18 -> 울산 | I18: 울산 | J18: =+IFERROR(HLOOKUP($B18,'[1]8월'!$D$6:$BN$259,2,),)/1000 -> 12 | K18: =+IFERROR(HLOOKUP($B18,'[2]8월'!$F$6:$CP$99,2,),)/1000 -> 9.494 | L18: =+K18-J18 -> -2.506 | M18: =+IFERROR(HLOOKUP($B18,'[3]8월'!$F$6:$CC$57,2,),)/1000 -> 12.604 | N18: =+K18-M18 -> -3.11 | O18: =+IFERROR(HLOOKUP($B18,'[1]8월'!$D$6:$BN$259,3,),)/1000 -> 1243.554 | P18: =+IFERROR(HLOOKUP($B18,'[2]8월'!$F$6:$CP$99,3,),)/1000 -> 954.0589 | Q18: =+P18-O18 -> -289.4951 | R18: =+IFERROR(HLOOKUP($B18,'[3]8월'!$F$6:$CC$57,3,),)/1000 -> 1333.9425 | S18: =+P18-R18 -> -379.8836 | T18: =+IFERROR(HLOOKUP($B18,'[1]8월'!$D$6:$BN$259,16,),)/1000 -> 123.08733 | U18: =+IFERROR(HLOOKUP($B18,'[2]8월'!$F$6:$CP$99,16,),)/1000 -> 46.051256 | V18: =+U18-T18 -> -77.036078 | W18: =+IFERROR(HLOOKUP($B18,'[3]8월'!$F$6:$CC$57,16,),)/1000 -> 205.15454 | X18: =+U18-W18 -> -159.10329 | Y18: =+[4]울산!$Q$85 -> 103629.5 | Z18: =+[4]울산!$R$85 -> 100490.72 | AA18: =+[5]울산!$Q$85 -> 105834.85 | AB18: =+[4]울산!$Q$89 -> 81660.866 | AC18: =+[4]울산!$R$89 -> 79196.931 | AD18: =+[5]울산!$Q$89 -> 79625.721 | AE18: =+Y18-AB18 -> 21968.634 | AF18: =+Z18-AC18 -> 21293.789 | AG18: =+AA18-AD18 -> 26209.133
B19: 아산 | G19: =+I19 -> 아산 | I19: 아산 | J19: =+IFERROR(HLOOKUP($B19,'[1]8월'!$D$6:$BN$259,2,),)/1000 -> 21 | K19: =+IFERROR(HLOOKUP($B19,'[2]8월'!$F$6:$CP$99,2,),)/1000 -> 17.801 | L19: =+K19-J19 -> -3.199 | M19: =+IFERROR(HLOOKUP($B19,'[3]8월'!$F$6:$CC$57,2,),)/1000 -> 22.751 | N19: =+K19-M19 -> -4.95 | O19: =+IFERROR(HLOOKUP($B19,'[1]8월'!$D$6:$BN$259,3,),)/1000 -> 2163 | P19: =+IFERROR(HLOOKUP($B19,'[2]8월'!$F$6:$CP$99,3,),)/1000 -> 1653.6116 | Q19: =+P19-O19 -> -509.38844 | R19: =+IFERROR(HLOOKUP($B19,'[3]8월'!$F$6:$CC$57,3,),)/1000 -> 2254.9744 | S19: =+P19-R19 -> -601.36287 | T19: =+IFERROR(HLOOKUP($B19,'[1]8월'!$D$6:$BN$259,16,),)/1000 -> 300.4957 | U19: =+IFERROR(HLOOKUP($B19,'[2]8월'!$F$6:$CP$99,16,),)/1000 -> 29.798174 | V19: =+U19-T19 -> -270.69752 | W19: =+IFERROR(HLOOKUP($B19,'[3]8월'!$F$6:$CC$57,16,),)/1000 -> 395.17701 | X19: =+U19-W19 -> -365.37883 | Y19: =+[4]아산!$Q$85 -> 103000 | Z19: =+[4]아산!$R$85 -> 92894.307 | AA19: =+[5]아산!$Q$85 -> 99115.398 | AB19: =+[4]아산!$Q$89 -> 77356.346 | AC19: =+[4]아산!$R$89 -> 78155.016 | AD19: =+[5]아산!$Q$89 -> 71709.151 | AE19: =+Y19-AB19 -> 25643.654 | AF19: =+Z19-AC19 -> 14739.291 | AG19: =+AA19-AD19 -> 27406.248
B20: 전주 | G20: =+I20 -> 전주 | I20: 전주 | J20: =+IFERROR(HLOOKUP($B20,'[1]8월'!$D$6:$BN$259,2,),)/1000 -> 12 | K20: =+IFERROR(HLOOKUP($B20,'[2]8월'!$F$6:$CP$99,2,),)/1000 -> 7.624 | L20: =+K20-J20 -> -4.376 | M20: =+IFERROR(HLOOKUP($B20,'[3]8월'!$F$6:$CC$57,2,),)/1000 -> 9.38 | N20: =+K20-M20 -> -1.756 | O20: =+IFERROR(HLOOKUP($B20,'[1]8월'!$D$6:$BN$259,3,),)/1000 -> 1204.6085 | P20: =+IFERROR(HLOOKUP($B20,'[2]8월'!$F$6:$CP$99,3,),)/1000 -> 752.19068 | Q20: =+P20-O20 -> -452.4178 | R20: =+IFERROR(HLOOKUP($B20,'[3]8월'!$F$6:$CC$57,3,),)/1000 -> 904.97124 | S20: =+P20-R20 -> -152.78056 | T20: =+IFERROR(HLOOKUP($B20,'[1]8월'!$D$6:$BN$259,16,),)/1000 -> 183.67955 | U20: =+IFERROR(HLOOKUP($B20,'[2]8월'!$F$6:$CP$99,16,),)/1000 -> 23.432485 | V20: =+U20-T20 -> -160.24707 | W20: =+IFERROR(HLOOKUP($B20,'[3]8월'!$F$6:$CC$57,16,),)/1000 -> 82.209062 | X20: =+U20-W20 -> -58.776577 | Y20: =+[4]전주!$Q$85 -> 100384.04 | Z20: =+[4]전주!$R$85 -> 98660.897 | AA20: =+[5]전주!$Q$85 -> 96478.811 | AB20: =+[4]전주!$Q$89 -> 72688.918 | AC20: =+[4]전주!$R$89 -> 76029.922 | AD20: =+[5]전주!$Q$89 -> 73241.205 | AE20: =+Y20-AB20 -> 27695.122 | AF20: =+Z20-AC20 -> 22630.975 | AG20: =+AA20-AD20 -> 23237.606
B21: 군산 | G21: =+I21 -> 군산 | I21: 군산 | J21: =+IFERROR(HLOOKUP($B21,'[1]8월'!$D$6:$BN$259,2,),)/1000 -> 8 | K21: =+IFERROR(HLOOKUP($B21,'[2]8월'!$F$6:$CP$99,2,),)/1000 -> 4.411 | L21: =+K21-J21 -> -3.589 | M21: =+IFERROR(HLOOKUP($B21,'[3]8월'!$F$6:$CC$57,2,),)/1000 -> 7.4135 | N21: =+K21-M21 -> -3.0025 | O21: =+IFERROR(HLOOKUP($B21,'[1]8월'!$D$6:$BN$259,3,),)/1000 -> 891.2369 | P21: =+IFERROR(HLOOKUP($B21,'[2]8월'!$F$6:$CP$99,3,),)/1000 -> 484.80174 | Q21: =+P21-O21 -> -406.43516 | R21: =+IFERROR(HLOOKUP($B21,'[3]8월'!$F$6:$CC$57,3,),)/1000 -> 868.569 | S21: =+P21-R21 -> -383.76725 | T21: =+IFERROR(HLOOKUP($B21,'[1]8월'!$D$6:$BN$259,16,),)/1000 -> 233.40876 | U21: =+IFERROR(HLOOKUP($B21,'[2]8월'!$F$6:$CP$99,16,),)/1000 -> 89.004881 | V21: =+U21-T21 -> -144.40388 | W21: =+IFERROR(HLOOKUP($B21,'[3]8월'!$F$6:$CC$57,16,),)/1000 -> 250.95442 | X21: =+U21-W21 -> -161.94954 | Y21: =+[4]군산!$Q$85 -> 111404.61 | Z21: =+[4]군산!$R$85 -> 109907.45 | AA21: =+[5]군산!$Q$85 -> 117258.21 | AB21: =+[4]군산!$Q$89 -> 72426.235 | AC21: =+[4]군산!$R$89 -> 71466.256 | AD21: =+[5]군산!$Q$89 -> 73218.403 | AE21: =+Y21-AB21 -> 38978.377 | AF21: =+Z21-AC21 -> 38441.19 | AG21: =+AA21-AD21 -> 44039.807
B22: 원주 | G22: =+I22 -> 원주 | I22: 원주 | J22: =+IFERROR(HLOOKUP($B22,'[1]8월'!$D$6:$BN$259,2,),)/1000 -> 5 | K22: =+IFERROR(HLOOKUP($B22,'[2]8월'!$F$6:$CP$99,2,),)/1000 -> 2.075 | L22: =+K22-J22 -> -2.925 | M22: =+IFERROR(HLOOKUP($B22,'[3]8월'!$F$6:$CC$57,2,),)/1000 -> 5.818 | N22: =+K22-M22 -> -3.743 | O22: =+IFERROR(HLOOKUP($B22,'[1]8월'!$D$6:$BN$259,3,),)/1000 -> 560 | P22: =+IFERROR(HLOOKUP($B22,'[2]8월'!$F$6:$CP$99,3,),)/1000 -> 233.5253 | Q22: =+P22-O22 -> -326.4747 | R22: =+IFERROR(HLOOKUP($B22,'[3]8월'!$F$6:$CC$57,3,),)/1000 -> 651.9123 | S22: =+P22-R22 -> -418.387 | T22: =+IFERROR(HLOOKUP($B22,'[1]8월'!$D$6:$BN$259,16,),)/1000 -> 109.87534 | U22: =+IFERROR(HLOOKUP($B22,'[2]8월'!$F$6:$CP$99,16,),)/1000 -> 2.170287 | V22: =+U22-T22 -> -107.70505 | W22: =+IFERROR(HLOOKUP($B22,'[3]8월'!$F$6:$CC$57,16,),)/1000 -> 125.92494 | X22: =+U22-W22 -> -123.75465 | Y22: =+[4]원주!$Q$85 -> 112000 | Z22: =+[4]원주!$R$85 -> 112542.31 | AA22: =+[5]원주!$Q$85 -> 112050.93 | AB22: =+[4]원주!$Q$89 -> 73062.22 | AC22: =+[4]원주!$R$89 -> 70887.076 | AD22: =+[5]원주!$Q$89 -> 74748.331 | AE22: =+Y22-AB22 -> 38937.78 | AF22: =+Z22-AC22 -> 41655.238 | AG22: =+AA22-AD22 -> 37302.597
B23: 제주 | F23: =+K27-J27 -> -71.14268 | G23: =+I23 -> 제주 | I23: 제주 | J23: =+IFERROR(HLOOKUP($B23,'[1]8월'!$D$6:$BN$259,2,),)/1000 -> 9 | K23: =+IFERROR(HLOOKUP($B23,'[2]8월'!$F$6:$CP$99,2,),)/1000 -> 4.256 | L23: =+K23-J23 -> -4.744 | M23: =+IFERROR(HLOOKUP($B23,'[3]8월'!$F$6:$CC$57,2,),)/1000 -> 4.057 | N23: =+K23-M23 -> 0.199 | O23: =+IFERROR(HLOOKUP($B23,'[1]8월'!$D$6:$BN$259,3,),)/1000 -> 1106.96 | P23: =+IFERROR(HLOOKUP($B23,'[2]8월'!$F$6:$CP$99,3,),)/1000 -> 530.40713 | Q23: =+P23-O23 -> -576.55287 | R23: =+IFERROR(HLOOKUP($B23,'[3]8월'!$F$6:$CC$57,3,),)/1000 -> 491.4649 | S23: =+P23-R23 -> 38.942232 | T23: =+IFERROR(HLOOKUP($B23,'[1]8월'!$D$6:$BN$259,16,),)/1000 -> 192.65373 | U23: =+IFERROR(HLOOKUP($B23,'[2]8월'!$F$6:$CP$99,16,),)/1000 -> 30.210348 | V23: =+U23-T23 -> -162.44338 | W23: =+IFERROR(HLOOKUP($B23,'[3]8월'!$F$6:$CC$57,16,),)/1000 -> 43.627251 | X23: =+U23-W23 -> -13.416903 | Y23: =+[4]제주!$Q$85 -> 122995.56 | Z23: =+[4]제주!$R$85 -> 124625.74 | AA23: =+[5]제주!$Q$85 -> 121139.98 | AB23: =+[4]제주!$Q$89 -> 91386.196 | AC23: =+[4]제주!$R$89 -> 96286.686 | AD23: =+[5]제주!$Q$89 -> 88295.429 | AE23: =+Y23-AB23 -> 31609.36 | AF23: =+Z23-AC23 -> 28339.05 | AG23: =+AA23-AD23 -> 32844.551
F24: =+K24/J24 -> 0.68121882 | G24: =+I24 -> 수도권 | I24: 수도권 | J24: =SUM(J7:J10) -> 102 | K24: =SUM(K7:K10) -> 69.48432 | L24: =+K24-J24 -> -32.51568 | M24: =SUM(M7:M10) -> 82.492 | N24: =+K24-M24 -> -13.00768 | O24: =SUM(O7:O10) -> 10098.604 | P24: =SUM(P7:P10) -> 6619.912 | Q24: =+P24-O24 -> -3478.6915 | R24: =SUM(R7:R10) -> 8110.6363 | S24: =+P24-R24 -> -1490.7243 | T24: =SUM(T7:T10) -> 942.33189 | U24: =SUM(U7:U10) -> 42.665041 | V24: =+U24-T24 -> -899.66685 | W24: =SUM(W7:W10) -> 557.01498 | X24: =+U24-W24 -> -514.34994 | Y24: =+[4]수도권!$Q$85 -> 99005.917 | Z24: =+[4]수도권!$R$85 -> 95390.139 | AA24: =+[5]수도권!$Q$85 -> 98331.463 | AB24: =+[4]수도권!$Q$89 -> 80391.248 | AC24: =+[4]수도권!$R$89 -> 80377.6 | AD24: =+[5]수도권!$Q$89 -> 80418.079 | AE24: =+Y24-AB24 -> 18614.67 | AF24: =+Z24-AC24 -> 15012.539 | AG24: =+AA24-AD24 -> 17913.385
F25: =+K25/J25 -> 0.82712664 | G25: =+I25 -> 영남권 | I25: 영남권 | J25: =SUM(J11:J18) -> 114.5 | K25: =SUM(K11:K18) -> 94.706 | L25: =+K25-J25 -> -19.794 | M25: =SUM(M11:M18) -> 125.6115 | N25: =+K25-M25 -> -30.9055 | O25: =SUM(O11:O18) -> 11499.326 | P25: =SUM(P11:P18) -> 9176.2794 | Q25: =+P25-O25 -> -2323.047 | R25: =SUM(R11:R18) -> 12514.313 | S25: =+P25-R25 -> -3338.034 | T25: =SUM(T11:T18) -> 1071.9453 | U25: =SUM(U11:U18) -> 363.18743 | V25: =+U25-T25 -> -708.75784 | W25: =SUM(W11:W18) -> 1297.3626 | X25: =+U25-W25 -> -934.1752 | Y25: =+[4]영남권!$Q$85 -> 100430.8 | Z25: =+[4]영남권!$R$85 -> 96920.994 | AA25: =+[5]영남권!$Q$85 -> 99644.239 | AB25: =+[4]영남권!$Q$89 -> 78540.047 | AC25: =+[4]영남권!$R$89 -> 78499.233 | AD25: =+[5]영남권!$Q$89 -> 77859.428 | AE25: =+Y25-AB25 -> 21890.751 | AF25: =+Z25-AC25 -> 18421.761 | AG25: =+AA25-AD25 -> 21784.811
F26: =+K26/J26 -> 0.65758182 | G26: =+I26 -> 중부권 | I26: 중부권 | J26: =SUM(J19:J23) -> 55 | K26: =SUM(K19:K23) -> 36.167 | L26: =+K26-J26 -> -18.833 | M26: =SUM(M19:M23) -> 49.4195 | N26: =+K26-M26 -> -13.2525 | O26: =SUM(O19:O23) -> 5925.8054 | P26: =SUM(P19:P23) -> 3654.5364 | Q26: =+P26-O26 -> -2271.269 | R26: =SUM(R19:R23) -> 5171.8919 | S26: =+P26-R26 -> -1517.3555 | T26: =SUM(T19:T23) -> 1020.1131 | U26: =SUM(U19:U23) -> 174.61617 | V26: =+U26-T26 -> -845.4969 | W26: =SUM(W19:W23) -> 897.89268 | X26: =+U26-W26 -> -723.27651 | Y26: =+[4]중부권!$Q$85 -> 107741.92 | Z26: =+[4]중부권!$R$85 -> 101046.16 | AA26: =+[5]중부권!$Q$85 -> 104659.87 | AB26: =+[4]중부권!$Q$89 -> 77526.31 | AC26: =+[4]중부권!$R$89 -> 78607.809 | AD26: =+[5]중부권!$Q$89 -> 73943.591 | AE26: =+Y26-AB26 -> 30215.606 | AF26: =+Z26-AC26 -> 22438.35 | AG26: =+AA26-AD26 -> 30716.283
F27: =+K27/M27 -> 0.77801719 | G27: =+K27/J27 -> 0.73796435 | H27: 레미콘 계 | J27: =SUM(J24:J26) -> 271.5 | K27: =SUM(K24:K26) -> 200.35732 | L27: =+K27-J27 -> -71.14268 | M27: =SUM(M24:M26) -> 257.523 | N27: =+K27-M27 -> -57.16568 | O27: =SUM(O24:O26) -> 27523.735 | P27: =SUM(P24:P26) -> 19450.728 | Q27: =+P27-O27 -> -8073.0075 | R27: =SUM(R24:R26) -> 25796.841 | S27: =+P27-R27 -> -6346.1137 | T27: =SUM(T24:T26) -> 3034.3902 | U27: =SUM(U24:U26) -> 580.46864 | V27: =+U27-T27 -> -2453.9216 | W27: =SUM(W24:W26) -> 2752.2703 | X27: =+U27-W27 -> -2171.8017 | Y27: =+[4]합계!$Q$85 -> 101376.56 | Z27: =+[4]합계!$R$85 -> 97142.344 | AA27: =+[5]합계!$Q$85 -> 100188.2 | AB27: =+[4]합계!$Q$89 -> 79030.165 | AC27: =+[4]합계!$R$89 -> 79165.193 | AD27: =+[5]합계!$Q$89 -> 77923.898 | AE27: =+Y27-AB27 -> 22346.393 | AF27: =+Z27-AC27 -> 17977.151 | AG27: =+AA27-AD27 -> 22264.3 | AI27: =+AF27-AE27 -> -4369.242 | AJ27: =+AF27-AG27 -> -4287.1496
B28: 건자재 | E28: 건자재영업 | G28: 건자재 | H28: 건자재 | J28: =+IFERROR(HLOOKUP($B28,'[1]8월'!$D$6:$BN$259,2,),) -> 12600 | K28: =+IFERROR(HLOOKUP($E28,'[2]8월'!$F$6:$CP$99,2,),) -> 6814.749 | L28: =+K28-J28 -> -5785.251 | M28: =+IFERROR(HLOOKUP($E28,'[3]8월'!$F$6:$CC$57,2,),) -> 9545.758 | N28: =+K28-M28 -> -2731.009 | O28: =+IFERROR(HLOOKUP($B28,'[1]8월'!$D$6:$BN$259,3,),)/1000 -> 13712.919 | P28: =+IFERROR(HLOOKUP($E28,'[2]8월'!$F$6:$CP$99,3,),)/1000 -> 6411.0741 | Q28: =+P28-O28 -> -7301.8448 | R28: =+IFERROR(HLOOKUP($E28,'[3]8월'!$F$6:$CC$57,3,),)/1000 -> 9493.1785 | S28: =+P28-R28 -> -3082.1043 | T28: =+IFERROR(HLOOKUP($B28,'[1]8월'!$D$6:$BN$259,16,),)/1000 -> 247.89226 | U28: =+IFERROR(HLOOKUP($E28,'[2]8월'!$F$6:$CP$99,16,),)/1000 -> 18.161034 | V28: =+U28-T28 -> -229.73123 | W28: =+IFERROR(HLOOKUP($E28,'[3]8월'!$F$6:$CC$57,16,),)/1000 -> 79.524753 | X28: =+U28-W28 -> -61.363719 | Y28: ■ 비고
