Workbook

Sheet 파워BI용
B2: 구분 | D2: 계획 | E2: 실적 | F2: 차이 | G2: 전년 | H2: 차이 | J2: 캡쳐도구 사용 → PNG 저장 → 파워BI 삽입 → 이미지
B3: 판매량 | C3: 레미콘 | D3: =+'사업장별(누계)_건자재제외'!$J$27 -> 3025 | E3: =+'사업장별(누계)_건자재제외'!$K$27 -> 2577.7873 | F3: =+E3/D3 -> 0.8521611 | G3: =+'사업장별(누계)_건자재제외'!$M$27 -> 3105.939 | H3: =+E3/G3 -> 0.82995427
C4: 골재 | D4: =+'사업장별(누계)_건자재제외'!$J$31 -> 1085.452 | E4: =+'사업장별(누계)_건자재제외'!$K$31 -> 719.006 | F4: =+E4/D4 -> 0.66240237 | G4: =+'사업장별(누계)_건자재제외'!$M$31 -> 780.431 | H4: =+E4/G4 -> 0.92129349
B5: 매출액 | C5: 레미콘 | D5: =+'사업장별(누계)_건자재제외'!$O$27 -> 305492.88 | E5: =+'사업장별(누계)_건자재제외'!$P$27 -> 253858.57 | F5: =+E5-D5 -> -51634.319 | G5: =+'사업장별(누계)_건자재제외'!$R$27 -> 312392.53 | H5: =+E5-G5 -> -58533.964
C6: 골재 | D6: =+'사업장별(누계)_건자재제외'!$O$31 -> 19974.039 | E6: =+'사업장별(누계)_건자재제외'!$P$31 -> 14723.488 | F6: =+E6-D6 -> -5250.5513 | G6: =+'사업장별(누계)'!$R$32 -> 15789.63 | H6: =+E6-G6 -> -1066.1421
C7: 기타 | D7: =+D8-D5-D6 -> 1642.0298 | E7: =+E8-E5-E6 -> 1424.043 | F7: =+E7-D7 -> -217.98679 | G7: =+G8-G5-G6 -> 1821.6955 | H7: =+E7-G7 -> -397.65249
C8: 계 | D8: =+'사업장별(누계)_건자재제외'!$O$42 -> 327108.95 | E8: =+'사업장별(누계)_건자재제외'!$P$42 -> 270006.1 | F8: =+E8-D8 -> -57102.857 | G8: =+'사업장별(누계)_건자재제외'!$R$42 -> 330003.85 | H8: =+E8-G8 -> -59997.759
B9: 영업이익 | C9: 레미콘 | D9: =+('사업장별(누계)_건자재제외'!$T$27+'사업장별(누계)_건자재제외'!$T$34) -> 12736.117 | E9: =+'사업장별(누계)_건자재제외'!$U$27+'사업장별(누계)_건자재제외'!$U$34 -> -4251.4595 | F9: =+E9-D9 -> -16987.577 | G9: =+'사업장별(누계)_건자재제외'!$W$27+'사업장별(누계)_건자재제외'!$W$34 -> 17115.212 | H9: =+E9-G9 -> -21366.671
C10: (%) | D10: =+D9/D5 -> 0.04169039 | E10: =+E9/E5 -> -0.016747355 | F10: =+E10-D10 -> -0.058437745 | G10: =+G9/G5 -> 0.05478752 | H10: =+E10-G10 -> -0.071534875
C11: 골재 | D11: =+'사업장별(누계)_건자재제외'!$T$31 -> 2024.1749 | E11: =+'사업장별(누계)_건자재제외'!$U$31 -> -1005.8875 | F11: =+E11-D11 -> -3030.0624 | G11: =+'사업장별(누계)_건자재제외'!$W$31 -> -294.10414 | H11: =+E11-G11 -> -711.7834
C12: 기타 | D12: =+D13-D9-D11 -> 215.27812 | E12: =+E13-E9-E11 -> -449.93439 | F12: =+E12-D12 -> -665.21251 | G12: =+G13-G9-G11 -> 1200.9937 | H12: =+E12-G12 -> -1650.9281
C13: 계 | D13: =+'사업장별(누계)_건자재제외'!$T$42 -> 14975.57 | E13: =+'사업장별(누계)_건자재제외'!$U$42 -> -5707.2814 | F13: =+E13-D13 -> -20682.852 | G13: =+'사업장별(누계)_건자재제외'!$W$42 -> 18022.101 | H13: =+E13-G13 -> -23729.383
D14: =+D13/D8 -> 0.045781598 | E14: =+E13/E8 -> -0.021137602 | F14: =+E14-D14 -> -0.0669192 | G14: =+G13/G8 -> 0.054611791 | H14: =+E14-G14 -> -0.075749393

Sheet 표지
A6: 2025년 11월 마감 손익
A24: 건재사업본부

Sheet 손익총괄
C3: □ 건재사업본부 손익실적(2025-11)
X4: [단위 : 천㎥, 톤, 원/㎥, 원/톤, 백만원]
C5: 구분 | E5: 11월 | J5: 11월 누계 | P5: 11월 주요지표
E6: 계획 | F6: 실적 | G6: 계획대비 | H6: 전년 | I6: 전년대비 | J6: 계획 | K6: 실적 | L6: 계획대비 | M6: 전년 | N6: 전년대비
C7: 물량 | D7: 레미콘 | E7: =+'[1]11월'!$Z$7/1000 -> 310.5 | F7: =+'[2]11월'!$Z$7/1000 -> 259.0905 | G7: =+F7-E7 -> -51.4095 | H7: =+'[3]11월'!$Z$7/1000 -> 280.6685 | I7: =+F7-H7 -> -21.578 | J7: =+'[1]11월누계'!$Z$7/1000 -> 3025 | K7: =+'[2]11월누계'!$Z$7/1000 -> 2577.7873 | L7: =+K7-J7 -> -447.21268 | M7: =+'[3]11월누계'!$Z$7/1000 -> 3105.939 | N7: =+K7-M7 -> -528.15168 | Q7: □ 레미콘
D8: 철강재 | E8: =+'[1]11월'!$AA$7 -> 12600 | F8: =+'[2]11월'!$AO$7 -> 9321.418 | G8: =+F8-E8 -> -3278.582 | H8: =+'[3]11월'!$AO$7 -> 10221.802 | I8: =+F8-H8 -> -900.384 | J8: =+'[1]11월누계'!$AA$7 -> 124500 | K8: =+'[2]11월누계'!$AO$7 -> 100870.89 | L8: =+K8-J8 -> -23629.108 | M8: =+'[3]11월누계'!$AO$7 -> 97161.154 | N8: =+K8-M8 -> 3709.738 | Q8: 구분 | S8: 계획 | T8: 실적 | U8: 계획대비 | V8: 전년 | W8: 전년대비
D9: 골재 | E9: =+'[1]11월'!$AE$7/1000 -> 113.98827 | F9: =+'[2]11월'!$AN$7/1000 -> 68.974 | G9: =+F9-E9 -> -45.014273 | H9: =+'[3]11월'!$AN$7/1000 -> 66.126 | I9: =+F9-H9 -> 2.848 | J9: =+'[1]11월누계'!$AE$7/1000 -> 1085.452 | K9: =+'[2]11월누계'!$AN$7/1000 -> 719.006 | L9: =+K9-J9 -> -366.44604 | M9: =+'[3]11월누계'!$AN$7/1000 -> 780.431 | N9: =+K9-M9 -> -61.425 | Q9: 물량 | R9: 수도권 | S9: =+[4]수도권!$T$5/1000 -> 112 | T9: =+[4]수도권!$U$5/1000 -> 92.7095 | U9: =+T9-S9 -> -19.2905 | V9: =+[5]수도권!$T$5/1000 -> 107.646 | W9: =+T9-V9 -> -14.9365
C10: 매출 | D10: 레미콘 | E10: =+'[1]11월'!$Z$8/1000 -> 31674.938 | F10: =+'[2]11월'!$Z$8/1000 -> 25856.152 | G10: =+F10-E10 -> -5818.7863 | H10: =+'[3]11월'!$Z$8/1000 -> 28069.669 | I10: =+F10-H10 -> -2213.5171 | J10: =+'[1]11월누계'!$Z$8/1000 -> 305492.88 | K10: =+'[2]11월누계'!$Z$8/1000 -> 253858.57 | L10: =+K10-J10 -> -51634.319 | M10: =+'[3]11월누계'!$Z$8/1000 -> 312392.53 | N10: =+K10-M10 -> -58533.964 | R10: 영남권 | S10: =+[4]영남권!$T$5/1000 -> 138 | T10: =+[4]영남권!$U$5/1000 -> 114.7065 | U10: =+T10-S10 -> -23.2935 | V10: =+[5]영남권!$T$5/1000 -> 121.551 | W10: =+T10-V10 -> -6.8445
D11: 건자재 | E11: =+'[1]11월'!$AA$8/1000 -> 13712.919 | F11: =+'[2]11월'!$AO$8/1000 -> 8458.8501 | G11: =+F11-E11 -> -5254.0687 | H11: =+'[3]11월'!$AO$8/1000 -> 9942.869 | I11: =+F11-H11 -> -1484.0189 | J11: =+'[1]11월누계'!$AA$8/1000 -> 135896.4 | K11: =+'[2]11월누계'!$AO$8/1000 -> 92280.217 | L11: =+K11-J11 -> -43616.18 | M11: =+'[3]11월누계'!$AO$8/1000 -> 96553.945 | N11: =+K11-M11 -> -4273.7287 | R11: 중부권 | S11: =+[4]중부권!$T$5/1000 -> 60.5 | T11: =+[4]중부권!$U$5/1000 -> 51.6745 | U11: =+T11-S11 -> -8.8255 | V11: =+[5]중부권!$T$5/1000 -> 51.4715 | W11: =+T11-V11 -> 0.203
D12: 골재 | E12: =+'[1]11월'!$AE$8/1000 -> 2080.8241 | F12: =+'[2]11월'!$AN$8/1000 -> 1385.2927 | G12: =+F12-E12 -> -695.53142 | H12: =+'[3]11월'!$AN$8/1000 -> 1414.0255 | I12: =+F12-H12 -> -28.7328 | J12: =+'[1]11월누계'!$AE$8/1000 -> 19974.039 | K12: =+'[2]11월누계'!$AN$8/1000 -> 14723.488 | L12: =+K12-J12 -> -5250.5513 | M12: =+'[3]11월누계'!$AN$8/1000 -> 15789.63 | N12: =+K12-M12 -> -1066.1421 | Q12: 계 | S12: =SUM(S9:S11) -> 310.5 | T12: =SUM(T9:T11) -> 259.0905 | U12: =+T12-S12 -> -51.4095 | V12: =SUM(V9:V11) -> 280.6685 | W12: =+T12-V12 -> -21.578
D13: 기타 | E13: =+'[1]11월'!$E$8/1000-E10-E11-E12 -> 142.52817 | F13: =+'[2]11월'!$F$8/1000-F10-F11-F12 -> 118.87862 | G13: =+F13-E13 -> -23.649543 | H13: =+'[3]11월'!$F$8/1000-H10-H11-H12 -> 165.32457 | I13: =+F13-H13 -> -46.445944 | J13: =+'[1]11월누계'!$E$8/1000-J10-J11-J12 -> 1642.0298 | K13: =+'[2]11월누계'!$F$8/1000-K10-K11-K12 -> 1424.043 | L13: =+K13-J13 -> -217.98679 | M13: =+'[3]11월누계'!$F$8/1000-M10-M11-M12 -> 1821.6955 | N13: =+K13-M13 -> -397.65249 | Q13: 판매단가 | R13: 수도권 | S13: =+[4]수도권!$T$61 -> 100966.5 | T13: =+[4]수도권!$U$61 -> 96297.03 | U13: =+T13-S13 -> -4669.4658 | V13: =+[5]수도권!$Q$85 -> 97363.141 | W13: =+T13-V13 -> -1066.1113
C14: 계 | E14: =SUM(E10:E13) -> 47611.21 | F14: =SUM(F10:F13) -> 35819.174 | G14: =+F14-E14 -> -11792.036 | H14: =SUM(H10:H13) -> 39591.888 | I14: =+F14-H14 -> -3772.7147 | J14: =SUM(J10:J13) -> 463005.35 | K14: =SUM(K10:K13) -> 362286.31 | L14: =+K14-J14 -> -100719.04 | M14: =SUM(M10:M13) -> 426557.8 | N14: =+K14-M14 -> -64271.487 | R14: 영남권 | S14: =+[4]영남권!$T$61 -> 100479.54 | T14: =+[4]영남권!$U$61 -> 100200.79 | U14: =+T14-S14 -> -278.74975 | V14: =+[5]영남권!$Q$85 -> 100718.16 | W14: =+T14-V14 -> -517.36985
C15: 매출원가 | D15: 레미콘 | E15: =+('[1]11월'!$Z$10+'[1]11월'!$Z$19)/1000 -> 27214.256 | F15: =+('[2]11월'!$Z$10+'[2]11월'!$Z$19)/1000 -> 23785.614 | G15: =+F15-E15 -> -3428.6421 | H15: =+('[3]11월'!$Z$10+'[3]11월'!$Z$19)/1000 -> 25171.805 | I15: =+F15-H15 -> -1386.1907 | J15: =+('[1]11월누계'!$Z$10+'[1]11월누계'!$Z$19)/1000 -> 268751.54 | K15: =+('[2]11월누계'!$Z$10+'[2]11월누계'!$Z$19)/1000 -> 233693.1 | L15: =+K15-J15 -> -35058.436 | M15: =+('[3]11월누계'!$Z$10+'[3]11월누계'!$Z$19)/1000 -> 272340.29 | N15: =+K15-M15 -> -38647.185 | R15: 중부권 | S15: =+[4]중부권!$T$61 -> 107446.52 | T15: =+[4]중부권!$U$61 -> 105331.24 | U15: =+T15-S15 -> -2115.2813 | V15: =+[5]중부권!$Q$85 -> 103847.09 | W15: =+T15-V15 -> 1484.1533
D16: 건자재 | E16: =+('[1]11월'!$AA$10+'[1]11월'!$AA$19)/1000 -> 13342.736 | F16: =+('[2]11월'!$AO$10+'[2]11월'!$AO$19)/1000 -> 8288.3784 | G16: =+F16-E16 -> -5054.3579 | H16: =+('[3]11월'!$AO$10+'[3]11월'!$AO$19)/1000 -> 9692.7755 | I16: =+F16-H16 -> -1404.3971 | J16: =+('[1]11월누계'!$AA$10+'[1]11월누계'!$AA$19)/1000 -> 132227.72 | K16: =+('[2]11월누계'!$AO$10+'[2]11월누계'!$AO$19)/1000 -> 90673.09 | L16: =+K16-J16 -> -41554.635 | M16: =+('[3]11월누계'!$AO$10+'[3]11월누계'!$AO$19)/1000 -> 94392.929 | N16: =+K16-M16 -> -3719.8392 | Q16: 계 | S16: =+[4]합계!$T$61 -> 102012.68 | T16: =+[4]합계!$U$61 -> 99838.666 | U16: =+T16-S16 -> -2174.0175 | V16: =+[5]합계!$Q$85 -> 100000.5 | W16: =+T16-V16 -> -161.83157
D17: 골재 | E17: =+('[1]11월'!$AE$10+'[1]11월'!$AE$19)/1000 -> 1734.0287 | F17: =+('[2]11월'!$AN$10+'[2]11월'!$AN$19)/1000 -> 1516.4555 | G17: =+F17-E17 -> -217.57316 | H17: =+('[3]11월'!$AN$10+'[3]11월'!$AN$19)/1000 -> 1633.277 | I17: =+F17-H17 -> -116.82141 | J17: =+('[1]11월누계'!$AE$10+'[1]11월누계'!$AE$19)/1000 -> 17421.107 | K17: =+('[2]11월누계'!$AN$10+'[2]11월누계'!$AN$19)/1000 -> 15197.668 | L17: =+K17-J17 -> -2223.4387 | M17: =+('[3]11월누계'!$AN$10+'[3]11월누계'!$AN$19)/1000 -> 15409.91 | N17: =+K17-M17 -> -212.24157 | Q17: 공헌이익 | R17: 수도권 | S17: =+[4]수도권!$Q$90 -> 19349.831 | T17: =+[4]수도권!$R$90 -> 13250.906 | U17: =+T17-S17 -> -6098.925 | V17: =+[5]수도권!$Q$90 -> 14160.07 | W17: =+T17-V17 -> -909.16442
D18: 기타 | E18: =+('[1]11월'!$E$10+'[1]11월'!$E$19)/1000-E15-E16-E17 -> 68.375599 | F18: =+('[2]11월'!$F$10+'[2]11월'!$F$19)/1000-F15-F16-F17 -> -378.92085 | G18: =+F18-E18 -> -447.29644 | H18: =+('[3]11월'!$F$10+'[3]11월'!$F$19)/1000-H15-H16-H17 -> -208.79434 | I18: =+F18-H18 -> -170.1265 | J18: =+('[1]11월누계'!$E$10+'[1]11월누계'!$E$19)/1000-J15-J16-J17 -> 677.99936 | K18: =+('[2]11월누계'!$F$10+'[2]11월누계'!$F$19)/1000-K15-K16-K17 -> -397.43886 | L18: =+K18-J18 -> -1075.4382 | M18: =+('[3]11월누계'!$F$10+'[3]11월누계'!$F$19)/1000-M15-M16-M17 -> -538.6119 | N18: =+K18-M18 -> 141.17304 | R18: 영남권 | S18: =+[4]영남권!$Q$90 -> 21091.445 | T18: =+[4]영남권!$R$90 -> 18098.237 | U18: =+T18-S18 -> -2993.208 | V18: =+[5]영남권!$Q$90 -> 21227.896 | W18: =+T18-V18 -> -3129.6589
C19: 계 | E19: =SUM(E15:E18) -> 42359.397 | F19: =SUM(F15:F18) -> 33211.527 | G19: =+F19-E19 -> -9147.8696 | H19: =SUM(H15:H18) -> 36289.063 | I19: =+F19-H19 -> -3077.5356 | J19: =SUM(J15:J18) -> 419078.37 | K19: =SUM(K15:K18) -> 339166.42 | L19: =+K19-J19 -> -79911.948 | M19: =SUM(M15:M18) -> 381604.51 | N19: =+K19-M19 -> -42438.093 | R19: 중부권 | S19: =+[4]중부권!$Q$90 -> 29091.365 | T19: =+[4]중부권!$R$90 -> 23719.354 | U19: =+T19-S19 -> -5372.0106 | V19: =+[5]중부권!$Q$90 -> 23600.464 | W19: =+T19-V19 -> 118.89012
C20: 매출이익 | D20: 레미콘 | E20: =+E10-E15 -> 4460.6819 | F20: =+F10-F15 -> 2070.5377 | G20: =+F20-E20 -> -2390.1442 | H20: =+H10-H15 -> 2897.8641 | I20: =+F20-H20 -> -827.32641 | J20: =+J10-J15 -> 36741.347 | K20: =+K10-K15 -> 20165.464 | L20: =+K20-J20 -> -16575.883 | M20: =+M10-M15 -> 40052.242 | N20: =+K20-M20 -> -19886.779 | Q20: 계 | S20: =+[4]합계!$Q$90 -> 22021.99 | T20: =+[4]합계!$R$90 -> 17498.384 | U20: =+T20-S20 -> -4523.6063 | V20: =+[5]합계!$Q$90 -> 18957.932 | W20: =+T20-V20 -> -1459.5482
D21: 건자재 | E21: =+E11-E16 -> 370.18261 | F21: =+F11-F16 -> 170.47174 | G21: =+F21-E21 -> -199.71087 | H21: =+H11-H16 -> 250.09354 | I21: =+F21-H21 -> -79.621802 | J21: =+J11-J16 -> 3668.6714 | K21: =+K11-K16 -> 1607.1268 | L21: =+K21-J21 -> -2061.5447 | M21: =+M11-M16 -> 2161.0162 | N21: =+K21-M21 -> -553.88947 | Q21: □ 건자재
D22: 골재 | E22: =+E12-E17 -> 346.79542 | F22: =+F12-F17 -> -131.16285 | G22: =+F22-E22 -> -477.95826 | H22: =+H12-H17 -> -219.25146 | I22: =+F22-H22 -> 88.08861 | J22: =+J12-J17 -> 2552.9318 | K22: =+K12-K17 -> -474.18078 | L22: =+K22-J22 -> -3027.1126 | M22: =+M12-M17 -> 379.71974 | N22: =+K22-M22 -> -853.90051 | Q22: 구분 | S22: 계획 | T22: 실적 | U22: 계획대비 | V22: 전년 | W22: 전년대비
D23: 기타 | E23: =+E13-E18 -> 74.152568 | F23: =+F13-F18 -> 497.79947 | G23: =+F23-E23 -> 423.6469 | H23: =+H13-H18 -> 374.11891 | I23: =+F23-H23 -> 123.68056 | J23: =+J13-J18 -> 964.03047 | K23: =+K13-K18 -> 1821.4819 | L23: =+K23-J23 -> 857.45143 | M23: =+M13-M18 -> 2360.3074 | N23: =+K23-M23 -> -538.82552 | Q23: 철강재 판매단가 | S23: =+'[6]11월'!$F$10 -> 873809.52 | T23: =+'[6]11월'!$G$10 -> 746100.56 | U23: =+T23-S23 -> -127708.96 | V23: =+'[7]11월'!$G$10 -> 798803.69 | W23: =+T23-V23 -> -52703.129
C24: 계 | E24: =SUM(E20:E23) -> 5251.8125 | F24: =SUM(F20:F23) -> 2607.6461 | G24: =+F24-E24 -> -2644.1664 | H24: =SUM(H20:H23) -> 3302.8251 | I24: =+F24-H24 -> -695.17904 | J24: =SUM(J20:J23) -> 43926.981 | K24: =SUM(K20:K23) -> 23119.892 | L24: =+K24-J24 -> -20807.089 | M24: =SUM(M20:M23) -> 44953.286 | N24: =+K24-M24 -> -21833.394 | Q24: 철강재 마진률 | S24: =+'[6]11월'!$F$15 -> 0.024058583 | T24: =+'[6]11월'!$G$15 -> 0.017646524 | U24: =+T24-S24 -> -0.0064120592 | V24: =+'[6]11월'!$G$15 -> 0.017646524 | W24: =+T24-V24 -> 0
C25: 판관비 | D25: 레미콘 | E25: =+('[1]11월'!$Z$13+'[1]11월'!$Z$20)/1000 -> 651.01474 | F25: =+('[2]11월'!$Z$13+'[2]11월'!$Z$20)/1000 -> 696.21834 | G25: =+F25-E25 -> 45.203599 | H25: =+('[3]11월'!$Z$13+'[3]11월'!$Z$20)/1000 -> 701.94071 | I25: =+F25-H25 -> -5.722366 | J25: =+('[1]11월누계'!$Z$13+'[1]11월누계'!$Z$20)/1000 -> 7401.3032 | K25: =+('[2]11월누계'!$Z$13+'[2]11월누계'!$Z$20)/1000 -> 7598.8117 | L25: =+K25-J25 -> 197.50847 | M25: =+('[3]11월누계'!$Z$13+'[3]11월누계'!$Z$20)/1000 -> 7583.1822 | N25: =+K25-M25 -> 15.629427 | Q25: □ 골재
D26: 건자재 | E26: =+('[1]11월'!$AA$13+'[1]11월'!$AA$20)/1000 -> 122.29035 | F26: =+('[2]11월'!$AO$13+'[2]11월'!$AO$20)/1000 -> 147.48019 | G26: =+F26-E26 -> 25.189844 | H26: =+('[3]11월'!$AO$13+'[3]11월'!$AO$20)/1000 -> 131.73689 | I26: =+F26-H26 -> 15.743301 | J26: =+('[1]11월누계'!$AA$13+'[1]11월누계'!$AA$20)/1000 -> 1405.5465 | K26: =+('[2]11월누계'!$AO$13+'[2]11월누계'!$AO$20)/1000 -> 1660.8853 | L26: =+K26-J26 -> 255.33881 | M26: =+('[3]11월누계'!$AO$13+'[3]11월누계'!$AO$20)/1000 -> 1559.1559 | N26: =+K26-M26 -> 101.72947 | Q26: 구분 | S26: 계획 | T26: 실적 | U26: 계획대비 | V26: 전년 | W26: 전년대비
D27: 골재 | E27: =+('[1]11월'!$AE$13+'[1]11월'!$AE$20+'[1]11월'!$AE$22)/1000 -> 46.796279 | F27: =+('[2]11월'!$AN$13+'[2]11월'!$AN$20+'[2]11월'!$AN$22)/1000 -> 48.191646 | G27: =+F27-E27 -> 1.3953664 | H27: =+('[3]11월'!$AN$13+'[3]11월'!$AN$20+'[3]11월'!$AN$22)/1000 -> 70.857428 | I27: =+F27-H27 -> -22.665782 | J27: =+('[1]11월누계'!$AE$13+'[1]11월누계'!$AE$20+'[1]11월누계'!$AE$22)/1000 -> 528.75698 | K27: =+('[2]11월누계'!$AN$13+'[2]11월누계'!$AN$20+'[2]11월누계'!$AN$22)/1000 -> 531.70676 | L27: =+K27-J27 -> 2.9497848 | M27: =+('[3]11월누계'!$AN$13+'[3]11월누계'!$AN$20+'[3]11월누계'!$AN$22)/1000 -> 673.82387 | N27: =+K27-M27 -> -142.11711 | Q27: 판매량 | R27: 자가 | S27: =+[8]원가손익!$W$10+[9]원가손익!$W$13+[10]손익!$F$10 -> 63988.273 | T27: =+[8]원가손익!$X$10+[9]원가손익!$X$13+[10]손익!$G$10 -> 52956 | U27: =+T27-S27 -> -11032.273 | V27: =+'[11]부산모래장(당월)'!$S$85 -> 36922 | W27: =+T27-V27 -> 16034
D28: 기타 | E28: =+('[1]11월'!$E$13+'[1]11월'!$E$20)/1000-E25-E26-E27+('[1]11월'!$E$22/1000) -> 1377.0047 | F28: =+('[2]11월'!$F$13+'[2]11월'!$F$20)/1000-F25-F26-F27+'[2]11월'!$F$22/1000 -> 1329.0822 | G28: =+F28-E28 -> -47.922485 | H28: =+('[3]11월'!$F$13+'[3]11월'!$F$20)/1000-H25-H26-H27+'[3]11월'!$F$22/1000 -> 1321.429 | I28: =+F28-H28 -> 7.6531284 | J28: =+('[1]11월누계'!$E$13+'[1]11월누계'!$E$20)/1000-J25-J26-J27+('[1]11월누계'!$E$22/1000) -> 17352.679 | K28: =+('[2]11월누계'!$F$13+'[2]11월누계'!$F$20)/1000-K25-K26-K27+'[2]11월누계'!$F$22/1000 -> 19089.528 | L28: =+K28-J28 -> 1736.8491 | M28: =+('[3]11월누계'!$F$13+'[3]11월누계'!$F$20)/1000-M25-M26-M27+'[3]11월누계'!$F$22/1000 -> 16513.162 | N28: =+K28-M28 -> 2576.3659 | R28: 외판 | S28: =+[8]원가손익!$W$14+[9]원가손익!$W$15+[10]손익!$F$12 -> 50000 | T28: =+[8]원가손익!$X$14+[9]원가손익!$X$15+[10]손익!$G$12 -> 16018 | U28: =+T28-S28 -> -33982 | V28: =+'[11]부산모래장(당월)'!$S$86 -> 29204 | W28: =+T28-V28 -> -13186
C29: 계 | E29: =SUM(E25:E28) -> 2197.106 | F29: =SUM(F25:F28) -> 2220.9723 | G29: =+F29-E29 -> 23.866324 | H29: =SUM(H25:H28) -> 2225.9641 | I29: =+F29-H29 -> -4.991719 | J29: =SUM(J25:J28) -> 26688.286 | K29: =SUM(K25:K28) -> 28880.932 | L29: =+K29-J29 -> 2192.6461 | M29: =SUM(M25:M28) -> 26329.324 | N29: =+K29-M29 -> 2551.6077 | Q29: 합 계 | S29: =SUM(S27:S28) -> 113988.27 | T29: =SUM(T27:T28) -> 68974 | U29: =+T29-S29 -> -45014.273 | V29: =SUM(V27:V28) -> 66126 | W29: =+T29-V29 -> 2848
C30: 영업이익 | D30: 레미콘 | E30: =+E20-E25 -> 3809.6671 | F30: =+F20-F25 -> 1374.3194 | G30: =+F30-E30 -> -2435.3478 | H30: =+H20-H25 -> 2195.9234 | I30: =+F30-H30 -> -821.60404 | J30: =+J20-J25 -> 29340.044 | K30: =+K20-K25 -> 12566.652 | L30: =+K30-J30 -> -16773.392 | M30: =+M20-M25 -> 32469.06 | N30: =+K30-M30 -> -19902.408 | Q30: □ 기타내역(영업이익)
D31: % | E31: =+E30/E10 -> 0.12027386 | F31: =+F30/F10 -> 0.053152509 | G31: =+F31-E31 -> -0.067121352 | H31: =+H30/H10 -> 0.078231182 | I31: =+F31-H31 -> -0.025078673 | J31: =+J30/J10 -> 0.096041661 | K31: =+K30/K10 -> 0.049502573 | L31: =+K31-J31 -> -0.046539088 | M31: =+M30/M10 -> 0.10393674 | N31: =+K31-M31 -> -0.054434164 | Q31: 구분 | S31: 계획 | T31: 실적 | U31: 계획대비 | V31: 전년 | W31: 전년대비
D32: 건자재 | E32: =+E21-E26 -> 247.89226 | F32: =+F21-F26 -> 22.991546 | G32: =+F32-E32 -> -224.90072 | H32: =+H21-H26 -> 118.35665 | I32: =+F32-H32 -> -95.365103 | J32: =+J21-J26 -> 2263.1249 | K32: =+K21-K26 -> -53.758588 | L32: =+K32-J32 -> -2316.8835 | M32: =+M21-M26 -> 601.86035 | N32: =+K32-M32 -> -655.61894 | Q32: 레미콘임대 | S32: =+'사업장별(당월)'!T33 -> 48.278888 | T32: =+'사업장별(당월)'!U33 -> 23.549857 | U32: =+T32-S32 -> -24.729031 | V32: =+'사업장별(당월)'!W33 -> 67.392238 | W32: =+T32-V32 -> -43.842381
D33: 골재 | E33: =+E22-E27 -> 299.99914 | F33: =+F22-F27 -> -179.35449 | G33: =+F33-E33 -> -479.35363 | H33: =+H22-H27 -> -290.10889 | I33: =+F33-H33 -> 110.75439 | J33: =+J22-J27 -> 2024.1749 | K33: =+K22-K27 -> -1005.8875 | L33: =+K33-J33 -> -3030.0624 | M33: =+M22-M27 -> -294.10414 | N33: =+K33-M33 -> -711.7834 | Q33: 임대 | S33: =+'사업장별(당월)'!T34 -> 63.941 | T33: =+'사업장별(당월)'!U34 -> 66.61316 | U33: =+T33-S33 -> 2.67216 | V33: =+'사업장별(당월)'!W34 -> 58.662833 | W33: =+T33-V33 -> 7.950327
D34: 기타 | E34: =+E23-E28 -> -1302.8521 | F34: =+F23-F28 -> -831.2827 | G34: =+F34-E34 -> 471.56939 | H34: =+H23-H28 -> -947.31013 | I34: =+F34-H34 -> 116.02743 | J34: =+J23-J28 -> -16388.648 | K34: =+K23-K28 -> -17268.046 | L34: =+K34-J34 -> -879.39763 | M34: =+M23-M28 -> -14152.855 | N34: =+K34-M34 -> -3115.1915 | Q34: 공통비 | S34: =+'사업장별(당월)'!T35 -> -1297.3901 | T34: =+'사업장별(당월)'!U35 -> -1271.3905 | U34: =+T34-S34 -> 25.999644 | V34: =+'사업장별(당월)'!W35 -> -1265.4311 | W34: =+T34-V34 -> -5.9593684
C35: 계 | E35: =SUM(E30,E32:E34) -> 3054.7064 | F35: =SUM(F30,F32:F34) -> 386.67371 | G35: =+F35-E35 -> -2668.0327 | H35: =SUM(H30,H32:H34) -> 1076.861 | I35: =+F35-H35 -> -690.18732 | J35: =SUM(J30,J32:J34) -> 17238.695 | K35: =SUM(K30,K32:K34) -> -5761.04 | L35: =+K35-J35 -> -22999.735 | M35: =SUM(M30,M32:M34) -> 18623.962 | N35: =+K35-M35 -> -24385.002 | Q35: 기타 | S35: =+S36-S32-S33-S34 -> -117.68187 | T35: =+T36-T32-T33-T34 -> 349.94474 | U35: =+T35-S35 -> 467.62661 | V35: =+V36-V32-V33-V34 -> 192.06589 | W35: =+T35-V35 -> 157.87885
D36: % | E36: =+E35/E14 -> 0.064159396 | F36: =+F35/F14 -> 0.01079516 | G36: =+F36-E36 -> -0.053364236 | H36: =+H35/H14 -> 0.027199032 | I36: =+F36-H36 -> -0.016403872 | J36: =+J35/J14 -> 0.037232173 | K36: =+K35/K14 -> -0.015901898 | L36: =+K36-J36 -> -0.053134071 | M36: =+M35/M14 -> 0.043661051 | N36: =+K36-M36 -> -0.059562949 | Q36: 합계 | S36: =+'사업장별(당월)'!T41 -> -1302.8521 | T36: =+'사업장별(당월)'!U41 -> -831.2827 | U36: =+T36-S36 -> 471.56939 | V36: =+'사업장별(당월)'!W41 -> -947.31013 | W36: =+T36-V36 -> 116.02743
E38: =+'[1]11월'!$E$26/1000 -> 3054.7064 | F38: =+'[2]11월'!$F$26/1000 -> 386.67371 | H38: =+'[3]11월'!$F$26/1000 -> 1076.861 | J38: =+'[1]11월누계'!$E$26/1000 -> 17238.695 | K38: =+'[2]11월누계'!$F$26/1000 -> -5761.04 | M38: =+'[3]11월누계'!$F$26/1000 -> 18623.962
E39: =+E35=E38 -> TRUE | F39: =+F35=F38 -> FALSE | H39: =+H35=H38 -> TRUE | J39: =+J35=J38 -> TRUE | K39: =+K35=K38 -> FALSE | M39: =+M35=M38 -> TRUE
E40: =+E35-E38 -> -5.0022209e-12 | F40: =+F35-F38 -> -6.7075234e-12 | H40: =+H35-H38 -> 1.8189894e-12 | J40: =+J35-J38 -> 0 | K40: =+K35-K38 -> 7.2759576e-12 | M40: =+M35-M38 -> 0

Sheet 레미콘 영업이익
H3: □ 레미콘 영업이익(11월)
H5: 구분 | J5: 11월 | T5: 11월누계
J6: 영업이익(공통비 배부전) | O6: 영업이익(공통비 배부후) | T6: 영업이익(공통비 배부전) | Y6: 영업이익(공통비 배부전)
A7: 2024년 11월 마감 손익 | J7: 계획 | K7: 실적 | L7: 차이 | M7: 전년 | N7: 차이 | O7: 계획 | P7: 실적 | Q7: 차이 | R7: 전년 | S7: 차이 | T7: 계획 | U7: 실적 | V7: 차이 | W7: 전년 | X7: 차이 | Y7: 계획 | Z7: 실적 | AA7: 차이 | AB7: 전년 | AC7: 차이
B8: 안양 | H8: 레미콘 | I8: 안양 | J8: =+[4]안양!$H$86/1000 -> 574.41974 | K8: =+[4]안양!$I$86/1000 -> 194.12147 | L8: =+K8-J8 -> -380.29827 | M8: =+[5]안양!$H$86/1000 -> 302.27516 | N8: =+K8-M8 -> -108.15369 | O8: =+[4]안양!$H$92/1000 -> 400.3266 | P8: =+[4]안양!$I$92/1000 -> 51.345576 | Q8: =+P8-O8 -> -348.98102 | R8: =+[5]안양!$H$92/1000 -> 131.7323 | S8: =+P8-R8 -> -80.386721 | T8: =+[12]안양!$H$86/1000 -> 4101.4598 | U8: =+[12]안양!$I$86/1000 -> 2371.0141 | V8: =+U8-T8 -> -1730.4458 | W8: =+[13]안양!$H$86/1000 -> 3797.4263 | X8: =+U8-W8 -> -1426.4123 | Y8: =+[12]안양!$H$92/1000 -> 1825.8684 | Z8: =+[12]안양!$I$92/1000 -> 155.13322 | AA8: =+Z8-Y8 -> -1670.7352 | AB8: =+[13]안양!$H$92/1000 -> 1798.8048 | AC8: =+Z8-AB8 -> -1643.6716
B9: 인천 | H9: 직영 | I9: 인천 | J9: =+[4]인천!$H$86/1000 -> 376.01935 | K9: =+[4]인천!$I$86/1000 -> 27.814643 | L9: =+K9-J9 -> -348.2047 | M9: =+[5]인천!$H$86/1000 -> 72.336657 | N9: =+K9-M9 -> -44.522014 | O9: =+[4]인천!$H$92/1000 -> 240.26126 | P9: =+[4]인천!$I$92/1000 -> -122.68243 | Q9: =+P9-O9 -> -362.94369 | R9: =+[5]인천!$H$92/1000 -> -58.611021 | S9: =+P9-R9 -> -64.07141 | T9: =+[12]인천!$H$86/1000 -> 1861.5286 | U9: =+[12]인천!$I$86/1000 -> 171.9589 | V9: =+U9-T9 -> -1689.5697 | W9: =+[13]인천!$H$86/1000 -> 1734.6983 | X9: =+U9-W9 -> -1562.7394 | Y9: =+[12]인천!$H$92/1000 -> 202.98967 | Z9: =+[12]인천!$I$92/1000 -> -1725.277 | AA9: =+Z9-Y9 -> -1928.2667 | AB9: =+[13]인천!$H$92/1000 -> 286.6128 | AC9: =+Z9-AB9 -> -2011.8898
B10: 파주 | I10: 파주 | J10: =+[4]파주!$H$86/1000 -> 141.18347 | K10: =+[4]파주!$I$86/1000 -> -44.1742 | L10: =+K10-J10 -> -185.35767 | M10: =+[5]파주!$H$86/1000 -> 79.622709 | N10: =+K10-M10 -> -123.79691 | O10: =+[4]파주!$H$92/1000 -> 50.670355 | P10: =+[4]파주!$I$92/1000 -> -114.00405 | Q10: =+P10-O10 -> -164.6744 | R10: =+[5]파주!$H$92/1000 -> -16.514878 | S10: =+P10-R10 -> -97.489171 | T10: =+[12]파주!$H$86/1000 -> 1156.2851 | U10: =+[12]파주!$I$86/1000 -> -449.69631 | V10: =+U10-T10 -> -1605.9815 | W10: =+[13]파주!$H$86/1000 -> 1773.5914 | X10: =+U10-W10 -> -2223.2877 | Y10: =+[12]파주!$H$92/1000 -> -39.012798 | Z10: =+[12]파주!$I$92/1000 -> -1318.3337 | AA10: =+Z10-Y10 -> -1279.321 | AB10: =+[13]파주!$H$92/1000 -> 494.8456 | AC10: =+Z10-AB10 -> -1813.1793
B11: 김포 | I11: 김포 | J11: =+[4]김포!$H$86/1000 -> 127.85874 | K11: =+[4]김포!$I$86/1000 -> 18.980567 | L11: =+K11-J11 -> -108.87818 | M11: =+[5]김포!$H$86/1000 -> 98.878248 | N11: =+K11-M11 -> -79.897681 | O11: =+[4]김포!$H$92/1000 -> 65.251848 | P11: =+[4]김포!$I$92/1000 -> -44.355784 | Q11: =+P11-O11 -> -109.60763 | R11: =+[5]김포!$H$92/1000 -> 24.530153 | S11: =+P11-R11 -> -68.885938 | T11: =+[12]김포!$H$86/1000 -> 983.84341 | U11: =+[12]김포!$I$86/1000 -> -25.577626 | V11: =+U11-T11 -> -1009.421 | W11: =+[13]김포!$H$86/1000 -> 1034.6775 | X11: =+U11-W11 -> -1060.2551 | Y11: =+[12]김포!$H$92/1000 -> 193.31269 | Z11: =+[12]김포!$I$92/1000 -> -723.90308 | AA11: =+Z11-Y11 -> -917.21577 | AB11: =+[13]김포!$H$92/1000 -> 424.80253 | AC11: =+Z11-AB11 -> -1148.7056
B12: 부산 | I12: 부산 | J12: =+[4]부산!$H$86/1000 -> 216.01864 | K12: =+[4]부산!$I$86/1000 -> 221.31097 | L12: =+K12-J12 -> 5.2923312 | M12: =+[5]부산!$H$86/1000 -> 175.17909 | N12: =+K12-M12 -> 46.131882 | O12: =+[4]부산!$H$92/1000 -> 121.57358 | P12: =+[4]부산!$I$92/1000 -> 95.197447 | Q12: =+P12-O12 -> -26.376137 | R12: =+[5]부산!$H$92/1000 -> 78.619485 | S12: =+P12-R12 -> 16.577962 | T12: =+[12]부산!$H$86/1000 -> 2012.6822 | U12: =+[12]부산!$I$86/1000 -> 2110.6866 | V12: =+U12-T12 -> 98.004476 | W12: =+[13]부산!$H$86/1000 -> 2226.0846 | X12: =+U12-W12 -> -115.39797 | Y12: =+[12]부산!$H$92/1000 -> 704.29076 | Z12: =+[12]부산!$I$92/1000 -> 505.12796 | AA12: =+Z12-Y12 -> -199.1628 | AB12: =+[13]부산!$H$92/1000 -> 1068.7468 | AC12: =+Z12-AB12 -> -563.61887
B13: 서부산 | I13: 서부산 | J13: =+[4]서부산!$H$86/1000 -> 264.26867 | K13: =+[4]서부산!$I$86/1000 -> 229.39877 | L13: =+K13-J13 -> -34.869894 | M13: =+[5]서부산!$H$86/1000 -> 124.8758 | N13: =+K13-M13 -> 104.52298 | O13: =+[4]서부산!$H$92/1000 -> 168.89696 | P13: =+[4]서부산!$I$92/1000 -> 111.14895 | Q13: =+P13-O13 -> -57.748014 | R13: =+[5]서부산!$H$92/1000 -> 38.294669 | S13: =+P13-R13 -> 72.854279 | T13: =+[12]서부산!$H$86/1000 -> 2076.6131 | U13: =+[12]서부산!$I$86/1000 -> 1420.0661 | V13: =+U13-T13 -> -656.54702 | W13: =+[13]서부산!$H$86/1000 -> 2415.4799 | X13: =+U13-W13 -> -995.41379 | Y13: =+[12]서부산!$H$92/1000 -> 883.5741 | Z13: =+[12]서부산!$I$92/1000 -> 148.07634 | AA13: =+Z13-Y13 -> -735.49776 | AB13: =+[13]서부산!$H$92/1000 -> 1275.3172 | AC13: =+Z13-AB13 -> -1127.2409
B14: 김해 | I14: 김해 | J14: =+[4]김해!$H$86/1000 -> 152.44152 | K14: =+[4]김해!$I$86/1000 -> -38.756984 | L14: =+K14-J14 -> -191.1985 | M14: =+[5]김해!$H$86/1000 -> 84.464322 | N14: =+K14-M14 -> -123.22131 | O14: =+[4]김해!$H$92/1000 -> 88.100233 | P14: =+[4]김해!$I$92/1000 -> -74.986139 | Q14: =+P14-O14 -> -163.08637 | R14: =+[5]김해!$H$92/1000 -> 30.15737 | S14: =+P14-R14 -> -105.14351 | T14: =+[12]김해!$H$86/1000 -> 1308.7789 | U14: =+[12]김해!$I$86/1000 -> -385.88006 | V14: =+U14-T14 -> -1694.6589 | W14: =+[13]김해!$H$86/1000 -> 804.51998 | X14: =+U14-W14 -> -1190.4 | Y14: =+[12]김해!$H$92/1000 -> 480.25237 | Z14: =+[12]김해!$I$92/1000 -> -959.05882 | AA14: =+Z14-Y14 -> -1439.3112 | AB14: =+[13]김해!$H$92/1000 -> 110.17571 | AC14: =+Z14-AB14 -> -1069.2345
B15: 정관 | I15: 정관 | J15: =+[4]정관!$H$86/1000 -> 217.22613 | K15: =+[4]정관!$I$86/1000 -> 103.48471 | L15: =+K15-J15 -> -113.74142 | M15: =+[5]정관!$H$86/1000 -> 141.17147 | N15: =+K15-M15 -> -37.686762 | O15: =+[4]정관!$H$92/1000 -> 127.77965 | P15: =+[4]정관!$I$92/1000 -> 5.0160422 | Q15: =+P15-O15 -> -122.76361 | R15: =+[5]정관!$H$92/1000 -> 57.158828 | S15: =+P15-R15 -> -52.142786 | T15: =+[12]정관!$H$86/1000 -> 1778.5087 | U15: =+[12]정관!$I$86/1000 -> 1811.1652 | V15: =+U15-T15 -> 32.656528 | W15: =+[13]정관!$H$86/1000 -> 1884.1901 | X15: =+U15-W15 -> -73.02484 | Y15: =+[12]정관!$H$92/1000 -> 584.70782 | Z15: =+[12]정관!$I$92/1000 -> 205.8367 | AA15: =+Z15-Y15 -> -378.87112 | AB15: =+[13]정관!$H$92/1000 -> 801.66866 | AC15: =+Z15-AB15 -> -595.83196
B16: 양산 | I16: 양산 | J16: =+[4]양산!$H$86/1000 -> 119.63528 | K16: =+[4]양산!$I$86/1000 -> -7.408493 | L16: =+K16-J16 -> -127.04377 | M16: =+[5]양산!$H$86/1000 -> 98.711031 | N16: =+K16-M16 -> -106.11952 | O16: =+[4]양산!$H$92/1000 -> 68.581341 | P16: =+[4]양산!$I$92/1000 -> -50.825524 | Q16: =+P16-O16 -> -119.40686 | R16: =+[5]양산!$H$92/1000 -> 51.143188 | S16: =+P16-R16 -> -101.96871 | T16: =+[12]양산!$H$86/1000 -> 1035.1134 | U16: =+[12]양산!$I$86/1000 -> -116.98529 | V16: =+U16-T16 -> -1152.0987 | W16: =+[13]양산!$H$86/1000 -> 1184.866 | X16: =+U16-W16 -> -1301.8512 | Y16: =+[12]양산!$H$92/1000 -> 366.13287 | Z16: =+[12]양산!$I$92/1000 -> -608.65097 | AA16: =+Z16-Y16 -> -974.78384 | AB16: =+[13]양산!$H$92/1000 -> 546.6356 | AC16: =+Z16-AB16 -> -1155.2866
B17: 창원 | I17: 창원 | J17: =+[4]창원!$H$86/1000 -> 275.53524 | K17: =+[4]창원!$I$86/1000 -> 95.80599 | L17: =+K17-J17 -> -179.72925 | M17: =+[5]창원!$H$86/1000 -> 134.08562 | N17: =+K17-M17 -> -38.279632 | O17: =+[4]창원!$H$92/1000 -> 196.19393 | P17: =+[4]창원!$I$92/1000 -> 34.36706 | Q17: =+P17-O17 -> -161.82687 | R17: =+[5]창원!$H$92/1000 -> 73.371842 | S17: =+P17-R17 -> -39.004783 | T17: =+[12]창원!$H$86/1000 -> 1379.1645 | U17: =+[12]창원!$I$86/1000 -> 332.37587 | V17: =+U17-T17 -> -1046.7887 | W17: =+[13]창원!$H$86/1000 -> 2572.8557 | X17: =+U17-W17 -> -2240.4798 | Y17: =+[12]창원!$H$92/1000 -> 606.68888 | Z17: =+[12]창원!$I$92/1000 -> -342.9065 | AA17: =+Z17-Y17 -> -949.59538 | AB17: =+[13]창원!$H$92/1000 -> 1635.421 | AC17: =+Z17-AB17 -> -1978.3275
B18: 대구 | I18: 대구 | J18: =+[4]대구!$H$86/1000 -> 122.69105 | K18: =+[4]대구!$I$86/1000 -> -68.392861 | L18: =+K18-J18 -> -191.08391 | M18: =+[5]대구!$H$86/1000 -> 166.75688 | N18: =+K18-M18 -> -235.14975 | O18: =+[4]대구!$H$92/1000 -> 73.957617 | P18: =+[4]대구!$I$92/1000 -> -97.321036 | Q18: =+P18-O18 -> -171.27865 | R18: =+[5]대구!$H$92/1000 -> 98.478441 | S18: =+P18-R18 -> -195.79948 | T18: =+[12]대구!$H$86/1000 -> 1200.6712 | U18: =+[12]대구!$I$86/1000 -> -44.250532 | V18: =+U18-T18 -> -1244.9217 | W18: =+[13]대구!$H$86/1000 -> 2383.4607 | X18: =+U18-W18 -> -2427.7113 | Y18: =+[12]대구!$H$92/1000 -> 478.51076 | Z18: =+[12]대구!$I$92/1000 -> -685.6439 | AA18: =+Z18-Y18 -> -1164.1547 | AB18: =+[13]대구!$H$92/1000 -> 1530.1144 | AC18: =+Z18-AB18 -> -2215.7583
B19: 울산 | I19: 울산 | J19: =+[4]울산!$H$86/1000 -> 117.51597 | K19: =+[4]울산!$I$86/1000 -> 92.955994 | L19: =+K19-J19 -> -24.559978 | M19: =+[5]울산!$H$86/1000 -> 169.85775 | N19: =+K19-M19 -> -76.901755 | O19: =+[4]울산!$H$92/1000 -> 61.219128 | P19: =+[4]울산!$I$92/1000 -> 21.078289 | Q19: =+P19-O19 -> -40.140839 | R19: =+[5]울산!$H$92/1000 -> 105.16452 | S19: =+P19-R19 -> -84.086235 | T19: =+[12]울산!$H$86/1000 -> 1064.7617 | U19: =+[12]울산!$I$86/1000 -> 1009.1216 | V19: =+U19-T19 -> -55.640065 | W19: =+[13]울산!$H$86/1000 -> 1408.0476 | X19: =+U19-W19 -> -398.92595 | Y19: =+[12]울산!$H$92/1000 -> 313.82481 | Z19: =+[12]울산!$I$92/1000 -> 159.57888 | AA19: =+Z19-Y19 -> -154.24594 | AB19: =+[13]울산!$H$92/1000 -> 762.50831 | AC19: =+Z19-AB19 -> -602.92943
B20: 아산 | I20: 아산 | J20: =+[4]아산!$H$86/1000 -> 389.43541 | K20: =+[4]아산!$I$86/1000 -> 175.51435 | L20: =+K20-J20 -> -213.92106 | M20: =+[5]아산!$H$86/1000 -> 245.55114 | N20: =+K20-M20 -> -70.036791 | O20: =+[4]아산!$H$92/1000 -> 284.22355 | P20: =+[4]아산!$I$92/1000 -> 59.428512 | Q20: =+P20-O20 -> -224.79504 | R20: =+[5]아산!$H$92/1000 -> 124.43852 | S20: =+P20-R20 -> -65.01001 | T20: =+[12]아산!$H$86/1000 -> 3254.013 | U20: =+[12]아산!$I$86/1000 -> 1019.9201 | V20: =+U20-T20 -> -2234.0929 | W20: =+[13]아산!$H$86/1000 -> 4128.2181 | X20: =+U20-W20 -> -3108.298 | Y20: =+[12]아산!$H$92/1000 -> 1944.5982 | Z20: =+[12]아산!$I$92/1000 -> -438.16024 | AA20: =+Z20-Y20 -> -2382.7585 | AB20: =+[13]아산!$H$92/1000 -> 2724.742 | AC20: =+Z20-AB20 -> -3162.9023
B21: 전주 | I21: 전주 | J21: =+[4]전주!$H$86/1000 -> 177.68968 | K21: =+[4]전주!$I$86/1000 -> 186.91676 | L21: =+K21-J21 -> 9.2270822 | M21: =+[5]전주!$H$86/1000 -> 64.246477 | N21: =+K21-M21 -> 122.67029 | O21: =+[4]전주!$H$92/1000 -> 130.13993 | P21: =+[4]전주!$I$92/1000 -> 111.59418 | Q21: =+P21-O21 -> -18.545753 | R21: =+[5]전주!$H$92/1000 -> 25.257746 | S21: =+P21-R21 -> 86.336436 | T21: =+[12]전주!$H$86/1000 -> 1352.8966 | U21: =+[12]전주!$I$86/1000 -> 1412.7517 | V21: =+U21-T21 -> 59.855104 | W21: =+[13]전주!$H$86/1000 -> 629.36368 | X21: =+U21-W21 -> 783.38801 | Y21: =+[12]전주!$H$92/1000 -> 742.01667 | Z21: =+[12]전주!$I$92/1000 -> 519.70107 | AA21: =+Z21-Y21 -> -222.31559 | AB21: =+[13]전주!$H$92/1000 -> 207.31771 | AC21: =+Z21-AB21 -> 312.38336
B22: 군산 | I22: 군산 | J22: =+[4]군산!$H$86/1000 -> 207.99971 | K22: =+[4]군산!$I$86/1000 -> 88.643465 | L22: =+K22-J22 -> -119.35624 | M22: =+[5]군산!$H$86/1000 -> 153.19348 | N22: =+K22-M22 -> -64.550012 | O22: =+[4]군산!$H$92/1000 -> 175.26336 | P22: =+[4]군산!$I$92/1000 -> 65.80578 | Q22: =+P22-O22 -> -109.45757 | R22: =+[5]군산!$H$92/1000 -> 120.19144 | S22: =+P22-R22 -> -54.385657 | T22: =+[12]군산!$H$86/1000 -> 2047.8773 | U22: =+[12]군산!$I$86/1000 -> 1041.032 | V22: =+U22-T22 -> -1006.8452 | W22: =+[13]군산!$H$86/1000 -> 2843.8162 | X22: =+U22-W22 -> -1802.7842 | Y22: =+[12]군산!$H$92/1000 -> 1602.6618 | Z22: =+[12]군산!$I$92/1000 -> 669.82685 | AA22: =+Z22-Y22 -> -932.83497 | AB22: =+[13]군산!$H$92/1000 -> 2343.918 | AC22: =+Z22-AB22 -> -1674.0912
B23: 원주 | I23: 원주 | J23: =+[4]원주!$H$86/1000 -> 145.42812 | K23: =+[4]원주!$I$86/1000 -> 57.96605 | L23: =+K23-J23 -> -87.462072 | M23: =+[5]원주!$H$86/1000 -> 96.375569 | N23: =+K23-M23 -> -38.409519 | O23: =+[4]원주!$H$92/1000 -> 119.02694 | P23: =+[4]원주!$I$92/1000 -> 37.523736 | Q23: =+P23-O23 -> -81.503202 | R23: =+[5]원주!$H$92/1000 -> 73.879351 | S23: =+P23-R23 -> -36.355615 | T23: =+[12]원주!$H$86/1000 -> 948.38752 | U23: =+[12]원주!$I$86/1000 -> 226.23234 | V23: =+U23-T23 -> -722.15518 | W23: =+[13]원주!$H$86/1000 -> 1329.3867 | X23: =+U23-W23 -> -1103.1543 | Y23: =+[12]원주!$H$92/1000 -> 652.69742 | Z23: =+[12]원주!$I$92/1000 -> -4.8779387 | AA23: =+Z23-Y23 -> -657.57536 | AB23: =+[13]원주!$H$92/1000 -> 1008.4779 | AC23: =+Z23-AB23 -> -1013.3558
B24: 제주 | I24: 제주 | J24: =+[4]제주!$H$86/1000 -> 184.3004 | K24: =+[4]제주!$I$86/1000 -> 40.13815 | L24: =+K24-J24 -> -144.16225 | M24: =+[5]제주!$H$86/1000 -> -11.658004 | N24: =+K24-M24 -> 51.796154 | O24: =+[4]제주!$H$92/1000 -> 140.81073 | P24: =+[4]제주!$I$92/1000 -> 14.598285 | Q24: =+P24-O24 -> -126.21245 | R24: =+[5]제주!$H$92/1000 -> -26.79965 | S24: =+P24-R24 -> 41.397935 | T24: =+[12]제주!$H$86/1000 -> 1777.4591 | U24: =+[12]제주!$I$86/1000 -> 662.71735 | V24: =+U24-T24 -> -1114.7418 | W24: =+[13]제주!$H$86/1000 -> 318.37748 | X24: =+U24-W24 -> 344.33987 | Y24: =+[12]제주!$H$92/1000 -> 1193.003 | Z24: =+[12]제주!$I$92/1000 -> 192.07166 | AA24: =+Z24-Y24 -> -1000.9314 | AB24: =+[13]제주!$H$92/1000 -> 95.102791 | AC24: =+Z24-AB24 -> 96.968867
I25: 수도권 | J25: =SUM(J8:J11) -> 1219.4813 | K25: =SUM(K8:K11) -> 196.74248 | L25: =+K25-J25 -> -1022.7388 | M25: =SUM(M8:M11) -> 553.11277 | N25: =+K25-M25 -> -356.37029 | O25: =SUM(O8:O11) -> 756.51006 | P25: =SUM(P8:P11) -> -229.69669 | Q25: =+P25-O25 -> -986.20674 | R25: =SUM(R8:R11) -> 81.136551 | S25: =+P25-R25 -> -310.83324 | T25: =SUM(T8:T11) -> 8103.1169 | U25: =SUM(U8:U11) -> 2067.6991 | V25: =+U25-T25 -> -6035.4179 | W25: =SUM(W8:W11) -> 8340.3936 | X25: =+U25-W25 -> -6272.6945 | Y25: =SUM(Y8:Y11) -> 2183.158 | Z25: =SUM(Z8:Z11) -> -3612.3806 | AA25: =+Z25-Y25 -> -5795.5386 | AB25: =SUM(AB8:AB11) -> 3005.0657 | AC25: =+Z25-AB25 -> -6617.4463
I26: 영남권 | J26: =SUM(J12:J19) -> 1485.3325 | K26: =SUM(K12:K19) -> 628.3981 | L26: =+K26-J26 -> -856.9344 | M26: =SUM(M12:M19) -> 1095.102 | N26: =+K26-M26 -> -466.70387 | O26: =SUM(O12:O19) -> 906.30245 | P26: =SUM(P12:P19) -> 43.675087 | Q26: =+P26-O26 -> -862.62736 | R26: =SUM(R12:R19) -> 532.38835 | S26: =+P26-R26 -> -488.71326 | T26: =SUM(T12:T19) -> 11856.294 | U26: =SUM(U12:U19) -> 6136.2996 | V26: =+U26-T26 -> -5719.994 | W26: =SUM(W12:W19) -> 14879.504 | X26: =+U26-W26 -> -8743.2049 | Y26: =SUM(Y12:Y19) -> 4417.9824 | Z26: =SUM(Z12:Z19) -> -1577.6403 | AA26: =+Z26-Y26 -> -5995.6227 | AB26: =SUM(AB12:AB19) -> 7730.5877 | AC26: =+Z26-AB26 -> -9308.228
I27: 중부권 | J27: =SUM(J20:J24) -> 1104.8533 | K27: =SUM(K20:K24) -> 549.17878 | L27: =+K27-J27 -> -555.67454 | M27: =SUM(M20:M24) -> 547.70866 | N27: =+K27-M27 -> 1.470117 | O27: =SUM(O20:O24) -> 849.46451 | P27: =SUM(P20:P24) -> 288.9505 | Q27: =+P27-O27 -> -560.51402 | R27: =SUM(R20:R24) -> 316.96741 | S27: =+P27-R27 -> -28.016912 | T27: =SUM(T20:T24) -> 9380.6335 | U27: =SUM(U20:U24) -> 4362.6535 | V27: =+U27-T27 -> -5017.98 | W27: =SUM(W20:W24) -> 9249.1621 | X27: =+U27-W27 -> -4886.5086 | Y27: =SUM(Y20:Y24) -> 6134.9772 | Z27: =SUM(Z20:Z24) -> 938.5614 | AA27: =+Z27-Y27 -> -5196.4158 | AB27: =SUM(AB20:AB24) -> 6379.5584 | AC27: =+Z27-AB27 -> -5440.997
H28: 레미콘 계 | J28: =SUM(J25:J27) -> 3809.6671 | K28: =SUM(K25:K27) -> 1374.3194 | L28: =+K28-J28 -> -2435.3478 | M28: =SUM(M25:M27) -> 2195.9234 | N28: =+K28-M28 -> -821.60404 | O28: =SUM(O25:O27) -> 2512.277 | P28: =SUM(P25:P27) -> 102.92889 | Q28: =+P28-O28 -> -2409.3481 | R28: =SUM(R25:R27) -> 930.49231 | S28: =+P28-R28 -> -827.56341 | T28: =SUM(T25:T27) -> 29340.044 | U28: =SUM(U25:U27) -> 12566.652 | V28: =+U28-T28 -> -16773.392 | W28: =SUM(W25:W27) -> 32469.06 | X28: =+U28-W28 -> -19902.408 | Y28: =SUM(Y25:Y27) -> 12736.117 | Z28: =SUM(Z25:Z27) -> -4251.4595 | AA28: =+Z28-Y28 -> -16987.577 | AB28: =SUM(AB25:AB27) -> 17115.212 | AC28: =+Z28-AB28 -> -21366.671

Sheet 사업장별(당월)
H3: □ 사업장별 손익실적(2025-11)
AG4: [단위 : 천㎥, 톤, 백만원]
H5: 구분 | J5: 물량 | O5: 매출 | T5: 영업이익(공통비 배부전) | Y5: 판매단가 | AB5: 변동비 | AE5: 공헌이익
A6: 2024년 11월 마감 손익 | J6: 계획 | K6: 실적 | L6: 차이 | M6: 전년 | N6: 차이 | O6: 계획 | P6: 실적 | Q6: 차이 | R6: 전년 | S6: 차이 | T6: 계획 | U6: 실적 | V6: 차이 | W6: 전년 | X6: 차이 | Y6: 계획 | Z6: 실적 | AA6: 전년 | AB6: 계획 | AC6: 실적 | AD6: 전년 | AE6: 계획 | AF6: 실적 | AG6: 전년
B7: 안양 | G7: =+I7 -> 안양 | H7: 레미콘 | I7: 안양 | J7: =+IFERROR(HLOOKUP($B7,'[1]11월'!$D$6:$BN$259,2,),)/1000 -> 41 | K7: =+IFERROR(HLOOKUP($B7,'[2]11월'!$F$6:$CP$99,2,),)/1000 -> 30.651 | L7: =+K7-J7 -> -10.349 | M7: =+IFERROR(HLOOKUP($B7,'[3]11월'!$F$6:$CC$57,2,),)/1000 -> 38.566 | N7: =+K7-M7 -> -7.915 | O7: =+IFERROR(HLOOKUP($B7,'[1]11월'!$D$6:$BN$259,3,),)/1000 -> 4252.2908 | P7: =+IFERROR(HLOOKUP($B7,'[2]11월'!$F$6:$CP$99,3,),)/1000 -> 2986.4414 | Q7: =+P7-O7 -> -1265.8494 | R7: =+IFERROR(HLOOKUP($B7,'[3]11월'!$F$6:$CC$57,3,),)/1000 -> 3786.5243 | S7: =+P7-R7 -> -800.08287 | T7: =+IFERROR(HLOOKUP($B7,'[1]11월'!$D$6:$BN$259,16,),)/1000 -> 574.41974 | U7: =+IFERROR(HLOOKUP($B7,'[2]11월'!$F$6:$CP$99,16,),)/1000 -> 194.12147 | V7: =+U7-T7 -> -380.29827 | W7: =+IFERROR(HLOOKUP($B7,'[3]11월'!$F$6:$CC$57,16,),)/1000 -> 302.27516 | X7: =+U7-W7 -> -108.15369 | Y7: =+[4]안양!$Q$85 -> 103714.41 | Z7: =+[4]안양!$R$85 -> 97433.734 | AA7: =+[5]안양!$Q$85 -> 98187.636 | AB7: =+[4]안양!$Q$89 -> 82850.095 | AC7: =+[4]안양!$R$89 -> 80972.182 | AD7: =+[5]안양!$Q$89 -> 83030.588 | AE7: =+Y7-AB7 -> 20864.314 | AF7: =+Z7-AC7 -> 16461.552 | AG7: =+AA7-AD7 -> 15157.048
B8: 인천 | G8: =+I8 -> 인천 | H8: 직영 | I8: 인천 | J8: =+IFERROR(HLOOKUP($B8,'[1]11월'!$D$6:$BN$259,2,),)/1000 -> 32 | K8: =+IFERROR(HLOOKUP($B8,'[2]11월'!$F$6:$CP$99,2,),)/1000 -> 31.7615 | L8: =+K8-J8 -> -0.2385 | M8: =+IFERROR(HLOOKUP($B8,'[3]11월'!$F$6:$CC$57,2,),)/1000 -> 29.507 | N8: =+K8-M8 -> 2.2545 | O8: =+IFERROR(HLOOKUP($B8,'[1]11월'!$D$6:$BN$259,3,),)/1000 -> 3315.9426 | P8: =+IFERROR(HLOOKUP($B8,'[2]11월'!$F$6:$CP$99,3,),)/1000 -> 3147.9453 | Q8: =+P8-O8 -> -167.99733 | R8: =+IFERROR(HLOOKUP($B8,'[3]11월'!$F$6:$CC$57,3,),)/1000 -> 2907.4014 | S8: =+P8-R8 -> 240.54382 | T8: =+IFERROR(HLOOKUP($B8,'[1]11월'!$D$6:$BN$259,16,),)/1000 -> 376.01935 | U8: =+IFERROR(HLOOKUP($B8,'[2]11월'!$F$6:$CP$99,16,),)/1000 -> 27.814643 | V8: =+U8-T8 -> -348.2047 | W8: =+IFERROR(HLOOKUP($B8,'[3]11월'!$F$6:$CC$57,16,),)/1000 -> 72.336657 | X8: =+U8-W8 -> -44.522014 | Y8: =+[4]인천!$Q$85 -> 103623.21 | Z8: =+[4]인천!$R$85 -> 99336.673 | AA8: =+[5]인천!$Q$85 -> 98532.601 | AB8: =+[4]인천!$Q$89 -> 83045.695 | AC8: =+[4]인천!$R$89 -> 87990.314 | AD8: =+[5]인천!$Q$89 -> 85841.298 | AE8: =+Y8-AB8 -> 20577.511 | AF8: =+Z8-AC8 -> 11346.359 | AG8: =+AA8-AD8 -> 12691.303
B9: 파주 | G9: =+I9 -> 파주 | I9: 파주 | J9: =+IFERROR(HLOOKUP($B9,'[1]11월'!$D$6:$BN$259,2,),)/1000 -> 23 | K9: =+IFERROR(HLOOKUP($B9,'[2]11월'!$F$6:$CP$99,2,),)/1000 -> 16.408 | L9: =+K9-J9 -> -6.592 | M9: =+IFERROR(HLOOKUP($B9,'[3]11월'!$F$6:$CC$57,2,),)/1000 -> 22.349 | N9: =+K9-M9 -> -5.941 | O9: =+IFERROR(HLOOKUP($B9,'[1]11월'!$D$6:$BN$259,3,),)/1000 -> 2210.8171 | P9: =+IFERROR(HLOOKUP($B9,'[2]11월'!$F$6:$CP$99,3,),)/1000 -> 1460.63 | Q9: =+P9-O9 -> -750.18708 | R9: =+IFERROR(HLOOKUP($B9,'[3]11월'!$F$6:$CC$57,3,),)/1000 -> 2134.5209 | S9: =+P9-R9 -> -673.89093 | T9: =+IFERROR(HLOOKUP($B9,'[1]11월'!$D$6:$BN$259,16,),)/1000 -> 141.18347 | U9: =+IFERROR(HLOOKUP($B9,'[2]11월'!$F$6:$CP$99,16,),)/1000 -> -44.1742 | V9: =+U9-T9 -> -185.35767 | W9: =+IFERROR(HLOOKUP($B9,'[3]11월'!$F$6:$CC$57,16,),)/1000 -> 79.622709 | X9: =+U9-W9 -> -123.79691 | Y9: =+[4]파주!$Q$85 -> 96122.482 | Z9: =+[4]파주!$R$85 -> 89118.992 | AA9: =+[5]파주!$Q$85 -> 95512.912 | AB9: =+[4]파주!$Q$89 -> 80492.007 | AC9: =+[4]파주!$R$89 -> 79049.85 | AD9: =+[5]파주!$Q$89 -> 81942.563 | AE9: =+Y9-AB9 -> 15630.475 | AF9: =+Z9-AC9 -> 10069.142 | AG9: =+AA9-AD9 -> 13570.349
B10: 김포 | G10: =+I10 -> 김포 | I10: 김포 | J10: =+IFERROR(HLOOKUP($B10,'[1]11월'!$D$6:$BN$259,2,),)/1000 -> 16 | K10: =+IFERROR(HLOOKUP($B10,'[2]11월'!$F$6:$CP$99,2,),)/1000 -> 13.889 | L10: =+K10-J10 -> -2.111 | M10: =+IFERROR(HLOOKUP($B10,'[3]11월'!$F$6:$CC$57,2,),)/1000 -> 17.224 | N10: =+K10-M10 -> -3.335 | O10: =+IFERROR(HLOOKUP($B10,'[1]11월'!$D$6:$BN$259,3,),)/1000 -> 1529.1971 | P10: =+IFERROR(HLOOKUP($B10,'[2]11월'!$F$6:$CP$99,3,),)/1000 -> 1324.8056 | Q10: =+P10-O10 -> -204.39144 | R10: =+IFERROR(HLOOKUP($B10,'[3]11월'!$F$6:$CC$57,3,),)/1000 -> 1650.7338 | S10: =+P10-R10 -> -325.92819 | T10: =+IFERROR(HLOOKUP($B10,'[1]11월'!$D$6:$BN$259,16,),)/1000 -> 127.85874 | U10: =+IFERROR(HLOOKUP($B10,'[2]11월'!$F$6:$CP$99,16,),)/1000 -> 18.980567 | V10: =+U10-T10 -> -108.87818 | W10: =+IFERROR(HLOOKUP($B10,'[3]11월'!$F$6:$CC$57,16,),)/1000 -> 98.878248 | X10: =+U10-W10 -> -79.897681 | Y10: =+[4]김포!$Q$85 -> 95574.816 | Z10: =+[4]김포!$R$85 -> 95300.794 | AA10: =+[5]김포!$Q$85 -> 95901.216 | AB10: =+[4]김포!$Q$89 -> 77214.635 | AC10: =+[4]김포!$R$89 -> 81097.926 | AD10: =+[5]김포!$Q$89 -> 80686.638 | AE10: =+Y10-AB10 -> 18360.181 | AF10: =+Z10-AC10 -> 14202.868 | AG10: =+AA10-AD10 -> 15214.577
B11: 부산 | G11: =+I11 -> 부산 | I11: 부산 | J11: =+IFERROR(HLOOKUP($B11,'[1]11월'!$D$6:$BN$259,2,),)/1000 -> 21 | K11: =+IFERROR(HLOOKUP($B11,'[2]11월'!$F$6:$CP$99,2,),)/1000 -> 22.523 | L11: =+K11-J11 -> 1.523 | M11: =+IFERROR(HLOOKUP($B11,'[3]11월'!$F$6:$CC$57,2,),)/1000 -> 19.12 | N11: =+K11-M11 -> 3.403 | O11: =+IFERROR(HLOOKUP($B11,'[1]11월'!$D$6:$BN$259,3,),)/1000 -> 2261.6992 | P11: =+IFERROR(HLOOKUP($B11,'[2]11월'!$F$6:$CP$99,3,),)/1000 -> 2478.8493 | Q11: =+P11-O11 -> 217.15001 | R11: =+IFERROR(HLOOKUP($B11,'[3]11월'!$F$6:$CC$57,3,),)/1000 -> 2100.75 | S11: =+P11-R11 -> 378.09924 | T11: =+IFERROR(HLOOKUP($B11,'[1]11월'!$D$6:$BN$259,16,),)/1000 -> 216.01864 | U11: =+IFERROR(HLOOKUP($B11,'[2]11월'!$F$6:$CP$99,16,),)/1000 -> 221.31097 | V11: =+U11-T11 -> 5.2923312 | W11: =+IFERROR(HLOOKUP($B11,'[3]11월'!$F$6:$CC$57,16,),)/1000 -> 175.17909 | X11: =+U11-W11 -> 46.131882 | Y11: =+[4]부산!$Q$85 -> 107699.96 | Z11: =+[4]부산!$R$85 -> 110058.57 | AA11: =+[5]부산!$Q$85 -> 109871.86 | AB11: =+[4]부산!$Q$89 -> 85567.362 | AC11: =+[4]부산!$R$89 -> 88858.859 | AD11: =+[5]부산!$Q$89 -> 86400.778 | AE11: =+Y11-AB11 -> 22132.602 | AF11: =+Z11-AC11 -> 21199.714 | AG11: =+AA11-AD11 -> 23471.085
B12: 서부산 | G12: =+I12 -> 서부산 | I12: 서부산 | J12: =+IFERROR(HLOOKUP($B12,'[1]11월'!$D$6:$BN$259,2,),)/1000 -> 23 | K12: =+IFERROR(HLOOKUP($B12,'[2]11월'!$F$6:$CP$99,2,),)/1000 -> 22.517 | L12: =+K12-J12 -> -0.483 | M12: =+IFERROR(HLOOKUP($B12,'[3]11월'!$F$6:$CC$57,2,),)/1000 -> 19.932 | N12: =+K12-M12 -> 2.585 | O12: =+IFERROR(HLOOKUP($B12,'[1]11월'!$D$6:$BN$259,3,),)/1000 -> 2283.8899 | P12: =+IFERROR(HLOOKUP($B12,'[2]11월'!$F$6:$CP$99,3,),)/1000 -> 2324.2827 | Q12: =+P12-O12 -> 40.392836 | R12: =+IFERROR(HLOOKUP($B12,'[3]11월'!$F$6:$CC$57,3,),)/1000 -> 1883.6583 | S12: =+P12-R12 -> 440.62441 | T12: =+IFERROR(HLOOKUP($B12,'[1]11월'!$D$6:$BN$259,16,),)/1000 -> 264.26867 | U12: =+IFERROR(HLOOKUP($B12,'[2]11월'!$F$6:$CP$99,16,),)/1000 -> 229.39877 | V12: =+U12-T12 -> -34.869894 | W12: =+IFERROR(HLOOKUP($B12,'[3]11월'!$F$6:$CC$57,16,),)/1000 -> 124.8758 | X12: =+U12-W12 -> 104.52298 | Y12: =+[4]서부산!$Q$85 -> 99299.559 | Z12: =+[4]서부산!$R$85 -> 103223.46 | AA12: =+[5]서부산!$Q$85 -> 94504.229 | AB12: =+[4]서부산!$Q$89 -> 78372.822 | AC12: =+[4]서부산!$R$89 -> 82592.91 | AD12: =+[5]서부산!$Q$89 -> 77003.708 | AE12: =+Y12-AB12 -> 20926.737 | AF12: =+Z12-AC12 -> 20630.552 | AG12: =+AA12-AD12 -> 17500.521
B13: 김해 | G13: =+I13 -> 김해 | I13: 김해 | J13: =+IFERROR(HLOOKUP($B13,'[1]11월'!$D$6:$BN$259,2,),)/1000 -> 16 | K13: =+IFERROR(HLOOKUP($B13,'[2]11월'!$F$6:$CP$99,2,),)/1000 -> 7.546 | L13: =+K13-J13 -> -8.454 | M13: =+IFERROR(HLOOKUP($B13,'[3]11월'!$F$6:$CC$57,2,),)/1000 -> 12.286 | N13: =+K13-M13 -> -4.74 | O13: =+IFERROR(HLOOKUP($B13,'[1]11월'!$D$6:$BN$259,3,),)/1000 -> 1540.7967 | P13: =+IFERROR(HLOOKUP($B13,'[2]11월'!$F$6:$CP$99,3,),)/1000 -> 712.1093 | Q13: =+P13-O13 -> -828.6874 | R13: =+IFERROR(HLOOKUP($B13,'[3]11월'!$F$6:$CC$57,3,),)/1000 -> 1181.5016 | S13: =+P13-R13 -> -469.3923 | T13: =+IFERROR(HLOOKUP($B13,'[1]11월'!$D$6:$BN$259,16,),)/1000 -> 152.44152 | U13: =+IFERROR(HLOOKUP($B13,'[2]11월'!$F$6:$CP$99,16,),)/1000 -> -38.756984 | V13: =+U13-T13 -> -191.1985 | W13: =+IFERROR(HLOOKUP($B13,'[3]11월'!$F$6:$CC$57,16,),)/1000 -> 84.464322 | X13: =+U13-W13 -> -123.22131 | Y13: =+[4]김해!$Q$85 -> 96299.794 | Z13: =+[4]김해!$R$85 -> 94411.974 | AA13: =+[5]김해!$Q$85 -> 96166.498 | AB13: =+[4]김해!$Q$89 -> 77604.526 | AC13: =+[4]김해!$R$89 -> 80826.376 | AD13: =+[5]김해!$Q$89 -> 77299.138 | AE13: =+Y13-AB13 -> 18695.268 | AF13: =+Z13-AC13 -> 13585.598 | AG13: =+AA13-AD13 -> 18867.36
B14: 정관 | G14: =+I14 -> 정관 | I14: 정관 | J14: =+IFERROR(HLOOKUP($B14,'[1]11월'!$D$6:$BN$259,2,),)/1000 -> 21 | K14: =+IFERROR(HLOOKUP($B14,'[2]11월'!$F$6:$CP$99,2,),)/1000 -> 19.745 | L14: =+K14-J14 -> -1.255 | M14: =+IFERROR(HLOOKUP($B14,'[3]11월'!$F$6:$CC$57,2,),)/1000 -> 18.063 | N14: =+K14-M14 -> 1.682 | O14: =+IFERROR(HLOOKUP($B14,'[1]11월'!$D$6:$BN$259,3,),)/1000 -> 2141.9971 | P14: =+IFERROR(HLOOKUP($B14,'[2]11월'!$F$6:$CP$99,3,),)/1000 -> 1935.4703 | Q14: =+P14-O14 -> -206.52677 | R14: =+IFERROR(HLOOKUP($B14,'[3]11월'!$F$6:$CC$57,3,),)/1000 -> 1827.7784 | S14: =+P14-R14 -> 107.69189 | T14: =+IFERROR(HLOOKUP($B14,'[1]11월'!$D$6:$BN$259,16,),)/1000 -> 217.22613 | U14: =+IFERROR(HLOOKUP($B14,'[2]11월'!$F$6:$CP$99,16,),)/1000 -> 103.48471 | V14: =+U14-T14 -> -113.74142 | W14: =+IFERROR(HLOOKUP($B14,'[3]11월'!$F$6:$CC$57,16,),)/1000 -> 141.17147 | X14: =+U14-W14 -> -37.686762 | Y14: =+[4]정관!$Q$85 -> 101999.86 | Z14: =+[4]정관!$R$85 -> 98023.312 | AA14: =+[5]정관!$Q$85 -> 101189.08 | AB14: =+[4]정관!$Q$89 -> 82449.919 | AC14: =+[4]정관!$R$89 -> 81988.449 | AD14: =+[5]정관!$Q$89 -> 82675.659 | AE14: =+Y14-AB14 -> 19549.942 | AF14: =+Z14-AC14 -> 16034.863 | AG14: =+AA14-AD14 -> 18513.424
B15: 양산 | G15: =+I15 -> 양산 | I15: 양산 | J15: =+IFERROR(HLOOKUP($B15,'[1]11월'!$D$6:$BN$259,2,),)/1000 -> 13 | K15: =+IFERROR(HLOOKUP($B15,'[2]11월'!$F$6:$CP$99,2,),)/1000 -> 9.445 | L15: =+K15-J15 -> -3.555 | M15: =+IFERROR(HLOOKUP($B15,'[3]11월'!$F$6:$CC$57,2,),)/1000 -> 10.32 | N15: =+K15-M15 -> -0.875 | O15: =+IFERROR(HLOOKUP($B15,'[1]11월'!$D$6:$BN$259,3,),)/1000 -> 1222.6012 | P15: =+IFERROR(HLOOKUP($B15,'[2]11월'!$F$6:$CP$99,3,),)/1000 -> 853.392 | Q15: =+P15-O15 -> -369.20925 | R15: =+IFERROR(HLOOKUP($B15,'[3]11월'!$F$6:$CC$57,3,),)/1000 -> 1034.8856 | S15: =+P15-R15 -> -181.4936 | T15: =+IFERROR(HLOOKUP($B15,'[1]11월'!$D$6:$BN$259,16,),)/1000 -> 119.63528 | U15: =+IFERROR(HLOOKUP($B15,'[2]11월'!$F$6:$CP$99,16,),)/1000 -> -7.408493 | V15: =+U15-T15 -> -127.04377 | W15: =+IFERROR(HLOOKUP($B15,'[3]11월'!$F$6:$CC$57,16,),)/1000 -> 98.711031 | X15: =+U15-W15 -> -106.11952 | Y15: =+[4]양산!$Q$85 -> 94046.25 | Z15: =+[4]양산!$R$85 -> 90353.838 | AA15: =+[5]양산!$Q$85 -> 100279.61 | AB15: =+[4]양산!$Q$89 -> 74328.036 | AC15: =+[4]양산!$R$89 -> 76357.628 | AD15: =+[5]양산!$Q$89 -> 76706.995 | AE15: =+Y15-AB15 -> 19718.214 | AF15: =+Z15-AC15 -> 13996.21 | AG15: =+AA15-AD15 -> 23572.618
B16: 창원 | G16: =+I16 -> 창원 | I16: 창원 | J16: =+IFERROR(HLOOKUP($B16,'[1]11월'!$D$6:$BN$259,2,),)/1000 -> 19 | K16: =+IFERROR(HLOOKUP($B16,'[2]11월'!$F$6:$CP$99,2,),)/1000 -> 12.547 | L16: =+K16-J16 -> -6.453 | M16: =+IFERROR(HLOOKUP($B16,'[3]11월'!$F$6:$CC$57,2,),)/1000 -> 13.393 | N16: =+K16-M16 -> -0.846 | O16: =+IFERROR(HLOOKUP($B16,'[1]11월'!$D$6:$BN$259,3,),)/1000 -> 1900.0061 | P16: =+IFERROR(HLOOKUP($B16,'[2]11월'!$F$6:$CP$99,3,),)/1000 -> 1207.625 | Q16: =+P16-O16 -> -692.38107 | R16: =+IFERROR(HLOOKUP($B16,'[3]11월'!$F$6:$CC$57,3,),)/1000 -> 1320.8885 | S16: =+P16-R16 -> -113.2635 | T16: =+IFERROR(HLOOKUP($B16,'[1]11월'!$D$6:$BN$259,16,),)/1000 -> 275.53524 | U16: =+IFERROR(HLOOKUP($B16,'[2]11월'!$F$6:$CP$99,16,),)/1000 -> 95.80599 | V16: =+U16-T16 -> -179.72925 | W16: =+IFERROR(HLOOKUP($B16,'[3]11월'!$F$6:$CC$57,16,),)/1000 -> 134.08562 | X16: =+U16-W16 -> -38.279632 | Y16: =+[4]창원!$Q$85 -> 100000.32 | Z16: =+[4]창원!$R$85 -> 96248.107 | AA16: =+[5]창원!$Q$85 -> 98625.289 | AB16: =+[4]창원!$Q$89 -> 76084.263 | AC16: =+[4]창원!$R$89 -> 74573.52 | AD16: =+[5]창원!$Q$89 -> 75355.289 | AE16: =+Y16-AB16 -> 23916.056 | AF16: =+Z16-AC16 -> 21674.587 | AG16: =+AA16-AD16 -> 23270
B17: 대구 | G17: =+I17 -> 대구 | I17: 대구 | J17: =+IFERROR(HLOOKUP($B17,'[1]11월'!$D$6:$BN$259,2,),)/1000 -> 12 | K17: =+IFERROR(HLOOKUP($B17,'[2]11월'!$F$6:$CP$99,2,),)/1000 -> 6.8825 | L17: =+K17-J17 -> -5.1175 | M17: =+IFERROR(HLOOKUP($B17,'[3]11월'!$F$6:$CC$57,2,),)/1000 -> 15.449 | N17: =+K17-M17 -> -8.5665 | O17: =+IFERROR(HLOOKUP($B17,'[1]11월'!$D$6:$BN$259,3,),)/1000 -> 1167.0317 | P17: =+IFERROR(HLOOKUP($B17,'[2]11월'!$F$6:$CP$99,3,),)/1000 -> 568.60345 | Q17: =+P17-O17 -> -598.42823 | R17: =+IFERROR(HLOOKUP($B17,'[3]11월'!$F$6:$CC$57,3,),)/1000 -> 1485.4652 | S17: =+P17-R17 -> -916.8618 | T17: =+IFERROR(HLOOKUP($B17,'[1]11월'!$D$6:$BN$259,16,),)/1000 -> 122.69105 | U17: =+IFERROR(HLOOKUP($B17,'[2]11월'!$F$6:$CP$99,16,),)/1000 -> -68.392861 | V17: =+U17-T17 -> -191.08391 | W17: =+IFERROR(HLOOKUP($B17,'[3]11월'!$F$6:$CC$57,16,),)/1000 -> 166.75688 | X17: =+U17-W17 -> -235.14975 | Y17: =+[4]대구!$Q$85 -> 97252.64 | Z17: =+[4]대구!$R$85 -> 82615.83 | AA17: =+[5]대구!$Q$85 -> 96152.842 | AB17: =+[4]대구!$Q$89 -> 73374.505 | AC17: =+[4]대구!$R$89 -> 72469.451 | AD17: =+[5]대구!$Q$89 -> 74152.653 | AE17: =+Y17-AB17 -> 23878.135 | AF17: =+Z17-AC17 -> 10146.379 | AG17: =+AA17-AD17 -> 22000.188
B18: 울산 | G18: =+I18 -> 울산 | I18: 울산 | J18: =+IFERROR(HLOOKUP($B18,'[1]11월'!$D$6:$BN$259,2,),)/1000 -> 13 | K18: =+IFERROR(HLOOKUP($B18,'[2]11월'!$F$6:$CP$99,2,),)/1000 -> 13.501 | L18: =+K18-J18 -> 0.501 | M18: =+IFERROR(HLOOKUP($B18,'[3]11월'!$F$6:$CC$57,2,),)/1000 -> 12.988 | N18: =+K18-M18 -> 0.513 | O18: =+IFERROR(HLOOKUP($B18,'[1]11월'!$D$6:$BN$259,3,),)/1000 -> 1348.1545 | P18: =+IFERROR(HLOOKUP($B18,'[2]11월'!$F$6:$CP$99,3,),)/1000 -> 1412.8064 | Q18: =+P18-O18 -> 64.6519 | R18: =+IFERROR(HLOOKUP($B18,'[3]11월'!$F$6:$CC$57,3,),)/1000 -> 1407.4653 | S18: =+P18-R18 -> 5.3411 | T18: =+IFERROR(HLOOKUP($B18,'[1]11월'!$D$6:$BN$259,16,),)/1000 -> 117.51597 | U18: =+IFERROR(HLOOKUP($B18,'[2]11월'!$F$6:$CP$99,16,),)/1000 -> 92.955994 | V18: =+U18-T18 -> -24.559978 | W18: =+IFERROR(HLOOKUP($B18,'[3]11월'!$F$6:$CC$57,16,),)/1000 -> 169.85775 | X18: =+U18-W18 -> -76.901755 | Y18: =+[4]울산!$Q$85 -> 103704.19 | Z18: =+[4]울산!$R$85 -> 104644.57 | AA18: =+[5]울산!$Q$85 -> 108366.59 | AB18: =+[4]울산!$Q$89 -> 83891.327 | AC18: =+[4]울산!$R$89 -> 86810.408 | AD18: =+[5]울산!$Q$89 -> 83931.342 | AE18: =+Y18-AB18 -> 19812.865 | AF18: =+Z18-AC18 -> 17834.166 | AG18: =+AA18-AD18 -> 24435.25
B19: 아산 | G19: =+I19 -> 아산 | I19: 아산 | J19: =+IFERROR(HLOOKUP($B19,'[1]11월'!$D$6:$BN$259,2,),)/1000 -> 26 | K19: =+IFERROR(HLOOKUP($B19,'[2]11월'!$F$6:$CP$99,2,),)/1000 -> 23.862 | L19: =+K19-J19 -> -2.138 | M19: =+IFERROR(HLOOKUP($B19,'[3]11월'!$F$6:$CC$57,2,),)/1000 -> 27.751 | N19: =+K19-M19 -> -3.889 | O19: =+IFERROR(HLOOKUP($B19,'[1]11월'!$D$6:$BN$259,3,),)/1000 -> 2678 | P19: =+IFERROR(HLOOKUP($B19,'[2]11월'!$F$6:$CP$99,3,),)/1000 -> 2428.1659 | Q19: =+P19-O19 -> -249.83413 | R19: =+IFERROR(HLOOKUP($B19,'[3]11월'!$F$6:$CC$57,3,),)/1000 -> 2807.1351 | S19: =+P19-R19 -> -378.96927 | T19: =+IFERROR(HLOOKUP($B19,'[1]11월'!$D$6:$BN$259,16,),)/1000 -> 389.43541 | U19: =+IFERROR(HLOOKUP($B19,'[2]11월'!$F$6:$CP$99,16,),)/1000 -> 175.51435 | V19: =+U19-T19 -> -213.92106 | W19: =+IFERROR(HLOOKUP($B19,'[3]11월'!$F$6:$CC$57,16,),)/1000 -> 245.55114 | X19: =+U19-W19 -> -70.036791 | Y19: =+[4]아산!$Q$85 -> 103000 | Z19: =+[4]아산!$R$85 -> 101758.69 | AA19: =+[5]아산!$Q$85 -> 100993.94 | AB19: =+[4]아산!$Q$89 -> 78637.252 | AC19: =+[4]아산!$R$89 -> 84413.805 | AD19: =+[5]아산!$Q$89 -> 82819.722 | AE19: =+Y19-AB19 -> 24362.748 | AF19: =+Z19-AC19 -> 17344.885 | AG19: =+AA19-AD19 -> 18174.222
B20: 전주 | G20: =+I20 -> 전주 | I20: 전주 | J20: =+IFERROR(HLOOKUP($B20,'[1]11월'!$D$6:$BN$259,2,),)/1000 -> 12 | K20: =+IFERROR(HLOOKUP($B20,'[2]11월'!$F$6:$CP$99,2,),)/1000 -> 15.8015 | L20: =+K20-J20 -> 3.8015 | M20: =+IFERROR(HLOOKUP($B20,'[3]11월'!$F$6:$CC$57,2,),)/1000 -> 9.1185 | N20: =+K20-M20 -> 6.683 | O20: =+IFERROR(HLOOKUP($B20,'[1]11월'!$D$6:$BN$259,3,),)/1000 -> 1210.3029 | P20: =+IFERROR(HLOOKUP($B20,'[2]11월'!$F$6:$CP$99,3,),)/1000 -> 1575.5214 | Q20: =+P20-O20 -> 365.21851 | R20: =+IFERROR(HLOOKUP($B20,'[3]11월'!$F$6:$CC$57,3,),)/1000 -> 903.67658 | S20: =+P20-R20 -> 671.84481 | T20: =+IFERROR(HLOOKUP($B20,'[1]11월'!$D$6:$BN$259,16,),)/1000 -> 177.68968 | U20: =+IFERROR(HLOOKUP($B20,'[2]11월'!$F$6:$CP$99,16,),)/1000 -> 186.91676 | V20: =+U20-T20 -> 9.2270822 | W20: =+IFERROR(HLOOKUP($B20,'[3]11월'!$F$6:$CC$57,16,),)/1000 -> 64.246477 | X20: =+U20-W20 -> 122.67029 | Y20: =+[4]전주!$Q$85 -> 100858.57 | Z20: =+[4]전주!$R$85 -> 99707.078 | AA20: =+[5]전주!$Q$85 -> 99117.984 | AB20: =+[4]전주!$Q$89 -> 73900.108 | AC20: =+[4]전주!$R$89 -> 77143.633 | AD20: =+[5]전주!$Q$89 -> 76865.183 | AE20: =+Y20-AB20 -> 26958.466 | AF20: =+Z20-AC20 -> 22563.444 | AG20: =+AA20-AD20 -> 22252.801
B21: 군산 | G21: =+I21 -> 군산 | I21: 군산 | J21: =+IFERROR(HLOOKUP($B21,'[1]11월'!$D$6:$BN$259,2,),)/1000 -> 7.5 | K21: =+IFERROR(HLOOKUP($B21,'[2]11월'!$F$6:$CP$99,2,),)/1000 -> 4.213 | L21: =+K21-J21 -> -3.287 | M21: =+IFERROR(HLOOKUP($B21,'[3]11월'!$F$6:$CC$57,2,),)/1000 -> 7.147 | N21: =+K21-M21 -> -2.934 | O21: =+IFERROR(HLOOKUP($B21,'[1]11월'!$D$6:$BN$259,3,),)/1000 -> 833.2516 | P21: =+IFERROR(HLOOKUP($B21,'[2]11월'!$F$6:$CP$99,3,),)/1000 -> 477.69554 | Q21: =+P21-O21 -> -355.55606 | R21: =+IFERROR(HLOOKUP($B21,'[3]11월'!$F$6:$CC$57,3,),)/1000 -> 764.9177 | S21: =+P21-R21 -> -287.22216 | T21: =+IFERROR(HLOOKUP($B21,'[1]11월'!$D$6:$BN$259,16,),)/1000 -> 207.99971 | U21: =+IFERROR(HLOOKUP($B21,'[2]11월'!$F$6:$CP$99,16,),)/1000 -> 88.643465 | V21: =+U21-T21 -> -119.35624 | W21: =+IFERROR(HLOOKUP($B21,'[3]11월'!$F$6:$CC$57,16,),)/1000 -> 153.19348 | X21: =+U21-W21 -> -64.550012 | Y21: =+[4]군산!$Q$85 -> 111100.21 | Z21: =+[4]군산!$R$85 -> 113386.08 | AA21: =+[5]군산!$Q$85 -> 107026.4 | AB21: =+[4]군산!$Q$89 -> 72961.062 | AC21: =+[4]군산!$R$89 -> 71279.945 | AD21: =+[5]군산!$Q$89 -> 73409.949 | AE21: =+Y21-AB21 -> 38139.151 | AF21: =+Z21-AC21 -> 42106.131 | AG21: =+AA21-AD21 -> 33616.454
B22: 원주 | G22: =+I22 -> 원주 | I22: 원주 | J22: =+IFERROR(HLOOKUP($B22,'[1]11월'!$D$6:$BN$259,2,),)/1000 -> 6 | K22: =+IFERROR(HLOOKUP($B22,'[2]11월'!$F$6:$CP$99,2,),)/1000 -> 3.611 | L22: =+K22-J22 -> -2.389 | M22: =+IFERROR(HLOOKUP($B22,'[3]11월'!$F$6:$CC$57,2,),)/1000 -> 4.554 | N22: =+K22-M22 -> -0.943 | O22: =+IFERROR(HLOOKUP($B22,'[1]11월'!$D$6:$BN$259,3,),)/1000 -> 672 | P22: =+IFERROR(HLOOKUP($B22,'[2]11월'!$F$6:$CP$99,3,),)/1000 -> 427.5916 | Q22: =+P22-O22 -> -244.4084 | R22: =+IFERROR(HLOOKUP($B22,'[3]11월'!$F$6:$CC$57,3,),)/1000 -> 521.4149 | S22: =+P22-R22 -> -93.8233 | T22: =+IFERROR(HLOOKUP($B22,'[1]11월'!$D$6:$BN$259,16,),)/1000 -> 145.42812 | U22: =+IFERROR(HLOOKUP($B22,'[2]11월'!$F$6:$CP$99,16,),)/1000 -> 57.96605 | V22: =+U22-T22 -> -87.462072 | W22: =+IFERROR(HLOOKUP($B22,'[3]11월'!$F$6:$CC$57,16,),)/1000 -> 96.375569 | X22: =+U22-W22 -> -38.409519 | Y22: =+[4]원주!$Q$85 -> 112000 | Z22: =+[4]원주!$R$85 -> 118413.63 | AA22: =+[5]원주!$Q$85 -> 114496.03 | AB22: =+[4]원주!$Q$89 -> 73238.886 | AC22: =+[4]원주!$R$89 -> 77803.148 | AD22: =+[5]원주!$Q$89 -> 74946.434 | AE22: =+Y22-AB22 -> 38761.114 | AF22: =+Z22-AC22 -> 40610.477 | AG22: =+AA22-AD22 -> 39549.592
B23: 제주 | F23: =+K27-J27 -> -51.4095 | G23: =+I23 -> 제주 | I23: 제주 | J23: =+IFERROR(HLOOKUP($B23,'[1]11월'!$D$6:$BN$259,2,),)/1000 -> 9 | K23: =+IFERROR(HLOOKUP($B23,'[2]11월'!$F$6:$CP$99,2,),)/1000 -> 4.187 | L23: =+K23-J23 -> -4.813 | M23: =+IFERROR(HLOOKUP($B23,'[3]11월'!$F$6:$CC$57,2,),)/1000 -> 2.901 | N23: =+K23-M23 -> 1.286 | O23: =+IFERROR(HLOOKUP($B23,'[1]11월'!$D$6:$BN$259,3,),)/1000 -> 1106.96 | P23: =+IFERROR(HLOOKUP($B23,'[2]11월'!$F$6:$CP$99,3,),)/1000 -> 534.21702 | Q23: =+P23-O23 -> -572.74298 | R23: =+IFERROR(HLOOKUP($B23,'[3]11월'!$F$6:$CC$57,3,),)/1000 -> 350.95144 | S23: =+P23-R23 -> 183.26558 | T23: =+IFERROR(HLOOKUP($B23,'[1]11월'!$D$6:$BN$259,16,),)/1000 -> 184.3004 | U23: =+IFERROR(HLOOKUP($B23,'[2]11월'!$F$6:$CP$99,16,),)/1000 -> 40.13815 | V23: =+U23-T23 -> -144.16225 | W23: =+IFERROR(HLOOKUP($B23,'[3]11월'!$F$6:$CC$57,16,),)/1000 -> -11.658004 | X23: =+U23-W23 -> 51.796154 | Y23: =+[4]제주!$Q$85 -> 122995.56 | Z23: =+[4]제주!$R$85 -> 127614.34 | AA23: =+[5]제주!$Q$85 -> 120976.02 | AB23: =+[4]제주!$Q$89 -> 91386.196 | AC23: =+[4]제주!$R$89 -> 96237.592 | AD23: =+[5]제주!$Q$89 -> 91677.915 | AE23: =+Y23-AB23 -> 31609.36 | AF23: =+Z23-AC23 -> 31376.749 | AG23: =+AA23-AD23 -> 29298.106
F24: =+K24/J24 -> 0.82776339 | G24: =+I24 -> 수도권 | I24: 수도권 | J24: =SUM(J7:J10) -> 112 | K24: =SUM(K7:K10) -> 92.7095 | L24: =+K24-J24 -> -19.2905 | M24: =SUM(M7:M10) -> 107.646 | N24: =+K24-M24 -> -14.9365 | O24: =SUM(O7:O10) -> 11308.247 | P24: =SUM(P7:P10) -> 8919.8223 | Q24: =+P24-O24 -> -2388.4252 | R24: =SUM(R7:R10) -> 10479.18 | S24: =+P24-R24 -> -1559.3582 | T24: =SUM(T7:T10) -> 1219.4813 | U24: =SUM(U7:U10) -> 196.74248 | V24: =+U24-T24 -> -1022.7388 | W24: =SUM(W7:W10) -> 553.11277 | X24: =+U24-W24 -> -356.37029 | Y24: =+[4]수도권!$Q$85 -> 100966.5 | Z24: =+[4]수도권!$R$85 -> 96297.03 | AA24: =+[5]수도권!$Q$85 -> 97363.141 | AB24: =+[4]수도권!$Q$89 -> 81616.665 | AC24: =+[4]수도권!$R$89 -> 83046.124 | AD24: =+[5]수도권!$Q$89 -> 83203.071 | AE24: =+Y24-AB24 -> 19349.831 | AF24: =+Z24-AC24 -> 13250.906 | AG24: =+AA24-AD24 -> 14160.07
F25: =+K25/J25 -> 0.83120652 | G25: =+I25 -> 영남권 | I25: 영남권 | J25: =SUM(J11:J18) -> 138 | K25: =SUM(K11:K18) -> 114.7065 | L25: =+K25-J25 -> -23.2935 | M25: =SUM(M11:M18) -> 121.551 | N25: =+K25-M25 -> -6.8445 | O25: =SUM(O11:O18) -> 13866.176 | P25: =SUM(P11:P18) -> 11493.138 | Q25: =+P25-O25 -> -2373.038 | R25: =SUM(R11:R18) -> 12242.393 | S25: =+P25-R25 -> -749.25455 | T25: =SUM(T11:T18) -> 1485.3325 | U25: =SUM(U11:U18) -> 628.3981 | V25: =+U25-T25 -> -856.9344 | W25: =SUM(W11:W18) -> 1095.102 | X25: =+U25-W25 -> -466.70387 | Y25: =+[4]영남권!$Q$85 -> 100479.54 | Z25: =+[4]영남권!$R$85 -> 100200.79 | AA25: =+[5]영남권!$Q$85 -> 100718.16 | AB25: =+[4]영남권!$Q$89 -> 79388.094 | AC25: =+[4]영남권!$R$89 -> 82102.552 | AD25: =+[5]영남권!$Q$89 -> 79490.263 | AE25: =+Y25-AB25 -> 21091.445 | AF25: =+Z25-AC25 -> 18098.237 | AG25: =+AA25-AD25 -> 21227.896
F26: =+K26/J26 -> 0.85412397 | G26: =+I26 -> 중부권 | I26: 중부권 | J26: =SUM(J19:J23) -> 60.5 | K26: =SUM(K19:K23) -> 51.6745 | L26: =+K26-J26 -> -8.8255 | M26: =SUM(M19:M23) -> 51.4715 | N26: =+K26-M26 -> 0.203 | O26: =SUM(O19:O23) -> 6500.5145 | P26: =SUM(P19:P23) -> 5443.1914 | Q26: =+P26-O26 -> -1057.3231 | R26: =SUM(R19:R23) -> 5348.0958 | S26: =+P26-R26 -> 95.095657 | T26: =SUM(T19:T23) -> 1104.8533 | U26: =SUM(U19:U23) -> 549.17878 | V26: =+U26-T26 -> -555.67454 | W26: =SUM(W19:W23) -> 547.70866 | X26: =+U26-W26 -> 1.470117 | Y26: =+[4]중부권!$Q$85 -> 107446.52 | Z26: =+[4]중부권!$R$85 -> 105331.24 | AA26: =+[5]중부권!$Q$85 -> 103847.09 | AB26: =+[4]중부권!$Q$89 -> 78355.155 | AC26: =+[4]중부권!$R$89 -> 81611.885 | AD26: =+[5]중부권!$Q$89 -> 80246.621 | AE26: =+Y26-AB26 -> 29091.365 | AF26: =+Z26-AC26 -> 23719.354 | AG26: =+AA26-AD26 -> 23600.464
F27: =+K27/M27 -> 0.92311927 | G27: =+K27/J27 -> 0.83442995 | H27: 레미콘 계 | J27: =SUM(J24:J26) -> 310.5 | K27: =SUM(K24:K26) -> 259.0905 | L27: =+K27-J27 -> -51.4095 | M27: =SUM(M24:M26) -> 280.6685 | N27: =+K27-M27 -> -21.578 | O27: =SUM(O24:O26) -> 31674.938 | P27: =SUM(P24:P26) -> 25856.152 | Q27: =+P27-O27 -> -5818.7863 | R27: =SUM(R24:R26) -> 28069.669 | S27: =+P27-R27 -> -2213.5171 | T27: =SUM(T24:T26) -> 3809.6671 | U27: =SUM(U24:U26) -> 1374.3194 | V27: =+U27-T27 -> -2435.3478 | W27: =SUM(W24:W26) -> 2195.9234 | X27: =+U27-W27 -> -821.60404 | Y27: =+[4]합계!$Q$85 -> 102012.68 | Z27: =+[4]합계!$R$85 -> 99838.666 | AA27: =+[5]합계!$Q$85 -> 100000.5 | AB27: =+[4]합계!$Q$89 -> 79990.693 | AC27: =+[4]합계!$R$89 -> 82340.282 | AD27: =+[5]합계!$Q$89 -> 81042.566 | AE27: =+Y27-AB27 -> 22021.99 | AF27: =+Z27-AC27 -> 17498.384 | AG27: =+AA27-AD27 -> 18957.932 | AI27: =+AF27-AE27 -> -4523.6063 | AJ27: =+AF27-AG27 -> -1459.5482
B28: 건자재 | E28: 건자재영업 | G28: 건자재 | H28: 건자재 | J28: =+IFERROR(HLOOKUP($B28,'[1]11월'!$D$6:$BN$259,2,),) -> 12600 | K28: =+IFERROR(HLOOKUP($E28,'[2]11월'!$F$6:$CP$99,2,),) -> 9321.418 | L28: =+K28-J28 -> -3278.582 | M28: =+IFERROR(HLOOKUP($E28,'[3]11월'!$F$6:$CC$57,2,),) -> 10221.802 | N28: =+K28-M28 -> -900.384 | O28: =+IFERROR(HLOOKUP($B28,'[1]11월'!$D$6:$BN$259,3,),)/1000 -> 13712.919 | P28: =+IFERROR(HLOOKUP($E28,'[2]11월'!$F$6:$CP$99,3,),)/1000 -> 8458.8501 | Q28: =+P28-O28 -> -5254.0687 | R28: =+IFERROR(HLOOKUP($E28,'[3]11월'!$F$6:$CC$57,3,),)/1000 -> 9942.869 | S28: =+P28-R28 -> -1484.0189 | T28: =+IFERROR(HLOOKUP($B28,'[1]11월'!$D$6:$BN$259,16,),)/1000 -> 247.89226 | U28: =+IFERROR(HLOOKUP($E28,'[2]11월'!$F$6:$CP$99,16,),)/1000 -> 22.991546 | V28: =+U28-T28 -> -224.90072 | W28: =+IFERROR(HLOOKUP($E28,'[3]11월'!$F$6:$CC$57,16,),)/1000 -> 118.35665 | X28: =+U28-W28 -> -95.365103 | Y28: ■ 비고
