Workbook

Sheet 표지
A6: 2025년 1월 마감 손익
A24: 건재사업본부

Sheet 손익총괄
C3: □ 건재사업본부 손익실적(2025-01) | Z3: □ 건재부문 실적(1월)
X4: [단위 : 천㎥, 톤, 원/㎥, 원/톤, 백만원] | AK4: (단위 : 천㎥, 천톤, 억원)
C5: 구분 | E5: 1월 | J5: 1월 누계 | P5: 1월 주요지표 | Z5: 구분 | AB5: =+E5 -> 1월 | AG5: =+J5 -> 1월 누계
A6: 2024년 11월 마감 손익 | E6: 계획 | F6: 실적 | G6: 계획대비 | H6: 전년 | I6: 전년대비 | J6: 계획 | K6: 실적 | L6: 계획대비 | M6: 전년 | N6: 전년대비 | AB6: =+E6 -> 계획 | AC6: =+F6 -> 실적 | AD6: =+G6 -> 계획대비 | AE6: =+H6 -> 전년 | AF6: =+I6 -> 전년대비 | AG6: =+J6 -> 계획 | AH6: =+K6 -> 실적 | AI6: =+L6 -> 계획대비 | ... AK6: =+N6 -> 전년대비
A7: =+F7/E7 -> 0.85932126 | B7: =+K7/J7 -> 0.85932126 | C7: 물량 | D7: 레미콘 | E7: =+'[1]1월'!$Z$7/1000 -> 207 | F7: =+'[2]1월'!$Z$7/1000 -> 177.8795 | G7: =+F7-E7 -> -29.1205 | H7: =+'[3]1월'!$Z$7/1000 -> 278.8855 | I7: =+F7-H7 -> -101.006 | J7: =+E7 -> 207 | K7: =+F7 -> 177.8795 | L7: =+K7-J7 -> -29.1205 | M7: =+H7 -> 278.8855 | N7: =+K7-M7 -> -101.006 | Q7: □ 레미콘 | Z7: 물량 | AA7: =+D7 -> 레미콘 | AB7: =+E7 -> 207 | AC7: =+F7 -> 177.8795 | AD7: =+AC7-AB7 -> -29.1205 | AE7: =+H7 -> 278.8855 | AF7: =+AC7-AE7 -> -101.006 | AG7: =+J7 -> 207 | AH7: =+K7 -> 177.8795 | AI7: =+AH7-AG7 -> -29.1205 | AJ7: =+M7 -> 278.8855 | AK7: =+AH7-AJ7 -> -101.006
D8: 철강재 | E8: =+'[1]1월'!$AA$7 -> 9800 | F8: =+'[2]1월'!$AO$7 -> 8735.502 | G8: =+F8-E8 -> -1064.498 | H8: =+'[3]1월'!$AO$7 -> 6425.093 | I8: =+F8-H8 -> 2310.409 | J8: =+E8 -> 9800 | K8: =+F8 -> 8735.502 | L8: =+K8-J8 -> -1064.498 | M8: =+H8 -> 6425.093 | N8: =+K8-M8 -> 2310.409 | Q8: 구분 | S8: 계획 | T8: 실적 | U8: 계획대비 | V8: 전년 | W8: 전년대비 | AA8: =+D8 -> 철강재 | AB8: =+E8/1000 -> 9.8 | AC8: =+F8/1000 -> 8.735502 | AD8: =+AC8-AB8 -> -1.064498 | AE8: =+H8/1000 -> 6.425093 | AF8: =+AC8-AE8 -> 2.310409 | AG8: =+J8/1000 -> 9.8 | AH8: =+K8/1000 -> 8.735502 | AI8: =+AH8-AG8 -> -1.064498 | AJ8: =+M8/1000 -> 6.425093 | AK8: =+AH8-AJ8 -> 2.310409
D9: 골재 | E9: =+'[1]1월'!$AE$7/1000 -> 90.818291 | F9: =+'[2]1월'!$AN$7/1000 -> 48.252 | G9: =+F9-E9 -> -42.566291 | H9: =+'[3]1월'!$AN$7/1000 -> 84.517 | I9: =+F9-H9 -> -36.265 | J9: =+E9 -> 90.818291 | K9: =+F9 -> 48.252 | L9: =+K9-J9 -> -42.566291 | M9: =+H9 -> 84.517 | N9: =+K9-M9 -> -36.265 | Q9: 물량 | R9: 수도권 | S9: =+[4]수도권!$T$5/1000 -> 76 | T9: =+[4]수도권!$U$5/1000 -> 56.9285 | U9: =+T9-S9 -> -19.0715 | V9: =+[5]수도권!$T$5/1000 -> 102.264 | W9: =+T9-V9 -> -45.3355 | AA9: =+D9 -> 골재 | AB9: =+E9 -> 90.818291 | AC9: =+F9 -> 48.252 | AD9: =+AC9-AB9 -> -42.566291 | AE9: =+H9 -> 84.517 | AF9: =+AC9-AE9 -> -36.265 | AG9: =+J9 -> 90.818291 | AH9: =+K9 -> 48.252 | AI9: =+AH9-AG9 -> -42.566291 | AJ9: =+M9 -> 84.517 | AK9: =+AH9-AJ9 -> -36.265
C10: 매출 | D10: 레미콘 | E10: =+'[1]1월'!$Z$8/1000 -> 20815.893 | F10: =+'[2]1월'!$Z$8/1000 -> 17974.392 | G10: =+F10-E10 -> -2841.501 | H10: =+'[3]1월'!$Z$8/1000 -> 27875.646 | I10: =+F10-H10 -> -9901.2538 | J10: =+E10 -> 20815.893 | K10: =+F10 -> 17974.392 | L10: =+K10-J10 -> -2841.501 | M10: =+H10 -> 27875.646 | N10: =+K10-M10 -> -9901.2538 | R10: 영남권 | S10: =+[4]영남권!$T$5/1000 -> 97 | T10: =+[4]영남권!$U$5/1000 -> 81.123 | U10: =+T10-S10 -> -15.877 | V10: =+[5]영남권!$T$5/1000 -> 132.898 | W10: =+T10-V10 -> -51.775 | Z10: 매출액 | AA10: =+D10 -> 레미콘 | AB10: =+E10/100 -> 208.15893 | AC10: =+F10/100 -> 179.74392 | AD10: =+AC10-AB10 -> -28.41501 | AE10: =+H10/100 -> 278.75646 | AF10: =+AC10-AE10 -> -99.012538 | AG10: =+J10/100 -> 208.15893 | AH10: =+K10/100 -> 179.74392 | AI10: =+AH10-AG10 -> -28.41501 | AJ10: =+M10/100 -> 278.75646 | AK10: =+AH10-AJ10 -> -99.012538
D11: 건자재 | E11: =+'[1]1월'!$AA$8/1000 -> 10731.323 | F11: =+'[2]1월'!$AO$8/1000 -> 7480.1197 | G11: =+F11-E11 -> -3251.2031 | H11: =+'[3]1월'!$AO$8/1000 -> 7407.9572 | I11: =+F11-H11 -> 72.162517 | J11: =+E11 -> 10731.323 | K11: =+F11 -> 7480.1197 | L11: =+K11-J11 -> -3251.2031 | M11: =+H11 -> 7407.9572 | N11: =+K11-M11 -> 72.162517 | R11: 중부권 | S11: =+[4]중부권!$T$5/1000 -> 34 | T11: =+[4]중부권!$U$5/1000 -> 39.828 | U11: =+T11-S11 -> 5.828 | V11: =+[5]중부권!$T$5/1000 -> 43.7235 | W11: =+T11-V11 -> -3.8955 | AA11: =+D11 -> 건자재 | AB11: =+E11/100 -> 107.31323 | AC11: =+F11/100 -> 74.801197 | AD11: =+AC11-AB11 -> -32.512031 | AE11: =+H11/100 -> 74.079572 | AF11: =+AC11-AE11 -> 0.72162517 | AG11: =+J11/100 -> 107.31323 | AH11: =+K11/100 -> 74.801197 | AI11: =+AH11-AG11 -> -32.512031 | AJ11: =+M11/100 -> 74.079572 | AK11: =+AH11-AJ11 -> 0.72162517
D12: 골재 | E12: =+'[1]1월'!$AE$8/1000 -> 1640.1944 | F12: =+'[2]1월'!$AN$8/1000 -> 1051.748 | G12: =+F12-E12 -> -588.44644 | H12: =+'[3]1월'!$AN$8/1000 -> 1719.52 | I12: =+F12-H12 -> -667.772 | J12: =+E12 -> 1640.1944 | K12: =+F12 -> 1051.748 | L12: =+K12-J12 -> -588.44644 | M12: =+H12 -> 1719.52 | N12: =+K12-M12 -> -667.772 | Q12: 계 | S12: =SUM(S9:S11) -> 207 | T12: =SUM(T9:T11) -> 177.8795 | U12: =+T12-S12 -> -29.1205 | V12: =SUM(V9:V11) -> 278.8855 | W12: =+T12-V12 -> -101.006 | AA12: =+D12 -> 골재 | AB12: =+E12/100 -> 16.401944 | AC12: =+F12/100 -> 10.51748 | AD12: =+AC12-AB12 -> -5.8844644 | AE12: =+H12/100 -> 17.1952 | AF12: =+AC12-AE12 -> -6.67772 | AG12: =+J12/100 -> 16.401944 | AH12: =+K12/100 -> 10.51748 | AI12: =+AH12-AG12 -> -5.8844644 | AJ12: =+M12/100 -> 17.1952 | AK12: =+AH12-AJ12 -> -6.67772
D13: 기타 | E13: =+'[1]1월'!$E$8/1000-E10-E11-E12 -> 166.7015 | F13: =+'[2]1월'!$F$8/1000-F10-F11-F12 -> 167.2526 | G13: =+F13-E13 -> 0.551099 | H13: =+'[3]1월'!$F$8/1000-H10-H11-H12 -> 164.47551 | I13: =+F13-H13 -> 2.777088 | J13: =+E13 -> 166.7015 | K13: =+F13 -> 167.2526 | L13: =+K13-J13 -> 0.551099 | M13: =+H13 -> 164.47551 | N13: =+K13-M13 -> 2.777088 | Q13: 판매단가 | R13: 수도권 | S13: =+[4]수도권!$T$61 -> 97486.591 | T13: =+[4]수도권!$U$61 -> 99000.139 | U13: =+T13-S13 -> 1513.5475 | V13: =+[5]수도권!$Q$85 -> 97064.272 | W13: =+T13-V13 -> 1935.8664 | AA13: =+D13 -> 기타 | AB13: =+E13/100 -> 1.667015 | AC13: =+F13/100 -> 1.672526 | AD13: =+AC13-AB13 -> 0.00551099 | AE13: =+H13/100 -> 1.6447551 | AF13: =+AC13-AE13 -> 0.02777088 | AG13: =+J13/100 -> 1.667015 | AH13: =+K13/100 -> 1.672526 | AI13: =+AH13-AG13 -> 0.00551099 | AJ13: =+M13/100 -> 1.6447551 | AK13: =+AH13-AJ13 -> 0.02777088
A14: =+F14/E14 -> 0.79970687 | B14: =+K14/J14 -> 0.79970687 | C14: 계 | E14: =SUM(E10:E13) -> 33354.112 | F14: =SUM(F10:F13) -> 26673.512 | G14: =+F14-E14 -> -6680.5995 | H14: =SUM(H10:H13) -> 37167.599 | I14: =+F14-H14 -> -10494.086 | J14: =SUM(J10:J13) -> 33354.112 | K14: =SUM(K10:K13) -> 26673.512 | L14: =+K14-J14 -> -6680.5995 | M14: =SUM(M10:M13) -> 37167.599 | N14: =+K14-M14 -> -10494.086 | R14: 영남권 | S14: =+[4]영남권!$T$61 -> 100500.16 | T14: =+[4]영남권!$U$61 -> 100960.81 | U14: =+T14-S14 -> 460.65932 | V14: =+[5]영남권!$Q$85 -> 101515.92 | W14: =+T14-V14 -> -555.10948 | AA14: 계 | AB14: =SUM(AB10:AB13) -> 333.54112 | AC14: =SUM(AC10:AC13) -> 266.73512 | AD14: =+AC14-AB14 -> -66.805995 | AE14: =SUM(AE10:AE13) -> 371.67599 | AF14: =+AC14-AE14 -> -104.94086 | AG14: =SUM(AG10:AG13) -> 333.54112 | AH14: =SUM(AH10:AH13) -> 266.73512 | AI14: =+AH14-AG14 -> -66.805995 | AJ14: =SUM(AJ10:AJ13) -> 371.67599 | AK14: =+AH14-AJ14 -> -104.94086
C15: 매출원가 | D15: 레미콘 | E15: =+('[1]1월'!$Z$10+'[1]1월'!$Z$19)/1000 -> 19400.689 | F15: =+('[2]1월'!$Z$10+'[2]1월'!$Z$19)/1000 -> 17240.725 | G15: =+F15-E15 -> -2159.964 | H15: =+('[3]1월'!$Z$10+'[3]1월'!$Z$19)/1000 -> 24879.532 | I15: =+F15-H15 -> -7638.8068 | J15: =+E15 -> 19400.689 | K15: =+F15 -> 17240.725 | L15: =+K15-J15 -> -2159.964 | M15: =+H15 -> 24879.532 | N15: =+K15-M15 -> -7638.8068 | R15: 중부권 | S15: =+[4]중부권!$T$61 -> 107599.91 | T15: =+[4]중부권!$U$61 -> 103685.34 | U15: =+T15-S15 -> -3914.5715 | V15: =+[5]중부권!$Q$85 -> 101965.11 | W15: =+T15-V15 -> 1720.2292 | Z15: 영업이익 | AA15: =+D30 -> 레미콘 | AB15: =+E30/100 -> 7.4272509 | AC15: =+F30/100 -> 0.23138241 | AD15: =+AC15-AB15 -> -7.1958685 | AE15: =+H30/100 -> 23.245893 | AF15: =+AC15-AE15 -> -23.01451 | AG15: =+J30/100 -> 7.4272509 | AH15: =+K30/100 -> 0.23138241 | AI15: =+AH15-AG15 -> -7.1958685 | AJ15: =+M30/100 -> 23.245893 | AK15: =+AH15-AJ15 -> -23.01451
D16: 건자재 | E16: =+('[1]1월'!$AA$10+'[1]1월'!$AA$19)/1000 -> 10441.182 | F16: =+('[2]1월'!$AO$10+'[2]1월'!$AO$19)/1000 -> 7334.2092 | G16: =+F16-E16 -> -3106.9731 | H16: =+('[3]1월'!$AO$10+'[3]1월'!$AO$19)/1000 -> 7210.525 | I16: =+F16-H16 -> 123.68423 | J16: =+E16 -> 10441.182 | K16: =+F16 -> 7334.2092 | L16: =+K16-J16 -> -3106.9731 | M16: =+H16 -> 7210.525 | N16: =+K16-M16 -> 123.68423 | Q16: 계 | S16: =+[4]합계!$T$61 -> 100559.87 | T16: =+[4]합계!$U$61 -> 100932.18 | U16: =+T16-S16 -> 372.31106 | V16: =+[5]합계!$Q$85 -> 99953.913 | W16: =+T16-V16 -> 978.26829 | AA16: =+D31 -> % | AB16: =+E31 -> 0.035680674 | AC16: =+F31 -> 0.0012872892 | AD16: =+AC16-AB16 -> -0.034393384 | AE16: =+H31 -> 0.083391406 | AF16: =+AC16-AE16 -> -0.082104116 | AG16: =+J31 -> 0.035680674 | AH16: =+K31 -> 0.0012872892 | AI16: =+AH16-AG16 -> -0.034393384 | AJ16: =+M31 -> 0.083391406 | AK16: =+AH16-AJ16 -> -0.082104116
D17: 골재 | E17: =+('[1]1월'!$AE$10+'[1]1월'!$AE$19)/1000 -> 1515.603 | F17: =+('[2]1월'!$AN$10+'[2]1월'!$AN$19)/1000 -> 1282.2655 | G17: =+F17-E17 -> -233.33745 | H17: =+('[3]1월'!$AN$10+'[3]1월'!$AN$19)/1000 -> 1493.2747 | I17: =+F17-H17 -> -211.00915 | J17: =+E17 -> 1515.603 | K17: =+F17 -> 1282.2655 | L17: =+K17-J17 -> -233.33745 | M17: =+H17 -> 1493.2747 | N17: =+K17-M17 -> -211.00915 | Q17: 공헌이익 | R17: 수도권 | S17: =+[4]수도권!$Q$90 -> 15650.864 | T17: =+[4]수도권!$R$90 -> 13670.147 | U17: =+T17-S17 -> -1980.7169 | V17: =+[5]수도권!$Q$90 -> 14738.448 | W17: =+T17-V17 -> -1068.3016 | AA17: =+D32 -> 건자재 | AB17: =+E32/100 -> 1.6736132 | AC17: =+F32/100 -> 0.01697249 | AD17: =+AC17-AB17 -> -1.6566407 | AE17: =+H32/100 -> 0.75267211 | AF17: =+AC17-AE17 -> -0.73569962 | AG17: =+J32/100 -> 1.6736132 | AH17: =+K32/100 -> 0.01697249 | AI17: =+AH17-AG17 -> -1.6566407 | AJ17: =+M32/100 -> 0.75267211 | AK17: =+AH17-AJ17 -> -0.73569962
D18: 기타 | E18: =+('[1]1월'!$E$10+'[1]1월'!$E$19)/1000-E15-E16-E17 -> 28.444279 | F18: =+('[2]1월'!$F$10+'[2]1월'!$F$19)/1000-F15-F16-F17 -> 331.19036 | G18: =+F18-E18 -> 302.74608 | H18: =+('[3]1월'!$F$10+'[3]1월'!$F$19)/1000-H15-H16-H17 -> 28.511818 | I18: =+F18-H18 -> 302.67854 | J18: =+E18 -> 28.444279 | K18: =+F18 -> 331.19036 | L18: =+K18-J18 -> 302.74608 | M18: =+H18 -> 28.511818 | N18: =+K18-M18 -> 302.67854 | R18: 영남권 | S18: =+[4]영남권!$Q$90 -> 21016.894 | T18: =+[4]영남권!$R$90 -> 20157.906 | U18: =+T18-S18 -> -858.98784 | V18: =+[5]영남권!$Q$90 -> 22138.533 | W18: =+T18-V18 -> -1980.6276 | AA18: =+D33 -> 골재 | AB18: =+E33/100 -> 0.76977514 | AC18: =+F33/100 -> -2.8008746 | AD18: =+AC18-AB18 -> -3.5706497 | AE18: =+H33/100 -> 1.8407373 | AF18: =+AC18-AE18 -> -4.6416119 | AG18: =+J33/100 -> 0.76977514 | AH18: =+K33/100 -> -2.8008746 | AI18: =+AH18-AG18 -> -3.5706497 | AJ18: =+M33/100 -> 1.8407373 | AK18: =+AH18-AJ18 -> -4.6416119
C19: 계 | E19: =SUM(E15:E18) -> 31385.919 | F19: =SUM(F15:F18) -> 26188.39 | G19: =+F19-E19 -> -5197.5285 | H19: =SUM(H15:H18) -> 33611.844 | I19: =+F19-H19 -> -7423.4532 | J19: =SUM(J15:J18) -> 31385.919 | K19: =SUM(K15:K18) -> 26188.39 | L19: =+K19-J19 -> -5197.5285 | M19: =SUM(M15:M18) -> 33611.844 | N19: =+K19-M19 -> -7423.4532 | R19: 중부권 | S19: =+[4]중부권!$Q$90 -> 28185.784 | T19: =+[4]중부권!$R$90 -> 20761.141 | U19: =+T19-S19 -> -7424.6432 | V19: =+[5]중부권!$Q$90 -> 22621.219 | W19: =+T19-V19 -> -1860.0788 | AA19: 공통비 | AB19: =+'사업장별(당월)'!T35/100 -> -17.847168 | AC19: =+'사업장별(당월)'!U35/100 -> -16.37191 | AD19: =+AC19-AB19 -> 1.475258 | AE19: =+'사업장별(당월)'!W35/100 -> -15.492991 | AF19: =+AC19-AE19 -> -0.87891838 | AG19: =+AB19 -> -17.847168 | AH19: =+AC19 -> -16.37191 | AI19: =+AH19-AG19 -> 1.475258 | AJ19: =+AE19 -> -15.492991 | AK19: =+AH19-AJ19 -> -0.87891838
C20: 매출이익 | D20: 레미콘 | E20: =+E10-E15 -> 1415.2037 | F20: =+F10-F15 -> 733.66668 | G20: =+F20-E20 -> -681.53698 | H20: =+H10-H15 -> 2996.1137 | I20: =+F20-H20 -> -2262.447 | J20: =+J10-J15 -> 1415.2037 | K20: =+K10-K15 -> 733.66668 | L20: =+K20-J20 -> -681.53698 | M20: =+M10-M15 -> 2996.1137 | N20: =+K20-M20 -> -2262.447 | Q20: 계 | S20: =+[4]합계!$Q$90 -> 20224.256 | T20: =+[4]합계!$R$90 -> 18230.839 | U20: =+T20-S20 -> -1993.4169 | V20: =+[5]합계!$Q$90 -> 19500.633 | W20: =+T20-V20 -> -1269.7937 | AA20: =+'사업장별(당월)'!I34 -> 임대 | AB20: =+('사업장별(당월)'!T33+'사업장별(당월)'!T34)/100 -> 1.3648722 | AC20: =+('사업장별(당월)'!U33+'사업장별(당월)'!U34)/100 -> 1.3690627 | AD20: =+AC20-AB20 -> 0.00419047 | AE20: =+('사업장별(당월)'!W33+'사업장별(당월)'!W34)/100 -> 1.3362087 | AF20: =+AC20-AE20 -> 0.03285394 | AG20: =+AB20 -> 1.3648722 | AH20: =+AC20 -> 1.3690627 | AI20: =+AH20-AG20 -> 0.00419047 | AJ20: =+AE20 -> 1.3362087 | AK20: =+AH20-AJ20 -> 0.03285394
D21: 건자재 | E21: =+E11-E16 -> 290.14051 | F21: =+F11-F16 -> 145.91049 | G21: =+F21-E21 -> -144.23002 | H21: =+H11-H16 -> 197.43221 | I21: =+F21-H21 -> -51.521715 | J21: =+J11-J16 -> 290.14051 | K21: =+K11-K16 -> 145.91049 | L21: =+K21-J21 -> -144.23002 | M21: =+M11-M16 -> 197.43221 | N21: =+K21-M21 -> -51.521715 | Q21: □ 건자재 | AA21: =+'사업장별(당월)'!I37 -> 대손 | AB21: =+'사업장별(당월)'!T37/100 -> 0 | AC21: =+'사업장별(당월)'!U37/100 -> 0 | AD21: =+AC21-AB21 -> 0 | AE21: =+'사업장별(당월)'!W37/100 -> 0 | AF21: =+AC21-AE21 -> 0 | AG21: =+AB21 -> 0 | AH21: =+AC21 -> 0 | AI21: =+AH21-AG21 -> 0 | AJ21: =+AE21 -> 0 | AK21: =+AH21-AJ21 -> 0
D22: 골재 | E22: =+E12-E17 -> 124.59145 | F22: =+F12-F17 -> -230.51754 | G22: =+F22-E22 -> -355.10899 | H22: =+H12-H17 -> 226.2453 | I22: =+F22-H22 -> -456.76285 | J22: =+J12-J17 -> 124.59145 | K22: =+K12-K17 -> -230.51754 | L22: =+K22-J22 -> -355.10899 | M22: =+M12-M17 -> 226.2453 | N22: =+K22-M22 -> -456.76285 | Q22: 구분 | S22: 계획 | T22: 실적 | U22: 계획대비 | V22: 전년 | W22: 전년대비 | AA22: =+D34 -> 기타 | AB22: =+AB26-AB19-AB20-AB21 -> -0.59307241 | AC22: =+AC26-AC19-AC20-AC21 -> -8.0842499 | AD22: =+AC22-AB22 -> -7.4911775 | AE22: =+AE26-AE19-AE20-AE21 -> -0.53183423 | AF22: =+AC22-AE22 -> -7.5524157 | AG22: =+AB22 -> -0.59307241 | AH22: =+AC22 -> -8.0842499 | AI22: =+AH22-AG22 -> -7.4911775 | AJ22: =+AE22 -> -0.53183423 | AK22: =+AH22-AJ22 -> -7.5524157
D23: 기타 | E23: =+E13-E18 -> 138.25722 | F23: =+F13-F18 -> -163.93776 | G23: =+F23-E23 -> -302.19498 | H23: =+H13-H18 -> 135.96369 | I23: =+F23-H23 -> -299.90145 | J23: =+J13-J18 -> 138.25722 | K23: =+K13-K18 -> -163.93776 | L23: =+K23-J23 -> -302.19498 | M23: =+M13-M18 -> 135.96369 | N23: =+K23-M23 -> -299.90145 | Q23: 철강재 판매단가 | S23: =+'[6]1월'!$F$10 -> 872959.18 | T23: =+'[6]1월'!$G$10 -> 756420.01 | U23: =+T23-S23 -> -116539.17 | V23: =+'[6]1월'!$G$10 -> 756420.01 | W23: =+T23-V23 -> 0 | AA23: 계 | AB23: =SUM(AB15,AB17:AB22) -> -7.2047289 | AC23: =SUM(AC15,AC17:AC22) -> -25.639617 | AD23: =+AC23-AB23 -> -18.434888 | AE23: =SUM(AE15,AE17:AE22) -> 11.150685 | AF23: =+AC23-AE23 -> -36.790302 | AG23: =SUM(AG15,AG17:AG22) -> -7.2047289 | AH23: =SUM(AH15,AH17:AH22) -> -25.639617 | AI23: =+AH23-AG23 -> -18.434888 | AJ23: =SUM(AJ15,AJ17:AJ22) -> 11.150685 | AK23: =+AH23-AJ23 -> -36.790302
C24: 계 | E24: =SUM(E20:E23) -> 1968.1928 | F24: =SUM(F20:F23) -> 485.12187 | G24: =+F24-E24 -> -1483.071 | H24: =SUM(H20:H23) -> 3555.7549 | I24: =+F24-H24 -> -3070.633 | J24: =SUM(J20:J23) -> 1968.1928 | K24: =SUM(K20:K23) -> 485.12187 | L24: =+K24-J24 -> -1483.071 | M24: =SUM(M20:M23) -> 3555.7549 | N24: =+K24-M24 -> -3070.633 | Q24: 철강재 마진률 | S24: =+'[6]1월'!$F$15 -> 0.024004383 | T24: =+'[6]1월'!$G$15 -> 0.017727214 | U24: =+T24-S24 -> -0.0062771689 | V24: =+'[6]1월'!$G$15 -> 0.017727214 | W24: =+T24-V24 -> 0 | AA24: =+D36 -> % | AB24: =+E36 -> -0.021600722 | AC24: =+F36 -> -0.096123887 | AD24: =+G36 -> -0.074523165 | AE24: =+H36 -> 0.030001092 | AF24: =+I36 -> -0.12612498 | AG24: =+J36 -> -0.021600722 | AH24: =+K36 -> -0.096123887 | ... AK24: =+N36 -> -0.12612498
C25: 판관비 | D25: 레미콘 | E25: =+('[1]1월'!$Z$13+'[1]1월'!$Z$20)/1000 -> 672.47856 | F25: =+('[2]1월'!$Z$13+'[2]1월'!$Z$20)/1000 -> 710.52843 | G25: =+F25-E25 -> 38.049871 | H25: =+('[3]1월'!$Z$13+'[3]1월'!$Z$20)/1000 -> 671.52442 | I25: =+F25-H25 -> 39.004019 | J25: =+E25 -> 672.47856 | K25: =+F25 -> 710.52843 | L25: =+K25-J25 -> 38.049871 | M25: =+H25 -> 671.52442 | N25: =+K25-M25 -> 39.004019 | Q25: □ 골재
D26: 건자재 | E26: =+('[1]1월'!$AA$13+'[1]1월'!$AA$20)/1000 -> 122.77919 | F26: =+('[2]1월'!$AO$13+'[2]1월'!$AO$20)/1000 -> 144.21324 | G26: =+F26-E26 -> 21.434055 | H26: =+('[3]1월'!$AO$13+'[3]1월'!$AO$20)/1000 -> 122.165 | I26: =+F26-H26 -> 22.048247 | J26: =+E26 -> 122.77919 | K26: =+F26 -> 144.21324 | L26: =+K26-J26 -> 21.434055 | M26: =+H26 -> 122.165 | N26: =+K26-M26 -> 22.048247 | Q26: 구분 | S26: 계획 | T26: 실적 | U26: 계획대비 | V26: 전년 | W26: 전년대비 | AB26: =+'사업장별(당월)'!T41/100 -> -17.075368 | AC26: =+'사업장별(당월)'!U41/100 -> -23.087097 | AD26: =+AC26-AB26 -> -6.011729 | AE26: =+'사업장별(당월)'!W41/100 -> -14.688617 | AF26: =+AE26-AD26 -> -8.6768879 | AG26: =+'사업장별(당월)'!Y41/100 -> 0 | AH26: =+'사업장별(당월)'!Z41/100 -> 0 | AJ26: =+'사업장별(당월)'!AB41/100 -> 0
D27: 골재 | E27: =+('[1]1월'!$AE$13+'[1]1월'!$AE$20+'[1]1월'!$AE$22)/1000 -> 47.613933 | F27: =+('[2]1월'!$AN$13+'[2]1월'!$AN$20+'[2]1월'!$AN$22)/1000 -> 49.569914 | G27: =+F27-E27 -> 1.9559812 | H27: =+('[3]1월'!$AN$13+'[3]1월'!$AN$20+'[3]1월'!$AN$22)/1000 -> 42.171572 | I27: =+F27-H27 -> 7.3983422 | J27: =+E27 -> 47.613933 | K27: =+F27 -> 49.569914 | L27: =+K27-J27 -> 1.9559812 | M27: =+H27 -> 42.171572 | N27: =+K27-M27 -> 7.3983422 | Q27: 판매량 | R27: 자가 | S27: =(+'[7]서부산크라샤(당월)'!$N$66+'[7]부산모래장(당월)'!$Q$48+'[7]부산크라샤(당월)'!$N$66)/1000 -> 46.818291 | T27: =(+'[7]서부산크라샤(당월)'!$O$66+'[7]부산모래장(당월)'!$R$48+'[7]부산크라샤(당월)'!$O$66)/1000 -> 30.26 | U27: =+T27-S27 -> -16.558291 | V27: =+'[7]부산모래장(당월)'!$S$85/1000 -> 30.26 | W27: =+T27-V27 -> 0
D28: 기타 | E28: =+('[1]1월'!$E$13+'[1]1월'!$E$20)/1000-E25-E26-E27+('[1]1월'!$E$22/1000) -> 1845.794 | F28: =+('[2]1월'!$F$13+'[2]1월'!$F$20)/1000-F25-F26-F27+'[2]1월'!$F$22/1000 -> 2144.772 | G28: =+F28-E28 -> 298.97792 | H28: =+('[3]1월'!$F$13+'[3]1월'!$F$20)/1000-H25-H26-H27+'[3]1월'!$F$22/1000 -> 1604.8254 | I28: =+F28-H28 -> 539.94656 | J28: =+E28 -> 1845.794 | K28: =+F28 -> 2144.772 | L28: =+K28-J28 -> 298.97792 | M28: =+H28 -> 1604.8254 | N28: =+K28-M28 -> 539.94656 | R28: 외판 | S28: =(+'[7]서부산크라샤(당월)'!$N$59+'[7]부산모래장(당월)'!$Q$47+'[7]부산크라샤(당월)'!$N$59)/1000 -> 44 | T28: =(+'[7]서부산크라샤(당월)'!$O$59+'[7]부산모래장(당월)'!$R$47+'[7]부산크라샤(당월)'!$O$59)/1000 -> 17.992 | U28: =+T28-S28 -> -26.008 | V28: =+'[7]부산모래장(당월)'!$S$86/1000 -> 17.992 | W28: =+T28-V28 -> 0 | AA28: =365/2.3 -> 158.69565
C29: 계 | E29: =SUM(E25:E28) -> 2688.6657 | F29: =SUM(F25:F28) -> 3049.0835 | G29: =+F29-E29 -> 360.41783 | H29: =SUM(H25:H28) -> 2440.6864 | I29: =+F29-H29 -> 608.39717 | J29: =SUM(J25:J28) -> 2688.6657 | K29: =SUM(K25:K28) -> 3049.0835 | L29: =+K29-J29 -> 360.41783 | M29: =SUM(M25:M28) -> 2440.6864 | N29: =+K29-M29 -> 608.39717 | Q29: 합 계 | S29: =SUM(S27:S28) -> 90.818291 | T29: =SUM(T27:T28) -> 48.252 | U29: =+T29-S29 -> -42.566291 | V29: =SUM(V27:V28) -> 48.252 | W29: =+T29-V29 -> 0
C30: 영업이익 | D30: 레미콘 | E30: =+E20-E25 -> 742.72509 | F30: =+F20-F25 -> 23.138241 | G30: =+F30-E30 -> -719.58685 | H30: =+H20-H25 -> 2324.5893 | I30: =+F30-H30 -> -2301.451 | J30: =+J20-J25 -> 742.72509 | K30: =+K20-K25 -> 23.138241 | L30: =+K30-J30 -> -719.58685 | M30: =+M20-M25 -> 2324.5893 | N30: =+K30-M30 -> -2301.451 | Q30: □ 기타내역(영업이익)
D31: % | E31: =+E30/E10 -> 0.035680674 | F31: =+F30/F10 -> 0.0012872892 | G31: =+F31-E31 -> -0.034393384 | H31: =+H30/H10 -> 0.083391406 | I31: =+F31-H31 -> -0.082104116 | J31: =+J30/J10 -> 0.035680674 | K31: =+K30/K10 -> 0.0012872892 | L31: =+K31-J31 -> -0.034393384 | M31: =+M30/M10 -> 0.083391406 | N31: =+K31-M31 -> -0.082104116 | Q31: 구분 | S31: 계획 | T31: 실적 | U31: 계획대비 | V31: 전년 | W31: 전년대비
D32: 건자재 | E32: =+E21-E26 -> 167.36132 | F32: =+F21-F26 -> 1.697249 | G32: =+F32-E32 -> -165.66407 | H32: =+H21-H26 -> 75.267211 | I32: =+F32-H32 -> -73.569962 | J32: =+J21-J26 -> 167.36132 | K32: =+K21-K26 -> 1.697249 | L32: =+K32-J32 -> -165.66407 | M32: =+M21-M26 -> 75.267211 | N32: =+K32-M32 -> -73.569962 | Q32: 레미콘임대 | S32: =+'사업장별(당월)'!T33 -> 72.523221 | T32: =+'사업장별(당월)'!U33 -> 72.305275 | U32: =+T32-S32 -> -0.217946 | V32: =+'사업장별(당월)'!W33 -> 71.79658 | W32: =+T32-V32 -> 0.508695
D33: 골재 | E33: =+E22-E27 -> 76.977514 | F33: =+F22-F27 -> -280.08746 | G33: =+F33-E33 -> -357.06497 | H33: =+H22-H27 -> 184.07373 | I33: =+F33-H33 -> -464.16119 | J33: =+J22-J27 -> 76.977514 | K33: =+K22-K27 -> -280.08746 | L33: =+K33-J33 -> -357.06497 | M33: =+M22-M27 -> 184.07373 | N33: =+K33-M33 -> -464.16119 | Q33: 임대 | S33: =+'사업장별(당월)'!T34 -> 63.964 | T33: =+'사업장별(당월)'!U34 -> 64.600993 | U33: =+T33-S33 -> 0.636993 | V33: =+'사업장별(당월)'!W34 -> 61.824294 | W33: =+T33-V33 -> 2.776699
D34: 기타 | E34: =+E23-E28 -> -1707.5368 | F34: =+F23-F28 -> -2308.7097 | G34: =+F34-E34 -> -601.1729 | H34: =+H23-H28 -> -1468.8617 | I34: =+F34-H34 -> -839.84801 | J34: =+J23-J28 -> -1707.5368 | K34: =+K23-K28 -> -2308.7097 | L34: =+K34-J34 -> -601.1729 | M34: =+M23-M28 -> -1468.8617 | N34: =+K34-M34 -> -839.84801 | Q34: 공통비 | S34: =+'사업장별(당월)'!T35 -> -1784.7168 | T34: =+'사업장별(당월)'!U35 -> -1637.191 | U34: =+T34-S34 -> 147.5258 | V34: =+'사업장별(당월)'!W35 -> -1549.2991 | W34: =+T34-V34 -> -87.891838
C35: 계 | E35: =SUM(E30,E32:E34) -> -720.47289 | F35: =SUM(F30,F32:F34) -> -2563.9617 | G35: =+F35-E35 -> -1843.4888 | H35: =SUM(H30,H32:H34) -> 1115.0685 | I35: =+F35-H35 -> -3679.0302 | J35: =SUM(J30,J32:J34) -> -720.47289 | K35: =SUM(K30,K32:K34) -> -2563.9617 | L35: =+K35-J35 -> -1843.4888 | M35: =SUM(M30,M32:M34) -> 1115.0685 | N35: =+K35-M35 -> -3679.0302 | Q35: 기타 | S35: =+S36-S32-S33-S34 -> -59.307241 | T35: =+T36-T32-T33-T34 -> -808.42499 | U35: =+T35-S35 -> -749.11775 | V35: =+V36-V32-V33-V34 -> -53.183423 | W35: =+T35-V35 -> -755.24157
D36: % | E36: =+E35/E14 -> -0.021600722 | F36: =+F35/F14 -> -0.096123887 | G36: =+F36-E36 -> -0.074523165 | H36: =+H35/H14 -> 0.030001092 | I36: =+F36-H36 -> -0.12612498 | J36: =+J35/J14 -> -0.021600722 | K36: =+K35/K14 -> -0.096123887 | L36: =+K36-J36 -> -0.074523165 | M36: =+M35/M14 -> 0.030001092 | N36: =+K36-M36 -> -0.12612498 | Q36: 합계 | S36: =+'사업장별(당월)'!T41 -> -1707.5368 | T36: =+'사업장별(당월)'!U41 -> -2308.7097 | U36: =+T36-S36 -> -601.1729 | V36: =+'사업장별(당월)'!W41 -> -1468.8617 | W36: =+T36-V36 -> -839.84801
E38: =+'[1]1월'!$E$26/1000 -> -720.47289 | F38: =+'[2]1월'!$F$26/1000 -> -2563.9617 | H38: =+'[3]1월'!$F$26/1000 -> 1115.0685 | J38: =+E38 -> -720.47289 | K38: =+F38 -> -2563.9617 | M38: =+H38 -> 1115.0685
E39: =+E35=E38 -> FALSE | F39: =+F35=F38 -> TRUE | H39: =+H35=H38 -> TRUE | J39: =+J35=J38 -> FALSE | K39: =+K35=K38 -> TRUE | M39: =+M35=M38 -> TRUE
E40: =+E35-E38 -> -1.8189894e-12 | F40: =+F35-F38 -> 0 | H40: =+H35-H38 -> 4.3200998e-12 | J40: =+J35-J38 -> -1.8189894e-12 | K40: =+K35-K38 -> 0 | M40: =+M35-M38 -> 4.3200998e-12

Sheet 사업장별(당월)
H3: □ 사업장별 손익실적(2025-01)
AG4: [단위 : 천㎥, 톤, 백만원]
H5: 구분 | J5: 물량 | O5: 매출 | T5: 영업이익(공통비 배부전) | Y5: 판매단가 | AB5: 변동비 | AE5: 공헌이익
A6: 2024년 1월 마감 손익 | J6: 계획 | K6: 실적 | L6: 차이 | M6: 전년 | N6: 차이 | O6: 계획 | P6: 실적 | Q6: 차이 | R6: 전년 | S6: 차이 | T6: 계획 | U6: 실적 | V6: 차이 | W6: 전년 | X6: 차이 | Y6: 계획 | Z6: 실적 | AA6: 전년 | AB6: 계획 | AC6: 실적 | AD6: 전년 | AE6: 계획 | AF6: 실적 | AG6: 전년
B7: 안양 | G7: =+I7 -> 안양 | H7: 레미콘 | I7: 안양 | J7: =+IFERROR(HLOOKUP($B7,'[1]1월'!$D$6:$BN$259,2,),)/1000 -> 30 | K7: =+IFERROR(HLOOKUP($B7,'[2]1월'!$F$6:$CP$99,2,),)/1000 -> 27.197 | L7: =+K7-J7 -> -2.803 | M7: =+IFERROR(HLOOKUP($B7,'[3]1월'!$F$6:$CC$57,2,),)/1000 -> 45.761 | N7: =+K7-M7 -> -18.564 | O7: =+IFERROR(HLOOKUP($B7,'[1]1월'!$D$6:$BN$259,3,),)/1000 -> 2946.5739 | P7: =+IFERROR(HLOOKUP($B7,'[2]1월'!$F$6:$CP$99,3,),)/1000 -> 2706.27 | Q7: =+P7-O7 -> -240.30389 | R7: =+IFERROR(HLOOKUP($B7,'[3]1월'!$F$6:$CC$57,3,),)/1000 -> 4371.1989 | S7: =+P7-R7 -> -1664.9289 | T7: =+IFERROR(HLOOKUP($B7,'[1]1월'!$D$6:$BN$259,16,),)/1000 -> 154.13647 | U7: =+IFERROR(HLOOKUP($B7,'[2]1월'!$F$6:$CP$99,16,),)/1000 -> 88.057685 | V7: =+U7-T7 -> -66.078782 | W7: =+IFERROR(HLOOKUP($B7,'[3]1월'!$F$6:$CC$57,16,),)/1000 -> 337.22639 | X7: =+U7-W7 -> -249.16871 | Y7: =+[4]안양!$Q$85 -> 98219.131 | Z7: =+[4]안양!$R$85 -> 99506.197 | AA7: =+[5]안양!$Q$85 -> 95522.364 | AB7: =+[4]안양!$Q$89 -> 82566.624 | AC7: =+[4]안양!$R$89 -> 84769.104 | AD7: =+[5]안양!$Q$89 -> 81107.602 | AE7: =+Y7-AB7 -> 15652.507 | AF7: =+Z7-AC7 -> 14737.092 | AG7: =+AA7-AD7 -> 14414.762
B8: 인천 | G8: =+I8 -> 인천 | H8: 직영 | I8: 인천 | J8: =+IFERROR(HLOOKUP($B8,'[1]1월'!$D$6:$BN$259,2,),)/1000 -> 25 | K8: =+IFERROR(HLOOKUP($B8,'[2]1월'!$F$6:$CP$99,2,),)/1000 -> 15.904 | L8: =+K8-J8 -> -9.096 | M8: =+IFERROR(HLOOKUP($B8,'[3]1월'!$F$6:$CC$57,2,),)/1000 -> 28.34 | N8: =+K8-M8 -> -12.436 | O8: =+IFERROR(HLOOKUP($B8,'[1]1월'!$D$6:$BN$259,3,),)/1000 -> 2433.9884 | P8: =+IFERROR(HLOOKUP($B8,'[2]1월'!$F$6:$CP$99,3,),)/1000 -> 1602.2818 | Q8: =+P8-O8 -> -831.70657 | R8: =+IFERROR(HLOOKUP($B8,'[3]1월'!$F$6:$CC$57,3,),)/1000 -> 2766.8113 | S8: =+P8-R8 -> -1164.5295 | T8: =+IFERROR(HLOOKUP($B8,'[1]1월'!$D$6:$BN$259,16,),)/1000 -> 18.630676 | U8: =+IFERROR(HLOOKUP($B8,'[2]1월'!$F$6:$CP$99,16,),)/1000 -> -127.14974 | V8: =+U8-T8 -> -145.78042 | W8: =+IFERROR(HLOOKUP($B8,'[3]1월'!$F$6:$CC$57,16,),)/1000 -> 102.92462 | X8: =+U8-W8 -> -230.07436 | Y8: =+[4]인천!$Q$85 -> 97359.535 | Z8: =+[4]인천!$R$85 -> 100747.1 | AA8: =+[5]인천!$Q$85 -> 97629.193 | AB8: =+[4]인천!$Q$89 -> 83665.025 | AC8: =+[4]인천!$R$89 -> 88700.837 | AD8: =+[5]인천!$Q$89 -> 84063.445 | AE8: =+Y8-AB8 -> 13694.51 | AF8: =+Z8-AC8 -> 12046.259 | AG8: =+AA8-AD8 -> 13565.748
B9: 파주 | G9: =+I9 -> 파주 | I9: 파주 | J9: =+IFERROR(HLOOKUP($B9,'[1]1월'!$D$6:$BN$259,2,),)/1000 -> 14 | K9: =+IFERROR(HLOOKUP($B9,'[2]1월'!$F$6:$CP$99,2,),)/1000 -> 8.443 | L9: =+K9-J9 -> -5.557 | M9: =+IFERROR(HLOOKUP($B9,'[3]1월'!$F$6:$CC$57,2,),)/1000 -> 22.882 | N9: =+K9-M9 -> -14.439 | O9: =+IFERROR(HLOOKUP($B9,'[1]1월'!$D$6:$BN$259,3,),)/1000 -> 1347.7288 | P9: =+IFERROR(HLOOKUP($B9,'[2]1월'!$F$6:$CP$99,3,),)/1000 -> 801.1718 | Q9: =+P9-O9 -> -546.55704 | R9: =+IFERROR(HLOOKUP($B9,'[3]1월'!$F$6:$CC$57,3,),)/1000 -> 2301.3269 | S9: =+P9-R9 -> -1500.1551 | T9: =+IFERROR(HLOOKUP($B9,'[1]1월'!$D$6:$BN$259,16,),)/1000 -> -13.542758 | U9: =+IFERROR(HLOOKUP($B9,'[2]1월'!$F$6:$CP$99,16,),)/1000 -> -106.54515 | V9: =+U9-T9 -> -93.002389 | W9: =+IFERROR(HLOOKUP($B9,'[3]1월'!$F$6:$CC$57,16,),)/1000 -> 116.27631 | X9: =+U9-W9 -> -222.82146 | Y9: =+[4]파주!$Q$85 -> 96266.346 | Z9: =+[4]파주!$R$85 -> 94891.839 | AA9: =+[5]파주!$Q$85 -> 100573.68 | AB9: =+[4]파주!$Q$89 -> 79356.82 | AC9: =+[4]파주!$R$89 -> 79812.611 | AD9: =+[5]파주!$Q$89 -> 84086.773 | AE9: =+Y9-AB9 -> 16909.526 | AF9: =+Z9-AC9 -> 15079.228 | AG9: =+AA9-AD9 -> 16486.906
B10: 김포 | G10: =+I10 -> 김포 | I10: 김포 | J10: =+IFERROR(HLOOKUP($B10,'[1]1월'!$D$6:$BN$259,2,),)/1000 -> 7 | K10: =+IFERROR(HLOOKUP($B10,'[2]1월'!$F$6:$CP$99,2,),)/1000 -> 5.3845 | L10: =+K10-J10 -> -1.6155 | M10: =+IFERROR(HLOOKUP($B10,'[3]1월'!$F$6:$CC$57,2,),)/1000 -> 5.281 | N10: =+K10-M10 -> 0.1035 | O10: =+IFERROR(HLOOKUP($B10,'[1]1월'!$D$6:$BN$259,3,),)/1000 -> 680.6898 | P10: =+IFERROR(HLOOKUP($B10,'[2]1월'!$F$6:$CP$99,3,),)/1000 -> 526.20577 | Q10: =+P10-O10 -> -154.48403 | R10: =+IFERROR(HLOOKUP($B10,'[3]1월'!$F$6:$CC$57,3,),)/1000 -> 486.8436 | S10: =+P10-R10 -> 39.362166 | T10: =+IFERROR(HLOOKUP($B10,'[1]1월'!$D$6:$BN$259,16,),)/1000 -> -34.423406 | U10: =+IFERROR(HLOOKUP($B10,'[2]1월'!$F$6:$CP$99,16,),)/1000 -> -107.3369 | V10: =+U10-T10 -> -72.91349 | W10: =+IFERROR(HLOOKUP($B10,'[3]1월'!$F$6:$CC$57,16,),)/1000 -> -70.351562 | X10: =+U10-W10 -> -36.985334 | Y10: =+[4]김포!$Q$85 -> 97241.4 | Z10: =+[4]김포!$R$85 -> 97726.022 | AA10: =+[5]김포!$Q$85 -> 92187.767 | AB10: =+[4]김포!$Q$89 -> 77127.928 | AC10: =+[4]김포!$R$89 -> 86838.295 | AD10: =+[5]김포!$Q$89 -> 75942.492 | AE10: =+Y10-AB10 -> 20113.472 | AF10: =+Z10-AC10 -> 10887.727 | AG10: =+AA10-AD10 -> 16245.275
B11: 부산 | G11: =+I11 -> 부산 | I11: 부산 | J11: =+IFERROR(HLOOKUP($B11,'[1]1월'!$D$6:$BN$259,2,),)/1000 -> 17 | K11: =+IFERROR(HLOOKUP($B11,'[2]1월'!$F$6:$CP$99,2,),)/1000 -> 13.731 | L11: =+K11-J11 -> -3.269 | M11: =+IFERROR(HLOOKUP($B11,'[3]1월'!$F$6:$CC$57,2,),)/1000 -> 23.815 | N11: =+K11-M11 -> -10.084 | O11: =+IFERROR(HLOOKUP($B11,'[1]1월'!$D$6:$BN$259,3,),)/1000 -> 1830.9043 | P11: =+IFERROR(HLOOKUP($B11,'[2]1월'!$F$6:$CP$99,3,),)/1000 -> 1446.2366 | Q11: =+P11-O11 -> -384.66771 | R11: =+IFERROR(HLOOKUP($B11,'[3]1월'!$F$6:$CC$57,3,),)/1000 -> 2518.1609 | S11: =+P11-R11 -> -1071.9243 | T11: =+IFERROR(HLOOKUP($B11,'[1]1월'!$D$6:$BN$259,16,),)/1000 -> 91.668576 | U11: =+IFERROR(HLOOKUP($B11,'[2]1월'!$F$6:$CP$99,16,),)/1000 -> 26.931239 | V11: =+U11-T11 -> -64.737337 | W11: =+IFERROR(HLOOKUP($B11,'[3]1월'!$F$6:$CC$57,16,),)/1000 -> 298.81115 | X11: =+U11-W11 -> -271.87991 | Y11: =+[4]부산!$Q$85 -> 107700.25 | Z11: =+[4]부산!$R$85 -> 105326.39 | AA11: =+[5]부산!$Q$85 -> 105738.44 | AB11: =+[4]부산!$Q$89 -> 84823.952 | AC11: =+[4]부산!$R$89 -> 84695.366 | AD11: =+[5]부산!$Q$89 -> 82993.734 | AE11: =+Y11-AB11 -> 22876.301 | AF11: =+Z11-AC11 -> 20631.019 | AG11: =+AA11-AD11 -> 22744.702
B12: 서부산 | G12: =+I12 -> 서부산 | I12: 서부산 | J12: =+IFERROR(HLOOKUP($B12,'[1]1월'!$D$6:$BN$259,2,),)/1000 -> 15 | K12: =+IFERROR(HLOOKUP($B12,'[2]1월'!$F$6:$CP$99,2,),)/1000 -> 12.446 | L12: =+K12-J12 -> -2.554 | M12: =+IFERROR(HLOOKUP($B12,'[3]1월'!$F$6:$CC$57,2,),)/1000 -> 23.91 | N12: =+K12-M12 -> -11.464 | O12: =+IFERROR(HLOOKUP($B12,'[1]1월'!$D$6:$BN$259,3,),)/1000 -> 1489.5025 | P12: =+IFERROR(HLOOKUP($B12,'[2]1월'!$F$6:$CP$99,3,),)/1000 -> 1219.8292 | Q12: =+P12-O12 -> -269.67334 | R12: =+IFERROR(HLOOKUP($B12,'[3]1월'!$F$6:$CC$57,3,),)/1000 -> 2338.4863 | S12: =+P12-R12 -> -1118.6571 | T12: =+IFERROR(HLOOKUP($B12,'[1]1월'!$D$6:$BN$259,16,),)/1000 -> 52.179473 | U12: =+IFERROR(HLOOKUP($B12,'[2]1월'!$F$6:$CP$99,16,),)/1000 -> 35.159033 | V12: =+U12-T12 -> -17.02044 | W12: =+IFERROR(HLOOKUP($B12,'[3]1월'!$F$6:$CC$57,16,),)/1000 -> 198.0884 | X12: =+U12-W12 -> -162.92937 | Y12: =+[4]서부산!$Q$85 -> 99300.169 | Z12: =+[4]서부산!$R$85 -> 98009.738 | AA12: =+[5]서부산!$Q$85 -> 97803.693 | AB12: =+[4]서부산!$Q$89 -> 78874.154 | AC12: =+[4]서부산!$R$89 -> 77288.175 | AD12: =+[5]서부산!$Q$89 -> 79885.068 | AE12: =+Y12-AB12 -> 20426.015 | AF12: =+Z12-AC12 -> 20721.563 | AG12: =+AA12-AD12 -> 17918.625
B13: 김해 | G13: =+I13 -> 김해 | I13: 김해 | J13: =+IFERROR(HLOOKUP($B13,'[1]1월'!$D$6:$BN$259,2,),)/1000 -> 12 | K13: =+IFERROR(HLOOKUP($B13,'[2]1월'!$F$6:$CP$99,2,),)/1000 -> 5.217 | L13: =+K13-J13 -> -6.783 | M13: =+IFERROR(HLOOKUP($B13,'[3]1월'!$F$6:$CC$57,2,),)/1000 -> 12.339 | N13: =+K13-M13 -> -7.122 | O13: =+IFERROR(HLOOKUP($B13,'[1]1월'!$D$6:$BN$259,3,),)/1000 -> 1155.6033 | P13: =+IFERROR(HLOOKUP($B13,'[2]1월'!$F$6:$CP$99,3,),)/1000 -> 492.6569 | Q13: =+P13-O13 -> -662.9464 | R13: =+IFERROR(HLOOKUP($B13,'[3]1월'!$F$6:$CC$57,3,),)/1000 -> 1225.7102 | S13: =+P13-R13 -> -733.0533 | T13: =+IFERROR(HLOOKUP($B13,'[1]1월'!$D$6:$BN$259,16,),)/1000 -> 56.902461 | U13: =+IFERROR(HLOOKUP($B13,'[2]1월'!$F$6:$CP$99,16,),)/1000 -> -64.487721 | V13: =+U13-T13 -> -121.39018 | W13: =+IFERROR(HLOOKUP($B13,'[3]1월'!$F$6:$CC$57,16,),)/1000 -> 82.439169 | X13: =+U13-W13 -> -146.92689 | Y13: =+[4]김해!$Q$85 -> 96300.275 | Z13: =+[4]김해!$R$85 -> 94432.372 | AA13: =+[5]김해!$Q$85 -> 99339.807 | AB13: =+[4]김해!$Q$89 -> 77158.582 | AC13: =+[4]김해!$R$89 -> 76391.455 | AD13: =+[5]김해!$Q$89 -> 80683.799 | AE13: =+Y13-AB13 -> 19141.693 | AF13: =+Z13-AC13 -> 18040.917 | AG13: =+AA13-AD13 -> 18656.008
B14: 정관 | G14: =+I14 -> 정관 | I14: 정관 | J14: =+IFERROR(HLOOKUP($B14,'[1]1월'!$D$6:$BN$259,2,),)/1000 -> 18 | K14: =+IFERROR(HLOOKUP($B14,'[2]1월'!$F$6:$CP$99,2,),)/1000 -> 16.167 | L14: =+K14-J14 -> -1.833 | M14: =+IFERROR(HLOOKUP($B14,'[3]1월'!$F$6:$CC$57,2,),)/1000 -> 21.5175 | N14: =+K14-M14 -> -5.3505 | O14: =+IFERROR(HLOOKUP($B14,'[1]1월'!$D$6:$BN$259,3,),)/1000 -> 1835.9943 | P14: =+IFERROR(HLOOKUP($B14,'[2]1월'!$F$6:$CP$99,3,),)/1000 -> 1665.2893 | Q14: =+P14-O14 -> -170.705 | R14: =+IFERROR(HLOOKUP($B14,'[3]1월'!$F$6:$CC$57,3,),)/1000 -> 2218.1056 | S14: =+P14-R14 -> -552.81635 | T14: =+IFERROR(HLOOKUP($B14,'[1]1월'!$D$6:$BN$259,16,),)/1000 -> 130.22967 | U14: =+IFERROR(HLOOKUP($B14,'[2]1월'!$F$6:$CP$99,16,),)/1000 -> 94.40849 | V14: =+U14-T14 -> -35.821177 | W14: =+IFERROR(HLOOKUP($B14,'[3]1월'!$F$6:$CC$57,16,),)/1000 -> 256.96584 | X14: =+U14-W14 -> -162.55735 | Y14: =+[4]정관!$Q$85 -> 101999.68 | Z14: =+[4]정관!$R$85 -> 103005.46 | AA14: =+[5]정관!$Q$85 -> 103083.8 | AB14: =+[4]정관!$Q$89 -> 81923.101 | AC14: =+[4]정관!$R$89 -> 85293.934 | AD14: =+[5]정관!$Q$89 -> 81962.525 | AE14: =+Y14-AB14 -> 20076.582 | AF14: =+Z14-AC14 -> 17711.527 | AG14: =+AA14-AD14 -> 21121.274
B15: 양산 | G15: =+I15 -> 양산 | I15: 양산 | J15: =+IFERROR(HLOOKUP($B15,'[1]1월'!$D$6:$BN$259,2,),)/1000 -> 10 | K15: =+IFERROR(HLOOKUP($B15,'[2]1월'!$F$6:$CP$99,2,),)/1000 -> 5.826 | L15: =+K15-J15 -> -4.174 | M15: =+IFERROR(HLOOKUP($B15,'[3]1월'!$F$6:$CC$57,2,),)/1000 -> 13.864 | N15: =+K15-M15 -> -8.038 | O15: =+IFERROR(HLOOKUP($B15,'[1]1월'!$D$6:$BN$259,3,),)/1000 -> 944.7875 | P15: =+IFERROR(HLOOKUP($B15,'[2]1월'!$F$6:$CP$99,3,),)/1000 -> 539.4139 | Q15: =+P15-O15 -> -405.3736 | R15: =+IFERROR(HLOOKUP($B15,'[3]1월'!$F$6:$CC$57,3,),)/1000 -> 1311.9159 | S15: =+P15-R15 -> -772.502 | T15: =+IFERROR(HLOOKUP($B15,'[1]1월'!$D$6:$BN$259,16,),)/1000 -> 40.01441 | U15: =+IFERROR(HLOOKUP($B15,'[2]1월'!$F$6:$CP$99,16,),)/1000 -> -50.209252 | V15: =+U15-T15 -> -90.223662 | W15: =+IFERROR(HLOOKUP($B15,'[3]1월'!$F$6:$CC$57,16,),)/1000 -> 152.26055 | X15: =+U15-W15 -> -202.4698 | Y15: =+[4]양산!$Q$85 -> 94478.75 | Z15: =+[4]양산!$R$85 -> 92587.35 | AA15: =+[5]양산!$Q$85 -> 94627.517 | AB15: =+[4]양산!$Q$89 -> 74478.645 | AC15: =+[4]양산!$R$89 -> 75380.246 | AD15: =+[5]양산!$Q$89 -> 73539.584 | AE15: =+Y15-AB15 -> 20000.105 | AF15: =+Z15-AC15 -> 17207.103 | AG15: =+AA15-AD15 -> 21087.933
B16: 창원 | G16: =+I16 -> 창원 | I16: 창원 | J16: =+IFERROR(HLOOKUP($B16,'[1]1월'!$D$6:$BN$259,2,),)/1000 -> 7 | K16: =+IFERROR(HLOOKUP($B16,'[2]1월'!$F$6:$CP$99,2,),)/1000 -> 9.07 | L16: =+K16-J16 -> 2.07 | M16: =+IFERROR(HLOOKUP($B16,'[3]1월'!$F$6:$CC$57,2,),)/1000 -> 17.315 | N16: =+K16-M16 -> -8.245 | O16: =+IFERROR(HLOOKUP($B16,'[1]1월'!$D$6:$BN$259,3,),)/1000 -> 700.0022 | P16: =+IFERROR(HLOOKUP($B16,'[2]1월'!$F$6:$CP$99,3,),)/1000 -> 915.39465 | Q16: =+P16-O16 -> 215.39245 | R16: =+IFERROR(HLOOKUP($B16,'[3]1월'!$F$6:$CC$57,3,),)/1000 -> 1843.6711 | S16: =+P16-R16 -> -928.27645 | T16: =+IFERROR(HLOOKUP($B16,'[1]1월'!$D$6:$BN$259,16,),)/1000 -> -17.82064 | U16: =+IFERROR(HLOOKUP($B16,'[2]1월'!$F$6:$CP$99,16,),)/1000 -> 7.209117 | V16: =+U16-T16 -> 25.029757 | W16: =+IFERROR(HLOOKUP($B16,'[3]1월'!$F$6:$CC$57,16,),)/1000 -> 299.90023 | X16: =+U16-W16 -> -292.69111 | Y16: =+[4]창원!$Q$85 -> 100000.31 | Z16: =+[4]창원!$R$85 -> 100925.54 | AA16: =+[5]창원!$Q$85 -> 106478.26 | AB16: =+[4]창원!$Q$89 -> 75787.34 | AC16: =+[4]창원!$R$89 -> 77749.251 | AD16: =+[5]창원!$Q$89 -> 77287.77 | AE16: =+Y16-AB16 -> 24212.975 | AF16: =+Z16-AC16 -> 23176.289 | AG16: =+AA16-AD16 -> 29190.491
B17: 대구 | G17: =+I17 -> 대구 | I17: 대구 | J17: =+IFERROR(HLOOKUP($B17,'[1]1월'!$D$6:$BN$259,2,),)/1000 -> 10 | K17: =+IFERROR(HLOOKUP($B17,'[2]1월'!$F$6:$CP$99,2,),)/1000 -> 9.533 | L17: =+K17-J17 -> -0.467 | M17: =+IFERROR(HLOOKUP($B17,'[3]1월'!$F$6:$CC$57,2,),)/1000 -> 14.7545 | N17: =+K17-M17 -> -5.2215 | O17: =+IFERROR(HLOOKUP($B17,'[1]1월'!$D$6:$BN$259,3,),)/1000 -> 974.65893 | P17: =+IFERROR(HLOOKUP($B17,'[2]1월'!$F$6:$CP$99,3,),)/1000 -> 932.0735 | Q17: =+P17-O17 -> -42.585435 | R17: =+IFERROR(HLOOKUP($B17,'[3]1월'!$F$6:$CC$57,3,),)/1000 -> 1474.5359 | S17: =+P17-R17 -> -542.4624 | T17: =+IFERROR(HLOOKUP($B17,'[1]1월'!$D$6:$BN$259,16,),)/1000 -> 34.369778 | U17: =+IFERROR(HLOOKUP($B17,'[2]1월'!$F$6:$CP$99,16,),)/1000 -> 22.030702 | V17: =+U17-T17 -> -12.339076 | W17: =+IFERROR(HLOOKUP($B17,'[3]1월'!$F$6:$CC$57,16,),)/1000 -> 205.45768 | X17: =+U17-W17 -> -183.42698 | Y17: =+[4]대구!$Q$85 -> 97465.893 | Z17: =+[4]대구!$R$85 -> 97773.366 | AA17: =+[5]대구!$Q$85 -> 99938.046 | AB17: =+[4]대구!$Q$89 -> 74770.401 | AC17: =+[4]대구!$R$89 -> 77456.301 | AD17: =+[5]대구!$Q$89 -> 74479.86 | AE17: =+Y17-AB17 -> 22695.492 | AF17: =+Z17-AC17 -> 20317.065 | AG17: =+AA17-AD17 -> 25458.186
B18: 울산 | G18: =+I18 -> 울산 | I18: 울산 | J18: =+IFERROR(HLOOKUP($B18,'[1]1월'!$D$6:$BN$259,2,),)/1000 -> 8 | K18: =+IFERROR(HLOOKUP($B18,'[2]1월'!$F$6:$CP$99,2,),)/1000 -> 9.133 | L18: =+K18-J18 -> 1.133 | M18: =+IFERROR(HLOOKUP($B18,'[3]1월'!$F$6:$CC$57,2,),)/1000 -> 5.383 | N18: =+K18-M18 -> 3.75 | O18: =+IFERROR(HLOOKUP($B18,'[1]1월'!$D$6:$BN$259,3,),)/1000 -> 817.062 | P18: =+IFERROR(HLOOKUP($B18,'[2]1월'!$F$6:$CP$99,3,),)/1000 -> 978.7919 | Q18: =+P18-O18 -> 161.7299 | R18: =+IFERROR(HLOOKUP($B18,'[3]1월'!$F$6:$CC$57,3,),)/1000 -> 560.6076 | S18: =+P18-R18 -> 418.1843 | T18: =+IFERROR(HLOOKUP($B18,'[1]1월'!$D$6:$BN$259,16,),)/1000 -> -4.3383708 | U18: =+IFERROR(HLOOKUP($B18,'[2]1월'!$F$6:$CP$99,16,),)/1000 -> 57.724488 | V18: =+U18-T18 -> 62.062859 | W18: =+IFERROR(HLOOKUP($B18,'[3]1월'!$F$6:$CC$57,16,),)/1000 -> -2.687835 | X18: =+U18-W18 -> 60.412323 | Y18: =+[4]울산!$Q$85 -> 102132.75 | Z18: =+[4]울산!$R$85 -> 107170.91 | AA18: =+[5]울산!$Q$85 -> 104144.08 | AB18: =+[4]울산!$Q$89 -> 82654.53 | AC18: =+[4]울산!$R$89 -> 85147.593 | AD18: =+[5]울산!$Q$89 -> 82948.249 | AE18: =+Y18-AB18 -> 19478.22 | AF18: =+Z18-AC18 -> 22023.314 | AG18: =+AA18-AD18 -> 21195.834
B19: 아산 | G19: =+I19 -> 아산 | I19: 아산 | J19: =+IFERROR(HLOOKUP($B19,'[1]1월'!$D$6:$BN$259,2,),)/1000 -> 13 | K19: =+IFERROR(HLOOKUP($B19,'[2]1월'!$F$6:$CP$99,2,),)/1000 -> 16.996 | L19: =+K19-J19 -> 3.996 | M19: =+IFERROR(HLOOKUP($B19,'[3]1월'!$F$6:$CC$57,2,),)/1000 -> 22.999 | N19: =+K19-M19 -> -6.003 | O19: =+IFERROR(HLOOKUP($B19,'[1]1월'!$D$6:$BN$259,3,),)/1000 -> 1339 | P19: =+IFERROR(HLOOKUP($B19,'[2]1월'!$F$6:$CP$99,3,),)/1000 -> 1719.2657 | Q19: =+P19-O19 -> 380.26574 | R19: =+IFERROR(HLOOKUP($B19,'[3]1월'!$F$6:$CC$57,3,),)/1000 -> 2225.2769 | S19: =+P19-R19 -> -506.01116 | T19: =+IFERROR(HLOOKUP($B19,'[1]1월'!$D$6:$BN$259,16,),)/1000 -> 29.853229 | U19: =+IFERROR(HLOOKUP($B19,'[2]1월'!$F$6:$CP$99,16,),)/1000 -> -30.781557 | V19: =+U19-T19 -> -60.634786 | W19: =+IFERROR(HLOOKUP($B19,'[3]1월'!$F$6:$CC$57,16,),)/1000 -> 76.583958 | X19: =+U19-W19 -> -107.36552 | Y19: =+[4]아산!$Q$85 -> 103000 | Z19: =+[4]아산!$R$85 -> 101157.08 | AA19: =+[5]아산!$Q$85 -> 96755.376 | AB19: =+[4]아산!$Q$89 -> 79215.307 | AC19: =+[4]아산!$R$89 -> 88061.244 | AD19: =+[5]아산!$Q$89 -> 82780.119 | AE19: =+Y19-AB19 -> 23784.693 | AF19: =+Z19-AC19 -> 13095.836 | AG19: =+AA19-AD19 -> 13975.257
B20: 전주 | G20: =+I20 -> 전주 | I20: 전주 | J20: =+IFERROR(HLOOKUP($B20,'[1]1월'!$D$6:$BN$259,2,),)/1000 -> 7 | K20: =+IFERROR(HLOOKUP($B20,'[2]1월'!$F$6:$CP$99,2,),)/1000 -> 12.05 | L20: =+K20-J20 -> 5.05 | M20: =+IFERROR(HLOOKUP($B20,'[3]1월'!$F$6:$CC$57,2,),)/1000 -> 6.567 | N20: =+K20-M20 -> 5.483 | O20: =+IFERROR(HLOOKUP($B20,'[1]1월'!$D$6:$BN$259,3,),)/1000 -> 678.03832 | P20: =+IFERROR(HLOOKUP($B20,'[2]1월'!$F$6:$CP$99,3,),)/1000 -> 1162.3579 | Q20: =+P20-O20 -> 484.31962 | R20: =+IFERROR(HLOOKUP($B20,'[3]1월'!$F$6:$CC$57,3,),)/1000 -> 648.20874 | S20: =+P20-R20 -> 514.1492 | T20: =+IFERROR(HLOOKUP($B20,'[1]1월'!$D$6:$BN$259,16,),)/1000 -> 5.6144257 | U20: =+IFERROR(HLOOKUP($B20,'[2]1월'!$F$6:$CP$99,16,),)/1000 -> 103.70416 | V20: =+U20-T20 -> 98.089735 | W20: =+IFERROR(HLOOKUP($B20,'[3]1월'!$F$6:$CC$57,16,),)/1000 -> 24.564714 | X20: =+U20-W20 -> 79.139447 | Y20: =+[4]전주!$Q$85 -> 96862.617 | Z20: =+[4]전주!$R$85 -> 96461.24 | AA20: =+[5]전주!$Q$85 -> 98706.98 | AB20: =+[4]전주!$Q$89 -> 73604.145 | AC20: =+[4]전주!$R$89 -> 74948.096 | AD20: =+[5]전주!$Q$89 -> 74181.954 | AE20: =+Y20-AB20 -> 23258.472 | AF20: =+Z20-AC20 -> 21513.144 | AG20: =+AA20-AD20 -> 24525.026
B21: 군산 | G21: =+I21 -> 군산 | I21: 군산 | J21: =+IFERROR(HLOOKUP($B21,'[1]1월'!$D$6:$BN$259,2,),)/1000 -> 5 | K21: =+IFERROR(HLOOKUP($B21,'[2]1월'!$F$6:$CP$99,2,),)/1000 -> 2.6255 | L21: =+K21-J21 -> -2.3745 | M21: =+IFERROR(HLOOKUP($B21,'[3]1월'!$F$6:$CC$57,2,),)/1000 -> 7.363 | N21: =+K21-M21 -> -4.7375 | O21: =+IFERROR(HLOOKUP($B21,'[1]1월'!$D$6:$BN$259,3,),)/1000 -> 557.60124 | P21: =+IFERROR(HLOOKUP($B21,'[2]1월'!$F$6:$CP$99,3,),)/1000 -> 293.55978 | Q21: =+P21-O21 -> -264.04146 | R21: =+IFERROR(HLOOKUP($B21,'[3]1월'!$F$6:$CC$57,3,),)/1000 -> 752.76158 | S21: =+P21-R21 -> -459.2018 | T21: =+IFERROR(HLOOKUP($B21,'[1]1월'!$D$6:$BN$259,16,),)/1000 -> 99.136846 | U21: =+IFERROR(HLOOKUP($B21,'[2]1월'!$F$6:$CP$99,16,),)/1000 -> 10.0572 | V21: =+U21-T21 -> -89.079646 | W21: =+IFERROR(HLOOKUP($B21,'[3]1월'!$F$6:$CC$57,16,),)/1000 -> 157.32964 | X21: =+U21-W21 -> -147.27244 | Y21: =+[4]군산!$Q$85 -> 111520.25 | Z21: =+[4]군산!$R$85 -> 111811 | AA21: =+[5]군산!$Q$85 -> 102235.72 | AB21: =+[4]군산!$Q$89 -> 73867.306 | AC21: =+[4]군산!$R$89 -> 76532.785 | AD21: =+[5]군산!$Q$89 -> 69601.844 | AE21: =+Y21-AB21 -> 37652.942 | AF21: =+Z21-AC21 -> 35278.214 | AG21: =+AA21-AD21 -> 32633.872
B22: 원주 | G22: =+I22 -> 원주 | I22: 원주 | J22: =+IFERROR(HLOOKUP($B22,'[1]1월'!$D$6:$BN$259,2,),)/1000 -> 2 | K22: =+IFERROR(HLOOKUP($B22,'[2]1월'!$F$6:$CP$99,2,),)/1000 -> 2.178 | L22: =+K22-J22 -> 0.178 | M22: =+IFERROR(HLOOKUP($B22,'[3]1월'!$F$6:$CC$57,2,),)/1000 -> 3.533 | N22: =+K22-M22 -> -1.355 | O22: =+IFERROR(HLOOKUP($B22,'[1]1월'!$D$6:$BN$259,3,),)/1000 -> 224 | P22: =+IFERROR(HLOOKUP($B22,'[2]1월'!$F$6:$CP$99,3,),)/1000 -> 248.3728 | Q22: =+P22-O22 -> 24.3728 | R22: =+IFERROR(HLOOKUP($B22,'[3]1월'!$F$6:$CC$57,3,),)/1000 -> 412.2751 | S22: =+P22-R22 -> -163.9023 | T22: =+IFERROR(HLOOKUP($B22,'[1]1월'!$D$6:$BN$259,16,),)/1000 -> -22.563248 | U22: =+IFERROR(HLOOKUP($B22,'[2]1월'!$F$6:$CP$99,16,),)/1000 -> -4.029704 | V22: =+U22-T22 -> 18.533544 | W22: =+IFERROR(HLOOKUP($B22,'[3]1월'!$F$6:$CC$57,16,),)/1000 -> 53.424534 | X22: =+U22-W22 -> -57.454238 | Y22: =+[4]원주!$Q$85 -> 112000 | Z22: =+[4]원주!$R$85 -> 114037.1 | AA22: =+[5]원주!$Q$85 -> 116692.64 | AB22: =+[4]원주!$Q$89 -> 76003.432 | AC22: =+[4]원주!$R$89 -> 75778.687 | AD22: =+[5]원주!$Q$89 -> 76321.153 | AE22: =+Y22-AB22 -> 35996.568 | AF22: =+Z22-AC22 -> 38258.411 | AG22: =+AA22-AD22 -> 40371.487
B23: 제주 | G23: =+I23 -> 제주 | I23: 제주 | J23: =+IFERROR(HLOOKUP($B23,'[1]1월'!$D$6:$BN$259,2,),)/1000 -> 7 | K23: =+IFERROR(HLOOKUP($B23,'[2]1월'!$F$6:$CP$99,2,),)/1000 -> 5.9785 | L23: =+K23-J23 -> -1.0215 | M23: =+IFERROR(HLOOKUP($B23,'[3]1월'!$F$6:$CC$57,2,),)/1000 -> 3.2615 | N23: =+K23-M23 -> 2.717 | O23: =+IFERROR(HLOOKUP($B23,'[1]1월'!$D$6:$BN$259,3,),)/1000 -> 859.7575 | P23: =+IFERROR(HLOOKUP($B23,'[2]1월'!$F$6:$CP$99,3,),)/1000 -> 725.22047 | Q23: =+P23-O23 -> -134.53703 | R23: =+IFERROR(HLOOKUP($B23,'[3]1월'!$F$6:$CC$57,3,),)/1000 -> 419.7493 | S23: =+P23-R23 -> 305.47117 | T23: =+IFERROR(HLOOKUP($B23,'[1]1월'!$D$6:$BN$259,16,),)/1000 -> 122.6775 | U23: =+IFERROR(HLOOKUP($B23,'[2]1월'!$F$6:$CP$99,16,),)/1000 -> 68.396145 | V23: =+U23-T23 -> -54.281356 | W23: =+IFERROR(HLOOKUP($B23,'[3]1월'!$F$6:$CC$57,16,),)/1000 -> 35.375497 | X23: =+U23-W23 -> 33.020648 | Y23: =+[4]제주!$Q$85 -> 122822.5 | Z23: =+[4]제주!$R$85 -> 120069.69 | AA23: =+[5]제주!$Q$85 -> 128698.24 | AB23: =+[4]제주!$Q$89 -> 90529.859 | AC23: =+[4]제주!$R$89 -> 90756.928 | AD23: =+[5]제주!$Q$89 -> 90773.836 | AE23: =+Y23-AB23 -> 32292.641 | AF23: =+Z23-AC23 -> 29312.767 | AG23: =+AA23-AD23 -> 37924.401
G24: =+I24 -> 수도권 | I24: 수도권 | J24: =SUM(J7:J10) -> 76 | K24: =SUM(K7:K10) -> 56.9285 | L24: =+K24-J24 -> -19.0715 | M24: =SUM(M7:M10) -> 102.264 | N24: =+K24-M24 -> -45.3355 | O24: =SUM(O7:O10) -> 7408.9809 | P24: =SUM(P7:P10) -> 5635.9294 | Q24: =+P24-O24 -> -1773.0515 | R24: =SUM(R7:R10) -> 9926.1808 | S24: =+P24-R24 -> -4290.2514 | T24: =SUM(T7:T10) -> 124.80098 | U24: =SUM(U7:U10) -> -252.9741 | V24: =+U24-T24 -> -377.77508 | W24: =SUM(W7:W10) -> 486.07577 | X24: =+U24-W24 -> -739.04987 | Y24: =+[4]수도권!$Q$85 -> 97486.591 | Z24: =+[4]수도권!$R$85 -> 99000.139 | AA24: =+[5]수도권!$Q$85 -> 97064.272 | AB24: =+[4]수도권!$Q$89 -> 81835.728 | AC24: =+[4]수도권!$R$89 -> 85329.992 | AD24: =+[5]수도권!$Q$89 -> 82325.824 | AE24: =+Y24-AB24 -> 15650.864 | AF24: =+Z24-AC24 -> 13670.147 | AG24: =+AA24-AD24 -> 14738.448
G25: =+I25 -> 영남권 | I25: 영남권 | J25: =SUM(J11:J18) -> 97 | K25: =SUM(K11:K18) -> 81.123 | L25: =+K25-J25 -> -15.877 | M25: =SUM(M11:M18) -> 132.898 | N25: =+K25-M25 -> -51.775 | O25: =SUM(O11:O18) -> 9748.5151 | P25: =SUM(P11:P18) -> 8189.686 | Q25: =+P25-O25 -> -1558.8291 | R25: =SUM(R11:R18) -> 13491.194 | S25: =+P25-R25 -> -5301.5076 | T25: =SUM(T11:T18) -> 383.20535 | U25: =SUM(U11:U18) -> 128.7661 | V25: =+U25-T25 -> -254.43926 | W25: =SUM(W11:W18) -> 1491.2352 | X25: =+U25-W25 -> -1362.4691 | Y25: =+[4]영남권!$Q$85 -> 100500.16 | Z25: =+[4]영남권!$R$85 -> 100960.81 | AA25: =+[5]영남권!$Q$85 -> 101515.92 | AB25: =+[4]영남권!$Q$89 -> 79483.262 | AC25: =+[4]영남권!$R$89 -> 80802.909 | AD25: =+[5]영남권!$Q$89 -> 79377.391 | AE25: =+Y25-AB25 -> 21016.894 | AF25: =+Z25-AC25 -> 20157.906 | AG25: =+AA25-AD25 -> 22138.533
G26: =+I26 -> 중부권 | I26: 중부권 | J26: =SUM(J19:J23) -> 34 | K26: =SUM(K19:K23) -> 39.828 | L26: =+K26-J26 -> 5.828 | M26: =SUM(M19:M23) -> 43.7235 | N26: =+K26-M26 -> -3.8955 | O26: =SUM(O19:O23) -> 3658.3971 | P26: =SUM(P19:P23) -> 4148.7767 | Q26: =+P26-O26 -> 490.37966 | R26: =SUM(R19:R23) -> 4458.2716 | S26: =+P26-R26 -> -309.49489 | T26: =SUM(T19:T23) -> 234.71875 | U26: =SUM(U19:U23) -> 147.34624 | V26: =+U26-T26 -> -87.372509 | W26: =SUM(W19:W23) -> 347.27834 | X26: =+U26-W26 -> -199.9321 | Y26: =+[4]중부권!$Q$85 -> 107599.91 | Z26: =+[4]중부권!$R$85 -> 103685.34 | AA26: =+[5]중부권!$Q$85 -> 101965.11 | AB26: =+[4]중부권!$Q$89 -> 79414.13 | AC26: =+[4]중부권!$R$89 -> 82924.201 | AD26: =+[5]중부권!$Q$89 -> 79343.893 | AE26: =+Y26-AB26 -> 28185.784 | AF26: =+Z26-AC26 -> 20761.141 | AG26: =+AA26-AD26 -> 22621.219
G27: =+K27/J27 -> 0.85932126 | H27: 레미콘 계 | J27: =SUM(J24:J26) -> 207 | K27: =SUM(K24:K26) -> 177.8795 | L27: =+K27-J27 -> -29.1205 | M27: =SUM(M24:M26) -> 278.8855 | N27: =+K27-M27 -> -101.006 | O27: =SUM(O24:O26) -> 20815.893 | P27: =SUM(P24:P26) -> 17974.392 | Q27: =+P27-O27 -> -2841.501 | R27: =SUM(R24:R26) -> 27875.646 | S27: =+P27-R27 -> -9901.2538 | T27: =SUM(T24:T26) -> 742.72509 | U27: =SUM(U24:U26) -> 23.138241 | V27: =+U27-T27 -> -719.58685 | W27: =SUM(W24:W26) -> 2324.5893 | X27: =+U27-W27 -> -2301.451 | Y27: =+[4]합계!$Q$85 -> 100559.87 | Z27: =+[4]합계!$R$85 -> 100932.18 | AA27: =+[5]합계!$Q$85 -> 99953.913 | AB27: =+[4]합계!$Q$89 -> 80335.614 | AC27: =+[4]합계!$R$89 -> 82701.342 | AD27: =+[5]합계!$Q$89 -> 80453.28 | AE27: =+Y27-AB27 -> 20224.256 | AF27: =+Z27-AC27 -> 18230.839 | AG27: =+AA27-AD27 -> 19500.633
B28: 건자재 | E28: 건자재영업 | G28: 건자재 | H28: 건자재 | J28: =+IFERROR(HLOOKUP($B28,'[1]1월'!$D$6:$BN$259,2,),) -> 9800 | K28: =+IFERROR(HLOOKUP($E28,'[2]1월'!$F$6:$CP$99,2,),) -> 8735.502 | L28: =+K28-J28 -> -1064.498 | M28: =+IFERROR(HLOOKUP($E28,'[3]1월'!$F$6:$CC$57,2,),) -> 6425.093 | N28: =+K28-M28 -> 2310.409 | O28: =+IFERROR(HLOOKUP($B28,'[1]1월'!$D$6:$BN$259,3,),)/1000 -> 10731.323 | P28: =+IFERROR(HLOOKUP($E28,'[2]1월'!$F$6:$CP$99,3,),)/1000 -> 7480.1197 | Q28: =+P28-O28 -> -3251.2031 | R28: =+IFERROR(HLOOKUP($E28,'[3]1월'!$F$6:$CC$57,3,),)/1000 -> 7407.9572 | S28: =+P28-R28 -> 72.162517 | T28: =+IFERROR(HLOOKUP($B28,'[1]1월'!$D$6:$BN$259,16,),)/1000 -> 167.36132 | U28: =+IFERROR(HLOOKUP($E28,'[2]1월'!$F$6:$CP$99,16,),)/1000 -> 1.697249 | V28: =+U28-T28 -> -165.66407 | W28: =+IFERROR(HLOOKUP($E28,'[3]1월'!$F$6:$CC$57,16,),)/1000 -> 75.267211 | X28: =+U28-W28 -> -73.569962 | Y28: ■ 비고
B29: 부산모래장 | C29: 부산골재 | G29: =+I29 -> 부산모래장 | H29: 골재 | I29: 부산모래장 | J29: =+IFERROR(HLOOKUP($B29,'[1]1월'!$D$6:$BN$259,2,),)/1000 -> 19.654135 | K29: =+IFERROR(HLOOKUP($C29,'[2]1월'!$F$6:$CP$99,2,),)/1000 -> 20.58 | L29: =+K29-J29 -> 0.92586478 | M29: =+IFERROR(HLOOKUP($C29,'[3]1월'!$F$6:$CC$57,2,),)/1000 -> 27.205 | N29: =+K29-M29 -> -6.625 | O29: =+IFERROR(HLOOKUP($B29,'[1]1월'!$D$6:$BN$259,3,),)/1000 -> 532.25661 | P29: =+IFERROR(HLOOKUP($C29,'[2]1월'!$F$6:$CP$99,3,),)/1000 -> 571.868 | Q29: =+P29-O29 -> 39.611388 | R29: =+IFERROR(HLOOKUP($C29,'[3]1월'!$F$6:$CC$57,3,),)/1000 -> 780.046 | S29: =+P29-R29 -> -208.178 | T29: =+IFERROR(HLOOKUP($B29,'[1]1월'!$D$6:$BN$259,21,),)/1000 -> 5.8105973 | U29: =+IFERROR(HLOOKUP($C29,'[2]1월'!$F$6:$CP$99,21,),)/1000 -> -2.7785453 | V29: =+U29-T29 -> -8.5891425 | W29: =+IFERROR(HLOOKUP($C29,'[3]1월'!$F$6:$CC$57,21,),)/1000 -> 57.434467 | X29: =+U29-W29 -> -60.213012
B30: 서부산크라샤 | C30: 서부산골재 | G30: =+I30 -> 서부산CR | I30: 서부산CR | J30: =+IFERROR(HLOOKUP($B30,'[1]1월'!$D$6:$BN$259,2,),)/1000 -> 36.43786 | K30: =+IFERROR(HLOOKUP($C30,'[2]1월'!$F$6:$CP$99,2,),)/1000 -> 1 | L30: =+K30-J30 -> -35.43786 | M30: =+IFERROR(HLOOKUP($C30,'[3]1월'!$F$6:$CC$57,2,),)/1000 -> 27.872 | N30: =+K30-M30 -> -26.872 | O30: =+IFERROR(HLOOKUP($B30,'[1]1월'!$D$6:$BN$259,3,),)/1000 -> 527.27896 | P30: =+IFERROR(HLOOKUP($C30,'[2]1월'!$F$6:$CP$99,3,),)/1000 -> 11.5 | Q30: =+P30-O30 -> -515.77896 | R30: =+IFERROR(HLOOKUP($C30,'[3]1월'!$F$6:$CC$57,3,),)/1000 -> 373.312 | S30: =+P30-R30 -> -361.812 | T30: =+IFERROR(HLOOKUP($B30,'[1]1월'!$D$6:$BN$259,21,),)/1000 -> 68.851888 | U30: =+IFERROR(HLOOKUP($C30,'[2]1월'!$F$6:$CP$99,21,),)/1000 -> -119.39961 | V30: =+U30-T30 -> -188.25149 | W30: =+IFERROR(HLOOKUP($C30,'[3]1월'!$F$6:$CC$57,21,),)/1000 -> 54.476102 | X30: =+U30-W30 -> -173.87571
B31: 부산크라샤 | C31: 부산크라샤 | G31: =+I31 -> 부산CR | I31: 부산CR | J31: =+IFERROR(HLOOKUP($B31,'[1]1월'!$D$6:$BN$259,2,),)/1000 -> 34.726295 | K31: =+IFERROR(HLOOKUP($C31,'[2]1월'!$F$6:$CP$99,2,),)/1000 -> 26.672 | L31: =+K31-J31 -> -8.0542954 | M31: =+IFERROR(HLOOKUP($C31,'[3]1월'!$F$6:$CC$57,2,),)/1000 -> 29.44 | N31: =+K31-M31 -> -2.768 | O31: =+IFERROR(HLOOKUP($B31,'[1]1월'!$D$6:$BN$259,3,),)/1000 -> 580.65887 | P31: =+IFERROR(HLOOKUP($C31,'[2]1월'!$F$6:$CP$99,3,),)/1000 -> 468.38 | Q31: =+P31-O31 -> -112.27887 | R31: =+IFERROR(HLOOKUP($C31,'[3]1월'!$F$6:$CC$57,3,),)/1000 -> 566.162 | S31: =+P31-R31 -> -97.782 | T31: =+IFERROR(HLOOKUP($B31,'[1]1월'!$D$6:$BN$259,21,),)/1000 -> 2.3150289 | U31: =+IFERROR(HLOOKUP($C31,'[2]1월'!$F$6:$CP$99,21,),)/1000 -> -157.90931 | V31: =+U31-T31 -> -160.22433 | W31: =+IFERROR(HLOOKUP($C31,'[3]1월'!$F$6:$CC$57,21,),)/1000 -> 72.163163 | X31: =+U31-W31 -> -230.07247
H32: 골재 계 | J32: =SUM(J29:J31) -> 90.818291 | K32: =SUM(K29:K31) -> 48.252 | L32: =+K32-J32 -> -42.566291 | M32: =SUM(M29:M31) -> 84.517 | N32: =+K32-M32 -> -36.265 | O32: =SUM(O29:O31) -> 1640.1944 | P32: =SUM(P29:P31) -> 1051.748 | Q32: =+P32-O32 -> -588.44644 | R32: =SUM(R29:R31) -> 1719.52 | S32: =+P32-R32 -> -667.772 | T32: =SUM(T29:T31) -> 76.977514 | U32: =SUM(U29:U31) -> -280.08746 | V32: =+U32-T32 -> -357.06497 | W32: =SUM(W29:W31) -> 184.07373 | X32: =+U32-W32 -> -464.16119
B33: 포항임대 | C33: 속초임대 | D33: 강릉임대 | E33: 레미콘임대 계 | G33: =+I33 -> 레미콘임대 | H33: 기타 | I33: 레미콘임대 | L33: =+K33-J33 -> 0 | N33: =+K33-M33 -> 0 | O33: =(IFERROR(HLOOKUP($B33,'[1]1월'!$D$6:$BN$259,3,),)++IFERROR(HLOOKUP($C33,'[1]1월'!$D$6:$BN$259,3,),)+IFERROR(HLOOKUP($D33,'[1]1월'!$D$6:$BN$259,3,),))/1000 -> 90.84 | P33: =+IFERROR(HLOOKUP($E33,'[2]1월'!$F$6:$CP$99,3,),)/1000 -> 90.84 | Q33: =+P33-O33 -> 0 | R33: =+IFERROR(HLOOKUP($E33,'[3]1월'!$F$6:$CC$57,3,),)/1000 -> 90.84 | S33: =+P33-R33 -> 0 | T33: =(IFERROR(HLOOKUP($B33,'[1]1월'!$D$6:$BN$259,21,),)++IFERROR(HLOOKUP($C33,'[1]1월'!$D$6:$BN$259,21,),)+IFERROR(HLOOKUP($D33,'[1]1월'!$D$6:$BN$259,21,),))/1000 -> 72.523221 | U33: =+IFERROR(HLOOKUP($E33,'[2]1월'!$F$6:$CP$99,16,),)/1000 -> 72.305275 | V33: =+U33-T33 -> -0.217946 | W33: =+IFERROR(HLOOKUP($E33,'[3]1월'!$F$6:$CC$57,16,),)/1000 -> 71.79658 | X33: =+U33-W33 -> 0.508695
B34: 부동산임대 | C34: 주유소임대 | E34: 임대 계 | G34: =+I34 -> 임대 | I34: 임대 | L34: =+K34-J34 -> 0 | M34: 0 | N34: =+K34-M34 -> 0 | O34: =(+IFERROR(HLOOKUP($B34,'[1]1월'!$D$6:$BN$259,3,),)+IFERROR(HLOOKUP($C34,'[1]1월'!$D$6:$BN$259,3,),))/1000 -> 74.0915 | P34: =+IFERROR(HLOOKUP($E34,'[2]1월'!$F$6:$CP$99,3,),)/1000 -> 74.732749 | Q34: =+P34-O34 -> 0.641249 | R34: =+IFERROR(HLOOKUP($E34,'[3]1월'!$F$6:$CC$57,3,),)/1000 -> 71.933111 | S34: =+P34-R34 -> 2.799638 | T34: =(+IFERROR(HLOOKUP($B34,'[1]1월'!$D$6:$BN$259,21,),)+IFERROR(HLOOKUP($C34,'[1]1월'!$D$6:$BN$259,21,),))/1000 -> 63.964 | U34: =+IFERROR(HLOOKUP($E34,'[2]1월'!$F$6:$CP$99,16,),)/1000 -> 64.600993 | V34: =+U34-T34 -> 0.636993 | W34: =+IFERROR(HLOOKUP($E34,'[3]1월'!$F$6:$CC$57,16,),)/1000 -> 61.824294 | X34: =+U34-W34 -> 2.776699
B35: 공 통 비 | G35: =+I35 -> 공통비 | I35: 공통비 | L35: =+K35-J35 -> 0 | N35: =+K35-M35 -> 0 | Q35: =+P35-O35 -> 0 | S35: =+P35-R35 -> 0 | T35: =-'[1]1월'!$Z$22/1000 -> -1784.7168 | U35: =+-'[2]1월'!$Z$22/1000 -> -1637.191 | V35: =+U35-T35 -> 147.5258 | W35: =+-'[3]1월'!$Z$22/1000 -> -1549.2991 | X35: =+U35-W35 -> -87.891838
G36: =+I36 -> OPC 소급분 | I36: OPC 소급분 | N36: =+K36-M36 -> 0 | Q36: =+P36-O36 -> 0 | S36: =+P36-R36 -> 0 | T36: =+'[1]1월'!$AS$26/1000 -> 0 | U36: ='[2]1월'!$BD$26/1000 -> 0 | V36: =+U36-T36 -> 0 | W36: =-'[3]1월'!$BD$26/1000 -> 0 | X36: =+U36-W36 -> 0
G37: =+I37 -> 대손 | I37: 대손 | N37: =+K37-M37 -> 0 | Q37: =+P37-O37 -> 0 | S37: =+P37-R37 -> 0 | U37: ='[2]1월'!$BE$26/1000 -> 0 | V37: =+U37-T37 -> 0 | W37: ='[3]1월'!$BE$26/1000 -> 0 | X37: =+U37-W37 -> 0
G38: =+I38 -> 미운영 공장 | I38: 미운영 공장 | M38: =SUM(M54:M59) -> 0 | N38: =+K38-M38 -> 0 | Q38: =+P38-O38 -> 0 | R38: =+IFERROR(HLOOKUP($I$38,'[3]1월'!$F$6:$BJ$50,3,),)/1000 -> 0 | S38: =+P38-R38 -> 0 | T38: =SUM('[1]1월'!$AM$26:$AQ$26)/1000 -> -42.504496 | U38: =+'[2]1월'!$BF$26/1000 -> -33.071712 | V38: =+U38-T38 -> 9.432784 | W38: =+'[3]1월'!$BF$26/1000 -> -36.069287 | X38: =+U38-W38 -> 2.997575
B39: 기타 계 | G39: =+I39 -> 퇴직금 | I39: 퇴직금 | U39: =+'[2]1월'!$BG$26/1000 -> -759.34319 | V39: =+U39-T39 -> -759.34319 | X39: =+U39-W39 -> -759.34319
G40: =+I40 -> 기타 | I40: 기타 | L40: =+K40-J40 -> 0 | N40: =+K40-M40 -> 0 | O40: =IFERROR(HLOOKUP($B39,'[1]1월'!$D$6:$BN$259,3,),)/1000 -> 1.77 | P40: =+('[2]1월'!$F$8-SUM('[2]1월'!$Z$8,'[2]1월'!$AH$8,'[2]1월'!$AN$8,'[2]1월'!$AO$8,'[2]1월'!$BA$8,'[2]1월'!$BD$8,'[2]1월'!$BE$8,'[2]1월'!$BF$8))/1000 -> 1.67985 | Q40: =+P40-O40 -> -0.09015 | R40: =+('[3]1월'!$F$8-SUM('[3]1월'!$Z$8,'[3]1월'!$AH$8,'[3]1월'!$AN$8,'[3]1월'!$AO$8,'[3]1월'!$BA$8,'[3]1월'!$BD$8,'[3]1월'!$BE$8,'[3]1월'!$BF$8))/1000 -> 1.7024 | S40: =+P40-R40 -> -0.02255 | T40: =+('[1]1월'!$E$26-'[1]1월'!$Z$26-'[1]1월'!$AA$26-'[1]1월'!$AE$26-'[1]1월'!$AL$26-'[1]1월'!$AM$26-'[1]1월'!$AN$26-'[1]1월'!$AO$26-'[1]1월'!$AP$26-'[1]1월'!$AQ$26-'[1]1월'!$AS$26)/1000 -> -16.802745 | U40: =+('[2]1월'!$F$26-SUM('[2]1월'!$Z$26,'[2]1월'!$AH$26,'[2]1월'!$AN$26,'[2]1월'!$AO$26,'[2]1월'!$BA$26,'[2]1월'!$BD$26,'[2]1월'!$BE$26,'[2]1월'!$BF$26))/1000-U39 -> -16.010092 | V40: =+U40-T40 -> 0.792653 | W40: =+('[3]1월'!$F$26-SUM('[3]1월'!$Z$26,'[3]1월'!$AH$26,'[3]1월'!$AN$26,'[3]1월'!$AO$26,'[3]1월'!$BA$26,'[3]1월'!$BD$26,'[3]1월'!$BE$26,'[3]1월'!$BF$26))/1000 -> -17.114136 | X40: =+U40-W40 -> 1.104044
H41: 기타 계 | J41: =SUM(J33:J40) -> 0 | K41: =SUM(K33:K40) -> 0 | L41: =+K41-J41 -> 0 | M41: =SUM(M33:M40) -> 0 | N41: =+K41-M41 -> 0 | O41: =SUM(O33:O40) -> 166.7015 | P41: =SUM(P33:P40) -> 167.2526 | Q41: =+P41-O41 -> 0.551099 | R41: =SUM(R33:R40) -> 164.47551 | S41: =+P41-R41 -> 2.777088 | T41: =SUM(T33:T40) -> -1707.5368 | U41: =SUM(U33:U40) -> -2308.7097 | V41: =+U41-T41 -> -601.1729 | W41: =SUM(W33:W40) -> -1468.8617 | X41: =+U41-W41 -> -839.84801
U42: 19 | V42: 12.4
...

Sheet 영업이익
D4: □ 레미콘 영업이익 차이분석(2025-01)
W5: [단위 : 백만원, 천㎥]
A6: 2024년 12월 마감 손익 | D6: 구분 | E6: 영업이익(공통비 미배부) | H6: 물량 차이 | L6: 판매단가 차이 | P6: 제조원가 차이 | T6: 판관비 등 차이
E7: 계획 | F7: 실적 | G7: 차이 | H7: 계획 | I7: 실적 | J7: 차이 | K7: 손익 | L7: 계획 | M7: 실적 | N7: 차이 | O7: 손익 | P7: 계획 | Q7: 실적 | R7: 차이 | S7: 손익 | T7: 계획 | U7: 실적 | V7: 차이 | W7: 손익
D8: 합계 | E8: =+[4]합계!$H$86/1000 -> 742.72509 | F8: =+[4]합계!$I$86/1000 -> 23.138241 | G8: =+F8-E8 -> -719.58685 | H8: =+[4]합계!$T$5/1000 -> 207 | I8: =+[4]합계!$U$5/1000 -> 177.8795 | J8: =+I8-H8 -> -29.1205 | K8: =+[4]합계!$M$86/1000 -> -255.80367 | L8: =+[4]합계!$Q$85 -> 100559.87 | M8: =+[4]합계!$R$85 -> 100932.18 | N8: =+M8-L8 -> 372.31106 | O8: =+[4]합계!$K$86/1000 -> 65.92605 | P8: =+[4]합계!$Q$50 -> 91988.451 | Q8: =+[4]합계!$R$50 -> 94581.983 | R8: =+Q8-P8 -> 2593.5326 | S8: =+[4]합계!$L$56/1000 -> -453.29121 | T8: =+([4]합계!$H$80+[4]합계!$H$85)/1000 -> 1027.9587 | U8: =+([4]합계!$I$80+[4]합계!$I$85)/1000 -> 1104.3767 | V8: =+U8-T8 -> 76.418013 | W8: =+([4]합계!$L$80+[4]합계!$L$85)/1000 -> -76.418013 | Y8: =+G8-K8-O8-S8-W8 -> -3.5385028e-12 | Z8: =+Y8*1000000 -> -3.5385028e-06
D9: 수도권 | E9: =+[4]수도권!$H$86/1000 -> 124.80098 | F9: =+[4]수도권!$I$86/1000 -> -252.9741 | G9: =+F9-E9 -> -377.77508 | H9: =+[4]수도권!$T$5/1000 -> 76 | I9: =+[4]수도권!$U$5/1000 -> 56.9285 | J9: =+I9-H9 -> -19.0715 | K9: =+[4]수도권!$M$86/1000 -> -111.17822 | L9: =+[4]수도권!$Q$85 -> 97486.591 | M9: =+[4]수도권!$R$85 -> 99000.139 | N9: =+M9-L9 -> 1513.5475 | O9: =+[4]수도권!$K$86/1000 -> 86.163989 | P9: =+[4]수도권!$Q$50 -> 91609.675 | Q9: =+[4]수도권!$R$50 -> 97530.53 | R9: =+Q9-P9 -> 5920.855 | S9: =+[4]수도권!$L$56/1000 -> -333.80223 | T9: =+([4]수도권!$H$80+[4]수도권!$H$85)/1000 -> 318.24465 | U9: =+([4]수도권!$I$80+[4]수도권!$I$85)/1000 -> 337.20327 | V9: =+U9-T9 -> 18.958613 | W9: =+([4]수도권!$L$80+[4]수도권!$L$85)/1000 -> -18.958613 | Y9: =+G9-K9-O9-S9-W9 -> -3.4816594e-13 | Z9: =+Y9*1000000 -> -3.4816594e-07
D10: 영남권 | E10: =+[4]영남권!$H$86/1000 -> 383.20535 | F10: =+[4]영남권!$I$86/1000 -> 128.7661 | G10: =+F10-E10 -> -254.43926 | H10: =+[4]영남권!$T$5/1000 -> 97 | I10: =+[4]영남권!$U$5/1000 -> 81.123 | J10: =+I10-H10 -> -15.877 | K10: =+[4]영남권!$M$86/1000 -> -146.38966 | L10: =+[4]영남권!$Q$85 -> 100500.16 | M10: =+[4]영남권!$R$85 -> 100960.81 | N10: =+M10-L10 -> 460.65932 | O10: =+[4]영남권!$K$86/1000 -> 37.330449 | P10: =+[4]영남권!$Q$50 -> 91317.254 | Q10: =+[4]영남권!$R$50 -> 92540.675 | R10: =+Q10-P10 -> 1223.421 | S10: =+[4]영남권!$L$56/1000 -> -92.046899 | T10: =+([4]영남권!$H$80+[4]영남권!$H$85)/1000 -> 507.53613 | U10: =+([4]영남권!$I$80+[4]영남권!$I$85)/1000 -> 560.86928 | V10: =+U10-T10 -> 53.333145 | W10: =+([4]영남권!$L$80+[4]영남권!$L$85)/1000 -> -53.333145 | Y10: =+G10-K10-O10-S10-W10 -> -6.5369932e-13 | Z10: =+Y10*1000000 -> -6.5369932e-07
D11: 기타권 | E11: =+[4]중부권!$H$86/1000 -> 234.71875 | F11: =+[4]중부권!$I$86/1000 -> 147.34624 | G11: =+F11-E11 -> -87.372509 | H11: =+[4]중부권!$T$5/1000 -> 34 | I11: =+[4]중부권!$U$5/1000 -> 39.828 | J11: =+I11-H11 -> 5.828 | K11: =+[4]중부권!$M$86/1000 -> 65.624453 | L11: =+[4]중부권!$Q$85 -> 107599.91 | M11: =+[4]중부권!$R$85 -> 103685.34 | N11: =+M11-L11 -> -3914.5715 | O11: =+[4]중부권!$K$86/1000 -> -153.08715 | P11: =+[4]중부권!$Q$50 -> 94750.011 | Q11: =+[4]중부권!$R$50 -> 94643.864 | R11: =+Q11-P11 -> -106.14699 | S11: =+[4]중부권!$L$56/1000 -> 4.2164411 | T11: =+([4]중부권!$H$80+[4]중부권!$H$85)/1000 -> 202.17792 | U11: =+([4]중부권!$I$80+[4]중부권!$I$85)/1000 -> 206.30418 | V11: =+U11-T11 -> 4.1262558 | W11: =+([4]중부권!$L$80+[4]중부권!$L$85)/1000 -> -4.1262558 | Y11: =+G11-K11-O11-S11-W11 -> -4.7961635e-13 | Z11: =+Y11*1000000 -> -4.7961635e-07
D12: 안양 | E12: =+[4]안양!$H$86/1000 -> 154.13647 | F12: =+[4]안양!$I$86/1000 -> 88.057685 | G12: =+F12-E12 -> -66.078782 | H12: =+[4]안양!$T$5/1000 -> 30 | I12: =+[4]안양!$U$5/1000 -> 27.197 | J12: =+I12-H12 -> -2.803 | K12: =+[4]안양!$M$86/1000 -> -23.432966 | L12: =+[4]안양!$Q$85 -> 98219.131 | M12: =+[4]안양!$R$85 -> 99506.197 | N12: =+M12-L12 -> 1287.0658 | O12: =+[4]안양!$K$86/1000 -> 35.004329 | P12: =+[4]안양!$Q$50 -> 89859.172 | Q12: =+[4]안양!$R$50 -> 92526.295 | R12: =+Q12-P12 -> 2667.1237 | S12: =+[4]안양!$L$56/1000 -> -72.53775 | T12: =+([4]안양!$H$80+[4]안양!$H$85)/1000 -> 96.662309 | U12: =+([4]안양!$I$80+[4]안양!$I$85)/1000 -> 101.7747 | V12: =+U12-T12 -> 5.1123958 | W12: =+([4]안양!$L$80+[4]안양!$L$85)/1000 -> -5.1123958 | Y12: =+G12-K12-O12-S12-W12 -> 3.5527137e-13 | Z12: =+Y12*1000000 -> 3.5527137e-07
D13: 인천 | E13: =+[4]인천!$H$86/1000 -> 18.630676 | F13: =+[4]인천!$I$86/1000 -> -127.14974 | G13: =+F13-E13 -> -145.78042 | H13: =+[4]인천!$T$5/1000 -> 25 | I13: =+[4]인천!$U$5/1000 -> 15.904 | J13: =+I13-H13 -> -9.096 | K13: =+[4]인천!$M$86/1000 -> -41.509108 | L13: =+[4]인천!$Q$85 -> 97359.535 | M13: =+[4]인천!$R$85 -> 100747.1 | N13: =+M13-L13 -> 3387.5605 | O13: =+[4]인천!$K$86/1000 -> 53.875762 | P13: =+[4]인천!$Q$50 -> 92716.088 | Q13: =+[4]인천!$R$50 -> 102157.96 | R13: =+Q13-P13 -> 9441.8727 | S13: =+[4]인천!$L$56/1000 -> -148.59588 | T13: =+([4]인천!$H$80+[4]인천!$H$85)/1000 -> 95.455482 | U13: =+([4]인천!$I$80+[4]인천!$I$85)/1000 -> 105.00667 | V13: =+U13-T13 -> 9.5511925 | W13: =+([4]인천!$L$80+[4]인천!$L$85)/1000 -> -9.5511925 | Y13: =+G13-K13-O13-S13-W13 -> -5.8619776e-14 | Z13: =+Y13*1000000 -> -5.8619776e-08
