Workbook

Sheet 파워BI용
B2: 구분 | D2: 계획 | E2: 실적 | F2: 차이 | G2: 전년 | H2: 차이 | J2: 캡쳐도구 사용 → PNG 저장 → 파워BI 삽입 → 이미지
B3: 판매량 | C3: 레미콘 | D3: =+'사업장별(누계)_건자재제외'!$J$27 -> 3330 | E3: =+'사업장별(누계)_건자재제외'!$K$27 -> 2806.3474 | F3: =+E3/D3 -> 0.84274696 | G3: =+'사업장별(누계)_건자재제외'!$M$27 -> 3378.228 | H3: =+E3/G3 -> 0.8307158
C4: 골재 | D4: =+'사업장별(누계)_건자재제외'!$J$31 -> 1199.9998 | E4: =+'사업장별(누계)_건자재제외'!$K$31 -> 786.934 | F4: =+E4/D4 -> 0.65577845 | G4: =+'사업장별(누계)_건자재제외'!$M$31 -> 840.111 | H4: =+E4/G4 -> 0.93670241
B5: 매출액 | C5: 레미콘 | D5: =+'사업장별(누계)_건자재제외'!$O$27 -> 336644.09 | E5: =+'사업장별(누계)_건자재제외'!$P$27 -> 277105.91 | F5: =+E5-D5 -> -59538.171 | G5: =+'사업장별(누계)_건자재제외'!$R$27 -> 339565.24 | H5: =+E5-G5 -> -62459.324
C6: 골재 | D6: =+'사업장별(누계)_건자재제외'!$O$31 -> 22084 | E6: =+'사업장별(누계)_건자재제외'!$P$31 -> 16060.283 | F6: =+E6-D6 -> -6023.717 | G6: =+'사업장별(누계)'!$R$32 -> 17070.144 | H6: =+E6-G6 -> -1009.8611
C7: 기타 | D7: =+D8-D5-D6 -> 1784.558 | E7: =+E8-E5-E6 -> 1542.9352 | F7: =+E7-D7 -> -241.62285 | G7: =+G8-G5-G6 -> 1986.9073 | H7: =+E7-G7 -> -443.97217
C8: 계 | D8: =+'사업장별(누계)_건자재제외'!$O$42 -> 360512.64 | E8: =+'사업장별(누계)_건자재제외'!$P$42 -> 294709.13 | F8: =+E8-D8 -> -65803.511 | G8: =+'사업장별(누계)_건자재제외'!$R$42 -> 358622.29 | H8: =+E8-G8 -> -63913.157
B9: 영업이익 | C9: 레미콘 | D9: =+('사업장별(누계)_건자재제외'!$T$27+'사업장별(누계)_건자재제외'!$T$34) -> 14994.946 | E9: =+'사업장별(누계)_건자재제외'!$U$27+'사업장별(누계)_건자재제외'!$U$34 -> -5887.4191 | F9: =+E9-D9 -> -20882.365 | G9: =+'사업장별(누계)_건자재제외'!$W$27+'사업장별(누계)_건자재제외'!$W$34 -> 15593.804 | H9: =+E9-G9 -> -21481.224
C10: (%) | D10: =+D9/D5 -> 0.044542432 | E10: =+E9/E5 -> -0.021246097 | F10: =+E10-D10 -> -0.065788528 | G10: =+G9/G5 -> 0.045922853 | H10: =+E10-G10 -> -0.067168949
C11: 골재 | D11: =+'사업장별(누계)_건자재제외'!$T$31 -> 2217.2575 | E11: =+'사업장별(누계)_건자재제외'!$U$31 -> -1335.4723 | F11: =+E11-D11 -> -3552.7298 | G11: =+'사업장별(누계)_건자재제외'!$W$31 -> -761.30637 | H11: =+E11-G11 -> -574.16592
C12: 기타 | D12: =+D13-D9-D11 -> 267.9149 | E12: =+E13-E9-E11 -> -425.24357 | F12: =+E12-D12 -> -693.15847 | G12: =+G13-G9-G11 -> 1984.4951 | H12: =+E12-G12 -> -2409.7387
C13: 계 | D13: =+'사업장별(누계)_건자재제외'!$T$42 -> 17480.119 | E13: =+'사업장별(누계)_건자재제외'!$U$42 -> -7648.1349 | F13: =+E13-D13 -> -25128.254 | G13: =+'사업장별(누계)_건자재제외'!$W$42 -> 16816.993 | H13: =+E13-G13 -> -24465.128
D14: =+D13/D8 -> 0.048486839 | E14: =+E13/E8 -> -0.025951469 | F14: =+E14-D14 -> -0.074438308 | G14: =+G13/G8 -> 0.046893329 | H14: =+E14-G14 -> -0.072844798

Sheet 표지
A6: 2025년 12월 마감 손익
A24: 건재사업본부

Sheet 손익총괄
C3: □ 건재사업본부 손익실적(2025-12)
X4: [단위 : 천㎥, 톤, 원/㎥, 원/톤, 백만원]
C5: 구분 | E5: 12월 | J5: 12월 누계 | P5: 12월 주요지표
E6: 계획 | F6: 실적 | G6: 계획대비 | H6: 전년 | I6: 전년대비 | J6: 계획 | K6: 실적 | L6: 계획대비 | M6: 전년 | N6: 전년대비
C7: 물량 | D7: 레미콘 | E7: =+'[1]12월'!$Z$7/1000 -> 305 | F7: =+'[2]12월'!$Z$7/1000 -> 228.56006 | G7: =+F7-E7 -> -76.43994 | H7: =+'[3]12월'!$Z$7/1000 -> 272.289 | I7: =+F7-H7 -> -43.72894 | J7: =+'[1]12월누계'!$Z$7/1000 -> 3330 | K7: =+'[2]12월누계'!$Z$7/1000 -> 2806.3474 | L7: =+K7-J7 -> -523.65262 | M7: =+'[3]12월누계'!$Z$7/1000 -> 3378.228 | N7: =+K7-M7 -> -571.88062 | Q7: □ 레미콘
D8: 철강재 | E8: =+'[1]12월'!$AA$7 -> 13100 | F8: =+'[2]12월'!$AO$7 -> 7354.454 | G8: =+F8-E8 -> -5745.546 | H8: =+'[3]12월'!$AO$7 -> 8003.057 | I8: =+F8-H8 -> -648.603 | J8: =+'[1]12월누계'!$AA$7 -> 137600 | K8: =+'[2]12월누계'!$AO$7 -> 108225.35 | L8: =+K8-J8 -> -29374.654 | M8: =+'[3]12월누계'!$AO$7 -> 105164.21 | N8: =+K8-M8 -> 3061.135 | Q8: 구분 | S8: 계획 | T8: 실적 | U8: 계획대비 | V8: 전년 | W8: 전년대비
D9: 골재 | E9: =+'[1]12월'!$AE$7/1000 -> 114.54775 | F9: =+'[2]12월'!$AN$7/1000 -> 67.928 | G9: =+F9-E9 -> -46.619754 | H9: =+'[3]12월'!$AN$7/1000 -> 59.68 | I9: =+F9-H9 -> 8.248 | J9: =+'[1]12월누계'!$AE$7/1000 -> 1199.9998 | K9: =+'[2]12월누계'!$AN$7/1000 -> 786.934 | L9: =+K9-J9 -> -413.06579 | M9: =+'[3]12월누계'!$AN$7/1000 -> 840.111 | N9: =+K9-M9 -> -53.177 | Q9: 물량 | R9: 수도권 | S9: =+[4]수도권!$T$5/1000 -> 109 | T9: =+[4]수도권!$U$5/1000 -> 88.27706 | U9: =+T9-S9 -> -20.72294 | V9: =+[5]수도권!$T$5/1000 -> 94.7535 | W9: =+T9-V9 -> -6.47644
C10: 매출 | D10: 레미콘 | E10: =+'[1]12월'!$Z$8/1000 -> 31151.201 | F10: =+'[2]12월'!$Z$8/1000 -> 23247.349 | G10: =+F10-E10 -> -7903.852 | H10: =+'[3]12월'!$Z$8/1000 -> 27172.709 | I10: =+F10-H10 -> -3925.36 | J10: =+'[1]12월누계'!$Z$8/1000 -> 336644.09 | K10: =+'[2]12월누계'!$Z$8/1000 -> 277105.91 | L10: =+K10-J10 -> -59538.171 | M10: =+'[3]12월누계'!$Z$8/1000 -> 339565.24 | N10: =+K10-M10 -> -62459.324 | R10: 영남권 | S10: =+[4]영남권!$T$5/1000 -> 138.5 | T10: =+[4]영남권!$U$5/1000 -> 99.727 | U10: =+T10-S10 -> -38.773 | V10: =+[5]영남권!$T$5/1000 -> 129.272 | W10: =+T10-V10 -> -29.545
D11: 건자재 | E11: =+'[1]12월'!$AA$8/1000 -> 14246.036 | F11: =+'[2]12월'!$AO$8/1000 -> 6900.9295 | G11: =+F11-E11 -> -7345.1062 | H11: =+'[3]12월'!$AO$8/1000 -> 7445.9016 | I11: =+F11-H11 -> -544.97213 | J11: =+'[1]12월누계'!$AA$8/1000 -> 150142.43 | K11: =+'[2]12월누계'!$AO$8/1000 -> 99181.146 | L11: =+K11-J11 -> -50961.286 | M11: =+'[3]12월누계'!$AO$8/1000 -> 103999.85 | N11: =+K11-M11 -> -4818.7008 | R11: 중부권 | S11: =+[4]중부권!$T$5/1000 -> 57.5 | T11: =+[4]중부권!$U$5/1000 -> 40.556 | U11: =+T11-S11 -> -16.944 | V11: =+[5]중부권!$T$5/1000 -> 48.2635 | W11: =+T11-V11 -> -7.7075
D12: 골재 | E12: =+'[1]12월'!$AE$8/1000 -> 2109.9612 | F12: =+'[2]12월'!$AN$8/1000 -> 1336.7955 | G12: =+F12-E12 -> -773.16574 | H12: =+'[3]12월'!$AN$8/1000 -> 1280.5145 | I12: =+F12-H12 -> 56.280953 | J12: =+'[1]12월누계'!$AE$8/1000 -> 22084 | K12: =+'[2]12월누계'!$AN$8/1000 -> 16060.283 | L12: =+K12-J12 -> -6023.717 | M12: =+'[3]12월누계'!$AN$8/1000 -> 17070.144 | N12: =+K12-M12 -> -1009.8611 | Q12: 계 | S12: =SUM(S9:S11) -> 305 | T12: =SUM(T9:T11) -> 228.56006 | U12: =+T12-S12 -> -76.43994 | V12: =SUM(V9:V11) -> 272.289 | W12: =+T12-V12 -> -43.72894
D13: 기타 | E13: =+'[1]12월'!$E$8/1000-E10-E11-E12 -> 142.52817 | F13: =+'[2]12월'!$F$8/1000-F10-F11-F12 -> 118.89211 | G13: =+F13-E13 -> -23.636059 | H13: =+'[3]12월'!$F$8/1000-H10-H11-H12 -> 165.21179 | I13: =+F13-H13 -> -46.319682 | J13: =+'[1]12월누계'!$E$8/1000-J10-J11-J12 -> 1784.558 | K13: =+'[2]12월누계'!$F$8/1000-K10-K11-K12 -> 1542.9352 | L13: =+K13-J13 -> -241.62285 | M13: =+'[3]12월누계'!$F$8/1000-M10-M11-M12 -> 1986.9073 | N13: =+K13-M13 -> -443.97217 | Q13: 판매단가 | R13: 수도권 | S13: =+[4]수도권!$T$61 -> 100867.18 | T13: =+[4]수도권!$U$61 -> 99894.501 | U13: =+T13-S13 -> -972.6754 | V13: =+[5]수도권!$Q$85 -> 95753.183 | W13: =+T13-V13 -> 4141.3184
C14: 계 | E14: =SUM(E10:E13) -> 47649.726 | F14: =SUM(F10:F13) -> 31603.966 | G14: =+F14-E14 -> -16045.76 | H14: =SUM(H10:H13) -> 36064.337 | I14: =+F14-H14 -> -4460.3708 | J14: =SUM(J10:J13) -> 510655.08 | K14: =SUM(K10:K13) -> 393890.28 | L14: =+K14-J14 -> -116764.8 | M14: =SUM(M10:M13) -> 462622.14 | N14: =+K14-M14 -> -68731.858 | R14: 영남권 | S14: =+[4]영남권!$T$61 -> 100786.02 | T14: =+[4]영남권!$U$61 -> 100842.57 | U14: =+T14-S14 -> 56.549592 | V14: =+[5]영남권!$Q$85 -> 101138.02 | W14: =+T14-V14 -> -295.44481
C15: 매출원가 | D15: 레미콘 | E15: =+('[1]12월'!$Z$10+'[1]12월'!$Z$19)/1000 -> 26909.111 | F15: =+('[2]12월'!$Z$10+'[2]12월'!$Z$19)/1000 -> 22308.478 | G15: =+F15-E15 -> -4600.6334 | H15: =+('[3]12월'!$Z$10+'[3]12월'!$Z$19)/1000 -> 25598.441 | I15: =+F15-H15 -> -3289.9637 | J15: =+('[1]12월누계'!$Z$10+'[1]12월누계'!$Z$19)/1000 -> 295660.65 | K15: =+('[2]12월누계'!$Z$10+'[2]12월누계'!$Z$19)/1000 -> 256001.58 | L15: =+K15-J15 -> -39659.069 | M15: =+('[3]12월누계'!$Z$10+'[3]12월누계'!$Z$19)/1000 -> 297938.73 | N15: =+K15-M15 -> -41937.149 | R15: 중부권 | S15: =+[4]중부권!$T$61 -> 107788.08 | T15: =+[4]중부권!$U$61 -> 107851.32 | U15: =+T15-S15 -> 63.232059 | V15: =+[5]중부권!$Q$85 -> 104182.09 | W15: =+T15-V15 -> 3669.2239
D16: 건자재 | E16: =+('[1]12월'!$AA$10+'[1]12월'!$AA$19)/1000 -> 13862.079 | F16: =+('[2]12월'!$AO$10+'[2]12월'!$AO$19)/1000 -> 6794.7573 | G16: =+F16-E16 -> -7067.3214 | H16: =+('[3]12월'!$AO$10+'[3]12월'!$AO$19)/1000 -> 7310.0571 | I16: =+F16-H16 -> -515.29979 | J16: =+('[1]12월누계'!$AA$10+'[1]12월누계'!$AA$19)/1000 -> 146089.8 | K16: =+('[2]12월누계'!$AO$10+'[2]12월누계'!$AO$19)/1000 -> 97467.847 | L16: =+K16-J16 -> -48621.956 | M16: =+('[3]12월누계'!$AO$10+'[3]12월누계'!$AO$19)/1000 -> 101702.99 | N16: =+K16-M16 -> -4235.139 | Q16: 계 | S16: =+[4]합계!$T$61 -> 102135.09 | T16: =+[4]합계!$U$61 -> 101721.48 | U16: =+T16-S16 -> -413.60533 | V16: =+[5]합계!$Q$85 -> 99802.99 | W16: =+T16-V16 -> 1918.4903
D17: 골재 | E17: =+('[1]12월'!$AE$10+'[1]12월'!$AE$19)/1000 -> 1870.0703 | F17: =+('[2]12월'!$AN$10+'[2]12월'!$AN$19)/1000 -> 1613.0808 | G17: =+F17-E17 -> -256.98949 | H17: =+('[3]12월'!$AN$10+'[3]12월'!$AN$19)/1000 -> 1654.2001 | I17: =+F17-H17 -> -41.119278 | J17: =+('[1]12월누계'!$AE$10+'[1]12월누계'!$AE$19)/1000 -> 19291.177 | K17: =+('[2]12월누계'!$AN$10+'[2]12월누계'!$AN$19)/1000 -> 16810.749 | L17: =+K17-J17 -> -2480.4282 | M17: =+('[3]12월누계'!$AN$10+'[3]12월누계'!$AN$19)/1000 -> 17064.11 | N17: =+K17-M17 -> -253.36085 | Q17: 공헌이익 | R17: 수도권 | S17: =+[4]수도권!$Q$90 -> 18915.067 | T17: =+[4]수도권!$R$90 -> 12490.517 | U17: =+T17-S17 -> -6424.5504 | V17: =+[5]수도권!$Q$90 -> 11822.292 | W17: =+T17-V17 -> 668.22478
D18: 기타 | E18: =+('[1]12월'!$E$10+'[1]12월'!$E$19)/1000-E15-E16-E17 -> 52.588339 | F18: =+('[2]12월'!$F$10+'[2]12월'!$F$19)/1000-F15-F16-F17 -> -361.81797 | G18: =+F18-E18 -> -414.40631 | H18: =+('[3]12월'!$F$10+'[3]12월'!$F$19)/1000-H15-H16-H17 -> -311.60497 | I18: =+F18-H18 -> -50.213 | J18: =+('[1]12월누계'!$E$10+'[1]12월누계'!$E$19)/1000-J15-J16-J17 -> 730.5877 | K18: =+('[2]12월누계'!$F$10+'[2]12월누계'!$F$19)/1000-K15-K16-K17 -> -759.25683 | L18: =+K18-J18 -> -1489.8445 | M18: =+('[3]12월누계'!$F$10+'[3]12월누계'!$F$19)/1000-M15-M16-M17 -> -850.21687 | N18: =+K18-M18 -> 90.960035 | R18: 영남권 | S18: =+[4]영남권!$Q$90 -> 20914.481 | T18: =+[4]영남권!$R$90 -> 16030.47 | U18: =+T18-S18 -> -4884.0109 | V18: =+[5]영남권!$Q$90 -> 19812.809 | W18: =+T18-V18 -> -3782.3396
C19: 계 | E19: =SUM(E15:E18) -> 42693.848 | F19: =SUM(F15:F18) -> 30354.498 | G19: =+F19-E19 -> -12339.351 | H19: =SUM(H15:H18) -> 34251.094 | I19: =+F19-H19 -> -3896.5958 | J19: =SUM(J15:J18) -> 461772.22 | K19: =SUM(K15:K18) -> 369520.92 | L19: =+K19-J19 -> -92251.298 | M19: =SUM(M15:M18) -> 415855.61 | N19: =+K19-M19 -> -46334.689 | R19: 중부권 | S19: =+[4]중부권!$Q$90 -> 27838.304 | T19: =+[4]중부권!$R$90 -> 21908.921 | U19: =+T19-S19 -> -5929.3833 | V19: =+[5]중부권!$Q$90 -> 22923.655 | W19: =+T19-V19 -> -1014.7342
C20: 매출이익 | D20: 레미콘 | E20: =+E10-E15 -> 4242.0899 | F20: =+F10-F15 -> 938.87128 | G20: =+F20-E20 -> -3303.2186 | H20: =+H10-H15 -> 1574.2675 | I20: =+F20-H20 -> -635.39625 | J20: =+J10-J15 -> 40983.437 | K20: =+K10-K15 -> 21104.335 | L20: =+K20-J20 -> -19879.102 | M20: =+M10-M15 -> 41626.51 | N20: =+K20-M20 -> -20522.175 | Q20: 계 | S20: =+[4]합계!$Q$90 -> 21505.247 | T20: =+[4]합계!$R$90 -> 15710.962 | U20: =+T20-S20 -> -5794.2848 | V20: =+[5]합계!$Q$90 -> 17589.968 | W20: =+T20-V20 -> -1879.0055
D21: 건자재 | E21: =+E11-E16 -> 383.95702 | F21: =+F11-F16 -> 106.17221 | G21: =+F21-E21 -> -277.7848 | H21: =+H11-H16 -> 135.84455 | I21: =+F21-H21 -> -29.67234 | J21: =+J11-J16 -> 4052.6285 | K21: =+K11-K16 -> 1713.299 | L21: =+K21-J21 -> -2339.3295 | M21: =+M11-M16 -> 2296.8608 | N21: =+K21-M21 -> -583.56181 | Q21: □ 건자재
D22: 골재 | E22: =+E12-E17 -> 239.89088 | F22: =+F12-F17 -> -276.28537 | G22: =+F22-E22 -> -516.17625 | H22: =+H12-H17 -> -373.6856 | I22: =+F22-H22 -> 97.400231 | J22: =+J12-J17 -> 2792.8227 | K22: =+K12-K17 -> -750.46614 | L22: =+K22-J22 -> -3543.2889 | M22: =+M12-M17 -> 6.034136 | N22: =+K22-M22 -> -756.50028 | Q22: 구분 | S22: 계획 | T22: 실적 | U22: 계획대비 | V22: 전년 | W22: 전년대비
D23: 기타 | E23: =+E13-E18 -> 89.939828 | F23: =+F13-F18 -> 480.71008 | G23: =+F23-E23 -> 390.77025 | H23: =+H13-H18 -> 476.81676 | I23: =+F23-H23 -> 3.893318 | J23: =+J13-J18 -> 1053.9703 | K23: =+K13-K18 -> 2302.192 | L23: =+K23-J23 -> 1248.2217 | M23: =+M13-M18 -> 2837.1242 | N23: =+K23-M23 -> -534.9322 | Q23: 철강재 판매단가 | S23: =+'[6]12월'!$F$10 -> 872900.76 | T23: =+'[6]12월'!$G$10 -> 717670.74 | U23: =+T23-S23 -> -155230.03 | V23: =+'[7]12월'!$G$10 -> 752238.02 | W23: =+T23-V23 -> -34567.281
C24: 계 | E24: =SUM(E20:E23) -> 4955.8776 | F24: =SUM(F20:F23) -> 1249.4682 | G24: =+F24-E24 -> -3706.4094 | H24: =SUM(H20:H23) -> 1813.2432 | I24: =+F24-H24 -> -563.77504 | J24: =SUM(J20:J23) -> 48882.859 | K24: =SUM(K20:K23) -> 24369.36 | L24: =+K24-J24 -> -24513.499 | M24: =SUM(M20:M23) -> 46766.529 | N24: =+K24-M24 -> -22397.169 | Q24: 철강재 마진률 | S24: =+'[6]12월'!$F$15 -> 0.024000656 | T24: =+'[6]12월'!$G$15 -> 0.010004349 | U24: =+T24-S24 -> -0.013996307 | V24: =+'[6]12월'!$G$15 -> 0.010004349 | W24: =+T24-V24 -> 0
C25: 판관비 | D25: 레미콘 | E25: =+('[1]12월'!$Z$13+'[1]12월'!$Z$20)/1000 -> 650.54596 | F25: =+('[2]12월'!$Z$13+'[2]12월'!$Z$20)/1000 -> 729.37211 | G25: =+F25-E25 -> 78.826154 | H25: =+('[3]12월'!$Z$13+'[3]12월'!$Z$20)/1000 -> 1006.0437 | I25: =+F25-H25 -> -276.67163 | J25: =+('[1]12월누계'!$Z$13+'[1]12월누계'!$Z$20)/1000 -> 8051.8491 | K25: =+('[2]12월누계'!$Z$13+'[2]12월누계'!$Z$20)/1000 -> 8328.1838 | L25: =+K25-J25 -> 276.33462 | M25: =+('[3]12월누계'!$Z$13+'[3]12월누계'!$Z$20)/1000 -> 8589.226 | N25: =+K25-M25 -> -261.04221 | Q25: □ 골재
D26: 건자재 | E26: =+('[1]12월'!$AA$13+'[1]12월'!$AA$20)/1000 -> 124.11733 | F26: =+('[2]12월'!$AO$13+'[2]12월'!$AO$20)/1000 -> 170.1817 | G26: =+F26-E26 -> 46.064372 | H26: =+('[3]12월'!$AO$13+'[3]12월'!$AO$20)/1000 -> 236.94663 | I26: =+F26-H26 -> -66.764925 | J26: =+('[1]12월누계'!$AA$13+'[1]12월누계'!$AA$20)/1000 -> 1529.6639 | K26: =+('[2]12월누계'!$AO$13+'[2]12월누계'!$AO$20)/1000 -> 1831.067 | L26: =+K26-J26 -> 301.40318 | M26: =+('[3]12월누계'!$AO$13+'[3]12월누계'!$AO$20)/1000 -> 1796.1025 | N26: =+K26-M26 -> 34.964545 | Q26: 구분 | S26: 계획 | T26: 실적 | U26: 계획대비 | V26: 전년 | W26: 전년대비
D27: 골재 | E27: =+('[1]12월'!$AE$13+'[1]12월'!$AE$20+'[1]12월'!$AE$22)/1000 -> 46.808212 | F27: =+('[2]12월'!$AN$13+'[2]12월'!$AN$20+'[2]12월'!$AN$22)/1000 -> 53.299383 | G27: =+F27-E27 -> 6.4911714 | H27: =+('[3]12월'!$AN$13+'[3]12월'!$AN$20+'[3]12월'!$AN$22)/1000 -> 93.516636 | I27: =+F27-H27 -> -40.217253 | J27: =+('[1]12월누계'!$AE$13+'[1]12월누계'!$AE$20+'[1]12월누계'!$AE$22)/1000 -> 575.56519 | K27: =+('[2]12월누계'!$AN$13+'[2]12월누계'!$AN$20+'[2]12월누계'!$AN$22)/1000 -> 585.00614 | L27: =+K27-J27 -> 9.4409562 | M27: =+('[3]12월누계'!$AN$13+'[3]12월누계'!$AN$20+'[3]12월누계'!$AN$22)/1000 -> 767.34051 | N27: =+K27-M27 -> -182.33437 | Q27: 판매량 | R27: 자가 | S27: =+[8]원가손익!$W$10+[9]원가손익!$W$13+[10]손익!$F$10 -> 65317.754 | T27: =+[8]원가손익!$X$10+[9]원가손익!$X$13+[10]손익!$G$10 -> 48483 | U27: =+T27-S27 -> -16834.754 | V27: =+'[11]부산모래장(당월)'!$S$85 -> 38160 | W27: =+T27-V27 -> 10323
D28: 기타 | E28: =+('[1]12월'!$E$13+'[1]12월'!$E$20)/1000-E25-E26-E27+('[1]12월'!$E$22/1000) -> 1370.0183 | F28: =+('[2]12월'!$F$13+'[2]12월'!$F$20)/1000-F25-F26-F27+'[2]12월'!$F$22/1000 -> 2301.478 | G28: =+F28-E28 -> 931.45968 | H28: =+('[3]12월'!$F$13+'[3]12월'!$F$20)/1000-H25-H26-H27+'[3]12월'!$F$22/1000 -> 1782.9466 | I28: =+F28-H28 -> 518.53141 | J28: =+('[1]12월누계'!$E$13+'[1]12월누계'!$E$20)/1000-J25-J26-J27+('[1]12월누계'!$E$22/1000) -> 18722.697 | K28: =+('[2]12월누계'!$F$13+'[2]12월누계'!$F$20)/1000-K25-K26-K27+'[2]12월누계'!$F$22/1000 -> 21391.006 | L28: =+K28-J28 -> 2668.3087 | M28: =+('[3]12월누계'!$F$13+'[3]12월누계'!$F$20)/1000-M25-M26-M27+'[3]12월누계'!$F$22/1000 -> 18296.109 | N28: =+K28-M28 -> 3094.8973 | R28: 외판 | S28: =+[8]원가손익!$W$14+[9]원가손익!$W$15+[10]손익!$F$12 -> 49230 | T28: =+[8]원가손익!$X$14+[9]원가손익!$X$15+[10]손익!$G$12 -> 19445 | U28: =+T28-S28 -> -29785 | V28: =+'[11]부산모래장(당월)'!$S$86 -> 21520 | W28: =+T28-V28 -> -2075
C29: 계 | E29: =SUM(E25:E28) -> 2191.4898 | F29: =SUM(F25:F28) -> 3254.3312 | G29: =+F29-E29 -> 1062.8414 | H29: =SUM(H25:H28) -> 3119.4536 | I29: =+F29-H29 -> 134.87759 | J29: =SUM(J25:J28) -> 28879.775 | K29: =SUM(K25:K28) -> 32135.263 | L29: =+K29-J29 -> 3255.4875 | M29: =SUM(M25:M28) -> 29448.778 | N29: =+K29-M29 -> 2686.4853 | Q29: 합 계 | S29: =SUM(S27:S28) -> 114547.75 | T29: =SUM(T27:T28) -> 67928 | U29: =+T29-S29 -> -46619.754 | V29: =SUM(V27:V28) -> 59680 | W29: =+T29-V29 -> 8248
C30: 영업이익 | D30: 레미콘 | E30: =+E20-E25 -> 3591.544 | F30: =+F20-F25 -> 209.49917 | G30: =+F30-E30 -> -3382.0448 | H30: =+H20-H25 -> 568.22379 | I30: =+F30-H30 -> -358.72461 | J30: =+J20-J25 -> 32931.588 | K30: =+K20-K25 -> 12776.151 | L30: =+K30-J30 -> -20155.437 | M30: =+M20-M25 -> 33037.284 | N30: =+K30-M30 -> -20261.133 | Q30: □ 기타내역(영업이익)
D31: % | E31: =+E30/E10 -> 0.11529392 | F31: =+F30/F10 -> 0.0090117446 | G31: =+F31-E31 -> -0.10628217 | H31: =+H30/H10 -> 0.020911562 | I31: =+F31-H31 -> -0.011899817 | J31: =+J30/J10 -> 0.097823159 | K31: =+K30/K10 -> 0.046105661 | L31: =+K31-J31 -> -0.051717498 | M31: =+M30/M10 -> 0.097292891 | N31: =+K31-M31 -> -0.051187231 | Q31: 구분 | S31: 계획 | T31: 실적 | U31: 계획대비 | V31: 전년 | W31: 전년대비
D32: 건자재 | E32: =+E21-E26 -> 259.83969 | F32: =+F21-F26 -> -64.009488 | G32: =+F32-E32 -> -323.84918 | H32: =+H21-H26 -> -101.10207 | I32: =+F32-H32 -> 37.092585 | J32: =+J21-J26 -> 2522.9646 | K32: =+K21-K26 -> -117.76808 | L32: =+K32-J32 -> -2640.7327 | M32: =+M21-M26 -> 500.75828 | N32: =+K32-M32 -> -618.52635 | Q32: 레미콘임대 | S32: =+'사업장별(당월)'!T33 -> 51.473204 | T32: =+'사업장별(당월)'!U33 -> 26.777421 | U32: =+T32-S32 -> -24.695783 | V32: =+'사업장별(당월)'!W33 -> 76.068675 | W32: =+T32-V32 -> -49.291254
D33: 골재 | E33: =+E22-E27 -> 193.08267 | F33: =+F22-F27 -> -329.58475 | G33: =+F33-E33 -> -522.66742 | H33: =+H22-H27 -> -467.20224 | I33: =+F33-H33 -> 137.61748 | J33: =+J22-J27 -> 2217.2575 | K33: =+K22-K27 -> -1335.4723 | L33: =+K33-J33 -> -3552.7298 | M33: =+M22-M27 -> -761.30637 | N33: =+K33-M33 -> -574.16592 | Q33: 임대 | S33: =+'사업장별(당월)'!T34 -> 76.533944 | T33: =+'사업장별(당월)'!U34 -> 70.357762 | U33: =+T33-S33 -> -6.176182 | V33: =+'사업장별(당월)'!W34 -> 75.153125 | W33: =+T33-V33 -> -4.795363
D34: 기타 | E34: =+E23-E28 -> -1280.0785 | F34: =+F23-F28 -> -1820.7679 | G34: =+F34-E34 -> -540.68943 | H34: =+H23-H28 -> -1306.1298 | I34: =+F34-H34 -> -514.63809 | J34: =+J23-J28 -> -17668.727 | K34: =+K23-K28 -> -19088.814 | L34: =+K34-J34 -> -1420.0871 | M34: =+M23-M28 -> -15458.984 | N34: =+K34-M34 -> -3629.8295 | Q34: 공통비 | S34: =+'사업장별(당월)'!T35 -> -1332.7153 | T34: =+'사업장별(당월)'!U35 -> -1845.4587 | U34: =+T34-S34 -> -512.74347 | V34: =+'사업장별(당월)'!W35 -> -2089.6312 | W34: =+T34-V34 -> 244.17248
C35: 계 | E35: =SUM(E30,E32:E34) -> 2764.3878 | F35: =SUM(F30,F32:F34) -> -2004.863 | G35: =+F35-E35 -> -4769.2508 | H35: =SUM(H30,H32:H34) -> -1306.2103 | I35: =+F35-H35 -> -698.65263 | J35: =SUM(J30,J32:J34) -> 20003.083 | K35: =SUM(K30,K32:K34) -> -7765.903 | L35: =+K35-J35 -> -27768.986 | M35: =SUM(M30,M32:M34) -> 17317.751 | N35: =+K35-M35 -> -25083.654 | Q35: 기타 | S35: =+S36-S32-S33-S34 -> -75.370363 | T35: =+T36-T32-T33-T34 -> -72.44436 | U35: =+T35-S35 -> 2.926003 | V35: =+V36-V32-V33-V34 -> 632.27959 | W35: =+T35-V35 -> -704.72395
D36: % | E36: =+E35/E14 -> 0.058014769 | F36: =+F35/F14 -> -0.063437069 | G36: =+F36-E36 -> -0.12145184 | H36: =+H35/H14 -> -0.036218892 | I36: =+F36-H36 -> -0.027218176 | J36: =+J35/J14 -> 0.039171418 | K36: =+K35/K14 -> -0.019715904 | L36: =+K36-J36 -> -0.058887322 | M36: =+M35/M14 -> 0.037433901 | N36: =+K36-M36 -> -0.057149806 | Q36: 합계 | S36: =+'사업장별(당월)'!T41 -> -1280.0785 | T36: =+'사업장별(당월)'!U41 -> -1820.7679 | U36: =+T36-S36 -> -540.68943 | V36: =+'사업장별(당월)'!W41 -> -1306.1298 | W36: =+T36-V36 -> -514.63809
E38: =+'[1]12월'!$E$26/1000 -> 2764.3878 | F38: =+'[2]12월'!$F$26/1000 -> -2004.863 | H38: =+'[3]12월'!$F$26/1000 -> -1306.2103 | J38: =+'[1]12월누계'!$E$26/1000 -> 20003.083 | K38: =+'[2]12월누계'!$F$26/1000 -> -7765.903 | M38: =+'[3]12월누계'!$F$26/1000 -> 17317.751
E39: =+E35=E38 -> TRUE | F39: =+F35=F38 -> TRUE | H39: =+H35=H38 -> FALSE | J39: =+J35=J38 -> TRUE | K39: =+K35=K38 -> FALSE | M39: =+M35=M38 -> TRUE
E40: =+E35-E38 -> 0 | F40: =+F35-F38 -> 0 | H40: =+H35-H38 -> 2.7284841e-12 | J40: =+J35-J38 -> 0 | K40: =+K35-K38 -> 9.094947e-12 | M40: =+M35-M38 -> 0

Sheet 레미콘 영업이익
H3: □ 레미콘 영업이익(12월)
H5: 구분 | J5: 12월 | T5: 12월누계
J6: 영업이익(공통비 배부전) | O6: 영업이익(공통비 배부후) | T6: 영업이익(공통비 배부전) | Y6: 영업이익(공통비 배부전)
A7: 2024년 12월 마감 손익 | J7: 계획 | K7: 실적 | L7: 차이 | M7: 전년 | N7: 차이 | O7: 계획 | P7: 실적 | Q7: 차이 | R7: 전년 | S7: 차이 | T7: 계획 | U7: 실적 | V7: 차이 | W7: 전년 | X7: 차이 | Y7: 계획 | Z7: 실적 | AA7: 차이 | AB7: 전년 | AC7: 차이
B8: 안양 | H8: 레미콘 | I8: 안양 | J8: =+[4]안양!$H$86/1000 -> 565.37708 | K8: =+[4]안양!$I$86/1000 -> 188.84256 | L8: =+K8-J8 -> -376.53452 | M8: =+[5]안양!$H$86/1000 -> 51.528149 | N8: =+K8-M8 -> 137.31441 | O8: =+[4]안양!$H$92/1000 -> 383.20058 | P8: =+[4]안양!$I$92/1000 -> -59.396898 | Q8: =+P8-O8 -> -442.59748 | R8: =+[5]안양!$H$92/1000 -> -206.13204 | S8: =+P8-R8 -> 146.73514 | T8: =+[12]안양!$H$86/1000 -> 4666.8369 | U8: =+[12]안양!$I$86/1000 -> 2559.8566 | V8: =+U8-T8 -> -2106.9803 | W8: =+[13]안양!$H$86/1000 -> 3848.9545 | X8: =+U8-W8 -> -1289.0979 | Y8: =+[12]안양!$H$92/1000 -> 2209.069 | Z8: =+[12]안양!$I$92/1000 -> 95.736318 | AA8: =+Z8-Y8 -> -2113.3327 | AB8: =+[13]안양!$H$92/1000 -> 1592.6727 | AC8: =+Z8-AB8 -> -1496.9364
B9: 인천 | H9: 직영 | I9: 인천 | J9: =+[4]인천!$H$86/1000 -> 335.03112 | K9: =+[4]인천!$I$86/1000 -> -60.530205 | L9: =+K9-J9 -> -395.56132 | M9: =+[5]인천!$H$86/1000 -> -49.54122 | N9: =+K9-M9 -> -10.988985 | O9: =+[4]인천!$H$92/1000 -> 193.1235 | P9: =+[4]인천!$I$92/1000 -> -302.30796 | Q9: =+P9-O9 -> -495.43146 | R9: =+[5]인천!$H$92/1000 -> -278.45659 | S9: =+P9-R9 -> -23.851362 | T9: =+[12]인천!$H$86/1000 -> 2196.5597 | U9: =+[12]인천!$I$86/1000 -> 111.4287 | V9: =+U9-T9 -> -2085.131 | W9: =+[13]인천!$H$86/1000 -> 1685.1571 | X9: =+U9-W9 -> -1573.7284 | Y9: =+[12]인천!$H$92/1000 -> 396.11317 | Z9: =+[12]인천!$I$92/1000 -> -2027.5849 | AA9: =+Z9-Y9 -> -2423.6981 | AB9: =+[13]인천!$H$92/1000 -> 8.1562106 | AC9: =+Z9-AB9 -> -2035.7412
B10: 파주 | I10: 파주 | J10: =+[4]파주!$H$86/1000 -> 89.794589 | K10: =+[4]파주!$I$86/1000 -> -96.411096 | L10: =+K10-J10 -> -186.20569 | M10: =+[5]파주!$H$86/1000 -> -160.22943 | N10: =+K10-M10 -> 63.81833 | O10: =+[4]파주!$H$92/1000 -> 4.1327756 | P10: =+[4]파주!$I$92/1000 -> -200.94707 | Q10: =+P10-O10 -> -205.07985 | R10: =+[5]파주!$H$92/1000 -> -276.8739 | S10: =+P10-R10 -> 75.926832 | T10: =+[12]파주!$H$86/1000 -> 1246.0797 | U10: =+[12]파주!$I$86/1000 -> -546.10741 | V10: =+U10-T10 -> -1792.1871 | W10: =+[13]파주!$H$86/1000 -> 1613.3619 | X10: =+U10-W10 -> -2159.4694 | Y10: =+[12]파주!$H$92/1000 -> -34.880022 | Z10: =+[12]파주!$I$92/1000 -> -1519.2808 | AA10: =+Z10-Y10 -> -1484.4008 | AB10: =+[13]파주!$H$92/1000 -> 217.97169 | AC10: =+Z10-AB10 -> -1737.2525
B11: 김포 | I11: 김포 | J11: =+[4]김포!$H$86/1000 -> 122.15246 | K11: =+[4]김포!$I$86/1000 -> -39.531496 | L11: =+K11-J11 -> -161.68395 | M11: =+[5]김포!$H$86/1000 -> -46.29355 | N11: =+K11-M11 -> 6.762054 | O11: =+[4]김포!$H$92/1000 -> 60.871439 | P11: =+[4]김포!$I$92/1000 -> -130.05978 | Q11: =+P11-O11 -> -190.93122 | R11: =+[5]김포!$H$92/1000 -> -142.47428 | S11: =+P11-R11 -> 12.414501 | T11: =+[12]김포!$H$86/1000 -> 1105.9959 | U11: =+[12]김포!$I$86/1000 -> -65.109122 | V11: =+U11-T11 -> -1171.105 | W11: =+[13]김포!$H$86/1000 -> 988.38396 | X11: =+U11-W11 -> -1053.4931 | Y11: =+[12]김포!$H$92/1000 -> 254.18413 | Z11: =+[12]김포!$I$92/1000 -> -853.96285 | AA11: =+Z11-Y11 -> -1108.147 | AB11: =+[13]김포!$H$92/1000 -> 282.32826 | AC11: =+Z11-AB11 -> -1136.2911
B12: 부산 | I12: 부산 | J12: =+[4]부산!$H$86/1000 -> 231.81377 | K12: =+[4]부산!$I$86/1000 -> 159.61886 | L12: =+K12-J12 -> -72.194902 | M12: =+[5]부산!$H$86/1000 -> 92.183809 | N12: =+K12-M12 -> 67.435055 | O12: =+[4]부산!$H$92/1000 -> 128.62069 | P12: =+[4]부산!$I$92/1000 -> -38.474903 | Q12: =+P12-O12 -> -167.09559 | R12: =+[5]부산!$H$92/1000 -> -61.779739 | S12: =+P12-R12 -> 23.304836 | T12: =+[12]부산!$H$86/1000 -> 2244.4959 | U12: =+[12]부산!$I$86/1000 -> 2270.3055 | V12: =+U12-T12 -> 25.809573 | W12: =+[13]부산!$H$86/1000 -> 2318.2684 | X12: =+U12-W12 -> -47.962912 | Y12: =+[12]부산!$H$92/1000 -> 832.91145 | Z12: =+[12]부산!$I$92/1000 -> 466.65306 | AA12: =+Z12-Y12 -> -366.25839 | AB12: =+[13]부산!$H$92/1000 -> 1006.9671 | AC12: =+Z12-AB12 -> -540.31404
B13: 서부산 | I13: 서부산 | J13: =+[4]서부산!$H$86/1000 -> 266.46368 | K13: =+[4]서부산!$I$86/1000 -> 119.86852 | L13: =+K13-J13 -> -146.59516 | M13: =+[5]서부산!$H$86/1000 -> 163.09231 | N13: =+K13-M13 -> -43.223798 | O13: =+[4]서부산!$H$92/1000 -> 166.99471 | P13: =+[4]서부산!$I$92/1000 -> -42.724481 | Q13: =+P13-O13 -> -209.71919 | R13: =+[5]서부산!$H$92/1000 -> -20.503483 | S13: =+P13-R13 -> -22.220998 | T13: =+[12]서부산!$H$86/1000 -> 2343.0768 | U13: =+[12]서부산!$I$86/1000 -> 1539.9346 | V13: =+U13-T13 -> -803.14218 | W13: =+[13]서부산!$H$86/1000 -> 2578.5722 | X13: =+U13-W13 -> -1038.6376 | Y13: =+[12]서부산!$H$92/1000 -> 1050.5688 | Z13: =+[12]서부산!$I$92/1000 -> 105.35186 | AA13: =+Z13-Y13 -> -945.21695 | AB13: =+[13]서부산!$H$92/1000 -> 1254.8137 | AC13: =+Z13-AB13 -> -1149.4619
B14: 김해 | I14: 김해 | J14: =+[4]김해!$H$86/1000 -> 149.52483 | K14: =+[4]김해!$I$86/1000 -> -123.04865 | L14: =+K14-J14 -> -272.57348 | M14: =+[5]김해!$H$86/1000 -> -58.225946 | N14: =+K14-M14 -> -64.822704 | O14: =+[4]김해!$H$92/1000 -> 82.419352 | P14: =+[4]김해!$I$92/1000 -> -164.33592 | Q14: =+P14-O14 -> -246.75527 | R14: =+[5]김해!$H$92/1000 -> -147.31411 | S14: =+P14-R14 -> -17.021801 | T14: =+[12]김해!$H$86/1000 -> 1458.3037 | U14: =+[12]김해!$I$86/1000 -> -508.92871 | V14: =+U14-T14 -> -1967.2324 | W14: =+[13]김해!$H$86/1000 -> 746.29403 | X14: =+U14-W14 -> -1255.2227 | Y14: =+[12]김해!$H$92/1000 -> 562.67173 | Z14: =+[12]김해!$I$92/1000 -> -1123.3947 | AA14: =+Z14-Y14 -> -1686.0665 | AB14: =+[13]김해!$H$92/1000 -> -37.138406 | AC14: =+Z14-AB14 -> -1086.2563
B15: 정관 | I15: 정관 | J15: =+[4]정관!$H$86/1000 -> 208.30033 | K15: =+[4]정관!$I$86/1000 -> 0.431591 | L15: =+K15-J15 -> -207.86874 | M15: =+[5]정관!$H$86/1000 -> 101.28182 | N15: =+K15-M15 -> -100.85023 | O15: =+[4]정관!$H$92/1000 -> 115.0111 | P15: =+[4]정관!$I$92/1000 -> -138.32215 | Q15: =+P15-O15 -> -253.33325 | R15: =+[5]정관!$H$92/1000 -> -76.666762 | S15: =+P15-R15 -> -61.655389 | T15: =+[12]정관!$H$86/1000 -> 1986.809 | U15: =+[12]정관!$I$86/1000 -> 1811.5968 | V15: =+U15-T15 -> -175.21221 | W15: =+[13]정관!$H$86/1000 -> 1985.4719 | X15: =+U15-W15 -> -173.87507 | Y15: =+[12]정관!$H$92/1000 -> 699.71892 | Z15: =+[12]정관!$I$92/1000 -> 67.514547 | AA15: =+Z15-Y15 -> -632.20438 | AB15: =+[13]정관!$H$92/1000 -> 725.0019 | AC15: =+Z15-AB15 -> -657.48735
B16: 양산 | I16: 양산 | J16: =+[4]양산!$H$86/1000 -> 115.63862 | K16: =+[4]양산!$I$86/1000 -> -104.9457 | L16: =+K16-J16 -> -220.58432 | M16: =+[5]양산!$H$86/1000 -> -28.828367 | N16: =+K16-M16 -> -76.117332 | O16: =+[4]양산!$H$92/1000 -> 62.391339 | P16: =+[4]양산!$I$92/1000 -> -153.85482 | Q16: =+P16-O16 -> -216.24616 | R16: =+[5]양산!$H$92/1000 -> -103.32208 | S16: =+P16-R16 -> -50.532736 | T16: =+[12]양산!$H$86/1000 -> 1150.752 | U16: =+[12]양산!$I$86/1000 -> -221.93098 | V16: =+U16-T16 -> -1372.683 | W16: =+[13]양산!$H$86/1000 -> 1156.0376 | X16: =+U16-W16 -> -1377.9686 | Y16: =+[12]양산!$H$92/1000 -> 428.52421 | Z16: =+[12]양산!$I$92/1000 -> -762.50579 | AA16: =+Z16-Y16 -> -1191.03 | AB16: =+[13]양산!$H$92/1000 -> 443.31351 | AC16: =+Z16-AB16 -> -1205.8193
B17: 창원 | I17: 창원 | J17: =+[4]창원!$H$86/1000 -> 309.29623 | K17: =+[4]창원!$I$86/1000 -> 53.035499 | L17: =+K17-J17 -> -256.26073 | M17: =+[5]창원!$H$86/1000 -> 72.758357 | N17: =+K17-M17 -> -19.722858 | O17: =+[4]창원!$H$92/1000 -> 225.02598 | P17: =+[4]창원!$I$92/1000 -> -36.530083 | Q17: =+P17-O17 -> -261.55606 | R17: =+[5]창원!$H$92/1000 -> -25.335978 | S17: =+P17-R17 -> -11.194105 | T17: =+[12]창원!$H$86/1000 -> 1688.4607 | U17: =+[12]창원!$I$86/1000 -> 385.41136 | V17: =+U17-T17 -> -1303.0494 | W17: =+[13]창원!$H$86/1000 -> 2645.614 | X17: =+U17-W17 -> -2260.2027 | Y17: =+[12]창원!$H$92/1000 -> 831.71486 | Z17: =+[12]창원!$I$92/1000 -> -379.43658 | AA17: =+Z17-Y17 -> -1211.1514 | AB17: =+[13]창원!$H$92/1000 -> 1610.085 | AC17: =+Z17-AB17 -> -1989.5216
B18: 대구 | I18: 대구 | J18: =+[4]대구!$H$86/1000 -> 102.30373 | K18: =+[4]대구!$I$86/1000 -> -127.9319 | L18: =+K18-J18 -> -230.23563 | M18: =+[5]대구!$H$86/1000 -> 168.03998 | N18: =+K18-M18 -> -295.97188 | O18: =+[4]대구!$H$92/1000 -> 51.462096 | P18: =+[4]대구!$I$92/1000 -> -156.22518 | Q18: =+P18-O18 -> -207.68728 | R18: =+[5]대구!$H$92/1000 -> 27.974852 | S18: =+P18-R18 -> -184.20003 | T18: =+[12]대구!$H$86/1000 -> 1302.9749 | U18: =+[12]대구!$I$86/1000 -> -172.18243 | V18: =+U18-T18 -> -1475.1573 | W18: =+[13]대구!$H$86/1000 -> 2551.5007 | X18: =+U18-W18 -> -2723.6831 | Y18: =+[12]대구!$H$92/1000 -> 529.97286 | Z18: =+[12]대구!$I$92/1000 -> -841.86908 | AA18: =+Z18-Y18 -> -1371.8419 | AB18: =+[13]대구!$H$92/1000 -> 1558.0893 | AC18: =+Z18-AB18 -> -2399.9584
B19: 울산 | I19: 울산 | J19: =+[4]울산!$H$86/1000 -> 117.75726 | K19: =+[4]울산!$I$86/1000 -> 66.511149 | L19: =+K19-J19 -> -51.246106 | M19: =+[5]울산!$H$86/1000 -> 24.366226 | N19: =+K19-M19 -> 42.144923 | O19: =+[4]울산!$H$92/1000 -> 61.230419 | P19: =+[4]울산!$I$92/1000 -> -46.272002 | Q19: =+P19-O19 -> -107.50242 | R19: =+[5]울산!$H$92/1000 -> -74.628237 | S19: =+P19-R19 -> 28.356235 | T19: =+[12]울산!$H$86/1000 -> 1182.519 | U19: =+[12]울산!$I$86/1000 -> 1075.6328 | V19: =+U19-T19 -> -106.88617 | W19: =+[13]울산!$H$86/1000 -> 1432.4138 | X19: =+U19-W19 -> -356.78103 | Y19: =+[12]울산!$H$92/1000 -> 375.05523 | Z19: =+[12]울산!$I$92/1000 -> 113.30687 | AA19: =+Z19-Y19 -> -261.74836 | AB19: =+[13]울산!$H$92/1000 -> 687.88007 | AC19: =+Z19-AB19 -> -574.5732
B20: 아산 | I20: 아산 | J20: =+[4]아산!$H$86/1000 -> 333.50742 | K20: =+[4]아산!$I$86/1000 -> 68.806506 | L20: =+K20-J20 -> -264.70091 | M20: =+[5]아산!$H$86/1000 -> 58.469241 | N20: =+K20-M20 -> 10.337265 | O20: =+[4]아산!$H$92/1000 -> 228.084 | P20: =+[4]아산!$I$92/1000 -> -82.739351 | Q20: =+P20-O20 -> -310.82335 | R20: =+[5]아산!$H$92/1000 -> -112.56156 | S20: =+P20-R20 -> 29.822212 | T20: =+[12]아산!$H$86/1000 -> 3587.5204 | U20: =+[12]아산!$I$86/1000 -> 1088.7266 | V20: =+U20-T20 -> -2498.7938 | W20: =+[13]아산!$H$86/1000 -> 4186.6874 | X20: =+U20-W20 -> -3097.9608 | Y20: =+[12]아산!$H$92/1000 -> 2172.6822 | Z20: =+[12]아산!$I$92/1000 -> -520.89959 | AA20: =+Z20-Y20 -> -2693.5818 | AB20: =+[13]아산!$H$92/1000 -> 2612.1804 | AC20: =+Z20-AB20 -> -3133.08
B21: 전주 | I21: 전주 | J21: =+[4]전주!$H$86/1000 -> 158.26084 | K21: =+[4]전주!$I$86/1000 -> 24.639246 | L21: =+K21-J21 -> -133.6216 | M21: =+[5]전주!$H$86/1000 -> 10.653327 | N21: =+K21-M21 -> 13.985919 | O21: =+[4]전주!$H$92/1000 -> 112.73126 | P21: =+[4]전주!$I$92/1000 -> -59.653322 | Q21: =+P21-O21 -> -172.38459 | R21: =+[5]전주!$H$92/1000 -> -63.877252 | S21: =+P21-R21 -> 4.2239295 | T21: =+[12]전주!$H$86/1000 -> 1511.1574 | U21: =+[12]전주!$I$86/1000 -> 1437.3909 | V21: =+U21-T21 -> -73.766492 | W21: =+[13]전주!$H$86/1000 -> 640.017 | X21: =+U21-W21 -> 797.37393 | Y21: =+[12]전주!$H$92/1000 -> 854.74793 | Z21: =+[12]전주!$I$92/1000 -> 460.04775 | AA21: =+Z21-Y21 -> -394.70018 | AB21: =+[13]전주!$H$92/1000 -> 143.44046 | AC21: =+Z21-AB21 -> 316.60729
B22: 군산 | I22: 군산 | J22: =+[4]군산!$H$86/1000 -> 198.94578 | K22: =+[4]군산!$I$86/1000 -> 36.294072 | L22: =+K22-J22 -> -162.65171 | M22: =+[5]군산!$H$86/1000 -> 80.152254 | N22: =+K22-M22 -> -43.858182 | O22: =+[4]군산!$H$92/1000 -> 164.83152 | P22: =+[4]군산!$I$92/1000 -> 5.549201 | Q22: =+P22-O22 -> -159.28232 | R22: =+[5]군산!$H$92/1000 -> 35.722282 | S22: =+P22-R22 -> -30.173081 | T22: =+[12]군산!$H$86/1000 -> 2246.823 | U22: =+[12]군산!$I$86/1000 -> 1077.3261 | V22: =+U22-T22 -> -1169.4969 | W22: =+[13]군산!$H$86/1000 -> 2923.9684 | X22: =+U22-W22 -> -1846.6423 | Y22: =+[12]군산!$H$92/1000 -> 1767.4933 | Z22: =+[12]군산!$I$92/1000 -> 675.37605 | AA22: =+Z22-Y22 -> -1092.1173 | AB22: =+[13]군산!$H$92/1000 -> 2379.6403 | AC22: =+Z22-AB22 -> -1704.2643
B23: 원주 | I23: 원주 | J23: =+[4]원주!$H$86/1000 -> 60.992161 | K23: =+[4]원주!$I$86/1000 -> 1.329257 | L23: =+K23-J23 -> -59.662904 | M23: =+[5]원주!$H$86/1000 -> 39.135277 | N23: =+K23-M23 -> -37.80602 | O23: =+[4]원주!$H$92/1000 -> 42.650534 | P23: =+[4]원주!$I$92/1000 -> -27.134323 | Q23: =+P23-O23 -> -69.784857 | R23: =+[5]원주!$H$92/1000 -> 4.8569295 | S23: =+P23-R23 -> -31.991252 | T23: =+[12]원주!$H$86/1000 -> 1009.3797 | U23: =+[12]원주!$I$86/1000 -> 227.5616 | V23: =+U23-T23 -> -781.81808 | W23: =+[13]원주!$H$86/1000 -> 1368.5219 | X23: =+U23-W23 -> -1140.9603 | Y23: =+[12]원주!$H$92/1000 -> 695.34795 | Z23: =+[12]원주!$I$92/1000 -> -32.012262 | AA23: =+Z23-Y23 -> -727.36022 | AB23: =+[13]원주!$H$92/1000 -> 1013.3348 | AC23: =+Z23-AB23 -> -1045.3471
B24: 제주 | I24: 제주 | J24: =+[4]제주!$H$86/1000 -> 226.38407 | K24: =+[4]제주!$I$86/1000 -> 42.520962 | L24: =+K24-J24 -> -183.86311 | M24: =+[5]제주!$H$86/1000 -> 49.681543 | N24: =+K24-M24 -> -7.160581 | O24: =+[4]제주!$H$92/1000 -> 176.0474 | P24: =+[4]제주!$I$92/1000 -> -2.5305222 | Q24: =+P24-O24 -> -178.57792 | R24: =+[5]제주!$H$92/1000 -> -0.035449118 | S24: =+P24-R24 -> -2.4950731 | T24: =+[12]제주!$H$86/1000 -> 2003.8432 | U24: =+[12]제주!$I$86/1000 -> 705.23831 | V24: =+U24-T24 -> -1298.6049 | W24: =+[13]제주!$H$86/1000 -> 368.05902 | X24: =+U24-W24 -> 337.17929 | Y24: =+[12]제주!$H$92/1000 -> 1369.0504 | Z24: =+[12]제주!$I$92/1000 -> 189.54114 | AA24: =+Z24-Y24 -> -1179.5093 | AB24: =+[13]제주!$H$92/1000 -> 95.067342 | AC24: =+Z24-AB24 -> 94.473794
I25: 수도권 | J25: =SUM(J8:J11) -> 1112.3552 | K25: =SUM(K8:K11) -> -7.630242 | L25: =+K25-J25 -> -1119.9855 | M25: =SUM(M8:M11) -> -204.53605 | N25: =+K25-M25 -> 196.9058 | O25: =SUM(O8:O11) -> 641.3283 | P25: =SUM(P8:P11) -> -692.7117 | Q25: =+P25-O25 -> -1334.04 | R25: =SUM(R8:R11) -> -903.93682 | S25: =+P25-R25 -> 211.22512 | T25: =SUM(T8:T11) -> 9215.4722 | U25: =SUM(U8:U11) -> 2060.0688 | V25: =+U25-T25 -> -7155.4034 | W25: =SUM(W8:W11) -> 8135.8575 | X25: =+U25-W25 -> -6075.7887 | Y25: =SUM(Y8:Y11) -> 2824.4862 | Z25: =SUM(Z8:Z11) -> -4305.0923 | AA25: =+Z25-Y25 -> -7129.5786 | AB25: =SUM(AB8:AB11) -> 2101.1289 | AC25: =+Z25-AB25 -> -6406.2212
I26: 영남권 | J26: =SUM(J12:J19) -> 1501.0984 | K26: =SUM(K12:K19) -> 43.539371 | L26: =+K26-J26 -> -1457.5591 | M26: =SUM(M12:M19) -> 534.66819 | N26: =+K26-M26 -> -491.12882 | O26: =SUM(O12:O19) -> 893.15568 | P26: =SUM(P12:P19) -> -776.73953 | Q26: =+P26-O26 -> -1669.8952 | R26: =SUM(R12:R19) -> -481.57554 | S26: =+P26-R26 -> -295.16399 | T26: =SUM(T12:T19) -> 13357.392 | U26: =SUM(U12:U19) -> 6179.8389 | V26: =+U26-T26 -> -7177.5531 | W26: =SUM(W12:W19) -> 15414.173 | X26: =+U26-W26 -> -9234.3337 | Y26: =SUM(Y12:Y19) -> 5311.1381 | Z26: =SUM(Z12:Z19) -> -2354.3798 | AA26: =+Z26-Y26 -> -7665.5179 | AB26: =SUM(AB12:AB19) -> 7249.0122 | AC26: =+Z26-AB26 -> -9603.392
I27: 중부권 | J27: =SUM(J20:J24) -> 978.09028 | K27: =SUM(K20:K24) -> 173.59004 | L27: =+K27-J27 -> -804.50024 | M27: =SUM(M20:M24) -> 238.09164 | N27: =+K27-M27 -> -64.501599 | O27: =SUM(O20:O24) -> 724.34472 | P27: =SUM(P20:P24) -> -166.50832 | Q27: =+P27-O27 -> -890.85304 | R27: =SUM(R20:R24) -> -135.89505 | S27: =+P27-R27 -> -30.613265 | T27: =SUM(T20:T24) -> 10358.724 | U27: =SUM(U20:U24) -> 4536.2435 | V27: =+U27-T27 -> -5822.4802 | W27: =SUM(W20:W24) -> 9487.2538 | X27: =+U27-W27 -> -4951.0102 | Y27: =SUM(Y20:Y24) -> 6859.3219 | Z27: =SUM(Z20:Z24) -> 772.05308 | AA27: =+Z27-Y27 -> -6087.2688 | AB27: =SUM(AB20:AB24) -> 6243.6634 | AC27: =+Z27-AB27 -> -5471.6103
H28: 레미콘 계 | J28: =SUM(J25:J27) -> 3591.544 | K28: =SUM(K25:K27) -> 209.49917 | L28: =+K28-J28 -> -3382.0448 | M28: =SUM(M25:M27) -> 568.22379 | N28: =+K28-M28 -> -358.72461 | O28: =SUM(O25:O27) -> 2258.8287 | P28: =SUM(P25:P27) -> -1635.9596 | Q28: =+P28-O28 -> -3894.7883 | R28: =SUM(R25:R27) -> -1521.4074 | S28: =+P28-R28 -> -114.55214 | T28: =SUM(T25:T27) -> 32931.588 | U28: =SUM(U25:U27) -> 12776.151 | V28: =+U28-T28 -> -20155.437 | W28: =SUM(W25:W27) -> 33037.284 | X28: =+U28-W28 -> -20261.133 | Y28: =SUM(Y25:Y27) -> 14994.946 | Z28: =SUM(Z25:Z27) -> -5887.4191 | AA28: =+Z28-Y28 -> -20882.365 | AB28: =SUM(AB25:AB27) -> 15593.804 | AC28: =+Z28-AB28 -> -21481.224

Sheet 사업장별(당월)
H3: □ 사업장별 손익실적(2025-12)
AG4: [단위 : 천㎥, 톤, 백만원]
H5: 구분 | J5: 물량 | O5: 매출 | T5: 영업이익(공통비 배부전) | Y5: 판매단가 | AB5: 변동비 | AE5: 공헌이익
A6: 2024년 12월 마감 손익 | J6: 계획 | K6: 실적 | L6: 차이 | M6: 전년 | N6: 차이 | O6: 계획 | P6: 실적 | Q6: 차이 | R6: 전년 | S6: 차이 | T6: 계획 | U6: 실적 | V6: 차이 | W6: 전년 | X6: 차이 | Y6: 계획 | Z6: 실적 | AA6: 전년 | AB6: 계획 | AC6: 실적 | AD6: 전년 | AE6: 계획 | AF6: 실적 | AG6: 전년
B7: 안양 | G7: =+I7 -> 안양 | H7: 레미콘 | I7: 안양 | J7: =+IFERROR(HLOOKUP($B7,'[1]12월'!$D$6:$BN$259,2,),)/1000 -> 41 | K7: =+IFERROR(HLOOKUP($B7,'[2]12월'!$F$6:$CP$99,2,),)/1000 -> 31.317 | L7: =+K7-J7 -> -9.683 | M7: =+IFERROR(HLOOKUP($B7,'[3]12월'!$F$6:$CC$57,2,),)/1000 -> 34.67 | N7: =+K7-M7 -> -3.353 | O7: =+IFERROR(HLOOKUP($B7,'[1]12월'!$D$6:$BN$259,3,),)/1000 -> 4252.2908 | P7: =+IFERROR(HLOOKUP($B7,'[2]12월'!$F$6:$CP$99,3,),)/1000 -> 3194.0082 | Q7: =+P7-O7 -> -1058.2826 | R7: =+IFERROR(HLOOKUP($B7,'[3]12월'!$F$6:$CC$57,3,),)/1000 -> 3342.2601 | S7: =+P7-R7 -> -148.25192 | T7: =+IFERROR(HLOOKUP($B7,'[1]12월'!$D$6:$BN$259,16,),)/1000 -> 565.37708 | U7: =+IFERROR(HLOOKUP($B7,'[2]12월'!$F$6:$CP$99,16,),)/1000 -> 188.84256 | V7: =+U7-T7 -> -376.53452 | W7: =+IFERROR(HLOOKUP($B7,'[3]12월'!$F$6:$CC$57,16,),)/1000 -> 51.528149 | X7: =+U7-W7 -> 137.31441 | Y7: =+[4]안양!$Q$85 -> 103714.41 | Z7: =+[4]안양!$R$85 -> 101989.6 | AA7: =+[5]안양!$Q$85 -> 96402.081 | AB7: =+[4]안양!$Q$89 -> 82971.278 | AC7: =+[4]안양!$R$89 -> 84587.481 | AD7: =+[5]안양!$Q$89 -> 82908.854 | AE7: =+Y7-AB7 -> 20743.131 | AF7: =+Z7-AC7 -> 17402.116 | AG7: =+AA7-AD7 -> 13493.227
B8: 인천 | G8: =+I8 -> 인천 | H8: 직영 | I8: 인천 | J8: =+IFERROR(HLOOKUP($B8,'[1]12월'!$D$6:$BN$259,2,),)/1000 -> 32 | K8: =+IFERROR(HLOOKUP($B8,'[2]12월'!$F$6:$CP$99,2,),)/1000 -> 31.475 | L8: =+K8-J8 -> -0.525 | M8: =+IFERROR(HLOOKUP($B8,'[3]12월'!$F$6:$CC$57,2,),)/1000 -> 30.362 | N8: =+K8-M8 -> 1.113 | O8: =+IFERROR(HLOOKUP($B8,'[1]12월'!$D$6:$BN$259,3,),)/1000 -> 3312.3507 | P8: =+IFERROR(HLOOKUP($B8,'[2]12월'!$F$6:$CP$99,3,),)/1000 -> 3110.8678 | Q8: =+P8-O8 -> -201.48294 | R8: =+IFERROR(HLOOKUP($B8,'[3]12월'!$F$6:$CC$57,3,),)/1000 -> 2969.3944 | S8: =+P8-R8 -> 141.47341 | T8: =+IFERROR(HLOOKUP($B8,'[1]12월'!$D$6:$BN$259,16,),)/1000 -> 335.03112 | U8: =+IFERROR(HLOOKUP($B8,'[2]12월'!$F$6:$CP$99,16,),)/1000 -> -60.530205 | V8: =+U8-T8 -> -395.56132 | W8: =+IFERROR(HLOOKUP($B8,'[3]12월'!$F$6:$CC$57,16,),)/1000 -> -49.54122 | X8: =+U8-W8 -> -10.988985 | Y8: =+[4]인천!$Q$85 -> 103510.96 | Z8: =+[4]인천!$R$85 -> 98884.465 | AA8: =+[5]인천!$Q$85 -> 97799.697 | AB8: =+[4]인천!$Q$89 -> 84269.957 | AC8: =+[4]인천!$R$89 -> 89818.639 | AD8: =+[5]인천!$Q$89 -> 86503.735 | AE8: =+Y8-AB8 -> 19241.004 | AF8: =+Z8-AC8 -> 9065.8265 | AG8: =+AA8-AD8 -> 11295.962
B9: 파주 | G9: =+I9 -> 파주 | I9: 파주 | J9: =+IFERROR(HLOOKUP($B9,'[1]12월'!$D$6:$BN$259,2,),)/1000 -> 21 | K9: =+IFERROR(HLOOKUP($B9,'[2]12월'!$F$6:$CP$99,2,),)/1000 -> 13.662 | L9: =+K9-J9 -> -7.338 | M9: =+IFERROR(HLOOKUP($B9,'[3]12월'!$F$6:$CC$57,2,),)/1000 -> 16.303 | N9: =+K9-M9 -> -2.641 | O9: =+IFERROR(HLOOKUP($B9,'[1]12월'!$D$6:$BN$259,3,),)/1000 -> 1999.4837 | P9: =+IFERROR(HLOOKUP($B9,'[2]12월'!$F$6:$CP$99,3,),)/1000 -> 1345.027 | Q9: =+P9-O9 -> -654.45674 | R9: =+IFERROR(HLOOKUP($B9,'[3]12월'!$F$6:$CC$57,3,),)/1000 -> 1513.0633 | S9: =+P9-R9 -> -168.03634 | T9: =+IFERROR(HLOOKUP($B9,'[1]12월'!$D$6:$BN$259,16,),)/1000 -> 89.794589 | U9: =+IFERROR(HLOOKUP($B9,'[2]12월'!$F$6:$CP$99,16,),)/1000 -> -96.411096 | V9: =+U9-T9 -> -186.20569 | W9: =+IFERROR(HLOOKUP($B9,'[3]12월'!$F$6:$CC$57,16,),)/1000 -> -160.22943 | X9: =+U9-W9 -> 63.81833 | Y9: =+[4]파주!$Q$85 -> 95213.511 | Z9: =+[4]파주!$R$85 -> 98582.895 | AA9: =+[5]파주!$Q$85 -> 92808.89 | AB9: =+[4]파주!$Q$89 -> 80317.167 | AC9: =+[4]파주!$R$89 -> 90468.02 | AD9: =+[5]파주!$Q$89 -> 85217.769 | AE9: =+Y9-AB9 -> 14896.345 | AF9: =+Z9-AC9 -> 8114.8749 | AG9: =+AA9-AD9 -> 7591.1217
B10: 김포 | G10: =+I10 -> 김포 | I10: 김포 | J10: =+IFERROR(HLOOKUP($B10,'[1]12월'!$D$6:$BN$259,2,),)/1000 -> 15 | K10: =+IFERROR(HLOOKUP($B10,'[2]12월'!$F$6:$CP$99,2,),)/1000 -> 11.82306 | L10: =+K10-J10 -> -3.17694 | M10: =+IFERROR(HLOOKUP($B10,'[3]12월'!$F$6:$CC$57,2,),)/1000 -> 13.4185 | N10: =+K10-M10 -> -1.59544 | O10: =+IFERROR(HLOOKUP($B10,'[1]12월'!$D$6:$BN$259,3,),)/1000 -> 1430.397 | P10: =+IFERROR(HLOOKUP($B10,'[2]12월'!$F$6:$CP$99,3,),)/1000 -> 1164.795 | Q10: =+P10-O10 -> -265.60199 | R10: =+IFERROR(HLOOKUP($B10,'[3]12월'!$F$6:$CC$57,3,),)/1000 -> 1247.6161 | S10: =+P10-R10 -> -82.821138 | T10: =+IFERROR(HLOOKUP($B10,'[1]12월'!$D$6:$BN$259,16,),)/1000 -> 122.15246 | U10: =+IFERROR(HLOOKUP($B10,'[2]12월'!$F$6:$CP$99,16,),)/1000 -> -39.531496 | V10: =+U10-T10 -> -161.68395 | W10: =+IFERROR(HLOOKUP($B10,'[3]12월'!$F$6:$CC$57,16,),)/1000 -> -46.29355 | X10: =+U10-W10 -> 6.762054 | Y10: =+[4]김포!$Q$85 -> 95359.8 | Z10: =+[4]김포!$R$85 -> 98518.912 | AA10: =+[5]김포!$Q$85 -> 93010.903 | AB10: =+[4]김포!$Q$89 -> 76510.559 | AC10: =+[4]김포!$R$89 -> 84962.316 | AD10: =+[5]김포!$Q$89 -> 79168.533 | AE10: =+Y10-AB10 -> 18849.241 | AF10: =+Z10-AC10 -> 13556.596 | AG10: =+AA10-AD10 -> 13842.37
B11: 부산 | G11: =+I11 -> 부산 | I11: 부산 | J11: =+IFERROR(HLOOKUP($B11,'[1]12월'!$D$6:$BN$259,2,),)/1000 -> 22 | K11: =+IFERROR(HLOOKUP($B11,'[2]12월'!$F$6:$CP$99,2,),)/1000 -> 22.261 | L11: =+K11-J11 -> 0.261 | M11: =+IFERROR(HLOOKUP($B11,'[3]12월'!$F$6:$CC$57,2,),)/1000 -> 17.339 | N11: =+K11-M11 -> 4.922 | O11: =+IFERROR(HLOOKUP($B11,'[1]12월'!$D$6:$BN$259,3,),)/1000 -> 2369.3977 | P11: =+IFERROR(HLOOKUP($B11,'[2]12월'!$F$6:$CP$99,3,),)/1000 -> 2428.6556 | Q11: =+P11-O11 -> 59.25793 | R11: =+IFERROR(HLOOKUP($B11,'[3]12월'!$F$6:$CC$57,3,),)/1000 -> 1980.4694 | S11: =+P11-R11 -> 448.1862 | T11: =+IFERROR(HLOOKUP($B11,'[1]12월'!$D$6:$BN$259,16,),)/1000 -> 231.81377 | U11: =+IFERROR(HLOOKUP($B11,'[2]12월'!$F$6:$CP$99,16,),)/1000 -> 159.61886 | V11: =+U11-T11 -> -72.194902 | W11: =+IFERROR(HLOOKUP($B11,'[3]12월'!$F$6:$CC$57,16,),)/1000 -> 92.183809 | X11: =+U11-W11 -> 67.435055 | Y11: =+[4]부산!$Q$85 -> 107699.89 | Z11: =+[4]부산!$R$85 -> 109099.12 | AA11: =+[5]부산!$Q$85 -> 114220.51 | AB11: =+[4]부산!$Q$89 -> 85882.676 | AC11: =+[4]부산!$R$89 -> 90355.725 | AD11: =+[5]부산!$Q$89 -> 90394.221 | AE11: =+Y11-AB11 -> 21817.219 | AF11: =+Z11-AC11 -> 18743.399 | AG11: =+AA11-AD11 -> 23826.288
B12: 서부산 | G12: =+I12 -> 서부산 | I12: 서부산 | J12: =+IFERROR(HLOOKUP($B12,'[1]12월'!$D$6:$BN$259,2,),)/1000 -> 23 | K12: =+IFERROR(HLOOKUP($B12,'[2]12월'!$F$6:$CP$99,2,),)/1000 -> 19.064 | L12: =+K12-J12 -> -3.936 | M12: =+IFERROR(HLOOKUP($B12,'[3]12월'!$F$6:$CC$57,2,),)/1000 -> 24.067 | N12: =+K12-M12 -> -5.003 | O12: =+IFERROR(HLOOKUP($B12,'[1]12월'!$D$6:$BN$259,3,),)/1000 -> 2283.889 | P12: =+IFERROR(HLOOKUP($B12,'[2]12월'!$F$6:$CP$99,3,),)/1000 -> 1993.4115 | Q12: =+P12-O12 -> -290.47752 | R12: =+IFERROR(HLOOKUP($B12,'[3]12월'!$F$6:$CC$57,3,),)/1000 -> 2361.636 | S12: =+P12-R12 -> -368.2245 | T12: =+IFERROR(HLOOKUP($B12,'[1]12월'!$D$6:$BN$259,16,),)/1000 -> 266.46368 | U12: =+IFERROR(HLOOKUP($B12,'[2]12월'!$F$6:$CP$99,16,),)/1000 -> 119.86852 | V12: =+U12-T12 -> -146.59516 | W12: =+IFERROR(HLOOKUP($B12,'[3]12월'!$F$6:$CC$57,16,),)/1000 -> 163.09231 | X12: =+U12-W12 -> -43.223798 | Y12: =+[4]서부산!$Q$85 -> 99299.523 | Z12: =+[4]서부산!$R$85 -> 104564.18 | AA12: =+[5]서부산!$Q$85 -> 98127.561 | AB12: =+[4]서부산!$Q$89 -> 79466.311 | AC12: =+[4]서부산!$R$89 -> 85738.617 | AD12: =+[5]서부산!$Q$89 -> 78950.52 | AE12: =+Y12-AB12 -> 19833.211 | AF12: =+Z12-AC12 -> 18825.562 | AG12: =+AA12-AD12 -> 19177.041
B13: 김해 | G13: =+I13 -> 김해 | I13: 김해 | J13: =+IFERROR(HLOOKUP($B13,'[1]12월'!$D$6:$BN$259,2,),)/1000 -> 16 | K13: =+IFERROR(HLOOKUP($B13,'[2]12월'!$F$6:$CP$99,2,),)/1000 -> 5.707 | L13: =+K13-J13 -> -10.293 | M13: =+IFERROR(HLOOKUP($B13,'[3]12월'!$F$6:$CC$57,2,),)/1000 -> 12.184 | N13: =+K13-M13 -> -6.477 | O13: =+IFERROR(HLOOKUP($B13,'[1]12월'!$D$6:$BN$259,3,),)/1000 -> 1540.7967 | P13: =+IFERROR(HLOOKUP($B13,'[2]12월'!$F$6:$CP$99,3,),)/1000 -> 506.1873 | Q13: =+P13-O13 -> -1034.6094 | R13: =+IFERROR(HLOOKUP($B13,'[3]12월'!$F$6:$CC$57,3,),)/1000 -> 1145.9621 | S13: =+P13-R13 -> -639.7748 | T13: =+IFERROR(HLOOKUP($B13,'[1]12월'!$D$6:$BN$259,16,),)/1000 -> 149.52483 | U13: =+IFERROR(HLOOKUP($B13,'[2]12월'!$F$6:$CP$99,16,),)/1000 -> -123.04865 | V13: =+U13-T13 -> -272.57348 | W13: =+IFERROR(HLOOKUP($B13,'[3]12월'!$F$6:$CC$57,16,),)/1000 -> -58.225946 | X13: =+U13-W13 -> -64.822704 | Y13: =+[4]김해!$Q$85 -> 96299.794 | Z13: =+[4]김해!$R$85 -> 88695.865 | AA13: =+[5]김해!$Q$85 -> 94036.649 | AB13: =+[4]김해!$Q$89 -> 77852.386 | AC13: =+[4]김해!$R$89 -> 82661.358 | AD13: =+[5]김해!$Q$89 -> 80796.704 | AE13: =+Y13-AB13 -> 18447.408 | AF13: =+Z13-AC13 -> 6034.5067 | AG13: =+AA13-AD13 -> 13239.945
B14: 정관 | G14: =+I14 -> 정관 | I14: 정관 | J14: =+IFERROR(HLOOKUP($B14,'[1]12월'!$D$6:$BN$259,2,),)/1000 -> 21 | K14: =+IFERROR(HLOOKUP($B14,'[2]12월'!$F$6:$CP$99,2,),)/1000 -> 17.197 | L14: =+K14-J14 -> -3.803 | M14: =+IFERROR(HLOOKUP($B14,'[3]12월'!$F$6:$CC$57,2,),)/1000 -> 22.034 | N14: =+K14-M14 -> -4.837 | O14: =+IFERROR(HLOOKUP($B14,'[1]12월'!$D$6:$BN$259,3,),)/1000 -> 2141.9971 | P14: =+IFERROR(HLOOKUP($B14,'[2]12월'!$F$6:$CP$99,3,),)/1000 -> 1701.1391 | Q14: =+P14-O14 -> -440.85797 | R14: =+IFERROR(HLOOKUP($B14,'[3]12월'!$F$6:$CC$57,3,),)/1000 -> 2288.9945 | S14: =+P14-R14 -> -587.8554 | T14: =+IFERROR(HLOOKUP($B14,'[1]12월'!$D$6:$BN$259,16,),)/1000 -> 208.30033 | U14: =+IFERROR(HLOOKUP($B14,'[2]12월'!$F$6:$CP$99,16,),)/1000 -> 0.431591 | V14: =+U14-T14 -> -207.86874 | W14: =+IFERROR(HLOOKUP($B14,'[3]12월'!$F$6:$CC$57,16,),)/1000 -> 101.28182 | X14: =+U14-W14 -> -100.85023 | Y14: =+[4]정관!$Q$85 -> 101999.86 | Z14: =+[4]정관!$R$85 -> 98920.69 | AA14: =+[5]정관!$Q$85 -> 103884.66 | AB14: =+[4]정관!$Q$89 -> 82449.919 | AC14: =+[4]정관!$R$89 -> 85268.573 | AD14: =+[5]정관!$Q$89 -> 86215.634 | AE14: =+Y14-AB14 -> 19549.942 | AF14: =+Z14-AC14 -> 13652.117 | AG14: =+AA14-AD14 -> 17669.022
B15: 양산 | G15: =+I15 -> 양산 | I15: 양산 | J15: =+IFERROR(HLOOKUP($B15,'[1]12월'!$D$6:$BN$259,2,),)/1000 -> 13 | K15: =+IFERROR(HLOOKUP($B15,'[2]12월'!$F$6:$CP$99,2,),)/1000 -> 6.497 | L15: =+K15-J15 -> -6.503 | M15: =+IFERROR(HLOOKUP($B15,'[3]12월'!$F$6:$CC$57,2,),)/1000 -> 10.174 | N15: =+K15-M15 -> -3.677 | O15: =+IFERROR(HLOOKUP($B15,'[1]12월'!$D$6:$BN$259,3,),)/1000 -> 1222.6012 | P15: =+IFERROR(HLOOKUP($B15,'[2]12월'!$F$6:$CP$99,3,),)/1000 -> 599.63222 | Q15: =+P15-O15 -> -622.96903 | R15: =+IFERROR(HLOOKUP($B15,'[3]12월'!$F$6:$CC$57,3,),)/1000 -> 958.2302 | S15: =+P15-R15 -> -358.59798 | T15: =+IFERROR(HLOOKUP($B15,'[1]12월'!$D$6:$BN$259,16,),)/1000 -> 115.63862 | U15: =+IFERROR(HLOOKUP($B15,'[2]12월'!$F$6:$CP$99,16,),)/1000 -> -104.9457 | V15: =+U15-T15 -> -220.58432 | W15: =+IFERROR(HLOOKUP($B15,'[3]12월'!$F$6:$CC$57,16,),)/1000 -> -28.828367 | X15: =+U15-W15 -> -76.117332 | Y15: =+[4]양산!$Q$85 -> 94046.25 | Z15: =+[4]양산!$R$85 -> 92293.708 | AA15: =+[5]양산!$Q$85 -> 94184.215 | AB15: =+[4]양산!$Q$89 -> 74732.837 | AC15: =+[4]양산!$R$89 -> 80972.964 | AD15: =+[5]양산!$Q$89 -> 78064.419 | AE15: =+Y15-AB15 -> 19313.413 | AF15: =+Z15-AC15 -> 11320.743 | AG15: =+AA15-AD15 -> 16119.796
B16: 창원 | G16: =+I16 -> 창원 | I16: 창원 | J16: =+IFERROR(HLOOKUP($B16,'[1]12월'!$D$6:$BN$259,2,),)/1000 -> 19 | K16: =+IFERROR(HLOOKUP($B16,'[2]12월'!$F$6:$CP$99,2,),)/1000 -> 11.71 | L16: =+K16-J16 -> -7.29 | M16: =+IFERROR(HLOOKUP($B16,'[3]12월'!$F$6:$CC$57,2,),)/1000 -> 12.315 | N16: =+K16-M16 -> -0.605 | O16: =+IFERROR(HLOOKUP($B16,'[1]12월'!$D$6:$BN$259,3,),)/1000 -> 1934.9141 | P16: =+IFERROR(HLOOKUP($B16,'[2]12월'!$F$6:$CP$99,3,),)/1000 -> 1098.0858 | Q16: =+P16-O16 -> -836.8283 | R16: =+IFERROR(HLOOKUP($B16,'[3]12월'!$F$6:$CC$57,3,),)/1000 -> 1261.8106 | S16: =+P16-R16 -> -163.72475 | T16: =+IFERROR(HLOOKUP($B16,'[1]12월'!$D$6:$BN$259,16,),)/1000 -> 309.29623 | U16: =+IFERROR(HLOOKUP($B16,'[2]12월'!$F$6:$CP$99,16,),)/1000 -> 53.035499 | V16: =+U16-T16 -> -256.26073 | W16: =+IFERROR(HLOOKUP($B16,'[3]12월'!$F$6:$CC$57,16,),)/1000 -> 72.758357 | X16: =+U16-W16 -> -19.722858 | Y16: =+[4]창원!$Q$85 -> 101837.58 | Z16: =+[4]창원!$R$85 -> 93773.339 | AA16: =+[5]창원!$Q$85 -> 102461.27 | AB16: =+[4]창원!$Q$89 -> 76200.161 | AC16: =+[4]창원!$R$89 -> 74074.051 | AD16: =+[5]창원!$Q$89 -> 76573.527 | AE16: =+Y16-AB16 -> 25637.424 | AF16: =+Z16-AC16 -> 19699.288 | AG16: =+AA16-AD16 -> 25887.744
B17: 대구 | G17: =+I17 -> 대구 | I17: 대구 | J17: =+IFERROR(HLOOKUP($B17,'[1]12월'!$D$6:$BN$259,2,),)/1000 -> 12 | K17: =+IFERROR(HLOOKUP($B17,'[2]12월'!$F$6:$CP$99,2,),)/1000 -> 4.07 | L17: =+K17-J17 -> -7.93 | M17: =+IFERROR(HLOOKUP($B17,'[3]12월'!$F$6:$CC$57,2,),)/1000 -> 18.708 | N17: =+K17-M17 -> -14.638 | O17: =+IFERROR(HLOOKUP($B17,'[1]12월'!$D$6:$BN$259,3,),)/1000 -> 1167.3657 | P17: =+IFERROR(HLOOKUP($B17,'[2]12월'!$F$6:$CP$99,3,),)/1000 -> 346.87933 | Q17: =+P17-O17 -> -820.48633 | R17: =+IFERROR(HLOOKUP($B17,'[3]12월'!$F$6:$CC$57,3,),)/1000 -> 1801.6908 | S17: =+P17-R17 -> -1454.8114 | T17: =+IFERROR(HLOOKUP($B17,'[1]12월'!$D$6:$BN$259,16,),)/1000 -> 102.30373 | U17: =+IFERROR(HLOOKUP($B17,'[2]12월'!$F$6:$CP$99,16,),)/1000 -> -127.9319 | V17: =+U17-T17 -> -230.23563 | W17: =+IFERROR(HLOOKUP($B17,'[3]12월'!$F$6:$CC$57,16,),)/1000 -> 168.03998 | X17: =+U17-W17 -> -295.97188 | Y17: =+[4]대구!$Q$85 -> 97280.472 | Z17: =+[4]대구!$R$85 -> 85228.338 | AA17: =+[5]대구!$Q$85 -> 96305.899 | AB17: =+[4]대구!$Q$89 -> 75132.541 | AC17: =+[4]대구!$R$89 -> 76470.767 | AD17: =+[5]대구!$Q$89 -> 73764.096 | AE17: =+Y17-AB17 -> 22147.931 | AF17: =+Z17-AC17 -> 8757.5705 | AG17: =+AA17-AD17 -> 22541.803
B18: 울산 | G18: =+I18 -> 울산 | I18: 울산 | J18: =+IFERROR(HLOOKUP($B18,'[1]12월'!$D$6:$BN$259,2,),)/1000 -> 12.5 | K18: =+IFERROR(HLOOKUP($B18,'[2]12월'!$F$6:$CP$99,2,),)/1000 -> 13.221 | L18: =+K18-J18 -> 0.721 | M18: =+IFERROR(HLOOKUP($B18,'[3]12월'!$F$6:$CC$57,2,),)/1000 -> 12.451 | N18: =+K18-M18 -> 0.77 | O18: =+IFERROR(HLOOKUP($B18,'[1]12월'!$D$6:$BN$259,3,),)/1000 -> 1297.9025 | P18: =+IFERROR(HLOOKUP($B18,'[2]12월'!$F$6:$CP$99,3,),)/1000 -> 1382.7362 | Q18: =+P18-O18 -> 84.83374 | R18: =+IFERROR(HLOOKUP($B18,'[3]12월'!$F$6:$CC$57,3,),)/1000 -> 1273.3891 | S18: =+P18-R18 -> 109.34714 | T18: =+IFERROR(HLOOKUP($B18,'[1]12월'!$D$6:$BN$259,16,),)/1000 -> 117.75726 | U18: =+IFERROR(HLOOKUP($B18,'[2]12월'!$F$6:$CP$99,16,),)/1000 -> 66.511149 | V18: =+U18-T18 -> -51.246106 | W18: =+IFERROR(HLOOKUP($B18,'[3]12월'!$F$6:$CC$57,16,),)/1000 -> 24.366226 | X18: =+U18-W18 -> 42.144923 | Y18: =+[4]울산!$Q$85 -> 103832.2 | Z18: =+[4]울산!$R$85 -> 104586.36 | AA18: =+[5]울산!$Q$85 -> 102272.03 | AB18: =+[4]울산!$Q$89 -> 83764.602 | AC18: =+[4]울산!$R$89 -> 88415.573 | AD18: =+[5]울산!$Q$89 -> 84277.211 | AE18: =+Y18-AB18 -> 20067.598 | AF18: =+Z18-AC18 -> 16170.785 | AG18: =+AA18-AD18 -> 17994.823
B19: 아산 | G19: =+I19 -> 아산 | I19: 아산 | J19: =+IFERROR(HLOOKUP($B19,'[1]12월'!$D$6:$BN$259,2,),)/1000 -> 25 | K19: =+IFERROR(HLOOKUP($B19,'[2]12월'!$F$6:$CP$99,2,),)/1000 -> 18.784 | L19: =+K19-J19 -> -6.216 | M19: =+IFERROR(HLOOKUP($B19,'[3]12월'!$F$6:$CC$57,2,),)/1000 -> 22.732 | N19: =+K19-M19 -> -3.948 | O19: =+IFERROR(HLOOKUP($B19,'[1]12월'!$D$6:$BN$259,3,),)/1000 -> 2575 | P19: =+IFERROR(HLOOKUP($B19,'[2]12월'!$F$6:$CP$99,3,),)/1000 -> 1949.8863 | Q19: =+P19-O19 -> -625.11368 | R19: =+IFERROR(HLOOKUP($B19,'[3]12월'!$F$6:$CC$57,3,),)/1000 -> 2299.4823 | S19: =+P19-R19 -> -349.59598 | T19: =+IFERROR(HLOOKUP($B19,'[1]12월'!$D$6:$BN$259,16,),)/1000 -> 333.50742 | U19: =+IFERROR(HLOOKUP($B19,'[2]12월'!$F$6:$CP$99,16,),)/1000 -> 68.806506 | V19: =+U19-T19 -> -264.70091 | W19: =+IFERROR(HLOOKUP($B19,'[3]12월'!$F$6:$CC$57,16,),)/1000 -> 58.469241 | X19: =+U19-W19 -> 10.337265 | Y19: =+[4]아산!$Q$85 -> 103000 | Z19: =+[4]아산!$R$85 -> 103805.7 | AA19: =+[5]아산!$Q$85 -> 101156.18 | AB19: =+[4]아산!$Q$89 -> 80551.044 | AC19: =+[4]아산!$R$89 -> 87355.136 | AD19: =+[5]아산!$Q$89 -> 85004.174 | AE19: =+Y19-AB19 -> 22448.956 | AF19: =+Z19-AC19 -> 16450.567 | AG19: =+AA19-AD19 -> 16152.007
B20: 전주 | G20: =+I20 -> 전주 | I20: 전주 | J20: =+IFERROR(HLOOKUP($B20,'[1]12월'!$D$6:$BN$259,2,),)/1000 -> 11 | K20: =+IFERROR(HLOOKUP($B20,'[2]12월'!$F$6:$CP$99,2,),)/1000 -> 10.639 | L20: =+K20-J20 -> -0.361 | M20: =+IFERROR(HLOOKUP($B20,'[3]12월'!$F$6:$CC$57,2,),)/1000 -> 10.326 | N20: =+K20-M20 -> 0.313 | O20: =+IFERROR(HLOOKUP($B20,'[1]12월'!$D$6:$BN$259,3,),)/1000 -> 1112.0742 | P20: =+IFERROR(HLOOKUP($B20,'[2]12월'!$F$6:$CP$99,3,),)/1000 -> 1084.5623 | Q20: =+P20-O20 -> -27.511884 | R20: =+IFERROR(HLOOKUP($B20,'[3]12월'!$F$6:$CC$57,3,),)/1000 -> 1002.0519 | S20: =+P20-R20 -> 82.510388 | T20: =+IFERROR(HLOOKUP($B20,'[1]12월'!$D$6:$BN$259,16,),)/1000 -> 158.26084 | U20: =+IFERROR(HLOOKUP($B20,'[2]12월'!$F$6:$CP$99,16,),)/1000 -> 24.639246 | V20: =+U20-T20 -> -133.6216 | W20: =+IFERROR(HLOOKUP($B20,'[3]12월'!$F$6:$CC$57,16,),)/1000 -> 10.653327 | X20: =+U20-W20 -> 13.985919 | Y20: =+[4]전주!$Q$85 -> 101097.65 | Z20: =+[4]전주!$R$85 -> 101942.13 | AA20: =+[5]전주!$Q$85 -> 97041.635 | AB20: =+[4]전주!$Q$89 -> 73656.495 | AC20: =+[4]전주!$R$89 -> 82680.208 | AD20: =+[5]전주!$Q$89 -> 74828.153 | AE20: =+Y20-AB20 -> 27441.159 | AF20: =+Z20-AC20 -> 19261.922 | AG20: =+AA20-AD20 -> 22213.483
B21: 군산 | G21: =+I21 -> 군산 | I21: 군산 | J21: =+IFERROR(HLOOKUP($B21,'[1]12월'!$D$6:$BN$259,2,),)/1000 -> 7.5 | K21: =+IFERROR(HLOOKUP($B21,'[2]12월'!$F$6:$CP$99,2,),)/1000 -> 3.546 | L21: =+K21-J21 -> -3.954 | M21: =+IFERROR(HLOOKUP($B21,'[3]12월'!$F$6:$CC$57,2,),)/1000 -> 5.608 | N21: =+K21-M21 -> -2.062 | O21: =+IFERROR(HLOOKUP($B21,'[1]12월'!$D$6:$BN$259,3,),)/1000 -> 833.2516 | P21: =+IFERROR(HLOOKUP($B21,'[2]12월'!$F$6:$CP$99,3,),)/1000 -> 395.58326 | Q21: =+P21-O21 -> -437.66835 | R21: =+IFERROR(HLOOKUP($B21,'[3]12월'!$F$6:$CC$57,3,),)/1000 -> 597.354 | S21: =+P21-R21 -> -201.77075 | T21: =+IFERROR(HLOOKUP($B21,'[1]12월'!$D$6:$BN$259,16,),)/1000 -> 198.94578 | U21: =+IFERROR(HLOOKUP($B21,'[2]12월'!$F$6:$CP$99,16,),)/1000 -> 36.294072 | V21: =+U21-T21 -> -162.65171 | W21: =+IFERROR(HLOOKUP($B21,'[3]12월'!$F$6:$CC$57,16,),)/1000 -> 80.152254 | X21: =+U21-W21 -> -43.858182 | Y21: =+[4]군산!$Q$85 -> 111100.21 | Z21: =+[4]군산!$R$85 -> 111557.6 | AA21: =+[5]군산!$Q$85 -> 106518.19 | AB21: =+[4]군산!$Q$89 -> 74168.252 | AC21: =+[4]군산!$R$89 -> 76050.378 | AD21: =+[5]군산!$Q$89 -> 73466.5 | AE21: =+Y21-AB21 -> 36931.961 | AF21: =+Z21-AC21 -> 35507.223 | AG21: =+AA21-AD21 -> 33051.688
B22: 원주 | G22: =+I22 -> 원주 | I22: 원주 | J22: =+IFERROR(HLOOKUP($B22,'[1]12월'!$D$6:$BN$259,2,),)/1000 -> 4 | K22: =+IFERROR(HLOOKUP($B22,'[2]12월'!$F$6:$CP$99,2,),)/1000 -> 3.0675 | L22: =+K22-J22 -> -0.9325 | M22: =+IFERROR(HLOOKUP($B22,'[3]12월'!$F$6:$CC$57,2,),)/1000 -> 4.01 | N22: =+K22-M22 -> -0.9425 | O22: =+IFERROR(HLOOKUP($B22,'[1]12월'!$D$6:$BN$259,3,),)/1000 -> 448 | P22: =+IFERROR(HLOOKUP($B22,'[2]12월'!$F$6:$CP$99,3,),)/1000 -> 366.2307 | Q22: =+P22-O22 -> -81.7693 | R22: =+IFERROR(HLOOKUP($B22,'[3]12월'!$F$6:$CC$57,3,),)/1000 -> 460.867 | S22: =+P22-R22 -> -94.6363 | T22: =+IFERROR(HLOOKUP($B22,'[1]12월'!$D$6:$BN$259,16,),)/1000 -> 60.992161 | U22: =+IFERROR(HLOOKUP($B22,'[2]12월'!$F$6:$CP$99,16,),)/1000 -> 1.329257 | V22: =+U22-T22 -> -59.662904 | W22: =+IFERROR(HLOOKUP($B22,'[3]12월'!$F$6:$CC$57,16,),)/1000 -> 39.135277 | X22: =+U22-W22 -> -37.80602 | Y22: =+[4]원주!$Q$85 -> 112000 | Z22: =+[4]원주!$R$85 -> 119466.75 | AA22: =+[5]원주!$Q$85 -> 114929.43 | AB22: =+[4]원주!$Q$89 -> 75699.82 | AC22: =+[4]원주!$R$89 -> 83044.874 | AD22: =+[5]원주!$Q$89 -> 76446.968 | AE22: =+Y22-AB22 -> 36300.18 | AF22: =+Z22-AC22 -> 36421.88 | AG22: =+AA22-AD22 -> 38482.458
B23: 제주 | F23: =+K27-J27 -> -76.43994 | G23: =+I23 -> 제주 | I23: 제주 | J23: =+IFERROR(HLOOKUP($B23,'[1]12월'!$D$6:$BN$259,2,),)/1000 -> 10 | K23: =+IFERROR(HLOOKUP($B23,'[2]12월'!$F$6:$CP$99,2,),)/1000 -> 4.5195 | L23: =+K23-J23 -> -5.4805 | M23: =+IFERROR(HLOOKUP($B23,'[3]12월'!$F$6:$CC$57,2,),)/1000 -> 5.5875 | N23: =+K23-M23 -> -1.068 | O23: =+IFERROR(HLOOKUP($B23,'[1]12월'!$D$6:$BN$259,3,),)/1000 -> 1229.489 | P23: =+IFERROR(HLOOKUP($B23,'[2]12월'!$F$6:$CP$99,3,),)/1000 -> 579.66133 | Q23: =+P23-O23 -> -649.82767 | R23: =+IFERROR(HLOOKUP($B23,'[3]12월'!$F$6:$CC$57,3,),)/1000 -> 668.43715 | S23: =+P23-R23 -> -88.775824 | T23: =+IFERROR(HLOOKUP($B23,'[1]12월'!$D$6:$BN$259,16,),)/1000 -> 226.38407 | U23: =+IFERROR(HLOOKUP($B23,'[2]12월'!$F$6:$CP$99,16,),)/1000 -> 42.520962 | V23: =+U23-T23 -> -183.86311 | W23: =+IFERROR(HLOOKUP($B23,'[3]12월'!$F$6:$CC$57,16,),)/1000 -> 49.681543 | X23: =+U23-W23 -> -7.160581 | Y23: =+[4]제주!$Q$85 -> 122948.9 | Z23: =+[4]제주!$R$85 -> 127942.33 | AA23: =+[5]제주!$Q$85 -> 119630.81 | AB23: =+[4]제주!$Q$89 -> 91405.357 | AC23: =+[4]제주!$R$89 -> 97531.989 | AD23: =+[5]제주!$Q$89 -> 89066.435 | AE23: =+Y23-AB23 -> 31543.543 | AF23: =+Z23-AC23 -> 30410.337 | AG23: =+AA23-AD23 -> 30564.375
F24: =+K24/J24 -> 0.80988128 | G24: =+I24 -> 수도권 | I24: 수도권 | J24: =SUM(J7:J10) -> 109 | K24: =SUM(K7:K10) -> 88.27706 | L24: =+K24-J24 -> -20.72294 | M24: =SUM(M7:M10) -> 94.7535 | N24: =+K24-M24 -> -6.47644 | O24: =SUM(O7:O10) -> 10994.522 | P24: =SUM(P7:P10) -> 8814.698 | Q24: =+P24-O24 -> -2179.8242 | R24: =SUM(R7:R10) -> 9072.334 | S24: =+P24-R24 -> -257.63599 | T24: =SUM(T7:T10) -> 1112.3552 | U24: =SUM(U7:U10) -> -7.630242 | V24: =+U24-T24 -> -1119.9855 | W24: =SUM(W7:W10) -> -204.53605 | X24: =+U24-W24 -> 196.9058 | Y24: =+[4]수도권!$Q$85 -> 100867.18 | Z24: =+[4]수도권!$R$85 -> 99894.501 | AA24: =+[5]수도권!$Q$85 -> 95753.183 | AB24: =+[4]수도권!$Q$89 -> 81952.109 | AC24: =+[4]수도권!$R$89 -> 87403.984 | AD24: =+[5]수도권!$Q$89 -> 83930.891 | AE24: =+Y24-AB24 -> 18915.067 | AF24: =+Z24-AC24 -> 12490.517 | AG24: =+AA24-AD24 -> 11822.292
F25: =+K25/J25 -> 0.72005054 | G25: =+I25 -> 영남권 | I25: 영남권 | J25: =SUM(J11:J18) -> 138.5 | K25: =SUM(K11:K18) -> 99.727 | L25: =+K25-J25 -> -38.773 | M25: =SUM(M11:M18) -> 129.272 | N25: =+K25-M25 -> -29.545 | O25: =SUM(O11:O18) -> 13958.864 | P25: =SUM(P11:P18) -> 10056.727 | Q25: =+P25-O25 -> -3902.1369 | R25: =SUM(R11:R18) -> 13072.183 | S25: =+P25-R25 -> -3015.4555 | T25: =SUM(T11:T18) -> 1501.0984 | U25: =SUM(U11:U18) -> 43.539371 | V25: =+U25-T25 -> -1457.5591 | W25: =SUM(W11:W18) -> 534.66819 | X25: =+U25-W25 -> -491.12882 | Y25: =+[4]영남권!$Q$85 -> 100786.02 | Z25: =+[4]영남권!$R$85 -> 100842.57 | AA25: =+[5]영남권!$Q$85 -> 101138.02 | AB25: =+[4]영남권!$Q$89 -> 79871.541 | AC25: =+[4]영남권!$R$89 -> 84812.101 | AD25: =+[5]영남권!$Q$89 -> 81325.207 | AE25: =+Y25-AB25 -> 20914.481 | AF25: =+Z25-AC25 -> 16030.47 | AG25: =+AA25-AD25 -> 19812.809
F26: =+K26/J26 -> 0.70532174 | G26: =+I26 -> 중부권 | I26: 중부권 | J26: =SUM(J19:J23) -> 57.5 | K26: =SUM(K19:K23) -> 40.556 | L26: =+K26-J26 -> -16.944 | M26: =SUM(M19:M23) -> 48.2635 | N26: =+K26-M26 -> -7.7075 | O26: =SUM(O19:O23) -> 6197.8148 | P26: =SUM(P19:P23) -> 4375.9239 | Q26: =+P26-O26 -> -1821.8909 | R26: =SUM(R19:R23) -> 5028.1924 | S26: =+P26-R26 -> -652.26846 | T26: =SUM(T19:T23) -> 978.09028 | U26: =SUM(U19:U23) -> 173.59004 | V26: =+U26-T26 -> -804.50024 | W26: =SUM(W19:W23) -> 238.09164 | X26: =+U26-W26 -> -64.501599 | Y26: =+[4]중부권!$Q$85 -> 107788.08 | Z26: =+[4]중부권!$R$85 -> 107851.32 | AA26: =+[5]중부권!$Q$85 -> 104182.09 | AB26: =+[4]중부권!$Q$89 -> 79949.779 | AC26: =+[4]중부권!$R$89 -> 85942.395 | AD26: =+[5]중부권!$Q$89 -> 81258.436 | AE26: =+Y26-AB26 -> 27838.304 | AF26: =+Z26-AC26 -> 21908.921 | AG26: =+AA26-AD26 -> 22923.655
F27: =+K27/M27 -> 0.83940247 | G27: =+K27/J27 -> 0.74937725 | H27: 레미콘 계 | J27: =SUM(J24:J26) -> 305 | K27: =SUM(K24:K26) -> 228.56006 | L27: =+K27-J27 -> -76.43994 | M27: =SUM(M24:M26) -> 272.289 | N27: =+K27-M27 -> -43.72894 | O27: =SUM(O24:O26) -> 31151.201 | P27: =SUM(P24:P26) -> 23247.349 | Q27: =+P27-O27 -> -7903.852 | R27: =SUM(R24:R26) -> 27172.709 | S27: =+P27-R27 -> -3925.36 | T27: =SUM(T24:T26) -> 3591.544 | U27: =SUM(U24:U26) -> 209.49917 | V27: =+U27-T27 -> -3382.0448 | W27: =SUM(W24:W26) -> 568.22379 | X27: =+U27-W27 -> -358.72461 | Y27: =+[4]합계!$Q$85 -> 102135.09 | Z27: =+[4]합계!$R$85 -> 101721.48 | AA27: =+[5]합계!$Q$85 -> 99802.99 | AB27: =+[4]합계!$Q$89 -> 80629.838 | AC27: =+[4]합계!$R$89 -> 86010.518 | AD27: =+[5]합계!$Q$89 -> 82213.022 | AE27: =+Y27-AB27 -> 21505.247 | AF27: =+Z27-AC27 -> 15710.962 | AG27: =+AA27-AD27 -> 17589.968 | AI27: =+AF27-AE27 -> -5794.2848 | AJ27: =+AF27-AG27 -> -1879.0055
B28: 건자재 | E28: 건자재영업 | G28: 건자재 | H28: 건자재 | J28: =+IFERROR(HLOOKUP($B28,'[1]12월'!$D$6:$BN$259,2,),) -> 13100 | K28: =+IFERROR(HLOOKUP($E28,'[2]12월'!$F$6:$CP$99,2,),) -> 7354.454 | L28: =+K28-J28 -> -5745.546 | M28: =+IFERROR(HLOOKUP($E28,'[3]12월'!$F$6:$CC$57,2,),) -> 8003.057 | N28: =+K28-M28 -> -648.603 | O28: =+IFERROR(HLOOKUP($B28,'[1]12월'!$D$6:$BN$259,3,),)/1000 -> 14246.036 | P28: =+IFERROR(HLOOKUP($E28,'[2]12월'!$F$6:$CP$99,3,),)/1000 -> 6900.9295 | Q28: =+P28-O28 -> -7345.1062 | R28: =+IFERROR(HLOOKUP($E28,'[3]12월'!$F$6:$CC$57,3,),)/1000 -> 7445.9016 | S28: =+P28-R28 -> -544.97213 | T28: =+IFERROR(HLOOKUP($B28,'[1]12월'!$D$6:$BN$259,16,),)/1000 -> 259.83969 | U28: =+IFERROR(HLOOKUP($E28,'[2]12월'!$F$6:$CP$99,16,),)/1000 -> -64.009488 | V28: =+U28-T28 -> -323.84918 | W28: =+IFERROR(HLOOKUP($E28,'[3]12월'!$F$6:$CC$57,16,),)/1000 -> -101.10207 | X28: =+U28-W28 -> 37.092585 | Y28: ■ 비고
