Workbook

Sheet 표지
A6: 2025년 5월 마감 손익
A24: 건재사업본부

Sheet 손익총괄
C3: □ 건재사업본부 손익실적(2025-05)
X4: [단위 : 천㎥, 톤, 원/㎥, 원/톤, 백만원]
C5: 구분 | E5: 5월 | J5: 5월 누계 | P5: 5월 주요지표
A6: 2024년 12월 마감 손익 | E6: 계획 | F6: 실적 | G6: 계획대비 | H6: 전년 | I6: 전년대비 | J6: 계획 | K6: 실적 | L6: 계획대비 | M6: 전년 | N6: 전년대비
A7: =+F7/E7 -> 0.83647332 | B7: =+K7/J7 -> 0.90830162 | C7: 물량 | D7: 레미콘 | E7: =+'[1]5월'!$Z$7/1000 -> 290.5 | F7: =+'[2]5월'!$Z$7/1000 -> 242.9955 | G7: =+F7-E7 -> -47.5045 | H7: =+'[3]5월'!$Z$7/1000 -> 347.129 | I7: =+F7-H7 -> -104.1335 | J7: =+'[1]5월누계'!$Z$7/1000 -> 1293 | K7: =+'[2]5월누계'!$Z$7/1000 -> 1174.434 | L7: =+K7-J7 -> -118.566 | M7: =+'[3]5월누계'!$Z$7/1000 -> 1473.095 | N7: =+K7-M7 -> -298.661 | Q7: □ 레미콘
D8: 철강재 | E8: =+'[1]5월'!$AA$7 -> 10700 | F8: =+'[2]5월'!$AO$7 -> 10256.286 | G8: =+F8-E8 -> -443.714 | H8: =+'[3]5월'!$AO$7 -> 9787.441 | I8: =+F8-H8 -> 468.845 | J8: =+'[1]5월누계'!$AA$7 -> 52000 | K8: =+'[2]5월누계'!$AO$7 -> 55602.746 | L8: =+K8-J8 -> 3602.746 | M8: =+'[3]5월누계'!$AO$7 -> 40097.987 | N8: =+K8-M8 -> 15504.759 | Q8: 구분 | S8: 계획 | T8: 실적 | U8: 계획대비 | V8: 전년 | W8: 전년대비
D9: 골재 | E9: =+'[1]5월'!$AE$7/1000 -> 115.73678 | F9: =+'[2]5월'!$AN$7/1000 -> 69.689 | G9: =+F9-E9 -> -46.047782 | H9: =+'[3]5월'!$AN$7/1000 -> 99.315 | I9: =+F9-H9 -> -29.626 | J9: =+'[1]5월누계'!$AE$7/1000 -> 444.19807 | K9: =+'[2]5월누계'!$AN$7/1000 -> 305.114 | L9: =+K9-J9 -> -139.08407 | M9: =+'[3]5월누계'!$AN$7/1000 -> 420.375 | N9: =+K9-M9 -> -115.261 | Q9: 물량 | R9: 수도권 | S9: =+[4]수도권!$T$5/1000 -> 105 | T9: =+[4]수도권!$U$5/1000 -> 85.7685 | U9: =+T9-S9 -> -19.2315 | V9: =+[5]수도권!$T$5/1000 -> 120.114 | W9: =+T9-V9 -> -34.3455
C10: 매출 | D10: 레미콘 | E10: =+'[1]5월'!$Z$8/1000 -> 29171.815 | F10: =+'[2]5월'!$Z$8/1000 -> 23799.928 | G10: =+F10-E10 -> -5371.8869 | H10: =+'[3]5월'!$Z$8/1000 -> 35125.944 | I10: =+F10-H10 -> -11326.016 | J10: =+'[1]5월누계'!$Z$8/1000 -> 129885.97 | K10: =+'[2]5월누계'!$Z$8/1000 -> 115938.49 | L10: =+K10-J10 -> -13947.481 | M10: =+'[3]5월누계'!$Z$8/1000 -> 149461.82 | N10: =+K10-M10 -> -33523.334 | R10: 영남권 | S10: =+[4]영남권!$T$5/1000 -> 127.5 | T10: =+[4]영남권!$U$5/1000 -> 106.883 | U10: =+T10-S10 -> -20.617 | V10: =+[5]영남권!$T$5/1000 -> 158.134 | W10: =+T10-V10 -> -51.251
D11: 건자재 | E11: =+'[1]5월'!$AA$8/1000 -> 11710.568 | F11: =+'[2]5월'!$AO$8/1000 -> 10025.106 | G11: =+F11-E11 -> -1685.4627 | H11: =+'[3]5월'!$AO$8/1000 -> 9774.8209 | I11: =+F11-H11 -> 250.28473 | J11: =+'[1]5월누계'!$AA$8/1000 -> 56918.973 | K11: =+'[2]5월누계'!$AO$8/1000 -> 48464.953 | L11: =+K11-J11 -> -8454.0199 | M11: =+'[3]5월누계'!$AO$8/1000 -> 41530.393 | N11: =+K11-M11 -> 6934.56 | R11: 중부권 | S11: =+[4]중부권!$T$5/1000 -> 58 | T11: =+[4]중부권!$U$5/1000 -> 50.344 | U11: =+T11-S11 -> -7.656 | V11: =+[5]중부권!$T$5/1000 -> 68.881 | W11: =+T11-V11 -> -18.537
D12: 골재 | E12: =+'[1]5월'!$AE$8/1000 -> 2087.718 | F12: =+'[2]5월'!$AN$8/1000 -> 1467.6265 | G12: =+F12-E12 -> -620.09148 | H12: =+'[3]5월'!$AN$8/1000 -> 1975.778 | I12: =+F12-H12 -> -508.1515 | J12: =+'[1]5월누계'!$AE$8/1000 -> 8314.6591 | K12: =+'[2]5월누계'!$AN$8/1000 -> 6494.441 | L12: =+K12-J12 -> -1820.2181 | M12: =+'[3]5월누계'!$AN$8/1000 -> 8504.2076 | N12: =+K12-M12 -> -2009.7666 | Q12: 계 | S12: =SUM(S9:S11) -> 290.5 | T12: =SUM(T9:T11) -> 242.9955 | U12: =+T12-S12 -> -47.5045 | V12: =SUM(V9:V11) -> 347.129 | W12: =+T12-V12 -> -104.1335
D13: 기타 | E13: =+'[1]5월'!$E$8/1000-E10-E11-E12 -> 142.52817 | F13: =+'[2]5월'!$F$8/1000-F10-F11-F12 -> 118.78848 | G13: =+F13-E13 -> -23.739686 | H13: =+'[3]5월'!$F$8/1000-H10-H11-H12 -> 166.22714 | I13: =+F13-H13 -> -47.438655 | J13: =+'[1]5월누계'!$E$8/1000-J10-J11-J12 -> 785.16083 | K13: =+'[2]5월누계'!$F$8/1000-K10-K11-K12 -> 710.11164 | L13: =+K13-J13 -> -75.049194 | M13: =+'[3]5월누계'!$F$8/1000-M10-M11-M12 -> 825.58077 | N13: =+K13-M13 -> -115.46913 | Q13: 판매단가 | R13: 수도권 | S13: =+[4]수도권!$T$61 -> 97007.731 | T13: =+[4]수도권!$U$61 -> 96609.726 | U13: =+T13-S13 -> -398.00433 | V13: =+[5]수도권!$Q$85 -> 99353.382 | W13: =+T13-V13 -> -2743.6558
A14: =+F14/E14 -> 0.82137066 | B14: =+K14/J14 -> 0.87597664 | C14: 계 | E14: =SUM(E10:E13) -> 43112.629 | F14: =SUM(F10:F13) -> 35411.449 | G14: =+F14-E14 -> -7701.1807 | H14: =SUM(H10:H13) -> 47042.77 | I14: =+F14-H14 -> -11631.321 | J14: =SUM(J10:J13) -> 195904.76 | K14: =SUM(K10:K13) -> 171608 | L14: =+K14-J14 -> -24296.768 | M14: =SUM(M10:M13) -> 200322.01 | N14: =+K14-M14 -> -28714.01 | R14: 영남권 | S14: =+[4]영남권!$T$61 -> 100476.31 | T14: =+[4]영남권!$U$61 -> 97803.84 | U14: =+T14-S14 -> -2672.4683 | V14: =+[5]영남권!$Q$85 -> 100729.73 | W14: =+T14-V14 -> -2925.8925
C15: 매출원가 | D15: 레미콘 | E15: =+('[1]5월'!$Z$10+'[1]5월'!$Z$19)/1000 -> 25482.517 | F15: =+('[2]5월'!$Z$10+'[2]5월'!$Z$19)/1000 -> 21588.831 | G15: =+F15-E15 -> -3893.6866 | H15: =+('[3]5월'!$Z$10+'[3]5월'!$Z$19)/1000 -> 29394.123 | I15: =+F15-H15 -> -7805.2924 | J15: =+('[1]5월누계'!$Z$10+'[1]5월누계'!$Z$19)/1000 -> 116138.39 | K15: =+('[2]5월누계'!$Z$10+'[2]5월누계'!$Z$19)/1000 -> 106232.04 | L15: =+K15-J15 -> -9906.3498 | M15: =+('[3]5월누계'!$Z$10+'[3]5월누계'!$Z$19)/1000 -> 128726.38 | N15: =+K15-M15 -> -22494.335 | R15: 중부권 | S15: =+[4]중부권!$T$61 -> 106470.24 | T15: =+[4]중부권!$U$61 -> 100717.64 | U15: =+T15-S15 -> -5752.5952 | V15: =+[5]중부권!$Q$85 -> 105549.17 | W15: =+T15-V15 -> -4831.5317
D16: 건자재 | E16: =+('[1]5월'!$AA$10+'[1]5월'!$AA$19)/1000 -> 11393.85 | F16: =+('[2]5월'!$AO$10+'[2]5월'!$AO$19)/1000 -> 9841.4109 | G16: =+F16-E16 -> -1552.4394 | H16: =+('[3]5월'!$AO$10+'[3]5월'!$AO$19)/1000 -> 9519.8983 | I16: =+F16-H16 -> 321.51255 | J16: =+('[1]5월누계'!$AA$10+'[1]5월누계'!$AA$19)/1000 -> 55381.107 | K16: =+('[2]5월누계'!$AO$10+'[2]5월누계'!$AO$19)/1000 -> 47781.099 | L16: =+K16-J16 -> -7600.0085 | M16: =+('[3]5월누계'!$AO$10+'[3]5월누계'!$AO$19)/1000 -> 40578.709 | N16: =+K16-M16 -> 7202.39 | Q16: 계 | S16: =+[4]합계!$T$61 -> 100419.33 | T16: =+[4]합계!$U$61 -> 97989.576 | U16: =+T16-S16 -> -2429.7523 | V16: =+[5]합계!$Q$85 -> 101219.55 | W16: =+T16-V16 -> -3229.9778
D17: 골재 | E17: =+('[1]5월'!$AE$10+'[1]5월'!$AE$19)/1000 -> 1741.8994 | F17: =+('[2]5월'!$AN$10+'[2]5월'!$AN$19)/1000 -> 1406.9589 | G17: =+F17-E17 -> -334.94052 | H17: =+('[3]5월'!$AN$10+'[3]5월'!$AN$19)/1000 -> 1758.9883 | I17: =+F17-H17 -> -352.02938 | J17: =+('[1]5월누계'!$AE$10+'[1]5월누계'!$AE$19)/1000 -> 7142.9452 | K17: =+('[2]5월누계'!$AN$10+'[2]5월누계'!$AN$19)/1000 -> 6694.1268 | L17: =+K17-J17 -> -448.81836 | M17: =+('[3]5월누계'!$AN$10+'[3]5월누계'!$AN$19)/1000 -> 7535.7403 | N17: =+K17-M17 -> -841.61352 | Q17: 공헌이익 | R17: 수도권 | S17: =+[4]수도권!$Q$90 -> 16455.164 | T17: =+[4]수도권!$R$90 -> 16471.138 | U17: =+T17-S17 -> 15.973569 | V17: =+[5]수도권!$Q$90 -> 19119.781 | W17: =+T17-V17 -> -2648.6429
D18: 기타 | E18: =+('[1]5월'!$E$10+'[1]5월'!$E$19)/1000-E15-E16-E17 -> 68.281599 | F18: =+('[2]5월'!$F$10+'[2]5월'!$F$19)/1000-F15-F16-F17 -> 18.465355 | G18: =+F18-E18 -> -49.816244 | H18: =+('[3]5월'!$F$10+'[3]5월'!$F$19)/1000-H15-H16-H17 -> 31.483638 | I18: =+F18-H18 -> -13.018283 | J18: =+('[1]5월누계'!$E$10+'[1]5월누계'!$E$19)/1000-J15-J16-J17 -> 245.9461 | K18: =+('[2]5월누계'!$F$10+'[2]5월누계'!$F$19)/1000-K15-K16-K17 -> 422.6893 | L18: =+K18-J18 -> 176.7432 | M18: =+('[3]5월누계'!$F$10+'[3]5월누계'!$F$19)/1000-M15-M16-M17 -> 131.40672 | N18: =+K18-M18 -> 291.28258 | R18: 영남권 | S18: =+[4]영남권!$Q$90 -> 21349.881 | T18: =+[4]영남권!$R$90 -> 19421.045 | U18: =+T18-S18 -> -1928.8354 | V18: =+[5]영남권!$Q$90 -> 22869.321 | W18: =+T18-V18 -> -3448.2755
C19: 계 | E19: =SUM(E15:E18) -> 38686.549 | F19: =SUM(F15:F18) -> 32855.666 | G19: =+F19-E19 -> -5830.8829 | H19: =SUM(H15:H18) -> 40704.493 | I19: =+F19-H19 -> -7848.8275 | J19: =SUM(J15:J18) -> 178908.39 | K19: =SUM(K15:K18) -> 161129.96 | L19: =+K19-J19 -> -17778.433 | M19: =SUM(M15:M18) -> 176972.23 | N19: =+K19-M19 -> -15842.276 | R19: 중부권 | S19: =+[4]중부권!$Q$90 -> 28840.861 | T19: =+[4]중부권!$R$90 -> 22337.894 | U19: =+T19-S19 -> -6502.9669 | V19: =+[5]중부권!$Q$90 -> 31197.021 | W19: =+T19-V19 -> -8859.1268
C20: 매출이익 | D20: 레미콘 | E20: =+E10-E15 -> 3689.2975 | F20: =+F10-F15 -> 2211.0972 | G20: =+F20-E20 -> -1478.2002 | H20: =+H10-H15 -> 5731.8206 | I20: =+F20-H20 -> -3520.7234 | J20: =+J10-J15 -> 13747.576 | K20: =+K10-K15 -> 9706.4454 | L20: =+K20-J20 -> -4041.1308 | M20: =+M10-M15 -> 20735.445 | N20: =+K20-M20 -> -11028.999 | Q20: 계 | S20: =+[4]합계!$Q$90 -> 21076.324 | T20: =+[4]합계!$R$90 -> 18989.722 | U20: =+T20-S20 -> -2086.6015 | V20: =+[5]합계!$Q$90 -> 23245.012 | W20: =+T20-V20 -> -4255.2898
D21: 건자재 | E21: =+E11-E16 -> 316.71794 | F21: =+F11-F16 -> 183.69473 | G21: =+F21-E21 -> -133.02321 | H21: =+H11-H16 -> 254.92255 | I21: =+F21-H21 -> -71.227825 | J21: =+J11-J16 -> 1537.8661 | K21: =+K11-K16 -> 683.85469 | L21: =+K21-J21 -> -854.01138 | M21: =+M11-M16 -> 951.6847 | N21: =+K21-M21 -> -267.83001 | Q21: □ 건자재
D22: 골재 | E22: =+E12-E17 -> 345.81855 | F22: =+F12-F17 -> 60.667594 | G22: =+F22-E22 -> -285.15095 | H22: =+H12-H17 -> 216.78972 | I22: =+F22-H22 -> -156.12212 | J22: =+J12-J17 -> 1171.7139 | K22: =+K12-K17 -> -199.68582 | L22: =+K22-J22 -> -1371.3997 | M22: =+M12-M17 -> 968.46724 | N22: =+K22-M22 -> -1168.1531 | Q22: 구분 | S22: 계획 | T22: 실적 | U22: 계획대비 | V22: 전년 | W22: 전년대비
D23: 기타 | E23: =+E13-E18 -> 74.246568 | F23: =+F13-F18 -> 100.32313 | G23: =+F23-E23 -> 26.076558 | H23: =+H13-H18 -> 134.7435 | I23: =+F23-H23 -> -34.420372 | J23: =+J13-J18 -> 539.21474 | K23: =+K13-K18 -> 287.42234 | L23: =+K23-J23 -> -251.7924 | M23: =+M13-M18 -> 694.17405 | N23: =+K23-M23 -> -406.75171 | Q23: 철강재 판매단가 | S23: =+'[6]5월'!$F$10 -> 873364.49 | T23: =+'[6]5월'!$G$10 -> 798001.53 | U23: =+T23-S23 -> -75362.96 | V23: =+'[6]5월'!$G$10 -> 798001.53 | W23: =+T23-V23 -> 0
C24: 계 | E24: =SUM(E20:E23) -> 4426.0805 | F24: =SUM(F20:F23) -> 2555.7827 | G24: =+F24-E24 -> -1870.2979 | H24: =SUM(H20:H23) -> 6338.2764 | I24: =+F24-H24 -> -3782.4937 | J24: =SUM(J20:J23) -> 16996.371 | K24: =SUM(K20:K23) -> 10478.037 | L24: =+K24-J24 -> -6518.3343 | M24: =SUM(M20:M23) -> 23349.771 | N24: =+K24-M24 -> -12871.734 | Q24: 철강재 마진률 | S24: =+'[6]5월'!$F$15 -> 0.02403023 | T24: =+'[6]5월'!$G$15 -> 0.016605664 | U24: =+T24-S24 -> -0.0074245662 | V24: =+'[6]5월'!$G$15 -> 0.016605664 | W24: =+T24-V24 -> 0
C25: 판관비 | D25: 레미콘 | E25: =+('[1]5월'!$Z$13+'[1]5월'!$Z$20)/1000 -> 661.21474 | F25: =+('[2]5월'!$Z$13+'[2]5월'!$Z$20)/1000 -> 656.78414 | G25: =+F25-E25 -> -4.4306 | H25: =+('[3]5월'!$Z$13+'[3]5월'!$Z$20)/1000 -> 669.0385 | I25: =+F25-H25 -> -12.254352 | J25: =+('[1]5월누계'!$Z$13+'[1]5월누계'!$Z$20)/1000 -> 3364.4818 | K25: =+('[2]5월누계'!$Z$13+'[2]5월누계'!$Z$20)/1000 -> 3328.4658 | L25: =+K25-J25 -> -36.016056 | M25: =+('[3]5월누계'!$Z$13+'[3]5월누계'!$Z$20)/1000 -> 3324.0288 | N25: =+K25-M25 -> 4.436967 | Q25: □ 골재
D26: 건자재 | E26: =+('[1]5월'!$AA$13+'[1]5월'!$AA$20)/1000 -> 124.24035 | F26: =+('[2]5월'!$AO$13+'[2]5월'!$AO$20)/1000 -> 137.432 | G26: =+F26-E26 -> 13.191649 | H26: =+('[3]5월'!$AO$13+'[3]5월'!$AO$20)/1000 -> 132.55453 | I26: =+F26-H26 -> 4.87747 | J26: =+('[1]5월누계'!$AA$13+'[1]5월누계'!$AA$20)/1000 -> 636.31962 | K26: =+('[2]5월누계'!$AO$13+'[2]5월누계'!$AO$20)/1000 -> 744.17489 | L26: =+K26-J26 -> 107.85527 | M26: =+('[3]5월누계'!$AO$13+'[3]5월누계'!$AO$20)/1000 -> 686.73211 | N26: =+K26-M26 -> 57.442781 | Q26: 구분 | S26: 계획 | T26: 실적 | U26: 계획대비 | V26: 전년 | W26: 전년대비
D27: 골재 | E27: =+('[1]5월'!$AE$13+'[1]5월'!$AE$20+'[1]5월'!$AE$22)/1000 -> 46.935969 | F27: =+('[2]5월'!$AN$13+'[2]5월'!$AN$20+'[2]5월'!$AN$22)/1000 -> 47.21642 | G27: =+F27-E27 -> 0.28045128 | H27: =+('[3]5월'!$AN$13+'[3]5월'!$AN$20+'[3]5월'!$AN$22)/1000 -> 45.210639 | I27: =+F27-H27 -> 2.0057812 | J27: =+('[1]5월누계'!$AE$13+'[1]5월누계'!$AE$20+'[1]5월누계'!$AE$22)/1000 -> 237.39466 | K27: =+('[2]5월누계'!$AN$13+'[2]5월누계'!$AN$20+'[2]5월누계'!$AN$22)/1000 -> 234.60151 | L27: =+K27-J27 -> -2.7931501 | M27: =+('[3]5월누계'!$AN$13+'[3]5월누계'!$AN$20+'[3]5월누계'!$AN$22)/1000 -> 223.89003 | N27: =+K27-M27 -> 10.711481 | Q27: 판매량 | R27: 자가 | S27: =(+'[7]서부산크라샤(당월)'!$Z$66+'[7]부산모래장(당월)'!$Q$48+'[7]부산크라샤(당월)'!$T$66)/1000 -> 40.83298 | T27: =(+'[7]서부산크라샤(당월)'!$AA$66+'[7]부산모래장(당월)'!$R$48+'[7]부산크라샤(당월)'!$U$66)/1000 -> 21.936 | U27: =+T27-S27 -> -18.89698 | V27: =+[8]손익총괄!$V$27 -> 41.968 | W27: =+T27-V27 -> -20.032
D28: 기타 | E28: =+('[1]5월'!$E$13+'[1]5월'!$E$20)/1000-E25-E26-E27+('[1]5월'!$E$22/1000) -> 1395.419 | F28: =+('[2]5월'!$F$13+'[2]5월'!$F$20)/1000-F25-F26-F27+'[2]5월'!$F$22/1000 -> 1469.2688 | G28: =+F28-E28 -> 73.849784 | H28: =+('[3]5월'!$F$13+'[3]5월'!$F$20)/1000-H25-H26-H27+'[3]5월'!$F$22/1000 -> 1274.1805 | I28: =+F28-H28 -> 195.08837 | J28: =+('[1]5월누계'!$E$13+'[1]5월누계'!$E$20)/1000-J25-J26-J27+('[1]5월누계'!$E$22/1000) -> 7677.1828 | K28: =+('[2]5월누계'!$F$13+'[2]5월누계'!$F$20)/1000-K25-K26-K27+'[2]5월누계'!$F$22/1000 -> 8527.5074 | L28: =+K28-J28 -> 850.32455 | M28: =+('[3]5월누계'!$F$13+'[3]5월누계'!$F$20)/1000-M25-M26-M27+'[3]5월누계'!$F$22/1000 -> 8444.433 | N28: =+K28-M28 -> 83.074356 | R28: 외판 | S28: =(+'[7]서부산크라샤(당월)'!$Z$59+'[7]부산모래장(당월)'!$Q$47+'[7]부산크라샤(당월)'!$T$59)/1000 -> 33.5 | T28: =(+'[7]서부산크라샤(당월)'!$AA$59+'[7]부산모래장(당월)'!$R$47+'[7]부산크라샤(당월)'!$U$59)/1000 -> 24.583 | U28: =+T28-S28 -> -8.917 | V28: =+[8]손익총괄!$V$28 -> 25.59 | W28: =+T28-V28 -> -1.007
C29: 계 | E29: =SUM(E25:E28) -> 2227.8101 | F29: =SUM(F25:F28) -> 2310.7014 | G29: =+F29-E29 -> 82.891284 | H29: =SUM(H25:H28) -> 2120.9841 | I29: =+F29-H29 -> 189.71727 | J29: =SUM(J25:J28) -> 11915.379 | K29: =SUM(K25:K28) -> 12834.75 | L29: =+K29-J29 -> 919.37061 | M29: =SUM(M25:M28) -> 12679.084 | N29: =+K29-M29 -> 155.66558 | Q29: 합 계 | S29: =SUM(S27:S28) -> 74.33298 | T29: =SUM(T27:T28) -> 46.519 | U29: =+T29-S29 -> -27.81398 | V29: =SUM(V27:V28) -> 67.558 | W29: =+T29-V29 -> -21.039
C30: 영업이익 | D30: 레미콘 | E30: =+E20-E25 -> 3028.0827 | F30: =+F20-F25 -> 1554.3131 | G30: =+F30-E30 -> -1473.7696 | H30: =+H20-H25 -> 5062.7821 | I30: =+F30-H30 -> -3508.469 | J30: =+J20-J25 -> 10383.094 | K30: =+K20-K25 -> 6377.9796 | L30: =+K30-J30 -> -4005.1148 | M30: =+M20-M25 -> 17411.416 | N30: =+K30-M30 -> -11033.436 | Q30: □ 기타내역(영업이익)
D31: % | E31: =+E30/E10 -> 0.10380166 | F31: =+F30/F10 -> 0.065307471 | G31: =+F31-E31 -> -0.038494187 | H31: =+H30/H10 -> 0.14413227 | I31: =+F31-H31 -> -0.078824802 | J31: =+J30/J10 -> 0.079940076 | K31: =+K30/K10 -> 0.055011753 | L31: =+K31-J31 -> -0.024928323 | M31: =+M30/M10 -> 0.11649407 | N31: =+K31-M31 -> -0.061482314 | Q31: 구분 | S31: 계획 | T31: 실적 | U31: 계획대비 | V31: 전년 | W31: 전년대비
D32: 건자재 | E32: =+E21-E26 -> 192.4776 | F32: =+F21-F26 -> 46.262732 | G32: =+F32-E32 -> -146.21486 | H32: =+H21-H26 -> 122.36803 | I32: =+F32-H32 -> -76.105295 | J32: =+J21-J26 -> 901.54644 | K32: =+K21-K26 -> -60.3202 | L32: =+K32-J32 -> -961.86664 | M32: =+M21-M26 -> 264.95259 | N32: =+K32-M32 -> -325.2728 | Q32: 레미콘임대 | S32: =+'사업장별(당월)'!T33 -> 48.349888 | T32: =+'사업장별(당월)'!U33 -> 23.178219 | U32: =+T32-S32 -> -25.171669 | V32: =+'사업장별(당월)'!W33 -> 68.93061 | W32: =+T32-V32 -> -45.752391
D33: 골재 | E33: =+E22-E27 -> 298.88258 | F33: =+F22-F27 -> 13.451174 | G33: =+F33-E33 -> -285.43141 | H33: =+H22-H27 -> 171.57908 | I33: =+F33-H33 -> -158.1279 | J33: =+J22-J27 -> 934.31923 | K33: =+K22-K27 -> -434.28733 | L33: =+K33-J33 -> -1368.6066 | M33: =+M22-M27 -> 744.57722 | N33: =+K33-M33 -> -1178.8645 | Q33: 임대 | S33: =+'사업장별(당월)'!T34 -> 63.964 | T33: =+'사업장별(당월)'!U34 -> 66.602381 | U33: =+T33-S33 -> 2.638381 | V33: =+'사업장별(당월)'!W34 -> 63.574319 | W33: =+T33-V33 -> 3.028062
D34: 기타 | E34: =+E23-E28 -> -1321.1725 | F34: =+F23-F28 -> -1368.9457 | G34: =+F34-E34 -> -47.773225 | H34: =+H23-H28 -> -1139.437 | I34: =+F34-H34 -> -229.50875 | J34: =+J23-J28 -> -7137.9681 | K34: =+K23-K28 -> -8240.085 | L34: =+K34-J34 -> -1102.1169 | M34: =+M23-M28 -> -7750.259 | N34: =+K34-M34 -> -489.82607 | Q34: 공통비 | S34: =+'사업장별(당월)'!T35 -> -1315.8435 | T34: =+'사업장별(당월)'!U35 -> -1405.8047 | U34: =+T34-S34 -> -89.961196 | V34: =+'사업장별(당월)'!W35 -> -1157.1102 | W34: =+T34-V34 -> -248.69454
C35: 계 | E35: =SUM(E30,E32:E34) -> 2198.2704 | F35: =SUM(F30,F32:F34) -> 245.08131 | G35: =+F35-E35 -> -1953.1891 | H35: =SUM(H30,H32:H34) -> 4217.2923 | I35: =+F35-H35 -> -3972.2109 | J35: =SUM(J30,J32:J34) -> 5080.9919 | K35: =SUM(K30,K32:K34) -> -2356.713 | L35: =+K35-J35 -> -7437.7049 | M35: =SUM(M30,M32:M34) -> 10670.687 | N35: =+K35-M35 -> -13027.4 | Q35: 기타 | S35: =+S36-S32-S33-S34 -> -117.64287 | T35: =+T36-T32-T33-T34 -> -52.921613 | U35: =+T35-S35 -> 64.721258 | V35: =+V36-V32-V33-V34 -> -114.83173 | W35: =+T35-V35 -> 61.91012
D36: % | E36: =+E35/E14 -> 0.050989014 | F36: =+F35/F14 -> 0.0069209625 | G36: =+F36-E36 -> -0.044068051 | H36: =+H35/H14 -> 0.089648043 | I36: =+F36-H36 -> -0.082727081 | J36: =+J35/J14 -> 0.025936031 | K36: =+K35/K14 -> -0.013733119 | L36: =+K36-J36 -> -0.039669149 | M36: =+M35/M14 -> 0.053267671 | N36: =+K36-M36 -> -0.06700079 | Q36: 합계 | S36: =+'사업장별(당월)'!T41 -> -1321.1725 | T36: =+'사업장별(당월)'!U41 -> -1368.9457 | U36: =+T36-S36 -> -47.773225 | V36: =+'사업장별(당월)'!W41 -> -1139.437 | W36: =+T36-V36 -> -229.50875
E38: =+'[1]5월'!$E$26/1000 -> 2198.2704 | F38: =+'[2]5월'!$F$26/1000 -> 245.08131 | H38: =+'[3]5월'!$F$26/1000 -> 4217.2923 | J38: =+'[1]5월누계'!$E$26/1000 -> 5080.9919 | K38: =+'[2]5월누계'!$F$26/1000 -> -2356.713 | M38: =+'[3]5월누계'!$F$26/1000 -> 10670.687
E39: =+E35=E38 -> FALSE | F39: =+F35=F38 -> FALSE | H39: =+H35=H38 -> FALSE | J39: =+J35=J38 -> TRUE | K39: =+K35=K38 -> FALSE | M39: =+M35=M38 -> TRUE
E40: =+E35-E38 -> 0 | F40: =+F35-F38 -> 1.9895197e-12 | H40: =+H35-H38 -> 0 | J40: =+J35-J38 -> 0 | K40: =+K35-K38 -> 5.9117156e-12 | M40: =+M35-M38 -> -1.8189894e-11

Sheet 사업장별(당월)
H3: □ 사업장별 손익실적(2025-05)
AG4: [단위 : 천㎥, 톤, 백만원]
H5: 구분 | J5: 물량 | O5: 매출 | T5: 영업이익(공통비 배부전) | Y5: 판매단가 | AB5: 변동비 | AE5: 공헌이익
A6: 2024년 5월 마감 손익 | J6: 계획 | K6: 실적 | L6: 차이 | M6: 전년 | N6: 차이 | O6: 계획 | P6: 실적 | Q6: 차이 | R6: 전년 | S6: 차이 | T6: 계획 | U6: 실적 | V6: 차이 | W6: 전년 | X6: 차이 | Y6: 계획 | Z6: 실적 | AA6: 전년 | AB6: 계획 | AC6: 실적 | AD6: 전년 | AE6: 계획 | AF6: 실적 | AG6: 전년
B7: 안양 | G7: =+I7 -> 안양 | H7: 레미콘 | I7: 안양 | J7: =+IFERROR(HLOOKUP($B7,'[1]5월'!$D$6:$BN$259,2,),)/1000 -> 40 | K7: =+IFERROR(HLOOKUP($B7,'[2]5월'!$F$6:$CP$99,2,),)/1000 -> 31.314 | L7: =+K7-J7 -> -8.686 | M7: =+IFERROR(HLOOKUP($B7,'[3]5월'!$F$6:$CC$57,2,),)/1000 -> 40.606 | N7: =+K7-M7 -> -9.292 | O7: =+IFERROR(HLOOKUP($B7,'[1]5월'!$D$6:$BN$259,3,),)/1000 -> 3920.1566 | P7: =+IFERROR(HLOOKUP($B7,'[2]5월'!$F$6:$CP$99,3,),)/1000 -> 2998.4996 | Q7: =+P7-O7 -> -921.65703 | R7: =+IFERROR(HLOOKUP($B7,'[3]5월'!$F$6:$CC$57,3,),)/1000 -> 4123.2946 | S7: =+P7-R7 -> -1124.795 | T7: =+IFERROR(HLOOKUP($B7,'[1]5월'!$D$6:$BN$259,16,),)/1000 -> 362.47826 | U7: =+IFERROR(HLOOKUP($B7,'[2]5월'!$F$6:$CP$99,16,),)/1000 -> 242.51179 | V7: =+U7-T7 -> -119.96647 | W7: =+IFERROR(HLOOKUP($B7,'[3]5월'!$F$6:$CC$57,16,),)/1000 -> 470.16461 | X7: =+U7-W7 -> -227.65282 | Y7: =+[4]안양!$Q$85 -> 98003.916 | Z7: =+[4]안양!$R$85 -> 95747.281 | AA7: =+[5]안양!$Q$85 -> 101543.97 | AB7: =+[4]안양!$Q$89 -> 81642.386 | AC7: =+[4]안양!$R$89 -> 78706.317 | AD7: =+[5]안양!$Q$89 -> 82761.713 | AE7: =+Y7-AB7 -> 16361.53 | AF7: =+Z7-AC7 -> 17040.964 | AG7: =+AA7-AD7 -> 18782.261
B8: 인천 | G8: =+I8 -> 인천 | H8: 직영 | I8: 인천 | J8: =+IFERROR(HLOOKUP($B8,'[1]5월'!$D$6:$BN$259,2,),)/1000 -> 25 | K8: =+IFERROR(HLOOKUP($B8,'[2]5월'!$F$6:$CP$99,2,),)/1000 -> 32.104 | L8: =+K8-J8 -> 7.104 | M8: =+IFERROR(HLOOKUP($B8,'[3]5월'!$F$6:$CC$57,2,),)/1000 -> 30.156 | N8: =+K8-M8 -> 1.948 | O8: =+IFERROR(HLOOKUP($B8,'[1]5월'!$D$6:$BN$259,3,),)/1000 -> 2453.0911 | P8: =+IFERROR(HLOOKUP($B8,'[2]5월'!$F$6:$CP$99,3,),)/1000 -> 3174.7652 | Q8: =+P8-O8 -> 721.67414 | R8: =+IFERROR(HLOOKUP($B8,'[3]5월'!$F$6:$CC$57,3,),)/1000 -> 2946.528 | S8: =+P8-R8 -> 228.23728 | T8: =+IFERROR(HLOOKUP($B8,'[1]5월'!$D$6:$BN$259,16,),)/1000 -> 104.02928 | U8: =+IFERROR(HLOOKUP($B8,'[2]5월'!$F$6:$CP$99,16,),)/1000 -> 160.60507 | V8: =+U8-T8 -> 56.575783 | W8: =+IFERROR(HLOOKUP($B8,'[3]5월'!$F$6:$CC$57,16,),)/1000 -> 266.18334 | X8: =+U8-W8 -> -105.57827 | Y8: =+[4]인천!$Q$85 -> 98123.644 | Z8: =+[4]인천!$R$85 -> 99229.134 | AA8: =+[5]인천!$Q$85 -> 97709.509 | AB8: =+[4]인천!$Q$89 -> 82677.846 | AC8: =+[4]인천!$R$89 -> 83784.72 | AD8: =+[5]인천!$Q$89 -> 79830.372 | AE8: =+Y8-AB8 -> 15445.798 | AF8: =+Z8-AC8 -> 15444.414 | AG8: =+AA8-AD8 -> 17879.137
B9: 파주 | G9: =+I9 -> 파주 | I9: 파주 | J9: =+IFERROR(HLOOKUP($B9,'[1]5월'!$D$6:$BN$259,2,),)/1000 -> 24 | K9: =+IFERROR(HLOOKUP($B9,'[2]5월'!$F$6:$CP$99,2,),)/1000 -> 11.412 | L9: =+K9-J9 -> -12.588 | M9: =+IFERROR(HLOOKUP($B9,'[3]5월'!$F$6:$CC$57,2,),)/1000 -> 28.609 | N9: =+K9-M9 -> -17.197 | O9: =+IFERROR(HLOOKUP($B9,'[1]5월'!$D$6:$BN$259,3,),)/1000 -> 2299.6799 | P9: =+IFERROR(HLOOKUP($B9,'[2]5월'!$F$6:$CP$99,3,),)/1000 -> 1059.6553 | Q9: =+P9-O9 -> -1240.0247 | R9: =+IFERROR(HLOOKUP($B9,'[3]5월'!$F$6:$CC$57,3,),)/1000 -> 2747.819 | S9: =+P9-R9 -> -1688.1637 | T9: =+IFERROR(HLOOKUP($B9,'[1]5월'!$D$6:$BN$259,16,),)/1000 -> 147.88633 | U9: =+IFERROR(HLOOKUP($B9,'[2]5월'!$F$6:$CP$99,16,),)/1000 -> -28.835518 | V9: =+U9-T9 -> -176.72185 | W9: =+IFERROR(HLOOKUP($B9,'[3]5월'!$F$6:$CC$57,16,),)/1000 -> 254.15168 | X9: =+U9-W9 -> -282.9872 | Y9: =+[4]파주!$Q$85 -> 95819.998 | Z9: =+[4]파주!$R$85 -> 92818.058 | AA9: =+[5]파주!$Q$85 -> 95934.038 | AB9: =+[4]파주!$Q$89 -> 80157.82 | AC9: =+[4]파주!$R$89 -> 76791.949 | AD9: =+[5]파주!$Q$89 -> 79393.119 | AE9: =+Y9-AB9 -> 15662.178 | AF9: =+Z9-AC9 -> 16026.109 | AG9: =+AA9-AD9 -> 16540.919
B10: 김포 | G10: =+I10 -> 김포 | I10: 김포 | J10: =+IFERROR(HLOOKUP($B10,'[1]5월'!$D$6:$BN$259,2,),)/1000 -> 16 | K10: =+IFERROR(HLOOKUP($B10,'[2]5월'!$F$6:$CP$99,2,),)/1000 -> 10.9385 | L10: =+K10-J10 -> -5.0615 | M10: =+IFERROR(HLOOKUP($B10,'[3]5월'!$F$6:$CC$57,2,),)/1000 -> 20.743 | N10: =+K10-M10 -> -9.8045 | O10: =+IFERROR(HLOOKUP($B10,'[1]5월'!$D$6:$BN$259,3,),)/1000 -> 1512.884 | P10: =+IFERROR(HLOOKUP($B10,'[2]5월'!$F$6:$CP$99,3,),)/1000 -> 1044.535 | Q10: =+P10-O10 -> -468.34905 | R10: =+IFERROR(HLOOKUP($B10,'[3]5월'!$F$6:$CC$57,3,),)/1000 -> 2113.5216 | S10: =+P10-R10 -> -1068.9866 | T10: =+IFERROR(HLOOKUP($B10,'[1]5월'!$D$6:$BN$259,16,),)/1000 -> 132.10269 | U10: =+IFERROR(HLOOKUP($B10,'[2]5월'!$F$6:$CP$99,16,),)/1000 -> 30.961596 | V10: =+U10-T10 -> -101.14109 | W10: =+IFERROR(HLOOKUP($B10,'[3]5월'!$F$6:$CC$57,16,),)/1000 -> 354.65027 | X10: =+U10-W10 -> -323.68867 | Y10: =+[4]김포!$Q$85 -> 94555.252 | Z10: =+[4]김포!$R$85 -> 95512.758 | AA10: =+[5]김포!$Q$85 -> 102058.93 | AB10: =+[4]김포!$Q$89 -> 75099.387 | AC10: =+[4]김포!$R$89 -> 77274.195 | AD10: =+[5]김포!$Q$89 -> 76893.344 | AE10: =+Y10-AB10 -> 19455.865 | AF10: =+Z10-AC10 -> 18238.563 | AG10: =+AA10-AD10 -> 25165.586
B11: 부산 | G11: =+I11 -> 부산 | I11: 부산 | J11: =+IFERROR(HLOOKUP($B11,'[1]5월'!$D$6:$BN$259,2,),)/1000 -> 21 | K11: =+IFERROR(HLOOKUP($B11,'[2]5월'!$F$6:$CP$99,2,),)/1000 -> 20.779 | L11: =+K11-J11 -> -0.221 | M11: =+IFERROR(HLOOKUP($B11,'[3]5월'!$F$6:$CC$57,2,),)/1000 -> 28.1265 | N11: =+K11-M11 -> -7.3475 | O11: =+IFERROR(HLOOKUP($B11,'[1]5월'!$D$6:$BN$259,3,),)/1000 -> 2261.6944 | P11: =+IFERROR(HLOOKUP($B11,'[2]5월'!$F$6:$CP$99,3,),)/1000 -> 2289.2581 | Q11: =+P11-O11 -> 27.563698 | R11: =+IFERROR(HLOOKUP($B11,'[3]5월'!$F$6:$CC$57,3,),)/1000 -> 2986.1182 | S11: =+P11-R11 -> -696.86011 | T11: =+IFERROR(HLOOKUP($B11,'[1]5월'!$D$6:$BN$259,16,),)/1000 -> 224.72844 | U11: =+IFERROR(HLOOKUP($B11,'[2]5월'!$F$6:$CP$99,16,),)/1000 -> 308.13145 | V11: =+U11-T11 -> 83.40301 | W11: =+IFERROR(HLOOKUP($B11,'[3]5월'!$F$6:$CC$57,16,),)/1000 -> 411.9241 | X11: =+U11-W11 -> -103.79266 | Y11: =+[4]부산!$Q$85 -> 107699.73 | Z11: =+[4]부산!$R$85 -> 110171.72 | AA11: =+[5]부산!$Q$85 -> 106167.43 | AB11: =+[4]부산!$Q$89 -> 85013.096 | AC11: =+[4]부산!$R$89 -> 83925.996 | AD11: =+[5]부산!$Q$89 -> 82923.267 | AE11: =+Y11-AB11 -> 22686.637 | AF11: =+Z11-AC11 -> 26245.72 | AG11: =+AA11-AD11 -> 23244.162
B12: 서부산 | G12: =+I12 -> 서부산 | I12: 서부산 | J12: =+IFERROR(HLOOKUP($B12,'[1]5월'!$D$6:$BN$259,2,),)/1000 -> 21 | K12: =+IFERROR(HLOOKUP($B12,'[2]5월'!$F$6:$CP$99,2,),)/1000 -> 17.147 | L12: =+K12-J12 -> -3.853 | M12: =+IFERROR(HLOOKUP($B12,'[3]5월'!$F$6:$CC$57,2,),)/1000 -> 23.976 | N12: =+K12-M12 -> -6.829 | O12: =+IFERROR(HLOOKUP($B12,'[1]5월'!$D$6:$BN$259,3,),)/1000 -> 2085.2984 | P12: =+IFERROR(HLOOKUP($B12,'[2]5월'!$F$6:$CP$99,3,),)/1000 -> 1653.59 | Q12: =+P12-O12 -> -431.70839 | R12: =+IFERROR(HLOOKUP($B12,'[3]5월'!$F$6:$CC$57,3,),)/1000 -> 2459.604 | S12: =+P12-R12 -> -806.014 | T12: =+IFERROR(HLOOKUP($B12,'[1]5월'!$D$6:$BN$259,16,),)/1000 -> 216.99265 | U12: =+IFERROR(HLOOKUP($B12,'[2]5월'!$F$6:$CP$99,16,),)/1000 -> 89.008721 | V12: =+U12-T12 -> -127.98392 | W12: =+IFERROR(HLOOKUP($B12,'[3]5월'!$F$6:$CC$57,16,),)/1000 -> 360.2204 | X12: =+U12-W12 -> -271.21168 | Y12: =+[4]서부산!$Q$85 -> 99299.923 | Z12: =+[4]서부산!$R$85 -> 96775.187 | AA12: =+[5]서부산!$Q$85 -> 102586.09 | AB12: =+[4]서부산!$Q$89 -> 78479.974 | AC12: =+[4]서부산!$R$89 -> 78037.415 | AD12: =+[5]서부산!$Q$89 -> 78582.596 | AE12: =+Y12-AB12 -> 20819.949 | AF12: =+Z12-AC12 -> 18737.772 | AG12: =+AA12-AD12 -> 24003.49
B13: 김해 | G13: =+I13 -> 김해 | I13: 김해 | J13: =+IFERROR(HLOOKUP($B13,'[1]5월'!$D$6:$BN$259,2,),)/1000 -> 15 | K13: =+IFERROR(HLOOKUP($B13,'[2]5월'!$F$6:$CP$99,2,),)/1000 -> 8.128 | L13: =+K13-J13 -> -6.872 | M13: =+IFERROR(HLOOKUP($B13,'[3]5월'!$F$6:$CC$57,2,),)/1000 -> 14.268 | N13: =+K13-M13 -> -6.14 | O13: =+IFERROR(HLOOKUP($B13,'[1]5월'!$D$6:$BN$259,3,),)/1000 -> 1444.4978 | P13: =+IFERROR(HLOOKUP($B13,'[2]5월'!$F$6:$CP$99,3,),)/1000 -> 696.279 | Q13: =+P13-O13 -> -748.2188 | R13: =+IFERROR(HLOOKUP($B13,'[3]5월'!$F$6:$CC$57,3,),)/1000 -> 1329.1365 | S13: =+P13-R13 -> -632.8575 | T13: =+IFERROR(HLOOKUP($B13,'[1]5월'!$D$6:$BN$259,16,),)/1000 -> 145.73735 | U13: =+IFERROR(HLOOKUP($B13,'[2]5월'!$F$6:$CP$99,16,),)/1000 -> -70.922998 | V13: =+U13-T13 -> -216.66035 | W13: =+IFERROR(HLOOKUP($B13,'[3]5월'!$F$6:$CC$57,16,),)/1000 -> 76.218467 | X13: =+U13-W13 -> -147.14147 | Y13: =+[4]김해!$Q$85 -> 96299.853 | Z13: =+[4]김해!$R$85 -> 85822.552 | AA13: =+[5]김해!$Q$85 -> 93214.324 | AB13: =+[4]김해!$Q$89 -> 76825.978 | AC13: =+[4]김해!$R$89 -> 78014.983 | AD13: =+[5]김해!$Q$89 -> 77424.481 | AE13: =+Y13-AB13 -> 19473.875 | AF13: =+Z13-AC13 -> 7807.5691 | AG13: =+AA13-AD13 -> 15789.844
B14: 정관 | G14: =+I14 -> 정관 | I14: 정관 | J14: =+IFERROR(HLOOKUP($B14,'[1]5월'!$D$6:$BN$259,2,),)/1000 -> 19 | K14: =+IFERROR(HLOOKUP($B14,'[2]5월'!$F$6:$CP$99,2,),)/1000 -> 23.4385 | L14: =+K14-J14 -> 4.4385 | M14: =+IFERROR(HLOOKUP($B14,'[3]5월'!$F$6:$CC$57,2,),)/1000 -> 24.315 | N14: =+K14-M14 -> -0.8765 | O14: =+IFERROR(HLOOKUP($B14,'[1]5월'!$D$6:$BN$259,3,),)/1000 -> 1937.9924 | P14: =+IFERROR(HLOOKUP($B14,'[2]5월'!$F$6:$CP$99,3,),)/1000 -> 2254.526 | Q14: =+P14-O14 -> 316.53359 | R14: =+IFERROR(HLOOKUP($B14,'[3]5월'!$F$6:$CC$57,3,),)/1000 -> 2465.0836 | S14: =+P14-R14 -> -210.5576 | T14: =+IFERROR(HLOOKUP($B14,'[1]5월'!$D$6:$BN$259,16,),)/1000 -> 172.35954 | U14: =+IFERROR(HLOOKUP($B14,'[2]5월'!$F$6:$CP$99,16,),)/1000 -> 201.7835 | V14: =+U14-T14 -> 29.423965 | W14: =+IFERROR(HLOOKUP($B14,'[3]5월'!$F$6:$CC$57,16,),)/1000 -> 313.18669 | X14: =+U14-W14 -> -111.40319 | Y14: =+[4]정관!$Q$85 -> 101999.6 | Z14: =+[4]정관!$R$85 -> 96261.012 | AA14: =+[5]정관!$Q$85 -> 101381.19 | AB14: =+[4]정관!$Q$89 -> 82461.938 | AC14: =+[4]정관!$R$89 -> 78911.617 | AD14: =+[5]정관!$Q$89 -> 80646.065 | AE14: =+Y14-AB14 -> 19537.662 | AF14: =+Z14-AC14 -> 17349.395 | AG14: =+AA14-AD14 -> 20735.124
B15: 양산 | G15: =+I15 -> 양산 | I15: 양산 | J15: =+IFERROR(HLOOKUP($B15,'[1]5월'!$D$6:$BN$259,2,),)/1000 -> 12 | K15: =+IFERROR(HLOOKUP($B15,'[2]5월'!$F$6:$CP$99,2,),)/1000 -> 8.737 | L15: =+K15-J15 -> -3.263 | M15: =+IFERROR(HLOOKUP($B15,'[3]5월'!$F$6:$CC$57,2,),)/1000 -> 14.568 | N15: =+K15-M15 -> -5.831 | O15: =+IFERROR(HLOOKUP($B15,'[1]5월'!$D$6:$BN$259,3,),)/1000 -> 1133.43 | P15: =+IFERROR(HLOOKUP($B15,'[2]5월'!$F$6:$CP$99,3,),)/1000 -> 783.76212 | Q15: =+P15-O15 -> -349.66788 | R15: =+IFERROR(HLOOKUP($B15,'[3]5월'!$F$6:$CC$57,3,),)/1000 -> 1362.5258 | S15: =+P15-R15 -> -578.76366 | T15: =+IFERROR(HLOOKUP($B15,'[1]5월'!$D$6:$BN$259,16,),)/1000 -> 104.55247 | U15: =+IFERROR(HLOOKUP($B15,'[2]5월'!$F$6:$CP$99,16,),)/1000 -> 38.252911 | V15: =+U15-T15 -> -66.299555 | W15: =+IFERROR(HLOOKUP($B15,'[3]5월'!$F$6:$CC$57,16,),)/1000 -> 152.34023 | X15: =+U15-W15 -> -114.08732 | Y15: =+[4]양산!$Q$85 -> 94452.5 | Z15: =+[4]양산!$R$85 -> 89706.091 | AA15: =+[5]양산!$Q$85 -> 93528.678 | AB15: =+[4]양산!$Q$89 -> 74267.729 | AC15: =+[4]양산!$R$89 -> 71251.382 | AD15: =+[5]양산!$Q$89 -> 73905.509 | AE15: =+Y15-AB15 -> 20184.771 | AF15: =+Z15-AC15 -> 18454.709 | AG15: =+AA15-AD15 -> 19623.169
B16: 창원 | G16: =+I16 -> 창원 | I16: 창원 | J16: =+IFERROR(HLOOKUP($B16,'[1]5월'!$D$6:$BN$259,2,),)/1000 -> 13 | K16: =+IFERROR(HLOOKUP($B16,'[2]5월'!$F$6:$CP$99,2,),)/1000 -> 8.83 | L16: =+K16-J16 -> -4.17 | M16: =+IFERROR(HLOOKUP($B16,'[3]5월'!$F$6:$CC$57,2,),)/1000 -> 20.1685 | N16: =+K16-M16 -> -11.3385 | O16: =+IFERROR(HLOOKUP($B16,'[1]5월'!$D$6:$BN$259,3,),)/1000 -> 1316.9027 | P16: =+IFERROR(HLOOKUP($B16,'[2]5월'!$F$6:$CP$99,3,),)/1000 -> 858.6514 | Q16: =+P16-O16 -> -458.25126 | R16: =+IFERROR(HLOOKUP($B16,'[3]5월'!$F$6:$CC$57,3,),)/1000 -> 1990.1033 | S16: =+P16-R16 -> -1131.4519 | T16: =+IFERROR(HLOOKUP($B16,'[1]5월'!$D$6:$BN$259,16,),)/1000 -> 138.6512 | U16: =+IFERROR(HLOOKUP($B16,'[2]5월'!$F$6:$CP$99,16,),)/1000 -> 24.863254 | V16: =+U16-T16 -> -113.78795 | W16: =+IFERROR(HLOOKUP($B16,'[3]5월'!$F$6:$CC$57,16,),)/1000 -> 309.32629 | X16: =+U16-W16 -> -284.46304 | Y16: =+[4]창원!$Q$85 -> 101300.2 | Z16: =+[4]창원!$R$85 -> 97242.514 | AA16: =+[5]창원!$Q$85 -> 98673.838 | AB16: =+[4]창원!$Q$89 -> 76404.741 | AC16: =+[4]창원!$R$89 -> 75675.416 | AD16: =+[5]창원!$Q$89 -> 74167.145 | AE16: =+Y16-AB16 -> 24895.464 | AF16: =+Z16-AC16 -> 21567.098 | AG16: =+AA16-AD16 -> 24506.693
B17: 대구 | G17: =+I17 -> 대구 | I17: 대구 | J17: =+IFERROR(HLOOKUP($B17,'[1]5월'!$D$6:$BN$259,2,),)/1000 -> 13 | K17: =+IFERROR(HLOOKUP($B17,'[2]5월'!$F$6:$CP$99,2,),)/1000 -> 8.3985 | L17: =+K17-J17 -> -4.6015 | M17: =+IFERROR(HLOOKUP($B17,'[3]5월'!$F$6:$CC$57,2,),)/1000 -> 20.795 | N17: =+K17-M17 -> -12.3965 | O17: =+IFERROR(HLOOKUP($B17,'[1]5월'!$D$6:$BN$259,3,),)/1000 -> 1267.1637 | P17: =+IFERROR(HLOOKUP($B17,'[2]5월'!$F$6:$CP$99,3,),)/1000 -> 714.62896 | Q17: =+P17-O17 -> -552.53474 | R17: =+IFERROR(HLOOKUP($B17,'[3]5월'!$F$6:$CC$57,3,),)/1000 -> 2090.7307 | S17: =+P17-R17 -> -1376.1017 | T17: =+IFERROR(HLOOKUP($B17,'[1]5월'!$D$6:$BN$259,16,),)/1000 -> 151.83098 | U17: =+IFERROR(HLOOKUP($B17,'[2]5월'!$F$6:$CP$99,16,),)/1000 -> -22.058378 | V17: =+U17-T17 -> -173.88935 | W17: =+IFERROR(HLOOKUP($B17,'[3]5월'!$F$6:$CC$57,16,),)/1000 -> 403.78828 | X17: =+U17-W17 -> -425.84666 | Y17: =+[4]대구!$Q$85 -> 97474.131 | Z17: =+[4]대구!$R$85 -> 85090.071 | AA17: =+[5]대구!$Q$85 -> 100540.07 | AB17: =+[4]대구!$Q$89 -> 72947.443 | AC17: =+[4]대구!$R$89 -> 70269.761 | AD17: =+[5]대구!$Q$89 -> 73272.696 | AE17: =+Y17-AB17 -> 24526.687 | AF17: =+Z17-AC17 -> 14820.31 | AG17: =+AA17-AD17 -> 27267.372
B18: 울산 | G18: =+I18 -> 울산 | I18: 울산 | J18: =+IFERROR(HLOOKUP($B18,'[1]5월'!$D$6:$BN$259,2,),)/1000 -> 13.5 | K18: =+IFERROR(HLOOKUP($B18,'[2]5월'!$F$6:$CP$99,2,),)/1000 -> 11.425 | L18: =+K18-J18 -> -2.075 | M18: =+IFERROR(HLOOKUP($B18,'[3]5월'!$F$6:$CC$57,2,),)/1000 -> 11.917 | N18: =+K18-M18 -> -0.492 | O18: =+IFERROR(HLOOKUP($B18,'[1]5월'!$D$6:$BN$259,3,),)/1000 -> 1363.75 | P18: =+IFERROR(HLOOKUP($B18,'[2]5월'!$F$6:$CP$99,3,),)/1000 -> 1191.1941 | Q18: =+P18-O18 -> -172.5559 | R18: =+IFERROR(HLOOKUP($B18,'[3]5월'!$F$6:$CC$57,3,),)/1000 -> 1241.1459 | S18: =+P18-R18 -> -49.95175 | T18: =+IFERROR(HLOOKUP($B18,'[1]5월'!$D$6:$BN$259,16,),)/1000 -> 115.02258 | U18: =+IFERROR(HLOOKUP($B18,'[2]5월'!$F$6:$CP$99,16,),)/1000 -> 111.42436 | V18: =+U18-T18 -> -3.598221 | W18: =+IFERROR(HLOOKUP($B18,'[3]5월'!$F$6:$CC$57,16,),)/1000 -> 187.53756 | X18: =+U18-W18 -> -76.113204 | Y18: =+[4]울산!$Q$85 -> 101018.52 | Z18: =+[4]울산!$R$85 -> 104262.07 | AA18: =+[5]울산!$Q$85 -> 104149.19 | AB18: =+[4]울산!$Q$89 -> 81726.476 | AC18: =+[4]울산!$R$89 -> 81655.985 | AD18: =+[5]울산!$Q$89 -> 78333.912 | AE18: =+Y18-AB18 -> 19292.043 | AF18: =+Z18-AC18 -> 22606.081 | AG18: =+AA18-AD18 -> 25815.274
B19: 아산 | G19: =+I19 -> 아산 | I19: 아산 | J19: =+IFERROR(HLOOKUP($B19,'[1]5월'!$D$6:$BN$259,2,),)/1000 -> 24 | K19: =+IFERROR(HLOOKUP($B19,'[2]5월'!$F$6:$CP$99,2,),)/1000 -> 22.644 | L19: =+K19-J19 -> -1.356 | M19: =+IFERROR(HLOOKUP($B19,'[3]5월'!$F$6:$CC$57,2,),)/1000 -> 32.637 | N19: =+K19-M19 -> -9.993 | O19: =+IFERROR(HLOOKUP($B19,'[1]5월'!$D$6:$BN$259,3,),)/1000 -> 2472 | P19: =+IFERROR(HLOOKUP($B19,'[2]5월'!$F$6:$CP$99,3,),)/1000 -> 2188.967 | Q19: =+P19-O19 -> -283.033 | R19: =+IFERROR(HLOOKUP($B19,'[3]5월'!$F$6:$CC$57,3,),)/1000 -> 3371.382 | S19: =+P19-R19 -> -1182.415 | T19: =+IFERROR(HLOOKUP($B19,'[1]5월'!$D$6:$BN$259,16,),)/1000 -> 348.62173 | U19: =+IFERROR(HLOOKUP($B19,'[2]5월'!$F$6:$CP$99,16,),)/1000 -> 136.46828 | V19: =+U19-T19 -> -212.15345 | W19: =+IFERROR(HLOOKUP($B19,'[3]5월'!$F$6:$CC$57,16,),)/1000 -> 681.32996 | X19: =+U19-W19 -> -544.86168 | Y19: =+[4]아산!$Q$85 -> 103000 | Z19: =+[4]아산!$R$85 -> 96668.742 | AA19: =+[5]아산!$Q$85 -> 103299.38 | AB19: =+[4]아산!$Q$89 -> 78366.26 | AC19: =+[4]아산!$R$89 -> 79974.966 | AD19: =+[5]아산!$Q$89 -> 75203.707 | AE19: =+Y19-AB19 -> 24633.74 | AF19: =+Z19-AC19 -> 16693.777 | AG19: =+AA19-AD19 -> 28095.677
B20: 전주 | G20: =+I20 -> 전주 | I20: 전주 | J20: =+IFERROR(HLOOKUP($B20,'[1]5월'!$D$6:$BN$259,2,),)/1000 -> 12 | K20: =+IFERROR(HLOOKUP($B20,'[2]5월'!$F$6:$CP$99,2,),)/1000 -> 13.9375 | L20: =+K20-J20 -> 1.9375 | M20: =+IFERROR(HLOOKUP($B20,'[3]5월'!$F$6:$CC$57,2,),)/1000 -> 14.1955 | N20: =+K20-M20 -> -0.258 | O20: =+IFERROR(HLOOKUP($B20,'[1]5월'!$D$6:$BN$259,3,),)/1000 -> 1162.2994 | P20: =+IFERROR(HLOOKUP($B20,'[2]5월'!$F$6:$CP$99,3,),)/1000 -> 1348.2397 | Q20: =+P20-O20 -> 185.9403 | R20: =+IFERROR(HLOOKUP($B20,'[3]5월'!$F$6:$CC$57,3,),)/1000 -> 1369.0424 | S20: =+P20-R20 -> -20.80265 | T20: =+IFERROR(HLOOKUP($B20,'[1]5월'!$D$6:$BN$259,16,),)/1000 -> 134.35065 | U20: =+IFERROR(HLOOKUP($B20,'[2]5월'!$F$6:$CP$99,16,),)/1000 -> 165.00719 | V20: =+U20-T20 -> 30.656538 | W20: =+IFERROR(HLOOKUP($B20,'[3]5월'!$F$6:$CC$57,16,),)/1000 -> 209.80582 | X20: =+U20-W20 -> -44.79863 | Y20: =+[4]전주!$Q$85 -> 96858.283 | Z20: =+[4]전주!$R$85 -> 96734.687 | AA20: =+[5]전주!$Q$85 -> 96441.996 | AB20: =+[4]전주!$Q$89 -> 73172.774 | AC20: =+[4]전주!$R$89 -> 74428.278 | AD20: =+[5]전주!$Q$89 -> 70782.447 | AE20: =+Y20-AB20 -> 23685.51 | AF20: =+Z20-AC20 -> 22306.409 | AG20: =+AA20-AD20 -> 25659.549
B21: 군산 | G21: =+I21 -> 군산 | I21: 군산 | J21: =+IFERROR(HLOOKUP($B21,'[1]5월'!$D$6:$BN$259,2,),)/1000 -> 8 | K21: =+IFERROR(HLOOKUP($B21,'[2]5월'!$F$6:$CP$99,2,),)/1000 -> 6.231 | L21: =+K21-J21 -> -1.769 | M21: =+IFERROR(HLOOKUP($B21,'[3]5월'!$F$6:$CC$57,2,),)/1000 -> 10.731 | N21: =+K21-M21 -> -4.5 | O21: =+IFERROR(HLOOKUP($B21,'[1]5월'!$D$6:$BN$259,3,),)/1000 -> 888.0664 | P21: =+IFERROR(HLOOKUP($B21,'[2]5월'!$F$6:$CP$99,3,),)/1000 -> 651.478 | Q21: =+P21-O21 -> -236.5884 | R21: =+IFERROR(HLOOKUP($B21,'[3]5월'!$F$6:$CC$57,3,),)/1000 -> 1218.0546 | S21: =+P21-R21 -> -566.5766 | T21: =+IFERROR(HLOOKUP($B21,'[1]5월'!$D$6:$BN$259,16,),)/1000 -> 220.37123 | U21: =+IFERROR(HLOOKUP($B21,'[2]5월'!$F$6:$CP$99,16,),)/1000 -> 130.46313 | V21: =+U21-T21 -> -89.908091 | W21: =+IFERROR(HLOOKUP($B21,'[3]5월'!$F$6:$CC$57,16,),)/1000 -> 349.47533 | X21: =+U21-W21 -> -219.01219 | Y21: =+[4]군산!$Q$85 -> 111008.3 | Z21: =+[4]군산!$R$85 -> 104554.33 | AA21: =+[5]군산!$Q$85 -> 113508.02 | AB21: =+[4]군산!$Q$89 -> 72311.475 | AC21: =+[4]군산!$R$89 -> 70840.843 | AD21: =+[5]군산!$Q$89 -> 73381.874 | AE21: =+Y21-AB21 -> 38696.825 | AF21: =+Z21-AC21 -> 33713.482 | AG21: =+AA21-AD21 -> 40126.149
B22: 원주 | G22: =+I22 -> 원주 | I22: 원주 | J22: =+IFERROR(HLOOKUP($B22,'[1]5월'!$D$6:$BN$259,2,),)/1000 -> 6 | K22: =+IFERROR(HLOOKUP($B22,'[2]5월'!$F$6:$CP$99,2,),)/1000 -> 1.6815 | L22: =+K22-J22 -> -4.3185 | M22: =+IFERROR(HLOOKUP($B22,'[3]5월'!$F$6:$CC$57,2,),)/1000 -> 7.601 | N22: =+K22-M22 -> -5.9195 | O22: =+IFERROR(HLOOKUP($B22,'[1]5월'!$D$6:$BN$259,3,),)/1000 -> 672 | P22: =+IFERROR(HLOOKUP($B22,'[2]5월'!$F$6:$CP$99,3,),)/1000 -> 184.23005 | Q22: =+P22-O22 -> -487.76995 | R22: =+IFERROR(HLOOKUP($B22,'[3]5월'!$F$6:$CC$57,3,),)/1000 -> 848.8332 | S22: =+P22-R22 -> -664.60315 | T22: =+IFERROR(HLOOKUP($B22,'[1]5월'!$D$6:$BN$259,16,),)/1000 -> 147.92445 | U22: =+IFERROR(HLOOKUP($B22,'[2]5월'!$F$6:$CP$99,16,),)/1000 -> -23.378171 | V22: =+U22-T22 -> -171.30262 | W22: =+IFERROR(HLOOKUP($B22,'[3]5월'!$F$6:$CC$57,16,),)/1000 -> 211.34338 | X22: =+U22-W22 -> -234.72155 | Y22: =+[4]원주!$Q$85 -> 112000 | Z22: =+[4]원주!$R$85 -> 109562.92 | AA22: =+[5]원주!$Q$85 -> 111673.89 | AB22: =+[4]원주!$Q$89 -> 72688.332 | AC22: =+[4]원주!$R$89 -> 72019.425 | AD22: =+[5]원주!$Q$89 -> 71854.954 | AE22: =+Y22-AB22 -> 39311.668 | AF22: =+Z22-AC22 -> 37543.495 | AG22: =+AA22-AD22 -> 39818.931
B23: 제주 | G23: =+I23 -> 제주 | I23: 제주 | J23: =+IFERROR(HLOOKUP($B23,'[1]5월'!$D$6:$BN$259,2,),)/1000 -> 8 | K23: =+IFERROR(HLOOKUP($B23,'[2]5월'!$F$6:$CP$99,2,),)/1000 -> 5.85 | L23: =+K23-J23 -> -2.15 | M23: =+IFERROR(HLOOKUP($B23,'[3]5월'!$F$6:$CC$57,2,),)/1000 -> 3.7165 | N23: =+K23-M23 -> 2.1335 | O23: =+IFERROR(HLOOKUP($B23,'[1]5월'!$D$6:$BN$259,3,),)/1000 -> 980.908 | P23: =+IFERROR(HLOOKUP($B23,'[2]5월'!$F$6:$CP$99,3,),)/1000 -> 707.66847 | Q23: =+P23-O23 -> -273.23953 | R23: =+IFERROR(HLOOKUP($B23,'[3]5월'!$F$6:$CC$57,3,),)/1000 -> 463.02055 | S23: =+P23-R23 -> 244.64792 | T23: =+IFERROR(HLOOKUP($B23,'[1]5월'!$D$6:$BN$259,16,),)/1000 -> 160.44292 | U23: =+IFERROR(HLOOKUP($B23,'[2]5월'!$F$6:$CP$99,16,),)/1000 -> 60.026911 | V23: =+U23-T23 -> -100.41601 | W23: =+IFERROR(HLOOKUP($B23,'[3]5월'!$F$6:$CC$57,16,),)/1000 -> 51.135698 | X23: =+U23-W23 -> 8.891213 | Y23: =+[4]제주!$Q$85 -> 122613.5 | Z23: =+[4]제주!$R$85 -> 120514.24 | AA23: =+[5]제주!$Q$85 -> 124585.11 | AB23: =+[4]제주!$Q$89 -> 91127.321 | AC23: =+[4]제주!$R$89 -> 92365.438 | AD23: =+[5]제주!$Q$89 -> 88417.978 | AE23: =+Y23-AB23 -> 31486.179 | AF23: =+Z23-AC23 -> 28148.799 | AG23: =+AA23-AD23 -> 36167.129
F24: =+K24/J24 -> 0.81684286 | G24: =+I24 -> 수도권 | I24: 수도권 | J24: =SUM(J7:J10) -> 105 | K24: =SUM(K7:K10) -> 85.7685 | L24: =+K24-J24 -> -19.2315 | M24: =SUM(M7:M10) -> 120.114 | N24: =+K24-M24 -> -34.3455 | O24: =SUM(O7:O10) -> 10185.812 | P24: =SUM(P7:P10) -> 8277.4551 | Q24: =+P24-O24 -> -1908.3566 | R24: =SUM(R7:R10) -> 11931.163 | S24: =+P24-R24 -> -3653.708 | T24: =SUM(T7:T10) -> 746.49657 | U24: =SUM(U7:U10) -> 405.24294 | V24: =+U24-T24 -> -341.25363 | W24: =SUM(W7:W10) -> 1345.1499 | X24: =+U24-W24 -> -939.90696 | Y24: =+[4]수도권!$Q$85 -> 97007.731 | Z24: =+[4]수도권!$R$85 -> 96609.726 | AA24: =+[5]수도권!$Q$85 -> 99353.382 | AB24: =+[4]수도권!$Q$89 -> 80552.566 | AC24: =+[4]수도권!$R$89 -> 80138.588 | AD24: =+[5]수도권!$Q$89 -> 80233.601 | AE24: =+Y24-AB24 -> 16455.164 | AF24: =+Z24-AC24 -> 16471.138 | AG24: =+AA24-AD24 -> 19119.781
F25: =+K25/J25 -> 0.83829804 | G25: =+I25 -> 영남권 | I25: 영남권 | J25: =SUM(J11:J18) -> 127.5 | K25: =SUM(K11:K18) -> 106.883 | L25: =+K25-J25 -> -20.617 | M25: =SUM(M11:M18) -> 158.134 | N25: =+K25-M25 -> -51.251 | O25: =SUM(O11:O18) -> 12810.729 | P25: =SUM(P11:P18) -> 10441.89 | Q25: =+P25-O25 -> -2368.8397 | R25: =SUM(R11:R18) -> 15924.448 | S25: =+P25-R25 -> -5482.5583 | T25: =SUM(T11:T18) -> 1269.8752 | U25: =SUM(U11:U18) -> 680.48282 | V25: =+U25-T25 -> -589.39238 | W25: =SUM(W11:W18) -> 2214.542 | X25: =+U25-W25 -> -1534.0592 | Y25: =+[4]영남권!$Q$85 -> 100476.31 | Z25: =+[4]영남권!$R$85 -> 97803.84 | AA25: =+[5]영남권!$Q$85 -> 100729.73 | AB25: =+[4]영남권!$Q$89 -> 79126.428 | AC25: =+[4]영남권!$R$89 -> 78382.795 | AD25: =+[5]영남권!$Q$89 -> 77860.412 | AE25: =+Y25-AB25 -> 21349.881 | AF25: =+Z25-AC25 -> 19421.045 | AG25: =+AA25-AD25 -> 22869.321
F26: =+K26/J26 -> 0.868 | G26: =+I26 -> 중부권 | I26: 중부권 | J26: =SUM(J19:J23) -> 58 | K26: =SUM(K19:K23) -> 50.344 | L26: =+K26-J26 -> -7.656 | M26: =SUM(M19:M23) -> 68.881 | N26: =+K26-M26 -> -18.537 | O26: =SUM(O19:O23) -> 6175.2738 | P26: =SUM(P19:P23) -> 5080.5832 | Q26: =+P26-O26 -> -1094.6906 | R26: =SUM(R19:R23) -> 7270.3327 | S26: =+P26-R26 -> -2189.7495 | T26: =SUM(T19:T23) -> 1011.711 | U26: =SUM(U19:U23) -> 468.58735 | V26: =+U26-T26 -> -543.12363 | W26: =SUM(W19:W23) -> 1503.0902 | X26: =+U26-W26 -> -1034.5028 | Y26: =+[4]중부권!$Q$85 -> 106470.24 | Z26: =+[4]중부권!$R$85 -> 100717.64 | AA26: =+[5]중부권!$Q$85 -> 105549.17 | AB26: =+[4]중부권!$Q$89 -> 77629.377 | AC26: =+[4]중부권!$R$89 -> 78379.749 | AD26: =+[5]중부권!$Q$89 -> 74352.154 | AE26: =+Y26-AB26 -> 28840.861 | AF26: =+Z26-AC26 -> 22337.894 | AG26: =+AA26-AD26 -> 31197.021
F27: =+K27/M27 -> 0.70001498 | G27: =+K27/J27 -> 0.83647332 | H27: 레미콘 계 | J27: =SUM(J24:J26) -> 290.5 | K27: =SUM(K24:K26) -> 242.9955 | L27: =+K27-J27 -> -47.5045 | M27: =SUM(M24:M26) -> 347.129 | N27: =+K27-M27 -> -104.1335 | O27: =SUM(O24:O26) -> 29171.815 | P27: =SUM(P24:P26) -> 23799.928 | Q27: =+P27-O27 -> -5371.8869 | R27: =SUM(R24:R26) -> 35125.944 | S27: =+P27-R27 -> -11326.016 | T27: =SUM(T24:T26) -> 3028.0827 | U27: =SUM(U24:U26) -> 1554.3131 | V27: =+U27-T27 -> -1473.7696 | W27: =SUM(W24:W26) -> 5062.7821 | X27: =+U27-W27 -> -3508.469 | Y27: =+[4]합계!$Q$85 -> 100419.33 | Z27: =+[4]합계!$R$85 -> 97989.576 | AA27: =+[5]합계!$Q$85 -> 101219.55 | AB27: =+[4]합계!$Q$89 -> 79343.005 | AC27: =+[4]합계!$R$89 -> 78999.854 | AD27: =+[5]합계!$Q$89 -> 77974.542 | AE27: =+Y27-AB27 -> 21076.324 | AF27: =+Z27-AC27 -> 18989.722 | AG27: =+AA27-AD27 -> 23245.012 | AI27: =+AF27-AE27 -> -2086.6015 | AJ27: =+AF27-AG27 -> -4255.2898
B28: 건자재 | E28: 건자재영업 | G28: 건자재 | H28: 건자재 | J28: =+IFERROR(HLOOKUP($B28,'[1]5월'!$D$6:$BN$259,2,),) -> 10700 | K28: =+IFERROR(HLOOKUP($E28,'[2]5월'!$F$6:$CP$99,2,),) -> 10256.286 | L28: =+K28-J28 -> -443.714 | M28: =+IFERROR(HLOOKUP($E28,'[3]5월'!$F$6:$CC$57,2,),) -> 9787.441 | N28: =+K28-M28 -> 468.845 | O28: =+IFERROR(HLOOKUP($B28,'[1]5월'!$D$6:$BN$259,3,),)/1000 -> 11710.568 | P28: =+IFERROR(HLOOKUP($E28,'[2]5월'!$F$6:$CP$99,3,),)/1000 -> 10025.106 | Q28: =+P28-O28 -> -1685.4627 | R28: =+IFERROR(HLOOKUP($E28,'[3]5월'!$F$6:$CC$57,3,),)/1000 -> 9774.8209 | S28: =+P28-R28 -> 250.28473 | T28: =+IFERROR(HLOOKUP($B28,'[1]5월'!$D$6:$BN$259,16,),)/1000 -> 192.4776 | U28: =+IFERROR(HLOOKUP($E28,'[2]5월'!$F$6:$CP$99,16,),)/1000 -> 46.262732 | V28: =+U28-T28 -> -146.21486 | W28: =+IFERROR(HLOOKUP($E28,'[3]5월'!$F$6:$CC$57,16,),)/1000 -> 122.36803 | X28: =+U28-W28 -> -76.105295 | Y28: ■ 비고
B29: 부산모래장 | C29: 부산골재 | G29: =+I29 -> 부산모래장 | H29: 골재 | I29: 부산모래장 | J29: =+IFERROR(HLOOKUP($B29,'[1]5월'!$D$6:$BN$259,2,),)/1000 -> 24.954729 | K29: =+IFERROR(HLOOKUP($C29,'[2]5월'!$F$6:$CP$99,2,),)/1000 -> 26.131 | L29: =+K29-J29 -> 1.1762714 | M29: =+IFERROR(HLOOKUP($C29,'[3]5월'!$F$6:$CC$57,2,),)/1000 -> 25.913 | N29: =+K29-M29 -> 0.218 | O29: =+IFERROR(HLOOKUP($B29,'[1]5월'!$D$6:$BN$259,3,),)/1000 -> 678.26088 | P29: =+IFERROR(HLOOKUP($C29,'[2]5월'!$F$6:$CP$99,3,),)/1000 -> 733.4355 | Q29: =+P29-O29 -> 55.174616 | R29: =+IFERROR(HLOOKUP($C29,'[3]5월'!$F$6:$CC$57,3,),)/1000 -> 748.562 | S29: =+P29-R29 -> -15.1265 | T29: =+IFERROR(HLOOKUP($B29,'[1]5월'!$D$6:$BN$259,21,),)/1000 -> 70.574216 | U29: =+IFERROR(HLOOKUP($C29,'[2]5월'!$F$6:$CP$99,21,),)/1000 -> 74.179301 | V29: =+U29-T29 -> 3.6050852 | W29: =+IFERROR(HLOOKUP($C29,'[3]5월'!$F$6:$CC$57,21,),)/1000 -> 42.923393 | X29: =+U29-W29 -> 31.255908 | Y29: - 판매단가 : 대구권 단가협상 4,900원/㎥↓(5/1부)
B30: 서부산크라샤 | C30: 서부산골재 | G30: =+I30 -> 서부산CR | I30: 서부산CR | J30: =+IFERROR(HLOOKUP($B30,'[1]5월'!$D$6:$BN$259,2,),)/1000 -> 49.378252 | K30: =+IFERROR(HLOOKUP($C30,'[2]5월'!$F$6:$CP$99,2,),)/1000 -> 20.388 | L30: =+K30-J30 -> -28.990252 | M30: =+IFERROR(HLOOKUP($C30,'[3]5월'!$F$6:$CC$57,2,),)/1000 -> 26.574 | N30: =+K30-M30 -> -6.186 | O30: =+IFERROR(HLOOKUP($B30,'[1]5월'!$D$6:$BN$259,3,),)/1000 -> 711.17443 | P30: =+IFERROR(HLOOKUP($C30,'[2]5월'!$F$6:$CP$99,3,),)/1000 -> 291.392 | Q30: =+P30-O30 -> -419.78243 | R30: =+IFERROR(HLOOKUP($C30,'[3]5월'!$F$6:$CC$57,3,),)/1000 -> 369.83 | S30: =+P30-R30 -> -78.438 | T30: =+IFERROR(HLOOKUP($B30,'[1]5월'!$D$6:$BN$259,21,),)/1000 -> 136.78435 | U30: =+IFERROR(HLOOKUP($C30,'[2]5월'!$F$6:$CP$99,21,),)/1000 -> 29.834151 | V30: =+U30-T30 -> -106.9502 | W30: =+IFERROR(HLOOKUP($C30,'[3]5월'!$F$6:$CC$57,21,),)/1000 -> 48.486048 | X30: =+U30-W30 -> -18.651897 | Y30: - 1군 판가 소급분(마이너스 계산서) : 0.8억
B31: 부산크라샤 | C31: 부산크라샤 | G31: =+I31 -> 부산CR | I31: 부산CR | J31: =+IFERROR(HLOOKUP($B31,'[1]5월'!$D$6:$BN$259,2,),)/1000 -> 41.403802 | K31: =+IFERROR(HLOOKUP($C31,'[2]5월'!$F$6:$CP$99,2,),)/1000 -> 23.17 | L31: =+K31-J31 -> -18.233802 | M31: =+IFERROR(HLOOKUP($C31,'[3]5월'!$F$6:$CC$57,2,),)/1000 -> 46.828 | N31: =+K31-M31 -> -23.658 | O31: =+IFERROR(HLOOKUP($B31,'[1]5월'!$D$6:$BN$259,3,),)/1000 -> 698.28267 | P31: =+IFERROR(HLOOKUP($C31,'[2]5월'!$F$6:$CP$99,3,),)/1000 -> 442.799 | Q31: =+P31-O31 -> -255.48367 | R31: =+IFERROR(HLOOKUP($C31,'[3]5월'!$F$6:$CC$57,3,),)/1000 -> 857.386 | S31: =+P31-R31 -> -414.587 | T31: =+IFERROR(HLOOKUP($B31,'[1]5월'!$D$6:$BN$259,21,),)/1000 -> 91.524011 | U31: =+IFERROR(HLOOKUP($C31,'[2]5월'!$F$6:$CP$99,21,),)/1000 -> -90.562278 | V31: =+U31-T31 -> -182.08629 | W31: =+IFERROR(HLOOKUP($C31,'[3]5월'!$F$6:$CC$57,21,),)/1000 -> 80.169636 | X31: =+U31-W31 -> -170.73191 | Y31: - 운반비 : 영남권 MT운반비 2개년 합의 인상 적용(5/1)
H32: 골재 계 | J32: =SUM(J29:J31) -> 115.73678 | K32: =SUM(K29:K31) -> 69.689 | L32: =+K32-J32 -> -46.047782 | M32: =SUM(M29:M31) -> 99.315 | N32: =+K32-M32 -> -29.626 | O32: =SUM(O29:O31) -> 2087.718 | P32: =SUM(P29:P31) -> 1467.6265 | Q32: =+P32-O32 -> -620.09148 | R32: =SUM(R29:R31) -> 1975.778 | S32: =+P32-R32 -> -508.1515 | T32: =SUM(T29:T31) -> 298.88258 | U32: =SUM(U29:U31) -> 13.451174 | V32: =+U32-T32 -> -285.43141 | W32: =SUM(W29:W31) -> 171.57908 | X32: =+U32-W32 -> -158.1279 | Y32: → 부산권 4천원, 창원 3.5천원 / 제주 협상完 500원/㎥ 인상
B33: 포항임대 | C33: 속초임대 | D33: 강릉임대 | E33: 레미콘임대 계 | G33: =+I33 -> 레미콘임대 | H33: 기타 | I33: 레미콘임대 | L33: =+K33-J33 -> 0 | N33: =+K33-M33 -> 0 | O33: =(IFERROR(HLOOKUP($B33,'[1]5월'!$D$6:$BN$259,3,),)++IFERROR(HLOOKUP($C33,'[1]5월'!$D$6:$BN$259,3,),)+IFERROR(HLOOKUP($D33,'[1]5월'!$D$6:$BN$259,3,),))/1000 -> 66.666667 | P33: =+IFERROR(HLOOKUP($E33,'[2]5월'!$F$6:$CP$99,3,),)/1000 -> 43.34 | Q33: =+P33-O33 -> -23.326667 | R33: =+IFERROR(HLOOKUP($E33,'[3]5월'!$F$6:$CC$57,3,),)/1000 -> 90.84 | S33: =+P33-R33 -> -47.5 | T33: =(IFERROR(HLOOKUP($B33,'[1]5월'!$D$6:$BN$259,21,),)++IFERROR(HLOOKUP($C33,'[1]5월'!$D$6:$BN$259,21,),)+IFERROR(HLOOKUP($D33,'[1]5월'!$D$6:$BN$259,21,),))/1000 -> 48.349888 | U33: =+IFERROR(HLOOKUP($E33,'[2]5월'!$F$6:$CP$99,16,),)/1000 -> 23.178219 | V33: =+U33-T33 -> -25.171669 | W33: =+IFERROR(HLOOKUP($E33,'[3]5월'!$F$6:$CC$57,16,),)/1000 -> 68.93061 | X33: =+U33-W33 -> -45.752391
B34: 부동산임대 | C34: 주유소임대 | E34: 임대 계 | G34: =+I34 -> 임대 | I34: 임대 | L34: =+K34-J34 -> 0 | M34: 0 | N34: =+K34-M34 -> 0 | O34: =(+IFERROR(HLOOKUP($B34,'[1]5월'!$D$6:$BN$259,3,),)+IFERROR(HLOOKUP($C34,'[1]5월'!$D$6:$BN$259,3,),))/1000 -> 74.0915 | P34: =+IFERROR(HLOOKUP($E34,'[2]5월'!$F$6:$CP$99,3,),)/1000 -> 73.768631 | Q34: =+P34-O34 -> -0.322869 | R34: =+IFERROR(HLOOKUP($E34,'[3]5월'!$F$6:$CC$57,3,),)/1000 -> 73.683136 | S34: =+P34-R34 -> 0.085495 | T34: =(+IFERROR(HLOOKUP($B34,'[1]5월'!$D$6:$BN$259,21,),)+IFERROR(HLOOKUP($C34,'[1]5월'!$D$6:$BN$259,21,),))/1000 -> 63.964 | U34: =+IFERROR(HLOOKUP($E34,'[2]5월'!$F$6:$CP$99,16,),)/1000 -> 66.602381 | V34: =+U34-T34 -> 2.638381 | W34: =+IFERROR(HLOOKUP($E34,'[3]5월'!$F$6:$CC$57,16,),)/1000 -> 63.574319 | X34: =+U34-W34 -> 3.028062
B35: 공 통 비 | G35: =+I35 -> 공통비 | I35: 공통비 | L35: =+K35-J35 -> 0 | N35: =+K35-M35 -> 0 | Q35: =+P35-O35 -> 0 | S35: =+P35-R35 -> 0 | T35: =-'[1]5월'!$Z$22/1000 -> -1315.8435 | U35: =+-'[2]5월'!$Z$22/1000 -> -1405.8047 | V35: =+U35-T35 -> -89.961196 | W35: =+-'[3]5월'!$Z$22/1000 -> -1157.1102 | X35: =+U35-W35 -> -248.69454
G36: =+I36 -> OPC 소급분 | I36: OPC 소급분 | N36: =+K36-M36 -> 0 | Q36: =+P36-O36 -> 0 | S36: =+P36-R36 -> 0 | U36: ='[2]5월'!$BD$26/1000 -> 0 | V36: =+U36-T36 -> 0 | W36: =-'[3]5월'!$BD$26/1000 -> 0 | X36: =+U36-W36 -> 0
G37: =+I37 -> 대손 | I37: 대손 | N37: =+K37-M37 -> 0 | Q37: =+P37-O37 -> 0 | S37: =+P37-R37 -> 0 | U37: ='[2]5월'!$BE$26/1000 -> 0 | V37: =+U37-T37 -> 0 | W37: ='[3]5월'!$BE$26/1000 -> 0 | X37: =+U37-W37 -> 0
G38: =+I38 -> 미운영 공장 | I38: 미운영 공장 | M38: =SUM(M54:M59) -> 0 | N38: =+K38-M38 -> 0 | Q38: =+P38-O38 -> 0 | R38: =+IFERROR(HLOOKUP($I$38,'[3]5월'!$F$6:$BJ$50,3,),)/1000 -> 0 | S38: =+P38-R38 -> 0 | T38: =SUM('[1]5월'!$AM$26:$AQ$26)/1000 -> -32.504496 | U38: =+'[2]5월'!$BF$26/1000 -> -37.499672 | V38: =+U38-T38 -> -4.995176 | W38: =+'[3]5월'!$BF$26/1000 -> -97.949849 | X38: =+U38-W38 -> 60.450177
B39: 기타 계 | G39: =+I39 -> 퇴직위로금 | I39: 퇴직위로금 | U39: =+'[2]5월'!$BG$26/1000 -> 0 | V39: =+U39-T39 -> 0 | X39: =+U39-W39 -> 0
G40: =+I40 -> 기타 | I40: 기타 | L40: =+K40-J40 -> 0 | N40: =+K40-M40 -> 0 | O40: =IFERROR(HLOOKUP($B39,'[1]5월'!$D$6:$BN$259,3,),)/1000 -> 1.77 | P40: =+('[2]5월'!$F$8-SUM('[2]5월'!$Z$8,'[2]5월'!$AH$8,'[2]5월'!$AN$8,'[2]5월'!$AO$8,'[2]5월'!$BA$8,'[2]5월'!$BD$8,'[2]5월'!$BE$8,'[2]5월'!$BF$8))/1000 -> 1.67985 | Q40: =+P40-O40 -> -0.09015 | R40: =+('[3]5월'!$F$8-SUM('[3]5월'!$Z$8,'[3]5월'!$AH$8,'[3]5월'!$AN$8,'[3]5월'!$AO$8,'[3]5월'!$BA$8,'[3]5월'!$BD$8,'[3]5월'!$BE$8,'[3]5월'!$BF$8))/1000 -> 1.704 | S40: =+P40-R40 -> -0.02415 | T40: =+('[1]5월'!$E$26-'[1]5월'!$Z$26-'[1]5월'!$AA$26-'[1]5월'!$AE$26-'[1]5월'!$AL$26-'[1]5월'!$AM$26-'[1]5월'!$AN$26-'[1]5월'!$AO$26-'[1]5월'!$AP$26-'[1]5월'!$AQ$26-'[1]5월'!$AS$26+'[1]5월'!$AS$26)/1000 -> -85.138375 | U40: =+('[2]5월'!$F$26-SUM('[2]5월'!$Z$26,'[2]5월'!$AH$26,'[2]5월'!$AN$26,'[2]5월'!$AO$26,'[2]5월'!$BA$26,'[2]5월'!$BD$26,'[2]5월'!$BE$26,'[2]5월'!$BF$26))/1000-U39 -> -15.421941 | V40: =+U40-T40 -> 69.716434 | W40: =+('[3]5월'!$F$26-SUM('[3]5월'!$Z$26,'[3]5월'!$AH$26,'[3]5월'!$AN$26,'[3]5월'!$AO$26,'[3]5월'!$BA$26,'[3]5월'!$BD$26,'[3]5월'!$BE$26,'[3]5월'!$BF$26))/1000 -> -16.881884 | X40: =+U40-W40 -> 1.459943
H41: 기타 계 | J41: =SUM(J33:J40) -> 0 | K41: =SUM(K33:K40) -> 0 | L41: =+K41-J41 -> 0 | M41: =SUM(M33:M40) -> 0 | N41: =+K41-M41 -> 0 | O41: =SUM(O33:O40) -> 142.52817 | P41: =SUM(P33:P40) -> 118.78848 | Q41: =+P41-O41 -> -23.739686 | R41: =SUM(R33:R40) -> 166.22714 | S41: =+P41-R41 -> -47.438655 | T41: =SUM(T33:T40) -> -1321.1725 | U41: =SUM(U33:U40) -> -1368.9457 | V41: =+U41-T41 -> -47.773225 | W41: =SUM(W33:W40) -> -1139.437 | X41: =+U41-W41 -> -229.50875
U42: 19 | V42: 12.4
...

Sheet 사업장별(누계)
H3: □ 사업장별 손익실적(2025-05누계)
AG4: [단위 : 천㎥, 톤, 백만원]
H5: 구분 | J5: 물량 | O5: 매출 | T5: 영업이익(공통비 배부전) | Y5: 판매단가 | AB5: 변동비 | AE5: 공헌이익
A6: 2024년 5월누계 마감 손익 | J6: 계획 | K6: 실적 | L6: 차이 | M6: 전년 | N6: 차이 | O6: 계획 | P6: 실적 | Q6: 차이 | R6: 전년 | S6: 차이 | T6: 계획 | U6: 실적 | V6: 차이 | W6: 전년 | X6: 차이 | Y6: 계획 | Z6: 실적 | AA6: 전년 | AB6: 계획 | AC6: 실적 | AD6: 전년 | AE6: 계획 | AF6: 실적 | AG6: 전년
B7: 안양 | G7: =+I7 -> 안양 | H7: 레미콘 | I7: 안양 | J7: =+IFERROR(HLOOKUP($B7,'[1]5월누계'!$D$6:$BN$259,2,),)/1000 -> 182 | K7: =+IFERROR(HLOOKUP($B7,'[2]5월누계'!$F$6:$CP$99,2,),)/1000 -> 171.774 | L7: =+K7-J7 -> -10.226 | M7: =+IFERROR(HLOOKUP($B7,'[3]5월누계'!$F$6:$CC$57,2,),)/1000 -> 211.304 | N7: =+K7-M7 -> -39.53 | O7: =+IFERROR(HLOOKUP($B7,'[1]5월누계'!$D$6:$BN$259,3,),)/1000 -> 17844.87 | P7: =+IFERROR(HLOOKUP($B7,'[2]5월누계'!$F$6:$CP$99,3,),)/1000 -> 16474.909 | Q7: =+P7-O7 -> -1369.9613 | R7: =+IFERROR(HLOOKUP($B7,'[3]5월누계'!$F$6:$CC$57,3,),)/1000 -> 20962.964 | S7: =+P7-R7 -> -4488.0551 | T7: =+IFERROR(HLOOKUP($B7,'[1]5월누계'!$D$6:$BN$259,16,),)/1000 -> 1366.5563 | U7: =+IFERROR(HLOOKUP($B7,'[2]5월누계'!$F$6:$CP$99,16,),)/1000 -> 1107.7854 | V7: =+U7-T7 -> -258.77093 | W7: =+IFERROR(HLOOKUP($B7,'[3]5월누계'!$F$6:$CC$57,16,),)/1000 -> 2251.0942 | X7: =+U7-W7 -> -1143.3088 | Y7: =+[9]안양!$Q$85 -> 98048.737 | Z7: =+[9]안양!$R$85 -> 95893.386 | AA7: =+[10]안양!$Q$85 -> 99203.365 | AB7: =+[9]안양!$Q$89 -> 82117.112 | AC7: =+[9]안양!$R$89 -> 80603.98 | AD7: =+[10]안양!$Q$89 -> 81339.683 | AE7: =+Y7-AB7 -> 15931.626 | AF7: =+Z7-AC7 -> 15289.407 | AG7: =+AA7-AD7 -> 17863.682
B8: 인천 | G8: =+I8 -> 인천 | H8: 직영 | I8: 인천 | J8: =+IFERROR(HLOOKUP($B8,'[1]5월누계'!$D$6:$BN$259,2,),)/1000 -> 135 | K8: =+IFERROR(HLOOKUP($B8,'[2]5월누계'!$F$6:$CP$99,2,),)/1000 -> 135.826 | L8: =+K8-J8 -> 0.826 | M8: =+IFERROR(HLOOKUP($B8,'[3]5월누계'!$F$6:$CC$57,2,),)/1000 -> 143.907 | N8: =+K8-M8 -> -8.081 | O8: =+IFERROR(HLOOKUP($B8,'[1]5월누계'!$D$6:$BN$259,3,),)/1000 -> 13214.933 | P8: =+IFERROR(HLOOKUP($B8,'[2]5월누계'!$F$6:$CP$99,3,),)/1000 -> 13329.679 | Q8: =+P8-O8 -> 114.74518 | R8: =+IFERROR(HLOOKUP($B8,'[3]5월누계'!$F$6:$CC$57,3,),)/1000 -> 14464.339 | S8: =+P8-R8 -> -1134.6604 | T8: =+IFERROR(HLOOKUP($B8,'[1]5월누계'!$D$6:$BN$259,16,),)/1000 -> 471.18145 | U8: =+IFERROR(HLOOKUP($B8,'[2]5월누계'!$F$6:$CP$99,16,),)/1000 -> 304.48832 | V8: =+U8-T8 -> -166.69313 | W8: =+IFERROR(HLOOKUP($B8,'[3]5월누계'!$F$6:$CC$57,16,),)/1000 -> 1221.7192 | X8: =+U8-W8 -> -917.2309 | Y8: =+[9]인천!$Q$85 -> 97888.396 | Z8: =+[9]인천!$R$85 -> 98223.973 | AA8: =+[10]인천!$Q$85 -> 100511.71 | AB8: =+[9]인천!$Q$89 -> 83228.421 | AC8: =+[9]인천!$R$89 -> 84575.512 | AD8: =+[10]인천!$Q$89 -> 82210.921 | AE8: =+Y8-AB8 -> 14659.974 | AF8: =+Z8-AC8 -> 13648.461 | AG8: =+AA8-AD8 -> 18300.792
B9: 파주 | G9: =+I9 -> 파주 | I9: 파주 | J9: =+IFERROR(HLOOKUP($B9,'[1]5월누계'!$D$6:$BN$259,2,),)/1000 -> 94 | K9: =+IFERROR(HLOOKUP($B9,'[2]5월누계'!$F$6:$CP$99,2,),)/1000 -> 54.693 | L9: =+K9-J9 -> -39.307 | M9: =+IFERROR(HLOOKUP($B9,'[3]5월누계'!$F$6:$CC$57,2,),)/1000 -> 123.386 | N9: =+K9-M9 -> -68.693 | O9: =+IFERROR(HLOOKUP($B9,'[1]5월누계'!$D$6:$BN$259,3,),)/1000 -> 9046.8854 | P9: =+IFERROR(HLOOKUP($B9,'[2]5월누계'!$F$6:$CP$99,3,),)/1000 -> 5056.7412 | Q9: =+P9-O9 -> -3990.1443 | R9: =+IFERROR(HLOOKUP($B9,'[3]5월누계'!$F$6:$CC$57,3,),)/1000 -> 12286.365 | S9: =+P9-R9 -> -7229.624 | T9: =+IFERROR(HLOOKUP($B9,'[1]5월누계'!$D$6:$BN$259,16,),)/1000 -> 339.74354 | U9: =+IFERROR(HLOOKUP($B9,'[2]5월누계'!$F$6:$CP$99,16,),)/1000 -> -341.58587 | V9: =+U9-T9 -> -681.3294 | W9: =+IFERROR(HLOOKUP($B9,'[3]5월누계'!$F$6:$CC$57,16,),)/1000 -> 974.81997 | X9: =+U9-W9 -> -1316.4058 | Y9: =+[9]파주!$Q$85 -> 96243.462 | Z9: =+[9]파주!$R$85 -> 92490.514 | AA9: =+[10]파주!$Q$85 -> 99613.277 | AB9: =+[9]파주!$Q$89 -> 79759.886 | AC9: =+[9]파주!$R$89 -> 78587.599 | AD9: =+[10]파주!$Q$89 -> 82206.609 | AE9: =+Y9-AB9 -> 16483.576 | AF9: =+Z9-AC9 -> 13902.915 | AG9: =+AA9-AD9 -> 17406.667
B10: 김포 | G10: =+I10 -> 김포 | I10: 김포 | J10: =+IFERROR(HLOOKUP($B10,'[1]5월누계'!$D$6:$BN$259,2,),)/1000 -> 64 | K10: =+IFERROR(HLOOKUP($B10,'[2]5월누계'!$F$6:$CP$99,2,),)/1000 -> 47.8655 | L10: =+K10-J10 -> -16.1345 | M10: =+IFERROR(HLOOKUP($B10,'[3]5월누계'!$F$6:$CC$57,2,),)/1000 -> 61.9005 | N10: =+K10-M10 -> -14.035 | O10: =+IFERROR(HLOOKUP($B10,'[1]5월누계'!$D$6:$BN$259,3,),)/1000 -> 6088.3355 | P10: =+IFERROR(HLOOKUP($B10,'[2]5월누계'!$F$6:$CP$99,3,),)/1000 -> 4562.9621 | Q10: =+P10-O10 -> -1525.3734 | R10: =+IFERROR(HLOOKUP($B10,'[3]5월누계'!$F$6:$CC$57,3,),)/1000 -> 6138.8182 | S10: =+P10-R10 -> -1575.8561 | T10: =+IFERROR(HLOOKUP($B10,'[1]5월누계'!$D$6:$BN$259,16,),)/1000 -> 319.9856 | U10: =+IFERROR(HLOOKUP($B10,'[2]5월누계'!$F$6:$CP$99,16,),)/1000 -> -19.549578 | V10: =+U10-T10 -> -339.53518 | W10: =+IFERROR(HLOOKUP($B10,'[3]5월누계'!$F$6:$CC$57,16,),)/1000 -> 621.5745 | X10: =+U10-W10 -> -641.12408 | Y10: =+[9]김포!$Q$85 -> 95130.242 | Z10: =+[9]김포!$R$85 -> 95383.145 | AA10: =+[10]김포!$Q$85 -> 99202.658 | AB10: =+[9]김포!$Q$89 -> 76478.377 | AC10: =+[9]김포!$R$89 -> 78207.019 | AD10: =+[10]김포!$Q$89 -> 76358.732 | AE10: =+Y10-AB10 -> 18651.866 | AF10: =+Z10-AC10 -> 17176.126 | AG10: =+AA10-AD10 -> 22843.926
B11: 부산 | G11: =+I11 -> 부산 | I11: 부산 | J11: =+IFERROR(HLOOKUP($B11,'[1]5월누계'!$D$6:$BN$259,2,),)/1000 -> 99 | K11: =+IFERROR(HLOOKUP($B11,'[2]5월누계'!$F$6:$CP$99,2,),)/1000 -> 95.626 | L11: =+K11-J11 -> -3.374 | M11: =+IFERROR(HLOOKUP($B11,'[3]5월누계'!$F$6:$CC$57,2,),)/1000 -> 113.1435 | N11: =+K11-M11 -> -17.5175 | O11: =+IFERROR(HLOOKUP($B11,'[1]5월누계'!$D$6:$BN$259,3,),)/1000 -> 10662.291 | P11: =+IFERROR(HLOOKUP($B11,'[2]5월누계'!$F$6:$CP$99,3,),)/1000 -> 10214.984 | Q11: =+P11-O11 -> -447.30659 | R11: =+IFERROR(HLOOKUP($B11,'[3]5월누계'!$F$6:$CC$57,3,),)/1000 -> 12068.068 | S11: =+P11-R11 -> -1853.0835 | T11: =+IFERROR(HLOOKUP($B11,'[1]5월누계'!$D$6:$BN$259,16,),)/1000 -> 931.66845 | U11: =+IFERROR(HLOOKUP($B11,'[2]5월누계'!$F$6:$CP$99,16,),)/1000 -> 984.20983 | V11: =+U11-T11 -> 52.541386 | W11: =+IFERROR(HLOOKUP($B11,'[3]5월누계'!$F$6:$CC$57,16,),)/1000 -> 1401.8406 | X11: =+U11-W11 -> -417.63076 | Y11: =+[9]부산!$Q$85 -> 107699.91 | Z11: =+[9]부산!$R$85 -> 106822.25 | AA11: =+[10]부산!$Q$85 -> 106661.61 | AB11: =+[9]부산!$Q$89 -> 84759.179 | AC11: =+[9]부산!$R$89 -> 83688.464 | AD11: =+[10]부산!$Q$89 -> 83541.955 | AE11: =+Y11-AB11 -> 22940.727 | AF11: =+Z11-AC11 -> 23133.782 | AG11: =+AA11-AD11 -> 23119.653
B12: 서부산 | G12: =+I12 -> 서부산 | I12: 서부산 | J12: =+IFERROR(HLOOKUP($B12,'[1]5월누계'!$D$6:$BN$259,2,),)/1000 -> 97 | K12: =+IFERROR(HLOOKUP($B12,'[2]5월누계'!$F$6:$CP$99,2,),)/1000 -> 84.37 | L12: =+K12-J12 -> -12.63 | M12: =+IFERROR(HLOOKUP($B12,'[3]5월누계'!$F$6:$CC$57,2,),)/1000 -> 112.951 | N12: =+K12-M12 -> -28.581 | O12: =+IFERROR(HLOOKUP($B12,'[1]5월누계'!$D$6:$BN$259,3,),)/1000 -> 9632.115 | P12: =+IFERROR(HLOOKUP($B12,'[2]5월누계'!$F$6:$CP$99,3,),)/1000 -> 8159.07 | Q12: =+P12-O12 -> -1473.045 | R12: =+IFERROR(HLOOKUP($B12,'[3]5월누계'!$F$6:$CC$57,3,),)/1000 -> 11446.633 | S12: =+P12-R12 -> -3287.5633 | T12: =+IFERROR(HLOOKUP($B12,'[1]5월누계'!$D$6:$BN$259,16,),)/1000 -> 820.1561 | U12: =+IFERROR(HLOOKUP($B12,'[2]5월누계'!$F$6:$CP$99,16,),)/1000 -> 503.89407 | V12: =+U12-T12 -> -316.26203 | W12: =+IFERROR(HLOOKUP($B12,'[3]5월누계'!$F$6:$CC$57,16,),)/1000 -> 1382.269 | X12: =+U12-W12 -> -878.37497 | Y12: =+[9]서부산!$Q$85 -> 99300.155 | Z12: =+[9]서부산!$R$85 -> 96774.728 | AA12: =+[10]서부산!$Q$85 -> 101341.58 | AB12: =+[9]서부산!$Q$89 -> 78766.478 | AC12: =+[9]서부산!$R$89 -> 77306.216 | AD12: =+[10]서부산!$Q$89 -> 79342.203 | AE12: =+Y12-AB12 -> 20533.677 | AF12: =+Z12-AC12 -> 19468.513 | AG12: =+AA12-AD12 -> 21999.382
B13: 김해 | G13: =+I13 -> 김해 | I13: 김해 | J13: =+IFERROR(HLOOKUP($B13,'[1]5월누계'!$D$6:$BN$259,2,),)/1000 -> 67 | K13: =+IFERROR(HLOOKUP($B13,'[2]5월누계'!$F$6:$CP$99,2,),)/1000 -> 42.403 | L13: =+K13-J13 -> -24.597 | M13: =+IFERROR(HLOOKUP($B13,'[3]5월누계'!$F$6:$CC$57,2,),)/1000 -> 66.61 | N13: =+K13-M13 -> -24.207 | O13: =+IFERROR(HLOOKUP($B13,'[1]5월누계'!$D$6:$BN$259,3,),)/1000 -> 6452.0979 | P13: =+IFERROR(HLOOKUP($B13,'[2]5월누계'!$F$6:$CP$99,3,),)/1000 -> 3813.6947 | Q13: =+P13-O13 -> -2638.4032 | R13: =+IFERROR(HLOOKUP($B13,'[3]5월누계'!$F$6:$CC$57,3,),)/1000 -> 6529.6297 | S13: =+P13-R13 -> -2715.935 | T13: =+IFERROR(HLOOKUP($B13,'[1]5월누계'!$D$6:$BN$259,16,),)/1000 -> 540.4734 | U13: =+IFERROR(HLOOKUP($B13,'[2]5월누계'!$F$6:$CP$99,16,),)/1000 -> -176.44743 | V13: =+U13-T13 -> -716.92083 | W13: =+IFERROR(HLOOKUP($B13,'[3]5월누계'!$F$6:$CC$57,16,),)/1000 -> 485.29445 | X13: =+U13-W13 -> -661.74188 | Y13: =+[9]김해!$Q$85 -> 96299.969 | Z13: =+[9]김해!$R$85 -> 89944.965 | AA13: =+[10]김해!$Q$85 -> 98145.406 | AB13: =+[9]김해!$Q$89 -> 76510.612 | AC13: =+[9]김해!$R$89 -> 76862.834 | AD13: =+[10]김해!$Q$89 -> 79751.019 | AE13: =+Y13-AB13 -> 19789.358 | AF13: =+Z13-AC13 -> 13082.13 | AG13: =+AA13-AD13 -> 18394.387
B14: 정관 | G14: =+I14 -> 정관 | I14: 정관 | J14: =+IFERROR(HLOOKUP($B14,'[1]5월누계'!$D$6:$BN$259,2,),)/1000 -> 95 | K14: =+IFERROR(HLOOKUP($B14,'[2]5월누계'!$F$6:$CP$99,2,),)/1000 -> 101.41 | L14: =+K14-J14 -> 6.41 | M14: =+IFERROR(HLOOKUP($B14,'[3]5월누계'!$F$6:$CC$57,2,),)/1000 -> 102.7595 | N14: =+K14-M14 -> -1.3495 | O14: =+IFERROR(HLOOKUP($B14,'[1]5월누계'!$D$6:$BN$259,3,),)/1000 -> 9689.9758 | P14: =+IFERROR(HLOOKUP($B14,'[2]5월누계'!$F$6:$CP$99,3,),)/1000 -> 10216.992 | Q14: =+P14-O14 -> 527.01595 | R14: =+IFERROR(HLOOKUP($B14,'[3]5월누계'!$F$6:$CC$57,3,),)/1000 -> 10528.989 | S14: =+P14-R14 -> -311.99746 | T14: =+IFERROR(HLOOKUP($B14,'[1]5월누계'!$D$6:$BN$259,16,),)/1000 -> 794.47509 | U14: =+IFERROR(HLOOKUP($B14,'[2]5월누계'!$F$6:$CP$99,16,),)/1000 -> 848.94541 | V14: =+U14-T14 -> 54.470316 | W14: =+IFERROR(HLOOKUP($B14,'[3]5월누계'!$F$6:$CC$57,16,),)/1000 -> 1098.6997 | X14: =+U14-W14 -> -249.75428 | Y14: =+[9]정관!$Q$85 -> 101999.75 | Z14: =+[9]정관!$R$85 -> 100786.57 | AA14: =+[10]정관!$Q$85 -> 102462.44 | AB14: =+[9]정관!$Q$89 -> 82054.191 | AC14: =+[9]정관!$R$89 -> 82885.372 | AD14: =+[10]정관!$Q$89 -> 82233.768 | AE14: =+Y14-AB14 -> 19945.555 | AF14: =+Z14-AC14 -> 17901.195 | AG14: =+AA14-AD14 -> 20228.673
