Workbook

Sheet 표지
A6: 2025년 4월 마감 손익
A24: 건재사업본부

Sheet 손익총괄
C3: □ 건재사업본부 손익실적(2025-04)
X4: [단위 : 천㎥, 톤, 원/㎥, 원/톤, 백만원]
C5: 구분 | E5: 4월 | J5: 4월 누계 | P5: 4월 주요지표
A6: 2024년 12월 마감 손익 | E6: 계획 | F6: 실적 | G6: 계획대비 | H6: 전년 | I6: 전년대비 | J6: 계획 | K6: 실적 | L6: 계획대비 | M6: 전년 | N6: 전년대비
A7: =+F7/E7 -> 0.93689679 | B7: =+K7/J7 -> 0.92911571 | C7: 물량 | D7: 레미콘 | E7: =+'[1]4월'!$Z$7/1000 -> 295.5 | F7: =+'[2]4월'!$Z$7/1000 -> 276.853 | G7: =+F7-E7 -> -18.647 | H7: =+'[3]4월'!$Z$7/1000 -> 331.0375 | I7: =+F7-H7 -> -54.1845 | J7: =+'[1]4월누계'!$Z$7/1000 -> 1002.5 | K7: =+'[2]4월누계'!$Z$7/1000 -> 931.4385 | L7: =+K7-J7 -> -71.0615 | M7: =+'[3]4월누계'!$Z$7/1000 -> 1125.966 | N7: =+K7-M7 -> -194.5275 | Q7: □ 레미콘
D8: 철강재 | E8: =+'[1]4월'!$AA$7 -> 11100 | F8: =+'[2]4월'!$AO$7 -> 11123.665 | G8: =+F8-E8 -> 23.665 | H8: =+'[3]4월'!$AO$7 -> 8574.983 | I8: =+F8-H8 -> 2548.682 | J8: =+'[1]4월누계'!$AA$7 -> 41300 | K8: =+'[2]4월누계'!$AO$7 -> 45346.46 | L8: =+K8-J8 -> 4046.46 | M8: =+'[3]4월누계'!$AO$7 -> 30310.546 | N8: =+K8-M8 -> 15035.914 | Q8: 구분 | S8: 계획 | T8: 실적 | U8: 계획대비 | V8: 전년 | W8: 전년대비
D9: 골재 | E9: =+'[1]4월'!$AE$7/1000 -> 84.994573 | F9: =+'[2]4월'!$AN$7/1000 -> 68.025 | G9: =+F9-E9 -> -16.969573 | H9: =+'[3]4월'!$AN$7/1000 -> 86.343 | I9: =+F9-H9 -> -18.318 | J9: =+'[1]4월누계'!$AE$7/1000 -> 328.46129 | K9: =+'[2]4월누계'!$AN$7/1000 -> 235.425 | L9: =+K9-J9 -> -93.036289 | M9: =+'[3]4월누계'!$AN$7/1000 -> 321.06 | N9: =+K9-M9 -> -85.635 | Q9: 물량 | R9: 수도권 | S9: =+[4]수도권!$T$5/1000 -> 110 | T9: =+[4]수도권!$U$5/1000 -> 99.752 | U9: =+T9-S9 -> -10.248 | V9: =+[5]수도권!$T$5/1000 -> 122.5135 | W9: =+T9-V9 -> -22.7615
C10: 매출 | D10: 레미콘 | E10: =+'[1]4월'!$Z$8/1000 -> 29678.682 | F10: =+'[2]4월'!$Z$8/1000 -> 27262.254 | G10: =+F10-E10 -> -2416.4278 | H10: =+'[3]4월'!$Z$8/1000 -> 33733.44 | I10: =+F10-H10 -> -6471.1854 | J10: =+'[1]4월누계'!$Z$8/1000 -> 100714.16 | K10: =+'[2]4월누계'!$Z$8/1000 -> 92138.562 | L10: =+K10-J10 -> -8575.5937 | M10: =+'[3]4월누계'!$Z$8/1000 -> 114335.88 | N10: =+K10-M10 -> -22197.318 | R10: 영남권 | S10: =+[4]영남권!$T$5/1000 -> 128.5 | T10: =+[4]영남권!$U$5/1000 -> 119.871 | U10: =+T10-S10 -> -8.629 | V10: =+[5]영남권!$T$5/1000 -> 147.2215 | W10: =+T10-V10 -> -27.3505
D11: 건자재 | E11: =+'[1]4월'!$AA$8/1000 -> 12145.191 | F11: =+'[2]4월'!$AO$8/1000 -> 10147.504 | G11: =+F11-E11 -> -1997.6868 | H11: =+'[3]4월'!$AO$8/1000 -> 8822.0395 | I11: =+F11-H11 -> 1325.4647 | J11: =+'[1]4월누계'!$AA$8/1000 -> 45208.405 | K11: =+'[2]4월누계'!$AO$8/1000 -> 38439.848 | L11: =+K11-J11 -> -6768.5572 | M11: =+'[3]4월누계'!$AO$8/1000 -> 31755.572 | N11: =+K11-M11 -> 6684.2753 | R11: 중부권 | S11: =+[4]중부권!$T$5/1000 -> 57 | T11: =+[4]중부권!$U$5/1000 -> 57.23 | U11: =+T11-S11 -> 0.23 | V11: =+[5]중부권!$T$5/1000 -> 61.3025 | W11: =+T11-V11 -> -4.0725
D12: 골재 | E12: =+'[1]4월'!$AE$8/1000 -> 1722.1224 | F12: =+'[2]4월'!$AN$8/1000 -> 1449.066 | G12: =+F12-E12 -> -273.05639 | H12: =+'[3]4월'!$AN$8/1000 -> 1746.8204 | I12: =+F12-H12 -> -297.75441 | J12: =+'[1]4월누계'!$AE$8/1000 -> 6226.9411 | K12: =+'[2]4월누계'!$AN$8/1000 -> 5026.8145 | L12: =+K12-J12 -> -1200.1266 | M12: =+'[3]4월누계'!$AN$8/1000 -> 6528.4296 | N12: =+K12-M12 -> -1501.6151 | Q12: 계 | S12: =SUM(S9:S11) -> 295.5 | T12: =SUM(T9:T11) -> 276.853 | U12: =+T12-S12 -> -18.647 | V12: =SUM(V9:V11) -> 331.0375 | W12: =+T12-V12 -> -54.1845
D13: 기타 | E13: =+'[1]4월'!$E$8/1000-E10-E11-E12 -> 142.52817 | F13: =+'[2]4월'!$F$8/1000-F10-F11-F12 -> 118.48886 | G13: =+F13-E13 -> -24.039303 | H13: =+'[3]4월'!$F$8/1000-H10-H11-H12 -> 165.79909 | I13: =+F13-H13 -> -47.31023 | J13: =+'[1]4월누계'!$E$8/1000-J10-J11-J12 -> 642.63267 | K13: =+'[2]4월누계'!$F$8/1000-K10-K11-K12 -> 591.32316 | L13: =+K13-J13 -> -51.309509 | M13: =+'[3]4월누계'!$F$8/1000-M10-M11-M12 -> 659.35363 | N13: =+K13-M13 -> -68.030474 | Q13: 판매단가 | R13: 수도권 | S13: =+[4]수도권!$T$61 -> 97316.07 | T13: =+[4]수도권!$U$61 -> 96454.113 | U13: =+T13-S13 -> -861.95694 | V13: =+[5]수도권!$Q$85 -> 99830.046 | W13: =+T13-V13 -> -3375.9322
A14: =+F14/E14 -> 0.89216366 | B14: =+K14/J14 -> 0.89138455 | C14: 계 | E14: =SUM(E10:E13) -> 43688.524 | F14: =SUM(F10:F13) -> 38977.313 | G14: =+F14-E14 -> -4711.2103 | H14: =SUM(H10:H13) -> 44468.099 | I14: =+F14-H14 -> -5490.7853 | J14: =SUM(J10:J13) -> 152792.13 | K14: =SUM(K10:K13) -> 136196.55 | L14: =+K14-J14 -> -16595.587 | M14: =SUM(M10:M13) -> 153279.24 | N14: =+K14-M14 -> -17082.689 | R14: 영남권 | S14: =+[4]영남권!$T$61 -> 100478.01 | T14: =+[4]영남권!$U$61 -> 98385.129 | U14: =+T14-S14 -> -2092.8788 | V14: =+[5]영남권!$Q$85 -> 101618.83 | W14: =+T14-V14 -> -3233.7061
C15: 매출원가 | D15: 레미콘 | E15: =+('[1]4월'!$Z$10+'[1]4월'!$Z$19)/1000 -> 25988.679 | F15: =+('[2]4월'!$Z$10+'[2]4월'!$Z$19)/1000 -> 24425.138 | G15: =+F15-E15 -> -1563.5409 | H15: =+('[3]4월'!$Z$10+'[3]4월'!$Z$19)/1000 -> 28415.357 | I15: =+F15-H15 -> -3990.2195 | J15: =+('[1]4월누계'!$Z$10+'[1]4월누계'!$Z$19)/1000 -> 90655.877 | K15: =+('[2]4월누계'!$Z$10+'[2]4월누계'!$Z$19)/1000 -> 84643.214 | L15: =+K15-J15 -> -6012.6631 | M15: =+('[3]4월누계'!$Z$10+'[3]4월누계'!$Z$19)/1000 -> 99332.256 | N15: =+K15-M15 -> -14689.042 | R15: 중부권 | S15: =+[4]중부권!$T$61 -> 106359.48 | T15: =+[4]중부권!$U$61 -> 102148.63 | U15: =+T15-S15 -> -4210.8499 | V15: =+[5]중부권!$Q$85 -> 106728.9 | W15: =+T15-V15 -> -4580.2728
D16: 건자재 | E16: =+('[1]4월'!$AA$10+'[1]4월'!$AA$19)/1000 -> 11817.137 | F16: =+('[2]4월'!$AO$10+'[2]4월'!$AO$19)/1000 -> 9979.7604 | G16: =+F16-E16 -> -1837.3765 | H16: =+('[3]4월'!$AO$10+'[3]4월'!$AO$19)/1000 -> 8659.0858 | I16: =+F16-H16 -> 1320.6746 | J16: =+('[1]4월누계'!$AA$10+'[1]4월누계'!$AA$19)/1000 -> 43987.257 | K16: =+('[2]4월누계'!$AO$10+'[2]4월누계'!$AO$19)/1000 -> 37939.688 | L16: =+K16-J16 -> -6047.569 | M16: =+('[3]4월누계'!$AO$10+'[3]4월누계'!$AO$19)/1000 -> 31058.81 | N16: =+K16-M16 -> 6880.8775 | Q16: 계 | S16: =+[4]합계!$T$61 -> 100435.47 | T16: =+[4]합계!$U$61 -> 98470.346 | U16: =+T16-S16 -> -1965.126 | V16: =+[5]합계!$Q$85 -> 101892.73 | W16: =+T16-V16 -> -3422.3869
D17: 골재 | E17: =+('[1]4월'!$AE$10+'[1]4월'!$AE$19)/1000 -> 1401.3031 | F17: =+('[2]4월'!$AN$10+'[2]4월'!$AN$19)/1000 -> 1346.1014 | G17: =+F17-E17 -> -55.201637 | H17: =+('[3]4월'!$AN$10+'[3]4월'!$AN$19)/1000 -> 1547.4416 | I17: =+F17-H17 -> -201.34016 | J17: =+('[1]4월누계'!$AE$10+'[1]4월누계'!$AE$19)/1000 -> 5401.0458 | K17: =+('[2]4월누계'!$AN$10+'[2]4월누계'!$AN$19)/1000 -> 5287.1679 | L17: =+K17-J17 -> -113.87784 | M17: =+('[3]4월누계'!$AN$10+'[3]4월누계'!$AN$19)/1000 -> 5776.7521 | N17: =+K17-M17 -> -489.58414 | Q17: 공헌이익 | R17: 수도권 | S17: =+[4]수도권!$Q$90 -> 16623.918 | T17: =+[4]수도권!$R$90 -> 16372.588 | U17: =+T17-S17 -> -251.33 | V17: =+[5]수도권!$Q$90 -> 19731.47 | W17: =+T17-V17 -> -3358.8819
D18: 기타 | E18: =+('[1]4월'!$E$10+'[1]4월'!$E$19)/1000-E15-E16-E17 -> 68.281599 | F18: =+('[2]4월'!$F$10+'[2]4월'!$F$19)/1000-F15-F16-F17 -> 22.623855 | G18: =+F18-E18 -> -45.657744 | H18: =+('[3]4월'!$F$10+'[3]4월'!$F$19)/1000-H15-H16-H17 -> 28.446048 | I18: =+F18-H18 -> -5.822193 | J18: =+('[1]4월누계'!$E$10+'[1]4월누계'!$E$19)/1000-J15-J16-J17 -> 177.6645 | K18: =+('[2]4월누계'!$F$10+'[2]4월누계'!$F$19)/1000-K15-K16-K17 -> 404.22394 | L18: =+K18-J18 -> 226.55945 | M18: =+('[3]4월누계'!$F$10+'[3]4월누계'!$F$19)/1000-M15-M16-M17 -> 99.923078 | N18: =+K18-M18 -> 304.30087 | R18: 영남권 | S18: =+[4]영남권!$Q$90 -> 21632.131 | T18: =+[4]영남권!$R$90 -> 19312.771 | U18: =+T18-S18 -> -2319.3605 | V18: =+[5]영남권!$Q$90 -> 23376.451 | W18: =+T18-V18 -> -4063.6801
C19: 계 | E19: =SUM(E15:E18) -> 39275.4 | F19: =SUM(F15:F18) -> 35773.623 | G19: =+F19-E19 -> -3501.7768 | H19: =SUM(H15:H18) -> 38650.331 | I19: =+F19-H19 -> -2876.7073 | J19: =SUM(J15:J18) -> 140221.84 | K19: =SUM(K15:K18) -> 128274.29 | L19: =+K19-J19 -> -11947.551 | M19: =SUM(M15:M18) -> 136267.74 | N19: =+K19-M19 -> -7993.4483 | R19: 중부권 | S19: =+[4]중부권!$Q$90 -> 28532.277 | T19: =+[4]중부권!$R$90 -> 24648.008 | U19: =+T19-S19 -> -3884.269 | V19: =+[5]중부권!$Q$90 -> 31984.708 | W19: =+T19-V19 -> -7336.7006
C20: 매출이익 | D20: 레미콘 | E20: =+E10-E15 -> 3690.0035 | F20: =+F10-F15 -> 2837.1165 | G20: =+F20-E20 -> -852.88693 | H20: =+H10-H15 -> 5318.0824 | I20: =+F20-H20 -> -2480.9659 | J20: =+J10-J15 -> 10058.279 | K20: =+K10-K15 -> 7495.3481 | L20: =+K20-J20 -> -2562.9306 | M20: =+M10-M15 -> 15003.624 | N20: =+K20-M20 -> -7508.2759 | Q20: 계 | S20: =+[4]합계!$Q$90 -> 21098.815 | T20: =+[4]합계!$R$90 -> 19361.122 | U20: =+T20-S20 -> -1737.693 | V20: =+[5]합계!$Q$90 -> 23604.168 | W20: =+T20-V20 -> -4243.0462
D21: 건자재 | E21: =+E11-E16 -> 328.05416 | F21: =+F11-F16 -> 167.74386 | G21: =+F21-E21 -> -160.3103 | H21: =+H11-H16 -> 162.9537 | I21: =+F21-H21 -> 4.790155 | J21: =+J11-J16 -> 1221.1481 | K21: =+K11-K16 -> 500.15996 | L21: =+K21-J21 -> -720.98816 | M21: =+M11-M16 -> 696.76215 | N21: =+K21-M21 -> -196.60219 | Q21: □ 건자재
D22: 골재 | E22: =+E12-E17 -> 320.81933 | F22: =+F12-F17 -> 102.96457 | G22: =+F22-E22 -> -217.85476 | H22: =+H12-H17 -> 199.37882 | I22: =+F22-H22 -> -96.414246 | J22: =+J12-J17 -> 825.89534 | K22: =+K12-K17 -> -260.35342 | L22: =+K22-J22 -> -1086.2488 | M22: =+M12-M17 -> 751.67753 | N22: =+K22-M22 -> -1012.0309 | Q22: 구분 | S22: 계획 | T22: 실적 | U22: 계획대비 | V22: 전년 | W22: 전년대비
D23: 기타 | E23: =+E13-E18 -> 74.246568 | F23: =+F13-F18 -> 95.865009 | G23: =+F23-E23 -> 21.618441 | H23: =+H13-H18 -> 137.35305 | I23: =+F23-H23 -> -41.488037 | J23: =+J13-J18 -> 464.96817 | K23: =+K13-K18 -> 187.09921 | L23: =+K23-J23 -> -277.86896 | M23: =+M13-M18 -> 559.43055 | N23: =+K23-M23 -> -372.33134 | Q23: 철강재 판매단가 | S23: =+'[6]4월'!$F$10 -> 872522.52 | T23: =+'[6]4월'!$G$10 -> 800210.93 | U23: =+T23-S23 -> -72311.59 | V23: =+'[6]4월'!$G$10 -> 800210.93 | W23: =+T23-V23 -> 0
C24: 계 | E24: =SUM(E20:E23) -> 4413.1235 | F24: =SUM(F20:F23) -> 3203.69 | G24: =+F24-E24 -> -1209.4336 | H24: =SUM(H20:H23) -> 5817.768 | I24: =+F24-H24 -> -2614.078 | J24: =SUM(J20:J23) -> 12570.29 | K24: =SUM(K20:K23) -> 7922.2539 | L24: =+K24-J24 -> -4648.0364 | M24: =SUM(M20:M23) -> 17011.494 | N24: =+K24-M24 -> -9089.2404 | Q24: 철강재 마진률 | S24: =+'[6]4월'!$F$15 -> 0.02397651 | T24: =+'[6]4월'!$G$15 -> 0.014249312 | U24: =+T24-S24 -> -0.0097271979 | V24: =+'[6]4월'!$G$15 -> 0.014249312 | W24: =+T24-V24 -> 0
C25: 판관비 | D25: 레미콘 | E25: =+('[1]4월'!$Z$13+'[1]4월'!$Z$20)/1000 -> 658.80674 | F25: =+('[2]4월'!$Z$13+'[2]4월'!$Z$20)/1000 -> 671.44764 | G25: =+F25-E25 -> 12.640902 | H25: =+('[3]4월'!$Z$13+'[3]4월'!$Z$20)/1000 -> 682.83624 | I25: =+F25-H25 -> -11.388596 | J25: =+('[1]4월누계'!$Z$13+'[1]4월누계'!$Z$20)/1000 -> 2703.2671 | K25: =+('[2]4월누계'!$Z$13+'[2]4월누계'!$Z$20)/1000 -> 2671.6816 | L25: =+K25-J25 -> -31.585456 | M25: =+('[3]4월누계'!$Z$13+'[3]4월누계'!$Z$20)/1000 -> 2654.9903 | N25: =+K25-M25 -> 16.691319 | Q25: □ 골재
D26: 건자재 | E26: =+('[1]4월'!$AA$13+'[1]4월'!$AA$20)/1000 -> 122.86235 | F26: =+('[2]4월'!$AO$13+'[2]4월'!$AO$20)/1000 -> 168.0154 | G26: =+F26-E26 -> 45.153057 | H26: =+('[3]4월'!$AO$13+'[3]4월'!$AO$20)/1000 -> 169.13637 | I26: =+F26-H26 -> -1.120967 | J26: =+('[1]4월누계'!$AA$13+'[1]4월누계'!$AA$20)/1000 -> 512.07927 | K26: =+('[2]4월누계'!$AO$13+'[2]4월누계'!$AO$20)/1000 -> 606.74289 | L26: =+K26-J26 -> 94.663618 | M26: =+('[3]4월누계'!$AO$13+'[3]4월누계'!$AO$20)/1000 -> 554.17758 | N26: =+K26-M26 -> 52.565311 | Q26: 구분 | S26: 계획 | T26: 실적 | U26: 계획대비 | V26: 전년 | W26: 전년대비
D27: 골재 | E27: =+('[1]4월'!$AE$13+'[1]4월'!$AE$20+'[1]4월'!$AE$22)/1000 -> 46.61091 | F27: =+('[2]4월'!$AN$13+'[2]4월'!$AN$20+'[2]4월'!$AN$22)/1000 -> 45.658013 | G27: =+F27-E27 -> -0.95289703 | H27: =+('[3]4월'!$AN$13+'[3]4월'!$AN$20+'[3]4월'!$AN$22)/1000 -> 45.501372 | I27: =+F27-H27 -> 0.15664074 | J27: =+('[1]4월누계'!$AE$13+'[1]4월누계'!$AE$20+'[1]4월누계'!$AE$22)/1000 -> 190.45869 | K27: =+('[2]4월누계'!$AN$13+'[2]4월누계'!$AN$20+'[2]4월누계'!$AN$22)/1000 -> 187.38509 | L27: =+K27-J27 -> -3.0736014 | M27: =+('[3]4월누계'!$AN$13+'[3]4월누계'!$AN$20+'[3]4월누계'!$AN$22)/1000 -> 178.67939 | N27: =+K27-M27 -> 8.7056996 | Q27: 판매량 | R27: 자가 | S27: =(+'[7]서부산크라샤(당월)'!$Z$66+'[7]부산모래장(당월)'!$Q$48+'[7]부산크라샤(당월)'!$T$66)/1000 -> 53.994473 | T27: =(+'[7]서부산크라샤(당월)'!$AA$66+'[7]부산모래장(당월)'!$R$48+'[7]부산크라샤(당월)'!$U$66)/1000 -> 29.139 | U27: =+T27-S27 -> -24.855473 | V27: =+[8]손익총괄!$V$27 -> 32.34 | W27: =+T27-V27 -> -3.201
D28: 기타 | E28: =+('[1]4월'!$E$13+'[1]4월'!$E$20)/1000-E25-E26-E27+('[1]4월'!$E$22/1000) -> 1750.4842 | F28: =+('[2]4월'!$F$13+'[2]4월'!$F$20)/1000-F25-F26-F27+'[2]4월'!$F$22/1000 -> 1711.0197 | G28: =+F28-E28 -> -39.464529 | H28: =+('[3]4월'!$F$13+'[3]4월'!$F$20)/1000-H25-H26-H27+'[3]4월'!$F$22/1000 -> 1617.9186 | I28: =+F28-H28 -> 93.101074 | J28: =+('[1]4월누계'!$E$13+'[1]4월누계'!$E$20)/1000-J25-J26-J27+('[1]4월누계'!$E$22/1000) -> 6281.7638 | K28: =+('[2]4월누계'!$F$13+'[2]4월누계'!$F$20)/1000-K25-K26-K27+'[2]4월누계'!$F$22/1000 -> 7058.2386 | L28: =+K28-J28 -> 776.47476 | M28: =+('[3]4월누계'!$F$13+'[3]4월누계'!$F$20)/1000-M25-M26-M27+'[3]4월누계'!$F$22/1000 -> 7170.2526 | N28: =+K28-M28 -> -112.01402 | R28: 외판 | S28: =(+'[7]서부산크라샤(당월)'!$Z$59+'[7]부산모래장(당월)'!$Q$47+'[7]부산크라샤(당월)'!$T$59)/1000 -> 31 | T28: =(+'[7]서부산크라샤(당월)'!$AA$59+'[7]부산모래장(당월)'!$R$47+'[7]부산크라샤(당월)'!$U$59)/1000 -> 23.326 | U28: =+T28-S28 -> -7.674 | V28: =+[8]손익총괄!$V$28 -> 25.899 | W28: =+T28-V28 -> -2.573
C29: 계 | E29: =SUM(E25:E28) -> 2578.7642 | F29: =SUM(F25:F28) -> 2596.1408 | G29: =+F29-E29 -> 17.376533 | H29: =SUM(H25:H28) -> 2515.3926 | I29: =+F29-H29 -> 80.748152 | J29: =SUM(J25:J28) -> 9687.5688 | K29: =SUM(K25:K28) -> 10524.048 | L29: =+K29-J29 -> 836.47932 | M29: =SUM(M25:M28) -> 10558.1 | N29: =+K29-M29 -> -34.051688 | Q29: 합 계 | S29: =SUM(S27:S28) -> 84.994473 | T29: =SUM(T27:T28) -> 52.465 | U29: =+T29-S29 -> -32.529473 | V29: =SUM(V27:V28) -> 58.239 | W29: =+T29-V29 -> -5.774
C30: 영업이익 | D30: 레미콘 | E30: =+E20-E25 -> 3031.1967 | F30: =+F20-F25 -> 2165.6689 | G30: =+F30-E30 -> -865.52784 | H30: =+H20-H25 -> 4635.2462 | I30: =+F30-H30 -> -2469.5773 | J30: =+J20-J25 -> 7355.0116 | K30: =+K20-K25 -> 4823.6665 | L30: =+K30-J30 -> -2531.3451 | M30: =+M20-M25 -> 12348.634 | N30: =+K30-M30 -> -7524.9672 | Q30: □ 기타내역(영업이익)
D31: % | E31: =+E30/E10 -> 0.1021338 | F31: =+F30/F10 -> 0.079438364 | G31: =+F31-E31 -> -0.02269544 | H31: =+H30/H10 -> 0.13740805 | I31: =+F31-H31 -> -0.057969686 | J31: =+J30/J10 -> 0.073028579 | K31: =+K30/K10 -> 0.05235231 | L31: =+K31-J31 -> -0.020676269 | M31: =+M30/M10 -> 0.10800314 | N31: =+K31-M31 -> -0.055650828 | Q31: 구분 | S31: 계획 | T31: 실적 | U31: 계획대비 | V31: 전년 | W31: 전년대비
D32: 건자재 | E32: =+E21-E26 -> 205.19181 | F32: =+F21-F26 -> -0.271546 | G32: =+F32-E32 -> -205.46336 | H32: =+H21-H26 -> -6.182668 | I32: =+F32-H32 -> 5.911122 | J32: =+J21-J26 -> 709.06885 | K32: =+K21-K26 -> -106.58293 | L32: =+K32-J32 -> -815.65178 | M32: =+M21-M26 -> 142.58457 | N32: =+K32-M32 -> -249.1675 | Q32: 레미콘임대 | S32: =+'사업장별(당월)'!T33 -> 48.349888 | T32: =+'사업장별(당월)'!U33 -> 23.021931 | U32: =+T32-S32 -> -25.327957 | V32: =+'사업장별(당월)'!W33 -> 71.958667 | W32: =+T32-V32 -> -48.936736
D33: 골재 | E33: =+E22-E27 -> 274.20842 | F33: =+F22-F27 -> 57.306559 | G33: =+F33-E33 -> -216.90186 | H33: =+H22-H27 -> 153.87745 | I33: =+F33-H33 -> -96.570887 | J33: =+J22-J27 -> 635.43665 | K33: =+K22-K27 -> -447.7385 | L33: =+K33-J33 -> -1083.1752 | M33: =+M22-M27 -> 572.99814 | N33: =+K33-M33 -> -1020.7366 | Q33: 임대 | S33: =+'사업장별(당월)'!T34 -> 63.964 | T33: =+'사업장별(당월)'!U34 -> 63.367074 | U33: =+T33-S33 -> -0.596926 | V33: =+'사업장별(당월)'!W34 -> 63.157758 | W33: =+T33-V33 -> 0.209316
D34: 기타 | E34: =+E23-E28 -> -1676.2377 | F34: =+F23-F28 -> -1615.1547 | G34: =+F34-E34 -> 61.08297 | H34: =+H23-H28 -> -1480.5656 | I34: =+F34-H34 -> -134.58911 | J34: =+J23-J28 -> -5816.7956 | K34: =+K23-K28 -> -6871.1393 | L34: =+K34-J34 -> -1054.3437 | M34: =+M23-M28 -> -6610.822 | N34: =+K34-M34 -> -260.31732 | Q34: 공통비 | S34: =+'사업장별(당월)'!T35 -> -1670.9087 | T34: =+'사업장별(당월)'!U35 -> -1654.8985 | U34: =+T34-S34 -> 16.010214 | V34: =+'사업장별(당월)'!W35 -> -1567.4228 | W34: =+T34-V34 -> -87.475651
C35: 계 | E35: =SUM(E30,E32:E34) -> 1834.3593 | F35: =SUM(F30,F32:F34) -> 607.54919 | G35: =+F35-E35 -> -1226.8101 | H35: =SUM(H30,H32:H34) -> 3302.3754 | I35: =+F35-H35 -> -2694.8262 | J35: =SUM(J30,J32:J34) -> 2882.7215 | K35: =SUM(K30,K32:K34) -> -2601.7943 | L35: =+K35-J35 -> -5484.5158 | M35: =SUM(M30,M32:M34) -> 6453.3944 | N35: =+K35-M35 -> -9055.1887 | Q35: 기타 | S35: =+S36-S32-S33-S34 -> -117.64287 | T35: =+T36-T32-T33-T34 -> -46.645232 | U35: =+T35-S35 -> 70.997639 | V35: =+V36-V32-V33-V34 -> -48.259192 | W35: =+T35-V35 -> 1.61396
D36: % | E36: =+E35/E14 -> 0.041987211 | F36: =+F35/F14 -> 0.015587252 | G36: =+F36-E36 -> -0.02639996 | H36: =+H35/H14 -> 0.074263921 | I36: =+F36-H36 -> -0.058676669 | J36: =+J35/J14 -> 0.01886695 | K36: =+K35/K14 -> -0.019103232 | L36: =+K36-J36 -> -0.037970182 | M36: =+M35/M14 -> 0.042102209 | N36: =+K36-M36 -> -0.061205441 | Q36: 합계 | S36: =+'사업장별(당월)'!T41 -> -1676.2377 | T36: =+'사업장별(당월)'!U41 -> -1615.1547 | U36: =+T36-S36 -> 61.08297 | V36: =+'사업장별(당월)'!W41 -> -1480.5656 | W36: =+T36-V36 -> -134.58911
E38: =+'[1]4월'!$E$26/1000 -> 1834.3593 | F38: =+'[2]4월'!$F$26/1000 -> 607.54919 | H38: =+'[3]4월'!$F$26/1000 -> 3302.3754 | J38: =+'[1]4월누계'!$E$26/1000 -> 2882.7215 | K38: =+'[2]4월누계'!$F$26/1000 -> -2601.7943 | M38: =+'[3]4월누계'!$F$26/1000 -> 6453.3944
E39: =+E35=E38 -> TRUE | F39: =+F35=F38 -> FALSE | H39: =+H35=H38 -> TRUE | J39: =+J35=J38 -> FALSE | K39: =+K35=K38 -> FALSE | M39: =+M35=M38 -> FALSE
E40: =+E35-E38 -> 0 | F40: =+F35-F38 -> 3.4106051e-12 | H40: =+H35-H38 -> 0 | J40: =+J35-J38 -> -9.5496944e-12 | K40: =+K35-K38 -> -6.3664629e-12 | M40: =+M35-M38 -> 2.1827873e-11

Sheet 사업장별(당월)
H3: □ 사업장별 손익실적(2025-04)
AG4: [단위 : 천㎥, 톤, 백만원]
H5: 구분 | J5: 물량 | O5: 매출 | T5: 영업이익(공통비 배부전) | Y5: 판매단가 | AB5: 변동비 | AE5: 공헌이익
A6: 2024년 4월 마감 손익 | J6: 계획 | K6: 실적 | L6: 차이 | M6: 전년 | N6: 차이 | O6: 계획 | P6: 실적 | Q6: 차이 | R6: 전년 | S6: 차이 | T6: 계획 | U6: 실적 | V6: 차이 | W6: 전년 | X6: 차이 | Y6: 계획 | Z6: 실적 | AA6: 전년 | AB6: 계획 | AC6: 실적 | AD6: 전년 | AE6: 계획 | AF6: 실적 | AG6: 전년
B7: 안양 | G7: =+I7 -> 안양 | H7: 레미콘 | I7: 안양 | J7: =+IFERROR(HLOOKUP($B7,'[1]4월'!$D$6:$BN$259,2,),)/1000 -> 42 | K7: =+IFERROR(HLOOKUP($B7,'[2]4월'!$F$6:$CP$99,2,),)/1000 -> 40.25 | L7: =+K7-J7 -> -1.75 | M7: =+IFERROR(HLOOKUP($B7,'[3]4월'!$F$6:$CC$57,2,),)/1000 -> 46.247 | N7: =+K7-M7 -> -5.997 | O7: =+IFERROR(HLOOKUP($B7,'[1]4월'!$D$6:$BN$259,3,),)/1000 -> 4118.15 | P7: =+IFERROR(HLOOKUP($B7,'[2]4월'!$F$6:$CP$99,3,),)/1000 -> 3841.7711 | Q7: =+P7-O7 -> -276.37893 | R7: =+IFERROR(HLOOKUP($B7,'[3]4월'!$F$6:$CC$57,3,),)/1000 -> 4615.8876 | S7: =+P7-R7 -> -774.11647 | T7: =+IFERROR(HLOOKUP($B7,'[1]4월'!$D$6:$BN$259,16,),)/1000 -> 413.70969 | U7: =+IFERROR(HLOOKUP($B7,'[2]4월'!$F$6:$CP$99,16,),)/1000 -> 321.01658 | V7: =+U7-T7 -> -92.693111 | W7: =+IFERROR(HLOOKUP($B7,'[3]4월'!$F$6:$CC$57,16,),)/1000 -> 589.76879 | X7: =+U7-W7 -> -268.75221 | Y7: =+[4]안양!$Q$85 -> 98051.191 | Z7: =+[4]안양!$R$85 -> 95439.9 | AA7: =+[5]안양!$Q$85 -> 99791.14 | AB7: =+[4]안양!$Q$89 -> 81257.915 | AC7: =+[4]안양!$R$89 -> 79659.206 | AD7: =+[5]안양!$Q$89 -> 80207.362 | AE7: =+Y7-AB7 -> 16793.277 | AF7: =+Z7-AC7 -> 15780.694 | AG7: =+AA7-AD7 -> 19583.777
B8: 인천 | G8: =+I8 -> 인천 | H8: 직영 | I8: 인천 | J8: =+IFERROR(HLOOKUP($B8,'[1]4월'!$D$6:$BN$259,2,),)/1000 -> 30 | K8: =+IFERROR(HLOOKUP($B8,'[2]4월'!$F$6:$CP$99,2,),)/1000 -> 33.57 | L8: =+K8-J8 -> 3.57 | M8: =+IFERROR(HLOOKUP($B8,'[3]4월'!$F$6:$CC$57,2,),)/1000 -> 30.095 | N8: =+K8-M8 -> 3.475 | O8: =+IFERROR(HLOOKUP($B8,'[1]4월'!$D$6:$BN$259,3,),)/1000 -> 2954.0596 | P8: =+IFERROR(HLOOKUP($B8,'[2]4월'!$F$6:$CP$99,3,),)/1000 -> 3322.1847 | Q8: =+P8-O8 -> 368.12512 | R8: =+IFERROR(HLOOKUP($B8,'[3]4월'!$F$6:$CC$57,3,),)/1000 -> 3074.4291 | S8: =+P8-R8 -> 247.75559 | T8: =+IFERROR(HLOOKUP($B8,'[1]4월'!$D$6:$BN$259,16,),)/1000 -> 185.05259 | U8: =+IFERROR(HLOOKUP($B8,'[2]4월'!$F$6:$CP$99,16,),)/1000 -> 222.53657 | V8: =+U8-T8 -> 37.483983 | W8: =+IFERROR(HLOOKUP($B8,'[3]4월'!$F$6:$CC$57,16,),)/1000 -> 331.00999 | X8: =+U8-W8 -> -108.47342 | Y8: =+[4]인천!$Q$85 -> 98468.654 | Z8: =+[4]인천!$R$85 -> 98978.103 | AA8: =+[5]인천!$Q$85 -> 102157.47 | AB8: =+[4]인천!$Q$89 -> 82591.236 | AC8: =+[4]인천!$R$89 -> 82750.98 | AD8: =+[5]인천!$Q$89 -> 81515.983 | AE8: =+Y8-AB8 -> 15877.418 | AF8: =+Z8-AC8 -> 16227.123 | AG8: =+AA8-AD8 -> 20641.489
B9: 파주 | G9: =+I9 -> 파주 | I9: 파주 | J9: =+IFERROR(HLOOKUP($B9,'[1]4월'!$D$6:$BN$259,2,),)/1000 -> 22 | K9: =+IFERROR(HLOOKUP($B9,'[2]4월'!$F$6:$CP$99,2,),)/1000 -> 13.605 | L9: =+K9-J9 -> -8.395 | M9: =+IFERROR(HLOOKUP($B9,'[3]4월'!$F$6:$CC$57,2,),)/1000 -> 28.573 | N9: =+K9-M9 -> -14.968 | O9: =+IFERROR(HLOOKUP($B9,'[1]4월'!$D$6:$BN$259,3,),)/1000 -> 2112.8558 | P9: =+IFERROR(HLOOKUP($B9,'[2]4월'!$F$6:$CP$99,3,),)/1000 -> 1269.8888 | Q9: =+P9-O9 -> -842.96696 | R9: =+IFERROR(HLOOKUP($B9,'[3]4월'!$F$6:$CC$57,3,),)/1000 -> 2775.4874 | S9: =+P9-R9 -> -1505.5986 | T9: =+IFERROR(HLOOKUP($B9,'[1]4월'!$D$6:$BN$259,16,),)/1000 -> 121.37226 | U9: =+IFERROR(HLOOKUP($B9,'[2]4월'!$F$6:$CP$99,16,),)/1000 -> -15.154132 | V9: =+U9-T9 -> -136.52639 | W9: =+IFERROR(HLOOKUP($B9,'[3]4월'!$F$6:$CC$57,16,),)/1000 -> 232.72628 | X9: =+U9-W9 -> -247.88042 | Y9: =+[4]파주!$Q$85 -> 96038.898 | Z9: =+[4]파주!$R$85 -> 93525.185 | AA9: =+[5]파주!$Q$85 -> 97212.84 | AB9: =+[4]파주!$Q$89 -> 79787.253 | AC9: =+[4]파주!$R$89 -> 78035.926 | AD9: =+[5]파주!$Q$89 -> 81147.556 | AE9: =+Y9-AB9 -> 16251.646 | AF9: =+Z9-AC9 -> 15489.259 | AG9: =+AA9-AD9 -> 16065.284
B10: 김포 | G10: =+I10 -> 김포 | I10: 김포 | J10: =+IFERROR(HLOOKUP($B10,'[1]4월'!$D$6:$BN$259,2,),)/1000 -> 16 | K10: =+IFERROR(HLOOKUP($B10,'[2]4월'!$F$6:$CP$99,2,),)/1000 -> 12.327 | L10: =+K10-J10 -> -3.673 | M10: =+IFERROR(HLOOKUP($B10,'[3]4월'!$F$6:$CC$57,2,),)/1000 -> 17.5985 | N10: =+K10-M10 -> -5.2715 | O10: =+IFERROR(HLOOKUP($B10,'[1]4월'!$D$6:$BN$259,3,),)/1000 -> 1519.7024 | P10: =+IFERROR(HLOOKUP($B10,'[2]4월'!$F$6:$CP$99,3,),)/1000 -> 1182.47 | Q10: =+P10-O10 -> -337.23239 | R10: =+IFERROR(HLOOKUP($B10,'[3]4월'!$F$6:$CC$57,3,),)/1000 -> 1762.1677 | S10: =+P10-R10 -> -579.69775 | T10: =+IFERROR(HLOOKUP($B10,'[1]4월'!$D$6:$BN$259,16,),)/1000 -> 109.18153 | U10: =+IFERROR(HLOOKUP($B10,'[2]4월'!$F$6:$CP$99,16,),)/1000 -> 64.83259 | V10: =+U10-T10 -> -44.348936 | W10: =+IFERROR(HLOOKUP($B10,'[3]4월'!$F$6:$CC$57,16,),)/1000 -> 272.51274 | X10: =+U10-W10 -> -207.68015 | Y10: =+[4]김포!$Q$85 -> 94981.397 | Z10: =+[4]김포!$R$85 -> 96085.257 | AA10: =+[5]김포!$Q$85 -> 100131.7 | AB10: =+[4]김포!$Q$89 -> 76890.48 | AC10: =+[4]김포!$R$89 -> 76364.794 | AD10: =+[5]김포!$Q$89 -> 75716.071 | AE10: =+Y10-AB10 -> 18090.917 | AF10: =+Z10-AC10 -> 19720.464 | AG10: =+AA10-AD10 -> 24415.629
B11: 부산 | G11: =+I11 -> 부산 | I11: 부산 | J11: =+IFERROR(HLOOKUP($B11,'[1]4월'!$D$6:$BN$259,2,),)/1000 -> 21 | K11: =+IFERROR(HLOOKUP($B11,'[2]4월'!$F$6:$CP$99,2,),)/1000 -> 20.499 | L11: =+K11-J11 -> -0.501 | M11: =+IFERROR(HLOOKUP($B11,'[3]4월'!$F$6:$CC$57,2,),)/1000 -> 22.909 | N11: =+K11-M11 -> -2.41 | O11: =+IFERROR(HLOOKUP($B11,'[1]4월'!$D$6:$BN$259,3,),)/1000 -> 2261.6911 | P11: =+IFERROR(HLOOKUP($B11,'[2]4월'!$F$6:$CP$99,3,),)/1000 -> 2136.8245 | Q11: =+P11-O11 -> -124.86659 | R11: =+IFERROR(HLOOKUP($B11,'[3]4월'!$F$6:$CC$57,3,),)/1000 -> 2386.548 | S11: =+P11-R11 -> -249.72353 | T11: =+IFERROR(HLOOKUP($B11,'[1]4월'!$D$6:$BN$259,16,),)/1000 -> 236.95571 | U11: =+IFERROR(HLOOKUP($B11,'[2]4월'!$F$6:$CP$99,16,),)/1000 -> 112.51179 | V11: =+U11-T11 -> -124.44392 | W11: =+IFERROR(HLOOKUP($B11,'[3]4월'!$F$6:$CC$57,16,),)/1000 -> 252.58252 | X11: =+U11-W11 -> -140.07073 | Y11: =+[4]부산!$Q$85 -> 107699.58 | Z11: =+[4]부산!$R$85 -> 104240.43 | AA11: =+[5]부산!$Q$85 -> 104175.13 | AB11: =+[4]부산!$Q$89 -> 84183.56 | AC11: =+[4]부산!$R$89 -> 86169.896 | AD11: =+[5]부산!$Q$89 -> 81975.794 | AE11: =+Y11-AB11 -> 23516.016 | AF11: =+Z11-AC11 -> 18070.53 | AG11: =+AA11-AD11 -> 22199.335
B12: 서부산 | G12: =+I12 -> 서부산 | I12: 서부산 | J12: =+IFERROR(HLOOKUP($B12,'[1]4월'!$D$6:$BN$259,2,),)/1000 -> 22 | K12: =+IFERROR(HLOOKUP($B12,'[2]4월'!$F$6:$CP$99,2,),)/1000 -> 19.392 | L12: =+K12-J12 -> -2.608 | M12: =+IFERROR(HLOOKUP($B12,'[3]4월'!$F$6:$CC$57,2,),)/1000 -> 25.12 | N12: =+K12-M12 -> -5.728 | O12: =+IFERROR(HLOOKUP($B12,'[1]4월'!$D$6:$BN$259,3,),)/1000 -> 2184.6009 | P12: =+IFERROR(HLOOKUP($B12,'[2]4월'!$F$6:$CP$99,3,),)/1000 -> 1895.2186 | Q12: =+P12-O12 -> -289.38235 | R12: =+IFERROR(HLOOKUP($B12,'[3]4월'!$F$6:$CC$57,3,),)/1000 -> 2565.4978 | S12: =+P12-R12 -> -670.2792 | T12: =+IFERROR(HLOOKUP($B12,'[1]4월'!$D$6:$BN$259,16,),)/1000 -> 210.32021 | U12: =+IFERROR(HLOOKUP($B12,'[2]4월'!$F$6:$CP$99,16,),)/1000 -> 155.86617 | V12: =+U12-T12 -> -54.45404 | W12: =+IFERROR(HLOOKUP($B12,'[3]4월'!$F$6:$CC$57,16,),)/1000 -> 358.97475 | X12: =+U12-W12 -> -203.10859 | Y12: =+[4]서부산!$Q$85 -> 99300.043 | Z12: =+[4]서부산!$R$85 -> 97731.982 | AA12: =+[5]서부산!$Q$85 -> 102129.69 | AB12: =+[4]서부산!$Q$89 -> 78928.445 | AC12: =+[4]서부산!$R$89 -> 77327.458 | AD12: =+[5]서부산!$Q$89 -> 78340.861 | AE12: =+Y12-AB12 -> 20371.598 | AF12: =+Z12-AC12 -> 20404.524 | AG12: =+AA12-AD12 -> 23788.829
B13: 김해 | G13: =+I13 -> 김해 | I13: 김해 | J13: =+IFERROR(HLOOKUP($B13,'[1]4월'!$D$6:$BN$259,2,),)/1000 -> 15 | K13: =+IFERROR(HLOOKUP($B13,'[2]4월'!$F$6:$CP$99,2,),)/1000 -> 11.975 | L13: =+K13-J13 -> -3.025 | M13: =+IFERROR(HLOOKUP($B13,'[3]4월'!$F$6:$CC$57,2,),)/1000 -> 17.236 | N13: =+K13-M13 -> -5.261 | O13: =+IFERROR(HLOOKUP($B13,'[1]4월'!$D$6:$BN$259,3,),)/1000 -> 1444.4978 | P13: =+IFERROR(HLOOKUP($B13,'[2]4월'!$F$6:$CP$99,3,),)/1000 -> 1030.4699 | Q13: =+P13-O13 -> -414.0279 | R13: =+IFERROR(HLOOKUP($B13,'[3]4월'!$F$6:$CC$57,3,),)/1000 -> 1721.9678 | S13: =+P13-R13 -> -691.4979 | T13: =+IFERROR(HLOOKUP($B13,'[1]4월'!$D$6:$BN$259,16,),)/1000 -> 150.40606 | U13: =+IFERROR(HLOOKUP($B13,'[2]4월'!$F$6:$CP$99,16,),)/1000 -> -22.904841 | V13: =+U13-T13 -> -173.3109 | W13: =+IFERROR(HLOOKUP($B13,'[3]4월'!$F$6:$CC$57,16,),)/1000 -> 209.1524 | X13: =+U13-W13 -> -232.05724 | Y13: =+[4]김해!$Q$85 -> 96299.853 | Z13: =+[4]김해!$R$85 -> 86017.766 | AA13: =+[5]김해!$Q$85 -> 99943.842 | AB13: =+[4]김해!$Q$89 -> 75958.305 | AC13: =+[4]김해!$R$89 -> 75417.831 | AD13: =+[5]김해!$Q$89 -> 79096.377 | AE13: =+Y13-AB13 -> 20341.548 | AF13: =+Z13-AC13 -> 10599.936 | AG13: =+AA13-AD13 -> 20847.465
B14: 정관 | G14: =+I14 -> 정관 | I14: 정관 | J14: =+IFERROR(HLOOKUP($B14,'[1]4월'!$D$6:$BN$259,2,),)/1000 -> 20 | K14: =+IFERROR(HLOOKUP($B14,'[2]4월'!$F$6:$CP$99,2,),)/1000 -> 23.6285 | L14: =+K14-J14 -> 3.6285 | M14: =+IFERROR(HLOOKUP($B14,'[3]4월'!$F$6:$CC$57,2,),)/1000 -> 21.272 | N14: =+K14-M14 -> 2.3565 | O14: =+IFERROR(HLOOKUP($B14,'[1]4월'!$D$6:$BN$259,3,),)/1000 -> 2039.9953 | P14: =+IFERROR(HLOOKUP($B14,'[2]4월'!$F$6:$CP$99,3,),)/1000 -> 2450.8407 | Q14: =+P14-O14 -> 410.84542 | R14: =+IFERROR(HLOOKUP($B14,'[3]4월'!$F$6:$CC$57,3,),)/1000 -> 2214.5889 | S14: =+P14-R14 -> 236.2518 | T14: =+IFERROR(HLOOKUP($B14,'[1]4월'!$D$6:$BN$259,16,),)/1000 -> 180.25227 | U14: =+IFERROR(HLOOKUP($B14,'[2]4월'!$F$6:$CP$99,16,),)/1000 -> 280.09121 | V14: =+U14-T14 -> 99.838939 | W14: =+IFERROR(HLOOKUP($B14,'[3]4월'!$F$6:$CC$57,16,),)/1000 -> 247.37615 | X14: =+U14-W14 -> 32.715061 | Y14: =+[4]정관!$Q$85 -> 101999.76 | Z14: =+[4]정관!$R$85 -> 103723.92 | AA14: =+[5]정관!$Q$85 -> 104108.17 | AB14: =+[4]정관!$Q$89 -> 82026.06 | AC14: =+[4]정관!$R$89 -> 83859.793 | AD14: =+[5]정관!$Q$89 -> 82781.134 | AE14: =+Y14-AB14 -> 19973.704 | AF14: =+Z14-AC14 -> 19864.129 | AG14: =+AA14-AD14 -> 21327.032
B15: 양산 | G15: =+I15 -> 양산 | I15: 양산 | J15: =+IFERROR(HLOOKUP($B15,'[1]4월'!$D$6:$BN$259,2,),)/1000 -> 12 | K15: =+IFERROR(HLOOKUP($B15,'[2]4월'!$F$6:$CP$99,2,),)/1000 -> 6.277 | L15: =+K15-J15 -> -5.723 | M15: =+IFERROR(HLOOKUP($B15,'[3]4월'!$F$6:$CC$57,2,),)/1000 -> 12.804 | N15: =+K15-M15 -> -6.527 | O15: =+IFERROR(HLOOKUP($B15,'[1]4월'!$D$6:$BN$259,3,),)/1000 -> 1133.46 | P15: =+IFERROR(HLOOKUP($B15,'[2]4월'!$F$6:$CP$99,3,),)/1000 -> 579.56165 | Q15: =+P15-O15 -> -553.89835 | R15: =+IFERROR(HLOOKUP($B15,'[3]4월'!$F$6:$CC$57,3,),)/1000 -> 1198.3639 | S15: =+P15-R15 -> -618.8023 | T15: =+IFERROR(HLOOKUP($B15,'[1]4월'!$D$6:$BN$259,16,),)/1000 -> 107.58257 | U15: =+IFERROR(HLOOKUP($B15,'[2]4월'!$F$6:$CP$99,16,),)/1000 -> -26.417206 | V15: =+U15-T15 -> -133.99978 | W15: =+IFERROR(HLOOKUP($B15,'[3]4월'!$F$6:$CC$57,16,),)/1000 -> 114.7124 | X15: =+U15-W15 -> -141.1296 | Y15: =+[4]양산!$Q$85 -> 94455 | Z15: =+[4]양산!$R$85 -> 92330.994 | AA15: =+[5]양산!$Q$85 -> 93592.935 | AB15: =+[4]양산!$Q$89 -> 73683.516 | AC15: =+[4]양산!$R$89 -> 72880.116 | AD15: =+[5]양산!$Q$89 -> 73554.02 | AE15: =+Y15-AB15 -> 20771.484 | AF15: =+Z15-AC15 -> 19450.879 | AG15: =+AA15-AD15 -> 20038.915
B16: 창원 | G16: =+I16 -> 창원 | I16: 창원 | J16: =+IFERROR(HLOOKUP($B16,'[1]4월'!$D$6:$BN$259,2,),)/1000 -> 13 | K16: =+IFERROR(HLOOKUP($B16,'[2]4월'!$F$6:$CP$99,2,),)/1000 -> 12.462 | L16: =+K16-J16 -> -0.538 | M16: =+IFERROR(HLOOKUP($B16,'[3]4월'!$F$6:$CC$57,2,),)/1000 -> 19.1115 | N16: =+K16-M16 -> -6.6495 | O16: =+IFERROR(HLOOKUP($B16,'[1]4월'!$D$6:$BN$259,3,),)/1000 -> 1300.0008 | P16: =+IFERROR(HLOOKUP($B16,'[2]4월'!$F$6:$CP$99,3,),)/1000 -> 1202.3307 | Q16: =+P16-O16 -> -97.670077 | R16: =+IFERROR(HLOOKUP($B16,'[3]4월'!$F$6:$CC$57,3,),)/1000 -> 1984.4876 | S16: =+P16-R16 -> -782.15685 | T16: =+IFERROR(HLOOKUP($B16,'[1]4월'!$D$6:$BN$259,16,),)/1000 -> 133.4246 | U16: =+IFERROR(HLOOKUP($B16,'[2]4월'!$F$6:$CP$99,16,),)/1000 -> 126.42044 | V16: =+U16-T16 -> -7.0041638 | W16: =+IFERROR(HLOOKUP($B16,'[3]4월'!$F$6:$CC$57,16,),)/1000 -> 350.89098 | X16: =+U16-W16 -> -224.47054 | Y16: =+[4]창원!$Q$85 -> 100000.06 | Z16: =+[4]창원!$R$85 -> 96479.754 | AA16: =+[5]창원!$Q$85 -> 103837.35 | AB16: =+[4]창원!$Q$89 -> 75916.258 | AC16: =+[4]창원!$R$89 -> 72322.007 | AD16: =+[5]창원!$Q$89 -> 74909.07 | AE16: =+Y16-AB16 -> 24083.802 | AF16: =+Z16-AC16 -> 24157.748 | AG16: =+AA16-AD16 -> 28928.282
B17: 대구 | G17: =+I17 -> 대구 | I17: 대구 | J17: =+IFERROR(HLOOKUP($B17,'[1]4월'!$D$6:$BN$259,2,),)/1000 -> 12.5 | K17: =+IFERROR(HLOOKUP($B17,'[2]4월'!$F$6:$CP$99,2,),)/1000 -> 11.7315 | L17: =+K17-J17 -> -0.7685 | M17: =+IFERROR(HLOOKUP($B17,'[3]4월'!$F$6:$CC$57,2,),)/1000 -> 17.659 | N17: =+K17-M17 -> -5.9275 | O17: =+IFERROR(HLOOKUP($B17,'[1]4월'!$D$6:$BN$259,3,),)/1000 -> 1221.1001 | P17: =+IFERROR(HLOOKUP($B17,'[2]4월'!$F$6:$CP$99,3,),)/1000 -> 1058.2244 | Q17: =+P17-O17 -> -162.87565 | R17: =+IFERROR(HLOOKUP($B17,'[3]4월'!$F$6:$CC$57,3,),)/1000 -> 1760.5862 | S17: =+P17-R17 -> -702.36175 | T17: =+IFERROR(HLOOKUP($B17,'[1]4월'!$D$6:$BN$259,16,),)/1000 -> 123.74206 | U17: =+IFERROR(HLOOKUP($B17,'[2]4월'!$F$6:$CP$99,16,),)/1000 -> 50.698716 | V17: =+U17-T17 -> -73.043346 | W17: =+IFERROR(HLOOKUP($B17,'[3]4월'!$F$6:$CC$57,16,),)/1000 -> 287.68352 | X17: =+U17-W17 -> -236.9848 | Y17: =+[4]대구!$Q$85 -> 97688.008 | Z17: =+[4]대구!$R$85 -> 90203.678 | AA17: =+[5]대구!$Q$85 -> 99699.088 | AB17: =+[4]대구!$Q$89 -> 72963.433 | AC17: =+[4]대구!$R$89 -> 72248.873 | AD17: =+[5]대구!$Q$89 -> 73859.704 | AE17: =+Y17-AB17 -> 24724.575 | AF17: =+Z17-AC17 -> 17954.805 | AG17: =+AA17-AD17 -> 25839.384
B18: 울산 | G18: =+I18 -> 울산 | I18: 울산 | J18: =+IFERROR(HLOOKUP($B18,'[1]4월'!$D$6:$BN$259,2,),)/1000 -> 13 | K18: =+IFERROR(HLOOKUP($B18,'[2]4월'!$F$6:$CP$99,2,),)/1000 -> 13.906 | L18: =+K18-J18 -> 0.906 | M18: =+IFERROR(HLOOKUP($B18,'[3]4월'!$F$6:$CC$57,2,),)/1000 -> 11.11 | N18: =+K18-M18 -> 2.796 | O18: =+IFERROR(HLOOKUP($B18,'[1]4월'!$D$6:$BN$259,3,),)/1000 -> 1326.078 | P18: =+IFERROR(HLOOKUP($B18,'[2]4월'!$F$6:$CP$99,3,),)/1000 -> 1439.8668 | Q18: =+P18-O18 -> 113.7888 | R18: =+IFERROR(HLOOKUP($B18,'[3]4월'!$F$6:$CC$57,3,),)/1000 -> 1127.6673 | S18: =+P18-R18 -> 312.1995 | T18: =+IFERROR(HLOOKUP($B18,'[1]4월'!$D$6:$BN$259,16,),)/1000 -> 114.98218 | U18: =+IFERROR(HLOOKUP($B18,'[2]4월'!$F$6:$CP$99,16,),)/1000 -> 174.90096 | V18: =+U18-T18 -> 59.918781 | W18: =+IFERROR(HLOOKUP($B18,'[3]4월'!$F$6:$CC$57,16,),)/1000 -> 133.17269 | X18: =+U18-W18 -> 41.728269 | Y18: =+[4]울산!$Q$85 -> 102006 | Z18: =+[4]울산!$R$85 -> 103542.84 | AA18: =+[5]울산!$Q$85 -> 101500.21 | AB18: =+[4]울산!$Q$89 -> 81874.025 | AC18: =+[4]울산!$R$89 -> 80692.96 | AD18: =+[5]울산!$Q$89 -> 78272.849 | AE18: =+Y18-AB18 -> 20131.975 | AF18: =+Z18-AC18 -> 22849.885 | AG18: =+AA18-AD18 -> 23227.358
B19: 아산 | G19: =+I19 -> 아산 | I19: 아산 | J19: =+IFERROR(HLOOKUP($B19,'[1]4월'!$D$6:$BN$259,2,),)/1000 -> 25 | K19: =+IFERROR(HLOOKUP($B19,'[2]4월'!$F$6:$CP$99,2,),)/1000 -> 23.173 | L19: =+K19-J19 -> -1.827 | M19: =+IFERROR(HLOOKUP($B19,'[3]4월'!$F$6:$CC$57,2,),)/1000 -> 30.069 | N19: =+K19-M19 -> -6.896 | O19: =+IFERROR(HLOOKUP($B19,'[1]4월'!$D$6:$BN$259,3,),)/1000 -> 2575 | P19: =+IFERROR(HLOOKUP($B19,'[2]4월'!$F$6:$CP$99,3,),)/1000 -> 2210.5821 | Q19: =+P19-O19 -> -364.41793 | R19: =+IFERROR(HLOOKUP($B19,'[3]4월'!$F$6:$CC$57,3,),)/1000 -> 3153.8162 | S19: =+P19-R19 -> -943.23413 | T19: =+IFERROR(HLOOKUP($B19,'[1]4월'!$D$6:$BN$259,16,),)/1000 -> 367.52539 | U19: =+IFERROR(HLOOKUP($B19,'[2]4월'!$F$6:$CP$99,16,),)/1000 -> 177.27361 | V19: =+U19-T19 -> -190.25178 | W19: =+IFERROR(HLOOKUP($B19,'[3]4월'!$F$6:$CC$57,16,),)/1000 -> 538.83441 | X19: =+U19-W19 -> -361.5608 | Y19: =+[4]아산!$Q$85 -> 103000 | Z19: =+[4]아산!$R$85 -> 95394.73 | AA19: =+[5]아산!$Q$85 -> 104707.69 | AB19: =+[4]아산!$Q$89 -> 78535.543 | AC19: =+[4]아산!$R$89 -> 77222.153 | AD19: =+[5]아산!$Q$89 -> 77280.259 | AE19: =+Y19-AB19 -> 24464.457 | AF19: =+Z19-AC19 -> 18172.577 | AG19: =+AA19-AD19 -> 27427.434
B20: 전주 | G20: =+I20 -> 전주 | I20: 전주 | J20: =+IFERROR(HLOOKUP($B20,'[1]4월'!$D$6:$BN$259,2,),)/1000 -> 11 | K20: =+IFERROR(HLOOKUP($B20,'[2]4월'!$F$6:$CP$99,2,),)/1000 -> 17.106 | L20: =+K20-J20 -> 6.106 | M20: =+IFERROR(HLOOKUP($B20,'[3]4월'!$F$6:$CC$57,2,),)/1000 -> 9.772 | N20: =+K20-M20 -> 7.334 | O20: =+IFERROR(HLOOKUP($B20,'[1]4월'!$D$6:$BN$259,3,),)/1000 -> 1067.6502 | P20: =+IFERROR(HLOOKUP($B20,'[2]4월'!$F$6:$CP$99,3,),)/1000 -> 1690.8336 | Q20: =+P20-O20 -> 623.18337 | R20: =+IFERROR(HLOOKUP($B20,'[3]4월'!$F$6:$CC$57,3,),)/1000 -> 934.79442 | S20: =+P20-R20 -> 756.03913 | T20: =+IFERROR(HLOOKUP($B20,'[1]4월'!$D$6:$BN$259,16,),)/1000 -> 113.79379 | U20: =+IFERROR(HLOOKUP($B20,'[2]4월'!$F$6:$CP$99,16,),)/1000 -> 227.34832 | V20: =+U20-T20 -> 113.55453 | W20: =+IFERROR(HLOOKUP($B20,'[3]4월'!$F$6:$CC$57,16,),)/1000 -> 98.974598 | X20: =+U20-W20 -> 128.37372 | Y20: =+[4]전주!$Q$85 -> 97059.107 | Z20: =+[4]전주!$R$85 -> 98858.36 | AA20: =+[5]전주!$Q$85 -> 95671.078 | AB20: =+[4]전주!$Q$89 -> 72864.539 | AC20: =+[4]전주!$R$89 -> 76136.612 | AD20: =+[5]전주!$Q$89 -> 70537.059 | AE20: =+Y20-AB20 -> 24194.568 | AF20: =+Z20-AC20 -> 22721.748 | AG20: =+AA20-AD20 -> 25134.02
B21: 군산 | G21: =+I21 -> 군산 | I21: 군산 | J21: =+IFERROR(HLOOKUP($B21,'[1]4월'!$D$6:$BN$259,2,),)/1000 -> 8 | K21: =+IFERROR(HLOOKUP($B21,'[2]4월'!$F$6:$CP$99,2,),)/1000 -> 7.043 | L21: =+K21-J21 -> -0.957 | M21: =+IFERROR(HLOOKUP($B21,'[3]4월'!$F$6:$CC$57,2,),)/1000 -> 10.98 | N21: =+K21-M21 -> -3.937 | O21: =+IFERROR(HLOOKUP($B21,'[1]4월'!$D$6:$BN$259,3,),)/1000 -> 878.93212 | P21: =+IFERROR(HLOOKUP($B21,'[2]4월'!$F$6:$CP$99,3,),)/1000 -> 750.89675 | Q21: =+P21-O21 -> -128.03537 | R21: =+IFERROR(HLOOKUP($B21,'[3]4월'!$F$6:$CC$57,3,),)/1000 -> 1236.6071 | S21: =+P21-R21 -> -485.71033 | T21: =+IFERROR(HLOOKUP($B21,'[1]4월'!$D$6:$BN$259,16,),)/1000 -> 219.11095 | U21: =+IFERROR(HLOOKUP($B21,'[2]4월'!$F$6:$CP$99,16,),)/1000 -> 173.95167 | V21: =+U21-T21 -> -45.15928 | W21: =+IFERROR(HLOOKUP($B21,'[3]4월'!$F$6:$CC$57,16,),)/1000 -> 393.17557 | X21: =+U21-W21 -> -219.2239 | Y21: =+[4]군산!$Q$85 -> 109866.52 | Z21: =+[4]군산!$R$85 -> 106616.04 | AA21: =+[5]군산!$Q$85 -> 112623.6 | AB21: =+[4]군산!$Q$89 -> 72311.475 | AC21: =+[4]군산!$R$89 -> 69387.862 | AD21: =+[5]군산!$Q$89 -> 69227.207 | AE21: =+Y21-AB21 -> 37555.04 | AF21: =+Z21-AC21 -> 37228.175 | AG21: =+AA21-AD21 -> 43396.388
B22: 원주 | G22: =+I22 -> 원주 | I22: 원주 | J22: =+IFERROR(HLOOKUP($B22,'[1]4월'!$D$6:$BN$259,2,),)/1000 -> 5 | K22: =+IFERROR(HLOOKUP($B22,'[2]4월'!$F$6:$CP$99,2,),)/1000 -> 2.5685 | L22: =+K22-J22 -> -2.4315 | M22: =+IFERROR(HLOOKUP($B22,'[3]4월'!$F$6:$CC$57,2,),)/1000 -> 6.9255 | N22: =+K22-M22 -> -4.357 | O22: =+IFERROR(HLOOKUP($B22,'[1]4월'!$D$6:$BN$259,3,),)/1000 -> 560 | P22: =+IFERROR(HLOOKUP($B22,'[2]4월'!$F$6:$CP$99,3,),)/1000 -> 290.20385 | Q22: =+P22-O22 -> -269.79615 | R22: =+IFERROR(HLOOKUP($B22,'[3]4월'!$F$6:$CC$57,3,),)/1000 -> 765.70114 | S22: =+P22-R22 -> -475.4973 | T22: =+IFERROR(HLOOKUP($B22,'[1]4월'!$D$6:$BN$259,16,),)/1000 -> 97.265946 | U22: =+IFERROR(HLOOKUP($B22,'[2]4월'!$F$6:$CP$99,16,),)/1000 -> 14.251573 | V22: =+U22-T22 -> -83.014373 | W22: =+IFERROR(HLOOKUP($B22,'[3]4월'!$F$6:$CC$57,16,),)/1000 -> 170.20888 | X22: =+U22-W22 -> -155.95731 | Y22: =+[4]원주!$Q$85 -> 112000 | Z22: =+[4]원주!$R$85 -> 112985.73 | AA22: =+[5]원주!$Q$85 -> 110562.58 | AB22: =+[4]원주!$Q$89 -> 72748.332 | AC22: =+[4]원주!$R$89 -> 73010.818 | AD22: =+[5]원주!$Q$89 -> 72123.369 | AE22: =+Y22-AB22 -> 39251.668 | AF22: =+Z22-AC22 -> 39974.913 | AG22: =+AA22-AD22 -> 38439.211
B23: 제주 | G23: =+I23 -> 제주 | I23: 제주 | J23: =+IFERROR(HLOOKUP($B23,'[1]4월'!$D$6:$BN$259,2,),)/1000 -> 8 | K23: =+IFERROR(HLOOKUP($B23,'[2]4월'!$F$6:$CP$99,2,),)/1000 -> 7.3395 | L23: =+K23-J23 -> -0.6605 | M23: =+IFERROR(HLOOKUP($B23,'[3]4월'!$F$6:$CC$57,2,),)/1000 -> 3.556 | N23: =+K23-M23 -> 3.7835 | O23: =+IFERROR(HLOOKUP($B23,'[1]4월'!$D$6:$BN$259,3,),)/1000 -> 980.908 | P23: =+IFERROR(HLOOKUP($B23,'[2]4월'!$F$6:$CP$99,3,),)/1000 -> 910.08608 | Q23: =+P23-O23 -> -70.821919 | R23: =+IFERROR(HLOOKUP($B23,'[3]4월'!$F$6:$CC$57,3,),)/1000 -> 454.84141 | S23: =+P23-R23 -> 455.24467 | T23: =+IFERROR(HLOOKUP($B23,'[1]4월'!$D$6:$BN$259,16,),)/1000 -> 146.51892 | U23: =+IFERROR(HLOOKUP($B23,'[2]4월'!$F$6:$CP$99,16,),)/1000 -> 128.44487 | V23: =+U23-T23 -> -18.07405 | W23: =+IFERROR(HLOOKUP($B23,'[3]4월'!$F$6:$CC$57,16,),)/1000 -> 53.489504 | X23: =+U23-W23 -> 74.955367 | Y23: =+[4]제주!$Q$85 -> 122613.5 | Z23: =+[4]제주!$R$85 -> 123584.35 | AA23: =+[5]제주!$Q$85 -> 127908.16 | AB23: =+[4]제주!$Q$89 -> 91127.321 | AC23: =+[4]제주!$R$89 -> 91260.284 | AD23: =+[5]제주!$Q$89 -> 87547.524 | AE23: =+Y23-AB23 -> 31486.179 | AF23: =+Z23-AC23 -> 32324.069 | AG23: =+AA23-AD23 -> 40360.635
F24: =+K24/J24 -> 0.90683636 | G24: =+I24 -> 수도권 | I24: 수도권 | J24: =SUM(J7:J10) -> 110 | K24: =SUM(K7:K10) -> 99.752 | L24: =+K24-J24 -> -10.248 | M24: =SUM(M7:M10) -> 122.5135 | N24: =+K24-M24 -> -22.7615 | O24: =SUM(O7:O10) -> 10704.768 | P24: =SUM(P7:P10) -> 9616.3146 | Q24: =+P24-O24 -> -1088.4532 | R24: =SUM(R7:R10) -> 12227.972 | S24: =+P24-R24 -> -2611.6572 | T24: =SUM(T7:T10) -> 829.31606 | U24: =SUM(U7:U10) -> 593.23161 | V24: =+U24-T24 -> -236.08445 | W24: =SUM(W7:W10) -> 1426.0178 | X24: =+U24-W24 -> -832.78619 | Y24: =+[4]수도권!$Q$85 -> 97316.07 | Z24: =+[4]수도권!$R$85 -> 96454.113 | AA24: =+[5]수도권!$Q$85 -> 99830.046 | AB24: =+[4]수도권!$Q$89 -> 80692.152 | AC24: =+[4]수도권!$R$89 -> 80081.525 | AD24: =+[5]수도권!$Q$89 -> 80098.575 | AE24: =+Y24-AB24 -> 16623.918 | AF24: =+Z24-AC24 -> 16372.588 | AG24: =+AA24-AD24 -> 19731.47
F25: =+K25/J25 -> 0.93284825 | G25: =+I25 -> 영남권 | I25: 영남권 | J25: =SUM(J11:J18) -> 128.5 | K25: =SUM(K11:K18) -> 119.871 | L25: =+K25-J25 -> -8.629 | M25: =SUM(M11:M18) -> 147.2215 | N25: =+K25-M25 -> -27.3505 | O25: =SUM(O11:O18) -> 12911.424 | P25: =SUM(P11:P18) -> 11793.337 | Q25: =+P25-O25 -> -1118.0867 | R25: =SUM(R11:R18) -> 14959.708 | S25: =+P25-R25 -> -3166.3702 | T25: =SUM(T11:T18) -> 1257.6657 | U25: =SUM(U11:U18) -> 851.16723 | V25: =+U25-T25 -> -406.49843 | W25: =SUM(W11:W18) -> 1954.5454 | X25: =+U25-W25 -> -1103.3782 | Y25: =+[4]영남권!$Q$85 -> 100478.01 | Z25: =+[4]영남권!$R$85 -> 98385.129 | AA25: =+[5]영남권!$Q$85 -> 101618.83 | AB25: =+[4]영남권!$Q$89 -> 78845.876 | AC25: =+[4]영남권!$R$89 -> 79072.358 | AD25: =+[5]영남권!$Q$89 -> 78242.384 | AE25: =+Y25-AB25 -> 21632.131 | AF25: =+Z25-AC25 -> 19312.771 | AG25: =+AA25-AD25 -> 23376.451
F26: =+K26/J26 -> 1.0040351 | G26: =+I26 -> 중부권 | I26: 중부권 | J26: =SUM(J19:J23) -> 57 | K26: =SUM(K19:K23) -> 57.23 | L26: =+K26-J26 -> 0.23 | M26: =SUM(M19:M23) -> 61.3025 | N26: =+K26-M26 -> -4.0725 | O26: =SUM(O19:O23) -> 6062.4903 | P26: =SUM(P19:P23) -> 5852.6023 | Q26: =+P26-O26 -> -209.888 | R26: =SUM(R19:R23) -> 6545.7603 | S26: =+P26-R26 -> -693.15796 | T26: =SUM(T19:T23) -> 944.21499 | U26: =SUM(U19:U23) -> 721.27004 | V26: =+U26-T26 -> -222.94495 | W26: =SUM(W19:W23) -> 1254.683 | X26: =+U26-W26 -> -533.41293 | Y26: =+[4]중부권!$Q$85 -> 106359.48 | Z26: =+[4]중부권!$R$85 -> 102148.63 | AA26: =+[5]중부권!$Q$85 -> 106728.9 | AB26: =+[4]중부권!$Q$89 -> 77827.202 | AC26: =+[4]중부권!$R$89 -> 77500.622 | AD26: =+[5]중부권!$Q$89 -> 74744.194 | AE26: =+Y26-AB26 -> 28532.277 | AF26: =+Z26-AC26 -> 24648.008 | AG26: =+AA26-AD26 -> 31984.708
F27: =+K27/M27 -> 0.83631915 | G27: =+K27/J27 -> 0.93689679 | H27: 레미콘 계 | J27: =SUM(J24:J26) -> 295.5 | K27: =SUM(K24:K26) -> 276.853 | L27: =+K27-J27 -> -18.647 | M27: =SUM(M24:M26) -> 331.0375 | N27: =+K27-M27 -> -54.1845 | O27: =SUM(O24:O26) -> 29678.682 | P27: =SUM(P24:P26) -> 27262.254 | Q27: =+P27-O27 -> -2416.4278 | R27: =SUM(R24:R26) -> 33733.44 | S27: =+P27-R27 -> -6471.1854 | T27: =SUM(T24:T26) -> 3031.1967 | U27: =SUM(U24:U26) -> 2165.6689 | V27: =+U27-T27 -> -865.52784 | W27: =SUM(W24:W26) -> 4635.2462 | X27: =+U27-W27 -> -2469.5773 | Y27: =+[4]합계!$Q$85 -> 100435.47 | Z27: =+[4]합계!$R$85 -> 98470.346 | AA27: =+[5]합계!$Q$85 -> 101892.73 | AB27: =+[4]합계!$Q$89 -> 79336.658 | AC27: =+[4]합계!$R$89 -> 79109.225 | AD27: =+[5]합계!$Q$89 -> 78288.565 | AE27: =+Y27-AB27 -> 21098.815 | AF27: =+Z27-AC27 -> 19361.122 | AG27: =+AA27-AD27 -> 23604.168 | AI27: =+AF27-AE27 -> -1737.693 | AJ27: =+AF27-AG27 -> -4243.0462
B28: 건자재 | E28: 건자재영업 | G28: 건자재 | H28: 건자재 | J28: =+IFERROR(HLOOKUP($B28,'[1]4월'!$D$6:$BN$259,2,),) -> 11100 | K28: =+IFERROR(HLOOKUP($E28,'[2]4월'!$F$6:$CP$99,2,),) -> 11123.665 | L28: =+K28-J28 -> 23.665 | M28: =+IFERROR(HLOOKUP($E28,'[3]4월'!$F$6:$CC$57,2,),) -> 8574.983 | N28: =+K28-M28 -> 2548.682 | O28: =+IFERROR(HLOOKUP($B28,'[1]4월'!$D$6:$BN$259,3,),)/1000 -> 12145.191 | P28: =+IFERROR(HLOOKUP($E28,'[2]4월'!$F$6:$CP$99,3,),)/1000 -> 10147.504 | Q28: =+P28-O28 -> -1997.6868 | R28: =+IFERROR(HLOOKUP($E28,'[3]4월'!$F$6:$CC$57,3,),)/1000 -> 8822.0395 | S28: =+P28-R28 -> 1325.4647 | T28: =+IFERROR(HLOOKUP($B28,'[1]4월'!$D$6:$BN$259,16,),)/1000 -> 205.19181 | U28: =+IFERROR(HLOOKUP($E28,'[2]4월'!$F$6:$CP$99,16,),)/1000 -> -0.271546 | V28: =+U28-T28 -> -205.46336 | W28: =+IFERROR(HLOOKUP($E28,'[3]4월'!$F$6:$CC$57,16,),)/1000 -> -6.182668 | X28: =+U28-W28 -> 5.911122 | Y28: ■ 비고
B29: 부산모래장 | C29: 부산골재 | G29: =+I29 -> 부산모래장 | H29: 골재 | I29: 부산모래장 | J29: =+IFERROR(HLOOKUP($B29,'[1]4월'!$D$6:$BN$259,2,),)/1000 -> 17.946228 | K29: =+IFERROR(HLOOKUP($C29,'[2]4월'!$F$6:$CP$99,2,),)/1000 -> 25.409 | L29: =+K29-J29 -> 7.4627717 | M29: =+IFERROR(HLOOKUP($C29,'[3]4월'!$F$6:$CC$57,2,),)/1000 -> 20.579 | N29: =+K29-M29 -> 4.83 | O29: =+IFERROR(HLOOKUP($B29,'[1]4월'!$D$6:$BN$259,3,),)/1000 -> 733.57402 | P29: =+IFERROR(HLOOKUP($C29,'[2]4월'!$F$6:$CP$99,3,),)/1000 -> 749.494 | Q29: =+P29-O29 -> 15.919978 | R29: =+IFERROR(HLOOKUP($C29,'[3]4월'!$F$6:$CC$57,3,),)/1000 -> 653.70641 | S29: =+P29-R29 -> 95.787592 | T29: =+IFERROR(HLOOKUP($B29,'[1]4월'!$D$6:$BN$259,21,),)/1000 -> 232.34492 | U29: =+IFERROR(HLOOKUP($C29,'[2]4월'!$F$6:$CP$99,21,),)/1000 -> -18.692086 | V29: =+U29-T29 -> -251.037 | W29: =+IFERROR(HLOOKUP($C29,'[3]4월'!$F$6:$CC$57,21,),)/1000 -> 40.624192 | X29: =+U29-W29 -> -59.316278 | Y29: - 1군 소급분 : 76백만원(단위당 : 275원/㎥↓) → 롯데 등
B30: 서부산크라샤 | C30: 서부산골재 | G30: =+I30 -> 서부산CR | I30: 서부산CR | J30: =+IFERROR(HLOOKUP($B30,'[1]4월'!$D$6:$BN$259,2,),)/1000 -> 67.048245 | K30: =+IFERROR(HLOOKUP($C30,'[2]4월'!$F$6:$CP$99,2,),)/1000 -> 27.056 | L30: =+K30-J30 -> -39.992245 | M30: =+IFERROR(HLOOKUP($C30,'[3]4월'!$F$6:$CC$57,2,),)/1000 -> 27.24 | N30: =+K30-M30 -> -0.184 | O30: =+IFERROR(HLOOKUP($B30,'[1]4월'!$D$6:$BN$259,3,),)/1000 -> 988.54837 | P30: =+IFERROR(HLOOKUP($C30,'[2]4월'!$F$6:$CP$99,3,),)/1000 -> 390.312 | Q30: =+P30-O30 -> -598.23637 | R30: =+IFERROR(HLOOKUP($C30,'[3]4월'!$F$6:$CC$57,3,),)/1000 -> 382.248 | S30: =+P30-R30 -> 8.064 | T30: =+IFERROR(HLOOKUP($B30,'[1]4월'!$D$6:$BN$259,21,),)/1000 -> 238.82367 | U30: =+IFERROR(HLOOKUP($C30,'[2]4월'!$F$6:$CP$99,21,),)/1000 -> 105.22194 | V30: =+U30-T30 -> -133.60172 | W30: =+IFERROR(HLOOKUP($C30,'[3]4월'!$F$6:$CC$57,21,),)/1000 -> 61.107316 | X30: =+U30-W30 -> 44.114629 | Y30: - 1군 단가협상 : 천안 아산지역 2,600원/㎥↓, 창원 2,900원/㎥↓(4/1)
B31: 부산크라샤 | C31: 부산크라샤 | G31: =+I31 -> 부산CR | I31: 부산CR | J31: =+IFERROR(HLOOKUP($B31,'[1]4월'!$D$6:$BN$259,2,),)/1000 -> 0.0001 | K31: =+IFERROR(HLOOKUP($C31,'[2]4월'!$F$6:$CP$99,2,),)/1000 -> 15.56 | L31: =+K31-J31 -> 15.5599 | M31: =+IFERROR(HLOOKUP($C31,'[3]4월'!$F$6:$CC$57,2,),)/1000 -> 38.524 | N31: =+K31-M31 -> -22.964 | O31: =+IFERROR(HLOOKUP($B31,'[1]4월'!$D$6:$BN$259,3,),)/1000 -> 0 | P31: =+IFERROR(HLOOKUP($C31,'[2]4월'!$F$6:$CP$99,3,),)/1000 -> 309.26 | Q31: =+P31-O31 -> 309.26 | R31: =+IFERROR(HLOOKUP($C31,'[3]4월'!$F$6:$CC$57,3,),)/1000 -> 710.866 | S31: =+P31-R31 -> -401.606 | T31: =+IFERROR(HLOOKUP($B31,'[1]4월'!$D$6:$BN$259,21,),)/1000 -> -196.96017 | U31: =+IFERROR(HLOOKUP($C31,'[2]4월'!$F$6:$CP$99,21,),)/1000 -> -29.2233 | V31: =+U31-T31 -> 167.73687 | W31: =+IFERROR(HLOOKUP($C31,'[3]4월'!$F$6:$CC$57,21,),)/1000 -> 52.145938 | X31: =+U31-W31 -> -81.369237
H32: 골재 계 | J32: =SUM(J29:J31) -> 84.994573 | K32: =SUM(K29:K31) -> 68.025 | L32: =+K32-J32 -> -16.969573 | M32: =SUM(M29:M31) -> 86.343 | N32: =+K32-M32 -> -18.318 | O32: =SUM(O29:O31) -> 1722.1224 | P32: =SUM(P29:P31) -> 1449.066 | Q32: =+P32-O32 -> -273.05639 | R32: =SUM(R29:R31) -> 1746.8204 | S32: =+P32-R32 -> -297.75441 | T32: =SUM(T29:T31) -> 274.20842 | U32: =SUM(U29:U31) -> 57.306559 | V32: =+U32-T32 -> -216.90186 | W32: =SUM(W29:W31) -> 153.87745 | X32: =+U32-W32 -> -96.570887 | Y32: - 판매단가 : 대구권 단가협상 4,900원/㎥↓(5/1부)
B33: 포항임대 | C33: 속초임대 | D33: 강릉임대 | E33: 레미콘임대 계 | G33: =+I33 -> 레미콘임대 | H33: 기타 | I33: 레미콘임대 | L33: =+K33-J33 -> 0 | N33: =+K33-M33 -> 0 | O33: =(IFERROR(HLOOKUP($B33,'[1]4월'!$D$6:$BN$259,3,),)++IFERROR(HLOOKUP($C33,'[1]4월'!$D$6:$BN$259,3,),)+IFERROR(HLOOKUP($D33,'[1]4월'!$D$6:$BN$259,3,),))/1000 -> 66.666667 | P33: =+IFERROR(HLOOKUP($E33,'[2]4월'!$F$6:$CP$99,3,),)/1000 -> 43.34 | Q33: =+P33-O33 -> -23.326667 | R33: =+IFERROR(HLOOKUP($E33,'[3]4월'!$F$6:$CC$57,3,),)/1000 -> 90.84 | S33: =+P33-R33 -> -47.5 | T33: =(IFERROR(HLOOKUP($B33,'[1]4월'!$D$6:$BN$259,21,),)++IFERROR(HLOOKUP($C33,'[1]4월'!$D$6:$BN$259,21,),)+IFERROR(HLOOKUP($D33,'[1]4월'!$D$6:$BN$259,21,),))/1000 -> 48.349888 | U33: =+IFERROR(HLOOKUP($E33,'[2]4월'!$F$6:$CP$99,16,),)/1000 -> 23.021931 | V33: =+U33-T33 -> -25.327957 | W33: =+IFERROR(HLOOKUP($E33,'[3]4월'!$F$6:$CC$57,16,),)/1000 -> 71.958667 | X33: =+U33-W33 -> -48.936736 | Y33: - 운반비 : 영남권 MT운반비 2개년 합의 인상 적용(5/1)
B34: 부동산임대 | C34: 주유소임대 | E34: 임대 계 | G34: =+I34 -> 임대 | I34: 임대 | L34: =+K34-J34 -> 0 | M34: 0 | N34: =+K34-M34 -> 0 | O34: =(+IFERROR(HLOOKUP($B34,'[1]4월'!$D$6:$BN$259,3,),)+IFERROR(HLOOKUP($C34,'[1]4월'!$D$6:$BN$259,3,),))/1000 -> 74.0915 | P34: =+IFERROR(HLOOKUP($E34,'[2]4월'!$F$6:$CP$99,3,),)/1000 -> 73.488214 | Q34: =+P34-O34 -> -0.603286 | R34: =+IFERROR(HLOOKUP($E34,'[3]4월'!$F$6:$CC$57,3,),)/1000 -> 73.256694 | S34: =+P34-R34 -> 0.23152 | T34: =(+IFERROR(HLOOKUP($B34,'[1]4월'!$D$6:$BN$259,21,),)+IFERROR(HLOOKUP($C34,'[1]4월'!$D$6:$BN$259,21,),))/1000 -> 63.964 | U34: =+IFERROR(HLOOKUP($E34,'[2]4월'!$F$6:$CP$99,16,),)/1000 -> 63.367074 | V34: =+U34-T34 -> -0.596926 | W34: =+IFERROR(HLOOKUP($E34,'[3]4월'!$F$6:$CC$57,16,),)/1000 -> 63.157758 | X34: =+U34-W34 -> 0.209316 | Y34: → 부산권 4천원, 창원 3.5천원 / 제주 협상完 500원/㎥ 인상
B35: 공 통 비 | G35: =+I35 -> 공통비 | I35: 공통비 | L35: =+K35-J35 -> 0 | N35: =+K35-M35 -> 0 | Q35: =+P35-O35 -> 0 | S35: =+P35-R35 -> 0 | T35: =-'[1]4월'!$Z$22/1000 -> -1670.9087 | U35: =+-'[2]4월'!$Z$22/1000 -> -1654.8985 | V35: =+U35-T35 -> 16.010214 | W35: =+-'[3]4월'!$Z$22/1000 -> -1567.4228 | X35: =+U35-W35 -> -87.475651
G36: =+I36 -> OPC 소급분 | I36: OPC 소급분 | N36: =+K36-M36 -> 0 | Q36: =+P36-O36 -> 0 | S36: =+P36-R36 -> 0 | U36: ='[2]4월'!$BD$26/1000 -> 0 | V36: =+U36-T36 -> 0 | W36: =-'[3]4월'!$BD$26/1000 -> 0 | X36: =+U36-W36 -> 0
G37: =+I37 -> 대손 | I37: 대손 | N37: =+K37-M37 -> 0 | Q37: =+P37-O37 -> 0 | S37: =+P37-R37 -> 0 | U37: ='[2]4월'!$BE$26/1000 -> 0 | V37: =+U37-T37 -> 0 | W37: ='[3]4월'!$BE$26/1000 -> 0 | X37: =+U37-W37 -> 0
G38: =+I38 -> 미운영 공장 | I38: 미운영 공장 | M38: =SUM(M54:M59) -> 0 | N38: =+K38-M38 -> 0 | Q38: =+P38-O38 -> 0 | R38: =+IFERROR(HLOOKUP($I$38,'[3]4월'!$F$6:$BJ$50,3,),)/1000 -> 0 | S38: =+P38-R38 -> 0 | T38: =SUM('[1]4월'!$AM$26:$AQ$26)/1000 -> -32.504496 | U38: =+'[2]4월'!$BF$26/1000 -> -31.15242 | V38: =+U38-T38 -> 1.352076 | W38: =+'[3]4월'!$BF$26/1000 -> -33.797813 | X38: =+U38-W38 -> 2.645393
B39: 기타 계 | G39: =+I39 -> 퇴직위로금 | I39: 퇴직위로금 | U39: =+'[2]4월'!$BG$26/1000 -> 0 | V39: =+U39-T39 -> 0 | X39: =+U39-W39 -> 0
G40: =+I40 -> 기타 | I40: 기타 | L40: =+K40-J40 -> 0 | N40: =+K40-M40 -> 0 | O40: =IFERROR(HLOOKUP($B39,'[1]4월'!$D$6:$BN$259,3,),)/1000 -> 1.77 | P40: =+('[2]4월'!$F$8-SUM('[2]4월'!$Z$8,'[2]4월'!$AH$8,'[2]4월'!$AN$8,'[2]4월'!$AO$8,'[2]4월'!$BA$8,'[2]4월'!$BD$8,'[2]4월'!$BE$8,'[2]4월'!$BF$8))/1000 -> 1.66065 | Q40: =+P40-O40 -> -0.10935 | R40: =+('[3]4월'!$F$8-SUM('[3]4월'!$Z$8,'[3]4월'!$AH$8,'[3]4월'!$AN$8,'[3]4월'!$AO$8,'[3]4월'!$BA$8,'[3]4월'!$BD$8,'[3]4월'!$BE$8,'[3]4월'!$BF$8))/1000 -> 1.7024 | S40: =+P40-R40 -> -0.04175 | T40: =+('[1]4월'!$E$26-'[1]4월'!$Z$26-'[1]4월'!$AA$26-'[1]4월'!$AE$26-'[1]4월'!$AL$26-'[1]4월'!$AM$26-'[1]4월'!$AN$26-'[1]4월'!$AO$26-'[1]4월'!$AP$26-'[1]4월'!$AQ$26-'[1]4월'!$AS$26+'[1]4월'!$AS$26)/1000 -> -85.138375 | U40: =+('[2]4월'!$F$26-SUM('[2]4월'!$Z$26,'[2]4월'!$AH$26,'[2]4월'!$AN$26,'[2]4월'!$AO$26,'[2]4월'!$BA$26,'[2]4월'!$BD$26,'[2]4월'!$BE$26,'[2]4월'!$BF$26))/1000-U39 -> -15.492812 | V40: =+U40-T40 -> 69.645563 | W40: =+('[3]4월'!$F$26-SUM('[3]4월'!$Z$26,'[3]4월'!$AH$26,'[3]4월'!$AN$26,'[3]4월'!$AO$26,'[3]4월'!$BA$26,'[3]4월'!$BD$26,'[3]4월'!$BE$26,'[3]4월'!$BF$26))/1000 -> -14.461379 | X40: =+U40-W40 -> -1.031433
H41: 기타 계 | J41: =SUM(J33:J40) -> 0 | K41: =SUM(K33:K40) -> 0 | L41: =+K41-J41 -> 0 | M41: =SUM(M33:M40) -> 0 | N41: =+K41-M41 -> 0 | O41: =SUM(O33:O40) -> 142.52817 | P41: =SUM(P33:P40) -> 118.48886 | Q41: =+P41-O41 -> -24.039303 | R41: =SUM(R33:R40) -> 165.79909 | S41: =+P41-R41 -> -47.31023 | T41: =SUM(T33:T40) -> -1676.2377 | U41: =SUM(U33:U40) -> -1615.1547 | V41: =+U41-T41 -> 61.08297 | W41: =SUM(W33:W40) -> -1480.5656 | X41: =+U41-W41 -> -134.58911
U42: 19 | V42: 12.4
...

Sheet 사업장별(누계)
H3: □ 사업장별 손익실적(2025-04누계)
AG4: [단위 : 천㎥, 톤, 백만원]
H5: 구분 | J5: 물량 | O5: 매출 | T5: 영업이익(공통비 배부전) | Y5: 판매단가 | AB5: 변동비 | AE5: 공헌이익
A6: 2024년 4월누계 마감 손익 | J6: 계획 | K6: 실적 | L6: 차이 | M6: 전년 | N6: 차이 | O6: 계획 | P6: 실적 | Q6: 차이 | R6: 전년 | S6: 차이 | T6: 계획 | U6: 실적 | V6: 차이 | W6: 전년 | X6: 차이 | Y6: 계획 | Z6: 실적 | AA6: 전년 | AB6: 계획 | AC6: 실적 | AD6: 전년 | AE6: 계획 | AF6: 실적 | AG6: 전년
B7: 안양 | G7: =+I7 -> 안양 | H7: 레미콘 | I7: 안양 | J7: =+IFERROR(HLOOKUP($B7,'[1]4월누계'!$D$6:$BN$259,2,),)/1000 -> 142 | K7: =+IFERROR(HLOOKUP($B7,'[2]4월누계'!$F$6:$CP$99,2,),)/1000 -> 140.46 | L7: =+K7-J7 -> -1.54 | M7: =+IFERROR(HLOOKUP($B7,'[3]4월누계'!$F$6:$CC$57,2,),)/1000 -> 170.698 | N7: =+K7-M7 -> -30.238 | O7: =+IFERROR(HLOOKUP($B7,'[1]4월누계'!$D$6:$BN$259,3,),)/1000 -> 13924.714 | P7: =+IFERROR(HLOOKUP($B7,'[2]4월누계'!$F$6:$CP$99,3,),)/1000 -> 13476.409 | Q7: =+P7-O7 -> -448.30427 | R7: =+IFERROR(HLOOKUP($B7,'[3]4월누계'!$F$6:$CC$57,3,),)/1000 -> 16839.669 | S7: =+P7-R7 -> -3363.2601 | T7: =+IFERROR(HLOOKUP($B7,'[1]4월누계'!$D$6:$BN$259,16,),)/1000 -> 1004.0781 | U7: =+IFERROR(HLOOKUP($B7,'[2]4월누계'!$F$6:$CP$99,16,),)/1000 -> 865.27363 | V7: =+U7-T7 -> -138.80446 | W7: =+IFERROR(HLOOKUP($B7,'[3]4월누계'!$F$6:$CC$57,16,),)/1000 -> 1780.9296 | X7: =+U7-W7 -> -915.65596 | Y7: =+[9]안양!$Q$85 -> 98061.363 | Z7: =+[9]안양!$R$85 -> 95926.124 | AA7: =+[10]안양!$Q$85 -> 98646.302 | AB7: =+[9]안양!$Q$89 -> 82250.837 | AC7: =+[9]안양!$R$89 -> 81028.978 | AD7: =+[10]안양!$Q$89 -> 81001.251 | AE7: =+Y7-AB7 -> 15810.526 | AF7: =+Z7-AC7 -> 14897.146 | AG7: =+AA7-AD7 -> 17645.051
B8: 인천 | G8: =+I8 -> 인천 | H8: 직영 | I8: 인천 | J8: =+IFERROR(HLOOKUP($B8,'[1]4월누계'!$D$6:$BN$259,2,),)/1000 -> 110 | K8: =+IFERROR(HLOOKUP($B8,'[2]4월누계'!$F$6:$CP$99,2,),)/1000 -> 103.722 | L8: =+K8-J8 -> -6.278 | M8: =+IFERROR(HLOOKUP($B8,'[3]4월누계'!$F$6:$CC$57,2,),)/1000 -> 113.751 | N8: =+K8-M8 -> -10.029 | O8: =+IFERROR(HLOOKUP($B8,'[1]4월누계'!$D$6:$BN$259,3,),)/1000 -> 10761.842 | P8: =+IFERROR(HLOOKUP($B8,'[2]4월누계'!$F$6:$CP$99,3,),)/1000 -> 10154.913 | Q8: =+P8-O8 -> -606.92896 | R8: =+IFERROR(HLOOKUP($B8,'[3]4월누계'!$F$6:$CC$57,3,),)/1000 -> 11517.811 | S8: =+P8-R8 -> -1362.8977 | T8: =+IFERROR(HLOOKUP($B8,'[1]4월누계'!$D$6:$BN$259,16,),)/1000 -> 367.15216 | U8: =+IFERROR(HLOOKUP($B8,'[2]4월누계'!$F$6:$CP$99,16,),)/1000 -> 143.88325 | V8: =+U8-T8 -> -223.26891 | W8: =+IFERROR(HLOOKUP($B8,'[3]4월누계'!$F$6:$CC$57,16,),)/1000 -> 955.53588 | X8: =+U8-W8 -> -811.65263 | Y8: =+[9]인천!$Q$85 -> 97834.93 | Z8: =+[9]인천!$R$85 -> 97920.696 | AA8: =+[10]인천!$Q$85 -> 101254.59 | AB8: =+[9]인천!$Q$89 -> 83353.552 | AC8: =+[9]인천!$R$89 -> 84814.027 | AD8: =+[10]인천!$Q$89 -> 82842.102 | AE8: =+Y8-AB8 -> 14481.378 | AF8: =+Z8-AC8 -> 13106.669 | AG8: =+AA8-AD8 -> 18412.49
B9: 파주 | G9: =+I9 -> 파주 | I9: 파주 | J9: =+IFERROR(HLOOKUP($B9,'[1]4월누계'!$D$6:$BN$259,2,),)/1000 -> 70 | K9: =+IFERROR(HLOOKUP($B9,'[2]4월누계'!$F$6:$CP$99,2,),)/1000 -> 43.281 | L9: =+K9-J9 -> -26.719 | M9: =+IFERROR(HLOOKUP($B9,'[3]4월누계'!$F$6:$CC$57,2,),)/1000 -> 94.777 | N9: =+K9-M9 -> -51.496 | O9: =+IFERROR(HLOOKUP($B9,'[1]4월누계'!$D$6:$BN$259,3,),)/1000 -> 6747.2055 | P9: =+IFERROR(HLOOKUP($B9,'[2]4월누계'!$F$6:$CP$99,3,),)/1000 -> 3997.0859 | Q9: =+P9-O9 -> -2750.1196 | R9: =+IFERROR(HLOOKUP($B9,'[3]4월누계'!$F$6:$CC$57,3,),)/1000 -> 9538.5462 | S9: =+P9-R9 -> -5541.4603 | T9: =+IFERROR(HLOOKUP($B9,'[1]4월누계'!$D$6:$BN$259,16,),)/1000 -> 191.85721 | U9: =+IFERROR(HLOOKUP($B9,'[2]4월누계'!$F$6:$CP$99,16,),)/1000 -> -312.75035 | V9: =+U9-T9 -> -504.60755 | W9: =+IFERROR(HLOOKUP($B9,'[3]4월누계'!$F$6:$CC$57,16,),)/1000 -> 720.6683 | X9: =+U9-W9 -> -1033.4186 | Y9: =+[9]파주!$Q$85 -> 96388.65 | Z9: =+[9]파주!$R$85 -> 92404.744 | AA9: =+[10]파주!$Q$85 -> 100686.07 | AB9: =+[9]파주!$Q$89 -> 79623.451 | AC9: =+[9]파주!$R$89 -> 79057.74 | AD9: =+[10]파주!$Q$89 -> 83027.045 | AE9: =+Y9-AB9 -> 16765.199 | AF9: =+Z9-AC9 -> 13347.004 | AG9: =+AA9-AD9 -> 17659.029
B10: 김포 | G10: =+I10 -> 김포 | I10: 김포 | J10: =+IFERROR(HLOOKUP($B10,'[1]4월누계'!$D$6:$BN$259,2,),)/1000 -> 48 | K10: =+IFERROR(HLOOKUP($B10,'[2]4월누계'!$F$6:$CP$99,2,),)/1000 -> 36.927 | L10: =+K10-J10 -> -11.073 | M10: =+IFERROR(HLOOKUP($B10,'[3]4월누계'!$F$6:$CC$57,2,),)/1000 -> 41.1575 | N10: =+K10-M10 -> -4.2305 | O10: =+IFERROR(HLOOKUP($B10,'[1]4월누계'!$D$6:$BN$259,3,),)/1000 -> 4575.4515 | P10: =+IFERROR(HLOOKUP($B10,'[2]4월누계'!$F$6:$CP$99,3,),)/1000 -> 3518.4271 | Q10: =+P10-O10 -> -1057.0243 | R10: =+IFERROR(HLOOKUP($B10,'[3]4월누계'!$F$6:$CC$57,3,),)/1000 -> 4025.2966 | S10: =+P10-R10 -> -506.86951 | T10: =+IFERROR(HLOOKUP($B10,'[1]4월누계'!$D$6:$BN$259,16,),)/1000 -> 187.88291 | U10: =+IFERROR(HLOOKUP($B10,'[2]4월누계'!$F$6:$CP$99,16,),)/1000 -> -50.511174 | V10: =+U10-T10 -> -238.39409 | W10: =+IFERROR(HLOOKUP($B10,'[3]4월누계'!$F$6:$CC$57,16,),)/1000 -> 266.92423 | X10: =+U10-W10 -> -317.43541 | Y10: =+[9]김포!$Q$85 -> 95321.906 | Z10: =+[9]김포!$R$85 -> 95344.508 | AA10: =+[10]김포!$Q$85 -> 97802.263 | AB10: =+[9]김포!$Q$89 -> 76938.04 | AC10: =+[9]김포!$R$89 -> 78484.915 | AD10: =+[10]김포!$Q$89 -> 76096.809 | AE10: =+Y10-AB10 -> 18383.866 | AF10: =+Z10-AC10 -> 16859.593 | AG10: =+AA10-AD10 -> 21705.454
B11: 부산 | G11: =+I11 -> 부산 | I11: 부산 | J11: =+IFERROR(HLOOKUP($B11,'[1]4월누계'!$D$6:$BN$259,2,),)/1000 -> 78 | K11: =+IFERROR(HLOOKUP($B11,'[2]4월누계'!$F$6:$CP$99,2,),)/1000 -> 74.847 | L11: =+K11-J11 -> -3.153 | M11: =+IFERROR(HLOOKUP($B11,'[3]4월누계'!$F$6:$CC$57,2,),)/1000 -> 85.017 | N11: =+K11-M11 -> -10.17 | O11: =+IFERROR(HLOOKUP($B11,'[1]4월누계'!$D$6:$BN$259,3,),)/1000 -> 8400.5963 | P11: =+IFERROR(HLOOKUP($B11,'[2]4월누계'!$F$6:$CP$99,3,),)/1000 -> 7925.726 | Q11: =+P11-O11 -> -474.87029 | R11: =+IFERROR(HLOOKUP($B11,'[3]4월누계'!$F$6:$CC$57,3,),)/1000 -> 9081.9494 | S11: =+P11-R11 -> -1156.2234 | T11: =+IFERROR(HLOOKUP($B11,'[1]4월누계'!$D$6:$BN$259,16,),)/1000 -> 706.94001 | U11: =+IFERROR(HLOOKUP($B11,'[2]4월누계'!$F$6:$CP$99,16,),)/1000 -> 676.07838 | V11: =+U11-T11 -> -30.861624 | W11: =+IFERROR(HLOOKUP($B11,'[3]4월누계'!$F$6:$CC$57,16,),)/1000 -> 989.91649 | X11: =+U11-W11 -> -313.83811 | Y11: =+[9]부산!$Q$85 -> 107699.95 | Z11: =+[9]부산!$R$85 -> 105892.37 | AA11: =+[10]부산!$Q$85 -> 106825.1 | AB11: =+[9]부산!$Q$89 -> 84690.817 | AC11: =+[9]부산!$R$89 -> 83622.631 | AD11: =+[10]부산!$Q$89 -> 83745.24 | AE11: =+Y11-AB11 -> 23009.136 | AF11: =+Z11-AC11 -> 22269.737 | AG11: =+AA11-AD11 -> 23079.859
B12: 서부산 | G12: =+I12 -> 서부산 | I12: 서부산 | J12: =+IFERROR(HLOOKUP($B12,'[1]4월누계'!$D$6:$BN$259,2,),)/1000 -> 76 | K12: =+IFERROR(HLOOKUP($B12,'[2]4월누계'!$F$6:$CP$99,2,),)/1000 -> 67.223 | L12: =+K12-J12 -> -8.777 | M12: =+IFERROR(HLOOKUP($B12,'[3]4월누계'!$F$6:$CC$57,2,),)/1000 -> 88.975 | N12: =+K12-M12 -> -21.752 | O12: =+IFERROR(HLOOKUP($B12,'[1]4월누계'!$D$6:$BN$259,3,),)/1000 -> 7546.8166 | P12: =+IFERROR(HLOOKUP($B12,'[2]4월누계'!$F$6:$CP$99,3,),)/1000 -> 6505.48 | Q12: =+P12-O12 -> -1041.3366 | R12: =+IFERROR(HLOOKUP($B12,'[3]4월누계'!$F$6:$CC$57,3,),)/1000 -> 8987.0293 | S12: =+P12-R12 -> -2481.5493 | T12: =+IFERROR(HLOOKUP($B12,'[1]4월누계'!$D$6:$BN$259,16,),)/1000 -> 603.16345 | U12: =+IFERROR(HLOOKUP($B12,'[2]4월누계'!$F$6:$CP$99,16,),)/1000 -> 414.88535 | V12: =+U12-T12 -> -188.2781 | W12: =+IFERROR(HLOOKUP($B12,'[3]4월누계'!$F$6:$CC$57,16,),)/1000 -> 1022.0486 | X12: =+U12-W12 -> -607.16329 | Y12: =+[9]서부산!$Q$85 -> 99300.219 | Z12: =+[9]서부산!$R$85 -> 96774.616 | AA12: =+[10]서부산!$Q$85 -> 101006.23 | AB12: =+[9]서부산!$Q$89 -> 78845.643 | AC12: =+[9]서부산!$R$89 -> 77141.006 | AD12: =+[10]서부산!$Q$89 -> 79548.427 | AE12: =+Y12-AB12 -> 20454.576 | AF12: =+Z12-AC12 -> 19633.61 | AG12: =+AA12-AD12 -> 21457.803
B13: 김해 | G13: =+I13 -> 김해 | I13: 김해 | J13: =+IFERROR(HLOOKUP($B13,'[1]4월누계'!$D$6:$BN$259,2,),)/1000 -> 52 | K13: =+IFERROR(HLOOKUP($B13,'[2]4월누계'!$F$6:$CP$99,2,),)/1000 -> 34.275 | L13: =+K13-J13 -> -17.725 | M13: =+IFERROR(HLOOKUP($B13,'[3]4월누계'!$F$6:$CC$57,2,),)/1000 -> 52.342 | N13: =+K13-M13 -> -18.067 | O13: =+IFERROR(HLOOKUP($B13,'[1]4월누계'!$D$6:$BN$259,3,),)/1000 -> 5007.6001 | P13: =+IFERROR(HLOOKUP($B13,'[2]4월누계'!$F$6:$CP$99,3,),)/1000 -> 3117.4157 | Q13: =+P13-O13 -> -1890.1844 | R13: =+IFERROR(HLOOKUP($B13,'[3]4월누계'!$F$6:$CC$57,3,),)/1000 -> 5200.4932 | S13: =+P13-R13 -> -2083.0775 | T13: =+IFERROR(HLOOKUP($B13,'[1]4월누계'!$D$6:$BN$259,16,),)/1000 -> 394.73605 | U13: =+IFERROR(HLOOKUP($B13,'[2]4월누계'!$F$6:$CP$99,16,),)/1000 -> -105.52443 | V13: =+U13-T13 -> -500.26048 | W13: =+IFERROR(HLOOKUP($B13,'[3]4월누계'!$F$6:$CC$57,16,),)/1000 -> 409.07598 | X13: =+U13-W13 -> -514.60041 | Y13: =+[9]김해!$Q$85 -> 96300.003 | Z13: =+[9]김해!$R$85 -> 90917.487 | AA13: =+[10]김해!$Q$85 -> 99460.374 | AB13: =+[9]김해!$Q$89 -> 76419.641 | AC13: =+[9]김해!$R$89 -> 76591.029 | AD13: =+[10]김해!$Q$89 -> 80371.435 | AE13: =+Y13-AB13 -> 19880.362 | AF13: =+Z13-AC13 -> 14326.458 | AG13: =+AA13-AD13 -> 19088.939
B14: 정관 | G14: =+I14 -> 정관 | I14: 정관 | J14: =+IFERROR(HLOOKUP($B14,'[1]4월누계'!$D$6:$BN$259,2,),)/1000 -> 76 | K14: =+IFERROR(HLOOKUP($B14,'[2]4월누계'!$F$6:$CP$99,2,),)/1000 -> 77.9715 | L14: =+K14-J14 -> 1.9715 | M14: =+IFERROR(HLOOKUP($B14,'[3]4월누계'!$F$6:$CC$57,2,),)/1000 -> 78.4445 | N14: =+K14-M14 -> -0.473 | O14: =+IFERROR(HLOOKUP($B14,'[1]4월누계'!$D$6:$BN$259,3,),)/1000 -> 7751.9834 | P14: =+IFERROR(HLOOKUP($B14,'[2]4월누계'!$F$6:$CP$99,3,),)/1000 -> 7962.4658 | Q14: =+P14-O14 -> 210.48236 | R14: =+IFERROR(HLOOKUP($B14,'[3]4월누계'!$F$6:$CC$57,3,),)/1000 -> 8063.9057 | S14: =+P14-R14 -> -101.43986 | T14: =+IFERROR(HLOOKUP($B14,'[1]4월누계'!$D$6:$BN$259,16,),)/1000 -> 622.11555 | U14: =+IFERROR(HLOOKUP($B14,'[2]4월누계'!$F$6:$CP$99,16,),)/1000 -> 647.1619 | V14: =+U14-T14 -> 25.04635 | W14: =+IFERROR(HLOOKUP($B14,'[3]4월누계'!$F$6:$CC$57,16,),)/1000 -> 785.513 | X14: =+U14-W14 -> -138.3511 | Y14: =+[9]정관!$Q$85 -> 101999.78 | Z14: =+[9]정관!$R$85 -> 102120.21 | AA14: =+[10]정관!$Q$85 -> 102797.59 | AB14: =+[9]정관!$Q$89 -> 81952.254 | AC14: =+[9]정관!$R$89 -> 84055.178 | AD14: =+[10]정관!$Q$89 -> 82725.871 | AE14: =+Y14-AB14 -> 20047.528 | AF14: =+Z14-AC14 -> 18065.03 | AG14: =+AA14-AD14 -> 20071.721
