Workbook

Sheet 표지
A6: 2025년 10월 마감 손익
A24: 건재사업본부

Sheet 손익총괄
C3: □ 건재사업본부 손익실적(2025-10)
X4: [단위 : 천㎥, 톤, 원/㎥, 원/톤, 백만원]
C5: 구분 | E5: 10월 | J5: 10월 누계 | P5: 10월 주요지표
E6: 계획 | F6: 실적 | G6: 계획대비 | H6: 전년 | I6: 전년대비 | J6: 계획 | K6: 실적 | L6: 계획대비 | M6: 전년 | N6: 전년대비
C7: 물량 | D7: 레미콘 | E7: =+'[1]10월'!$Z$7/1000 -> 276 | F7: =+'[2]10월'!$Z$7/1000 -> 215.288 | G7: =+F7-E7 -> -60.712 | H7: =+'[3]10월'!$Z$7/1000 -> 296.557 | I7: =+F7-H7 -> -81.269 | J7: =+'[1]10월누계'!$Z$7/1000 -> 2714.5 | K7: =+'[2]10월누계'!$Z$7/1000 -> 2318.6968 | L7: =+K7-J7 -> -395.80318 | M7: =+'[3]10월누계'!$Z$7/1000 -> 2825.2705 | N7: =+K7-M7 -> -506.57368 | Q7: □ 레미콘
D8: 철강재 | E8: =+'[1]10월'!$AA$7 -> 11000 | F8: =+'[2]10월'!$AO$7 -> 6655.619 | G8: =+F8-E8 -> -4344.381 | H8: =+'[3]10월'!$AO$7 -> 8972.008 | I8: =+F8-H8 -> -2316.389 | J8: =+'[1]10월누계'!$AA$7 -> 111900 | K8: =+'[2]10월누계'!$AO$7 -> 91549.474 | L8: =+K8-J8 -> -20350.526 | M8: =+'[3]10월누계'!$AO$7 -> 86939.352 | N8: =+K8-M8 -> 4610.122 | Q8: 구분 | S8: 계획 | T8: 실적 | U8: 계획대비 | V8: 전년 | W8: 전년대비
D9: 골재 | E9: =+'[1]10월'!$AE$7/1000 -> 108.21768 | F9: =+'[2]10월'!$AN$7/1000 -> 66.589 | G9: =+F9-E9 -> -41.628677 | H9: =+'[3]10월'!$AN$7/1000 -> 60.09 | I9: =+F9-H9 -> 6.499 | J9: =+'[1]10월누계'!$AE$7/1000 -> 971.46376 | K9: =+'[2]10월누계'!$AN$7/1000 -> 650.032 | L9: =+K9-J9 -> -321.43176 | M9: =+'[3]10월누계'!$AN$7/1000 -> 714.305 | N9: =+K9-M9 -> -64.273 | Q9: 물량 | R9: 수도권 | S9: =+[4]수도권!$T$5/1000 -> 96 | T9: =+[4]수도권!$U$5/1000 -> 79.0215 | U9: =+T9-S9 -> -16.9785 | V9: =+[5]수도권!$T$5/1000 -> 103.91 | W9: =+T9-V9 -> -24.8885
C10: 매출 | D10: 레미콘 | E10: =+'[1]10월'!$Z$8/1000 -> 28067.332 | F10: =+'[2]10월'!$Z$8/1000 -> 21143.952 | G10: =+F10-E10 -> -6923.3804 | H10: =+'[3]10월'!$Z$8/1000 -> 28528.552 | I10: =+F10-H10 -> -7384.5995 | J10: =+'[1]10월누계'!$Z$8/1000 -> 273817.95 | K10: =+'[2]10월누계'!$Z$8/1000 -> 228002.41 | L10: =+K10-J10 -> -45815.533 | M10: =+'[3]10월누계'!$Z$8/1000 -> 284322.86 | N10: =+K10-M10 -> -56320.447 | R10: 영남권 | S10: =+[4]영남권!$T$5/1000 -> 126.5 | T10: =+[4]영남권!$U$5/1000 -> 89.7445 | U10: =+T10-S10 -> -36.7555 | V10: =+[5]영남권!$T$5/1000 -> 130.221 | W10: =+T10-V10 -> -40.4765
D11: 건자재 | E11: =+'[1]10월'!$AA$8/1000 -> 11978.569 | F11: =+'[2]10월'!$AO$8/1000 -> 6923.7765 | G11: =+F11-E11 -> -5054.7921 | H11: =+'[3]10월'!$AO$8/1000 -> 8678.6853 | I11: =+F11-H11 -> -1754.9088 | J11: =+'[1]10월누계'!$AA$8/1000 -> 122183.48 | K11: =+'[2]10월누계'!$AO$8/1000 -> 83821.367 | L11: =+K11-J11 -> -38362.111 | M11: =+'[3]10월누계'!$AO$8/1000 -> 86611.076 | N11: =+K11-M11 -> -2789.7098 | R11: 중부권 | S11: =+[4]중부권!$T$5/1000 -> 53.5 | T11: =+[4]중부권!$U$5/1000 -> 46.522 | U11: =+T11-S11 -> -6.978 | V11: =+[5]중부권!$T$5/1000 -> 62.426 | W11: =+T11-V11 -> -15.904
D12: 골재 | E12: =+'[1]10월'!$AE$8/1000 -> 1946.6595 | F12: =+'[2]10월'!$AN$8/1000 -> 1260.9058 | G12: =+F12-E12 -> -685.75369 | H12: =+'[3]10월'!$AN$8/1000 -> 1245.8185 | I12: =+F12-H12 -> 15.0873 | J12: =+'[1]10월누계'!$AE$8/1000 -> 17893.215 | K12: =+'[2]10월누계'!$AN$8/1000 -> 13338.195 | L12: =+K12-J12 -> -4555.0199 | M12: =+'[3]10월누계'!$AN$8/1000 -> 14375.604 | N12: =+K12-M12 -> -1037.4093 | Q12: 계 | S12: =SUM(S9:S11) -> 276 | T12: =SUM(T9:T11) -> 215.288 | U12: =+T12-S12 -> -60.712 | V12: =SUM(V9:V11) -> 296.557 | W12: =+T12-V12 -> -81.269
D13: 기타 | E13: =+'[1]10월'!$E$8/1000-E10-E11-E12 -> 143.02817 | F13: =+'[2]10월'!$F$8/1000-F10-F11-F12 -> 119.2792 | G13: =+F13-E13 -> -23.748963 | H13: =+'[3]10월'!$F$8/1000-H10-H11-H12 -> 166.49562 | I13: =+F13-H13 -> -47.216417 | J13: =+'[1]10월누계'!$E$8/1000-J10-J11-J12 -> 1499.5017 | K13: =+'[2]10월누계'!$F$8/1000-K10-K11-K12 -> 1305.1644 | L13: =+K13-J13 -> -194.33725 | M13: =+'[3]10월누계'!$F$8/1000-M10-M11-M12 -> 1656.371 | N13: =+K13-M13 -> -351.20654 | Q13: 판매단가 | R13: 수도권 | S13: =+[4]수도권!$T$61 -> 100069.32 | T13: =+[4]수도권!$U$61 -> 94672.854 | U13: =+T13-S13 -> -5396.4627 | V13: =+[5]수도권!$Q$85 -> 93480.666 | W13: =+T13-V13 -> 1192.1884
C14: 계 | E14: =SUM(E10:E13) -> 42135.589 | F14: =SUM(F10:F13) -> 29447.914 | G14: =+F14-E14 -> -12687.675 | H14: =SUM(H10:H13) -> 38619.551 | I14: =+F14-H14 -> -9171.6374 | J14: =SUM(J10:J13) -> 415394.14 | K14: =SUM(K10:K13) -> 326467.14 | L14: =+K14-J14 -> -88927.001 | M14: =SUM(M10:M13) -> 386965.91 | N14: =+K14-M14 -> -60498.773 | R14: 영남권 | S14: =+[4]영남권!$T$61 -> 100505.81 | T14: =+[4]영남권!$U$61 -> 99815.877 | U14: =+T14-S14 -> -689.93624 | V14: =+[5]영남권!$Q$85 -> 96016.649 | W14: =+T14-V14 -> 3799.2281
C15: 매출원가 | D15: 레미콘 | E15: =+('[1]10월'!$Z$10+'[1]10월'!$Z$19)/1000 -> 24415.691 | F15: =+('[2]10월'!$Z$10+'[2]10월'!$Z$19)/1000 -> 19873.591 | G15: =+F15-E15 -> -4542.1 | H15: =+('[3]10월'!$Z$10+'[3]10월'!$Z$19)/1000 -> 25663.485 | I15: =+F15-H15 -> -5789.8943 | J15: =+('[1]10월누계'!$Z$10+'[1]10월누계'!$Z$19)/1000 -> 241537.28 | K15: =+('[2]10월누계'!$Z$10+'[2]10월누계'!$Z$19)/1000 -> 209907.49 | L15: =+K15-J15 -> -31629.794 | M15: =+('[3]10월누계'!$Z$10+'[3]10월누계'!$Z$19)/1000 -> 247168.48 | N15: =+K15-M15 -> -37260.995 | R15: 중부권 | S15: =+[4]중부권!$T$61 -> 107414.82 | T15: =+[4]중부권!$U$61 -> 101081.36 | U15: =+T15-S15 -> -6333.4612 | V15: =+[5]중부권!$Q$85 -> 101095.66 | W15: =+T15-V15 -> -14.300635
D16: 건자재 | E16: =+('[1]10월'!$AA$10+'[1]10월'!$AA$19)/1000 -> 11655.607 | F16: =+('[2]10월'!$AO$10+'[2]10월'!$AO$19)/1000 -> 6793.6222 | G16: =+F16-E16 -> -4861.9846 | H16: =+('[3]10월'!$AO$10+'[3]10월'!$AO$19)/1000 -> 8468.1695 | I16: =+F16-H16 -> -1674.5473 | J16: =+('[1]10월누계'!$AA$10+'[1]10월누계'!$AA$19)/1000 -> 118884.99 | K16: =+('[2]10월누계'!$AO$10+'[2]10월누계'!$AO$19)/1000 -> 82384.711 | L16: =+K16-J16 -> -36500.277 | M16: =+('[3]10월누계'!$AO$10+'[3]10월누계'!$AO$19)/1000 -> 84700.154 | N16: =+K16-M16 -> -2315.4422 | Q16: 계 | S16: =+[4]합계!$T$61 -> 101693.23 | T16: =+[4]합계!$U$61 -> 98207.724 | U16: =+T16-S16 -> -3485.5095 | V16: =+[5]합계!$Q$85 -> 96197.561 | W16: =+T16-V16 -> 2010.1627
D17: 골재 | E17: =+('[1]10월'!$AE$10+'[1]10월'!$AE$19)/1000 -> 1690.0132 | F17: =+('[2]10월'!$AN$10+'[2]10월'!$AN$19)/1000 -> 1333.4911 | G17: =+F17-E17 -> -356.52211 | H17: =+('[3]10월'!$AN$10+'[3]10월'!$AN$19)/1000 -> 1321.95 | I17: =+F17-H17 -> 11.541121 | J17: =+('[1]10월누계'!$AE$10+'[1]10월누계'!$AE$19)/1000 -> 15687.078 | K17: =+('[2]10월누계'!$AN$10+'[2]10월누계'!$AN$19)/1000 -> 13681.213 | L17: =+K17-J17 -> -2005.8655 | M17: =+('[3]10월누계'!$AN$10+'[3]10월누계'!$AN$19)/1000 -> 13776.633 | N17: =+K17-M17 -> -95.420158 | Q17: 공헌이익 | R17: 수도권 | S17: =+[4]수도권!$Q$90 -> 18749.347 | T17: =+[4]수도권!$R$90 -> 13808.455 | U17: =+T17-S17 -> -4940.8925 | V17: =+[5]수도권!$Q$90 -> 12984.216 | W17: =+T17-V17 -> 824.23809
D18: 기타 | E18: =+('[1]10월'!$E$10+'[1]10월'!$E$19)/1000-E15-E16-E17 -> 68.375599 | F18: =+('[2]10월'!$F$10+'[2]10월'!$F$19)/1000-F15-F16-F17 -> -477.91892 | G18: =+F18-E18 -> -546.29452 | H18: =+('[3]10월'!$F$10+'[3]10월'!$F$19)/1000-H15-H16-H17 -> -220.72587 | I18: =+F18-H18 -> -257.19305 | J18: =+('[1]10월누계'!$E$10+'[1]10월누계'!$E$19)/1000-J15-J16-J17 -> 609.62376 | K18: =+('[2]10월누계'!$F$10+'[2]10월누계'!$F$19)/1000-K15-K16-K17 -> -18.518018 | L18: =+K18-J18 -> -628.14178 | M18: =+('[3]10월누계'!$F$10+'[3]10월누계'!$F$19)/1000-M15-M16-M17 -> -329.81756 | N18: =+K18-M18 -> 311.29954 | R18: 영남권 | S18: =+[4]영남권!$Q$90 -> 21578.581 | T18: =+[4]영남권!$R$90 -> 18101.069 | U18: =+T18-S18 -> -3477.5117 | V18: =+[5]영남권!$Q$90 -> 17824.891 | W18: =+T18-V18 -> 276.17846
C19: 계 | E19: =SUM(E15:E18) -> 37829.686 | F19: =SUM(F15:F18) -> 27522.785 | G19: =+F19-E19 -> -10306.901 | H19: =SUM(H15:H18) -> 35232.879 | I19: =+F19-H19 -> -7710.0936 | J19: =SUM(J15:J18) -> 376718.97 | K19: =SUM(K15:K18) -> 305954.89 | L19: =+K19-J19 -> -70764.078 | M19: =SUM(M15:M18) -> 345315.45 | N19: =+K19-M19 -> -39360.558 | R19: 중부권 | S19: =+[4]중부권!$Q$90 -> 29714.673 | T19: =+[4]중부권!$R$90 -> 21131.108 | U19: =+T19-S19 -> -8583.5654 | V19: =+[5]중부권!$Q$90 -> 25702.179 | W19: =+T19-V19 -> -4571.071
C20: 매출이익 | D20: 레미콘 | E20: =+E10-E15 -> 3651.6416 | F20: =+F10-F15 -> 1270.3612 | G20: =+F20-E20 -> -2381.2804 | H20: =+H10-H15 -> 2865.0663 | I20: =+F20-H20 -> -1594.7052 | J20: =+J10-J15 -> 32280.665 | K20: =+K10-K15 -> 18094.926 | L20: =+K20-J20 -> -14185.739 | M20: =+M10-M15 -> 37154.378 | N20: =+K20-M20 -> -19059.452 | Q20: 계 | S20: =+[4]합계!$Q$90 -> 22171.604 | T20: =+[4]합계!$R$90 -> 17185.695 | U20: =+T20-S20 -> -4985.9095 | V20: =+[5]합계!$Q$90 -> 17786.111 | W20: =+T20-V20 -> -600.41591
D21: 건자재 | E21: =+E11-E16 -> 322.9619 | F21: =+F11-F16 -> 130.15433 | G21: =+F21-E21 -> -192.80756 | H21: =+H11-H16 -> 210.51578 | I21: =+F21-H21 -> -80.361441 | J21: =+J11-J16 -> 3298.4888 | K21: =+K11-K16 -> 1436.655 | L21: =+K21-J21 -> -1861.8338 | M21: =+M11-M16 -> 1910.9227 | N21: =+K21-M21 -> -474.26766 | Q21: □ 건자재
D22: 골재 | E22: =+E12-E17 -> 256.64628 | F22: =+F12-F17 -> -72.585311 | G22: =+F22-E22 -> -329.23159 | H22: =+H12-H17 -> -76.13149 | I22: =+F22-H22 -> 3.546179 | J22: =+J12-J17 -> 2206.1364 | K22: =+K12-K17 -> -343.01793 | L22: =+K22-J22 -> -2549.1544 | M22: =+M12-M17 -> 598.97119 | N22: =+K22-M22 -> -941.98912 | Q22: 구분 | S22: 계획 | T22: 실적 | U22: 계획대비 | V22: 전년 | W22: 전년대비
D23: 기타 | E23: =+E13-E18 -> 74.652568 | F23: =+F13-F18 -> 597.19812 | G23: =+F23-E23 -> 522.54556 | H23: =+H13-H18 -> 387.22149 | I23: =+F23-H23 -> 209.97663 | J23: =+J13-J18 -> 889.87791 | K23: =+K13-K18 -> 1323.6824 | L23: =+K23-J23 -> 433.80453 | M23: =+M13-M18 -> 1986.1885 | N23: =+K23-M23 -> -662.50608 | Q23: 철강재 판매단가 | S23: =+'[6]10월'!$F$10 -> 872727.27 | T23: =+'[6]10월'!$G$10 -> 809127.48 | U23: =+T23-S23 -> -63599.792 | V23: =+'[7]10월'!$G$10 -> 818946.48 | W23: =+T23-V23 -> -9818.9971
C24: 계 | E24: =SUM(E20:E23) -> 4305.9023 | F24: =SUM(F20:F23) -> 1925.1283 | G24: =+F24-E24 -> -2380.774 | H24: =SUM(H20:H23) -> 3386.6721 | I24: =+F24-H24 -> -1461.5438 | J24: =SUM(J20:J23) -> 38675.168 | K24: =SUM(K20:K23) -> 20512.246 | L24: =+K24-J24 -> -18162.923 | M24: =SUM(M20:M23) -> 41650.461 | N24: =+K24-M24 -> -21138.215 | Q24: 철강재 마진률 | S24: =+'[6]10월'!$F$15 -> 0.023989583 | T24: =+'[6]10월'!$G$15 -> 0.015942638 | U24: =+T24-S24 -> -0.0080469456 | V24: =+'[6]10월'!$G$15 -> 0.015942638 | W24: =+T24-V24 -> 0
C25: 판관비 | D25: 레미콘 | E25: =+('[1]10월'!$Z$13+'[1]10월'!$Z$20)/1000 -> 659.01074 | F25: =+('[2]10월'!$Z$13+'[2]10월'!$Z$20)/1000 -> 718.50202 | G25: =+F25-E25 -> 59.49128 | H25: =+('[3]10월'!$Z$13+'[3]10월'!$Z$20)/1000 -> 723.79491 | I25: =+F25-H25 -> -5.292889 | J25: =+('[1]10월누계'!$Z$13+'[1]10월누계'!$Z$20)/1000 -> 6750.2884 | K25: =+('[2]10월누계'!$Z$13+'[2]10월누계'!$Z$20)/1000 -> 6902.5933 | L25: =+K25-J25 -> 152.30487 | M25: =+('[3]10월누계'!$Z$13+'[3]10월누계'!$Z$20)/1000 -> 6881.2415 | N25: =+K25-M25 -> 21.351793 | Q25: □ 골재
D26: 건자재 | E26: =+('[1]10월'!$AA$13+'[1]10월'!$AA$20)/1000 -> 122.90135 | F26: =+('[2]10월'!$AO$13+'[2]10월'!$AO$20)/1000 -> 167.24112 | G26: =+F26-E26 -> 44.339772 | H26: =+('[3]10월'!$AO$13+'[3]10월'!$AO$20)/1000 -> 166.51045 | I26: =+F26-H26 -> 0.730673 | J26: =+('[1]10월누계'!$AA$13+'[1]10월누계'!$AA$20)/1000 -> 1283.2562 | K26: =+('[2]10월누계'!$AO$13+'[2]10월누계'!$AO$20)/1000 -> 1513.4051 | L26: =+K26-J26 -> 230.14897 | M26: =+('[3]10월누계'!$AO$13+'[3]10월누계'!$AO$20)/1000 -> 1427.419 | N26: =+K26-M26 -> 85.986169 | Q26: 구분 | S26: 계획 | T26: 실적 | U26: 계획대비 | V26: 전년 | W26: 전년대비
D27: 골재 | E27: =+('[1]10월'!$AE$13+'[1]10월'!$AE$20+'[1]10월'!$AE$22)/1000 -> 46.829551 | F27: =+('[2]10월'!$AN$13+'[2]10월'!$AN$20+'[2]10월'!$AN$22)/1000 -> 50.038114 | G27: =+F27-E27 -> 3.2085631 | H27: =+('[3]10월'!$AN$13+'[3]10월'!$AN$20+'[3]10월'!$AN$22)/1000 -> 73.826361 | I27: =+F27-H27 -> -23.788247 | J27: =+('[1]10월누계'!$AE$13+'[1]10월누계'!$AE$20+'[1]10월누계'!$AE$22)/1000 -> 481.9607 | K27: =+('[2]10월누계'!$AN$13+'[2]10월누계'!$AN$20+'[2]10월누계'!$AN$22)/1000 -> 483.51512 | L27: =+K27-J27 -> 1.5544184 | M27: =+('[3]10월누계'!$AN$13+'[3]10월누계'!$AN$20+'[3]10월누계'!$AN$22)/1000 -> 602.96645 | N27: =+K27-M27 -> -119.45133 | Q27: 판매량 | R27: 자가 | S27: =+[8]원가손익!$W$10+[9]원가손익!$W$13+[10]손익!$F$10 -> 56217.677 | T27: =+[8]원가손익!$X$10+[9]원가손익!$X$13+[10]손익!$G$10 -> 43690 | U27: =+T27-S27 -> -12527.677 | V27: =+'[11]부산모래장(당월)'!$S$85 -> 38555 | W27: =+T27-V27 -> 5135
D28: 기타 | E28: =+('[1]10월'!$E$13+'[1]10월'!$E$20)/1000-E25-E26-E27+('[1]10월'!$E$22/1000) -> 1452.1673 | F28: =+('[2]10월'!$F$13+'[2]10월'!$F$20)/1000-F25-F26-F27+'[2]10월'!$F$22/1000 -> 1426.935 | G28: =+F28-E28 -> -25.23234 | H28: =+('[3]10월'!$F$13+'[3]10월'!$F$20)/1000-H25-H26-H27+'[3]10월'!$F$22/1000 -> 1248.3048 | I28: =+F28-H28 -> 178.6302 | J28: =+('[1]10월누계'!$E$13+'[1]10월누계'!$E$20)/1000-J25-J26-J27+('[1]10월누계'!$E$22/1000) -> 15975.674 | K28: =+('[2]10월누계'!$F$13+'[2]10월누계'!$F$20)/1000-K25-K26-K27+'[2]10월누계'!$F$22/1000 -> 17760.446 | L28: =+K28-J28 -> 1784.7715 | M28: =+('[3]10월누계'!$F$13+'[3]10월누계'!$F$20)/1000-M25-M26-M27+'[3]10월누계'!$F$22/1000 -> 15191.733 | N28: =+K28-M28 -> 2568.7128 | R28: 외판 | S28: =+[8]원가손익!$W$14+[9]원가손익!$W$15+[10]손익!$F$12 -> 52000 | T28: =+[8]원가손익!$X$14+[9]원가손익!$X$15+[10]손익!$G$12 -> 22899 | U28: =+T28-S28 -> -29101 | V28: =+'[11]부산모래장(당월)'!$S$86 -> 21535 | W28: =+T28-V28 -> 1364
C29: 계 | E29: =SUM(E25:E28) -> 2280.909 | F29: =SUM(F25:F28) -> 2362.7162 | G29: =+F29-E29 -> 81.807276 | H29: =SUM(H25:H28) -> 2212.4365 | I29: =+F29-H29 -> 150.27974 | J29: =SUM(J25:J28) -> 24491.18 | K29: =SUM(K25:K28) -> 26659.959 | L29: =+K29-J29 -> 2168.7798 | M29: =SUM(M25:M28) -> 24103.36 | N29: =+K29-M29 -> 2556.5994 | Q29: 합 계 | S29: =SUM(S27:S28) -> 108217.68 | T29: =SUM(T27:T28) -> 66589 | U29: =+T29-S29 -> -41628.677 | V29: =SUM(V27:V28) -> 60090 | W29: =+T29-V29 -> 6499
C30: 영업이익 | D30: 레미콘 | E30: =+E20-E25 -> 2992.6308 | F30: =+F20-F25 -> 551.85915 | G30: =+F30-E30 -> -2440.7717 | H30: =+H20-H25 -> 2141.2714 | I30: =+F30-H30 -> -1589.4123 | J30: =+J20-J25 -> 25530.377 | K30: =+K20-K25 -> 11192.333 | L30: =+K30-J30 -> -14338.044 | M30: =+M20-M25 -> 30273.137 | N30: =+K30-M30 -> -19080.804 | Q30: □ 기타내역(영업이익)
D31: % | E31: =+E30/E10 -> 0.10662327 | F31: =+F30/F10 -> 0.026100094 | G31: =+F31-E31 -> -0.080523178 | H31: =+H30/H10 -> 0.075057138 | I31: =+F31-H31 -> -0.048957044 | J31: =+J30/J10 -> 0.093238508 | K31: =+K30/K10 -> 0.049088659 | L31: =+K31-J31 -> -0.044149849 | M31: =+M30/M10 -> 0.10647451 | N31: =+K31-M31 -> -0.057385849 | Q31: 구분 | S31: 계획 | T31: 실적 | U31: 계획대비 | V31: 전년 | W31: 전년대비
D32: 건자재 | E32: =+E21-E26 -> 200.06055 | F32: =+F21-F26 -> -37.086785 | G32: =+F32-E32 -> -237.14733 | H32: =+H21-H26 -> 44.005329 | I32: =+F32-H32 -> -81.092114 | J32: =+J21-J26 -> 2015.2326 | K32: =+K21-K26 -> -76.750134 | L32: =+K32-J32 -> -2091.9828 | M32: =+M21-M26 -> 483.5037 | N32: =+K32-M32 -> -560.25383 | Q32: 레미콘임대 | S32: =+'사업장별(당월)'!T33 -> 48.278888 | T32: =+'사업장별(당월)'!U33 -> 23.592101 | U32: =+T32-S32 -> -24.686787 | V32: =+'사업장별(당월)'!W33 -> 71.16796 | W32: =+T32-V32 -> -47.575859
D33: 골재 | E33: =+E22-E27 -> 209.81672 | F33: =+F22-F27 -> -122.62343 | G33: =+F33-E33 -> -332.44015 | H33: =+H22-H27 -> -149.95785 | I33: =+F33-H33 -> 27.334426 | J33: =+J22-J27 -> 1724.1757 | K33: =+K22-K27 -> -826.53304 | L33: =+K33-J33 -> -2550.7088 | M33: =+M22-M27 -> -3.9952527 | N33: =+K33-M33 -> -822.53779 | Q33: 임대 | S33: =+'사업장별(당월)'!T34 -> 64.441 | T33: =+'사업장별(당월)'!U34 -> 66.994835 | U33: =+T33-S33 -> 2.553835 | V33: =+'사업장별(당월)'!W34 -> 63.705665 | W33: =+T33-V33 -> 3.28917
D34: 기타 | E34: =+E23-E28 -> -1377.5148 | F34: =+F23-F28 -> -829.73686 | G34: =+F34-E34 -> 547.7779 | H34: =+H23-H28 -> -861.08329 | I34: =+F34-H34 -> 31.346433 | J34: =+J23-J28 -> -15085.796 | K34: =+K23-K28 -> -16436.763 | L34: =+K34-J34 -> -1350.967 | M34: =+M23-M28 -> -13205.544 | N34: =+K34-M34 -> -3231.2189 | Q34: 공통비 | S34: =+'사업장별(당월)'!T35 -> -1372.5528 | T34: =+'사업장별(당월)'!U35 -> -1374.3193 | U34: =+T34-S34 -> -1.7665445 | V34: =+'사업장별(당월)'!W35 -> -1196.5785 | W34: =+T34-V34 -> -177.74081
C35: 계 | E35: =SUM(E30,E32:E34) -> 2024.9934 | F35: =SUM(F30,F32:F34) -> -437.58792 | G35: =+F35-E35 -> -2462.5813 | H35: =SUM(H30,H32:H34) -> 1174.2356 | I35: =+F35-H35 -> -1611.8235 | J35: =SUM(J30,J32:J34) -> 14183.989 | K35: =SUM(K30,K32:K34) -> -6147.7137 | L35: =+K35-J35 -> -20331.703 | M35: =SUM(M30,M32:M34) -> 17547.101 | N35: =+K35-M35 -> -23694.815 | Q35: 기타 | S35: =+S36-S32-S33-S34 -> -117.68187 | T35: =+T36-T32-T33-T34 -> 453.99552 | U35: =+T35-S35 -> 571.67739 | V35: =+V36-V32-V33-V34 -> 200.62159 | W35: =+T35-V35 -> 253.37393
D36: % | E36: =+E35/E14 -> 0.048058979 | F36: =+F35/F14 -> -0.014859726 | G36: =+F36-E36 -> -0.062918705 | H36: =+H35/H14 -> 0.030405212 | I36: =+F36-H36 -> -0.045264938 | J36: =+J35/J14 -> 0.034145857 | K36: =+K35/K14 -> -0.018831034 | L36: =+K36-J36 -> -0.052976891 | M36: =+M35/M14 -> 0.04534534 | N36: =+K36-M36 -> -0.064176374 | Q36: 합계 | S36: =+'사업장별(당월)'!T41 -> -1377.5148 | T36: =+'사업장별(당월)'!U41 -> -829.73686 | U36: =+T36-S36 -> 547.7779 | V36: =+'사업장별(당월)'!W41 -> -861.08329 | W36: =+T36-V36 -> 31.346433
E38: =+'[1]10월'!$E$26/1000 -> 2024.9934 | F38: =+'[2]10월'!$F$26/1000 -> -437.58792 | H38: =+'[3]10월'!$F$26/1000 -> 1174.2356 | J38: =+'[1]10월누계'!$E$26/1000 -> 14183.989 | K38: =+'[2]10월누계'!$F$26/1000 -> -6147.7137 | M38: =+'[3]10월누계'!$F$26/1000 -> 17547.101
E39: =+E35=E38 -> TRUE | F39: =+F35=F38 -> FALSE | H39: =+H35=H38 -> FALSE | J39: =+J35=J38 -> TRUE | K39: =+K35=K38 -> FALSE | M39: =+M35=M38 -> TRUE
E40: =+E35-E38 -> 0 | F40: =+F35-F38 -> 0 | H40: =+H35-H38 -> -6.5938366e-12 | J40: =+J35-J38 -> 1.8189894e-11 | K40: =+K35-K38 -> -1.9099389e-11 | M40: =+M35-M38 -> 0

Sheet 레미콘 영업이익
H3: □ 레미콘 영업이익(10월)
H5: 구분 | J5: 10월 | T5: 10월누계
J6: 영업이익(공통비 배부전) | O6: 영업이익(공통비 배부후) | T6: 영업이익(공통비 배부전) | Y6: 영업이익(공통비 배부전)
A7: 2024년 10월 마감 손익 | J7: 계획 | K7: 실적 | L7: 차이 | M7: 전년 | N7: 차이 | O7: 계획 | P7: 실적 | Q7: 차이 | R7: 전년 | S7: 차이 | T7: 계획 | U7: 실적 | V7: 차이 | W7: 전년 | X7: 차이 | Y7: 계획 | Z7: 실적 | AA7: 차이 | AB7: 전년 | AC7: 차이
B8: 안양 | H8: 레미콘 | I8: 안양 | J8: =+[4]안양!$H$86/1000 -> 415.60971 | K8: =+[4]안양!$I$86/1000 -> 233.33186 | L8: =+K8-J8 -> -182.27785 | M8: =+[5]안양!$H$86/1000 -> 151.42127 | N8: =+K8-M8 -> 81.910587 | O8: =+[4]안양!$H$92/1000 -> 241.20644 | P8: =+[4]안양!$I$92/1000 -> 54.097811 | Q8: =+P8-O8 -> -187.10863 | R8: =+[5]안양!$H$92/1000 -> -2.8503994 | S8: =+P8-R8 -> 56.948211 | T8: =+[12]안양!$H$86/1000 -> 3527.0401 | U8: =+[12]안양!$I$86/1000 -> 2176.8926 | V8: =+U8-T8 -> -1350.1475 | W8: =+[13]안양!$H$86/1000 -> 3495.1512 | X8: =+U8-W8 -> -1318.2586 | Y8: =+[12]안양!$H$92/1000 -> 1425.5418 | Z8: =+[12]안양!$I$92/1000 -> 130.18959 | AA8: =+Z8-Y8 -> -1295.3522 | AB8: =+[13]안양!$H$92/1000 -> 1667.0725 | AC8: =+Z8-AB8 -> -1536.8829
B9: 인천 | H9: 직영 | I9: 인천 | J9: =+[4]인천!$H$86/1000 -> 237.49324 | K9: =+[4]인천!$I$86/1000 -> -104.18711 | L9: =+K9-J9 -> -341.68035 | M9: =+[5]인천!$H$86/1000 -> 63.89366 | N9: =+K9-M9 -> -168.08077 | O9: =+[4]인천!$H$92/1000 -> 105.58774 | P9: =+[4]인천!$I$92/1000 -> -258.70732 | Q9: =+P9-O9 -> -364.29506 | R9: =+[5]인천!$H$92/1000 -> -43.296751 | S9: =+P9-R9 -> -215.41057 | T9: =+[12]인천!$H$86/1000 -> 1485.5092 | U9: =+[12]인천!$I$86/1000 -> 144.14426 | V9: =+U9-T9 -> -1341.365 | W9: =+[13]인천!$H$86/1000 -> 1662.3617 | X9: =+U9-W9 -> -1518.2174 | Y9: =+[12]인천!$H$92/1000 -> -37.271588 | Z9: =+[12]인천!$I$92/1000 -> -1569.5084 | AA9: =+Z9-Y9 -> -1532.2368 | AB9: =+[13]인천!$H$92/1000 -> 345.22383 | AC9: =+Z9-AB9 -> -1914.7322
B10: 파주 | I10: 파주 | J10: =+[4]파주!$H$86/1000 -> 90.273885 | K10: =+[4]파주!$I$86/1000 -> -62.289172 | L10: =+K10-J10 -> -152.56306 | M10: =+[5]파주!$H$86/1000 -> 73.448678 | N10: =+K10-M10 -> -135.73785 | O10: =+[4]파주!$H$92/1000 -> -8.6466815 | P10: =+[4]파주!$I$92/1000 -> -143.41219 | Q10: =+P10-O10 -> -134.76551 | R10: =+[5]파주!$H$92/1000 -> -23.888845 | S10: =+P10-R10 -> -119.52335 | T10: =+[12]파주!$H$86/1000 -> 1015.1017 | U10: =+[12]파주!$I$86/1000 -> -405.52211 | V10: =+U10-T10 -> -1420.6238 | W10: =+[13]파주!$H$86/1000 -> 1693.9687 | X10: =+U10-W10 -> -2099.4908 | Y10: =+[12]파주!$H$92/1000 -> -89.683153 | Z10: =+[12]파주!$I$92/1000 -> -1187.0911 | AA10: =+Z10-Y10 -> -1097.408 | AB10: =+[13]파주!$H$92/1000 -> 511.36048 | AC10: =+Z10-AB10 -> -1698.4516
B11: 김포 | I11: 김포 | J11: =+[4]김포!$H$86/1000 -> 84.478737 | K11: =+[4]김포!$I$86/1000 -> 5.850372 | L11: =+K11-J11 -> -78.628365 | M11: =+[5]김포!$H$86/1000 -> 74.662069 | N11: =+K11-M11 -> -68.811697 | O11: =+[4]김포!$H$92/1000 -> 19.339222 | P11: =+[4]김포!$I$92/1000 -> -52.509407 | Q11: =+P11-O11 -> -71.848629 | R11: =+[5]김포!$H$92/1000 -> 26.523305 | S11: =+P11-R11 -> -79.032712 | T11: =+[12]김포!$H$86/1000 -> 855.98466 | U11: =+[12]김포!$I$86/1000 -> -44.558193 | V11: =+U11-T11 -> -900.54285 | W11: =+[13]김포!$H$86/1000 -> 935.79926 | X11: =+U11-W11 -> -980.35746 | Y11: =+[12]김포!$H$92/1000 -> 128.06084 | Z11: =+[12]김포!$I$92/1000 -> -758.58701 | AA11: =+Z11-Y11 -> -886.64785 | AB11: =+[13]김포!$H$92/1000 -> 400.27238 | AC11: =+Z11-AB11 -> -1158.8594
B12: 부산 | I12: 부산 | J12: =+[4]부산!$H$86/1000 -> 166.34786 | K12: =+[4]부산!$I$86/1000 -> 113.69739 | L12: =+K12-J12 -> -52.650466 | M12: =+[5]부산!$H$86/1000 -> 57.651193 | N12: =+K12-M12 -> 56.046198 | O12: =+[4]부산!$H$92/1000 -> 64.628994 | P12: =+[4]부산!$I$92/1000 -> -17.122379 | Q12: =+P12-O12 -> -81.751373 | R12: =+[5]부산!$H$92/1000 -> -16.70386 | S12: =+P12-R12 -> -0.41851891 | T12: =+[12]부산!$H$86/1000 -> 1796.6635 | U12: =+[12]부산!$I$86/1000 -> 1889.3757 | V12: =+U12-T12 -> 92.712144 | W12: =+[13]부산!$H$86/1000 -> 2050.9055 | X12: =+U12-W12 -> -161.52985 | Y12: =+[12]부산!$H$92/1000 -> 582.71718 | Z12: =+[12]부산!$I$92/1000 -> 456.02029 | AA12: =+Z12-Y12 -> -126.69689 | AB12: =+[13]부산!$H$92/1000 -> 990.12735 | AC12: =+Z12-AB12 -> -534.10707
B13: 서부산 | I13: 서부산 | J13: =+[4]서부산!$H$86/1000 -> 178.71898 | K13: =+[4]서부산!$I$86/1000 -> 182.61007 | L13: =+K13-J13 -> 3.8910847 | M13: =+[5]서부산!$H$86/1000 -> 132.60606 | N13: =+K13-M13 -> 50.004007 | O13: =+[4]서부산!$H$92/1000 -> 84.933276 | P13: =+[4]서부산!$I$92/1000 -> 45.122991 | Q13: =+P13-O13 -> -39.810285 | R13: =+[5]서부산!$H$92/1000 -> 52.377763 | S13: =+P13-R13 -> -7.2547715 | T13: =+[12]서부산!$H$86/1000 -> 1812.3444 | U13: =+[12]서부산!$I$86/1000 -> 1190.6673 | V13: =+U13-T13 -> -621.67712 | W13: =+[13]서부산!$H$86/1000 -> 2290.6041 | X13: =+U13-W13 -> -1099.9368 | Y13: =+[12]서부산!$H$92/1000 -> 714.67713 | Z13: =+[12]서부산!$I$92/1000 -> 30.72516 | AA13: =+Z13-Y13 -> -683.95197 | AB13: =+[13]서부산!$H$92/1000 -> 1237.0225 | AC13: =+Z13-AB13 -> -1206.2974
B14: 김해 | I14: 김해 | J14: =+[4]김해!$H$86/1000 -> 147.10502 | K14: =+[4]김해!$I$86/1000 -> -38.691111 | L14: =+K14-J14 -> -185.79613 | M14: =+[5]김해!$H$86/1000 -> 10.398047 | N14: =+K14-M14 -> -49.089158 | O14: =+[4]김해!$H$92/1000 -> 70.514076 | P14: =+[4]김해!$I$92/1000 -> -81.086159 | Q14: =+P14-O14 -> -151.60023 | R14: =+[5]김해!$H$92/1000 -> -42.669719 | S14: =+P14-R14 -> -38.416439 | T14: =+[12]김해!$H$86/1000 -> 1156.3373 | U14: =+[12]김해!$I$86/1000 -> -347.12308 | V14: =+U14-T14 -> -1503.4604 | W14: =+[13]김해!$H$86/1000 -> 720.05566 | X14: =+U14-W14 -> -1067.1787 | Y14: =+[12]김해!$H$92/1000 -> 392.15214 | Z14: =+[12]김해!$I$92/1000 -> -922.49373 | AA14: =+Z14-Y14 -> -1314.6459 | AB14: =+[13]김해!$H$92/1000 -> 80.018337 | AC14: =+Z14-AB14 -> -1002.5121
B15: 정관 | I15: 정관 | J15: =+[4]정관!$H$86/1000 -> 140.96725 | K15: =+[4]정관!$I$86/1000 -> 70.235029 | L15: =+K15-J15 -> -70.732224 | M15: =+[5]정관!$H$86/1000 -> 142.76763 | N15: =+K15-M15 -> -72.532597 | O15: =+[4]정관!$H$92/1000 -> 49.701762 | P15: =+[4]정관!$I$92/1000 -> -51.391856 | Q15: =+P15-O15 -> -101.09362 | R15: =+[5]정관!$H$92/1000 -> 51.510287 | S15: =+P15-R15 -> -102.90214 | T15: =+[12]정관!$H$86/1000 -> 1561.2825 | U15: =+[12]정관!$I$86/1000 -> 1707.6805 | V15: =+U15-T15 -> 146.39795 | W15: =+[13]정관!$H$86/1000 -> 1743.0186 | X15: =+U15-W15 -> -35.338078 | Y15: =+[12]정관!$H$92/1000 -> 456.92817 | Z15: =+[12]정관!$I$92/1000 -> 288.98611 | AA15: =+Z15-Y15 -> -167.94206 | AB15: =+[13]정관!$H$92/1000 -> 744.50983 | AC15: =+Z15-AB15 -> -455.52372
B16: 양산 | I16: 양산 | J16: =+[4]양산!$H$86/1000 -> 111.54797 | K16: =+[4]양산!$I$86/1000 -> -76.735298 | L16: =+K16-J16 -> -188.28327 | M16: =+[5]양산!$H$86/1000 -> 152.35462 | N16: =+K16-M16 -> -229.08992 | O16: =+[4]양산!$H$92/1000 -> 55.249923 | P16: =+[4]양산!$I$92/1000 -> -100.08864 | Q16: =+P16-O16 -> -155.33856 | R16: =+[5]양산!$H$92/1000 -> 96.056728 | S16: =+P16-R16 -> -196.14537 | T16: =+[12]양산!$H$86/1000 -> 915.4781 | U16: =+[12]양산!$I$86/1000 -> -109.57679 | V16: =+U16-T16 -> -1025.0549 | W16: =+[13]양산!$H$86/1000 -> 1086.1549 | X16: =+U16-W16 -> -1195.7317 | Y16: =+[12]양산!$H$92/1000 -> 297.55153 | Z16: =+[12]양산!$I$92/1000 -> -526.25696 | AA16: =+Z16-Y16 -> -823.80848 | AB16: =+[13]양산!$H$92/1000 -> 495.49241 | AC16: =+Z16-AB16 -> -1021.7494
B17: 창원 | I17: 창원 | J17: =+[4]창원!$H$86/1000 -> 251.9365 | K17: =+[4]창원!$I$86/1000 -> -42.600381 | L17: =+K17-J17 -> -294.53688 | M17: =+[5]창원!$H$86/1000 -> 76.578861 | N17: =+K17-M17 -> -119.17924 | O17: =+[4]창원!$H$92/1000 -> 162.3712 | P17: =+[4]창원!$I$92/1000 -> -89.113415 | Q17: =+P17-O17 -> -251.48461 | R17: =+[5]창원!$H$92/1000 -> 18.191434 | S17: =+P17-R17 -> -107.30485 | T17: =+[12]창원!$H$86/1000 -> 1103.6293 | U17: =+[12]창원!$I$86/1000 -> 236.56988 | V17: =+U17-T17 -> -867.0594 | W17: =+[13]창원!$H$86/1000 -> 2438.7701 | X17: =+U17-W17 -> -2202.2002 | Y17: =+[12]창원!$H$92/1000 -> 410.49496 | Z17: =+[12]창원!$I$92/1000 -> -386.37952 | AA17: =+Z17-Y17 -> -796.87447 | AB17: =+[13]창원!$H$92/1000 -> 1562.0491 | AC17: =+Z17-AB17 -> -1948.4286
B18: 대구 | I18: 대구 | J18: =+[4]대구!$H$86/1000 -> 112.89939 | K18: =+[4]대구!$I$86/1000 -> -60.636872 | L18: =+K18-J18 -> -173.53626 | M18: =+[5]대구!$H$86/1000 -> 100.63415 | N18: =+K18-M18 -> -161.27102 | O18: =+[4]대구!$H$92/1000 -> 54.887798 | P18: =+[4]대구!$I$92/1000 -> -100.6668 | Q18: =+P18-O18 -> -155.5546 | R18: =+[5]대구!$H$92/1000 -> 37.610825 | S18: =+P18-R18 -> -138.27763 | T18: =+[12]대구!$H$86/1000 -> 1077.9801 | U18: =+[12]대구!$I$86/1000 -> 24.142329 | V18: =+U18-T18 -> -1053.8378 | W18: =+[13]대구!$H$86/1000 -> 2216.7039 | X18: =+U18-W18 -> -2192.5615 | Y18: =+[12]대구!$H$92/1000 -> 404.55314 | Z18: =+[12]대구!$I$92/1000 -> -510.9418 | AA18: =+Z18-Y18 -> -915.49494 | AB18: =+[13]대구!$H$92/1000 -> 1431.636 | AC18: =+Z18-AB18 -> -1942.5778
B19: 울산 | I19: 울산 | J19: =+[4]울산!$H$86/1000 -> 135.82855 | K19: =+[4]울산!$I$86/1000 -> 31.565002 | L19: =+K19-J19 -> -104.26355 | M19: =+[5]울산!$H$86/1000 -> 157.77048 | N19: =+K19-M19 -> -126.20548 | O19: =+[4]울산!$H$92/1000 -> 71.069244 | P19: =+[4]울산!$I$92/1000 -> -29.596118 | Q19: =+P19-O19 -> -100.66536 | R19: =+[5]울산!$H$92/1000 -> 96.676348 | S19: =+P19-R19 -> -126.27247 | T19: =+[12]울산!$H$86/1000 -> 947.24573 | U19: =+[12]울산!$I$86/1000 -> 916.16564 | V19: =+U19-T19 -> -31.080087 | W19: =+[13]울산!$H$86/1000 -> 1238.1898 | X19: =+U19-W19 -> -322.02419 | Y19: =+[12]울산!$H$92/1000 -> 252.60568 | Z19: =+[12]울산!$I$92/1000 -> 262.91331 | AA19: =+Z19-Y19 -> 10.307628 | AB19: =+[13]울산!$H$92/1000 -> 657.34379 | AC19: =+Z19-AB19 -> -394.43047
B20: 아산 | I20: 아산 | J20: =+[4]아산!$H$86/1000 -> 281.74952 | K20: =+[4]아산!$I$86/1000 -> 68.467208 | L20: =+K20-J20 -> -213.28232 | M20: =+[5]아산!$H$86/1000 -> 518.14114 | N20: =+K20-M20 -> -449.67393 | O20: =+[4]아산!$H$92/1000 -> 180.0531 | P20: =+[4]아산!$I$92/1000 -> -58.754126 | Q20: =+P20-O20 -> -238.80722 | R20: =+[5]아산!$H$92/1000 -> 381.74849 | S20: =+P20-R20 -> -440.50262 | T20: =+[12]아산!$H$86/1000 -> 2864.5776 | U20: =+[12]아산!$I$86/1000 -> 844.40573 | V20: =+U20-T20 -> -2020.1719 | W20: =+[13]아산!$H$86/1000 -> 3882.667 | X20: =+U20-W20 -> -3038.2612 | Y20: =+[12]아산!$H$92/1000 -> 1660.3747 | Z20: =+[12]아산!$I$92/1000 -> -479.64278 | AA20: =+Z20-Y20 -> -2140.0175 | AB20: =+[13]아산!$H$92/1000 -> 2600.3035 | AC20: =+Z20-AB20 -> -3079.9463
B21: 전주 | I21: 전주 | J21: =+[4]전주!$H$86/1000 -> 178.63194 | K21: =+[4]전주!$I$86/1000 -> 116.3473 | L21: =+K21-J21 -> -62.284642 | M21: =+[5]전주!$H$86/1000 -> 51.295807 | N21: =+K21-M21 -> 65.051495 | O21: =+[4]전주!$H$92/1000 -> 121.74538 | P21: =+[4]전주!$I$92/1000 -> 29.224898 | Q21: =+P21-O21 -> -92.520479 | R21: =+[5]전주!$H$92/1000 -> 14.527564 | S21: =+P21-R21 -> 14.697334 | T21: =+[12]전주!$H$86/1000 -> 1175.2069 | U21: =+[12]전주!$I$86/1000 -> 1225.8349 | V21: =+U21-T21 -> 50.628022 | W21: =+[13]전주!$H$86/1000 -> 565.1172 | X21: =+U21-W21 -> 660.71773 | Y21: =+[12]전주!$H$92/1000 -> 611.87673 | Z21: =+[12]전주!$I$92/1000 -> 472.53366 | AA21: =+Z21-Y21 -> -139.34307 | AB21: =+[13]전주!$H$92/1000 -> 182.05997 | AC21: =+Z21-AB21 -> 290.47369
B22: 군산 | I22: 군산 | J22: =+[4]군산!$H$86/1000 -> 205.06836 | K22: =+[4]군산!$I$86/1000 -> 39.536474 | L22: =+K22-J22 -> -165.53188 | M22: =+[5]군산!$H$86/1000 -> 268.54539 | N22: =+K22-M22 -> -229.00891 | O22: =+[4]군산!$H$92/1000 -> 165.91059 | P22: =+[4]군산!$I$92/1000 -> 15.925403 | Q22: =+P22-O22 -> -149.98519 | R22: =+[5]군산!$H$92/1000 -> 228.51094 | S22: =+P22-R22 -> -212.58554 | T22: =+[12]군산!$H$86/1000 -> 1839.8775 | U22: =+[12]군산!$I$86/1000 -> 952.38856 | V22: =+U22-T22 -> -887.48898 | W22: =+[13]군산!$H$86/1000 -> 2690.6227 | X22: =+U22-W22 -> -1738.2341 | Y22: =+[12]군산!$H$92/1000 -> 1427.3985 | Z22: =+[12]군산!$I$92/1000 -> 631.65655 | AA22: =+Z22-Y22 -> -795.74191 | AB22: =+[13]군산!$H$92/1000 -> 2223.7266 | AC22: =+Z22-AB22 -> -1592.0701
B23: 원주 | I23: 원주 | J23: =+[4]원주!$H$86/1000 -> 103.86534 | K23: =+[4]원주!$I$86/1000 -> 85.403377 | L23: =+K23-J23 -> -18.461964 | M23: =+[5]원주!$H$86/1000 -> 104.30831 | N23: =+K23-M23 -> -18.904933 | O23: =+[4]원주!$H$92/1000 -> 77.53617 | P23: =+[4]원주!$I$92/1000 -> 55.427884 | Q23: =+P23-O23 -> -22.108286 | R23: =+[5]원주!$H$92/1000 -> 80.200221 | S23: =+P23-R23 -> -24.772337 | T23: =+[12]원주!$H$86/1000 -> 802.9594 | U23: =+[12]원주!$I$86/1000 -> 168.26629 | V23: =+U23-T23 -> -634.69311 | W23: =+[13]원주!$H$86/1000 -> 1233.0111 | X23: =+U23-W23 -> -1064.7448 | Y23: =+[12]원주!$H$92/1000 -> 533.67048 | Z23: =+[12]원주!$I$92/1000 -> -85.856574 | AA23: =+Z23-Y23 -> -619.52706 | AB23: =+[13]원주!$H$92/1000 -> 934.59853 | AC23: =+Z23-AB23 -> -1020.4551
B24: 제주 | I24: 제주 | J24: =+[4]제주!$H$86/1000 -> 150.10859 | K24: =+[4]제주!$I$86/1000 -> -10.044988 | L24: =+K24-J24 -> -160.15358 | M24: =+[5]제주!$H$86/1000 -> 4.79407 | N24: =+K24-M24 -> -14.839058 | O24: =+[4]제주!$H$92/1000 -> 103.98985 | P24: =+[4]제주!$I$92/1000 -> -39.810747 | Q24: =+P24-O24 -> -143.80059 | R24: =+[5]제주!$H$92/1000 -> -9.831406 | S24: =+P24-R24 -> -29.979341 | T24: =+[12]제주!$H$86/1000 -> 1593.1587 | U24: =+[12]제주!$I$86/1000 -> 622.5792 | V24: =+U24-T24 -> -970.57951 | W24: =+[13]제주!$H$86/1000 -> 330.03549 | X24: =+U24-W24 -> 292.54372 | Y24: =+[12]제주!$H$92/1000 -> 1052.1923 | Z24: =+[12]제주!$I$92/1000 -> 219.72277 | AA24: =+Z24-Y24 -> -832.46954 | AB24: =+[13]제주!$H$92/1000 -> 121.90244 | AC24: =+Z24-AB24 -> 97.820327
I25: 수도권 | J25: =SUM(J8:J11) -> 827.85557 | K25: =SUM(K8:K11) -> 72.705947 | L25: =+K25-J25 -> -755.14962 | M25: =SUM(M8:M11) -> 363.42568 | N25: =+K25-M25 -> -290.71973 | O25: =SUM(O8:O11) -> 357.48672 | P25: =SUM(P8:P11) -> -400.5311 | Q25: =+P25-O25 -> -758.01783 | R25: =SUM(R8:R11) -> -43.512691 | S25: =+P25-R25 -> -357.01841 | T25: =SUM(T8:T11) -> 6883.6356 | U25: =SUM(U8:U11) -> 1870.9566 | V25: =+U25-T25 -> -5012.6791 | W25: =SUM(W8:W11) -> 7787.2808 | X25: =+U25-W25 -> -5916.3242 | Y25: =SUM(Y8:Y11) -> 1426.6479 | Z25: =SUM(Z8:Z11) -> -3384.9969 | AA25: =+Z25-Y25 -> -4811.6448 | AB25: =SUM(AB8:AB11) -> 2923.9292 | AC25: =+Z25-AB25 -> -6308.9261
I26: 영남권 | J26: =SUM(J12:J19) -> 1245.3515 | K26: =SUM(K12:K19) -> 179.44382 | L26: =+K26-J26 -> -1065.9077 | M26: =SUM(M12:M19) -> 830.76104 | N26: =+K26-M26 -> -651.31721 | O26: =SUM(O12:O19) -> 613.35627 | P26: =SUM(P12:P19) -> -423.94238 | Q26: =+P26-O26 -> -1037.2986 | R26: =SUM(R12:R19) -> 293.04981 | S26: =+P26-R26 -> -716.99218 | T26: =SUM(T12:T19) -> 10370.961 | U26: =SUM(U12:U19) -> 5507.9015 | V26: =+U26-T26 -> -4863.0596 | W26: =SUM(W12:W19) -> 13784.402 | X26: =+U26-W26 -> -8276.501 | Y26: =SUM(Y12:Y19) -> 3511.6799 | Z26: =SUM(Z12:Z19) -> -1307.4271 | AA26: =+Z26-Y26 -> -4819.1071 | AB26: =SUM(AB12:AB19) -> 7198.1994 | AC26: =+Z26-AB26 -> -8505.6265
I27: 중부권 | J27: =SUM(J20:J24) -> 919.42375 | K27: =SUM(K20:K24) -> 299.70937 | L27: =+K27-J27 -> -619.71438 | M27: =SUM(M20:M24) -> 947.08472 | N27: =+K27-M27 -> -647.37534 | O27: =SUM(O20:O24) -> 649.23508 | P27: =SUM(P20:P24) -> 2.0133114 | Q27: =+P27-O27 -> -647.22177 | R27: =SUM(R20:R24) -> 695.15581 | S27: =+P27-R27 -> -693.1425 | T27: =SUM(T20:T24) -> 8275.7801 | U27: =SUM(U20:U24) -> 3813.4747 | V27: =+U27-T27 -> -4462.3054 | W27: =SUM(W20:W24) -> 8701.4535 | X27: =+U27-W27 -> -4887.9787 | Y27: =SUM(Y20:Y24) -> 5285.5127 | Z27: =SUM(Z20:Z24) -> 758.41363 | AA27: =+Z27-Y27 -> -4527.099 | AB27: =SUM(AB20:AB24) -> 6062.591 | AC27: =+Z27-AB27 -> -5304.1774
H28: 레미콘 계 | J28: =SUM(J25:J27) -> 2992.6308 | K28: =SUM(K25:K27) -> 551.85915 | L28: =+K28-J28 -> -2440.7717 | M28: =SUM(M25:M27) -> 2141.2714 | N28: =+K28-M28 -> -1589.4123 | O28: =SUM(O25:O27) -> 1620.0781 | P28: =SUM(P25:P27) -> -822.46017 | Q28: =+P28-O28 -> -2442.5382 | R28: =SUM(R25:R27) -> 944.69292 | S28: =+P28-R28 -> -1767.1531 | T28: =SUM(T25:T27) -> 25530.377 | U28: =SUM(U25:U27) -> 11192.333 | V28: =+U28-T28 -> -14338.044 | W28: =SUM(W25:W27) -> 30273.137 | X28: =+U28-W28 -> -19080.804 | Y28: =SUM(Y25:Y27) -> 10223.84 | Z28: =SUM(Z25:Z27) -> -3934.0104 | AA28: =+Z28-Y28 -> -14157.851 | AB28: =SUM(AB25:AB27) -> 16184.72 | AC28: =+Z28-AB28 -> -20118.73

Sheet 사업장별(당월)
H3: □ 사업장별 손익실적(2025-10)
AG4: [단위 : 천㎥, 톤, 백만원]
H5: 구분 | J5: 물량 | O5: 매출 | T5: 영업이익(공통비 배부전) | Y5: 판매단가 | AB5: 변동비 | AE5: 공헌이익
A6: 2024년 10월 마감 손익 | J6: 계획 | K6: 실적 | L6: 차이 | M6: 전년 | N6: 차이 | O6: 계획 | P6: 실적 | Q6: 차이 | R6: 전년 | S6: 차이 | T6: 계획 | U6: 실적 | V6: 차이 | W6: 전년 | X6: 차이 | Y6: 계획 | Z6: 실적 | AA6: 전년 | AB6: 계획 | AC6: 실적 | AD6: 전년 | AE6: 계획 | AF6: 실적 | AG6: 전년
B7: 안양 | G7: =+I7 -> 안양 | H7: 레미콘 | I7: 안양 | J7: =+IFERROR(HLOOKUP($B7,'[1]10월'!$D$6:$BN$259,2,),)/1000 -> 35 | K7: =+IFERROR(HLOOKUP($B7,'[2]10월'!$F$6:$CP$99,2,),)/1000 -> 29.011 | L7: =+K7-J7 -> -5.989 | M7: =+IFERROR(HLOOKUP($B7,'[3]10월'!$F$6:$CC$57,2,),)/1000 -> 39.055 | N7: =+K7-M7 -> -10.044 | O7: =+IFERROR(HLOOKUP($B7,'[1]10월'!$D$6:$BN$259,3,),)/1000 -> 3561.9535 | P7: =+IFERROR(HLOOKUP($B7,'[2]10월'!$F$6:$CP$99,3,),)/1000 -> 2833.1262 | Q7: =+P7-O7 -> -728.82735 | R7: =+IFERROR(HLOOKUP($B7,'[3]10월'!$F$6:$CC$57,3,),)/1000 -> 3682.4273 | S7: =+P7-R7 -> -849.30114 | T7: =+IFERROR(HLOOKUP($B7,'[1]10월'!$D$6:$BN$259,16,),)/1000 -> 415.60971 | U7: =+IFERROR(HLOOKUP($B7,'[2]10월'!$F$6:$CP$99,16,),)/1000 -> 233.33186 | V7: =+U7-T7 -> -182.27785 | W7: =+IFERROR(HLOOKUP($B7,'[3]10월'!$F$6:$CC$57,16,),)/1000 -> 151.42127 | X7: =+U7-W7 -> 81.910587 | Y7: =+[4]안양!$Q$85 -> 101770.1 | Z7: =+[4]안양!$R$85 -> 97656.964 | AA7: =+[5]안양!$Q$85 -> 94288.243 | AB7: =+[4]안양!$Q$89 -> 81611.79 | AC7: =+[4]안양!$R$89 -> 78918.014 | AD7: =+[5]안양!$Q$89 -> 82720.758 | AE7: =+Y7-AB7 -> 20158.31 | AF7: =+Z7-AC7 -> 18738.949 | AG7: =+AA7-AD7 -> 11567.484
B8: 인천 | G8: =+I8 -> 인천 | H8: 직영 | I8: 인천 | J8: =+IFERROR(HLOOKUP($B8,'[1]10월'!$D$6:$BN$259,2,),)/1000 -> 26 | K8: =+IFERROR(HLOOKUP($B8,'[2]10월'!$F$6:$CP$99,2,),)/1000 -> 26.297 | L8: =+K8-J8 -> 0.297 | M8: =+IFERROR(HLOOKUP($B8,'[3]10월'!$F$6:$CC$57,2,),)/1000 -> 26.461 | N8: =+K8-M8 -> -0.164 | O8: =+IFERROR(HLOOKUP($B8,'[1]10월'!$D$6:$BN$259,3,),)/1000 -> 2693.9932 | P8: =+IFERROR(HLOOKUP($B8,'[2]10월'!$F$6:$CP$99,3,),)/1000 -> 2442.4781 | Q8: =+P8-O8 -> -251.51509 | R8: =+IFERROR(HLOOKUP($B8,'[3]10월'!$F$6:$CC$57,3,),)/1000 -> 2558.6091 | S8: =+P8-R8 -> -116.13094 | T8: =+IFERROR(HLOOKUP($B8,'[1]10월'!$D$6:$BN$259,16,),)/1000 -> 237.49324 | U8: =+IFERROR(HLOOKUP($B8,'[2]10월'!$F$6:$CP$99,16,),)/1000 -> -104.18711 | V8: =+U8-T8 -> -341.68035 | W8: =+IFERROR(HLOOKUP($B8,'[3]10월'!$F$6:$CC$57,16,),)/1000 -> 63.89366 | X8: =+U8-W8 -> -168.08077 | Y8: =+[4]인천!$Q$85 -> 103615.12 | Z8: =+[4]인천!$R$85 -> 92880.485 | AA8: =+[5]인천!$Q$85 -> 96693.589 | AB8: =+[4]인천!$Q$89 -> 83139.384 | AC8: =+[4]인천!$R$89 -> 84696.301 | AD8: =+[5]인천!$Q$89 -> 82558.135 | AE8: =+Y8-AB8 -> 20475.74 | AF8: =+Z8-AC8 -> 8184.1849 | AG8: =+AA8-AD8 -> 14135.455
B9: 파주 | G9: =+I9 -> 파주 | I9: 파주 | J9: =+IFERROR(HLOOKUP($B9,'[1]10월'!$D$6:$BN$259,2,),)/1000 -> 21 | K9: =+IFERROR(HLOOKUP($B9,'[2]10월'!$F$6:$CP$99,2,),)/1000 -> 14.177 | L9: =+K9-J9 -> -6.823 | M9: =+IFERROR(HLOOKUP($B9,'[3]10월'!$F$6:$CC$57,2,),)/1000 -> 26.27 | N9: =+K9-M9 -> -12.093 | O9: =+IFERROR(HLOOKUP($B9,'[1]10월'!$D$6:$BN$259,3,),)/1000 -> 2020.3202 | P9: =+IFERROR(HLOOKUP($B9,'[2]10월'!$F$6:$CP$99,3,),)/1000 -> 1282.2996 | Q9: =+P9-O9 -> -738.02065 | R9: =+IFERROR(HLOOKUP($B9,'[3]10월'!$F$6:$CC$57,3,),)/1000 -> 2323.423 | S9: =+P9-R9 -> -1041.1234 | T9: =+IFERROR(HLOOKUP($B9,'[1]10월'!$D$6:$BN$259,16,),)/1000 -> 90.273885 | U9: =+IFERROR(HLOOKUP($B9,'[2]10월'!$F$6:$CP$99,16,),)/1000 -> -62.289172 | V9: =+U9-T9 -> -152.56306 | W9: =+IFERROR(HLOOKUP($B9,'[3]10월'!$F$6:$CC$57,16,),)/1000 -> 73.448678 | X9: =+U9-W9 -> -135.73785 | Y9: =+[4]파주!$Q$85 -> 96205.726 | Z9: =+[4]파주!$R$85 -> 90400.804 | AA9: =+[5]파주!$Q$85 -> 88417.962 | AB9: =+[4]파주!$Q$89 -> 81454.568 | AC9: =+[4]파주!$R$89 -> 79486.703 | AD9: =+[5]파주!$Q$89 -> 77319.908 | AE9: =+Y9-AB9 -> 14751.159 | AF9: =+Z9-AC9 -> 10914.101 | AG9: =+AA9-AD9 -> 11098.054
B10: 김포 | G10: =+I10 -> 김포 | I10: 김포 | J10: =+IFERROR(HLOOKUP($B10,'[1]10월'!$D$6:$BN$259,2,),)/1000 -> 14 | K10: =+IFERROR(HLOOKUP($B10,'[2]10월'!$F$6:$CP$99,2,),)/1000 -> 9.5365 | L10: =+K10-J10 -> -4.4635 | M10: =+IFERROR(HLOOKUP($B10,'[3]10월'!$F$6:$CC$57,2,),)/1000 -> 12.124 | N10: =+K10-M10 -> -2.5875 | O10: =+IFERROR(HLOOKUP($B10,'[1]10월'!$D$6:$BN$259,3,),)/1000 -> 1330.3874 | P10: =+IFERROR(HLOOKUP($B10,'[2]10월'!$F$6:$CP$99,3,),)/1000 -> 922.48442 | Q10: =+P10-O10 -> -407.90303 | R10: =+IFERROR(HLOOKUP($B10,'[3]10월'!$F$6:$CC$57,3,),)/1000 -> 1149.0606 | S10: =+P10-R10 -> -226.57618 | T10: =+IFERROR(HLOOKUP($B10,'[1]10월'!$D$6:$BN$259,16,),)/1000 -> 84.478737 | U10: =+IFERROR(HLOOKUP($B10,'[2]10월'!$F$6:$CP$99,16,),)/1000 -> 5.850372 | V10: =+U10-T10 -> -78.628365 | W10: =+IFERROR(HLOOKUP($B10,'[3]10월'!$F$6:$CC$57,16,),)/1000 -> 74.662069 | X10: =+U10-W10 -> -68.811697 | Y10: =+[4]김포!$Q$85 -> 95027.675 | Z10: =+[4]김포!$R$85 -> 96819.911 | AA10: =+[5]김포!$Q$85 -> 94775.701 | AB10: =+[4]김포!$Q$89 -> 77009.612 | AC10: =+[4]김포!$R$89 -> 78178.961 | AD10: =+[5]김포!$Q$89 -> 75594.089 | AE10: =+Y10-AB10 -> 18018.063 | AF10: =+Z10-AC10 -> 18640.95 | AG10: =+AA10-AD10 -> 19181.613
B11: 부산 | G11: =+I11 -> 부산 | I11: 부산 | J11: =+IFERROR(HLOOKUP($B11,'[1]10월'!$D$6:$BN$259,2,),)/1000 -> 19 | K11: =+IFERROR(HLOOKUP($B11,'[2]10월'!$F$6:$CP$99,2,),)/1000 -> 17.712 | L11: =+K11-J11 -> -1.288 | M11: =+IFERROR(HLOOKUP($B11,'[3]10월'!$F$6:$CC$57,2,),)/1000 -> 16.752 | N11: =+K11-M11 -> 0.96 | O11: =+IFERROR(HLOOKUP($B11,'[1]10월'!$D$6:$BN$259,3,),)/1000 -> 2046.3004 | P11: =+IFERROR(HLOOKUP($B11,'[2]10월'!$F$6:$CP$99,3,),)/1000 -> 1942.1621 | Q11: =+P11-O11 -> -104.13829 | R11: =+IFERROR(HLOOKUP($B11,'[3]10월'!$F$6:$CC$57,3,),)/1000 -> 1728.9812 | S11: =+P11-R11 -> 213.18094 | T11: =+IFERROR(HLOOKUP($B11,'[1]10월'!$D$6:$BN$259,16,),)/1000 -> 166.34786 | U11: =+IFERROR(HLOOKUP($B11,'[2]10월'!$F$6:$CP$99,16,),)/1000 -> 113.69739 | V11: =+U11-T11 -> -52.650466 | W11: =+IFERROR(HLOOKUP($B11,'[3]10월'!$F$6:$CC$57,16,),)/1000 -> 57.651193 | X11: =+U11-W11 -> 56.046198 | Y11: =+[4]부산!$Q$85 -> 107700.02 | Z11: =+[4]부산!$R$85 -> 109652.33 | AA11: =+[5]부산!$Q$85 -> 103210.43 | AB11: =+[4]부산!$Q$89 -> 85358.086 | AC11: =+[4]부산!$R$89 -> 88816.14 | AD11: =+[5]부산!$Q$89 -> 83827.02 | AE11: =+Y11-AB11 -> 22341.934 | AF11: =+Z11-AC11 -> 20836.192 | AG11: =+AA11-AD11 -> 19383.412
B12: 서부산 | G12: =+I12 -> 서부산 | I12: 서부산 | J12: =+IFERROR(HLOOKUP($B12,'[1]10월'!$D$6:$BN$259,2,),)/1000 -> 19 | K12: =+IFERROR(HLOOKUP($B12,'[2]10월'!$F$6:$CP$99,2,),)/1000 -> 20.565 | L12: =+K12-J12 -> 1.565 | M12: =+IFERROR(HLOOKUP($B12,'[3]10월'!$F$6:$CC$57,2,),)/1000 -> 19.663 | N12: =+K12-M12 -> 0.902 | O12: =+IFERROR(HLOOKUP($B12,'[1]10월'!$D$6:$BN$259,3,),)/1000 -> 1886.7073 | P12: =+IFERROR(HLOOKUP($B12,'[2]10월'!$F$6:$CP$99,3,),)/1000 -> 2041.1455 | Q12: =+P12-O12 -> 154.43818 | R12: =+IFERROR(HLOOKUP($B12,'[3]10월'!$F$6:$CC$57,3,),)/1000 -> 1865.5519 | S12: =+P12-R12 -> 175.59358 | T12: =+IFERROR(HLOOKUP($B12,'[1]10월'!$D$6:$BN$259,16,),)/1000 -> 178.71898 | U12: =+IFERROR(HLOOKUP($B12,'[2]10월'!$F$6:$CP$99,16,),)/1000 -> 182.61007 | V12: =+U12-T12 -> 3.8910847 | W12: =+IFERROR(HLOOKUP($B12,'[3]10월'!$F$6:$CC$57,16,),)/1000 -> 132.60606 | X12: =+U12-W12 -> 50.004007 | Y12: =+[4]서부산!$Q$85 -> 99300.385 | Z12: =+[4]서부산!$R$85 -> 99253.367 | AA12: =+[5]서부산!$Q$85 -> 94876.261 | AB12: =+[4]서부산!$Q$89 -> 78051.441 | AC12: =+[4]서부산!$R$89 -> 79067.725 | AD12: =+[5]서부산!$Q$89 -> 77092.366 | AE12: =+Y12-AB12 -> 21248.944 | AF12: =+Z12-AC12 -> 20185.642 | AG12: =+AA12-AD12 -> 17783.895
B13: 김해 | G13: =+I13 -> 김해 | I13: 김해 | J13: =+IFERROR(HLOOKUP($B13,'[1]10월'!$D$6:$BN$259,2,),)/1000 -> 16 | K13: =+IFERROR(HLOOKUP($B13,'[2]10월'!$F$6:$CP$99,2,),)/1000 -> 6.521 | L13: =+K13-J13 -> -9.479 | M13: =+IFERROR(HLOOKUP($B13,'[3]10월'!$F$6:$CC$57,2,),)/1000 -> 13.655 | N13: =+K13-M13 -> -7.134 | O13: =+IFERROR(HLOOKUP($B13,'[1]10월'!$D$6:$BN$259,3,),)/1000 -> 1540.7967 | P13: =+IFERROR(HLOOKUP($B13,'[2]10월'!$F$6:$CP$99,3,),)/1000 -> 629.4007 | Q13: =+P13-O13 -> -911.396 | R13: =+IFERROR(HLOOKUP($B13,'[3]10월'!$F$6:$CC$57,3,),)/1000 -> 1233.987 | S13: =+P13-R13 -> -604.5863 | T13: =+IFERROR(HLOOKUP($B13,'[1]10월'!$D$6:$BN$259,16,),)/1000 -> 147.10502 | U13: =+IFERROR(HLOOKUP($B13,'[2]10월'!$F$6:$CP$99,16,),)/1000 -> -38.691111 | V13: =+U13-T13 -> -185.79613 | W13: =+IFERROR(HLOOKUP($B13,'[3]10월'!$F$6:$CC$57,16,),)/1000 -> 10.398047 | X13: =+U13-W13 -> -49.089158 | Y13: =+[4]김해!$Q$85 -> 96299.794 | Z13: =+[4]김해!$R$85 -> 96519.046 | AA13: =+[5]김해!$Q$85 -> 90368.876 | AB13: =+[4]김해!$Q$89 -> 77583.786 | AC13: =+[4]김해!$R$89 -> 80973.757 | AD13: =+[5]김해!$Q$89 -> 78384.071 | AE13: =+Y13-AB13 -> 18716.008 | AF13: =+Z13-AC13 -> 15545.29 | AG13: =+AA13-AD13 -> 11984.804
B14: 정관 | G14: =+I14 -> 정관 | I14: 정관 | J14: =+IFERROR(HLOOKUP($B14,'[1]10월'!$D$6:$BN$259,2,),)/1000 -> 18 | K14: =+IFERROR(HLOOKUP($B14,'[2]10월'!$F$6:$CP$99,2,),)/1000 -> 18.1365 | L14: =+K14-J14 -> 0.1365 | M14: =+IFERROR(HLOOKUP($B14,'[3]10월'!$F$6:$CC$57,2,),)/1000 -> 21.756 | N14: =+K14-M14 -> -3.6195 | O14: =+IFERROR(HLOOKUP($B14,'[1]10월'!$D$6:$BN$259,3,),)/1000 -> 1836.0077 | P14: =+IFERROR(HLOOKUP($B14,'[2]10월'!$F$6:$CP$99,3,),)/1000 -> 1805.6837 | Q14: =+P14-O14 -> -30.323955 | R14: =+IFERROR(HLOOKUP($B14,'[3]10월'!$F$6:$CC$57,3,),)/1000 -> 2122.0107 | S14: =+P14-R14 -> -316.32702 | T14: =+IFERROR(HLOOKUP($B14,'[1]10월'!$D$6:$BN$259,16,),)/1000 -> 140.96725 | U14: =+IFERROR(HLOOKUP($B14,'[2]10월'!$F$6:$CP$99,16,),)/1000 -> 70.235029 | V14: =+U14-T14 -> -70.732224 | W14: =+IFERROR(HLOOKUP($B14,'[3]10월'!$F$6:$CC$57,16,),)/1000 -> 142.76763 | X14: =+U14-W14 -> -72.532597 | Y14: =+[4]정관!$Q$85 -> 102000.43 | Z14: =+[4]정관!$R$85 -> 99560.759 | AA14: =+[5]정관!$Q$85 -> 97536.805 | AB14: =+[4]정관!$Q$89 -> 82546.042 | AC14: =+[4]정관!$R$89 -> 83833.872 | AD14: =+[5]정관!$Q$89 -> 81346.355 | AE14: =+Y14-AB14 -> 19454.383 | AF14: =+Z14-AC14 -> 15726.886 | AG14: =+AA14-AD14 -> 16190.45
B15: 양산 | G15: =+I15 -> 양산 | I15: 양산 | J15: =+IFERROR(HLOOKUP($B15,'[1]10월'!$D$6:$BN$259,2,),)/1000 -> 12 | K15: =+IFERROR(HLOOKUP($B15,'[2]10월'!$F$6:$CP$99,2,),)/1000 -> 3.796 | L15: =+K15-J15 -> -8.204 | M15: =+IFERROR(HLOOKUP($B15,'[3]10월'!$F$6:$CC$57,2,),)/1000 -> 13.908 | N15: =+K15-M15 -> -10.112 | O15: =+IFERROR(HLOOKUP($B15,'[1]10월'!$D$6:$BN$259,3,),)/1000 -> 1132.56 | P15: =+IFERROR(HLOOKUP($B15,'[2]10월'!$F$6:$CP$99,3,),)/1000 -> 346.7058 | Q15: =+P15-O15 -> -785.8542 | R15: =+IFERROR(HLOOKUP($B15,'[3]10월'!$F$6:$CC$57,3,),)/1000 -> 1309.0972 | S15: =+P15-R15 -> -962.3914 | T15: =+IFERROR(HLOOKUP($B15,'[1]10월'!$D$6:$BN$259,16,),)/1000 -> 111.54797 | U15: =+IFERROR(HLOOKUP($B15,'[2]10월'!$F$6:$CP$99,16,),)/1000 -> -76.735298 | V15: =+U15-T15 -> -188.28327 | W15: =+IFERROR(HLOOKUP($B15,'[3]10월'!$F$6:$CC$57,16,),)/1000 -> 152.35462 | X15: =+U15-W15 -> -229.08992 | Y15: =+[4]양산!$Q$85 -> 94380 | Z15: =+[4]양산!$R$85 -> 91334.51 | AA15: =+[5]양산!$Q$85 -> 94125.482 | AB15: =+[4]양산!$Q$89 -> 73434.127 | AC15: =+[4]양산!$R$89 -> 76729.467 | AD15: =+[5]양산!$Q$89 -> 72678.271 | AE15: =+Y15-AB15 -> 20945.873 | AF15: =+Z15-AC15 -> 14605.043 | AG15: =+AA15-AD15 -> 21447.211
B16: 창원 | G16: =+I16 -> 창원 | I16: 창원 | J16: =+IFERROR(HLOOKUP($B16,'[1]10월'!$D$6:$BN$259,2,),)/1000 -> 18 | K16: =+IFERROR(HLOOKUP($B16,'[2]10월'!$F$6:$CP$99,2,),)/1000 -> 7.563 | L16: =+K16-J16 -> -10.437 | M16: =+IFERROR(HLOOKUP($B16,'[3]10월'!$F$6:$CC$57,2,),)/1000 -> 14.58 | N16: =+K16-M16 -> -7.017 | O16: =+IFERROR(HLOOKUP($B16,'[1]10월'!$D$6:$BN$259,3,),)/1000 -> 1801.8046 | P16: =+IFERROR(HLOOKUP($B16,'[2]10월'!$F$6:$CP$99,3,),)/1000 -> 690.5367 | Q16: =+P16-O16 -> -1111.2679 | R16: =+IFERROR(HLOOKUP($B16,'[3]10월'!$F$6:$CC$57,3,),)/1000 -> 1357.6853 | S16: =+P16-R16 -> -667.1486 | T16: =+IFERROR(HLOOKUP($B16,'[1]10월'!$D$6:$BN$259,16,),)/1000 -> 251.9365 | U16: =+IFERROR(HLOOKUP($B16,'[2]10월'!$F$6:$CP$99,16,),)/1000 -> -42.600381 | V16: =+U16-T16 -> -294.53688 | W16: =+IFERROR(HLOOKUP($B16,'[3]10월'!$F$6:$CC$57,16,),)/1000 -> 76.578861 | X16: =+U16-W16 -> -119.17924 | Y16: =+[4]창원!$Q$85 -> 100100.26 | Z16: =+[4]창원!$R$85 -> 91304.601 | AA16: =+[5]창원!$Q$85 -> 93119.705 | AB16: =+[4]창원!$Q$89 -> 76013.851 | AC16: =+[4]창원!$R$89 -> 72525.175 | AD16: =+[5]창원!$Q$89 -> 74871.475 | AE16: =+Y16-AB16 -> 24086.407 | AF16: =+Z16-AC16 -> 18779.426 | AG16: =+AA16-AD16 -> 18248.23
B17: 대구 | G17: =+I17 -> 대구 | I17: 대구 | J17: =+IFERROR(HLOOKUP($B17,'[1]10월'!$D$6:$BN$259,2,),)/1000 -> 12 | K17: =+IFERROR(HLOOKUP($B17,'[2]10월'!$F$6:$CP$99,2,),)/1000 -> 6.879 | L17: =+K17-J17 -> -5.121 | M17: =+IFERROR(HLOOKUP($B17,'[3]10월'!$F$6:$CC$57,2,),)/1000 -> 15.64 | N17: =+K17-M17 -> -8.761 | O17: =+IFERROR(HLOOKUP($B17,'[1]10월'!$D$6:$BN$259,3,),)/1000 -> 1167.0317 | P17: =+IFERROR(HLOOKUP($B17,'[2]10월'!$F$6:$CP$99,3,),)/1000 -> 594.28798 | Q17: =+P17-O17 -> -572.7437 | R17: =+IFERROR(HLOOKUP($B17,'[3]10월'!$F$6:$CC$57,3,),)/1000 -> 1465.4841 | S17: =+P17-R17 -> -871.19607 | T17: =+IFERROR(HLOOKUP($B17,'[1]10월'!$D$6:$BN$259,16,),)/1000 -> 112.89939 | U17: =+IFERROR(HLOOKUP($B17,'[2]10월'!$F$6:$CP$99,16,),)/1000 -> -60.636872 | V17: =+U17-T17 -> -173.53626 | W17: =+IFERROR(HLOOKUP($B17,'[3]10월'!$F$6:$CC$57,16,),)/1000 -> 100.63415 | X17: =+U17-W17 -> -161.27102 | Y17: =+[4]대구!$Q$85 -> 97252.64 | Z17: =+[4]대구!$R$85 -> 86391.624 | AA17: =+[5]대구!$Q$85 -> 93698.609 | AB17: =+[4]대구!$Q$89 -> 73374.505 | AC17: =+[4]대구!$R$89 -> 74755.375 | AD17: =+[5]대구!$Q$89 -> 76355.669 | AE17: =+Y17-AB17 -> 23878.135 | AF17: =+Z17-AC17 -> 11636.249 | AG17: =+AA17-AD17 -> 17342.941
B18: 울산 | G18: =+I18 -> 울산 | I18: 울산 | J18: =+IFERROR(HLOOKUP($B18,'[1]10월'!$D$6:$BN$259,2,),)/1000 -> 12.5 | K18: =+IFERROR(HLOOKUP($B18,'[2]10월'!$F$6:$CP$99,2,),)/1000 -> 8.572 | L18: =+K18-J18 -> -3.928 | M18: =+IFERROR(HLOOKUP($B18,'[3]10월'!$F$6:$CC$57,2,),)/1000 -> 14.267 | N18: =+K18-M18 -> -5.695 | O18: =+IFERROR(HLOOKUP($B18,'[1]10월'!$D$6:$BN$259,3,),)/1000 -> 1302.777 | P18: =+IFERROR(HLOOKUP($B18,'[2]10월'!$F$6:$CP$99,3,),)/1000 -> 908.0035 | Q18: =+P18-O18 -> -394.7735 | R18: =+IFERROR(HLOOKUP($B18,'[3]10월'!$F$6:$CC$57,3,),)/1000 -> 1420.6245 | S18: =+P18-R18 -> -512.621 | T18: =+IFERROR(HLOOKUP($B18,'[1]10월'!$D$6:$BN$259,16,),)/1000 -> 135.82855 | U18: =+IFERROR(HLOOKUP($B18,'[2]10월'!$F$6:$CP$99,16,),)/1000 -> 31.565002 | V18: =+U18-T18 -> -104.26355 | W18: =+IFERROR(HLOOKUP($B18,'[3]10월'!$F$6:$CC$57,16,),)/1000 -> 157.77048 | X18: =+U18-W18 -> -126.20548 | Y18: =+[4]울산!$Q$85 -> 104222.16 | Z18: =+[4]울산!$R$85 -> 105926.68 | AA18: =+[5]울산!$Q$85 -> 99574.157 | AB18: =+[4]울산!$Q$89 -> 81791.334 | AC18: =+[4]울산!$R$89 -> 85389.419 | AD18: =+[5]울산!$Q$89 -> 78942.319 | AE18: =+Y18-AB18 -> 22430.826 | AF18: =+Z18-AC18 -> 20537.261 | AG18: =+AA18-AD18 -> 20631.838
B19: 아산 | G19: =+I19 -> 아산 | I19: 아산 | J19: =+IFERROR(HLOOKUP($B19,'[1]10월'!$D$6:$BN$259,2,),)/1000 -> 21 | K19: =+IFERROR(HLOOKUP($B19,'[2]10월'!$F$6:$CP$99,2,),)/1000 -> 20.895 | L19: =+K19-J19 -> -0.105 | M19: =+IFERROR(HLOOKUP($B19,'[3]10월'!$F$6:$CC$57,2,),)/1000 -> 35.1425 | N19: =+K19-M19 -> -14.2475 | O19: =+IFERROR(HLOOKUP($B19,'[1]10월'!$D$6:$BN$259,3,),)/1000 -> 2163 | P19: =+IFERROR(HLOOKUP($B19,'[2]10월'!$F$6:$CP$99,3,),)/1000 -> 2010.9689 | Q19: =+P19-O19 -> -152.03113 | R19: =+IFERROR(HLOOKUP($B19,'[3]10월'!$F$6:$CC$57,3,),)/1000 -> 3417.0639 | S19: =+P19-R19 -> -1406.095 | T19: =+IFERROR(HLOOKUP($B19,'[1]10월'!$D$6:$BN$259,16,),)/1000 -> 281.74952 | U19: =+IFERROR(HLOOKUP($B19,'[2]10월'!$F$6:$CP$99,16,),)/1000 -> 68.467208 | V19: =+U19-T19 -> -213.28232 | W19: =+IFERROR(HLOOKUP($B19,'[3]10월'!$F$6:$CC$57,16,),)/1000 -> 518.14114 | X19: =+U19-W19 -> -449.67393 | Y19: =+[4]아산!$Q$85 -> 103000 | Z19: =+[4]아산!$R$85 -> 96241.631 | AA19: =+[5]아산!$Q$85 -> 97210.458 | AB19: =+[4]아산!$Q$89 -> 78015.497 | AC19: =+[4]아산!$R$89 -> 81396.674 | AD19: =+[5]아산!$Q$89 -> 75321.505 | AE19: =+Y19-AB19 -> 24984.503 | AF19: =+Z19-AC19 -> 14844.957 | AG19: =+AA19-AD19 -> 21888.953
B20: 전주 | G20: =+I20 -> 전주 | I20: 전주 | J20: =+IFERROR(HLOOKUP($B20,'[1]10월'!$D$6:$BN$259,2,),)/1000 -> 12 | K20: =+IFERROR(HLOOKUP($B20,'[2]10월'!$F$6:$CP$99,2,),)/1000 -> 14.1595 | L20: =+K20-J20 -> 2.1595 | M20: =+IFERROR(HLOOKUP($B20,'[3]10월'!$F$6:$CC$57,2,),)/1000 -> 9.6695 | N20: =+K20-M20 -> 4.49 | O20: =+IFERROR(HLOOKUP($B20,'[1]10월'!$D$6:$BN$259,3,),)/1000 -> 1209.9309 | P20: =+IFERROR(HLOOKUP($B20,'[2]10월'!$F$6:$CP$99,3,),)/1000 -> 1377.131 | Q20: =+P20-O20 -> 167.20013 | R20: =+IFERROR(HLOOKUP($B20,'[3]10월'!$F$6:$CC$57,3,),)/1000 -> 921.15986 | S20: =+P20-R20 -> 455.97114 | T20: =+IFERROR(HLOOKUP($B20,'[1]10월'!$D$6:$BN$259,16,),)/1000 -> 178.63194 | U20: =+IFERROR(HLOOKUP($B20,'[2]10월'!$F$6:$CP$99,16,),)/1000 -> 116.3473 | V20: =+U20-T20 -> -62.284642 | W20: =+IFERROR(HLOOKUP($B20,'[3]10월'!$F$6:$CC$57,16,),)/1000 -> 51.295807 | X20: =+U20-W20 -> 65.051495 | Y20: =+[4]전주!$Q$85 -> 100827.57 | Z20: =+[4]전주!$R$85 -> 97258.448 | AA20: =+[5]전주!$Q$85 -> 95264.477 | AB20: =+[4]전주!$Q$89 -> 73158.252 | AC20: =+[4]전주!$R$89 -> 77596.677 | AD20: =+[5]전주!$Q$89 -> 74505.129 | AE20: =+Y20-AB20 -> 27669.321 | AF20: =+Z20-AC20 -> 19661.771 | AG20: =+AA20-AD20 -> 20759.349
B21: 군산 | G21: =+I21 -> 군산 | I21: 군산 | J21: =+IFERROR(HLOOKUP($B21,'[1]10월'!$D$6:$BN$259,2,),)/1000 -> 7.5 | K21: =+IFERROR(HLOOKUP($B21,'[2]10월'!$F$6:$CP$99,2,),)/1000 -> 3.4525 | L21: =+K21-J21 -> -4.0475 | M21: =+IFERROR(HLOOKUP($B21,'[3]10월'!$F$6:$CC$57,2,),)/1000 -> 9.023 | N21: =+K21-M21 -> -5.5705 | O21: =+IFERROR(HLOOKUP($B21,'[1]10월'!$D$6:$BN$259,3,),)/1000 -> 832.8538 | P21: =+IFERROR(HLOOKUP($B21,'[2]10월'!$F$6:$CP$99,3,),)/1000 -> 373.21672 | Q21: =+P21-O21 -> -459.63708 | R21: =+IFERROR(HLOOKUP($B21,'[3]10월'!$F$6:$CC$57,3,),)/1000 -> 1002.9886 | S21: =+P21-R21 -> -629.77183 | T21: =+IFERROR(HLOOKUP($B21,'[1]10월'!$D$6:$BN$259,16,),)/1000 -> 205.06836 | U21: =+IFERROR(HLOOKUP($B21,'[2]10월'!$F$6:$CP$99,16,),)/1000 -> 39.536474 | V21: =+U21-T21 -> -165.53188 | W21: =+IFERROR(HLOOKUP($B21,'[3]10월'!$F$6:$CC$57,16,),)/1000 -> 268.54539 | X21: =+U21-W21 -> -229.00891 | Y21: =+[4]군산!$Q$85 -> 111047.17 | Z21: =+[4]군산!$R$85 -> 108100.43 | AA21: =+[5]군산!$Q$85 -> 111159.1 | AB21: =+[4]군산!$Q$89 -> 72853.802 | AC21: =+[4]군산!$R$89 -> 72659.812 | AD21: =+[5]군산!$Q$89 -> 72170.12 | AE21: =+Y21-AB21 -> 38193.371 | AF21: =+Z21-AC21 -> 35440.613 | AG21: =+AA21-AD21 -> 38988.979
B22: 원주 | G22: =+I22 -> 원주 | I22: 원주 | J22: =+IFERROR(HLOOKUP($B22,'[1]10월'!$D$6:$BN$259,2,),)/1000 -> 5 | K22: =+IFERROR(HLOOKUP($B22,'[2]10월'!$F$6:$CP$99,2,),)/1000 -> 4.295 | L22: =+K22-J22 -> -0.705 | M22: =+IFERROR(HLOOKUP($B22,'[3]10월'!$F$6:$CC$57,2,),)/1000 -> 5.544 | N22: =+K22-M22 -> -1.249 | O22: =+IFERROR(HLOOKUP($B22,'[1]10월'!$D$6:$BN$259,3,),)/1000 -> 560 | P22: =+IFERROR(HLOOKUP($B22,'[2]10월'!$F$6:$CP$99,3,),)/1000 -> 473.8182 | Q22: =+P22-O22 -> -86.1818 | R22: =+IFERROR(HLOOKUP($B22,'[3]10월'!$F$6:$CC$57,3,),)/1000 -> 603.98328 | S22: =+P22-R22 -> -130.16508 | T22: =+IFERROR(HLOOKUP($B22,'[1]10월'!$D$6:$BN$259,16,),)/1000 -> 103.86534 | U22: =+IFERROR(HLOOKUP($B22,'[2]10월'!$F$6:$CP$99,16,),)/1000 -> 85.403377 | V22: =+U22-T22 -> -18.461964 | W22: =+IFERROR(HLOOKUP($B22,'[3]10월'!$F$6:$CC$57,16,),)/1000 -> 104.30831 | X22: =+U22-W22 -> -18.904933 | Y22: =+[4]원주!$Q$85 -> 112000 | Z22: =+[4]원주!$R$85 -> 110318.56 | AA22: =+[5]원주!$Q$85 -> 108943.59 | AB22: =+[4]원주!$Q$89 -> 73062.22 | AC22: =+[4]원주!$R$89 -> 70416.195 | AD22: =+[5]원주!$Q$89 -> 73906.808 | AE22: =+Y22-AB22 -> 38937.78 | AF22: =+Z22-AC22 -> 39902.362 | AG22: =+AA22-AD22 -> 35036.784
B23: 제주 | F23: =+K27-J27 -> -60.712 | G23: =+I23 -> 제주 | I23: 제주 | J23: =+IFERROR(HLOOKUP($B23,'[1]10월'!$D$6:$BN$259,2,),)/1000 -> 8 | K23: =+IFERROR(HLOOKUP($B23,'[2]10월'!$F$6:$CP$99,2,),)/1000 -> 3.72 | L23: =+K23-J23 -> -4.28 | M23: =+IFERROR(HLOOKUP($B23,'[3]10월'!$F$6:$CC$57,2,),)/1000 -> 3.047 | N23: =+K23-M23 -> 0.673 | O23: =+IFERROR(HLOOKUP($B23,'[1]10월'!$D$6:$BN$259,3,),)/1000 -> 980.908 | P23: =+IFERROR(HLOOKUP($B23,'[2]10월'!$F$6:$CP$99,3,),)/1000 -> 470.50297 | Q23: =+P23-O23 -> -510.40503 | R23: =+IFERROR(HLOOKUP($B23,'[3]10월'!$F$6:$CC$57,3,),)/1000 -> 366.41407 | S23: =+P23-R23 -> 104.0889 | T23: =+IFERROR(HLOOKUP($B23,'[1]10월'!$D$6:$BN$259,16,),)/1000 -> 150.10859 | U23: =+IFERROR(HLOOKUP($B23,'[2]10월'!$F$6:$CP$99,16,),)/1000 -> -10.044988 | V23: =+U23-T23 -> -160.15358 | W23: =+IFERROR(HLOOKUP($B23,'[3]10월'!$F$6:$CC$57,16,),)/1000 -> 4.79407 | X23: =+U23-W23 -> -14.839058 | Y23: =+[4]제주!$Q$85 -> 122613.5 | Z23: =+[4]제주!$R$85 -> 126350.89 | AA23: =+[5]제주!$Q$85 -> 120254.04 | AB23: =+[4]제주!$Q$89 -> 91127.321 | AC23: =+[4]제주!$R$89 -> 99085.227 | AD23: =+[5]제주!$Q$89 -> 91133.112 | AE23: =+Y23-AB23 -> 31486.179 | AF23: =+Z23-AC23 -> 27265.664 | AG23: =+AA23-AD23 -> 29120.931
F24: =+K24/J24 -> 0.82314063 | G24: =+I24 -> 수도권 | I24: 수도권 | J24: =SUM(J7:J10) -> 96 | K24: =SUM(K7:K10) -> 79.0215 | L24: =+K24-J24 -> -16.9785 | M24: =SUM(M7:M10) -> 103.91 | N24: =+K24-M24 -> -24.8885 | O24: =SUM(O7:O10) -> 9606.6544 | P24: =SUM(P7:P10) -> 7480.3883 | Q24: =+P24-O24 -> -2126.2661 | R24: =SUM(R7:R10) -> 9713.52 | S24: =+P24-R24 -> -2233.1317 | T24: =SUM(T7:T10) -> 827.85557 | U24: =SUM(U7:U10) -> 72.705947 | V24: =+U24-T24 -> -755.14962 | W24: =SUM(W7:W10) -> 363.42568 | X24: =+U24-W24 -> -290.71973 | Y24: =+[4]수도권!$Q$85 -> 100069.32 | Z24: =+[4]수도권!$R$85 -> 94672.854 | AA24: =+[5]수도권!$Q$85 -> 93480.666 | AB24: =+[4]수도권!$Q$89 -> 81319.97 | AC24: =+[4]수도권!$R$89 -> 80864.4 | AD24: =+[5]수도권!$Q$89 -> 80496.449 | AE24: =+Y24-AB24 -> 18749.347 | AF24: =+Z24-AC24 -> 13808.455 | AG24: =+AA24-AD24 -> 12984.216
F25: =+K25/J25 -> 0.70944269 | G25: =+I25 -> 영남권 | I25: 영남권 | J25: =SUM(J11:J18) -> 126.5 | K25: =SUM(K11:K18) -> 89.7445 | L25: =+K25-J25 -> -36.7555 | M25: =SUM(M11:M18) -> 130.221 | N25: =+K25-M25 -> -40.4765 | O25: =SUM(O11:O18) -> 12713.985 | P25: =SUM(P11:P18) -> 8957.926 | Q25: =+P25-O25 -> -3756.0594 | R25: =SUM(R11:R18) -> 12503.422 | S25: =+P25-R25 -> -3545.4959 | T25: =SUM(T11:T18) -> 1245.3515 | U25: =SUM(U11:U18) -> 179.44382 | V25: =+U25-T25 -> -1065.9077 | W25: =SUM(W11:W18) -> 830.76104 | X25: =+U25-W25 -> -651.31721 | Y25: =+[4]영남권!$Q$85 -> 100505.81 | Z25: =+[4]영남권!$R$85 -> 99815.877 | AA25: =+[5]영남권!$Q$85 -> 96016.649 | AB25: =+[4]영남권!$Q$89 -> 78927.233 | AC25: =+[4]영남권!$R$89 -> 81714.808 | AD25: =+[5]영남권!$Q$89 -> 78191.758 | AE25: =+Y25-AB25 -> 21578.581 | AF25: =+Z25-AC25 -> 18101.069 | AG25: =+AA25-AD25 -> 17824.891
F26: =+K26/J26 -> 0.86957009 | G26: =+I26 -> 중부권 | I26: 중부권 | J26: =SUM(J19:J23) -> 53.5 | K26: =SUM(K19:K23) -> 46.522 | L26: =+K26-J26 -> -6.978 | M26: =SUM(M19:M23) -> 62.426 | N26: =+K26-M26 -> -15.904 | O26: =SUM(O19:O23) -> 5746.6927 | P26: =SUM(P19:P23) -> 4705.6378 | Q26: =+P26-O26 -> -1041.0549 | R26: =SUM(R19:R23) -> 6311.6097 | S26: =+P26-R26 -> -1605.9719 | T26: =SUM(T19:T23) -> 919.42375 | U26: =SUM(U19:U23) -> 299.70937 | V26: =+U26-T26 -> -619.71438 | W26: =SUM(W19:W23) -> 947.08472 | X26: =+U26-W26 -> -647.37534 | Y26: =+[4]중부권!$Q$85 -> 107414.82 | Z26: =+[4]중부권!$R$85 -> 101081.36 | AA26: =+[5]중부권!$Q$85 -> 101095.66 | AB26: =+[4]중부권!$Q$89 -> 77700.143 | AC26: =+[4]중부권!$R$89 -> 79950.247 | AD26: =+[5]중부권!$Q$89 -> 75393.477 | AE26: =+Y26-AB26 -> 29714.673 | AF26: =+Z26-AC26 -> 21131.108 | AG26: =+AA26-AD26 -> 25702.179
F27: =+K27/M27 -> 0.72595825 | G27: =+K27/J27 -> 0.78002899 | H27: 레미콘 계 | J27: =SUM(J24:J26) -> 276 | K27: =SUM(K24:K26) -> 215.288 | L27: =+K27-J27 -> -60.712 | M27: =SUM(M24:M26) -> 296.557 | N27: =+K27-M27 -> -81.269 | O27: =SUM(O24:O26) -> 28067.332 | P27: =SUM(P24:P26) -> 21143.952 | Q27: =+P27-O27 -> -6923.3804 | R27: =SUM(R24:R26) -> 28528.552 | S27: =+P27-R27 -> -7384.5995 | T27: =SUM(T24:T26) -> 2992.6308 | U27: =SUM(U24:U26) -> 551.85915 | V27: =+U27-T27 -> -2440.7717 | W27: =SUM(W24:W26) -> 2141.2714 | X27: =+U27-W27 -> -1589.4123 | Y27: =+[4]합계!$Q$85 -> 101693.23 | Z27: =+[4]합계!$R$85 -> 98207.724 | AA27: =+[5]합계!$Q$85 -> 96197.561 | AB27: =+[4]합계!$Q$89 -> 79521.629 | AC27: =+[4]합계!$R$89 -> 81022.029 | AD27: =+[5]합계!$Q$89 -> 78411.451 | AE27: =+Y27-AB27 -> 22171.604 | AF27: =+Z27-AC27 -> 17185.695 | AG27: =+AA27-AD27 -> 17786.111 | AI27: =+AF27-AE27 -> -4985.9095 | AJ27: =+AF27-AG27 -> -600.41591
B28: 건자재 | E28: 건자재영업 | G28: 건자재 | H28: 건자재 | J28: =+IFERROR(HLOOKUP($B28,'[1]10월'!$D$6:$BN$259,2,),) -> 11000 | K28: =+IFERROR(HLOOKUP($E28,'[2]10월'!$F$6:$CP$99,2,),) -> 6655.619 | L28: =+K28-J28 -> -4344.381 | M28: =+IFERROR(HLOOKUP($E28,'[3]10월'!$F$6:$CC$57,2,),) -> 8972.008 | N28: =+K28-M28 -> -2316.389 | O28: =+IFERROR(HLOOKUP($B28,'[1]10월'!$D$6:$BN$259,3,),)/1000 -> 11978.569 | P28: =+IFERROR(HLOOKUP($E28,'[2]10월'!$F$6:$CP$99,3,),)/1000 -> 6923.7765 | Q28: =+P28-O28 -> -5054.7921 | R28: =+IFERROR(HLOOKUP($E28,'[3]10월'!$F$6:$CC$57,3,),)/1000 -> 8678.6853 | S28: =+P28-R28 -> -1754.9088 | T28: =+IFERROR(HLOOKUP($B28,'[1]10월'!$D$6:$BN$259,16,),)/1000 -> 200.06055 | U28: =+IFERROR(HLOOKUP($E28,'[2]10월'!$F$6:$CP$99,16,),)/1000 -> -37.086785 | V28: =+U28-T28 -> -237.14733 | W28: =+IFERROR(HLOOKUP($E28,'[3]10월'!$F$6:$CC$57,16,),)/1000 -> 44.005329 | X28: =+U28-W28 -> -81.092114 | Y28: ■ 비고
B29: 부산모래장 | C29: 부산골재 | G29: =+I29 -> 부산모래장 | H29: 골재 | I29: 부산모래장 | J29: =+IFERROR(HLOOKUP($B29,'[1]10월'!$D$6:$BN$259,2,),)/1000 -> 22.914307 | K29: =+IFERROR(HLOOKUP($C29,'[2]10월'!$F$6:$CP$99,2,),)/1000 -> 19.249 | L29: =+K29-J29 -> -3.6653074 | M29: =+IFERROR(HLOOKUP($C29,'[3]10월'!$F$6:$CC$57,2,),)/1000 -> 20.119 | N29: =+K29-M29 -> -0.87 | O29: =+IFERROR(HLOOKUP($B29,'[1]10월'!$D$6:$BN$259,3,),)/1000 -> 620.32427 | P29: =+IFERROR(HLOOKUP($C29,'[2]10월'!$F$6:$CP$99,3,),)/1000 -> 548.1334 | Q29: =+P29-O29 -> -72.190867 | R29: =+IFERROR(HLOOKUP($C29,'[3]10월'!$F$6:$CC$57,3,),)/1000 -> 571.11 | S29: =+P29-R29 -> -22.9766 | T29: =+IFERROR(HLOOKUP($B29,'[1]10월'!$D$6:$BN$259,21,),)/1000 -> 50.5739 | U29: =+IFERROR(HLOOKUP($C29,'[2]10월'!$F$6:$CP$99,21,),)/1000 -> 15.814881 | V29: =+U29-T29 -> -34.759019 | W29: =+IFERROR(HLOOKUP($C29,'[3]10월'!$F$6:$CC$57,21,),)/1000 -> 53.934357 | X29: =+U29-W29 -> -38.119476
B30: 서부산크라샤 | C30: 서부산골재 | G30: =+I30 -> 서부산CR | I30: 서부산CR | J30: =+IFERROR(HLOOKUP($B30,'[1]10월'!$D$6:$BN$259,2,),)/1000 -> 45.741815 | K30: =+IFERROR(HLOOKUP($C30,'[2]10월'!$F$6:$CP$99,2,),)/1000 -> 32.2 | L30: =+K30-J30 -> -13.541815 | M30: =+IFERROR(HLOOKUP($C30,'[3]10월'!$F$6:$CC$57,2,),)/1000 -> 1.36 | N30: =+K30-M30 -> 30.84 | O30: =+IFERROR(HLOOKUP($B30,'[1]10월'!$D$6:$BN$259,3,),)/1000 -> 659.92864 | P30: =+IFERROR(HLOOKUP($C30,'[2]10월'!$F$6:$CP$99,3,),)/1000 -> 415.688 | Q30: =+P30-O30 -> -244.24064 | R30: =+IFERROR(HLOOKUP($C30,'[3]10월'!$F$6:$CC$57,3,),)/1000 -> 15.64 | S30: =+P30-R30 -> 400.048 | T30: =+IFERROR(HLOOKUP($B30,'[1]10월'!$D$6:$BN$259,21,),)/1000 -> 81.628816 | U30: =+IFERROR(HLOOKUP($C30,'[2]10월'!$F$6:$CP$99,21,),)/1000 -> -36.946808 | V30: =+U30-T30 -> -118.57562 | W30: =+IFERROR(HLOOKUP($C30,'[3]10월'!$F$6:$CC$57,21,),)/1000 -> -83.948514 | X30: =+U30-W30 -> 47.001706
